package net.arcticraft.world.gen;

import java.util.Random;

import net.arcticraft.block.ACBlocks;
import net.minecraft.block.Block;
import net.minecraft.init.Blocks;
import net.minecraft.tileentity.TileEntityChest;
import net.minecraft.util.WeightedRandomChestContent;
import net.minecraft.world.World;
import net.minecraft.world.chunk.IChunkProvider;
import net.minecraftforge.common.ChestGenHooks;
import cpw.mods.fml.common.IWorldGenerator;

public class WorldGenIceberg implements IWorldGenerator {
	protected Block[] GetValidSpawnBlocks() {
		return new Block[] { ACBlocks.frostWaterBlock };
	}

	public boolean LocationIsValidSpawn(World world, int i, int j, int k) {
		int distanceToAir = 0;
		Block checkID = world.getBlock(i, j, k);

		while (checkID != null) {
			distanceToAir++;
			checkID = world.getBlock(i, j + distanceToAir, k);
		}

		if (distanceToAir > 9) {
			return false;
		}
		j += distanceToAir - 1;

		Block blockID = world.getBlock(i, j, k);
		Block blockIDAbove = world.getBlock(i, j + 1, k);
		Block blockIDBelow = world.getBlock(i, j - 1, k);
		for (Block x : GetValidSpawnBlocks()) {
			if (blockIDAbove != null) {
				return false;
			}
			if (blockID == x) {
				return true;
			} else if (blockID == Blocks.snow && blockIDBelow == x) {
				return true;
			}
		}
		return false;
	}

	public boolean generate(World world, Random rand, int i, int j, int k) {
		if (rand.nextInt(1000) > 5)
			return false;
		
		j -= 11;
		
		world.setBlock(i + 0, j + 0, k + 17, ACBlocks.frostWaterIce);
		world.setBlock(i + 0, j + 0, k + 18, ACBlocks.frostWaterIce);
		world.setBlock(i + 0, j + 0, k + 19, ACBlocks.frostWaterIce);
		world.setBlock(i + 0, j + 0, k + 20, ACBlocks.frostWaterIce);
		world.setBlock(i + 0, j + 1, k + 17, ACBlocks.frostWaterIce);
		world.setBlock(i + 0, j + 1, k + 18, ACBlocks.frostWaterIce);
		world.setBlock(i + 0, j + 1, k + 19, ACBlocks.frostWaterIce);
		world.setBlock(i + 0, j + 1, k + 20, ACBlocks.frostWaterIce);
		world.setBlock(i + 0, j + 2, k + 17, ACBlocks.frostWaterIce);
		world.setBlock(i + 0, j + 2, k + 18, ACBlocks.frostWaterIce);
		world.setBlock(i + 0, j + 2, k + 19, ACBlocks.frostWaterIce);
		world.setBlock(i + 0, j + 2, k + 20, ACBlocks.frostWaterIce);
		world.setBlock(i + 1, j + 0, k + 15, ACBlocks.frostWaterIce);
		world.setBlock(i + 1, j + 0, k + 16, ACBlocks.frostWaterIce);
		world.setBlock(i + 1, j + 0, k + 17, ACBlocks.frostWaterIce);
		world.setBlock(i + 1, j + 0, k + 18, ACBlocks.frostWaterIce);
		world.setBlock(i + 1, j + 0, k + 19, ACBlocks.frostWaterIce);
		world.setBlock(i + 1, j + 0, k + 20, ACBlocks.frostWaterIce);
		world.setBlock(i + 1, j + 0, k + 21, ACBlocks.frostWaterIce);
		world.setBlock(i + 1, j + 0, k + 22, ACBlocks.frostWaterIce);
		world.setBlock(i + 1, j + 1, k + 15, ACBlocks.frostWaterIce);
		world.setBlock(i + 1, j + 1, k + 16, ACBlocks.frostWaterIce);
		world.setBlock(i + 1, j + 1, k + 17, ACBlocks.frostWaterIce);
		world.setBlock(i + 1, j + 1, k + 18, ACBlocks.frostWaterIce);
		world.setBlock(i + 1, j + 1, k + 19, ACBlocks.frostWaterIce);
		world.setBlock(i + 1, j + 1, k + 20, ACBlocks.frostWaterIce);
		world.setBlock(i + 1, j + 1, k + 21, ACBlocks.frostWaterIce);
		world.setBlock(i + 1, j + 1, k + 22, ACBlocks.frostWaterIce);
		world.setBlock(i + 1, j + 2, k + 16, ACBlocks.frostWaterIce);
		world.setBlock(i + 1, j + 2, k + 17, ACBlocks.frostWaterIce);
		world.setBlock(i + 1, j + 2, k + 18, ACBlocks.frostWaterIce);
		world.setBlock(i + 1, j + 2, k + 19, ACBlocks.frostWaterIce);
		world.setBlock(i + 1, j + 2, k + 20, ACBlocks.frostWaterIce);
		world.setBlock(i + 1, j + 2, k + 21, ACBlocks.frostWaterIce);
		world.setBlock(i + 1, j + 3, k + 16, ACBlocks.frostWaterIce);
		world.setBlock(i + 1, j + 3, k + 17, ACBlocks.frostWaterIce);
		world.setBlock(i + 1, j + 3, k + 18, ACBlocks.frostWaterIce);
		world.setBlock(i + 1, j + 3, k + 19, ACBlocks.frostWaterIce);
		world.setBlock(i + 1, j + 3, k + 20, ACBlocks.frostWaterIce);
		world.setBlock(i + 1, j + 3, k + 21, ACBlocks.frostWaterIce);
		world.setBlock(i + 1, j + 4, k + 18, ACBlocks.frostWaterIce);
		world.setBlock(i + 1, j + 4, k + 19, ACBlocks.frostWaterIce);
		world.setBlock(i + 2, j + 0, k + 13, ACBlocks.frostWaterIce);
		world.setBlock(i + 2, j + 0, k + 14, ACBlocks.frostWaterIce);
		world.setBlock(i + 2, j + 0, k + 15, ACBlocks.frostWaterIce);
		world.setBlock(i + 2, j + 0, k + 16, ACBlocks.frostWaterIce);
		world.setBlock(i + 2, j + 0, k + 17, ACBlocks.frostWaterIce);
		world.setBlock(i + 2, j + 0, k + 18, ACBlocks.frostWaterIce);
		world.setBlock(i + 2, j + 0, k + 19, ACBlocks.frostWaterIce);
		world.setBlock(i + 2, j + 0, k + 20, ACBlocks.frostWaterIce);
		world.setBlock(i + 2, j + 0, k + 21, ACBlocks.frostWaterIce);
		world.setBlock(i + 2, j + 0, k + 22, ACBlocks.frostWaterIce);
		world.setBlock(i + 2, j + 1, k + 13, ACBlocks.frostWaterIce);
		world.setBlock(i + 2, j + 1, k + 14, ACBlocks.frostWaterIce);
		world.setBlock(i + 2, j + 1, k + 15, ACBlocks.frostWaterIce);
		world.setBlock(i + 2, j + 1, k + 16, ACBlocks.frostWaterIce);
		world.setBlock(i + 2, j + 1, k + 17, ACBlocks.frostWaterIce);
		world.setBlock(i + 2, j + 1, k + 18, ACBlocks.frostWaterIce);
		world.setBlock(i + 2, j + 1, k + 19, ACBlocks.frostWaterIce);
		world.setBlock(i + 2, j + 1, k + 20, ACBlocks.frostWaterIce);
		world.setBlock(i + 2, j + 1, k + 21, ACBlocks.frostWaterIce);
		world.setBlock(i + 2, j + 1, k + 22, ACBlocks.frostWaterIce);
		world.setBlock(i + 2, j + 2, k + 15, ACBlocks.frostWaterIce);
		world.setBlock(i + 2, j + 2, k + 16, ACBlocks.frostWaterIce);
		world.setBlock(i + 2, j + 2, k + 17, ACBlocks.frostWaterIce);
		world.setBlock(i + 2, j + 2, k + 18, ACBlocks.frostWaterIce);
		world.setBlock(i + 2, j + 2, k + 19, ACBlocks.frostWaterIce);
		world.setBlock(i + 2, j + 2, k + 20, ACBlocks.frostWaterIce);
		world.setBlock(i + 2, j + 2, k + 21, ACBlocks.frostWaterIce);
		world.setBlock(i + 2, j + 2, k + 22, ACBlocks.frostWaterIce);
		world.setBlock(i + 2, j + 3, k + 15, ACBlocks.frostWaterIce);
		world.setBlock(i + 2, j + 3, k + 16, ACBlocks.frostWaterIce);
		world.setBlock(i + 2, j + 3, k + 17, ACBlocks.frostWaterIce);
		world.setBlock(i + 2, j + 3, k + 18, ACBlocks.frostWaterIce);
		world.setBlock(i + 2, j + 3, k + 19, ACBlocks.frostWaterIce);
		world.setBlock(i + 2, j + 3, k + 20, ACBlocks.frostWaterIce);
		world.setBlock(i + 2, j + 3, k + 21, ACBlocks.frostWaterIce);
		world.setBlock(i + 2, j + 3, k + 22, ACBlocks.frostWaterIce);
		world.setBlock(i + 2, j + 4, k + 16, ACBlocks.frostWaterIce);
		world.setBlock(i + 2, j + 4, k + 17, ACBlocks.frostWaterIce);
		world.setBlock(i + 2, j + 4, k + 18, ACBlocks.frostWaterIce);
		world.setBlock(i + 2, j + 4, k + 19, ACBlocks.frostWaterIce);
		world.setBlock(i + 2, j + 4, k + 20, ACBlocks.frostWaterIce);
		world.setBlock(i + 2, j + 4, k + 21, ACBlocks.frostWaterIce);
		world.setBlock(i + 3, j + 0, k + 11, ACBlocks.frostWaterIce);
		world.setBlock(i + 3, j + 0, k + 12, ACBlocks.frostWaterIce);
		world.setBlock(i + 3, j + 0, k + 13, ACBlocks.frostWaterIce);
		world.setBlock(i + 3, j + 0, k + 14, ACBlocks.frostWaterIce);
		world.setBlock(i + 3, j + 0, k + 15, ACBlocks.frostWaterIce);
		world.setBlock(i + 3, j + 0, k + 16, ACBlocks.frostWaterIce);
		world.setBlock(i + 3, j + 0, k + 17, ACBlocks.frostWaterIce);
		world.setBlock(i + 3, j + 0, k + 18, ACBlocks.frostWaterIce);
		world.setBlock(i + 3, j + 0, k + 19, ACBlocks.frostWaterIce);
		world.setBlock(i + 3, j + 0, k + 20, ACBlocks.frostWaterIce);
		world.setBlock(i + 3, j + 0, k + 21, ACBlocks.frostWaterIce);
		world.setBlock(i + 3, j + 0, k + 22, ACBlocks.frostWaterIce);
		world.setBlock(i + 3, j + 0, k + 23, ACBlocks.frostWaterIce);
		world.setBlock(i + 3, j + 1, k + 12, ACBlocks.frostWaterIce);
		world.setBlock(i + 3, j + 1, k + 13, ACBlocks.frostWaterIce);
		world.setBlock(i + 3, j + 1, k + 14, ACBlocks.frostWaterIce);
		world.setBlock(i + 3, j + 1, k + 15, ACBlocks.frostWaterIce);
		world.setBlock(i + 3, j + 1, k + 16, ACBlocks.frostWaterIce);
		world.setBlock(i + 3, j + 1, k + 17, ACBlocks.frostWaterIce);
		world.setBlock(i + 3, j + 1, k + 18, ACBlocks.frostWaterIce);
		world.setBlock(i + 3, j + 1, k + 19, ACBlocks.frostWaterIce);
		world.setBlock(i + 3, j + 1, k + 20, ACBlocks.frostWaterIce);
		world.setBlock(i + 3, j + 1, k + 21, ACBlocks.frostWaterIce);
		world.setBlock(i + 3, j + 1, k + 22, ACBlocks.frostWaterIce);
		world.setBlock(i + 3, j + 1, k + 23, ACBlocks.frostWaterIce);
		world.setBlock(i + 3, j + 2, k + 12, ACBlocks.frostWaterIce);
		world.setBlock(i + 3, j + 2, k + 13, ACBlocks.frostWaterIce);
		world.setBlock(i + 3, j + 2, k + 14, ACBlocks.frostWaterIce);
		world.setBlock(i + 3, j + 2, k + 15, ACBlocks.frostWaterIce);
		world.setBlock(i + 3, j + 2, k + 16, ACBlocks.frostWaterIce);
		world.setBlock(i + 3, j + 2, k + 17, ACBlocks.frostWaterIce);
		world.setBlock(i + 3, j + 2, k + 18, ACBlocks.frostWaterIce);
		world.setBlock(i + 3, j + 2, k + 19, ACBlocks.frostWaterIce);
		world.setBlock(i + 3, j + 2, k + 20, ACBlocks.frostWaterIce);
		world.setBlock(i + 3, j + 2, k + 21, ACBlocks.frostWaterIce);
		world.setBlock(i + 3, j + 2, k + 22, ACBlocks.frostWaterIce);
		world.setBlock(i + 3, j + 2, k + 23, ACBlocks.frostWaterIce);
		world.setBlock(i + 3, j + 3, k + 14, ACBlocks.frostWaterIce);
		world.setBlock(i + 3, j + 3, k + 15, ACBlocks.frostWaterIce);
		world.setBlock(i + 3, j + 3, k + 16, ACBlocks.frostWaterIce);
		world.setBlock(i + 3, j + 3, k + 17, ACBlocks.frostWaterIce);
		world.setBlock(i + 3, j + 3, k + 18, ACBlocks.frostWaterIce);
		world.setBlock(i + 3, j + 3, k + 19, ACBlocks.frostWaterIce);
		world.setBlock(i + 3, j + 3, k + 20, ACBlocks.frostWaterIce);
		world.setBlock(i + 3, j + 3, k + 21, ACBlocks.frostWaterIce);
		world.setBlock(i + 3, j + 3, k + 22, ACBlocks.frostWaterIce);
		world.setBlock(i + 3, j + 4, k + 16, ACBlocks.frostWaterIce);
		world.setBlock(i + 3, j + 4, k + 17, ACBlocks.frostWaterIce);
		world.setBlock(i + 3, j + 4, k + 18, ACBlocks.frostWaterIce);
		world.setBlock(i + 3, j + 4, k + 19, ACBlocks.frostWaterIce);
		world.setBlock(i + 3, j + 4, k + 20, ACBlocks.frostWaterIce);
		world.setBlock(i + 3, j + 4, k + 21, ACBlocks.frostWaterIce);
		world.setBlock(i + 3, j + 5, k + 17, ACBlocks.frostWaterIce);
		world.setBlock(i + 3, j + 5, k + 18, ACBlocks.frostWaterIce);
		world.setBlock(i + 3, j + 5, k + 19, ACBlocks.frostWaterIce);
		world.setBlock(i + 3, j + 5, k + 20, ACBlocks.frostWaterIce);
		world.setBlock(i + 4, j + 0, k + 9, ACBlocks.frostWaterIce);
		world.setBlock(i + 4, j + 0, k + 10, ACBlocks.frostWaterIce);
		world.setBlock(i + 4, j + 0, k + 11, ACBlocks.frostWaterIce);
		world.setBlock(i + 4, j + 0, k + 12, ACBlocks.frostWaterIce);
		world.setBlock(i + 4, j + 0, k + 13, ACBlocks.frostWaterIce);
		world.setBlock(i + 4, j + 0, k + 14, ACBlocks.frostWaterIce);
		world.setBlock(i + 4, j + 0, k + 15, ACBlocks.frostWaterIce);
		world.setBlock(i + 4, j + 0, k + 16, ACBlocks.frostWaterIce);
		world.setBlock(i + 4, j + 0, k + 17, ACBlocks.frostWaterIce);
		world.setBlock(i + 4, j + 0, k + 18, ACBlocks.frostWaterIce);
		world.setBlock(i + 4, j + 0, k + 19, ACBlocks.frostWaterIce);
		world.setBlock(i + 4, j + 0, k + 20, ACBlocks.frostWaterIce);
		world.setBlock(i + 4, j + 0, k + 21, ACBlocks.frostWaterIce);
		world.setBlock(i + 4, j + 0, k + 22, ACBlocks.frostWaterIce);
		world.setBlock(i + 4, j + 0, k + 23, ACBlocks.frostWaterIce);
		world.setBlock(i + 4, j + 1, k + 9, ACBlocks.frostWaterIce);
		world.setBlock(i + 4, j + 1, k + 10, ACBlocks.frostWaterIce);
		world.setBlock(i + 4, j + 1, k + 11, ACBlocks.frostWaterIce);
		world.setBlock(i + 4, j + 1, k + 12, ACBlocks.frostWaterIce);
		world.setBlock(i + 4, j + 1, k + 13, ACBlocks.frostWaterIce);
		world.setBlock(i + 4, j + 1, k + 14, ACBlocks.frostWaterIce);
		world.setBlock(i + 4, j + 1, k + 15, ACBlocks.frostWaterIce);
		world.setBlock(i + 4, j + 1, k + 16, ACBlocks.frostWaterIce);
		world.setBlock(i + 4, j + 1, k + 17, ACBlocks.frostWaterIce);
		world.setBlock(i + 4, j + 1, k + 18, ACBlocks.frostWaterIce);
		world.setBlock(i + 4, j + 1, k + 19, ACBlocks.frostWaterIce);
		world.setBlock(i + 4, j + 1, k + 20, ACBlocks.frostWaterIce);
		world.setBlock(i + 4, j + 1, k + 21, ACBlocks.frostWaterIce);
		world.setBlock(i + 4, j + 1, k + 22, ACBlocks.frostWaterIce);
		world.setBlock(i + 4, j + 1, k + 23, ACBlocks.frostWaterIce);
		world.setBlock(i + 4, j + 2, k + 11, ACBlocks.frostWaterIce);
		world.setBlock(i + 4, j + 2, k + 12, ACBlocks.frostWaterIce);
		world.setBlock(i + 4, j + 2, k + 13, ACBlocks.frostWaterIce);
		world.setBlock(i + 4, j + 2, k + 14, ACBlocks.frostWaterIce);
		world.setBlock(i + 4, j + 2, k + 15, ACBlocks.frostWaterIce);
		world.setBlock(i + 4, j + 2, k + 16, ACBlocks.frostWaterIce);
		world.setBlock(i + 4, j + 2, k + 17, ACBlocks.frostWaterIce);
		world.setBlock(i + 4, j + 2, k + 18, ACBlocks.frostWaterIce);
		world.setBlock(i + 4, j + 2, k + 19, ACBlocks.frostWaterIce);
		world.setBlock(i + 4, j + 2, k + 20, ACBlocks.frostWaterIce);
		world.setBlock(i + 4, j + 2, k + 21, ACBlocks.frostWaterIce);
		world.setBlock(i + 4, j + 2, k + 22, ACBlocks.frostWaterIce);
		world.setBlock(i + 4, j + 2, k + 23, ACBlocks.frostWaterIce);
		world.setBlock(i + 4, j + 3, k + 12, ACBlocks.frostWaterIce);
		world.setBlock(i + 4, j + 3, k + 13, ACBlocks.frostWaterIce);
		world.setBlock(i + 4, j + 3, k + 14, ACBlocks.frostWaterIce);
		world.setBlock(i + 4, j + 3, k + 15, ACBlocks.frostWaterIce);
		world.setBlock(i + 4, j + 3, k + 16, ACBlocks.frostWaterIce);
		world.setBlock(i + 4, j + 3, k + 17, ACBlocks.frostWaterIce);
		world.setBlock(i + 4, j + 3, k + 18, ACBlocks.frostWaterIce);
		world.setBlock(i + 4, j + 3, k + 19, ACBlocks.frostWaterIce);
		world.setBlock(i + 4, j + 3, k + 20, ACBlocks.frostWaterIce);
		world.setBlock(i + 4, j + 3, k + 21, ACBlocks.frostWaterIce);
		world.setBlock(i + 4, j + 3, k + 22, ACBlocks.frostWaterIce);
		world.setBlock(i + 4, j + 4, k + 15, ACBlocks.frostWaterIce);
		world.setBlock(i + 4, j + 4, k + 16, ACBlocks.frostWaterIce);
		world.setBlock(i + 4, j + 4, k + 17, ACBlocks.frostWaterIce);
		world.setBlock(i + 4, j + 4, k + 18, ACBlocks.frostWaterIce);
		world.setBlock(i + 4, j + 4, k + 19, ACBlocks.frostWaterIce);
		world.setBlock(i + 4, j + 4, k + 20, ACBlocks.frostWaterIce);
		world.setBlock(i + 4, j + 4, k + 21, ACBlocks.frostWaterIce);
		world.setBlock(i + 4, j + 4, k + 22, ACBlocks.frostWaterIce);
		world.setBlock(i + 4, j + 5, k + 17, ACBlocks.frostWaterIce);
		world.setBlock(i + 4, j + 5, k + 18, ACBlocks.frostWaterIce);
		world.setBlock(i + 4, j + 5, k + 19, ACBlocks.frostWaterIce);
		world.setBlock(i + 4, j + 5, k + 20, ACBlocks.frostWaterIce);
		world.setBlock(i + 5, j + 0, k + 7, ACBlocks.frostWaterIce);
		world.setBlock(i + 5, j + 0, k + 8, ACBlocks.frostWaterIce);
		world.setBlock(i + 5, j + 0, k + 9, ACBlocks.frostWaterIce);
		world.setBlock(i + 5, j + 0, k + 10, ACBlocks.frostWaterIce);
		world.setBlock(i + 5, j + 0, k + 11, ACBlocks.frostWaterIce);
		world.setBlock(i + 5, j + 0, k + 12, ACBlocks.frostWaterIce);
		world.setBlock(i + 5, j + 0, k + 13, ACBlocks.frostWaterIce);
		world.setBlock(i + 5, j + 0, k + 14, ACBlocks.frostWaterIce);
		world.setBlock(i + 5, j + 0, k + 15, ACBlocks.frostWaterIce);
		world.setBlock(i + 5, j + 0, k + 16, ACBlocks.frostWaterIce);
		world.setBlock(i + 5, j + 0, k + 17, ACBlocks.frostWaterIce);
		world.setBlock(i + 5, j + 0, k + 18, ACBlocks.frostWaterIce);
		world.setBlock(i + 5, j + 0, k + 19, ACBlocks.frostWaterIce);
		world.setBlock(i + 5, j + 0, k + 20, ACBlocks.frostWaterIce);
		world.setBlock(i + 5, j + 0, k + 21, ACBlocks.frostWaterIce);
		world.setBlock(i + 5, j + 0, k + 22, ACBlocks.frostWaterIce);
		world.setBlock(i + 5, j + 0, k + 23, ACBlocks.frostWaterIce);
		world.setBlock(i + 5, j + 1, k + 8, ACBlocks.frostWaterIce);
		world.setBlock(i + 5, j + 1, k + 9, ACBlocks.frostWaterIce);
		world.setBlock(i + 5, j + 1, k + 10, ACBlocks.frostWaterIce);
		world.setBlock(i + 5, j + 1, k + 11, ACBlocks.frostWaterIce);
		world.setBlock(i + 5, j + 1, k + 12, ACBlocks.frostWaterIce);
		world.setBlock(i + 5, j + 1, k + 13, ACBlocks.frostWaterIce);
		world.setBlock(i + 5, j + 1, k + 14, ACBlocks.frostWaterIce);
		world.setBlock(i + 5, j + 1, k + 15, ACBlocks.frostWaterIce);
		world.setBlock(i + 5, j + 1, k + 16, ACBlocks.frostWaterIce);
		world.setBlock(i + 5, j + 1, k + 17, ACBlocks.frostWaterIce);
		world.setBlock(i + 5, j + 1, k + 18, ACBlocks.frostWaterIce);
		world.setBlock(i + 5, j + 1, k + 19, ACBlocks.frostWaterIce);
		world.setBlock(i + 5, j + 1, k + 20, ACBlocks.frostWaterIce);
		world.setBlock(i + 5, j + 1, k + 21, ACBlocks.frostWaterIce);
		world.setBlock(i + 5, j + 1, k + 22, ACBlocks.frostWaterIce);
		world.setBlock(i + 5, j + 1, k + 23, ACBlocks.frostWaterIce);
		world.setBlock(i + 5, j + 2, k + 8, ACBlocks.frostWaterIce);
		world.setBlock(i + 5, j + 2, k + 9, ACBlocks.frostWaterIce);
		world.setBlock(i + 5, j + 2, k + 10, ACBlocks.frostWaterIce);
		world.setBlock(i + 5, j + 2, k + 11, ACBlocks.frostWaterIce);
		world.setBlock(i + 5, j + 2, k + 12, ACBlocks.frostWaterIce);
		world.setBlock(i + 5, j + 2, k + 13, ACBlocks.frostWaterIce);
		world.setBlock(i + 5, j + 2, k + 14, ACBlocks.frostWaterIce);
		world.setBlock(i + 5, j + 2, k + 15, ACBlocks.frostWaterIce);
		world.setBlock(i + 5, j + 2, k + 16, ACBlocks.frostWaterIce);
		world.setBlock(i + 5, j + 2, k + 17, ACBlocks.frostWaterIce);
		world.setBlock(i + 5, j + 2, k + 18, ACBlocks.frostWaterIce);
		world.setBlock(i + 5, j + 2, k + 19, ACBlocks.frostWaterIce);
		world.setBlock(i + 5, j + 2, k + 20, ACBlocks.frostWaterIce);
		world.setBlock(i + 5, j + 2, k + 21, ACBlocks.frostWaterIce);
		world.setBlock(i + 5, j + 2, k + 22, ACBlocks.frostWaterIce);
		world.setBlock(i + 5, j + 2, k + 23, ACBlocks.frostWaterIce);
		world.setBlock(i + 5, j + 3, k + 10, ACBlocks.frostWaterIce);
		world.setBlock(i + 5, j + 3, k + 11, ACBlocks.frostWaterIce);
		world.setBlock(i + 5, j + 3, k + 12, ACBlocks.frostWaterIce);
		world.setBlock(i + 5, j + 3, k + 13, ACBlocks.frostWaterIce);
		world.setBlock(i + 5, j + 3, k + 14, ACBlocks.frostWaterIce);
		world.setBlock(i + 5, j + 3, k + 15, ACBlocks.frostWaterIce);
		world.setBlock(i + 5, j + 3, k + 16, ACBlocks.frostWaterIce);
		world.setBlock(i + 5, j + 3, k + 17, ACBlocks.frostWaterIce);
		world.setBlock(i + 5, j + 3, k + 18, ACBlocks.frostWaterIce);
		world.setBlock(i + 5, j + 3, k + 19, ACBlocks.frostWaterIce);
		world.setBlock(i + 5, j + 3, k + 20, ACBlocks.frostWaterIce);
		world.setBlock(i + 5, j + 3, k + 21, ACBlocks.frostWaterIce);
		world.setBlock(i + 5, j + 3, k + 22, ACBlocks.frostWaterIce);
		world.setBlock(i + 5, j + 4, k + 13, ACBlocks.frostWaterIce);
		world.setBlock(i + 5, j + 4, k + 14, ACBlocks.frostWaterIce);
		world.setBlock(i + 5, j + 4, k + 15, ACBlocks.frostWaterIce);
		world.setBlock(i + 5, j + 4, k + 16, ACBlocks.frostWaterIce);
		world.setBlock(i + 5, j + 4, k + 17, ACBlocks.frostWaterIce);
		world.setBlock(i + 5, j + 4, k + 18, ACBlocks.frostWaterIce);
		world.setBlock(i + 5, j + 4, k + 19, ACBlocks.frostWaterIce);
		world.setBlock(i + 5, j + 4, k + 20, ACBlocks.frostWaterIce);
		world.setBlock(i + 5, j + 4, k + 21, ACBlocks.frostWaterIce);
		world.setBlock(i + 5, j + 4, k + 22, ACBlocks.frostWaterIce);
		world.setBlock(i + 5, j + 5, k + 13, ACBlocks.frostWaterIce);
		world.setBlock(i + 5, j + 5, k + 14, ACBlocks.frostWaterIce);
		world.setBlock(i + 5, j + 5, k + 15, ACBlocks.frostWaterIce);
		world.setBlock(i + 5, j + 5, k + 16, ACBlocks.frostWaterIce);
		world.setBlock(i + 5, j + 5, k + 17, ACBlocks.frostWaterIce);
		world.setBlock(i + 5, j + 5, k + 18, ACBlocks.frostWaterIce);
		world.setBlock(i + 5, j + 5, k + 19, ACBlocks.frostWaterIce);
		world.setBlock(i + 5, j + 5, k + 20, ACBlocks.frostWaterIce);
		world.setBlock(i + 5, j + 6, k + 13, ACBlocks.frostWaterIce);
		world.setBlock(i + 5, j + 6, k + 14, ACBlocks.frostWaterIce);
		world.setBlock(i + 5, j + 6, k + 15, ACBlocks.frostWaterIce);
		world.setBlock(i + 5, j + 6, k + 16, ACBlocks.frostWaterIce);
		world.setBlock(i + 6, j + 0, k + 7, ACBlocks.frostWaterIce);
		world.setBlock(i + 6, j + 0, k + 8, ACBlocks.frostWaterIce);
		world.setBlock(i + 6, j + 0, k + 9, ACBlocks.frostWaterIce);
		world.setBlock(i + 6, j + 0, k + 10, ACBlocks.frostWaterIce);
		world.setBlock(i + 6, j + 0, k + 11, ACBlocks.frostWaterIce);
		world.setBlock(i + 6, j + 0, k + 12, ACBlocks.frostWaterIce);
		world.setBlock(i + 6, j + 0, k + 13, ACBlocks.frostWaterIce);
		world.setBlock(i + 6, j + 0, k + 14, ACBlocks.frostWaterIce);
		world.setBlock(i + 6, j + 0, k + 15, ACBlocks.frostWaterIce);
		world.setBlock(i + 6, j + 0, k + 16, ACBlocks.frostWaterIce);
		world.setBlock(i + 6, j + 0, k + 17, ACBlocks.frostWaterIce);
		world.setBlock(i + 6, j + 0, k + 18, ACBlocks.frostWaterIce);
		world.setBlock(i + 6, j + 0, k + 19, ACBlocks.frostWaterIce);
		world.setBlock(i + 6, j + 0, k + 20, ACBlocks.frostWaterIce);
		world.setBlock(i + 6, j + 0, k + 21, ACBlocks.frostWaterIce);
		world.setBlock(i + 6, j + 0, k + 22, ACBlocks.frostWaterIce);
		world.setBlock(i + 6, j + 0, k + 23, ACBlocks.frostWaterIce);
		world.setBlock(i + 6, j + 1, k + 7, ACBlocks.frostWaterIce);
		world.setBlock(i + 6, j + 1, k + 8, ACBlocks.frostWaterIce);
		world.setBlock(i + 6, j + 1, k + 9, ACBlocks.frostWaterIce);
		world.setBlock(i + 6, j + 1, k + 10, ACBlocks.frostWaterIce);
		world.setBlock(i + 6, j + 1, k + 11, ACBlocks.frostWaterIce);
		world.setBlock(i + 6, j + 1, k + 12, ACBlocks.frostWaterIce);
		world.setBlock(i + 6, j + 1, k + 13, ACBlocks.frostWaterIce);
		world.setBlock(i + 6, j + 1, k + 14, ACBlocks.frostWaterIce);
		world.setBlock(i + 6, j + 1, k + 15, ACBlocks.frostWaterIce);
		world.setBlock(i + 6, j + 1, k + 16, ACBlocks.frostWaterIce);
		world.setBlock(i + 6, j + 1, k + 17, ACBlocks.frostWaterIce);
		world.setBlock(i + 6, j + 1, k + 18, ACBlocks.frostWaterIce);
		world.setBlock(i + 6, j + 1, k + 19, ACBlocks.frostWaterIce);
		world.setBlock(i + 6, j + 1, k + 20, ACBlocks.frostWaterIce);
		world.setBlock(i + 6, j + 1, k + 21, ACBlocks.frostWaterIce);
		world.setBlock(i + 6, j + 1, k + 22, ACBlocks.frostWaterIce);
		world.setBlock(i + 6, j + 1, k + 23, ACBlocks.frostWaterIce);
		world.setBlock(i + 6, j + 2, k + 7, ACBlocks.frostWaterIce);
		world.setBlock(i + 6, j + 2, k + 8, ACBlocks.frostWaterIce);
		world.setBlock(i + 6, j + 2, k + 9, ACBlocks.frostWaterIce);
		world.setBlock(i + 6, j + 2, k + 10, ACBlocks.frostWaterIce);
		world.setBlock(i + 6, j + 2, k + 11, ACBlocks.frostWaterIce);
		world.setBlock(i + 6, j + 2, k + 12, ACBlocks.frostWaterIce);
		world.setBlock(i + 6, j + 2, k + 13, ACBlocks.frostWaterIce);
		world.setBlock(i + 6, j + 2, k + 14, ACBlocks.frostWaterIce);
		world.setBlock(i + 6, j + 2, k + 15, ACBlocks.frostWaterIce);
		world.setBlock(i + 6, j + 2, k + 16, ACBlocks.frostWaterIce);
		world.setBlock(i + 6, j + 2, k + 17, ACBlocks.frostWaterIce);
		world.setBlock(i + 6, j + 2, k + 18, ACBlocks.frostWaterIce);
		world.setBlock(i + 6, j + 2, k + 19, ACBlocks.frostWaterIce);
		world.setBlock(i + 6, j + 2, k + 20, ACBlocks.frostWaterIce);
		world.setBlock(i + 6, j + 2, k + 21, ACBlocks.frostWaterIce);
		world.setBlock(i + 6, j + 2, k + 22, ACBlocks.frostWaterIce);
		world.setBlock(i + 6, j + 2, k + 23, ACBlocks.frostWaterIce);
		world.setBlock(i + 6, j + 3, k + 8, ACBlocks.frostWaterIce);
		world.setBlock(i + 6, j + 3, k + 9, ACBlocks.frostWaterIce);
		world.setBlock(i + 6, j + 3, k + 10, ACBlocks.frostWaterIce);
		world.setBlock(i + 6, j + 3, k + 11, ACBlocks.frostWaterIce);
		world.setBlock(i + 6, j + 3, k + 12, ACBlocks.frostWaterIce);
		world.setBlock(i + 6, j + 3, k + 13, ACBlocks.frostWaterIce);
		world.setBlock(i + 6, j + 3, k + 14, ACBlocks.frostWaterIce);
		world.setBlock(i + 6, j + 3, k + 15, ACBlocks.frostWaterIce);
		world.setBlock(i + 6, j + 3, k + 16, ACBlocks.frostWaterIce);
		world.setBlock(i + 6, j + 3, k + 17, ACBlocks.frostWaterIce);
		world.setBlock(i + 6, j + 3, k + 18, ACBlocks.frostWaterIce);
		world.setBlock(i + 6, j + 3, k + 19, ACBlocks.frostWaterIce);
		world.setBlock(i + 6, j + 3, k + 20, ACBlocks.frostWaterIce);
		world.setBlock(i + 6, j + 3, k + 21, ACBlocks.frostWaterIce);
		world.setBlock(i + 6, j + 3, k + 22, ACBlocks.frostWaterIce);
		world.setBlock(i + 6, j + 4, k + 11, ACBlocks.frostWaterIce);
		world.setBlock(i + 6, j + 4, k + 12, ACBlocks.frostWaterIce);
		world.setBlock(i + 6, j + 4, k + 13, ACBlocks.frostWaterIce);
		world.setBlock(i + 6, j + 4, k + 14, ACBlocks.frostWaterIce);
		world.setBlock(i + 6, j + 4, k + 15, ACBlocks.frostWaterIce);
		world.setBlock(i + 6, j + 4, k + 16, ACBlocks.frostWaterIce);
		world.setBlock(i + 6, j + 4, k + 17, ACBlocks.frostWaterIce);
		world.setBlock(i + 6, j + 4, k + 18, ACBlocks.frostWaterIce);
		world.setBlock(i + 6, j + 4, k + 19, ACBlocks.frostWaterIce);
		world.setBlock(i + 6, j + 4, k + 20, ACBlocks.frostWaterIce);
		world.setBlock(i + 6, j + 4, k + 21, ACBlocks.frostWaterIce);
		world.setBlock(i + 6, j + 5, k + 11, ACBlocks.frostWaterIce);
		world.setBlock(i + 6, j + 5, k + 12, ACBlocks.frostWaterIce);
		world.setBlock(i + 6, j + 5, k + 13, ACBlocks.frostWaterIce);
		world.setBlock(i + 6, j + 5, k + 14, ACBlocks.frostWaterIce);
		world.setBlock(i + 6, j + 5, k + 15, ACBlocks.frostWaterIce);
		world.setBlock(i + 6, j + 5, k + 16, ACBlocks.frostWaterIce);
		world.setBlock(i + 6, j + 5, k + 17, ACBlocks.frostWaterIce);
		world.setBlock(i + 6, j + 5, k + 18, ACBlocks.frostWaterIce);
		world.setBlock(i + 6, j + 5, k + 19, ACBlocks.frostWaterIce);
		world.setBlock(i + 6, j + 5, k + 20, ACBlocks.frostWaterIce);
		world.setBlock(i + 6, j + 6, k + 12, ACBlocks.frostWaterIce);
		world.setBlock(i + 6, j + 6, k + 13, ACBlocks.frostWaterIce);
		world.setBlock(i + 6, j + 6, k + 14, ACBlocks.frostWaterIce);
		world.setBlock(i + 6, j + 6, k + 15, ACBlocks.frostWaterIce);
		world.setBlock(i + 6, j + 6, k + 16, ACBlocks.frostWaterIce);
		world.setBlock(i + 6, j + 6, k + 17, ACBlocks.frostWaterIce);
		world.setBlock(i + 6, j + 7, k + 12, ACBlocks.frostWaterIce);
		world.setBlock(i + 6, j + 7, k + 13, ACBlocks.frostWaterIce);
		world.setBlock(i + 6, j + 7, k + 14, ACBlocks.frostWaterIce);
		world.setBlock(i + 6, j + 7, k + 15, ACBlocks.frostWaterIce);
		world.setBlock(i + 6, j + 7, k + 16, ACBlocks.frostWaterIce);
		world.setBlock(i + 6, j + 7, k + 17, ACBlocks.frostWaterIce);
		world.setBlock(i + 6, j + 8, k + 8, ACBlocks.frostWaterIce);
		world.setBlock(i + 6, j + 8, k + 9, ACBlocks.frostWaterIce);
		world.setBlock(i + 6, j + 8, k + 10, ACBlocks.frostWaterIce);
		world.setBlock(i + 6, j + 8, k + 11, ACBlocks.frostWaterIce);
		world.setBlock(i + 6, j + 8, k + 14, ACBlocks.frostWaterIce);
		world.setBlock(i + 6, j + 8, k + 15, ACBlocks.frostWaterIce);
		world.setBlock(i + 6, j + 9, k + 8, ACBlocks.frostWaterIce);
		world.setBlock(i + 6, j + 9, k + 9, ACBlocks.frostWaterIce);
		world.setBlock(i + 6, j + 9, k + 10, ACBlocks.frostWaterIce);
		world.setBlock(i + 6, j + 9, k + 11, ACBlocks.frostWaterIce);
		world.setBlock(i + 6, j + 10, k + 8, ACBlocks.frostWaterIce);
		world.setBlock(i + 6, j + 10, k + 9, ACBlocks.frostWaterIce);
		world.setBlock(i + 6, j + 10, k + 10, ACBlocks.frostWaterIce);
		world.setBlock(i + 6, j + 10, k + 11, ACBlocks.frostWaterIce);
		world.setBlock(i + 6, j + 11, k + 8, ACBlocks.frostWaterIce);
		world.setBlock(i + 6, j + 11, k + 9, ACBlocks.frostWaterIce);
		world.setBlock(i + 6, j + 11, k + 10, ACBlocks.frostWaterIce);
		world.setBlock(i + 6, j + 11, k + 11, ACBlocks.frostWaterIce);
		world.setBlock(i + 6, j + 16, k + 6, ACBlocks.frostWaterIce, 0, k);
		world.setBlock(i + 7, j + 0, k + 6, ACBlocks.frostWaterIce);
		world.setBlock(i + 7, j + 0, k + 7, ACBlocks.frostWaterIce);
		world.setBlock(i + 7, j + 0, k + 8, ACBlocks.frostWaterIce);
		world.setBlock(i + 7, j + 0, k + 9, ACBlocks.frostWaterIce);
		world.setBlock(i + 7, j + 0, k + 10, ACBlocks.frostWaterIce);
		world.setBlock(i + 7, j + 0, k + 11, ACBlocks.frostWaterIce);
		world.setBlock(i + 7, j + 0, k + 12, ACBlocks.frostWaterIce);
		world.setBlock(i + 7, j + 0, k + 13, ACBlocks.frostWaterIce);
		world.setBlock(i + 7, j + 0, k + 14, ACBlocks.frostWaterIce);
		world.setBlock(i + 7, j + 0, k + 15, ACBlocks.frostWaterIce);
		world.setBlock(i + 7, j + 0, k + 16, ACBlocks.frostWaterIce);
		world.setBlock(i + 7, j + 0, k + 17, ACBlocks.frostWaterIce);
		world.setBlock(i + 7, j + 0, k + 18, ACBlocks.frostWaterIce);
		world.setBlock(i + 7, j + 0, k + 19, ACBlocks.frostWaterIce);
		world.setBlock(i + 7, j + 0, k + 20, ACBlocks.frostWaterIce);
		world.setBlock(i + 7, j + 0, k + 21, ACBlocks.frostWaterIce);
		world.setBlock(i + 7, j + 0, k + 22, ACBlocks.frostWaterIce);
		world.setBlock(i + 7, j + 1, k + 6, ACBlocks.frostWaterIce);
		world.setBlock(i + 7, j + 1, k + 7, ACBlocks.frostWaterIce);
		world.setBlock(i + 7, j + 1, k + 8, ACBlocks.frostWaterIce);
		world.setBlock(i + 7, j + 1, k + 9, ACBlocks.frostWaterIce);
		world.setBlock(i + 7, j + 1, k + 10, ACBlocks.frostWaterIce);
		world.setBlock(i + 7, j + 1, k + 11, ACBlocks.frostWaterIce);
		world.setBlock(i + 7, j + 1, k + 12, ACBlocks.frostWaterIce);
		world.setBlock(i + 7, j + 1, k + 13, ACBlocks.frostWaterIce);
		world.setBlock(i + 7, j + 1, k + 14, ACBlocks.frostWaterIce);
		world.setBlock(i + 7, j + 1, k + 15, ACBlocks.frostWaterIce);
		world.setBlock(i + 7, j + 1, k + 16, ACBlocks.frostWaterIce);
		world.setBlock(i + 7, j + 1, k + 17, ACBlocks.frostWaterIce);
		world.setBlock(i + 7, j + 1, k + 18, ACBlocks.frostWaterIce);
		world.setBlock(i + 7, j + 1, k + 19, ACBlocks.frostWaterIce);
		world.setBlock(i + 7, j + 1, k + 20, ACBlocks.frostWaterIce);
		world.setBlock(i + 7, j + 1, k + 21, ACBlocks.frostWaterIce);
		world.setBlock(i + 7, j + 1, k + 22, ACBlocks.frostWaterIce);
		world.setBlock(i + 7, j + 2, k + 7, ACBlocks.frostWaterIce);
		world.setBlock(i + 7, j + 2, k + 8, ACBlocks.frostWaterIce);
		world.setBlock(i + 7, j + 2, k + 9, ACBlocks.frostWaterIce);
		world.setBlock(i + 7, j + 2, k + 10, ACBlocks.frostWaterIce);
		world.setBlock(i + 7, j + 2, k + 11, ACBlocks.frostWaterIce);
		world.setBlock(i + 7, j + 2, k + 12, ACBlocks.frostWaterIce);
		world.setBlock(i + 7, j + 2, k + 13, ACBlocks.frostWaterIce);
		world.setBlock(i + 7, j + 2, k + 14, ACBlocks.frostWaterIce);
		world.setBlock(i + 7, j + 2, k + 15, ACBlocks.frostWaterIce);
		world.setBlock(i + 7, j + 2, k + 16, ACBlocks.frostWaterIce);
		world.setBlock(i + 7, j + 2, k + 17, ACBlocks.frostWaterIce);
		world.setBlock(i + 7, j + 2, k + 18, ACBlocks.frostWaterIce);
		world.setBlock(i + 7, j + 2, k + 19, ACBlocks.frostWaterIce);
		world.setBlock(i + 7, j + 2, k + 20, ACBlocks.frostWaterIce);
		world.setBlock(i + 7, j + 2, k + 21, ACBlocks.frostWaterIce);
		world.setBlock(i + 7, j + 2, k + 22, ACBlocks.frostWaterIce);
		world.setBlock(i + 7, j + 3, k + 5, ACBlocks.frostWaterIce);
		world.setBlock(i + 7, j + 3, k + 6, ACBlocks.frostWaterIce);
		world.setBlock(i + 7, j + 3, k + 7, ACBlocks.frostWaterIce);
		world.setBlock(i + 7, j + 3, k + 8, ACBlocks.frostWaterIce);
		world.setBlock(i + 7, j + 3, k + 9, ACBlocks.frostWaterIce);
		world.setBlock(i + 7, j + 3, k + 10, ACBlocks.frostWaterIce);
		world.setBlock(i + 7, j + 3, k + 11, ACBlocks.frostWaterIce);
		world.setBlock(i + 7, j + 3, k + 12, ACBlocks.frostWaterIce);
		world.setBlock(i + 7, j + 3, k + 13, ACBlocks.frostWaterIce);
		world.setBlock(i + 7, j + 3, k + 14, ACBlocks.frostWaterIce);
		world.setBlock(i + 7, j + 3, k + 15, ACBlocks.frostWaterIce);
		world.setBlock(i + 7, j + 3, k + 16, ACBlocks.frostWaterIce);
		world.setBlock(i + 7, j + 3, k + 17, ACBlocks.frostWaterIce);
		world.setBlock(i + 7, j + 3, k + 18, ACBlocks.frostWaterIce);
		world.setBlock(i + 7, j + 3, k + 19, ACBlocks.frostWaterIce);
		world.setBlock(i + 7, j + 3, k + 20, ACBlocks.frostWaterIce);
		world.setBlock(i + 7, j + 3, k + 21, ACBlocks.frostWaterIce);
		world.setBlock(i + 7, j + 3, k + 22, ACBlocks.frostWaterIce);
		world.setBlock(i + 7, j + 4, k + 5, ACBlocks.frostWaterIce);
		world.setBlock(i + 7, j + 4, k + 6, ACBlocks.frostWaterIce);
		world.setBlock(i + 7, j + 4, k + 7, ACBlocks.frostWaterIce);
		world.setBlock(i + 7, j + 4, k + 8, ACBlocks.frostWaterIce);
		world.setBlock(i + 7, j + 4, k + 9, ACBlocks.frostWaterIce);
		world.setBlock(i + 7, j + 4, k + 10, ACBlocks.frostWaterIce);
		world.setBlock(i + 7, j + 4, k + 11, ACBlocks.frostWaterIce);
		world.setBlock(i + 7, j + 4, k + 12, ACBlocks.frostWaterIce);
		world.setBlock(i + 7, j + 4, k + 13, ACBlocks.frostWaterIce);
		world.setBlock(i + 7, j + 4, k + 14, ACBlocks.frostWaterIce);
		world.setBlock(i + 7, j + 4, k + 15, ACBlocks.frostWaterIce);
		world.setBlock(i + 7, j + 4, k + 16, ACBlocks.frostWaterIce);
		world.setBlock(i + 7, j + 4, k + 17, ACBlocks.frostWaterIce);
		world.setBlock(i + 7, j + 4, k + 18, ACBlocks.frostWaterIce);
		world.setBlock(i + 7, j + 4, k + 19, ACBlocks.frostWaterIce);
		world.setBlock(i + 7, j + 4, k + 20, ACBlocks.frostWaterIce);
		world.setBlock(i + 7, j + 4, k + 21, ACBlocks.frostWaterIce);
		world.setBlock(i + 7, j + 5, k + 5, ACBlocks.frostWaterIce);
		world.setBlock(i + 7, j + 5, k + 6, ACBlocks.frostWaterIce);
		world.setBlock(i + 7, j + 5, k + 7, ACBlocks.frostWaterIce);
		world.setBlock(i + 7, j + 5, k + 8, ACBlocks.frostWaterIce);
		world.setBlock(i + 7, j + 5, k + 11, ACBlocks.frostWaterIce);
		world.setBlock(i + 7, j + 5, k + 12, ACBlocks.frostWaterIce);
		world.setBlock(i + 7, j + 5, k + 13, ACBlocks.frostWaterIce);
		world.setBlock(i + 7, j + 5, k + 14, ACBlocks.frostWaterIce);
		world.setBlock(i + 7, j + 5, k + 15, ACBlocks.frostWaterIce);
		world.setBlock(i + 7, j + 5, k + 16, ACBlocks.frostWaterIce);
		world.setBlock(i + 7, j + 5, k + 17, ACBlocks.frostWaterIce);
		world.setBlock(i + 7, j + 5, k + 18, ACBlocks.frostWaterIce);
		world.setBlock(i + 7, j + 6, k + 5, ACBlocks.frostWaterIce);
		world.setBlock(i + 7, j + 6, k + 6, ACBlocks.frostWaterIce);
		world.setBlock(i + 7, j + 6, k + 7, ACBlocks.frostWaterIce);
		world.setBlock(i + 7, j + 6, k + 8, ACBlocks.frostWaterIce);
		world.setBlock(i + 7, j + 6, k + 9, ACBlocks.frostWaterIce);
		world.setBlock(i + 7, j + 6, k + 10, ACBlocks.frostWaterIce);
		world.setBlock(i + 7, j + 6, k + 11, ACBlocks.frostWaterIce);
		world.setBlock(i + 7, j + 6, k + 12, ACBlocks.frostWaterIce);
		world.setBlock(i + 7, j + 6, k + 13, ACBlocks.frostWaterIce);
		world.setBlock(i + 7, j + 6, k + 14, ACBlocks.frostWaterIce);
		world.setBlock(i + 7, j + 6, k + 15, ACBlocks.frostWaterIce);
		world.setBlock(i + 7, j + 6, k + 16, ACBlocks.frostWaterIce);
		world.setBlock(i + 7, j + 6, k + 17, ACBlocks.frostWaterIce);
		world.setBlock(i + 7, j + 6, k + 18, ACBlocks.frostWaterIce);
		world.setBlock(i + 7, j + 7, k + 7, ACBlocks.frostWaterIce);
		world.setBlock(i + 7, j + 7, k + 8, ACBlocks.frostWaterIce);
		world.setBlock(i + 7, j + 7, k + 9, ACBlocks.frostWaterIce);
		world.setBlock(i + 7, j + 7, k + 10, ACBlocks.frostWaterIce);
		world.setBlock(i + 7, j + 7, k + 11, ACBlocks.frostWaterIce);
		world.setBlock(i + 7, j + 7, k + 12, ACBlocks.frostWaterIce);
		world.setBlock(i + 7, j + 7, k + 13, ACBlocks.frostWaterIce);
		world.setBlock(i + 7, j + 7, k + 14, ACBlocks.frostWaterIce);
		world.setBlock(i + 7, j + 7, k + 15, ACBlocks.frostWaterIce);
		world.setBlock(i + 7, j + 7, k + 16, ACBlocks.frostWaterIce);
		world.setBlock(i + 7, j + 7, k + 17, ACBlocks.frostWaterIce);
		world.setBlock(i + 7, j + 7, k + 18, ACBlocks.frostWaterIce);
		world.setBlock(i + 7, j + 8, k + 7, ACBlocks.frostWaterIce);
		world.setBlock(i + 7, j + 8, k + 8, ACBlocks.frostWaterIce);
		world.setBlock(i + 7, j + 8, k + 9, ACBlocks.frostWaterIce);
		world.setBlock(i + 7, j + 8, k + 10, ACBlocks.frostWaterIce);
		world.setBlock(i + 7, j + 8, k + 11, ACBlocks.frostWaterIce);
		world.setBlock(i + 7, j + 8, k + 12, ACBlocks.frostWaterIce);
		world.setBlock(i + 7, j + 8, k + 13, ACBlocks.frostWaterIce);
		world.setBlock(i + 7, j + 8, k + 14, ACBlocks.frostWaterIce);
		world.setBlock(i + 7, j + 8, k + 15, ACBlocks.frostWaterIce);
		world.setBlock(i + 7, j + 8, k + 16, ACBlocks.frostWaterIce);
		world.setBlock(i + 7, j + 8, k + 17, ACBlocks.frostWaterIce);
		world.setBlock(i + 7, j + 9, k + 6, ACBlocks.frostWaterIce);
		world.setBlock(i + 7, j + 9, k + 7, ACBlocks.frostWaterIce);
		world.setBlock(i + 7, j + 9, k + 8, ACBlocks.frostWaterIce);
		world.setBlock(i + 7, j + 9, k + 9, ACBlocks.frostWaterIce);
		world.setBlock(i + 7, j + 9, k + 10, ACBlocks.frostWaterIce);
		world.setBlock(i + 7, j + 9, k + 11, ACBlocks.frostWaterIce);
		world.setBlock(i + 7, j + 9, k + 12, ACBlocks.frostWaterIce);
		world.setBlock(i + 7, j + 9, k + 13, ACBlocks.frostWaterIce);
		world.setBlock(i + 7, j + 9, k + 14, ACBlocks.frostWaterIce);
		world.setBlock(i + 7, j + 9, k + 15, ACBlocks.frostWaterIce);
		world.setBlock(i + 7, j + 9, k + 16, ACBlocks.frostWaterIce);
		world.setBlock(i + 7, j + 10, k + 6, ACBlocks.frostWaterIce);
		world.setBlock(i + 7, j + 10, k + 7, ACBlocks.frostWaterIce);
		world.setBlock(i + 7, j + 10, k + 8, ACBlocks.frostWaterIce);
		world.setBlock(i + 7, j + 10, k + 9, ACBlocks.frostWaterIce);
		world.setBlock(i + 7, j + 10, k + 10, ACBlocks.frostWaterIce);
		world.setBlock(i + 7, j + 10, k + 11, ACBlocks.frostWaterIce);
		world.setBlock(i + 7, j + 10, k + 12, ACBlocks.frostWaterIce);
		world.setBlock(i + 7, j + 10, k + 13, ACBlocks.frostWaterIce);
		world.setBlock(i + 7, j + 10, k + 14, ACBlocks.frostWaterIce);
		world.setBlock(i + 7, j + 10, k + 15, ACBlocks.frostWaterIce);
		world.setBlock(i + 7, j + 10, k + 16, ACBlocks.frostWaterIce);
		world.setBlock(i + 7, j + 11, k + 7, ACBlocks.frostWaterIce);
		world.setBlock(i + 7, j + 11, k + 8, ACBlocks.frostWaterIce);
		world.setBlock(i + 7, j + 11, k + 9, ACBlocks.frostWaterIce);
		world.setBlock(i + 7, j + 11, k + 10, ACBlocks.frostWaterIce);
		world.setBlock(i + 7, j + 11, k + 11, ACBlocks.frostWaterIce);
		world.setBlock(i + 7, j + 11, k + 12, ACBlocks.frostWaterIce);
		world.setBlock(i + 7, j + 11, k + 13, ACBlocks.frostWaterIce);
		world.setBlock(i + 7, j + 11, k + 14, ACBlocks.frostWaterIce);
		world.setBlock(i + 7, j + 11, k + 15, ACBlocks.frostWaterIce);
		world.setBlock(i + 7, j + 11, k + 16, ACBlocks.frostWaterIce);
		world.setBlock(i + 7, j + 12, k + 7, ACBlocks.frostWaterIce);
		world.setBlock(i + 7, j + 12, k + 8, ACBlocks.frostWaterIce);
		world.setBlock(i + 7, j + 12, k + 9, ACBlocks.frostWaterIce);
		world.setBlock(i + 7, j + 12, k + 10, ACBlocks.frostWaterIce);
		world.setBlock(i + 7, j + 12, k + 11, ACBlocks.frostWaterIce);
		world.setBlock(i + 7, j + 12, k + 12, ACBlocks.frostWaterIce);
		world.setBlock(i + 7, j + 12, k + 13, ACBlocks.frostWaterIce);
		world.setBlock(i + 7, j + 12, k + 14, ACBlocks.frostWaterIce);
		world.setBlock(i + 7, j + 12, k + 15, ACBlocks.frostWaterIce);
		world.setBlock(i + 7, j + 12, k + 16, ACBlocks.frostWaterIce);
		world.setBlock(i + 7, j + 13, k + 9, ACBlocks.frostWaterIce);
		world.setBlock(i + 7, j + 13, k + 10, ACBlocks.frostWaterIce);
		world.setBlock(i + 8, j + 0, k + 6, ACBlocks.frostWaterIce);
		world.setBlock(i + 8, j + 0, k + 7, ACBlocks.frostWaterIce);
		world.setBlock(i + 8, j + 0, k + 8, ACBlocks.frostWaterIce);
		world.setBlock(i + 8, j + 0, k + 9, ACBlocks.frostWaterIce);
		world.setBlock(i + 8, j + 0, k + 10, ACBlocks.frostWaterIce);
		world.setBlock(i + 8, j + 0, k + 11, ACBlocks.frostWaterIce);
		world.setBlock(i + 8, j + 0, k + 12, ACBlocks.frostWaterIce);
		world.setBlock(i + 8, j + 0, k + 13, ACBlocks.frostWaterIce);
		world.setBlock(i + 8, j + 0, k + 14, ACBlocks.frostWaterIce);
		world.setBlock(i + 8, j + 0, k + 15, ACBlocks.frostWaterIce);
		world.setBlock(i + 8, j + 0, k + 16, ACBlocks.frostWaterIce);
		world.setBlock(i + 8, j + 0, k + 17, ACBlocks.frostWaterIce);
		world.setBlock(i + 8, j + 0, k + 18, ACBlocks.frostWaterIce);
		world.setBlock(i + 8, j + 0, k + 19, ACBlocks.frostWaterIce);
		world.setBlock(i + 8, j + 0, k + 20, ACBlocks.frostWaterIce);
		world.setBlock(i + 8, j + 0, k + 21, ACBlocks.frostWaterIce);
		world.setBlock(i + 8, j + 0, k + 22, ACBlocks.frostWaterIce);
		world.setBlock(i + 8, j + 1, k + 6, ACBlocks.frostWaterIce);
		world.setBlock(i + 8, j + 1, k + 7, ACBlocks.frostWaterIce);
		world.setBlock(i + 8, j + 1, k + 8, ACBlocks.frostWaterIce);
		world.setBlock(i + 8, j + 1, k + 9, ACBlocks.frostWaterIce);
		world.setBlock(i + 8, j + 1, k + 10, ACBlocks.frostWaterIce);
		world.setBlock(i + 8, j + 1, k + 11, ACBlocks.frostWaterIce);
		world.setBlock(i + 8, j + 1, k + 12, ACBlocks.frostWaterIce);
		world.setBlock(i + 8, j + 1, k + 13, ACBlocks.frostWaterIce);
		world.setBlock(i + 8, j + 1, k + 14, ACBlocks.frostWaterIce);
		world.setBlock(i + 8, j + 1, k + 15, ACBlocks.frostWaterIce);
		world.setBlock(i + 8, j + 1, k + 16, ACBlocks.frostWaterIce);
		world.setBlock(i + 8, j + 1, k + 17, ACBlocks.frostWaterIce);
		world.setBlock(i + 8, j + 1, k + 18, ACBlocks.frostWaterIce);
		world.setBlock(i + 8, j + 1, k + 19, ACBlocks.frostWaterIce);
		world.setBlock(i + 8, j + 1, k + 20, ACBlocks.frostWaterIce);
		world.setBlock(i + 8, j + 1, k + 21, ACBlocks.frostWaterIce);
		world.setBlock(i + 8, j + 1, k + 22, ACBlocks.frostWaterIce);
		world.setBlock(i + 8, j + 2, k + 4, ACBlocks.frostWaterIce);
		world.setBlock(i + 8, j + 2, k + 5, ACBlocks.frostWaterIce);
		world.setBlock(i + 8, j + 2, k + 6, ACBlocks.frostWaterIce);
		world.setBlock(i + 8, j + 2, k + 7, ACBlocks.frostWaterIce);
		world.setBlock(i + 8, j + 2, k + 8, ACBlocks.frostWaterIce);
		world.setBlock(i + 8, j + 2, k + 9, ACBlocks.frostWaterIce);
		world.setBlock(i + 8, j + 2, k + 10, ACBlocks.frostWaterIce);
		world.setBlock(i + 8, j + 2, k + 11, ACBlocks.frostWaterIce);
		world.setBlock(i + 8, j + 2, k + 12, ACBlocks.frostWaterIce);
		world.setBlock(i + 8, j + 2, k + 13, ACBlocks.frostWaterIce);
		world.setBlock(i + 8, j + 2, k + 14, ACBlocks.frostWaterIce);
		world.setBlock(i + 8, j + 2, k + 15, ACBlocks.frostWaterIce);
		world.setBlock(i + 8, j + 2, k + 16, ACBlocks.frostWaterIce);
		world.setBlock(i + 8, j + 2, k + 17, ACBlocks.frostWaterIce);
		world.setBlock(i + 8, j + 2, k + 18, ACBlocks.frostWaterIce);
		world.setBlock(i + 8, j + 2, k + 19, ACBlocks.frostWaterIce);
		world.setBlock(i + 8, j + 2, k + 20, ACBlocks.frostWaterIce);
		world.setBlock(i + 8, j + 2, k + 21, ACBlocks.frostWaterIce);
		world.setBlock(i + 8, j + 3, k + 4, ACBlocks.frostWaterIce);
		world.setBlock(i + 8, j + 3, k + 5, ACBlocks.frostWaterIce);
		world.setBlock(i + 8, j + 3, k + 6, ACBlocks.frostWaterIce);
		world.setBlock(i + 8, j + 3, k + 7, ACBlocks.frostWaterIce);
		world.setBlock(i + 8, j + 3, k + 8, ACBlocks.frostWaterIce);
		world.setBlock(i + 8, j + 3, k + 9, ACBlocks.frostWaterIce);
		world.setBlock(i + 8, j + 3, k + 10, ACBlocks.frostWaterIce);
		world.setBlock(i + 8, j + 3, k + 11, ACBlocks.frostWaterIce);
		world.setBlock(i + 8, j + 3, k + 12, ACBlocks.frostWaterIce);
		world.setBlock(i + 8, j + 3, k + 13, ACBlocks.frostWaterIce);
		world.setBlock(i + 8, j + 3, k + 14, ACBlocks.frostWaterIce);
		world.setBlock(i + 8, j + 3, k + 15, ACBlocks.frostWaterIce);
		world.setBlock(i + 8, j + 3, k + 16, ACBlocks.frostWaterIce);
		world.setBlock(i + 8, j + 3, k + 17, ACBlocks.frostWaterIce);
		world.setBlock(i + 8, j + 3, k + 18, ACBlocks.frostWaterIce);
		world.setBlock(i + 8, j + 3, k + 19, ACBlocks.frostWaterIce);
		world.setBlock(i + 8, j + 3, k + 20, ACBlocks.frostWaterIce);
		world.setBlock(i + 8, j + 3, k + 21, ACBlocks.frostWaterIce);
		world.setBlock(i + 8, j + 4, k + 3, ACBlocks.frostWaterIce);
		world.setBlock(i + 8, j + 4, k + 4, ACBlocks.frostWaterIce);
		world.setBlock(i + 8, j + 4, k + 5, ACBlocks.frostWaterIce);
		world.setBlock(i + 8, j + 4, k + 6, ACBlocks.frostWaterIce);
		world.setBlock(i + 8, j + 4, k + 7, ACBlocks.frostWaterIce);
		world.setBlock(i + 8, j + 4, k + 8, ACBlocks.frostWaterIce);
		world.setBlock(i + 8, j + 4, k + 9, ACBlocks.frostWaterIce);
		world.setBlock(i + 8, j + 4, k + 10, ACBlocks.frostWaterIce);
		world.setBlock(i + 8, j + 4, k + 11, ACBlocks.frostWaterIce);
		world.setBlock(i + 8, j + 4, k + 12, ACBlocks.frostWaterIce);
		world.setBlock(i + 8, j + 4, k + 13, ACBlocks.frostWaterIce);
		world.setBlock(i + 8, j + 4, k + 14, ACBlocks.frostWaterIce);
		world.setBlock(i + 8, j + 4, k + 15, ACBlocks.frostWaterIce);
		world.setBlock(i + 8, j + 4, k + 16, ACBlocks.frostWaterIce);
		world.setBlock(i + 8, j + 4, k + 17, ACBlocks.frostWaterIce);
		world.setBlock(i + 8, j + 4, k + 18, ACBlocks.frostWaterIce);
		world.setBlock(i + 8, j + 4, k + 19, ACBlocks.frostWaterIce);
		world.setBlock(i + 8, j + 5, k + 3, ACBlocks.frostWaterIce);
		world.setBlock(i + 8, j + 5, k + 4, ACBlocks.frostWaterIce);
		world.setBlock(i + 8, j + 5, k + 5, ACBlocks.frostWaterIce);
		world.setBlock(i + 8, j + 5, k + 6, ACBlocks.frostWaterIce);
		world.setBlock(i + 8, j + 5, k + 7, ACBlocks.frostWaterIce);
		world.setBlock(i + 8, j + 5, k + 8, ACBlocks.frostWaterIce);
		world.setBlock(i + 8, j + 5, k + 9, ACBlocks.frostWaterIce);
		world.setBlock(i + 8, j + 5, k + 10, ACBlocks.frostWaterIce);
		world.setBlock(i + 8, j + 5, k + 11, ACBlocks.frostWaterIce);
		world.setBlock(i + 8, j + 5, k + 12, ACBlocks.frostWaterIce);
		world.setBlock(i + 8, j + 5, k + 13, ACBlocks.frostWaterIce);
		world.setBlock(i + 8, j + 5, k + 14, ACBlocks.frostWaterIce);
		world.setBlock(i + 8, j + 5, k + 15, ACBlocks.frostWaterIce);
		world.setBlock(i + 8, j + 5, k + 16, ACBlocks.frostWaterIce);
		world.setBlock(i + 8, j + 5, k + 17, ACBlocks.frostWaterIce);
		world.setBlock(i + 8, j + 5, k + 18, ACBlocks.frostWaterIce);
		world.setBlock(i + 8, j + 5, k + 19, ACBlocks.frostWaterIce);
		world.setBlock(i + 8, j + 6, k + 4, ACBlocks.frostWaterIce);
		world.setBlock(i + 8, j + 6, k + 5, ACBlocks.frostWaterIce);
		world.setBlock(i + 8, j + 6, k + 6, ACBlocks.frostWaterIce);
		world.setBlock(i + 8, j + 6, k + 7, ACBlocks.frostWaterIce);
		world.setBlock(i + 8, j + 6, k + 8, ACBlocks.frostWaterIce);
		world.setBlock(i + 8, j + 6, k + 9, ACBlocks.frostWaterIce);
		world.setBlock(i + 8, j + 6, k + 10, ACBlocks.frostWaterIce);
		world.setBlock(i + 8, j + 6, k + 11, ACBlocks.frostWaterIce);
		world.setBlock(i + 8, j + 6, k + 12, ACBlocks.frostWaterIce);
		world.setBlock(i + 8, j + 6, k + 13, ACBlocks.frostWaterIce);
		world.setBlock(i + 8, j + 6, k + 14, ACBlocks.frostWaterIce);
		world.setBlock(i + 8, j + 6, k + 15, ACBlocks.frostWaterIce);
		world.setBlock(i + 8, j + 6, k + 16, ACBlocks.frostWaterIce);
		world.setBlock(i + 8, j + 6, k + 17, ACBlocks.frostWaterIce);
		world.setBlock(i + 8, j + 6, k + 18, ACBlocks.frostWaterIce);
		world.setBlock(i + 8, j + 6, k + 19, ACBlocks.frostWaterIce);
		world.setBlock(i + 8, j + 7, k + 4, ACBlocks.frostWaterIce);
		world.setBlock(i + 8, j + 7, k + 5, ACBlocks.frostWaterIce);
		world.setBlock(i + 8, j + 7, k + 6, ACBlocks.frostWaterIce);
		world.setBlock(i + 8, j + 7, k + 7, ACBlocks.frostWaterIce);
		world.setBlock(i + 8, j + 7, k + 8, ACBlocks.frostWaterIce);
		world.setBlock(i + 8, j + 7, k + 9, ACBlocks.frostWaterIce);
		world.setBlock(i + 8, j + 7, k + 10, ACBlocks.frostWaterIce);
		world.setBlock(i + 8, j + 7, k + 11, ACBlocks.frostWaterIce);
		world.setBlock(i + 8, j + 7, k + 12, ACBlocks.frostWaterIce);
		world.setBlock(i + 8, j + 7, k + 13, ACBlocks.frostWaterIce);
		world.setBlock(i + 8, j + 7, k + 14, ACBlocks.frostWaterIce);
		world.setBlock(i + 8, j + 7, k + 15, ACBlocks.frostWaterIce);
		world.setBlock(i + 8, j + 7, k + 16, ACBlocks.frostWaterIce);
		world.setBlock(i + 8, j + 7, k + 17, ACBlocks.frostWaterIce);
		world.setBlock(i + 8, j + 7, k + 18, ACBlocks.frostWaterIce);
		world.setBlock(i + 8, j + 8, k + 6, ACBlocks.frostWaterIce);
		world.setBlock(i + 8, j + 8, k + 7, ACBlocks.frostWaterIce);
		world.setBlock(i + 8, j + 8, k + 8, ACBlocks.frostWaterIce);
		world.setBlock(i + 8, j + 8, k + 9, ACBlocks.frostWaterIce);
		world.setBlock(i + 8, j + 8, k + 10, ACBlocks.frostWaterIce);
		world.setBlock(i + 8, j + 8, k + 11, ACBlocks.frostWaterIce);
		world.setBlock(i + 8, j + 8, k + 12, ACBlocks.frostWaterIce);
		world.setBlock(i + 8, j + 8, k + 13, ACBlocks.frostWaterIce);
		world.setBlock(i + 8, j + 8, k + 14, ACBlocks.frostWaterIce);
		world.setBlock(i + 8, j + 8, k + 15, ACBlocks.frostWaterIce);
		world.setBlock(i + 8, j + 8, k + 16, ACBlocks.frostWaterIce);
		world.setBlock(i + 8, j + 8, k + 17, ACBlocks.frostWaterIce);
		world.setBlock(i + 8, j + 9, k + 6, ACBlocks.frostWaterIce);
		world.setBlock(i + 8, j + 9, k + 7, ACBlocks.frostWaterIce);
		world.setBlock(i + 8, j + 9, k + 8, ACBlocks.frostWaterIce);
		world.setBlock(i + 8, j + 9, k + 9, ACBlocks.frostWaterIce);
		world.setBlock(i + 8, j + 9, k + 10, ACBlocks.frostWaterIce);
		world.setBlock(i + 8, j + 9, k + 11, ACBlocks.frostWaterIce);
		world.setBlock(i + 8, j + 9, k + 12, ACBlocks.frostWaterIce);
		world.setBlock(i + 8, j + 9, k + 13, ACBlocks.frostWaterIce);
		world.setBlock(i + 8, j + 9, k + 14, ACBlocks.frostWaterIce);
		world.setBlock(i + 8, j + 9, k + 15, ACBlocks.frostWaterIce);
		world.setBlock(i + 8, j + 9, k + 16, ACBlocks.frostWaterIce);
		world.setBlock(i + 8, j + 9, k + 17, ACBlocks.frostWaterIce);
		world.setBlock(i + 8, j + 10, k + 6, ACBlocks.frostWaterIce);
		world.setBlock(i + 8, j + 10, k + 7, ACBlocks.frostWaterIce);
		world.setBlock(i + 8, j + 10, k + 8, ACBlocks.frostWaterIce);
		world.setBlock(i + 8, j + 10, k + 9, ACBlocks.frostWaterIce);
		world.setBlock(i + 8, j + 10, k + 10, ACBlocks.frostWaterIce);
		world.setBlock(i + 8, j + 10, k + 11, ACBlocks.frostWaterIce);
		world.setBlock(i + 8, j + 10, k + 12, ACBlocks.frostWaterIce);
		world.setBlock(i + 8, j + 10, k + 13, ACBlocks.frostWaterIce);
		world.setBlock(i + 8, j + 10, k + 14, ACBlocks.frostWaterIce);
		world.setBlock(i + 8, j + 10, k + 15, ACBlocks.frostWaterIce);
		world.setBlock(i + 8, j + 10, k + 16, ACBlocks.frostWaterIce);
		world.setBlock(i + 8, j + 10, k + 17, ACBlocks.frostWaterIce);
		world.setBlock(i + 8, j + 10, k + 18, ACBlocks.frostWaterIce);
		world.setBlock(i + 8, j + 11, k + 6, ACBlocks.frostWaterIce);
		world.setBlock(i + 8, j + 11, k + 7, ACBlocks.frostWaterIce);
		world.setBlock(i + 8, j + 11, k + 8, ACBlocks.frostWaterIce);
		world.setBlock(i + 8, j + 11, k + 9, ACBlocks.frostWaterIce);
		world.setBlock(i + 8, j + 11, k + 10, ACBlocks.frostWaterIce);
		world.setBlock(i + 8, j + 11, k + 11, ACBlocks.frostWaterIce);
		world.setBlock(i + 8, j + 11, k + 12, ACBlocks.frostWaterIce);
		world.setBlock(i + 8, j + 11, k + 13, ACBlocks.frostWaterIce);
		world.setBlock(i + 8, j + 11, k + 14, ACBlocks.frostWaterIce);
		world.setBlock(i + 8, j + 11, k + 15, ACBlocks.frostWaterIce);
		world.setBlock(i + 8, j + 11, k + 16, ACBlocks.frostWaterIce);
		world.setBlock(i + 8, j + 11, k + 17, ACBlocks.frostWaterIce);
		world.setBlock(i + 8, j + 11, k + 18, ACBlocks.frostWaterIce);
		world.setBlock(i + 8, j + 12, k + 6, ACBlocks.frostWaterIce);
		world.setBlock(i + 8, j + 12, k + 7, ACBlocks.frostWaterIce);
		world.setBlock(i + 8, j + 12, k + 8, ACBlocks.frostWaterIce);
		world.setBlock(i + 8, j + 12, k + 9, ACBlocks.frostWaterIce);
		world.setBlock(i + 8, j + 12, k + 10, ACBlocks.frostWaterIce);
		world.setBlock(i + 8, j + 12, k + 11, ACBlocks.frostWaterIce);
		world.setBlock(i + 8, j + 12, k + 12, ACBlocks.frostWaterIce);
		world.setBlock(i + 8, j + 12, k + 13, ACBlocks.frostWaterIce);
		world.setBlock(i + 8, j + 12, k + 14, ACBlocks.frostWaterIce);
		world.setBlock(i + 8, j + 12, k + 15, ACBlocks.frostWaterIce);
		world.setBlock(i + 8, j + 12, k + 16, ACBlocks.frostWaterIce);
		world.setBlock(i + 8, j + 12, k + 17, ACBlocks.frostWaterIce);
		world.setBlock(i + 8, j + 13, k + 7, ACBlocks.frostWaterIce);
		world.setBlock(i + 8, j + 13, k + 8, ACBlocks.frostWaterIce);
		world.setBlock(i + 8, j + 13, k + 9, ACBlocks.frostWaterIce);
		world.setBlock(i + 8, j + 13, k + 10, ACBlocks.frostWaterIce);
		world.setBlock(i + 8, j + 13, k + 11, ACBlocks.frostWaterIce);
		world.setBlock(i + 8, j + 13, k + 12, ACBlocks.frostWaterIce);
		world.setBlock(i + 8, j + 13, k + 13, ACBlocks.frostWaterIce);
		world.setBlock(i + 8, j + 13, k + 14, ACBlocks.frostWaterIce);
		world.setBlock(i + 8, j + 13, k + 15, ACBlocks.frostWaterIce);
		world.setBlock(i + 8, j + 13, k + 16, ACBlocks.frostWaterIce);
		world.setBlock(i + 8, j + 13, k + 17, ACBlocks.frostWaterIce);
		world.setBlock(i + 8, j + 14, k + 14, ACBlocks.frostWaterIce);
		world.setBlock(i + 8, j + 14, k + 15, ACBlocks.frostWaterIce);
		world.setBlock(i + 8, j + 16, k + 8, ACBlocks.frostWaterIce, 0, k);
		world.setBlock(i + 9, j + 0, k + 6, ACBlocks.frostWaterIce);
		world.setBlock(i + 9, j + 0, k + 7, ACBlocks.frostWaterIce);
		world.setBlock(i + 9, j + 0, k + 8, ACBlocks.frostWaterIce);
		world.setBlock(i + 9, j + 0, k + 9, ACBlocks.frostWaterIce);
		world.setBlock(i + 9, j + 0, k + 10, ACBlocks.frostWaterIce);
		world.setBlock(i + 9, j + 0, k + 11, ACBlocks.frostWaterIce);
		world.setBlock(i + 9, j + 0, k + 12, ACBlocks.frostWaterIce);
		world.setBlock(i + 9, j + 0, k + 13, ACBlocks.frostWaterIce);
		world.setBlock(i + 9, j + 0, k + 14, ACBlocks.frostWaterIce);
		world.setBlock(i + 9, j + 0, k + 15, ACBlocks.frostWaterIce);
		world.setBlock(i + 9, j + 0, k + 16, ACBlocks.frostWaterIce);
		world.setBlock(i + 9, j + 0, k + 17, ACBlocks.frostWaterIce);
		world.setBlock(i + 9, j + 0, k + 18, ACBlocks.frostWaterIce);
		world.setBlock(i + 9, j + 0, k + 19, ACBlocks.frostWaterIce);
		world.setBlock(i + 9, j + 0, k + 20, ACBlocks.frostWaterIce);
		world.setBlock(i + 9, j + 1, k + 4, ACBlocks.frostWaterIce);
		world.setBlock(i + 9, j + 1, k + 5, ACBlocks.frostWaterIce);
		world.setBlock(i + 9, j + 1, k + 6, ACBlocks.frostWaterIce);
		world.setBlock(i + 9, j + 1, k + 7, ACBlocks.frostWaterIce);
		world.setBlock(i + 9, j + 1, k + 8, ACBlocks.frostWaterIce);
		world.setBlock(i + 9, j + 1, k + 9, ACBlocks.frostWaterIce);
		world.setBlock(i + 9, j + 1, k + 10, ACBlocks.frostWaterIce);
		world.setBlock(i + 9, j + 1, k + 11, ACBlocks.frostWaterIce);
		world.setBlock(i + 9, j + 1, k + 12, ACBlocks.frostWaterIce);
		world.setBlock(i + 9, j + 1, k + 13, ACBlocks.frostWaterIce);
		world.setBlock(i + 9, j + 1, k + 14, ACBlocks.frostWaterIce);
		world.setBlock(i + 9, j + 1, k + 15, ACBlocks.frostWaterIce);
		world.setBlock(i + 9, j + 1, k + 16, ACBlocks.frostWaterIce);
		world.setBlock(i + 9, j + 1, k + 17, ACBlocks.frostWaterIce);
		world.setBlock(i + 9, j + 1, k + 18, ACBlocks.frostWaterIce);
		world.setBlock(i + 9, j + 1, k + 19, ACBlocks.frostWaterIce);
		world.setBlock(i + 9, j + 1, k + 20, ACBlocks.frostWaterIce);
		world.setBlock(i + 9, j + 2, k + 3, ACBlocks.frostWaterIce);
		world.setBlock(i + 9, j + 2, k + 4, ACBlocks.frostWaterIce);
		world.setBlock(i + 9, j + 2, k + 5, ACBlocks.frostWaterIce);
		world.setBlock(i + 9, j + 2, k + 6, ACBlocks.frostWaterIce);
		world.setBlock(i + 9, j + 2, k + 7, ACBlocks.frostWaterIce);
		world.setBlock(i + 9, j + 2, k + 8, ACBlocks.frostWaterIce);
		world.setBlock(i + 9, j + 2, k + 9, ACBlocks.frostWaterIce);
		world.setBlock(i + 9, j + 2, k + 10, ACBlocks.frostWaterIce);
		world.setBlock(i + 9, j + 2, k + 11, ACBlocks.frostWaterIce);
		world.setBlock(i + 9, j + 2, k + 12, ACBlocks.frostWaterIce);
		world.setBlock(i + 9, j + 2, k + 13, ACBlocks.frostWaterIce);
		world.setBlock(i + 9, j + 2, k + 14, ACBlocks.frostWaterIce);
		world.setBlock(i + 9, j + 2, k + 15, ACBlocks.frostWaterIce);
		world.setBlock(i + 9, j + 2, k + 16, ACBlocks.frostWaterIce);
		world.setBlock(i + 9, j + 2, k + 17, ACBlocks.frostWaterIce);
		world.setBlock(i + 9, j + 2, k + 18, ACBlocks.frostWaterIce);
		world.setBlock(i + 9, j + 2, k + 19, ACBlocks.frostWaterIce);
		world.setBlock(i + 9, j + 2, k + 20, ACBlocks.frostWaterIce);
		world.setBlock(i + 9, j + 3, k + 3, ACBlocks.frostWaterIce);
		world.setBlock(i + 9, j + 3, k + 4, ACBlocks.frostWaterIce);
		world.setBlock(i + 9, j + 3, k + 5, ACBlocks.frostWaterIce);
		world.setBlock(i + 9, j + 3, k + 6, ACBlocks.frostWaterIce);
		world.setBlock(i + 9, j + 3, k + 7, ACBlocks.frostWaterIce);
		world.setBlock(i + 9, j + 3, k + 8, ACBlocks.frostWaterIce);
		world.setBlock(i + 9, j + 3, k + 9, ACBlocks.frostWaterIce);
		world.setBlock(i + 9, j + 3, k + 10, ACBlocks.frostWaterIce);
		world.setBlock(i + 9, j + 3, k + 11, ACBlocks.frostWaterIce);
		world.setBlock(i + 9, j + 3, k + 12, ACBlocks.frostWaterIce);
		world.setBlock(i + 9, j + 3, k + 13, ACBlocks.frostWaterIce);
		world.setBlock(i + 9, j + 3, k + 14, ACBlocks.frostWaterIce);
		world.setBlock(i + 9, j + 3, k + 15, ACBlocks.frostWaterIce);
		world.setBlock(i + 9, j + 3, k + 16, ACBlocks.frostWaterIce);
		world.setBlock(i + 9, j + 3, k + 17, ACBlocks.frostWaterIce);
		world.setBlock(i + 9, j + 3, k + 18, ACBlocks.frostWaterIce);
		world.setBlock(i + 9, j + 3, k + 19, ACBlocks.frostWaterIce);
		world.setBlock(i + 9, j + 4, k + 3, ACBlocks.frostWaterIce);
		world.setBlock(i + 9, j + 4, k + 4, ACBlocks.frostWaterIce);
		world.setBlock(i + 9, j + 4, k + 5, ACBlocks.frostWaterIce);
		world.setBlock(i + 9, j + 4, k + 6, ACBlocks.frostWaterIce);
		world.setBlock(i + 9, j + 4, k + 7, ACBlocks.frostWaterIce);
		world.setBlock(i + 9, j + 4, k + 8, ACBlocks.frostWaterIce);
		world.setBlock(i + 9, j + 4, k + 9, ACBlocks.frostWaterIce);
		world.setBlock(i + 9, j + 4, k + 10, ACBlocks.frostWaterIce);
		world.setBlock(i + 9, j + 4, k + 11, ACBlocks.frostWaterIce);
		world.setBlock(i + 9, j + 4, k + 12, ACBlocks.frostWaterIce);
		world.setBlock(i + 9, j + 4, k + 13, ACBlocks.frostWaterIce);
		world.setBlock(i + 9, j + 4, k + 14, ACBlocks.frostWaterIce);
		world.setBlock(i + 9, j + 4, k + 15, ACBlocks.frostWaterIce);
		world.setBlock(i + 9, j + 4, k + 16, ACBlocks.frostWaterIce);
		world.setBlock(i + 9, j + 4, k + 17, ACBlocks.frostWaterIce);
		world.setBlock(i + 9, j + 4, k + 18, ACBlocks.frostWaterIce);
		world.setBlock(i + 9, j + 4, k + 19, ACBlocks.frostWaterIce);
		world.setBlock(i + 9, j + 5, k + 3, ACBlocks.frostWaterIce);
		world.setBlock(i + 9, j + 5, k + 4, ACBlocks.frostWaterIce);
		world.setBlock(i + 9, j + 5, k + 5, ACBlocks.frostWaterIce);
		world.setBlock(i + 9, j + 5, k + 6, ACBlocks.frostWaterIce);
		world.setBlock(i + 9, j + 5, k + 7, ACBlocks.frostWaterIce);
		world.setBlock(i + 9, j + 5, k + 8, ACBlocks.frostWaterIce);
		world.setBlock(i + 9, j + 5, k + 9, ACBlocks.frostWaterIce);
		world.setBlock(i + 9, j + 5, k + 10, ACBlocks.frostWaterIce);
		world.setBlock(i + 9, j + 5, k + 11, ACBlocks.frostWaterIce);
		world.setBlock(i + 9, j + 5, k + 12, ACBlocks.frostWaterIce);
		world.setBlock(i + 9, j + 5, k + 13, ACBlocks.frostWaterIce);
		world.setBlock(i + 9, j + 5, k + 14, ACBlocks.frostWaterIce);
		world.setBlock(i + 9, j + 5, k + 15, ACBlocks.frostWaterIce);
		world.setBlock(i + 9, j + 5, k + 16, ACBlocks.frostWaterIce);
		world.setBlock(i + 9, j + 5, k + 17, ACBlocks.frostWaterIce);
		world.setBlock(i + 9, j + 5, k + 18, ACBlocks.frostWaterIce);
		world.setBlock(i + 9, j + 5, k + 19, ACBlocks.frostWaterIce);
		world.setBlock(i + 9, j + 6, k + 3, ACBlocks.frostWaterIce);
		world.setBlock(i + 9, j + 6, k + 4, ACBlocks.frostWaterIce);
		world.setBlock(i + 9, j + 6, k + 5, ACBlocks.frostWaterIce);
		world.setBlock(i + 9, j + 6, k + 6, ACBlocks.frostWaterIce);
		world.setBlock(i + 9, j + 6, k + 7, ACBlocks.frostWaterIce);
		world.setBlock(i + 9, j + 6, k + 8, ACBlocks.frostWaterIce);
		world.setBlock(i + 9, j + 6, k + 9, ACBlocks.frostWaterIce);
		world.setBlock(i + 9, j + 6, k + 10, ACBlocks.frostWaterIce);
		world.setBlock(i + 9, j + 6, k + 11, ACBlocks.frostWaterIce);
		world.setBlock(i + 9, j + 6, k + 12, ACBlocks.frostWaterIce);
		world.setBlock(i + 9, j + 6, k + 13, ACBlocks.frostWaterIce);
		world.setBlock(i + 9, j + 6, k + 14, ACBlocks.frostWaterIce);
		world.setBlock(i + 9, j + 6, k + 15, ACBlocks.frostWaterIce);
		world.setBlock(i + 9, j + 6, k + 16, ACBlocks.frostWaterIce);
		world.setBlock(i + 9, j + 6, k + 17, ACBlocks.frostWaterIce);
		world.setBlock(i + 9, j + 6, k + 18, ACBlocks.frostWaterIce);
		world.setBlock(i + 9, j + 6, k + 19, ACBlocks.frostWaterIce);
		world.setBlock(i + 9, j + 7, k + 3, ACBlocks.frostWaterIce);
		world.setBlock(i + 9, j + 7, k + 4, ACBlocks.frostWaterIce);
		world.setBlock(i + 9, j + 7, k + 5, ACBlocks.frostWaterIce);
		world.setBlock(i + 9, j + 7, k + 6, ACBlocks.frostWaterIce);
		world.setBlock(i + 9, j + 7, k + 7, ACBlocks.frostWaterIce);
		world.setBlock(i + 9, j + 7, k + 8, ACBlocks.frostWaterIce);
		world.setBlock(i + 9, j + 7, k + 9, ACBlocks.frostWaterIce);
		world.setBlock(i + 9, j + 7, k + 10, ACBlocks.frostWaterIce);
		world.setBlock(i + 9, j + 7, k + 11, ACBlocks.frostWaterIce);
		world.setBlock(i + 9, j + 7, k + 12, ACBlocks.frostWaterIce);
		world.setBlock(i + 9, j + 7, k + 13, ACBlocks.frostWaterIce);
		world.setBlock(i + 9, j + 7, k + 14, ACBlocks.frostWaterIce);
		world.setBlock(i + 9, j + 7, k + 15, ACBlocks.frostWaterIce);
		world.setBlock(i + 9, j + 7, k + 16, ACBlocks.frostWaterIce);
		world.setBlock(i + 9, j + 7, k + 17, ACBlocks.frostWaterIce);
		world.setBlock(i + 9, j + 7, k + 18, ACBlocks.frostWaterIce);
		world.setBlock(i + 9, j + 8, k + 4, ACBlocks.frostWaterIce);
		world.setBlock(i + 9, j + 8, k + 5, ACBlocks.frostWaterIce);
		world.setBlock(i + 9, j + 8, k + 6, ACBlocks.frostWaterIce);
		world.setBlock(i + 9, j + 8, k + 7, ACBlocks.frostWaterIce);
		world.setBlock(i + 9, j + 8, k + 8, ACBlocks.frostWaterIce);
		world.setBlock(i + 9, j + 8, k + 9, ACBlocks.frostWaterIce);
		world.setBlock(i + 9, j + 8, k + 10, ACBlocks.frostWaterIce);
		world.setBlock(i + 9, j + 8, k + 11, ACBlocks.frostWaterIce);
		world.setBlock(i + 9, j + 8, k + 12, ACBlocks.frostWaterIce);
		world.setBlock(i + 9, j + 8, k + 13, ACBlocks.frostWaterIce);
		world.setBlock(i + 9, j + 8, k + 14, ACBlocks.frostWaterIce);
		world.setBlock(i + 9, j + 8, k + 15, ACBlocks.frostWaterIce);
		world.setBlock(i + 9, j + 8, k + 16, ACBlocks.frostWaterIce);
		world.setBlock(i + 9, j + 8, k + 17, ACBlocks.frostWaterIce);
		world.setBlock(i + 9, j + 8, k + 18, ACBlocks.frostWaterIce);
		world.setBlock(i + 9, j + 9, k + 5, ACBlocks.frostWaterIce);
		world.setBlock(i + 9, j + 9, k + 6, ACBlocks.frostWaterIce);
		world.setBlock(i + 9, j + 9, k + 7, ACBlocks.frostWaterIce);
		world.setBlock(i + 9, j + 9, k + 8, ACBlocks.frostWaterIce);
		world.setBlock(i + 9, j + 9, k + 9, ACBlocks.frostWaterIce);
		world.setBlock(i + 9, j + 9, k + 10, ACBlocks.frostWaterIce);
		world.setBlock(i + 9, j + 9, k + 11, ACBlocks.frostWaterIce);
		world.setBlock(i + 9, j + 9, k + 12, ACBlocks.frostWaterIce);
		world.setBlock(i + 9, j + 9, k + 13, ACBlocks.frostWaterIce);
		world.setBlock(i + 9, j + 9, k + 14, ACBlocks.frostWaterIce);
		world.setBlock(i + 9, j + 9, k + 15, ACBlocks.frostWaterIce);
		world.setBlock(i + 9, j + 9, k + 16, ACBlocks.frostWaterIce);
		world.setBlock(i + 9, j + 9, k + 17, ACBlocks.frostWaterIce);
		world.setBlock(i + 9, j + 9, k + 18, ACBlocks.frostWaterIce);
		world.setBlock(i + 9, j + 10, k + 5, ACBlocks.frostWaterIce);
		world.setBlock(i + 9, j + 10, k + 6, ACBlocks.frostWaterIce);
		world.setBlock(i + 9, j + 10, k + 7, ACBlocks.frostWaterIce);
		world.setBlock(i + 9, j + 10, k + 8, ACBlocks.frostWaterIce);
		world.setBlock(i + 9, j + 10, k + 9, ACBlocks.frostWaterIce);
		world.setBlock(i + 9, j + 10, k + 10, ACBlocks.frostWaterIce);
		world.setBlock(i + 9, j + 10, k + 11, ACBlocks.frostWaterIce);
		world.setBlock(i + 9, j + 10, k + 12, ACBlocks.frostWaterIce);
		world.setBlock(i + 9, j + 10, k + 13, ACBlocks.frostWaterIce);
		world.setBlock(i + 9, j + 10, k + 14, ACBlocks.frostWaterIce);
		world.setBlock(i + 9, j + 10, k + 15, ACBlocks.frostWaterIce);
		world.setBlock(i + 9, j + 10, k + 16, ACBlocks.frostWaterIce);
		world.setBlock(i + 9, j + 10, k + 17, ACBlocks.frostWaterIce);
		world.setBlock(i + 9, j + 10, k + 18, ACBlocks.frostWaterIce);
		world.setBlock(i + 9, j + 11, k + 5, ACBlocks.frostWaterIce);
		world.setBlock(i + 9, j + 11, k + 6, ACBlocks.frostWaterIce);
		world.setBlock(i + 9, j + 11, k + 7, ACBlocks.frostWaterIce);
		world.setBlock(i + 9, j + 11, k + 8, ACBlocks.frostWaterIce);
		world.setBlock(i + 9, j + 11, k + 9, ACBlocks.frostWaterIce);
		world.setBlock(i + 9, j + 11, k + 10, ACBlocks.frostWaterIce);
		world.setBlock(i + 9, j + 11, k + 11, ACBlocks.frostWaterIce);
		world.setBlock(i + 9, j + 11, k + 12, ACBlocks.frostWaterIce);
		world.setBlock(i + 9, j + 11, k + 13, ACBlocks.frostWaterIce);
		world.setBlock(i + 9, j + 11, k + 14, ACBlocks.frostWaterIce);
		world.setBlock(i + 9, j + 11, k + 15, ACBlocks.frostWaterIce);
		world.setBlock(i + 9, j + 11, k + 16, ACBlocks.frostWaterIce);
		world.setBlock(i + 9, j + 11, k + 17, ACBlocks.frostWaterIce);
		world.setBlock(i + 9, j + 11, k + 18, ACBlocks.frostWaterIce);
		world.setBlock(i + 9, j + 12, k + 6, ACBlocks.frostWaterIce);
		world.setBlock(i + 9, j + 12, k + 7, ACBlocks.frostWaterIce);
		world.setBlock(i + 9, j + 12, k + 8, ACBlocks.frostWaterIce);
		world.setBlock(i + 9, j + 12, k + 9, ACBlocks.frostWaterIce);
		world.setBlock(i + 9, j + 12, k + 10, ACBlocks.frostWaterIce);
		world.setBlock(i + 9, j + 12, k + 11, ACBlocks.frostWaterIce);
		world.setBlock(i + 9, j + 12, k + 12, ACBlocks.frostWaterIce);
		world.setBlock(i + 9, j + 12, k + 13, ACBlocks.frostWaterIce);
		world.setBlock(i + 9, j + 12, k + 14, ACBlocks.frostWaterIce);
		world.setBlock(i + 9, j + 12, k + 15, ACBlocks.frostWaterIce);
		world.setBlock(i + 9, j + 12, k + 16, ACBlocks.frostWaterIce);
		world.setBlock(i + 9, j + 12, k + 17, ACBlocks.frostWaterIce);
		world.setBlock(i + 9, j + 12, k + 18, ACBlocks.frostWaterIce);
		world.setBlock(i + 9, j + 13, k + 7, ACBlocks.frostWaterIce);
		world.setBlock(i + 9, j + 13, k + 8, ACBlocks.frostWaterIce);
		world.setBlock(i + 9, j + 13, k + 9, ACBlocks.frostWaterIce);
		world.setBlock(i + 9, j + 13, k + 10, ACBlocks.frostWaterIce);
		world.setBlock(i + 9, j + 13, k + 11, ACBlocks.frostWaterIce);
		world.setBlock(i + 9, j + 13, k + 12, ACBlocks.frostWaterIce);
		world.setBlock(i + 9, j + 13, k + 13, ACBlocks.frostWaterIce);
		world.setBlock(i + 9, j + 13, k + 14, ACBlocks.frostWaterIce);
		world.setBlock(i + 9, j + 13, k + 15, ACBlocks.frostWaterIce);
		world.setBlock(i + 9, j + 13, k + 16, ACBlocks.frostWaterIce);
		world.setBlock(i + 9, j + 13, k + 17, ACBlocks.frostWaterIce);
		world.setBlock(i + 9, j + 13, k + 18, ACBlocks.frostWaterIce);
		world.setBlock(i + 9, j + 14, k + 8, ACBlocks.frostWaterIce);
		world.setBlock(i + 9, j + 14, k + 9, ACBlocks.frostWaterIce);
		world.setBlock(i + 9, j + 14, k + 10, ACBlocks.frostWaterIce);
		world.setBlock(i + 9, j + 14, k + 11, ACBlocks.frostWaterIce);
		world.setBlock(i + 9, j + 14, k + 12, ACBlocks.frostWaterIce);
		world.setBlock(i + 9, j + 14, k + 13, ACBlocks.frostWaterIce);
		world.setBlock(i + 9, j + 14, k + 14, ACBlocks.frostWaterIce);
		world.setBlock(i + 9, j + 14, k + 15, ACBlocks.frostWaterIce);
		world.setBlock(i + 9, j + 14, k + 16, ACBlocks.frostWaterIce);
		world.setBlock(i + 9, j + 14, k + 17, ACBlocks.frostWaterIce);
		world.setBlock(i + 10, j + 0, k + 3, ACBlocks.frostWaterIce);
		world.setBlock(i + 10, j + 0, k + 4, ACBlocks.frostWaterIce);
		world.setBlock(i + 10, j + 0, k + 5, ACBlocks.frostWaterIce);
		world.setBlock(i + 10, j + 0, k + 6, ACBlocks.frostWaterIce);
		world.setBlock(i + 10, j + 0, k + 7, ACBlocks.frostWaterIce);
		world.setBlock(i + 10, j + 0, k + 8, ACBlocks.frostWaterIce);
		world.setBlock(i + 10, j + 0, k + 9, ACBlocks.frostWaterIce);
		world.setBlock(i + 10, j + 0, k + 10, ACBlocks.frostWaterIce);
		world.setBlock(i + 10, j + 0, k + 11, ACBlocks.frostWaterIce);
		world.setBlock(i + 10, j + 0, k + 12, ACBlocks.frostWaterIce);
		world.setBlock(i + 10, j + 0, k + 13, ACBlocks.frostWaterIce);
		world.setBlock(i + 10, j + 0, k + 14, ACBlocks.frostWaterIce);
		world.setBlock(i + 10, j + 0, k + 15, ACBlocks.frostWaterIce);
		world.setBlock(i + 10, j + 0, k + 16, ACBlocks.frostWaterIce);
		world.setBlock(i + 10, j + 0, k + 17, ACBlocks.frostWaterIce);
		world.setBlock(i + 10, j + 0, k + 19, ACBlocks.frostWaterIce);
		world.setBlock(i + 10, j + 1, k + 3, ACBlocks.frostWaterIce);
		world.setBlock(i + 10, j + 1, k + 4, ACBlocks.frostWaterIce);
		world.setBlock(i + 10, j + 1, k + 5, ACBlocks.frostWaterIce);
		world.setBlock(i + 10, j + 1, k + 6, ACBlocks.frostWaterIce);
		world.setBlock(i + 10, j + 1, k + 7, ACBlocks.frostWaterIce);
		world.setBlock(i + 10, j + 1, k + 8, ACBlocks.frostWaterIce);
		world.setBlock(i + 10, j + 1, k + 9, ACBlocks.frostWaterIce);
		world.setBlock(i + 10, j + 1, k + 10, ACBlocks.frostWaterIce);
		world.setBlock(i + 10, j + 1, k + 11, ACBlocks.frostWaterIce);
		world.setBlock(i + 10, j + 1, k + 12, ACBlocks.frostWaterIce);
		world.setBlock(i + 10, j + 1, k + 13, ACBlocks.frostWaterIce);
		world.setBlock(i + 10, j + 1, k + 14, ACBlocks.frostWaterIce);
		world.setBlock(i + 10, j + 1, k + 15, ACBlocks.frostWaterIce);
		world.setBlock(i + 10, j + 1, k + 16, ACBlocks.frostWaterIce);
		world.setBlock(i + 10, j + 1, k + 17, ACBlocks.frostWaterIce);
		world.setBlock(i + 10, j + 1, k + 18, ACBlocks.frostWaterIce);
		world.setBlock(i + 10, j + 1, k + 19, ACBlocks.frostWaterIce);
		world.setBlock(i + 10, j + 2, k + 3, ACBlocks.frostWaterIce);
		world.setBlock(i + 10, j + 2, k + 4, ACBlocks.frostWaterIce);
		world.setBlock(i + 10, j + 2, k + 5, ACBlocks.frostWaterIce);
		world.setBlock(i + 10, j + 2, k + 6, ACBlocks.frostWaterIce);
		world.setBlock(i + 10, j + 2, k + 7, ACBlocks.frostWaterIce);
		world.setBlock(i + 10, j + 2, k + 8, ACBlocks.frostWaterIce);
		world.setBlock(i + 10, j + 2, k + 9, ACBlocks.frostWaterIce);
		world.setBlock(i + 10, j + 2, k + 10, ACBlocks.frostWaterIce);
		world.setBlock(i + 10, j + 2, k + 11, ACBlocks.frostWaterIce);
		world.setBlock(i + 10, j + 2, k + 12, ACBlocks.frostWaterIce);
		world.setBlock(i + 10, j + 2, k + 13, ACBlocks.frostWaterIce);
		world.setBlock(i + 10, j + 2, k + 14, ACBlocks.frostWaterIce);
		world.setBlock(i + 10, j + 2, k + 15, ACBlocks.frostWaterIce);
		world.setBlock(i + 10, j + 2, k + 16, ACBlocks.frostWaterIce);
		world.setBlock(i + 10, j + 2, k + 17, ACBlocks.frostWaterIce);
		world.setBlock(i + 10, j + 2, k + 18, ACBlocks.frostWaterIce);
		world.setBlock(i + 10, j + 2, k + 19, ACBlocks.frostWaterIce);
		world.setBlock(i + 10, j + 3, k + 2, ACBlocks.frostWaterIce);
		world.setBlock(i + 10, j + 3, k + 3, ACBlocks.frostWaterIce);
		world.setBlock(i + 10, j + 3, k + 4, ACBlocks.frostWaterIce);
		world.setBlock(i + 10, j + 3, k + 5, ACBlocks.frostWaterIce);
		world.setBlock(i + 10, j + 3, k + 6, ACBlocks.frostWaterIce);
		world.setBlock(i + 10, j + 3, k + 7, ACBlocks.frostWaterIce);
		world.setBlock(i + 10, j + 3, k + 8, ACBlocks.frostWaterIce);
		world.setBlock(i + 10, j + 3, k + 9, ACBlocks.frostWaterIce);
		world.setBlock(i + 10, j + 3, k + 10, ACBlocks.frostWaterIce);
		world.setBlock(i + 10, j + 3, k + 11, ACBlocks.frostWaterIce);
		world.setBlock(i + 10, j + 3, k + 12, ACBlocks.frostWaterIce);
		world.setBlock(i + 10, j + 3, k + 13, ACBlocks.frostWaterIce);
		world.setBlock(i + 10, j + 3, k + 14, ACBlocks.frostWaterIce);
		world.setBlock(i + 10, j + 3, k + 15, ACBlocks.frostWaterIce);
		world.setBlock(i + 10, j + 3, k + 16, ACBlocks.frostWaterIce);
		world.setBlock(i + 10, j + 3, k + 17, ACBlocks.frostWaterIce);
		world.setBlock(i + 10, j + 3, k + 18, ACBlocks.frostWaterIce);
		world.setBlock(i + 10, j + 3, k + 19, ACBlocks.frostWaterIce);
		world.setBlock(i + 10, j + 4, k + 2, ACBlocks.frostWaterIce);
		world.setBlock(i + 10, j + 4, k + 3, ACBlocks.frostWaterIce);
		world.setBlock(i + 10, j + 4, k + 4, ACBlocks.frostWaterIce);
		world.setBlock(i + 10, j + 4, k + 5, ACBlocks.frostWaterIce);
		world.setBlock(i + 10, j + 4, k + 6, ACBlocks.frostWaterIce);
		world.setBlock(i + 10, j + 4, k + 7, ACBlocks.frostWaterIce);
		world.setBlock(i + 10, j + 4, k + 8, ACBlocks.frostWaterIce);
		world.setBlock(i + 10, j + 4, k + 9, ACBlocks.frostWaterIce);
		world.setBlock(i + 10, j + 4, k + 10, ACBlocks.frostWaterIce);
		world.setBlock(i + 10, j + 4, k + 11, ACBlocks.frostWaterIce);
		world.setBlock(i + 10, j + 4, k + 12, ACBlocks.frostWaterIce);
		world.setBlock(i + 10, j + 4, k + 13, ACBlocks.frostWaterIce);
		world.setBlock(i + 10, j + 4, k + 14, ACBlocks.frostWaterIce);
		world.setBlock(i + 10, j + 4, k + 15, ACBlocks.frostWaterIce);
		world.setBlock(i + 10, j + 4, k + 16, ACBlocks.frostWaterIce);
		world.setBlock(i + 10, j + 4, k + 17, ACBlocks.frostWaterIce);
		world.setBlock(i + 10, j + 4, k + 18, ACBlocks.frostWaterIce);
		world.setBlock(i + 10, j + 4, k + 19, ACBlocks.frostWaterIce);
		world.setBlock(i + 10, j + 5, k + 2, ACBlocks.frostWaterIce);
		world.setBlock(i + 10, j + 5, k + 3, ACBlocks.frostWaterIce);
		world.setBlock(i + 10, j + 5, k + 4, ACBlocks.frostWaterIce);
		world.setBlock(i + 10, j + 5, k + 5, ACBlocks.frostWaterIce);
		world.setBlock(i + 10, j + 5, k + 6, ACBlocks.frostWaterIce);
		world.setBlock(i + 10, j + 5, k + 7, ACBlocks.frostWaterIce);
		world.setBlock(i + 10, j + 5, k + 8, ACBlocks.frostWaterIce);
		world.setBlock(i + 10, j + 5, k + 9, ACBlocks.frostWaterIce);
		world.setBlock(i + 10, j + 5, k + 10, ACBlocks.frostWaterIce);
		world.setBlock(i + 10, j + 5, k + 11, ACBlocks.frostWaterIce);
		world.setBlock(i + 10, j + 5, k + 12, ACBlocks.frostWaterIce);
		world.setBlock(i + 10, j + 5, k + 13, ACBlocks.frostWaterIce);
		world.setBlock(i + 10, j + 5, k + 14, ACBlocks.frostWaterIce);
		world.setBlock(i + 10, j + 5, k + 15, ACBlocks.frostWaterIce);
		world.setBlock(i + 10, j + 5, k + 16, ACBlocks.frostWaterIce);
		world.setBlock(i + 10, j + 5, k + 17, ACBlocks.frostWaterIce);
		world.setBlock(i + 10, j + 5, k + 18, ACBlocks.frostWaterIce);
		world.setBlock(i + 10, j + 5, k + 19, ACBlocks.frostWaterIce);
		world.setBlock(i + 10, j + 6, k + 2, ACBlocks.frostWaterIce);
		world.setBlock(i + 10, j + 6, k + 3, ACBlocks.frostWaterIce);
		world.setBlock(i + 10, j + 6, k + 4, ACBlocks.frostWaterIce);
		world.setBlock(i + 10, j + 6, k + 5, ACBlocks.frostWaterIce);
		world.setBlock(i + 10, j + 6, k + 6, ACBlocks.frostWaterIce);
		world.setBlock(i + 10, j + 6, k + 7, ACBlocks.frostWaterIce);
		world.setBlock(i + 10, j + 6, k + 8, ACBlocks.frostWaterIce);
		world.setBlock(i + 10, j + 6, k + 9, ACBlocks.frostWaterIce);
		world.setBlock(i + 10, j + 6, k + 10, ACBlocks.frostWaterIce);
		world.setBlock(i + 10, j + 6, k + 11, ACBlocks.frostWaterIce);
		world.setBlock(i + 10, j + 6, k + 12, ACBlocks.frostWaterIce);
		world.setBlock(i + 10, j + 6, k + 13, ACBlocks.frostWaterIce);
		world.setBlock(i + 10, j + 6, k + 14, ACBlocks.frostWaterIce);
		world.setBlock(i + 10, j + 6, k + 15, ACBlocks.frostWaterIce);
		world.setBlock(i + 10, j + 6, k + 16, ACBlocks.frostWaterIce);
		world.setBlock(i + 10, j + 6, k + 17, ACBlocks.frostWaterIce);
		world.setBlock(i + 10, j + 6, k + 18, ACBlocks.frostWaterIce);
		world.setBlock(i + 10, j + 6, k + 19, ACBlocks.frostWaterIce);
		world.setBlock(i + 10, j + 7, k + 3, ACBlocks.frostWaterIce);
		world.setBlock(i + 10, j + 7, k + 4, ACBlocks.frostWaterIce);
		world.setBlock(i + 10, j + 7, k + 5, ACBlocks.frostWaterIce);
		world.setBlock(i + 10, j + 7, k + 6, ACBlocks.frostWaterIce);
		world.setBlock(i + 10, j + 7, k + 7, ACBlocks.frostWaterIce);
		world.setBlock(i + 10, j + 7, k + 8, ACBlocks.frostWaterIce);
		world.setBlock(i + 10, j + 7, k + 9, ACBlocks.frostWaterIce);
		world.setBlock(i + 10, j + 7, k + 10, ACBlocks.frostWaterIce);
		world.setBlock(i + 10, j + 7, k + 11, ACBlocks.frostWaterIce);
		world.setBlock(i + 10, j + 7, k + 12, ACBlocks.frostWaterIce);
		world.setBlock(i + 10, j + 7, k + 13, ACBlocks.frostWaterIce);
		world.setBlock(i + 10, j + 7, k + 14, ACBlocks.frostWaterIce);
		world.setBlock(i + 10, j + 7, k + 15, ACBlocks.frostWaterIce);
		world.setBlock(i + 10, j + 7, k + 16, ACBlocks.frostWaterIce);
		world.setBlock(i + 10, j + 7, k + 17, ACBlocks.frostWaterIce);
		world.setBlock(i + 10, j + 7, k + 18, ACBlocks.frostWaterIce);
		world.setBlock(i + 10, j + 8, k + 4, ACBlocks.frostWaterIce);
		world.setBlock(i + 10, j + 8, k + 5, ACBlocks.frostWaterIce);
		world.setBlock(i + 10, j + 8, k + 6, ACBlocks.frostWaterIce);
		world.setBlock(i + 10, j + 8, k + 7, ACBlocks.frostWaterIce);
		world.setBlock(i + 10, j + 8, k + 8, ACBlocks.frostWaterIce);
		world.setBlock(i + 10, j + 8, k + 9, ACBlocks.frostWaterIce);
		world.setBlock(i + 10, j + 8, k + 10, ACBlocks.frostWaterIce);
		world.setBlock(i + 10, j + 8, k + 11, ACBlocks.frostWaterIce);
		world.setBlock(i + 10, j + 8, k + 12, ACBlocks.frostWaterIce);
		world.setBlock(i + 10, j + 8, k + 13, ACBlocks.frostWaterIce);
		world.setBlock(i + 10, j + 8, k + 14, ACBlocks.frostWaterIce);
		world.setBlock(i + 10, j + 8, k + 15, ACBlocks.frostWaterIce);
		world.setBlock(i + 10, j + 8, k + 16, ACBlocks.frostWaterIce);
		world.setBlock(i + 10, j + 8, k + 17, ACBlocks.frostWaterIce);
		world.setBlock(i + 10, j + 8, k + 18, ACBlocks.frostWaterIce);
		world.setBlock(i + 10, j + 9, k + 5, ACBlocks.frostWaterIce);
		world.setBlock(i + 10, j + 9, k + 6, ACBlocks.frostWaterIce);
		world.setBlock(i + 10, j + 9, k + 7, ACBlocks.frostWaterIce);
		world.setBlock(i + 10, j + 9, k + 8, ACBlocks.frostWaterIce);
		world.setBlock(i + 10, j + 9, k + 9, ACBlocks.frostWaterIce);
		world.setBlock(i + 10, j + 9, k + 10, ACBlocks.frostWaterIce);
		world.setBlock(i + 10, j + 9, k + 11, ACBlocks.frostWaterIce);
		world.setBlock(i + 10, j + 9, k + 12, ACBlocks.frostWaterIce);
		world.setBlock(i + 10, j + 9, k + 13, ACBlocks.frostWaterIce);
		world.setBlock(i + 10, j + 9, k + 14, ACBlocks.frostWaterIce);
		world.setBlock(i + 10, j + 9, k + 15, ACBlocks.frostWaterIce);
		world.setBlock(i + 10, j + 9, k + 16, ACBlocks.frostWaterIce);
		world.setBlock(i + 10, j + 9, k + 17, ACBlocks.frostWaterIce);
		world.setBlock(i + 10, j + 9, k + 18, ACBlocks.frostWaterIce);
		world.setBlock(i + 10, j + 9, k + 19, ACBlocks.frostWaterIce);
		world.setBlock(i + 10, j + 10, k + 5, ACBlocks.frostWaterIce);
		world.setBlock(i + 10, j + 10, k + 6, ACBlocks.frostWaterIce);
		world.setBlock(i + 10, j + 10, k + 7, ACBlocks.frostWaterIce);
		world.setBlock(i + 10, j + 10, k + 8, ACBlocks.frostWaterIce);
		world.setBlock(i + 10, j + 10, k + 9, ACBlocks.frostWaterIce);
		world.setBlock(i + 10, j + 10, k + 10, ACBlocks.frostWaterIce);
		world.setBlock(i + 10, j + 10, k + 11, ACBlocks.frostWaterIce);
		world.setBlock(i + 10, j + 10, k + 12, ACBlocks.frostWaterIce);
		world.setBlock(i + 10, j + 10, k + 13, ACBlocks.frostWaterIce);
		world.setBlock(i + 10, j + 10, k + 14, ACBlocks.frostWaterIce);
		world.setBlock(i + 10, j + 10, k + 15, ACBlocks.frostWaterIce);
		world.setBlock(i + 10, j + 10, k + 16, ACBlocks.frostWaterIce);
		world.setBlock(i + 10, j + 10, k + 17, ACBlocks.frostWaterIce);
		world.setBlock(i + 10, j + 10, k + 18, ACBlocks.frostWaterIce);
		world.setBlock(i + 10, j + 10, k + 19, ACBlocks.frostWaterIce);
		world.setBlock(i + 10, j + 11, k + 5, ACBlocks.frostWaterIce);
		world.setBlock(i + 10, j + 11, k + 6, ACBlocks.frostWaterIce);
		world.setBlock(i + 10, j + 11, k + 7, ACBlocks.frostWaterIce);
		world.setBlock(i + 10, j + 11, k + 8, ACBlocks.frostWaterIce);
		world.setBlock(i + 10, j + 11, k + 9, ACBlocks.frostWaterIce);
		world.setBlock(i + 10, j + 11, k + 10, ACBlocks.frostWaterIce);
		world.setBlock(i + 10, j + 11, k + 11, ACBlocks.frostWaterIce);
		world.setBlock(i + 10, j + 11, k + 12, ACBlocks.frostWaterIce);
		world.setBlock(i + 10, j + 11, k + 13, ACBlocks.frostWaterIce);
		world.setBlock(i + 10, j + 11, k + 14, ACBlocks.frostWaterIce);
		world.setBlock(i + 10, j + 11, k + 15, ACBlocks.frostWaterIce);
		world.setBlock(i + 10, j + 11, k + 16, ACBlocks.frostWaterIce);
		world.setBlock(i + 10, j + 11, k + 17, ACBlocks.frostWaterIce);
		world.setBlock(i + 10, j + 11, k + 18, ACBlocks.frostWaterIce);
		world.setBlock(i + 10, j + 11, k + 19, ACBlocks.frostWaterIce);
		world.setBlock(i + 10, j + 12, k + 6, ACBlocks.frostWaterIce);
		world.setBlock(i + 10, j + 12, k + 7, ACBlocks.frostWaterIce);
		world.setBlock(i + 10, j + 12, k + 8, ACBlocks.frostWaterIce);
		world.setBlock(i + 10, j + 12, k + 9, ACBlocks.frostWaterIce);
		world.setBlock(i + 10, j + 12, k + 10, ACBlocks.frostWaterIce);
		world.setBlock(i + 10, j + 12, k + 11, ACBlocks.frostWaterIce);
		world.setBlock(i + 10, j + 12, k + 12, ACBlocks.frostWaterIce);
		world.setBlock(i + 10, j + 12, k + 13, ACBlocks.frostWaterIce);
		world.setBlock(i + 10, j + 12, k + 14, ACBlocks.frostWaterIce);
		world.setBlock(i + 10, j + 12, k + 15, ACBlocks.frostWaterIce);
		world.setBlock(i + 10, j + 12, k + 16, ACBlocks.frostWaterIce);
		world.setBlock(i + 10, j + 12, k + 17, ACBlocks.frostWaterIce);
		world.setBlock(i + 10, j + 12, k + 18, ACBlocks.frostWaterIce);
		world.setBlock(i + 10, j + 12, k + 19, ACBlocks.frostWaterIce);
		world.setBlock(i + 10, j + 13, k + 6, ACBlocks.frostWaterIce);
		world.setBlock(i + 10, j + 13, k + 7, ACBlocks.frostWaterIce);
		world.setBlock(i + 10, j + 13, k + 8, ACBlocks.frostWaterIce);
		world.setBlock(i + 10, j + 13, k + 9, ACBlocks.frostWaterIce);
		world.setBlock(i + 10, j + 13, k + 10, ACBlocks.frostWaterIce);
		world.setBlock(i + 10, j + 13, k + 11, ACBlocks.frostWaterIce);
		world.setBlock(i + 10, j + 13, k + 12, ACBlocks.frostWaterIce);
		world.setBlock(i + 10, j + 13, k + 13, ACBlocks.frostWaterIce);
		world.setBlock(i + 10, j + 13, k + 14, ACBlocks.frostWaterIce);
		world.setBlock(i + 10, j + 13, k + 15, ACBlocks.frostWaterIce);
		world.setBlock(i + 10, j + 13, k + 16, ACBlocks.frostWaterIce);
		world.setBlock(i + 10, j + 13, k + 17, ACBlocks.frostWaterIce);
		world.setBlock(i + 10, j + 13, k + 18, ACBlocks.frostWaterIce);
		world.setBlock(i + 10, j + 14, k + 8, ACBlocks.frostWaterIce);
		world.setBlock(i + 10, j + 14, k + 9, ACBlocks.frostWaterIce);
		world.setBlock(i + 10, j + 14, k + 10, ACBlocks.frostWaterIce);
		world.setBlock(i + 10, j + 14, k + 11, ACBlocks.frostWaterIce);
		world.setBlock(i + 10, j + 14, k + 12, ACBlocks.frostWaterIce);
		world.setBlock(i + 10, j + 14, k + 13, ACBlocks.frostWaterIce);
		world.setBlock(i + 10, j + 14, k + 14, ACBlocks.frostWaterIce);
		world.setBlock(i + 10, j + 14, k + 15, ACBlocks.frostWaterIce);
		world.setBlock(i + 10, j + 14, k + 16, ACBlocks.frostWaterIce);
		world.setBlock(i + 10, j + 14, k + 17, ACBlocks.frostWaterIce);
		world.setBlock(i + 10, j + 15, k + 13, ACBlocks.frostWaterIce);
		world.setBlock(i + 10, j + 15, k + 14, ACBlocks.frostWaterIce);
		world.setBlock(i + 10, j + 15, k + 15, ACBlocks.frostWaterIce);
		world.setBlock(i + 10, j + 15, k + 16, ACBlocks.frostWaterIce);
		world.setBlock(i + 11, j + 0, k + 1, ACBlocks.frostWaterIce);
		world.setBlock(i + 11, j + 0, k + 2, ACBlocks.frostWaterIce);
		world.setBlock(i + 11, j + 0, k + 3, ACBlocks.frostWaterIce);
		world.setBlock(i + 11, j + 0, k + 4, ACBlocks.frostWaterIce);
		world.setBlock(i + 11, j + 0, k + 5, ACBlocks.frostWaterIce);
		world.setBlock(i + 11, j + 0, k + 6, ACBlocks.frostWaterIce);
		world.setBlock(i + 11, j + 0, k + 7, ACBlocks.frostWaterIce);
		world.setBlock(i + 11, j + 0, k + 8, ACBlocks.frostWaterIce);
		world.setBlock(i + 11, j + 0, k + 9, ACBlocks.frostWaterIce);
		world.setBlock(i + 11, j + 0, k + 10, ACBlocks.frostWaterIce);
		world.setBlock(i + 11, j + 0, k + 11, ACBlocks.frostWaterIce);
		world.setBlock(i + 11, j + 0, k + 12, ACBlocks.frostWaterIce);
		world.setBlock(i + 11, j + 0, k + 13, ACBlocks.frostWaterIce);
		world.setBlock(i + 11, j + 0, k + 14, ACBlocks.frostWaterIce);
		world.setBlock(i + 11, j + 0, k + 15, ACBlocks.frostWaterIce);
		world.setBlock(i + 11, j + 0, k + 16, ACBlocks.frostWaterIce);
		world.setBlock(i + 11, j + 0, k + 17, ACBlocks.frostWaterIce);
		world.setBlock(i + 11, j + 0, k + 18, ACBlocks.frostWaterIce);
		world.setBlock(i + 11, j + 0, k + 19, ACBlocks.frostWaterIce);
		world.setBlock(i + 11, j + 1, k + 2, ACBlocks.frostWaterIce);
		world.setBlock(i + 11, j + 1, k + 3, ACBlocks.frostWaterIce);
		world.setBlock(i + 11, j + 1, k + 4, ACBlocks.frostWaterIce);
		world.setBlock(i + 11, j + 1, k + 5, ACBlocks.frostWaterIce);
		world.setBlock(i + 11, j + 1, k + 6, ACBlocks.frostWaterIce);
		world.setBlock(i + 11, j + 1, k + 7, ACBlocks.frostWaterIce);
		world.setBlock(i + 11, j + 1, k + 8, ACBlocks.frostWaterIce);
		world.setBlock(i + 11, j + 1, k + 9, ACBlocks.frostWaterIce);
		world.setBlock(i + 11, j + 1, k + 10, ACBlocks.frostWaterIce);
		world.setBlock(i + 11, j + 1, k + 11, ACBlocks.frostWaterIce);
		world.setBlock(i + 11, j + 1, k + 12, ACBlocks.frostWaterIce);
		world.setBlock(i + 11, j + 1, k + 13, ACBlocks.frostWaterIce);
		world.setBlock(i + 11, j + 1, k + 14, ACBlocks.frostWaterIce);
		world.setBlock(i + 11, j + 1, k + 15, ACBlocks.frostWaterIce);
		world.setBlock(i + 11, j + 1, k + 16, ACBlocks.frostWaterIce);
		world.setBlock(i + 11, j + 1, k + 17, ACBlocks.frostWaterIce);
		world.setBlock(i + 11, j + 1, k + 18, ACBlocks.frostWaterIce);
		world.setBlock(i + 11, j + 1, k + 19, ACBlocks.frostWaterIce);
		world.setBlock(i + 11, j + 2, k + 2, ACBlocks.frostWaterIce);
		world.setBlock(i + 11, j + 2, k + 3, ACBlocks.frostWaterIce);
		world.setBlock(i + 11, j + 2, k + 4, ACBlocks.frostWaterIce);
		world.setBlock(i + 11, j + 2, k + 5, ACBlocks.frostWaterIce);
		world.setBlock(i + 11, j + 2, k + 6, ACBlocks.frostWaterIce);
		world.setBlock(i + 11, j + 2, k + 7, ACBlocks.frostWaterIce);
		world.setBlock(i + 11, j + 2, k + 8, ACBlocks.frostWaterIce);
		world.setBlock(i + 11, j + 2, k + 9, ACBlocks.frostWaterIce);
		world.setBlock(i + 11, j + 2, k + 10, ACBlocks.frostWaterIce);
		world.setBlock(i + 11, j + 2, k + 11, ACBlocks.frostWaterIce);
		world.setBlock(i + 11, j + 2, k + 12, ACBlocks.frostWaterIce);
		world.setBlock(i + 11, j + 2, k + 13, ACBlocks.frostWaterIce);
		world.setBlock(i + 11, j + 2, k + 14, ACBlocks.frostWaterIce);
		world.setBlock(i + 11, j + 2, k + 15, ACBlocks.frostWaterIce);
		world.setBlock(i + 11, j + 2, k + 16, ACBlocks.frostWaterIce);
		world.setBlock(i + 11, j + 2, k + 17, ACBlocks.frostWaterIce);
		world.setBlock(i + 11, j + 2, k + 18, ACBlocks.frostWaterIce);
		world.setBlock(i + 11, j + 2, k + 19, ACBlocks.frostWaterIce);
		world.setBlock(i + 11, j + 2, k + 20, ACBlocks.frostWaterIce);
		world.setBlock(i + 11, j + 3, k + 2, ACBlocks.frostWaterIce);
		world.setBlock(i + 11, j + 3, k + 3, ACBlocks.frostWaterIce);
		world.setBlock(i + 11, j + 3, k + 4, ACBlocks.frostWaterIce);
		world.setBlock(i + 11, j + 3, k + 5, ACBlocks.frostWaterIce);
		world.setBlock(i + 11, j + 3, k + 6, ACBlocks.frostWaterIce);
		world.setBlock(i + 11, j + 3, k + 7, ACBlocks.frostWaterIce);
		world.setBlock(i + 11, j + 3, k + 8, ACBlocks.frostWaterIce);
		world.setBlock(i + 11, j + 3, k + 9, ACBlocks.frostWaterIce);
		world.setBlock(i + 11, j + 3, k + 10, ACBlocks.frostWaterIce);
		world.setBlock(i + 11, j + 3, k + 11, ACBlocks.frostWaterIce);
		world.setBlock(i + 11, j + 3, k + 12, ACBlocks.frostWaterIce);
		world.setBlock(i + 11, j + 3, k + 13, ACBlocks.frostWaterIce);
		world.setBlock(i + 11, j + 3, k + 14, ACBlocks.frostWaterIce);
		world.setBlock(i + 11, j + 3, k + 15, ACBlocks.frostWaterIce);
		world.setBlock(i + 11, j + 3, k + 16, ACBlocks.frostWaterIce);
		world.setBlock(i + 11, j + 3, k + 17, ACBlocks.frostWaterIce);
		world.setBlock(i + 11, j + 3, k + 18, ACBlocks.frostWaterIce);
		world.setBlock(i + 11, j + 3, k + 19, ACBlocks.frostWaterIce);
		world.setBlock(i + 11, j + 3, k + 20, ACBlocks.frostWaterIce);
		world.setBlock(i + 11, j + 4, k + 2, ACBlocks.frostWaterIce);
		world.setBlock(i + 11, j + 4, k + 3, ACBlocks.frostWaterIce);
		world.setBlock(i + 11, j + 4, k + 4, ACBlocks.frostWaterIce);
		world.setBlock(i + 11, j + 4, k + 5, ACBlocks.frostWaterIce);
		world.setBlock(i + 11, j + 4, k + 6, ACBlocks.frostWaterIce);
		world.setBlock(i + 11, j + 4, k + 7, ACBlocks.frostWaterIce);
		world.setBlock(i + 11, j + 4, k + 8, ACBlocks.frostWaterIce);
		world.setBlock(i + 11, j + 4, k + 9, ACBlocks.frostWaterIce);
		world.setBlock(i + 11, j + 4, k + 10, ACBlocks.frostWaterIce);
		world.setBlock(i + 11, j + 4, k + 11, ACBlocks.frostWaterIce);
		world.setBlock(i + 11, j + 4, k + 12, ACBlocks.frostWaterIce);
		world.setBlock(i + 11, j + 4, k + 13, ACBlocks.frostWaterIce);
		world.setBlock(i + 11, j + 4, k + 14, ACBlocks.frostWaterIce);
		world.setBlock(i + 11, j + 4, k + 15, ACBlocks.frostWaterIce);
		world.setBlock(i + 11, j + 4, k + 16, ACBlocks.frostWaterIce);
		world.setBlock(i + 11, j + 4, k + 17, ACBlocks.frostWaterIce);
		world.setBlock(i + 11, j + 4, k + 18, ACBlocks.frostWaterIce);
		world.setBlock(i + 11, j + 4, k + 19, ACBlocks.frostWaterIce);
		world.setBlock(i + 11, j + 4, k + 20, ACBlocks.frostWaterIce);
		world.setBlock(i + 11, j + 5, k + 2, ACBlocks.frostWaterIce);
		world.setBlock(i + 11, j + 5, k + 3, ACBlocks.frostWaterIce);
		world.setBlock(i + 11, j + 5, k + 4, ACBlocks.frostWaterIce);
		world.setBlock(i + 11, j + 5, k + 5, ACBlocks.frostWaterIce);
		world.setBlock(i + 11, j + 5, k + 6, ACBlocks.frostWaterIce);
		world.setBlock(i + 11, j + 5, k + 7, ACBlocks.frostWaterIce);
		world.setBlock(i + 11, j + 5, k + 8, ACBlocks.frostWaterIce);
		world.setBlock(i + 11, j + 5, k + 9, ACBlocks.frostWaterIce);
		world.setBlock(i + 11, j + 5, k + 10, ACBlocks.frostWaterIce);
		world.setBlock(i + 11, j + 5, k + 11, ACBlocks.frostWaterIce);
		world.setBlock(i + 11, j + 5, k + 12, ACBlocks.frostWaterIce);
		world.setBlock(i + 11, j + 5, k + 13, ACBlocks.frostWaterIce);
		world.setBlock(i + 11, j + 5, k + 14, ACBlocks.frostWaterIce);
		world.setBlock(i + 11, j + 5, k + 15, ACBlocks.frostWaterIce);
		world.setBlock(i + 11, j + 5, k + 16, ACBlocks.frostWaterIce);
		world.setBlock(i + 11, j + 5, k + 17, ACBlocks.frostWaterIce);
		world.setBlock(i + 11, j + 5, k + 18, ACBlocks.frostWaterIce);
		world.setBlock(i + 11, j + 5, k + 19, ACBlocks.frostWaterIce);
		world.setBlock(i + 11, j + 5, k + 20, ACBlocks.frostWaterIce);
		world.setBlock(i + 11, j + 6, k + 2, ACBlocks.frostWaterIce);
		world.setBlock(i + 11, j + 6, k + 3, ACBlocks.frostWaterIce);
		world.setBlock(i + 11, j + 6, k + 4, ACBlocks.frostWaterIce);
		world.setBlock(i + 11, j + 6, k + 5, ACBlocks.frostWaterIce);
		world.setBlock(i + 11, j + 6, k + 6, ACBlocks.frostWaterIce);
		world.setBlock(i + 11, j + 6, k + 7, ACBlocks.frostWaterIce);
		world.setBlock(i + 11, j + 6, k + 8, ACBlocks.frostWaterIce);
		world.setBlock(i + 11, j + 6, k + 9, ACBlocks.frostWaterIce);
		world.setBlock(i + 11, j + 6, k + 10, ACBlocks.frostWaterIce);
		world.setBlock(i + 11, j + 6, k + 11, ACBlocks.frostWaterIce);
		world.setBlock(i + 11, j + 6, k + 12, ACBlocks.frostWaterIce);
		world.setBlock(i + 11, j + 6, k + 13, ACBlocks.frostWaterIce);
		world.setBlock(i + 11, j + 6, k + 14, ACBlocks.frostWaterIce);
		world.setBlock(i + 11, j + 6, k + 15, ACBlocks.frostWaterIce);
		world.setBlock(i + 11, j + 6, k + 16, ACBlocks.frostWaterIce);
		world.setBlock(i + 11, j + 6, k + 17, ACBlocks.frostWaterIce);
		world.setBlock(i + 11, j + 6, k + 18, ACBlocks.frostWaterIce);
		world.setBlock(i + 11, j + 6, k + 19, ACBlocks.frostWaterIce);
		world.setBlock(i + 11, j + 7, k + 3, ACBlocks.frostWaterIce);
		world.setBlock(i + 11, j + 7, k + 4, ACBlocks.frostWaterIce);
		world.setBlock(i + 11, j + 7, k + 5, ACBlocks.frostWaterIce);
		world.setBlock(i + 11, j + 7, k + 6, ACBlocks.frostWaterIce);
		world.setBlock(i + 11, j + 7, k + 7, ACBlocks.frostWaterIce);
		world.setBlock(i + 11, j + 7, k + 8, ACBlocks.frostWaterIce);
		world.setBlock(i + 11, j + 7, k + 9, ACBlocks.frostWaterIce);
		world.setBlock(i + 11, j + 7, k + 10, ACBlocks.frostWaterIce);
		world.setBlock(i + 11, j + 7, k + 11, ACBlocks.frostWaterIce);
		world.setBlock(i + 11, j + 7, k + 12, ACBlocks.frostWaterIce);
		world.setBlock(i + 11, j + 7, k + 13, ACBlocks.frostWaterIce);
		world.setBlock(i + 11, j + 7, k + 14, ACBlocks.frostWaterIce);
		world.setBlock(i + 11, j + 7, k + 15, ACBlocks.frostWaterIce);
		world.setBlock(i + 11, j + 7, k + 16, ACBlocks.frostWaterIce);
		world.setBlock(i + 11, j + 7, k + 17, ACBlocks.frostWaterIce);
		world.setBlock(i + 11, j + 7, k + 18, ACBlocks.frostWaterIce);
		world.setBlock(i + 11, j + 8, k + 3, ACBlocks.frostWaterIce);
		world.setBlock(i + 11, j + 8, k + 4, ACBlocks.frostWaterIce);
		world.setBlock(i + 11, j + 8, k + 5, ACBlocks.frostWaterIce);
		world.setBlock(i + 11, j + 8, k + 6, ACBlocks.frostWaterIce);
		world.setBlock(i + 11, j + 8, k + 7, ACBlocks.frostWaterIce);
		world.setBlock(i + 11, j + 8, k + 8, ACBlocks.frostWaterIce);
		world.setBlock(i + 11, j + 8, k + 9, ACBlocks.frostWaterIce);
		world.setBlock(i + 11, j + 8, k + 10, ACBlocks.frostWaterIce);
		world.setBlock(i + 11, j + 8, k + 11, ACBlocks.frostWaterIce);
		world.setBlock(i + 11, j + 8, k + 12, ACBlocks.frostWaterIce);
		world.setBlock(i + 11, j + 8, k + 13, ACBlocks.frostWaterIce);
		world.setBlock(i + 11, j + 8, k + 14, ACBlocks.frostWaterIce);
		world.setBlock(i + 11, j + 8, k + 15, ACBlocks.frostWaterIce);
		world.setBlock(i + 11, j + 8, k + 16, ACBlocks.frostWaterIce);
		world.setBlock(i + 11, j + 8, k + 17, ACBlocks.frostWaterIce);
		world.setBlock(i + 11, j + 8, k + 18, ACBlocks.frostWaterIce);
		world.setBlock(i + 11, j + 9, k + 5, ACBlocks.frostWaterIce);
		world.setBlock(i + 11, j + 9, k + 6, ACBlocks.frostWaterIce);
		world.setBlock(i + 11, j + 9, k + 7, ACBlocks.frostWaterIce);
		world.setBlock(i + 11, j + 9, k + 8, ACBlocks.frostWaterIce);
		world.setBlock(i + 11, j + 9, k + 9, ACBlocks.frostWaterIce);
		world.setBlock(i + 11, j + 9, k + 10, ACBlocks.frostWaterIce);
		world.setBlock(i + 11, j + 9, k + 11, ACBlocks.frostWaterIce);
		world.setBlock(i + 11, j + 9, k + 12, ACBlocks.frostWaterIce);
		world.setBlock(i + 11, j + 9, k + 13, ACBlocks.frostWaterIce);
		world.setBlock(i + 11, j + 9, k + 14, ACBlocks.frostWaterIce);
		world.setBlock(i + 11, j + 9, k + 15, ACBlocks.frostWaterIce);
		world.setBlock(i + 11, j + 9, k + 16, ACBlocks.frostWaterIce);
		world.setBlock(i + 11, j + 9, k + 17, ACBlocks.frostWaterIce);
		world.setBlock(i + 11, j + 9, k + 18, ACBlocks.frostWaterIce);
		world.setBlock(i + 11, j + 9, k + 19, ACBlocks.frostWaterIce);
		world.setBlock(i + 11, j + 10, k + 5, ACBlocks.frostWaterIce);
		world.setBlock(i + 11, j + 10, k + 6, ACBlocks.frostWaterIce);
		world.setBlock(i + 11, j + 10, k + 7, ACBlocks.frostWaterIce);
		world.setBlock(i + 11, j + 10, k + 8, ACBlocks.frostWaterIce);
		world.setBlock(i + 11, j + 10, k + 9, ACBlocks.frostWaterIce);
		world.setBlock(i + 11, j + 10, k + 10, ACBlocks.frostWaterIce);
		world.setBlock(i + 11, j + 10, k + 11, ACBlocks.frostWaterIce);
		world.setBlock(i + 11, j + 10, k + 12, ACBlocks.frostWaterIce);
		world.setBlock(i + 11, j + 10, k + 13, ACBlocks.frostWaterIce);
		world.setBlock(i + 11, j + 10, k + 14, ACBlocks.frostWaterIce);
		world.setBlock(i + 11, j + 10, k + 15, ACBlocks.frostWaterIce);
		world.setBlock(i + 11, j + 10, k + 16, ACBlocks.frostWaterIce);
		world.setBlock(i + 11, j + 10, k + 17, ACBlocks.frostWaterIce);
		world.setBlock(i + 11, j + 10, k + 18, ACBlocks.frostWaterIce);
		world.setBlock(i + 11, j + 10, k + 19, ACBlocks.frostWaterIce);
		world.setBlock(i + 11, j + 11, k + 5, ACBlocks.frostWaterIce);
		world.setBlock(i + 11, j + 11, k + 6, ACBlocks.frostWaterIce);
		world.setBlock(i + 11, j + 11, k + 7, ACBlocks.frostWaterIce);
		world.setBlock(i + 11, j + 11, k + 8, ACBlocks.frostWaterIce);
		world.setBlock(i + 11, j + 11, k + 9, ACBlocks.frostWaterIce);
		world.setBlock(i + 11, j + 11, k + 10, ACBlocks.frostWaterIce);
		world.setBlock(i + 11, j + 11, k + 11, ACBlocks.frostWaterIce);
		world.setBlock(i + 11, j + 11, k + 12, ACBlocks.frostWaterIce);
		world.setBlock(i + 11, j + 11, k + 13, ACBlocks.frostWaterIce);
		world.setBlock(i + 11, j + 11, k + 14, ACBlocks.frostWaterIce);
		world.setBlock(i + 11, j + 11, k + 15, ACBlocks.frostWaterIce);
		world.setBlock(i + 11, j + 11, k + 16, ACBlocks.frostWaterIce);
		world.setBlock(i + 11, j + 11, k + 17, ACBlocks.frostWaterIce);
		world.setBlock(i + 11, j + 11, k + 18, ACBlocks.frostWaterIce);
		world.setBlock(i + 11, j + 11, k + 19, ACBlocks.frostWaterIce);
		world.setBlock(i + 11, j + 12, k + 6, ACBlocks.frostWaterIce);
		world.setBlock(i + 11, j + 12, k + 7, ACBlocks.frostWaterIce);
		world.setBlock(i + 11, j + 12, k + 8, ACBlocks.frostWaterIce);
		world.setBlock(i + 11, j + 12, k + 9, ACBlocks.frostWaterIce);
		world.setBlock(i + 11, j + 12, k + 10, ACBlocks.frostWaterIce);
		world.setBlock(i + 11, j + 12, k + 11, ACBlocks.frostWaterIce);
		world.setBlock(i + 11, j + 12, k + 12, ACBlocks.frostWaterIce);
		world.setBlock(i + 11, j + 12, k + 13, ACBlocks.frostWaterIce);
		world.setBlock(i + 11, j + 12, k + 14, ACBlocks.frostWaterIce);
		world.setBlock(i + 11, j + 12, k + 15, ACBlocks.frostWaterIce);
		world.setBlock(i + 11, j + 12, k + 16, ACBlocks.frostWaterIce);
		world.setBlock(i + 11, j + 12, k + 17, ACBlocks.frostWaterIce);
		world.setBlock(i + 11, j + 12, k + 18, ACBlocks.frostWaterIce);
		world.setBlock(i + 11, j + 12, k + 19, ACBlocks.frostWaterIce);
		world.setBlock(i + 11, j + 13, k + 6, ACBlocks.frostWaterIce);
		world.setBlock(i + 11, j + 13, k + 7, ACBlocks.frostWaterIce);
		world.setBlock(i + 11, j + 13, k + 8, ACBlocks.frostWaterIce);
		world.setBlock(i + 11, j + 13, k + 9, ACBlocks.frostWaterIce);
		world.setBlock(i + 11, j + 13, k + 10, ACBlocks.frostWaterIce);
		world.setBlock(i + 11, j + 13, k + 11, ACBlocks.frostWaterIce);
		world.setBlock(i + 11, j + 13, k + 12, ACBlocks.frostWaterIce);
		world.setBlock(i + 11, j + 13, k + 13, ACBlocks.frostWaterIce);
		world.setBlock(i + 11, j + 13, k + 14, ACBlocks.frostWaterIce);
		world.setBlock(i + 11, j + 13, k + 15, ACBlocks.frostWaterIce);
		world.setBlock(i + 11, j + 13, k + 16, ACBlocks.frostWaterIce);
		world.setBlock(i + 11, j + 13, k + 17, ACBlocks.frostWaterIce);
		world.setBlock(i + 11, j + 13, k + 18, ACBlocks.frostWaterIce);
		world.setBlock(i + 11, j + 14, k + 8, ACBlocks.frostWaterIce);
		world.setBlock(i + 11, j + 14, k + 9, ACBlocks.frostWaterIce);
		world.setBlock(i + 11, j + 14, k + 10, ACBlocks.frostWaterIce);

		generate2(world, rand, i, j, k);
		return true;
	}

	public boolean generate2(World world, Random rand, int i, int j, int k) {
		world.setBlock(i + 11, j + 14, k + 11, ACBlocks.frostWaterIce);
		world.setBlock(i + 11, j + 14, k + 12, ACBlocks.frostWaterIce);
		world.setBlock(i + 11, j + 14, k + 13, ACBlocks.frostWaterIce);
		world.setBlock(i + 11, j + 14, k + 14, ACBlocks.frostWaterIce);
		world.setBlock(i + 11, j + 14, k + 15, ACBlocks.frostWaterIce);
		world.setBlock(i + 11, j + 14, k + 16, ACBlocks.frostWaterIce);
		world.setBlock(i + 11, j + 14, k + 17, ACBlocks.frostWaterIce);
		world.setBlock(i + 11, j + 14, k + 18, ACBlocks.frostWaterIce);
		world.setBlock(i + 11, j + 15, k + 13, ACBlocks.frostWaterIce);
		world.setBlock(i + 11, j + 15, k + 14, ACBlocks.frostWaterIce);
		world.setBlock(i + 11, j + 15, k + 15, ACBlocks.frostWaterIce);
		world.setBlock(i + 11, j + 15, k + 16, ACBlocks.frostWaterIce);
		world.setBlock(i + 12, j + 0, k + 1, ACBlocks.frostWaterIce);
		world.setBlock(i + 12, j + 0, k + 2, ACBlocks.frostWaterIce);
		world.setBlock(i + 12, j + 0, k + 3, ACBlocks.frostWaterIce);
		world.setBlock(i + 12, j + 0, k + 4, ACBlocks.frostWaterIce);
		world.setBlock(i + 12, j + 0, k + 5, ACBlocks.frostWaterIce);
		world.setBlock(i + 12, j + 0, k + 6, ACBlocks.frostWaterIce);
		world.setBlock(i + 12, j + 0, k + 7, ACBlocks.frostWaterIce);
		world.setBlock(i + 12, j + 0, k + 8, ACBlocks.frostWaterIce);
		world.setBlock(i + 12, j + 0, k + 9, ACBlocks.frostWaterIce);
		world.setBlock(i + 12, j + 0, k + 10, ACBlocks.frostWaterIce);
		world.setBlock(i + 12, j + 0, k + 11, ACBlocks.frostWaterIce);
		world.setBlock(i + 12, j + 0, k + 12, ACBlocks.frostWaterIce);
		world.setBlock(i + 12, j + 0, k + 13, ACBlocks.frostWaterIce);
		world.setBlock(i + 12, j + 0, k + 14, ACBlocks.frostWaterIce);
		world.setBlock(i + 12, j + 0, k + 15, ACBlocks.frostWaterIce);
		world.setBlock(i + 12, j + 0, k + 16, ACBlocks.frostWaterIce);
		world.setBlock(i + 12, j + 0, k + 17, ACBlocks.frostWaterIce);
		world.setBlock(i + 12, j + 0, k + 18, ACBlocks.frostWaterIce);
		world.setBlock(i + 12, j + 0, k + 19, ACBlocks.frostWaterIce);
