package net.arcticraft.world.gen;

import java.util.Random;

import net.minecraft.block.Block;
import net.minecraft.init.Blocks;
import net.minecraft.world.World;
import net.minecraft.world.gen.feature.WorldGenerator;

public class WorldGenShip extends WorldGenerator
{
	private static final int MIN_SHIP_DISTANCE = 600; // Minimal distance between two ships
	private static final int SIZE_X = 16; // Ship Base
	private static final int SIZE_Y = 32;
	private static final int SIZE_Z = 64;
	private static final int PLATFORM_AREA = SIZE_X * SIZE_Z; //Ship Base
	private static final int VOLUME = SIZE_X * SIZE_Y * SIZE_Z; //Volume of the ship

	public WorldGenShip()
	{}
	

	public void setBlock(World world, int x, int y, int z, Block block, int metadata)
	{
		Block b1 = world.getBlock(x, y, z);

		world.setBlock(x, y, z, block, metadata, 2);
	}

	@Override
	public boolean generate(World world, Random rand, int i, int j, int k) {
		System.out.println(i + ", " + j + ", " + k);
		
		this.setBlock(world, i + 14, j + 13, k + 30, Blocks.wool, 3);
		this.setBlock(world, i + 14, j + 22, k + 31, Blocks.wool, 7);
		this.setBlock(world, i + 14, j + 23, k + 30, Blocks.wool, 8);
		this.setBlock(world, i + 14, j + 24, k + 28, Blocks.log, 1);
		this.setBlock(world, i + 14, j + 24, k + 29, Blocks.wool, 7);
		this.setBlock(world, i + 14, j + 25, k + 28, Blocks.wooden_slab, 1);
		this.setBlock(world, i + 15, j + 13, k + 29, Blocks.log, 1);
		this.setBlock(world, i + 15, j + 13, k + 30, Blocks.wool, 8);
		this.setBlock(world, i + 15, j + 14, k + 29, Blocks.wooden_slab, 1);
		this.setBlock(world, i + 15, j + 14, k + 31, Blocks.wool, 8);
		this.setBlock(world, i + 15, j + 14, k + 43, Blocks.log, 1);
		this.setBlock(world, i + 15, j + 14, k + 44, Blocks.wool, 8);
		this.setBlock(world, i + 15, j + 15, k + 32, Blocks.wool, 7);
		this.setBlock(world, i + 15, j + 15, k + 43, Blocks.wooden_slab, 1);
		this.setBlock(world, i + 15, j + 15, k + 45, Blocks.wool, 3);
		this.setBlock(world, i + 15, j + 16, k + 32, Blocks.wool, 8);
		this.setBlock(world, i + 15, j + 16, k + 33, Blocks.wool, 3);
		this.setBlock(world, i + 15, j + 16, k + 45, Blocks.wool, 7);
		this.setBlock(world, i + 15, j + 17, k + 33, Blocks.wool, 8);
		this.setBlock(world, i + 15, j + 21, k + 32, Blocks.wool, 8);
		this.setBlock(world, i + 15, j + 22, k + 31, Blocks.wool, 8);
		this.setBlock(world, i + 15, j + 23, k + 30, Blocks.wool, 3);
		this.setBlock(world, i + 15, j + 24, k + 28, Blocks.log, 1);
		this.setBlock(world, i + 15, j + 24, k + 29, Blocks.wool, 8);
		this.setBlock(world, i + 15, j + 25, k + 28, Blocks.wooden_slab, 1);
		this.setBlock(world, i + 15, j + 26, k + 29, Blocks.wool, 7);
		this.setBlock(world, i + 15, j + 27, k + 30, Blocks.wool, 3);
		this.setBlock(world, i + 15, j + 28, k + 31, Blocks.wool, 7);
		this.setBlock(world, i + 15, j + 31, k + 30, Blocks.wool, 8);
		this.setBlock(world, i + 16, j + 13, k + 29, Blocks.log, 1);
		this.setBlock(world, i + 16, j + 14, k + 29, Blocks.wooden_slab, 1);
		this.setBlock(world, i + 16, j + 14, k + 31, Blocks.wool, 8);
		this.setBlock(world, i + 16, j + 14, k + 43, Blocks.log, 1);
		this.setBlock(world, i + 16, j + 14, k + 44, Blocks.wool, 3);
		this.setBlock(world, i + 16, j + 15, k + 32, Blocks.wool, 3);
		this.setBlock(world, i + 16, j + 15, k + 43, Blocks.wooden_slab, 1);
		this.setBlock(world, i + 16, j + 15, k + 44, Blocks.wool, 3);
		this.setBlock(world, i + 16, j + 15, k + 45, Blocks.wool, 8);
		this.setBlock(world, i + 16, j + 16, k + 32, Blocks.wool, 8);
		this.setBlock(world, i + 16, j + 16, k + 33, Blocks.wool, 7);
		this.setBlock(world, i + 16, j + 16, k + 45, Blocks.wool, 3);
		this.setBlock(world, i + 16, j + 17, k + 33, Blocks.wool, 8);
		this.setBlock(world, i + 16, j + 17, k + 46, Blocks.wool, 3);
		this.setBlock(world, i + 16, j + 18, k + 33, Blocks.wool, 8);
		this.setBlock(world, i + 16, j + 18, k + 46, Blocks.wool, 8);
		this.setBlock(world, i + 16, j + 19, k + 33, Blocks.wool, 8);
		this.setBlock(world, i + 16, j + 19, k + 46, Blocks.wool, 8);
		this.setBlock(world, i + 16, j + 20, k + 32, Blocks.wool, 8);
		this.setBlock(world, i + 16, j + 21, k + 32, Blocks.wool, 7);
		this.setBlock(world, i + 16, j + 22, k + 31, Blocks.wool, 8);
		this.setBlock(world, i + 16, j + 23, k + 30, Blocks.wool, 3);
		this.setBlock(world, i + 16, j + 24, k + 28, Blocks.log, 1);
		this.setBlock(world, i + 16, j + 24, k + 29, Blocks.wool, 8);
		this.setBlock(world, i + 16, j + 25, k + 28, Blocks.wooden_slab, 1);
		this.setBlock(world, i + 16, j + 26, k + 29, Blocks.wool, 8);
		this.setBlock(world, i + 16, j + 27, k + 30, Blocks.wool, 8);
		this.setBlock(world, i + 16, j + 28, k + 31, Blocks.wool, 7);
		this.setBlock(world, i + 16, j + 29, k + 31, Blocks.wool, 7);
		this.setBlock(world, i + 16, j + 30, k + 31, Blocks.wool, 8);
		this.setBlock(world, i + 16, j + 31, k + 30, Blocks.wool, 7);
		this.setBlock(world, i + 16, j + 32, k + 29, Blocks.wool, 7);
		this.setBlock(world, i + 17, j + 4, k + 18, Blocks.planks, 1);
		this.setBlock(world, i + 17, j + 4, k + 19, Blocks.planks, 1);
		this.setBlock(world, i + 17, j + 4, k + 20, Blocks.planks, 1);
		this.setBlock(world, i + 17, j + 4, k + 21, Blocks.planks, 1);
		this.setBlock(world, i + 17, j + 4, k + 22, Blocks.planks, 1);
		this.setBlock(world, i + 17, j + 4, k + 23, Blocks.planks, 1);
		this.setBlock(world, i + 17, j + 4, k + 24, Blocks.planks, 1);
		this.setBlock(world, i + 17, j + 4, k + 25, Blocks.planks, 1);
		this.setBlock(world, i + 17, j + 4, k + 26, Blocks.planks, 1);
		this.setBlock(world, i + 17, j + 4, k + 27, Blocks.planks, 1);
		this.setBlock(world, i + 17, j + 4, k + 28, Blocks.planks, 1);
		this.setBlock(world, i + 17, j + 4, k + 29, Blocks.planks, 1);
		this.setBlock(world, i + 17, j + 4, k + 30, Blocks.planks, 1);
		this.setBlock(world, i + 17, j + 4, k + 31, Blocks.planks, 1);
		this.setBlock(world, i + 17, j + 4, k + 32, Blocks.planks, 1);
		this.setBlock(world, i + 17, j + 4, k + 33, Blocks.planks, 1);
		this.setBlock(world, i + 17, j + 4, k + 34, Blocks.planks, 1);
		this.setBlock(world, i + 17, j + 4, k + 35, Blocks.planks, 1);
		this.setBlock(world, i + 17, j + 4, k + 36, Blocks.planks, 1);
		this.setBlock(world, i + 17, j + 4, k + 37, Blocks.planks, 1);
		this.setBlock(world, i + 17, j + 4, k + 38, Blocks.planks, 1);
		this.setBlock(world, i + 17, j + 4, k + 39, Blocks.planks, 1);
		this.setBlock(world, i + 17, j + 4, k + 40, Blocks.planks, 1);
		this.setBlock(world, i + 17, j + 5, k + 17, Blocks.planks, 1);
		this.setBlock(world, i + 17, j + 5, k + 18, Blocks.planks, 1);
		this.setBlock(world, i + 17, j + 5, k + 19, Blocks.planks, 1);
		this.setBlock(world, i + 17, j + 5, k + 20, Blocks.planks, 1);
		this.setBlock(world, i + 17, j + 5, k + 21, Blocks.planks, 1);
		this.setBlock(world, i + 17, j + 5, k + 23, Blocks.planks, 1);
		this.setBlock(world, i + 17, j + 5, k + 24, Blocks.planks, 1);
		this.setBlock(world, i + 17, j + 5, k + 26, Blocks.planks, 1);
		this.setBlock(world, i + 17, j + 5, k + 27, Blocks.planks, 1);
		this.setBlock(world, i + 17, j + 5, k + 29, Blocks.planks, 1);
		this.setBlock(world, i + 17, j + 5, k + 30, Blocks.planks, 1);
		this.setBlock(world, i + 17, j + 5, k + 32, Blocks.planks, 1);
		this.setBlock(world, i + 17, j + 5, k + 33, Blocks.planks, 1);
		this.setBlock(world, i + 17, j + 5, k + 35, Blocks.planks, 1);
		this.setBlock(world, i + 17, j + 5, k + 36, Blocks.planks, 1);
		this.setBlock(world, i + 17, j + 5, k + 38, Blocks.planks, 1);
		this.setBlock(world, i + 17, j + 5, k + 39, Blocks.planks, 1);
		this.setBlock(world, i + 17, j + 5, k + 40, Blocks.planks, 1);
		this.setBlock(world, i + 17, j + 5, k + 41, Blocks.planks, 1);
		this.setBlock(world, i + 17, j + 5, k + 42, Blocks.planks, 1);
		this.setBlock(world, i + 17, j + 6, k + 17, Blocks.log, 1);
		this.setBlock(world, i + 17, j + 6, k + 18, Blocks.log, 1);
		this.setBlock(world, i + 17, j + 6, k + 19, Blocks.log, 1);
		this.setBlock(world, i + 17, j + 6, k + 20, Blocks.log, 1);
		this.setBlock(world, i + 17, j + 6, k + 21, Blocks.log, 1);
		this.setBlock(world, i + 17, j + 6, k + 22, Blocks.log, 1);
		this.setBlock(world, i + 17, j + 6, k + 23, Blocks.log, 1);
		this.setBlock(world, i + 17, j + 6, k + 24, Blocks.log, 1);
		this.setBlock(world, i + 17, j + 6, k + 25, Blocks.log, 1);
		this.setBlock(world, i + 17, j + 6, k + 26, Blocks.log, 1);
		this.setBlock(world, i + 17, j + 6, k + 27, Blocks.log, 1);
		this.setBlock(world, i + 17, j + 6, k + 28, Blocks.log, 1);
		this.setBlock(world, i + 17, j + 6, k + 29, Blocks.log, 1);
		this.setBlock(world, i + 17, j + 6, k + 30, Blocks.log, 1);
		this.setBlock(world, i + 17, j + 6, k + 31, Blocks.log, 1);
		this.setBlock(world, i + 17, j + 6, k + 32, Blocks.log, 1);
		this.setBlock(world, i + 17, j + 6, k + 33, Blocks.log, 1);
		this.setBlock(world, i + 17, j + 6, k + 34, Blocks.log, 1);
		this.setBlock(world, i + 17, j + 6, k + 35, Blocks.log, 1);
		this.setBlock(world, i + 17, j + 6, k + 36, Blocks.log, 1);
		this.setBlock(world, i + 17, j + 6, k + 37, Blocks.log, 1);
		this.setBlock(world, i + 17, j + 6, k + 38, Blocks.log, 1);
		this.setBlock(world, i + 17, j + 6, k + 39, Blocks.log, 1);
		this.setBlock(world, i + 17, j + 6, k + 40, Blocks.log, 1);
		this.setBlock(world, i + 17, j + 6, k + 41, Blocks.log, 1);
		this.setBlock(world, i + 17, j + 6, k + 42, Blocks.log, 1);
		this.setBlock(world, i + 17, j + 6, k + 43, Blocks.log, 1);
		this.setBlock(world, i + 17, j + 7, k + 16, Blocks.log, 1);
		this.setBlock(world, i + 17, j + 7, k + 17, Blocks.log, 1);
		this.setBlock(world, i + 17, j + 7, k + 18, Blocks.log, 1);
		this.setBlock(world, i + 17, j + 7, k + 19, Blocks.log, 1);
		this.setBlock(world, i + 17, j + 7, k + 20, Blocks.log, 1);
		this.setBlock(world, i + 17, j + 7, k + 21, Blocks.log, 1);
		this.setBlock(world, i + 17, j + 7, k + 22, Blocks.log, 1);
		this.setBlock(world, i + 17, j + 7, k + 23, Blocks.log, 1);
		this.setBlock(world, i + 17, j + 7, k + 24, Blocks.log, 1);
		this.setBlock(world, i + 17, j + 7, k + 25, Blocks.planks, 1);
		this.setBlock(world, i + 17, j + 7, k + 26, Blocks.planks, 1);
		this.setBlock(world, i + 17, j + 7, k + 27, Blocks.planks, 1);
		this.setBlock(world, i + 17, j + 7, k + 28, Blocks.planks, 1);
		this.setBlock(world, i + 17, j + 7, k + 29, Blocks.planks, 1);
		this.setBlock(world, i + 17, j + 7, k + 30, Blocks.planks, 1);
		this.setBlock(world, i + 17, j + 7, k + 31, Blocks.planks, 1);
		this.setBlock(world, i + 17, j + 7, k + 32, Blocks.planks, 1);
		this.setBlock(world, i + 17, j + 7, k + 33, Blocks.planks, 1);
		this.setBlock(world, i + 17, j + 7, k + 34, Blocks.planks, 1);
		this.setBlock(world, i + 17, j + 7, k + 35, Blocks.planks, 1);
		this.setBlock(world, i + 17, j + 7, k + 36, Blocks.log, 1);
		this.setBlock(world, i + 17, j + 7, k + 37, Blocks.log, 1);
		this.setBlock(world, i + 17, j + 7, k + 38, Blocks.log, 1);
		this.setBlock(world, i + 17, j + 7, k + 39, Blocks.log, 1);
		this.setBlock(world, i + 17, j + 7, k + 40, Blocks.log, 1);
		this.setBlock(world, i + 17, j + 7, k + 41, Blocks.log, 1);
		this.setBlock(world, i + 17, j + 7, k + 42, Blocks.log, 1);
		this.setBlock(world, i + 17, j + 7, k + 43, Blocks.log, 1);
		this.setBlock(world, i + 17, j + 7, k + 44, Blocks.log, 1);
		this.setBlock(world, i + 17, j + 8, k + 16, Blocks.planks, 1);
		this.setBlock(world, i + 17, j + 8, k + 17, Blocks.planks, 1);
		this.setBlock(world, i + 17, j + 8, k + 18, Blocks.air, 8);
		this.setBlock(world, i + 17, j + 8, k + 19, Blocks.air, 8);
		this.setBlock(world, i + 17, j + 8, k + 20, Blocks.planks, 1);
		this.setBlock(world, i + 17, j + 8, k + 21, Blocks.planks, 1);
		this.setBlock(world, i + 17, j + 8, k + 22, Blocks.planks, 1);
		this.setBlock(world, i + 17, j + 8, k + 23, Blocks.planks, 1);
		this.setBlock(world, i + 17, j + 8, k + 24, Blocks.planks, 1);
		this.setBlock(world, i + 17, j + 8, k + 25, Blocks.fence, 0);
		this.setBlock(world, i + 17, j + 8, k + 26, Blocks.fence, 0);
		this.setBlock(world, i + 17, j + 8, k + 27, Blocks.fence, 0);
		this.setBlock(world, i + 17, j + 8, k + 28, Blocks.fence, 0);
		this.setBlock(world, i + 17, j + 8, k + 29, Blocks.fence, 0);
		this.setBlock(world, i + 17, j + 8, k + 30, Blocks.fence, 0);
		this.setBlock(world, i + 17, j + 8, k + 31, Blocks.fence, 0);
		this.setBlock(world, i + 17, j + 8, k + 32, Blocks.fence, 0);
		this.setBlock(world, i + 17, j + 8, k + 33, Blocks.fence, 0);
		this.setBlock(world, i + 17, j + 8, k + 34, Blocks.fence, 0);
		this.setBlock(world, i + 17, j + 8, k + 35, Blocks.fence, 0);
		this.setBlock(world, i + 17, j + 8, k + 36, Blocks.fence, 0);
		this.setBlock(world, i + 17, j + 8, k + 37, Blocks.planks, 1);
		this.setBlock(world, i + 17, j + 8, k + 38, Blocks.planks, 1);
		this.setBlock(world, i + 17, j + 8, k + 39, Blocks.planks, 1);
		this.setBlock(world, i + 17, j + 8, k + 40, Blocks.planks, 1);
		this.setBlock(world, i + 17, j + 8, k + 41, Blocks.planks, 1);
		this.setBlock(world, i + 17, j + 8, k + 42, Blocks.planks, 1);
		this.setBlock(world, i + 17, j + 8, k + 43, Blocks.planks, 1);
		this.setBlock(world, i + 17, j + 8, k + 44, Blocks.planks, 1);
		this.setBlock(world, i + 17, j + 9, k + 16, Blocks.log, 1);
		this.setBlock(world, i + 17, j + 9, k + 17, Blocks.log, 1);
		this.setBlock(world, i + 17, j + 9, k + 18, Blocks.log, 1);
		this.setBlock(world, i + 17, j + 9, k + 19, Blocks.log, 1);
		this.setBlock(world, i + 17, j + 9, k + 20, Blocks.log, 1);
		this.setBlock(world, i + 17, j + 9, k + 21, Blocks.log, 1);
		this.setBlock(world, i + 17, j + 9, k + 22, Blocks.log, 1);
		this.setBlock(world, i + 17, j + 9, k + 23, Blocks.log, 1);
		this.setBlock(world, i + 17, j + 9, k + 24, Blocks.fence, 0);
		this.setBlock(world, i + 17, j + 9, k + 37, Blocks.fence, 0);
		this.setBlock(world, i + 17, j + 9, k + 38, Blocks.log, 1);
		this.setBlock(world, i + 17, j + 9, k + 39, Blocks.log, 1);
		this.setBlock(world, i + 17, j + 9, k + 40, Blocks.log, 1);
		this.setBlock(world, i + 17, j + 9, k + 41, Blocks.log, 1);
		this.setBlock(world, i + 17, j + 9, k + 42, Blocks.log, 1);
		this.setBlock(world, i + 17, j + 9, k + 43, Blocks.log, 1);
		this.setBlock(world, i + 17, j + 10, k + 16, Blocks.log, 1);
		this.setBlock(world, i + 17, j + 10, k + 17, Blocks.log, 1);
		this.setBlock(world, i + 17, j + 10, k + 18, Blocks.log, 1);
		this.setBlock(world, i + 17, j + 10, k + 19, Blocks.log, 1);
		this.setBlock(world, i + 17, j + 10, k + 20, Blocks.log, 1);
		this.setBlock(world, i + 17, j + 10, k + 21, Blocks.log, 1);
		this.setBlock(world, i + 17, j + 10, k + 22, Blocks.log, 1);
		this.setBlock(world, i + 17, j + 10, k + 23, Blocks.fence, 0);
		this.setBlock(world, i + 17, j + 10, k + 38, Blocks.fence, 0);
		this.setBlock(world, i + 17, j + 10, k + 39, Blocks.log, 1);
		this.setBlock(world, i + 17, j + 10, k + 40, Blocks.log, 1);
		this.setBlock(world, i + 17, j + 10, k + 41, Blocks.log, 1);
		this.setBlock(world, i + 17, j + 10, k + 42, Blocks.log, 1);
		this.setBlock(world, i + 17, j + 10, k + 43, Blocks.wooden_slab, 1);
		this.setBlock(world, i + 17, j + 11, k + 16, Blocks.fence, 0);
		this.setBlock(world, i + 17, j + 11, k + 17, Blocks.fence, 0);
		this.setBlock(world, i + 17, j + 11, k + 18, Blocks.fence, 0);
		this.setBlock(world, i + 17, j + 11, k + 19, Blocks.fence, 0);
		this.setBlock(world, i + 17, j + 11, k + 20, Blocks.fence, 0);
		this.setBlock(world, i + 17, j + 11, k + 21, Blocks.fence, 0);
		this.setBlock(world, i + 17, j + 11, k + 22, Blocks.fence, 0);
		this.setBlock(world, i + 17, j + 11, k + 39, Blocks.fence, 0);
		this.setBlock(world, i + 17, j + 11, k + 40, Blocks.fence, 0);
		this.setBlock(world, i + 17, j + 11, k + 41, Blocks.fence, 0);
		this.setBlock(world, i + 17, j + 11, k + 42, Blocks.fence, 0);
		this.setBlock(world, i + 17, j + 13, k + 28, Blocks.log, 1);
		this.setBlock(world, i + 17, j + 14, k + 28, Blocks.wooden_slab, 1);
		this.setBlock(world, i + 17, j + 14, k + 31, Blocks.wool, 8);
		this.setBlock(world, i + 17, j + 14, k + 42, Blocks.log, 1);
		this.setBlock(world, i + 17, j + 14, k + 44, Blocks.wool, 7);
		this.setBlock(world, i + 17, j + 15, k + 32, Blocks.wool, 7);
		this.setBlock(world, i + 17, j + 15, k + 42, Blocks.wooden_slab, 1);
		this.setBlock(world, i + 17, j + 15, k + 45, Blocks.wool, 7);
		this.setBlock(world, i + 17, j + 16, k + 33, Blocks.wool, 8);
		this.setBlock(world, i + 17, j + 16, k + 46, Blocks.wool, 3);
		this.setBlock(world, i + 17, j + 17, k + 33, Blocks.wool, 3);
		this.setBlock(world, i + 17, j + 17, k + 46, Blocks.wool, 8);
		this.setBlock(world, i + 17, j + 18, k + 33, Blocks.wool, 7);
		this.setBlock(world, i + 17, j + 18, k + 46, Blocks.wool, 7);
		this.setBlock(world, i + 17, j + 19, k + 33, Blocks.wool, 8);
		this.setBlock(world, i + 17, j + 19, k + 46, Blocks.wool, 3);
		this.setBlock(world, i + 17, j + 20, k + 32, Blocks.wool, 8);
		this.setBlock(world, i + 17, j + 20, k + 45, Blocks.wool, 3);
		this.setBlock(world, i + 17, j + 20, k + 46, Blocks.wool, 3);
		this.setBlock(world, i + 17, j + 21, k + 32, Blocks.wool, 3);
		this.setBlock(world, i + 17, j + 21, k + 45, Blocks.wool, 3);
		this.setBlock(world, i + 17, j + 22, k + 31, Blocks.wool, 7);
		this.setBlock(world, i + 17, j + 22, k + 44, Blocks.wool, 8);
		this.setBlock(world, i + 17, j + 23, k + 30, Blocks.wool, 8);
		this.setBlock(world, i + 17, j + 23, k + 43, Blocks.wool, 7);
		this.setBlock(world, i + 17, j + 24, k + 28, Blocks.log, 1);
		this.setBlock(world, i + 17, j + 24, k + 29, Blocks.wool, 8);
		this.setBlock(world, i + 17, j + 24, k + 42, Blocks.log, 1);
		this.setBlock(world, i + 17, j + 24, k + 43, Blocks.wool, 8);
		this.setBlock(world, i + 17, j + 25, k + 28, Blocks.wooden_slab, 1);
		this.setBlock(world, i + 17, j + 25, k + 42, Blocks.wooden_slab, 1);
		this.setBlock(world, i + 17, j + 26, k + 29, Blocks.wool, 8);
		this.setBlock(world, i + 17, j + 27, k + 30, Blocks.wool, 7);
		this.setBlock(world, i + 17, j + 28, k + 31, Blocks.wool, 3);
		this.setBlock(world, i + 17, j + 29, k + 31, Blocks.wool, 3);
		this.setBlock(world, i + 17, j + 30, k + 31, Blocks.wool, 3);
		this.setBlock(world, i + 17, j + 31, k + 30, Blocks.wool, 8);
		this.setBlock(world, i + 17, j + 32, k + 29, Blocks.wool, 3);
		this.setBlock(world, i + 18, j + 3, k + 17, Blocks.planks, 1);
		this.setBlock(world, i + 18, j + 3, k + 18, Blocks.planks, 1);
		this.setBlock(world, i + 18, j + 3, k + 19, Blocks.planks, 1);
		this.setBlock(world, i + 18, j + 3, k + 20, Blocks.planks, 1);
		this.setBlock(world, i + 18, j + 3, k + 21, Blocks.planks, 1);
		this.setBlock(world, i + 18, j + 3, k + 22, Blocks.planks, 1);
		this.setBlock(world, i + 18, j + 3, k + 23, Blocks.planks, 1);
		this.setBlock(world, i + 18, j + 3, k + 24, Blocks.planks, 1);
		this.setBlock(world, i + 18, j + 3, k + 25, Blocks.planks, 1);
		this.setBlock(world, i + 18, j + 3, k + 26, Blocks.planks, 1);
		this.setBlock(world, i + 18, j + 3, k + 27, Blocks.planks, 1);
		this.setBlock(world, i + 18, j + 3, k + 28, Blocks.planks, 1);
		this.setBlock(world, i + 18, j + 3, k + 29, Blocks.planks, 1);
		this.setBlock(world, i + 18, j + 3, k + 30, Blocks.planks, 1);
		this.setBlock(world, i + 18, j + 3, k + 31, Blocks.planks, 1);
		this.setBlock(world, i + 18, j + 3, k + 32, Blocks.planks, 1);
		this.setBlock(world, i + 18, j + 3, k + 33, Blocks.planks, 1);
		this.setBlock(world, i + 18, j + 3, k + 34, Blocks.planks, 1);
		this.setBlock(world, i + 18, j + 3, k + 35, Blocks.planks, 1);
		this.setBlock(world, i + 18, j + 3, k + 36, Blocks.planks, 1);
		this.setBlock(world, i + 18, j + 3, k + 37, Blocks.planks, 1);
		this.setBlock(world, i + 18, j + 3, k + 38, Blocks.planks, 1);
		this.setBlock(world, i + 18, j + 3, k + 39, Blocks.planks, 1);
		this.setBlock(world, i + 18, j + 3, k + 40, Blocks.planks, 1);
		this.setBlock(world, i + 18, j + 3, k + 41, Blocks.planks, 1);
		this.setBlock(world, i + 18, j + 3, k + 42, Blocks.planks, 1);
		this.setBlock(world, i + 18, j + 4, k + 16, Blocks.planks, 1);
		this.setBlock(world, i + 18, j + 4, k + 17, Blocks.planks, 1);
		this.setBlock(world, i + 18, j + 4, k + 18, Blocks.wooden_slab, 0);
		this.setBlock(world, i + 18, j + 4, k + 19, Blocks.wooden_slab, 0);
		this.setBlock(world, i + 18, j + 4, k + 20, Blocks.wooden_slab, 0);
		this.setBlock(world, i + 18, j + 4, k + 21, Blocks.wooden_slab, 0);
		this.setBlock(world, i + 18, j + 4, k + 22, Blocks.dispenser, 4);
		this.setBlock(world, i + 18, j + 4, k + 23, Blocks.wooden_slab, 0);
		this.setBlock(world, i + 18, j + 4, k + 24, Blocks.wooden_slab, 0);
		this.setBlock(world, i + 18, j + 4, k + 25, Blocks.dispenser, 4);
		this.setBlock(world, i + 18, j + 4, k + 26, Blocks.wooden_slab, 0);
		this.setBlock(world, i + 18, j + 4, k + 27, Blocks.wooden_slab, 0);
		this.setBlock(world, i + 18, j + 4, k + 28, Blocks.dispenser, 4);
		this.setBlock(world, i + 18, j + 4, k + 29, Blocks.wooden_slab, 0);
		this.setBlock(world, i + 18, j + 4, k + 30, Blocks.wooden_slab, 0);
		this.setBlock(world, i + 18, j + 4, k + 31, Blocks.dispenser, 4);
		this.setBlock(world, i + 18, j + 4, k + 32, Blocks.wooden_slab, 0);
		this.setBlock(world, i + 18, j + 4, k + 33, Blocks.wooden_slab, 0);
		this.setBlock(world, i + 18, j + 4, k + 34, Blocks.dispenser, 4);
		this.setBlock(world, i + 18, j + 4, k + 35, Blocks.wooden_slab, 0);
		this.setBlock(world, i + 18, j + 4, k + 36, Blocks.wooden_slab, 0);
		this.setBlock(world, i + 18, j + 4, k + 37, Blocks.dispenser, 4);
		this.setBlock(world, i + 18, j + 4, k + 38, Blocks.wooden_slab, 0);
		this.setBlock(world, i + 18, j + 4, k + 39, Blocks.wooden_slab, 0);
		this.setBlock(world, i + 18, j + 4, k + 40, Blocks.wooden_slab, 0);
		this.setBlock(world, i + 18, j + 4, k + 41, Blocks.planks, 1);
		this.setBlock(world, i + 18, j + 4, k + 42, Blocks.planks, 1);
		this.setBlock(world, i + 18, j + 4, k + 43, Blocks.planks, 1);
		this.setBlock(world, i + 18, j + 5, k + 15, Blocks.planks, 1);
		this.setBlock(world, i + 18, j + 5, k + 16, Blocks.planks, 1);
		this.setBlock(world, i + 18, j + 5, k + 17, Blocks.wooden_slab, 0);
		this.setBlock(world, i + 18, j + 5, k + 43, Blocks.planks, 1);
		this.setBlock(world, i + 18, j + 5, k + 44, Blocks.planks, 1);
		this.setBlock(world, i + 18, j + 6, k + 14, Blocks.log, 1);
		this.setBlock(world, i + 18, j + 6, k + 15, Blocks.log, 1);
		this.setBlock(world, i + 18, j + 6, k + 16, Blocks.log, 1);
		this.setBlock(world, i + 18, j + 6, k + 17, Blocks.planks, 1);
		this.setBlock(world, i + 18, j + 6, k + 18, Blocks.planks, 1);
		this.setBlock(world, i + 18, j + 6, k + 19, Blocks.planks, 1);
		this.setBlock(world, i + 18, j + 6, k + 20, Blocks.planks, 1);
		this.setBlock(world, i + 18, j + 6, k + 21, Blocks.planks, 1);
		this.setBlock(world, i + 18, j + 6, k + 22, Blocks.planks, 1);
		this.setBlock(world, i + 18, j + 6, k + 23, Blocks.planks, 1);
		this.setBlock(world, i + 18, j + 6, k + 24, Blocks.planks, 1);
		this.setBlock(world, i + 18, j + 6, k + 25, Blocks.planks, 1);
		this.setBlock(world, i + 18, j + 6, k + 26, Blocks.planks, 1);
		this.setBlock(world, i + 18, j + 6, k + 27, Blocks.planks, 1);
		this.setBlock(world, i + 18, j + 6, k + 28, Blocks.planks, 1);
		this.setBlock(world, i + 18, j + 6, k + 29, Blocks.planks, 1);
		this.setBlock(world, i + 18, j + 6, k + 30, Blocks.planks, 1);
		this.setBlock(world, i + 18, j + 6, k + 31, Blocks.planks, 1);
		this.setBlock(world, i + 18, j + 6, k + 32, Blocks.planks, 1);
		this.setBlock(world, i + 18, j + 6, k + 33, Blocks.planks, 1);
		this.setBlock(world, i + 18, j + 6, k + 34, Blocks.planks, 1);
		this.setBlock(world, i + 18, j + 6, k + 35, Blocks.planks, 1);
		this.setBlock(world, i + 18, j + 6, k + 36, Blocks.planks, 1);
		this.setBlock(world, i + 18, j + 6, k + 37, Blocks.planks, 1);
		this.setBlock(world, i + 18, j + 6, k + 38, Blocks.planks, 1);
		this.setBlock(world, i + 18, j + 6, k + 39, Blocks.planks, 1);
		this.setBlock(world, i + 18, j + 6, k + 40, Blocks.planks, 1);
		this.setBlock(world, i + 18, j + 6, k + 41, Blocks.planks, 1);
		this.setBlock(world, i + 18, j + 6, k + 42, Blocks.planks, 1);
		this.setBlock(world, i + 18, j + 6, k + 43, Blocks.log, 1);
		this.setBlock(world, i + 18, j + 6, k + 44, Blocks.log, 1);
		this.setBlock(world, i + 18, j + 7, k + 14, Blocks.log, 1);
		this.setBlock(world, i + 18, j + 7, k + 15, Blocks.log, 1);
		this.setBlock(world, i + 18, j + 7, k + 16, Blocks.double_wooden_slab, 0);
		this.setBlock(world, i + 18, j + 7, k + 17, Blocks.wooden_slab, 0);
		this.setBlock(world, i + 18, j + 7, k + 18, Blocks.fence, 0);
		this.setBlock(world, i + 18, j + 7, k + 19, Blocks.fence, 0);
		this.setBlock(world, i + 18, j + 7, k + 20, Blocks.air, 5);
		this.setBlock(world, i + 18, j + 7, k + 21, Blocks.air, 5);
		this.setBlock(world, i + 18, j + 7, k + 22, Blocks.planks, 1);
		this.setBlock(world, i + 18, j + 7, k + 23, Blocks.planks, 1);
		this.setBlock(world, i + 18, j + 7, k + 24, Blocks.air, 3);
		this.setBlock(world, i + 18, j + 7, k + 36, Blocks.air, 2);
		this.setBlock(world, i + 18, j + 7, k + 37, Blocks.planks, 1);
		this.setBlock(world, i + 18, j + 7, k + 43, Blocks.log, 1);
		this.setBlock(world, i + 18, j + 7, k + 44, Blocks.log, 1);
		this.setBlock(world, i + 18, j + 7, k + 45, Blocks.log, 1);
		this.setBlock(world, i + 18, j + 8, k + 14, Blocks.planks, 1);
		this.setBlock(world, i + 18, j + 8, k + 15, Blocks.planks, 1);
		this.setBlock(world, i + 18, j + 8, k + 16, Blocks.double_wooden_slab, 0);
		this.setBlock(world, i + 18, j + 8, k + 17, Blocks.fence, 0);
		this.setBlock(world, i + 18, j + 8, k + 20, Blocks.wooden_slab, 8);
		this.setBlock(world, i + 18, j + 8, k + 21, Blocks.wooden_slab, 8);
		this.setBlock(world, i + 18, j + 8, k + 22, Blocks.planks, 1);
		this.setBlock(world, i + 18, j + 8, k + 23, Blocks.air, 3);
		this.setBlock(world, i + 18, j + 8, k + 37, Blocks.air, 2);
		this.setBlock(world, i + 18, j + 8, k + 38, Blocks.planks, 1);
		this.setBlock(world, i + 18, j + 8, k + 43, Blocks.planks, 1);
		this.setBlock(world, i + 18, j + 8, k + 44, Blocks.planks, 1);
		this.setBlock(world, i + 18, j + 8, k + 45, Blocks.planks, 1);
		this.setBlock(world, i + 18, j + 9, k + 14, Blocks.wooden_slab, 1);
		this.setBlock(world, i + 18, j + 9, k + 15, Blocks.log, 1);
		this.setBlock(world, i + 18, j + 9, k + 16, Blocks.planks, 1);
		this.setBlock(world, i + 18, j + 9, k + 17, Blocks.planks, 1);
		this.setBlock(world, i + 18, j + 9, k + 18, Blocks.planks, 1);
		this.setBlock(world, i + 18, j + 9, k + 19, Blocks.planks, 1);
		this.setBlock(world, i + 18, j + 9, k + 20, Blocks.planks, 1);
		this.setBlock(world, i + 18, j + 9, k + 21, Blocks.planks, 1);
		this.setBlock(world, i + 18, j + 9, k + 22, Blocks.air, 3);
		this.setBlock(world, i + 18, j + 9, k + 38, Blocks.air, 2);
		this.setBlock(world, i + 18, j + 9, k + 39, Blocks.planks, 1);
		this.setBlock(world, i + 18, j + 9, k + 40, Blocks.planks, 1);
		this.setBlock(world, i + 18, j + 9, k + 41, Blocks.planks, 1);
		this.setBlock(world, i + 18, j + 9, k + 42, Blocks.planks, 1);
		this.setBlock(world, i + 18, j + 9, k + 43, Blocks.log, 1);
		this.setBlock(world, i + 18, j + 9, k + 44, Blocks.log, 1);
		this.setBlock(world, i + 18, j + 10, k + 15, Blocks.log, 1);
		this.setBlock(world, i + 18, j + 10, k + 43, Blocks.log, 1);
		this.setBlock(world, i + 18, j + 10, k + 44, Blocks.log, 1);
		this.setBlock(world, i + 18, j + 11, k + 15, Blocks.fence, 0);
		this.setBlock(world, i + 18, j + 11, k + 43, Blocks.fence, 0);
		this.setBlock(world, i + 18, j + 11, k + 44, Blocks.fence, 0);
		this.setBlock(world, i + 18, j + 13, k + 28, Blocks.log, 1);
		this.setBlock(world, i + 18, j + 14, k + 28, Blocks.wooden_slab, 1);
		this.setBlock(world, i + 18, j + 14, k + 31, Blocks.wool, 7);
		this.setBlock(world, i + 18, j + 14, k + 42, Blocks.log, 1);
		this.setBlock(world, i + 18, j + 15, k + 32, Blocks.wool, 3);
		this.setBlock(world, i + 18, j + 15, k + 42, Blocks.wooden_slab, 1);
		this.setBlock(world, i + 18, j + 15, k + 44, Blocks.wool, 7);
		this.setBlock(world, i + 18, j + 15, k + 45, Blocks.wool, 7);
		this.setBlock(world, i + 18, j + 16, k + 33, Blocks.wool, 7);
		this.setBlock(world, i + 18, j + 16, k + 46, Blocks.wool, 7);
		this.setBlock(world, i + 18, j + 17, k + 33, Blocks.wool, 8);
		this.setBlock(world, i + 18, j + 17, k + 46, Blocks.wool, 7);
		this.setBlock(world, i + 18, j + 18, k + 33, Blocks.wool, 3);
		this.setBlock(world, i + 18, j + 18, k + 46, Blocks.wool, 8);
		this.setBlock(world, i + 18, j + 19, k + 33, Blocks.wool, 8);
		this.setBlock(world, i + 18, j + 19, k + 46, Blocks.wool, 8);
		this.setBlock(world, i + 18, j + 20, k + 33, Blocks.wool, 8);
		this.setBlock(world, i + 18, j + 20, k + 46, Blocks.wool, 7);
		this.setBlock(world, i + 18, j + 21, k + 32, Blocks.wool, 8);
		this.setBlock(world, i + 18, j + 21, k + 46, Blocks.wool, 7);
		this.setBlock(world, i + 18, j + 22, k + 31, Blocks.wool, 3);
		this.setBlock(world, i + 18, j + 22, k + 45, Blocks.wool, 8);
		this.setBlock(world, i + 18, j + 23, k + 30, Blocks.wool, 8);
		this.setBlock(world, i + 18, j + 23, k + 44, Blocks.wool, 8);
		this.setBlock(world, i + 18, j + 24, k + 28, Blocks.log, 1);
		this.setBlock(world, i + 18, j + 24, k + 29, Blocks.wool, 3);
		this.setBlock(world, i + 18, j + 24, k + 42, Blocks.log, 1);
		this.setBlock(world, i + 18, j + 24, k + 43, Blocks.wool, 8);
		this.setBlock(world, i + 18, j + 25, k + 28, Blocks.wooden_slab, 1);
		this.setBlock(world, i + 18, j + 25, k + 42, Blocks.wooden_slab, 1);
		this.setBlock(world, i + 18, j + 26, k + 29, Blocks.wool, 8);
		this.setBlock(world, i + 18, j + 27, k + 30, Blocks.wool, 3);
		this.setBlock(world, i + 18, j + 28, k + 31, Blocks.wool, 8);
		this.setBlock(world, i + 18, j + 29, k + 31, Blocks.wool, 8);
		this.setBlock(world, i + 18, j + 30, k + 31, Blocks.wool, 8);
		this.setBlock(world, i + 18, j + 31, k + 30, Blocks.wool, 7);
		this.setBlock(world, i + 18, j + 32, k + 29, Blocks.wool, 8);
		this.setBlock(world, i + 19, j + 2, k + 17, Blocks.planks, 1);
		this.setBlock(world, i + 19, j + 2, k + 18, Blocks.planks, 1);
		this.setBlock(world, i + 19, j + 2, k + 19, Blocks.planks, 1);
		this.setBlock(world, i + 19, j + 2, k + 20, Blocks.planks, 1);
		this.setBlock(world, i + 19, j + 2, k + 21, Blocks.planks, 1);
		this.setBlock(world, i + 19, j + 2, k + 22, Blocks.planks, 1);
		this.setBlock(world, i + 19, j + 2, k + 23, Blocks.planks, 1);
		this.setBlock(world, i + 19, j + 2, k + 24, Blocks.planks, 1);
		this.setBlock(world, i + 19, j + 2, k + 25, Blocks.planks, 1);
		this.setBlock(world, i + 19, j + 2, k + 26, Blocks.planks, 1);
		this.setBlock(world, i + 19, j + 2, k + 27, Blocks.planks, 1);
		this.setBlock(world, i + 19, j + 2, k + 28, Blocks.planks, 1);
		this.setBlock(world, i + 19, j + 2, k + 29, Blocks.planks, 1);
		this.setBlock(world, i + 19, j + 2, k + 30, Blocks.planks, 1);
		this.setBlock(world, i + 19, j + 2, k + 31, Blocks.planks, 1);
		this.setBlock(world, i + 19, j + 2, k + 32, Blocks.planks, 1);
		this.setBlock(world, i + 19, j + 2, k + 33, Blocks.planks, 1);
		this.setBlock(world, i + 19, j + 2, k + 34, Blocks.planks, 1);
		this.setBlock(world, i + 19, j + 2, k + 35, Blocks.planks, 1);
		this.setBlock(world, i + 19, j + 2, k + 36, Blocks.planks, 1);
		this.setBlock(world, i + 19, j + 2, k + 37, Blocks.planks, 1);
		this.setBlock(world, i + 19, j + 2, k + 38, Blocks.planks, 1);
		this.setBlock(world, i + 19, j + 2, k + 39, Blocks.planks, 1);
		this.setBlock(world, i + 19, j + 2, k + 40, Blocks.planks, 1);
		this.setBlock(world, i + 19, j + 2, k + 41, Blocks.planks, 1);
		this.setBlock(world, i + 19, j + 2, k + 42, Blocks.planks, 1);
		this.setBlock(world, i + 19, j + 3, k + 16, Blocks.planks, 1);
		this.setBlock(world, i + 19, j + 3, k + 17, Blocks.wooden_slab, 0);
		this.setBlock(world, i + 19, j + 3, k + 18, Blocks.wooden_slab, 0);
		this.setBlock(world, i + 19, j + 3, k + 19, Blocks.wooden_slab, 0);
		this.setBlock(world, i + 19, j + 3, k + 20, Blocks.wooden_slab, 0);
		this.setBlock(world, i + 19, j + 3, k + 21, Blocks.wooden_slab, 0);
		this.setBlock(world, i + 19, j + 3, k + 22, Blocks.wooden_slab, 0);
		this.setBlock(world, i + 19, j + 3, k + 23, Blocks.wooden_slab, 0);
		this.setBlock(world, i + 19, j + 3, k + 24, Blocks.wooden_slab, 0);
		this.setBlock(world, i + 19, j + 3, k + 25, Blocks.wooden_slab, 0);
		this.setBlock(world, i + 19, j + 3, k + 26, Blocks.wooden_slab, 0);
		this.setBlock(world, i + 19, j + 3, k + 27, Blocks.wooden_slab, 0);
		this.setBlock(world, i + 19, j + 3, k + 28, Blocks.wooden_slab, 0);
		this.setBlock(world, i + 19, j + 3, k + 29, Blocks.wooden_slab, 0);
		this.setBlock(world, i + 19, j + 3, k + 30, Blocks.wooden_slab, 0);
		this.setBlock(world, i + 19, j + 3, k + 31, Blocks.wooden_slab, 0);
		this.setBlock(world, i + 19, j + 3, k + 32, Blocks.wooden_slab, 0);
		this.setBlock(world, i + 19, j + 3, k + 33, Blocks.wooden_slab, 0);
		this.setBlock(world, i + 19, j + 3, k + 34, Blocks.wooden_slab, 0);
		this.setBlock(world, i + 19, j + 3, k + 35, Blocks.wooden_slab, 0);
		this.setBlock(world, i + 19, j + 3, k + 36, Blocks.wooden_slab, 0);
		this.setBlock(world, i + 19, j + 3, k + 37, Blocks.wooden_slab, 0);
		this.setBlock(world, i + 19, j + 3, k + 38, Blocks.wooden_slab, 0);
		this.setBlock(world, i + 19, j + 3, k + 39, Blocks.wooden_slab, 0);
		this.setBlock(world, i + 19, j + 3, k + 40, Blocks.wooden_slab, 0);
		this.setBlock(world, i + 19, j + 3, k + 41, Blocks.wooden_slab, 0);
		this.setBlock(world, i + 19, j + 3, k + 42, Blocks.wooden_slab, 0);
		this.setBlock(world, i + 19, j + 3, k + 43, Blocks.planks, 1);
		this.setBlock(world, i + 19, j + 4, k + 15, Blocks.planks, 1);
		this.setBlock(world, i + 19, j + 4, k + 16, Blocks.wooden_slab, 0);
		this.setBlock(world, i + 19, j + 4, k + 43, Blocks.wooden_slab, 0);
		this.setBlock(world, i + 19, j + 4, k + 44, Blocks.planks, 1);
		this.setBlock(world, i + 19, j + 5, k + 14, Blocks.planks, 1);
		this.setBlock(world, i + 19, j + 5, k + 15, Blocks.wooden_slab, 0);
		this.setBlock(world, i + 19, j + 5, k + 44, Blocks.wooden_slab, 0);
		this.setBlock(world, i + 19, j + 5, k + 45, Blocks.planks, 1);
		this.setBlock(world, i + 19, j + 6, k + 14, Blocks.log, 1);
		this.setBlock(world, i + 19, j + 6, k + 15, Blocks.planks, 1);
		this.setBlock(world, i + 19, j + 6, k + 16, Blocks.planks, 1);
		this.setBlock(world, i + 19, j + 6, k + 17, Blocks.planks, 1);
		this.setBlock(world, i + 19, j + 6, k + 18, Blocks.planks, 1);
		this.setBlock(world, i + 19, j + 6, k + 19, Blocks.planks, 1);
		this.setBlock(world, i + 19, j + 6, k + 20, Blocks.planks, 1);
		this.setBlock(world, i + 19, j + 6, k + 21, Blocks.planks, 1);
		this.setBlock(world, i + 19, j + 6, k + 22, Blocks.planks, 1);
		this.setBlock(world, i + 19, j + 6, k + 23, Blocks.planks, 1);
		this.setBlock(world, i + 19, j + 6, k + 24, Blocks.planks, 1);
		this.setBlock(world, i + 19, j + 6, k + 25, Blocks.planks, 1);
		this.setBlock(world, i + 19, j + 6, k + 26, Blocks.planks, 1);
		this.setBlock(world, i + 19, j + 6, k + 27, Blocks.planks, 1);
		this.setBlock(world, i + 19, j + 6, k + 28, Blocks.planks, 1);
		this.setBlock(world, i + 19, j + 6, k + 29, Blocks.planks, 1);
		this.setBlock(world, i + 19, j + 6, k + 30, Blocks.planks, 1);
		this.setBlock(world, i + 19, j + 6, k + 31, Blocks.planks, 1);
		this.setBlock(world, i + 19, j + 6, k + 32, Blocks.planks, 1);
		this.setBlock(world, i + 19, j + 6, k + 33, Blocks.planks, 1);
		this.setBlock(world, i + 19, j + 6, k + 34, Blocks.planks, 1);
		this.setBlock(world, i + 19, j + 6, k + 35, Blocks.planks, 1);
		this.setBlock(world, i + 19, j + 6, k + 36, Blocks.planks, 1);
		this.setBlock(world, i + 19, j + 6, k + 37, Blocks.planks, 1);
		this.setBlock(world, i + 19, j + 6, k + 38, Blocks.planks, 1);
		this.setBlock(world, i + 19, j + 6, k + 39, Blocks.planks, 1);
		this.setBlock(world, i + 19, j + 6, k + 40, Blocks.planks, 1);
		this.setBlock(world, i + 19, j + 6, k + 41, Blocks.planks, 1);
		this.setBlock(world, i + 19, j + 6, k + 42, Blocks.planks, 1);
		this.setBlock(world, i + 19, j + 6, k + 43, Blocks.planks, 1);
		this.setBlock(world, i + 19, j + 6, k + 44, Blocks.planks, 1);
		this.setBlock(world, i + 19, j + 6, k + 45, Blocks.log, 1);
		this.setBlock(world, i + 19, j + 6, k + 46, Blocks.log, 1);
		this.setBlock(world, i + 19, j + 7, k + 13, Blocks.log, 1);
		this.setBlock(world, i + 19, j + 7, k + 14, Blocks.planks, 1);
		this.setBlock(world, i + 19, j + 7, k + 15, Blocks.planks, 1);
		this.setBlock(world, i + 19, j + 7, k + 16, Blocks.wooden_slab, 0);
		this.setBlock(world, i + 19, j + 7, k + 22, Blocks.planks, 1);
		this.setBlock(world, i + 19, j + 7, k + 23, Blocks.planks, 1);
		this.setBlock(world, i + 19, j + 7, k + 24, Blocks.planks, 1);
		this.setBlock(world, i + 19, j + 7, k + 25, Blocks.planks, 1);
		//this.setBlock(world, i + 19, j + 7, k + 29, Blocks.blockSteel, 0);
		//this.setBlock(world, i + 19, j + 7, k + 34, Blocks.blockSteel, 0);
		this.setBlock(world, i + 19, j + 7, k + 36, Blocks.planks, 1);
		this.setBlock(world, i + 19, j + 7, k + 37, Blocks.planks, 1);
		this.setBlock(world, i + 19, j + 7, k + 38, Blocks.planks, 1);
		this.setBlock(world, i + 19, j + 7, k + 39, Blocks.planks, 1);
		this.setBlock(world, i + 19, j + 7, k + 44, Blocks.planks, 1);
		this.setBlock(world, i + 19, j + 7, k + 45, Blocks.log, 1);
		this.setBlock(world, i + 19, j + 7, k + 46, Blocks.log, 1);
		this.setBlock(world, i + 19, j + 8, k + 13, Blocks.planks, 1);
		this.setBlock(world, i + 19, j + 8, k + 15, Blocks.planks, 1);
		this.setBlock(world, i + 19, j + 8, k + 21, Blocks.wooden_slab, 8);
		this.setBlock(world, i + 19, j + 8, k + 22, Blocks.planks, 1);
		this.setBlock(world, i + 19, j + 8, k + 23, Blocks.planks, 1);
		this.setBlock(world, i + 19, j + 8, k + 24, Blocks.planks, 1);
		this.setBlock(world, i + 19, j + 8, k + 25, Blocks.wooden_slab, 0);
		this.setBlock(world, i + 19, j + 8, k + 36, Blocks.wooden_slab, 0);
		this.setBlock(world, i + 19, j + 8, k + 37, Blocks.planks, 1);
		this.setBlock(world, i + 19, j + 8, k + 38, Blocks.planks, 1);
		this.setBlock(world, i + 19, j + 8, k + 39, Blocks.planks, 1);
		this.setBlock(world, i + 19, j + 8, k + 44, Blocks.planks, 1);
		this.setBlock(world, i + 19, j + 8, k + 45, Blocks.planks, 1);
		this.setBlock(world, i + 19, j + 8, k + 46, Blocks.planks, 1);
		this.setBlock(world, i + 19, j + 9, k + 13, Blocks.log, 1);
		this.setBlock(world, i + 19, j + 9, k + 14, Blocks.log, 1);
		this.setBlock(world, i + 19, j + 9, k + 15, Blocks.log, 1);
		this.setBlock(world, i + 19, j + 9, k + 16, Blocks.planks, 1);
		this.setBlock(world, i + 19, j + 9, k + 17, Blocks.planks, 1);
		this.setBlock(world, i + 19, j + 9, k + 18, Blocks.planks, 1);
		this.setBlock(world, i + 19, j + 9, k + 19, Blocks.planks, 1);
		this.setBlock(world, i + 19, j + 9, k + 20, Blocks.planks, 1);
		this.setBlock(world, i + 19, j + 9, k + 21, Blocks.planks, 1);
		this.setBlock(world, i + 19, j + 9, k + 22, Blocks.planks, 1);
		this.setBlock(world, i + 19, j + 9, k + 23, Blocks.planks, 1);
		this.setBlock(world, i + 19, j + 9, k + 24, Blocks.wooden_slab, 0);
		this.setBlock(world, i + 19, j + 9, k + 37, Blocks.wooden_slab, 0);
		this.setBlock(world, i + 19, j + 9, k + 38, Blocks.planks, 1);
		this.setBlock(world, i + 19, j + 9, k + 39, Blocks.planks, 1);
		this.setBlock(world, i + 19, j + 9, k + 40, Blocks.planks, 1);
		this.setBlock(world, i + 19, j + 9, k + 41, Blocks.planks, 1);
		this.setBlock(world, i + 19, j + 9, k + 42, Blocks.planks, 1);
		this.setBlock(world, i + 19, j + 9, k + 43, Blocks.planks, 1);
		this.setBlock(world, i + 19, j + 9, k + 44, Blocks.planks, 1);
		this.setBlock(world, i + 19, j + 9, k + 45, Blocks.log, 1);
		this.setBlock(world, i + 19, j + 9, k + 46, Blocks.log, 1);
		this.setBlock(world, i + 19, j + 10, k + 13, Blocks.wooden_slab, 1);
		this.setBlock(world, i + 19, j + 10, k + 14, Blocks.wooden_slab, 1);
		this.setBlock(world, i + 19, j + 10, k + 15, Blocks.log, 1);
		//this.setBlock(world, i + 19, j + 10, k + 17, Blocks.blockSteel, 0);
		this.setBlock(world, i + 19, j + 10, k + 23, Blocks.fence, 0);
		this.setBlock(world, i + 19, j + 10, k + 38, Blocks.planks, 1);
		this.setBlock(world, i + 19, j + 10, k + 45, Blocks.log, 1);
		this.setBlock(world, i + 19, j + 10, k + 46, Blocks.log, 1);
		this.setBlock(world, i + 19, j + 11, k + 15, Blocks.fence, 0);
		this.setBlock(world, i + 19, j + 11, k + 38, Blocks.fence, 0);
		this.setBlock(world, i + 19, j + 11, k + 45, Blocks.fence, 0);
		this.setBlock(world, i + 19, j + 11, k + 46, Blocks.fence, 0);
		this.setBlock(world, i + 19, j + 13, k + 28, Blocks.log, 1);
		this.setBlock(world, i + 19, j + 14, k + 28, Blocks.wooden_slab, 1);
		this.setBlock(world, i + 19, j + 14, k + 31, Blocks.wool, 8);
		this.setBlock(world, i + 19, j + 14, k + 42, Blocks.log, 1);
		this.setBlock(world, i + 19, j + 15, k + 32, Blocks.wool, 8);
		this.setBlock(world, i + 19, j + 15, k + 42, Blocks.wooden_slab, 1);
		this.setBlock(world, i + 19, j + 15, k + 44, Blocks.wool, 7);
		this.setBlock(world, i + 19, j + 15, k + 45, Blocks.wool, 7);
		this.setBlock(world, i + 19, j + 16, k + 32, Blocks.wool, 7);
		this.setBlock(world, i + 19, j + 16, k + 45, Blocks.wool, 3);
		this.setBlock(world, i + 19, j + 17, k + 33, Blocks.wool, 7);
		this.setBlock(world, i + 19, j + 17, k + 46, Blocks.wool, 7);
		this.setBlock(world, i + 19, j + 18, k + 33, Blocks.wool, 8);
		this.setBlock(world, i + 19, j + 18, k + 46, Blocks.wool, 3);
		this.setBlock(world, i + 19, j + 19, k + 33, Blocks.wool, 3);
		this.setBlock(world, i + 19, j + 19, k + 46, Blocks.wool, 8);
		this.setBlock(world, i + 19, j + 20, k + 33, Blocks.wool, 8);
		this.setBlock(world, i + 19, j + 20, k + 46, Blocks.wool, 8);
		this.setBlock(world, i + 19, j + 21, k + 32, Blocks.wool, 7);
		this.setBlock(world, i + 19, j + 21, k + 45, Blocks.wool, 7);
		this.setBlock(world, i + 19, j + 21, k + 46, Blocks.wool, 8);
		this.setBlock(world, i + 19, j + 22, k + 31, Blocks.wool, 8);
		this.setBlock(world, i + 19, j + 22, k + 45, Blocks.wool, 8);
		this.setBlock(world, i + 19, j + 23, k + 30, Blocks.wool, 8);
		this.setBlock(world, i + 19, j + 23, k + 44, Blocks.wool, 7);
		this.setBlock(world, i + 19, j + 24, k + 28, Blocks.log, 1);
		this.setBlock(world, i + 19, j + 24, k + 29, Blocks.wool, 8);
		this.setBlock(world, i + 19, j + 24, k + 42, Blocks.log, 1);
		this.setBlock(world, i + 19, j + 24, k + 43, Blocks.wool, 7);
		this.setBlock(world, i + 19, j + 25, k + 28, Blocks.wooden_slab, 1);
		this.setBlock(world, i + 19, j + 25, k + 42, Blocks.wooden_slab, 1);
		this.setBlock(world, i + 19, j + 26, k + 29, Blocks.wool, 8);
		this.setBlock(world, i + 19, j + 27, k + 30, Blocks.wool, 8);
		this.setBlock(world, i + 19, j + 28, k + 31, Blocks.wool, 7);
		this.setBlock(world, i + 19, j + 29, k + 31, Blocks.wool, 3);
		this.setBlock(world, i + 19, j + 30, k + 31, Blocks.wool, 8);
		this.setBlock(world, i + 19, j + 31, k + 30, Blocks.wool, 8);
		this.setBlock(world, i + 19, j + 32, k + 28, Blocks.log, 1);
		this.setBlock(world, i + 19, j + 32, k + 29, Blocks.wool, 3);
		this.setBlock(world, i + 19, j + 33, k + 28, Blocks.wooden_slab, 1);
		this.setBlock(world, i + 20, j + 1, k + 17, Blocks.planks, 1);
		this.setBlock(world, i + 20, j + 1, k + 18, Blocks.planks, 1);
		this.setBlock(world, i + 20, j + 1, k + 19, Blocks.planks, 1);
		this.setBlock(world, i + 20, j + 1, k + 20, Blocks.planks, 1);
		this.setBlock(world, i + 20, j + 1, k + 21, Blocks.planks, 1);
		this.setBlock(world, i + 20, j + 1, k + 22, Blocks.planks, 1);
		this.setBlock(world, i + 20, j + 1, k + 23, Blocks.planks, 1);
		this.setBlock(world, i + 20, j + 1, k + 24, Blocks.planks, 1);
		this.setBlock(world, i + 20, j + 1, k + 25, Blocks.planks, 1);
		this.setBlock(world, i + 20, j + 1, k + 26, Blocks.planks, 1);
		this.setBlock(world, i + 20, j + 1, k + 27, Blocks.planks, 1);
		this.setBlock(world, i + 20, j + 1, k + 28, Blocks.planks, 1);
		this.setBlock(world, i + 20, j + 1, k + 29, Blocks.planks, 1);
		this.setBlock(world, i + 20, j + 1, k + 30, Blocks.planks, 1);
		this.setBlock(world, i + 20, j + 1, k + 31, Blocks.planks, 1);
		this.setBlock(world, i + 20, j + 1, k + 32, Blocks.planks, 1);
		this.setBlock(world, i + 20, j + 1, k + 33, Blocks.planks, 1);
		this.setBlock(world, i + 20, j + 1, k + 34, Blocks.planks, 1);
		this.setBlock(world, i + 20, j + 1, k + 35, Blocks.planks, 1);
		this.setBlock(world, i + 20, j + 1, k + 36, Blocks.planks, 1);
		this.setBlock(world, i + 20, j + 1, k + 37, Blocks.planks, 1);
		this.setBlock(world, i + 20, j + 1, k + 38, Blocks.planks, 1);
		this.setBlock(world, i + 20, j + 1, k + 39, Blocks.planks, 1);
		this.setBlock(world, i + 20, j + 1, k + 40, Blocks.planks, 1);
		this.setBlock(world, i + 20, j + 1, k + 41, Blocks.planks, 1);
		this.setBlock(world, i + 20, j + 2, k + 16, Blocks.planks, 1);
		this.setBlock(world, i + 20, j + 2, k + 17, Blocks.planks, 1);
		this.setBlock(world, i + 20, j + 2, k + 18, Blocks.planks, 1);
		this.setBlock(world, i + 20, j + 2, k + 19, Blocks.planks, 1);
		this.setBlock(world, i + 20, j + 2, k + 20, Blocks.planks, 1);
		this.setBlock(world, i + 20, j + 2, k + 21, Blocks.planks, 1);
		this.setBlock(world, i + 20, j + 2, k + 22, Blocks.planks, 1);
		this.setBlock(world, i + 20, j + 2, k + 23, Blocks.planks, 1);
		this.setBlock(world, i + 20, j + 2, k + 24, Blocks.planks, 1);
		this.setBlock(world, i + 20, j + 2, k + 25, Blocks.planks, 1);
		this.setBlock(world, i + 20, j + 2, k + 26, Blocks.planks, 1);
		this.setBlock(world, i + 20, j + 2, k + 27, Blocks.planks, 1);
		this.setBlock(world, i + 20, j + 2, k + 28, Blocks.planks, 1);
		this.setBlock(world, i + 20, j + 2, k + 29, Blocks.planks, 1);
		this.setBlock(world, i + 20, j + 2, k + 30, Blocks.planks, 1);
		this.setBlock(world, i + 20, j + 2, k + 31, Blocks.planks, 1);
		this.setBlock(world, i + 20, j + 2, k + 32, Blocks.planks, 1);
		this.setBlock(world, i + 20, j + 2, k + 33, Blocks.planks, 1);
		this.setBlock(world, i + 20, j + 2, k + 34, Blocks.planks, 1);
		this.setBlock(world, i + 20, j + 2, k + 35, Blocks.planks, 1);
		this.setBlock(world, i + 20, j + 2, k + 36, Blocks.planks, 1);
		this.setBlock(world, i + 20, j + 2, k + 37, Blocks.planks, 1);
		this.setBlock(world, i + 20, j + 2, k + 38, Blocks.planks, 1);
		this.setBlock(world, i + 20, j + 2, k + 39, Blocks.planks, 1);
		this.setBlock(world, i + 20, j + 2, k + 40, Blocks.planks, 1);
		this.setBlock(world, i + 20, j + 2, k + 41, Blocks.planks, 1);
		this.setBlock(world, i + 20, j + 2, k + 42, Blocks.planks, 1);
		this.setBlock(world, i + 20, j + 2, k + 43, Blocks.planks, 1);
		this.setBlock(world, i + 20, j + 3, k + 15, Blocks.planks, 1);
		this.setBlock(world, i + 20, j + 3, k + 16, Blocks.planks, 1);
		this.setBlock(world, i + 20, j + 3, k + 17, Blocks.wooden_slab, 0);
		//this.setBlock(world, i + 20, j + 3, k + 22, Blocks.blockSteel, 0);
		//this.setBlock(world, i + 20, j + 3, k + 25, Blocks.blockSteel, 0);
		//this.setBlock(world, i + 20, j + 3, k + 28, Blocks.blockSteel, 0);
		//this.setBlock(world, i + 20, j + 3, k + 31, Blocks.blockSteel, 0);
		//this.setBlock(world, i + 20, j + 3, k + 34, Blocks.blockSteel, 0);
		//this.setBlock(world, i + 20, j + 3, k + 37, Blocks.blockSteel, 0);
		this.setBlock(world, i + 20, j + 3, k + 43, Blocks.wooden_slab, 0);
		this.setBlock(world, i + 20, j + 3, k + 44, Blocks.planks, 1);
		this.setBlock(world, i + 20, j + 4, k + 14, Blocks.planks, 1);
		this.setBlock(world, i + 20, j + 4, k + 15, Blocks.wooden_slab, 0);
		this.setBlock(world, i + 20, j + 4, k + 44, Blocks.wooden_slab, 0);
		this.setBlock(world, i + 20, j + 4, k + 45, Blocks.planks, 1);
		this.setBlock(world, i + 20, j + 5, k + 13, Blocks.air, 6);
		//this.setBlock(world, i + 20, j + 5, k + 14, Blocks.blockDiamond, 0);
		this.setBlock(world, i + 20, j + 5, k + 45, Blocks.wooden_slab, 0);
		this.setBlock(world, i + 20, j + 5, k + 46, Blocks.planks, 1);
		this.setBlock(world, i + 20, j + 6, k + 13, Blocks.log, 1);
		this.setBlock(world, i + 20, j + 6, k + 14, Blocks.wooden_slab, 9);
		this.setBlock(world, i + 20, j + 6, k + 15, Blocks.planks, 1);
		this.setBlock(world, i + 20, j + 6, k + 16, Blocks.planks, 1);
		this.setBlock(world, i + 20, j + 6, k + 17, Blocks.planks, 1);
		this.setBlock(world, i + 20, j + 6, k + 18, Blocks.planks, 1);
		this.setBlock(world, i + 20, j + 6, k + 19, Blocks.planks, 1);
		this.setBlock(world, i + 20, j + 6, k + 20, Blocks.planks, 1);
		this.setBlock(world, i + 20, j + 6, k + 21, Blocks.planks, 1);
		this.setBlock(world, i + 20, j + 6, k + 22, Blocks.planks, 1);
		this.setBlock(world, i + 20, j + 6, k + 23, Blocks.planks, 1);
		this.setBlock(world, i + 20, j + 6, k + 24, Blocks.planks, 1);
		this.setBlock(world, i + 20, j + 6, k + 25, Blocks.planks, 1);
		this.setBlock(world, i + 20, j + 6, k + 26, Blocks.planks, 1);
		this.setBlock(world, i + 20, j + 6, k + 27, Blocks.planks, 1);
		this.setBlock(world, i + 20, j + 6, k + 28, Blocks.planks, 1);
		this.setBlock(world, i + 20, j + 6, k + 29, Blocks.planks, 1);
		this.setBlock(world, i + 20, j + 6, k + 30, Blocks.planks, 1);
		this.setBlock(world, i + 20, j + 6, k + 31, Blocks.planks, 1);
		this.setBlock(world, i + 20, j + 6, k + 32, Blocks.planks, 1);
		this.setBlock(world, i + 20, j + 6, k + 33, Blocks.planks, 1);
		this.setBlock(world, i + 20, j + 6, k + 34, Blocks.planks, 1);
		this.setBlock(world, i + 20, j + 6, k + 35, Blocks.planks, 1);
		this.setBlock(world, i + 20, j + 6, k + 36, Blocks.planks, 1);
		this.setBlock(world, i + 20, j + 6, k + 37, Blocks.planks, 1);
		this.setBlock(world, i + 20, j + 6, k + 38, Blocks.planks, 1);
		this.setBlock(world, i + 20, j + 6, k + 39, Blocks.planks, 1);
		this.setBlock(world, i + 20, j + 6, k + 40, Blocks.planks, 1);
		this.setBlock(world, i + 20, j + 6, k + 41, Blocks.planks, 1);
		this.setBlock(world, i + 20, j + 6, k + 42, Blocks.planks, 1);
		this.setBlock(world, i + 20, j + 6, k + 43, Blocks.planks, 1);
		this.setBlock(world, i + 20, j + 6, k + 44, Blocks.planks, 1);
		this.setBlock(world, i + 20, j + 6, k + 45, Blocks.planks, 1);
		this.setBlock(world, i + 20, j + 6, k + 46, Blocks.planks, 1);
		this.setBlock(world, i + 20, j + 6, k + 47, Blocks.log, 1);
		this.setBlock(world, i + 20, j + 7, k + 13, Blocks.log, 1);
		this.setBlock(world, i + 20, j + 7, k + 14, Blocks.air, 3);
		this.setBlock(world, i + 20, j + 7, k + 22, Blocks.air, 2);
		this.setBlock(world, i + 20, j + 7, k + 23, Blocks.planks, 1);
		this.setBlock(world, i + 20, j + 7, k + 38, Blocks.planks, 1);
		this.setBlock(world, i + 20, j + 7, k + 41, Blocks.wooden_slab, 1);
		this.setBlock(world, i + 20, j + 7, k + 42, Blocks.wooden_slab, 1);
		this.setBlock(world, i + 20, j + 7, k + 47, Blocks.log, 1);
		this.setBlock(world, i + 20, j + 8, k + 13, Blocks.air, 8);
		this.setBlock(world, i + 20, j + 8, k + 22, Blocks.wooden_slab, 8);
		this.setBlock(world, i + 20, j + 8, k + 23, Blocks.planks, 1);
		this.setBlock(world, i + 20, j + 8, k + 38, Blocks.planks, 1);
		this.setBlock(world, i + 20, j + 8, k + 47, Blocks.planks, 1);
		this.setBlock(world, i + 20, j + 8, k + 48, Blocks.planks, 1);
		this.setBlock(world, i + 20, j + 9, k + 13, Blocks.log, 1);
		this.setBlock(world, i + 20, j + 9, k + 14, Blocks.log, 1);
		this.setBlock(world, i + 20, j + 9, k + 15, Blocks.planks, 1);
		this.setBlock(world, i + 20, j + 9, k + 16, Blocks.planks, 1);
		this.setBlock(world, i + 20, j + 9, k + 17, Blocks.planks, 1);
		this.setBlock(world, i + 20, j + 9, k + 18, Blocks.planks, 1);
		this.setBlock(world, i + 20, j + 9, k + 19, Blocks.planks, 1);
		this.setBlock(world, i + 20, j + 9, k + 20, Blocks.planks, 1);
		this.setBlock(world, i + 20, j + 9, k + 21, Blocks.planks, 1);
		this.setBlock(world, i + 20, j + 9, k + 22, Blocks.planks, 1);
		this.setBlock(world, i + 20, j + 9, k + 23, Blocks.planks, 1);
		this.setBlock(world, i + 20, j + 9, k + 38, Blocks.planks, 1);
		this.setBlock(world, i + 20, j + 9, k + 39, Blocks.planks, 1);
		this.setBlock(world, i + 20, j + 9, k + 40, Blocks.planks, 1);
		this.setBlock(world, i + 20, j + 9, k + 41, Blocks.planks, 1);
		this.setBlock(world, i + 20, j + 9, k + 42, Blocks.planks, 1);
		this.setBlock(world, i + 20, j + 9, k + 43, Blocks.planks, 1);
		this.setBlock(world, i + 20, j + 9, k + 44, Blocks.planks, 1);
		this.setBlock(world, i + 20, j + 9, k + 45, Blocks.planks, 1);
		this.setBlock(world, i + 20, j + 9, k + 46, Blocks.planks, 1);
		this.setBlock(world, i + 20, j + 9, k + 47, Blocks.log, 1);
		this.setBlock(world, i + 20, j + 9, k + 48, Blocks.log, 1);
		this.setBlock(world, i + 20, j + 10, k + 13, Blocks.air, 2);
		this.setBlock(world, i + 20, j + 10, k + 14, Blocks.log, 1);
		this.setBlock(world, i + 20, j + 10, k + 23, Blocks.fence, 0);
		this.setBlock(world, i + 20, j + 10, k + 38, Blocks.planks, 1);
		this.setBlock(world, i + 20, j + 10, k + 47, Blocks.log, 1);
		this.setBlock(world, i + 20, j + 10, k + 48, Blocks.wooden_slab, 1);
		this.setBlock(world, i + 20, j + 11, k + 14, Blocks.fence, 0);
		this.setBlock(world, i + 20, j + 11, k + 38, Blocks.fence, 0);
		this.setBlock(world, i + 20, j + 11, k + 47, Blocks.planks, 1);
		this.setBlock(world, i + 20, j + 12, k + 47, Blocks.wooden_slab, 0);
		this.setBlock(world, i + 20, j + 13, k + 27, Blocks.log, 1);
		this.setBlock(world, i + 20, j + 14, k + 27, Blocks.wooden_slab, 1);
		this.setBlock(world, i + 20, j + 14, k + 30, Blocks.wool, 7);
		this.setBlock(world, i + 20, j + 14, k + 41, Blocks.log, 1);
		this.setBlock(world, i + 20, j + 15, k + 31, Blocks.wool, 8);
		this.setBlock(world, i + 20, j + 15, k + 41, Blocks.wooden_slab, 1);
		this.setBlock(world, i + 20, j + 15, k + 44, Blocks.wool, 8);
		this.setBlock(world, i + 20, j + 16, k + 32, Blocks.wool, 8);
		this.setBlock(world, i + 20, j + 16, k + 45, Blocks.wool, 7);
		this.setBlock(world, i + 20, j + 17, k + 33, Blocks.wool, 7);
		this.setBlock(world, i + 20, j + 17, k + 45, Blocks.wool, 8);
		this.setBlock(world, i + 20, j + 18, k + 33, Blocks.wool, 7);
		this.setBlock(world, i + 20, j + 18, k + 46, Blocks.wool, 3);
		this.setBlock(world, i + 20, j + 19, k + 33, Blocks.wool, 7);
		this.setBlock(world, i + 20, j + 19, k + 46, Blocks.wool, 8);
		this.setBlock(world, i + 20, j + 20, k + 32, Blocks.wool, 3);
		this.setBlock(world, i + 20, j + 20, k + 45, Blocks.wool, 8);
		this.setBlock(world, i + 20, j + 20, k + 46, Blocks.wool, 7);
		this.setBlock(world, i + 20, j + 21, k + 31, Blocks.wool, 8);
		this.setBlock(world, i + 20, j + 21, k + 45, Blocks.wool, 7);
		this.setBlock(world, i + 20, j + 22, k + 31, Blocks.wool, 7);
		this.setBlock(world, i + 20, j + 22, k + 44, Blocks.wool, 7);
		this.setBlock(world, i + 20, j + 22, k + 45, Blocks.wool, 7);
		this.setBlock(world, i + 20, j + 23, k + 30, Blocks.wool, 7);
		this.setBlock(world, i + 20, j + 23, k + 43, Blocks.wool, 8);
		this.setBlock(world, i + 20, j + 24, k + 27, Blocks.log, 1);
		this.setBlock(world, i + 20, j + 24, k + 28, Blocks.wool, 8);
		this.setBlock(world, i + 20, j + 24, k + 29, Blocks.wool, 8);
		this.setBlock(world, i + 20, j + 24, k + 41, Blocks.log, 1);
		this.setBlock(world, i + 20, j + 24, k + 42, Blocks.wool, 8);
		this.setBlock(world, i + 20, j + 24, k + 43, Blocks.wool, 8);
		this.setBlock(world, i + 20, j + 25, k + 27, Blocks.wooden_slab, 1);
		this.setBlock(world, i + 20, j + 25, k + 41, Blocks.wooden_slab, 1);
		this.setBlock(world, i + 20, j + 26, k + 29, Blocks.wool, 8);
		this.setBlock(world, i + 20, j + 27, k + 30, Blocks.wool, 7);
		this.setBlock(world, i + 20, j + 28, k + 30, Blocks.wool, 7);
		this.setBlock(world, i + 20, j + 29, k + 31, Blocks.wool, 3);
		this.setBlock(world, i + 20, j + 30, k + 31, Blocks.wool, 3);
		this.setBlock(world, i + 20, j + 31, k + 31, Blocks.wool, 8);
		this.setBlock(world, i + 20, j + 32, k + 27, Blocks.log, 1);
		this.setBlock(world, i + 20, j + 32, k + 29, Blocks.wool, 3);
		this.setBlock(world, i + 20, j + 32, k + 30, Blocks.wool, 8);
		this.setBlock(world, i + 20, j + 33, k + 27, Blocks.wooden_slab, 1);
		this.setBlock(world, i + 21, j + 0, k + 12, Blocks.spruce_stairs, 2);
		this.setBlock(world, i + 21, j + 0, k + 13, Blocks.planks, 1);
		this.setBlock(world, i + 21, j + 0, k + 14, Blocks.planks, 1);
		this.setBlock(world, i + 21, j + 0, k + 15, Blocks.planks, 1);
		this.setBlock(world, i + 21, j + 0, k + 16, Blocks.planks, 1);
		this.setBlock(world, i + 21, j + 0, k + 17, Blocks.planks, 1);
		this.setBlock(world, i + 21, j + 0, k + 18, Blocks.planks, 1);
		this.setBlock(world, i + 21, j + 0, k + 19, Blocks.planks, 1);
		this.setBlock(world, i + 21, j + 0, k + 20, Blocks.planks, 1);
		this.setBlock(world, i + 21, j + 0, k + 21, Blocks.planks, 1);
		this.setBlock(world, i + 21, j + 0, k + 22, Blocks.planks, 1);
		this.setBlock(world, i + 21, j + 0, k + 23, Blocks.planks, 1);
		this.setBlock(world, i + 21, j + 0, k + 24, Blocks.planks, 1);
		this.setBlock(world, i + 21, j + 0, k + 25, Blocks.planks, 1);
		this.setBlock(world, i + 21, j + 0, k + 26, Blocks.planks, 1);
		this.setBlock(world, i + 21, j + 0, k + 27, Blocks.planks, 1);
		this.setBlock(world, i + 21, j + 0, k + 28, Blocks.planks, 1);
		this.setBlock(world, i + 21, j + 0, k + 29, Blocks.planks, 1);
		this.setBlock(world, i + 21, j + 0, k + 30, Blocks.planks, 1);
		this.setBlock(world, i + 21, j + 0, k + 31, Blocks.planks, 1);
		this.setBlock(world, i + 21, j + 0, k + 32, Blocks.planks, 1);
		this.setBlock(world, i + 21, j + 0, k + 33, Blocks.planks, 1);
		this.setBlock(world, i + 21, j + 0, k + 34, Blocks.planks, 1);
		this.setBlock(world, i + 21, j + 0, k + 35, Blocks.planks, 1);
		this.setBlock(world, i + 21, j + 0, k + 36, Blocks.planks, 1);
		this.setBlock(world, i + 21, j + 0, k + 37, Blocks.planks, 1);
		this.setBlock(world, i + 21, j + 0, k + 38, Blocks.planks, 1);
		this.setBlock(world, i + 21, j + 1, k + 13, Blocks.wooden_slab, 0);
		this.setBlock(world, i + 21, j + 1, k + 14, Blocks.planks, 1);
		this.setBlock(world, i + 21, j + 1, k + 15, Blocks.planks, 1);
		this.setBlock(world, i + 21, j + 1, k + 16, Blocks.planks, 1);
		this.setBlock(world, i + 21, j + 1, k + 17, Blocks.planks, 1);
		this.setBlock(world, i + 21, j + 1, k + 18, Blocks.planks, 1);
		this.setBlock(world, i + 21, j + 1, k + 19, Blocks.planks, 1);
		this.setBlock(world, i + 21, j + 1, k + 20, Blocks.planks, 1);
		this.setBlock(world, i + 21, j + 1, k + 21, Blocks.planks, 1);
		this.setBlock(world, i + 21, j + 1, k + 22, Blocks.planks, 1);
		this.setBlock(world, i + 21, j + 1, k + 23, Blocks.planks, 1);
		this.setBlock(world, i + 21, j + 1, k + 24, Blocks.planks, 1);
		this.setBlock(world, i + 21, j + 1, k + 25, Blocks.planks, 1);
		this.setBlock(world, i + 21, j + 1, k + 26, Blocks.planks, 1);
		this.setBlock(world, i + 21, j + 1, k + 27, Blocks.planks, 1);
		this.setBlock(world, i + 21, j + 1, k + 28, Blocks.planks, 1);
		this.setBlock(world, i + 21, j + 1, k + 29, Blocks.planks, 1);
		this.setBlock(world, i + 21, j + 1, k + 30, Blocks.planks, 1);
		this.setBlock(world, i + 21, j + 1, k + 31, Blocks.planks, 1);
		this.setBlock(world, i + 21, j + 1, k + 32, Blocks.planks, 1);
		this.setBlock(world, i + 21, j + 1, k + 33, Blocks.planks, 1);
		this.setBlock(world, i + 21, j + 1, k + 34, Blocks.planks, 1);
		this.setBlock(world, i + 21, j + 1, k + 35, Blocks.planks, 1);
		this.setBlock(world, i + 21, j + 1, k + 36, Blocks.planks, 1);
		this.setBlock(world, i + 21, j + 1, k + 37, Blocks.planks, 1);
		this.setBlock(world, i + 21, j + 1, k + 38, Blocks.planks, 1);
		this.setBlock(world, i + 21, j + 1, k + 39, Blocks.planks, 1);
		this.setBlock(world, i + 21, j + 1, k + 40, Blocks.planks, 1);
		this.setBlock(world, i + 21, j + 1, k + 41, Blocks.planks, 1);
		this.setBlock(world, i + 21, j + 1, k + 42, Blocks.planks, 1);
		this.setBlock(world, i + 21, j + 2, k + 14, Blocks.fence, 0);
		this.setBlock(world, i + 21, j + 2, k + 15, Blocks.planks, 1);
		this.setBlock(world, i + 21, j + 2, k + 16, Blocks.planks, 1);
		this.setBlock(world, i + 21, j + 2, k + 17, Blocks.planks, 1);
		this.setBlock(world, i + 21, j + 2, k + 18, Blocks.planks, 1);
		this.setBlock(world, i + 21, j + 2, k + 19, Blocks.planks, 1);
		this.setBlock(world, i + 21, j + 2, k + 20, Blocks.planks, 1);
		this.setBlock(world, i + 21, j + 2, k + 21, Blocks.planks, 1);
		this.setBlock(world, i + 21, j + 2, k + 22, Blocks.planks, 1);
		this.setBlock(world, i + 21, j + 2, k + 23, Blocks.planks, 1);
		this.setBlock(world, i + 21, j + 2, k + 24, Blocks.planks, 1);
		this.setBlock(world, i + 21, j + 2, k + 25, Blocks.planks, 1);
		this.setBlock(world, i + 21, j + 2, k + 26, Blocks.planks, 1);
		this.setBlock(world, i + 21, j + 2, k + 27, Blocks.planks, 1);
		this.setBlock(world, i + 21, j + 2, k + 28, Blocks.planks, 1);
		this.setBlock(world, i + 21, j + 2, k + 29, Blocks.planks, 1);
		this.setBlock(world, i + 21, j + 2, k + 30, Blocks.planks, 1);
		this.setBlock(world, i + 21, j + 2, k + 31, Blocks.planks, 1);
		this.setBlock(world, i + 21, j + 2, k + 32, Blocks.planks, 1);
		this.setBlock(world, i + 21, j + 2, k + 33, Blocks.planks, 1);
		this.setBlock(world, i + 21, j + 2, k + 34, Blocks.planks, 1);
		this.setBlock(world, i + 21, j + 2, k + 35, Blocks.planks, 1);
		this.setBlock(world, i + 21, j + 2, k + 36, Blocks.planks, 1);
		this.setBlock(world, i + 21, j + 2, k + 37, Blocks.planks, 1);
		this.setBlock(world, i + 21, j + 2, k + 38, Blocks.planks, 1);
		this.setBlock(world, i + 21, j + 2, k + 39, Blocks.planks, 1);
		this.setBlock(world, i + 21, j + 2, k + 40, Blocks.planks, 1);
		this.setBlock(world, i + 21, j + 2, k + 41, Blocks.planks, 1);
		this.setBlock(world, i + 21, j + 2, k + 42, Blocks.planks, 1);
		this.setBlock(world, i + 21, j + 2, k + 43, Blocks.planks, 1);
		this.setBlock(world, i + 21, j + 2, k + 44, Blocks.planks, 1);
		this.setBlock(world, i + 21, j + 3, k + 14, Blocks.fence, 0);
		this.setBlock(world, i + 21, j + 3, k + 15, Blocks.planks, 1);
		this.setBlock(world, i + 21, j + 3, k + 16, Blocks.planks, 1);
		this.setBlock(world, i + 21, j + 3, k + 17, Blocks.wooden_slab, 0);
		this.setBlock(world, i + 21, j + 3, k + 40, Blocks.air, 2);
		this.setBlock(world, i + 21, j + 3, k + 41, Blocks.planks, 1);
		this.setBlock(world, i + 21, j + 3, k + 42, Blocks.planks, 1);
		this.setBlock(world, i + 21, j + 3, k + 43, Blocks.planks, 1);
		this.setBlock(world, i + 21, j + 3, k + 44, Blocks.planks, 1);
		this.setBlock(world, i + 21, j + 3, k + 45, Blocks.planks, 1);
		this.setBlock(world, i + 21, j + 4, k + 14, Blocks.planks, 1);
		this.setBlock(world, i + 21, j + 4, k + 15, Blocks.wooden_slab, 0);
		this.setBlock(world, i + 21, j + 4, k + 41, Blocks.air, 2);
		this.setBlock(world, i + 21, j + 4, k + 42, Blocks.planks, 1);
		this.setBlock(world, i + 21, j + 4, k + 43, Blocks.planks, 1);
		this.setBlock(world, i + 21, j + 4, k + 44, Blocks.planks, 1);
		this.setBlock(world, i + 21, j + 4, k + 45, Blocks.planks, 1);
		this.setBlock(world, i + 21, j + 4, k + 46, Blocks.planks, 1);
		this.setBlock(world, i + 21, j + 5, k + 13, Blocks.planks, 1);
		this.setBlock(world, i + 21, j + 5, k + 14, Blocks.wooden_slab, 0);
		this.setBlock(world, i + 21, j + 5, k + 42, Blocks.air, 2);
		this.setBlock(world, i + 21, j + 5, k + 43, Blocks.planks, 1);
		this.setBlock(world, i + 21, j + 5, k + 44, Blocks.planks, 1);
		this.setBlock(world, i + 21, j + 5, k + 46, Blocks.planks, 1);
		this.setBlock(world, i + 21, j + 6, k + 13, Blocks.log, 1);
		this.setBlock(world, i + 21, j + 6, k + 14, Blocks.planks, 1);
		this.setBlock(world, i + 21, j + 6, k + 15, Blocks.planks, 1);
		this.setBlock(world, i + 21, j + 6, k + 16, Blocks.planks, 1);
		this.setBlock(world, i + 21, j + 6, k + 17, Blocks.planks, 1);
		this.setBlock(world, i + 21, j + 6, k + 18, Blocks.planks, 1);
		this.setBlock(world, i + 21, j + 6, k + 19, Blocks.planks, 1);
		this.setBlock(world, i + 21, j + 6, k + 20, Blocks.planks, 1);
		this.setBlock(world, i + 21, j + 6, k + 21, Blocks.planks, 1);
		this.setBlock(world, i + 21, j + 6, k + 22, Blocks.planks, 1);
		this.setBlock(world, i + 21, j + 6, k + 23, Blocks.planks, 1);
		this.setBlock(world, i + 21, j + 6, k + 24, Blocks.planks, 1);
		this.setBlock(world, i + 21, j + 6, k + 25, Blocks.planks, 1);
		this.setBlock(world, i + 21, j + 6, k + 26, Blocks.planks, 1);
		this.setBlock(world, i + 21, j + 6, k + 27, Blocks.planks, 1);
		this.setBlock(world, i + 21, j + 6, k + 28, Blocks.planks, 1);
		this.setBlock(world, i + 21, j + 6, k + 29, Blocks.planks, 1);
		this.setBlock(world, i + 21, j + 6, k + 30, Blocks.planks, 1);
		this.setBlock(world, i + 21, j + 6, k + 31, Blocks.planks, 1);
		this.setBlock(world, i + 21, j + 6, k + 32, Blocks.planks, 1);
		this.setBlock(world, i + 21, j + 6, k + 33, Blocks.planks, 1);
		this.setBlock(world, i + 21, j + 6, k + 34, Blocks.planks, 1);
		this.setBlock(world, i + 21, j + 6, k + 35, Blocks.planks, 1);
		this.setBlock(world, i + 21, j + 6, k + 36, Blocks.planks, 1);
		this.setBlock(world, i + 21, j + 6, k + 37, Blocks.planks, 1);
		this.setBlock(world, i + 21, j + 6, k + 38, Blocks.planks, 1);
		this.setBlock(world, i + 21, j + 6, k + 39, Blocks.planks, 1);
		this.setBlock(world, i + 21, j + 6, k + 43, Blocks.air, 2);
		this.setBlock(world, i + 21, j + 6, k + 44, Blocks.planks, 1);
		this.setBlock(world, i + 21, j + 6, k + 45, Blocks.planks, 1);
		this.setBlock(world, i + 21, j + 6, k + 46, Blocks.planks, 1);
		this.setBlock(world, i + 21, j + 6, k + 47, Blocks.log, 1);
		this.setBlock(world, i + 21, j + 7, k + 13, Blocks.log, 1);
		this.setBlock(world, i + 21, j + 7, k + 14, Blocks.wooden_slab, 0);
		this.setBlock(world, i + 21, j + 7, k + 27, Blocks.log, 1);
		//this.setBlock(world, i + 21, j + 7, k + 32, Blocks.blockSteel, 0);
		this.setBlock(world, i + 21, j + 7, k + 40, Blocks.wooden_slab, 1);
		//this.setBlock(world, i + 21, j + 7, k + 45, Blocks.blockSteel, 0);
		this.setBlock(world, i + 21, j + 7, k + 47, Blocks.air, 2);
		this.setBlock(world, i + 21, j + 7, k + 48, Blocks.log, 1);
		this.setBlock(world, i + 21, j + 8, k + 13, Blocks.air, 8);
		this.setBlock(world, i + 21, j + 8, k + 27, Blocks.log, 1);
		this.setBlock(world, i + 21, j + 8, k + 48, Blocks.glass, 0);
		this.setBlock(world, i + 21, j + 9, k + 13, Blocks.log, 1);
		this.setBlock(world, i + 21, j + 9, k + 14, Blocks.log, 1);
		this.setBlock(world, i + 21, j + 9, k + 15, Blocks.planks, 1);
		this.setBlock(world, i + 21, j + 9, k + 16, Blocks.planks, 1);
		this.setBlock(world, i + 21, j + 9, k + 17, Blocks.planks, 1);
		this.setBlock(world, i + 21, j + 9, k + 18, Blocks.planks, 1);
		this.setBlock(world, i + 21, j + 9, k + 19, Blocks.planks, 1);
		this.setBlock(world, i + 21, j + 9, k + 20, Blocks.planks, 1);
		this.setBlock(world, i + 21, j + 9, k + 21, Blocks.planks, 1);
		this.setBlock(world, i + 21, j + 9, k + 22, Blocks.planks, 1);
		this.setBlock(world, i + 21, j + 9, k + 23, Blocks.planks, 1);
		this.setBlock(world, i + 21, j + 9, k + 27, Blocks.log, 1);
		this.setBlock(world, i + 21, j + 9, k + 38, Blocks.planks, 1);
		this.setBlock(world, i + 21, j + 9, k + 39, Blocks.planks, 1);
		this.setBlock(world, i + 21, j + 9, k + 40, Blocks.planks, 1);
		this.setBlock(world, i + 21, j + 9, k + 41, Blocks.planks, 1);
		this.setBlock(world, i + 21, j + 9, k + 42, Blocks.planks, 1);
		this.setBlock(world, i + 21, j + 9, k + 43, Blocks.planks, 1);
		this.setBlock(world, i + 21, j + 9, k + 44, Blocks.planks, 1);
		this.setBlock(world, i + 21, j + 9, k + 45, Blocks.planks, 1);
		this.setBlock(world, i + 21, j + 9, k + 46, Blocks.planks, 1);
		this.setBlock(world, i + 21, j + 9, k + 48, Blocks.planks, 1);
		this.setBlock(world, i + 21, j + 9, k + 49, Blocks.log, 1);
		this.setBlock(world, i + 21, j + 10, k + 13, Blocks.air, 2);
		this.setBlock(world, i + 21, j + 10, k + 14, Blocks.log, 1);
		this.setBlock(world, i + 21, j + 10, k + 17, Blocks.log, 1);
		//this.setBlock(world, i + 21, j + 10, k + 20, Blocks.blockGold, 0);
		this.setBlock(world, i + 21, j + 10, k + 22, Blocks.log, 1);
		this.setBlock(world, i + 21, j + 10, k + 23, Blocks.fence, 0);
		this.setBlock(world, i + 21, j + 10, k + 27, Blocks.log, 1);
		this.setBlock(world, i + 21, j + 10, k + 38, Blocks.planks, 1);
		this.setBlock(world, i + 21, j + 10, k + 41, Blocks.log, 1);
		this.setBlock(world, i + 21, j + 10, k + 47, Blocks.log, 1);
		this.setBlock(world, i + 21, j + 10, k + 48, Blocks.planks, 1);
		this.setBlock(world, i + 21, j + 10, k + 49, Blocks.planks, 1);
		this.setBlock(world, i + 21, j + 10, k + 50, Blocks.log, 1);
		this.setBlock(world, i + 21, j + 11, k + 14, Blocks.fence, 0);
		this.setBlock(world, i + 21, j + 11, k + 17, Blocks.log, 1);
		this.setBlock(world, i + 21, j + 11, k + 22, Blocks.fence, 0);
		this.setBlock(world, i + 21, j + 11, k + 27, Blocks.log, 1);
		this.setBlock(world, i + 21, j + 11, k + 38, Blocks.fence, 0);
		this.setBlock(world, i + 21, j + 11, k + 41, Blocks.log, 1);
		this.setBlock(world, i + 21, j + 11, k + 47, Blocks.planks, 1);
		this.setBlock(world, i + 21, j + 11, k + 48, Blocks.planks, 1);
		this.setBlock(world, i + 21, j + 11, k + 49, Blocks.planks, 1);
		this.setBlock(world, i + 21, j + 11, k + 50, Blocks.planks, 1);
		this.setBlock(world, i + 21, j + 11, k + 51, Blocks.air, 7);
		this.setBlock(world, i + 21, j + 11, k + 52, Blocks.wooden_slab, 9);
		this.setBlock(world, i + 21, j + 12, k + 17, Blocks.log, 1);
		this.setBlock(world, i + 21, j + 12, k + 27, Blocks.log, 1);
		this.setBlock(world, i + 21, j + 12, k + 41, Blocks.log, 1);
		this.setBlock(world, i + 21, j + 12, k + 48, Blocks.wooden_slab, 0);
		this.setBlock(world, i + 21, j + 12, k + 49, Blocks.wooden_slab, 0);
		this.setBlock(world, i + 21, j + 12, k + 50, Blocks.wooden_slab, 0);
		this.setBlock(world, i + 21, j + 12, k + 51, Blocks.wooden_slab, 0);
		this.setBlock(world, i + 21, j + 12, k + 52, Blocks.wooden_slab, 0);
		this.setBlock(world, i + 21, j + 12, k + 53, Blocks.double_wooden_slab, 0);
		this.setBlock(world, i + 21, j + 12, k + 54, Blocks.double_wooden_slab, 0);
		this.setBlock(world, i + 21, j + 12, k + 55, Blocks.wooden_slab, 8);
		this.setBlock(world, i + 21, j + 12, k + 56, Blocks.wooden_slab, 8);
		this.setBlock(world, i + 21, j + 13, k + 17, Blocks.log, 1);
		this.setBlock(world, i + 21, j + 13, k + 27, Blocks.log, 1);
		this.setBlock(world, i + 21, j + 13, k + 41, Blocks.log, 1);
		this.setBlock(world, i + 21, j + 13, k + 55, Blocks.fence, 0);
		this.setBlock(world, i + 21, j + 13, k + 56, Blocks.fence, 0);
		this.setBlock(world, i + 21, j + 14, k + 17, Blocks.log, 1);
		this.setBlock(world, i + 21, j + 14, k + 27, Blocks.log, 1);
		this.setBlock(world, i + 21, j + 14, k + 30, Blocks.wool, 8);
		this.setBlock(world, i + 21, j + 14, k + 41, Blocks.log, 1);
		this.setBlock(world, i + 21, j + 14, k + 54, Blocks.fence, 0);
		this.setBlock(world, i + 21, j + 14, k + 55, Blocks.fence, 0);
		this.setBlock(world, i + 21, j + 15, k + 17, Blocks.log, 1);
		this.setBlock(world, i + 21, j + 15, k + 27, Blocks.log, 1);
		this.setBlock(world, i + 21, j + 15, k + 31, Blocks.wool, 8);
		this.setBlock(world, i + 21, j + 15, k + 41, Blocks.log, 1);
		this.setBlock(world, i + 21, j + 15, k + 44, Blocks.wool, 8);
		this.setBlock(world, i + 21, j + 15, k + 53, Blocks.fence, 0);
		this.setBlock(world, i + 21, j + 15, k + 54, Blocks.fence, 0);
		this.setBlock(world, i + 21, j + 16, k + 17, Blocks.log, 1);
		this.setBlock(world, i + 21, j + 16, k + 27, Blocks.log, 1);
		this.setBlock(world, i + 21, j + 16, k + 32, Blocks.wool, 8);
		this.setBlock(world, i + 21, j + 16, k + 41, Blocks.log, 1);
		this.setBlock(world, i + 21, j + 16, k + 45, Blocks.wool, 3);
		this.setBlock(world, i + 21, j + 16, k + 52, Blocks.fence, 0);
		this.setBlock(world, i + 21, j + 16, k + 53, Blocks.fence, 0);
		this.setBlock(world, i + 21, j + 17, k + 17, Blocks.log, 1);
		this.setBlock(world, i + 21, j + 17, k + 27, Blocks.log, 1);
		this.setBlock(world, i + 21, j + 17, k + 32, Blocks.wool, 7);
		this.setBlock(world, i + 21, j + 17, k + 41, Blocks.log, 1);
		this.setBlock(world, i + 21, j + 17, k + 45, Blocks.wool, 3);
		this.setBlock(world, i + 21, j + 17, k + 51, Blocks.fence, 0);
		this.setBlock(world, i + 21, j + 17, k + 52, Blocks.fence, 0);
		this.setBlock(world, i + 21, j + 18, k + 17, Blocks.log, 1);
		this.setBlock(world, i + 21, j + 18, k + 27, Blocks.log, 1);
		this.setBlock(world, i + 21, j + 18, k + 33, Blocks.wool, 8);
		this.setBlock(world, i + 21, j + 18, k + 41, Blocks.log, 1);
		this.setBlock(world, i + 21, j + 18, k + 45, Blocks.wool, 3);
		this.setBlock(world, i + 21, j + 18, k + 50, Blocks.fence, 0);
		this.setBlock(world, i + 21, j + 18, k + 51, Blocks.fence, 0);
		this.setBlock(world, i + 21, j + 19, k + 17, Blocks.log, 1);
		this.setBlock(world, i + 21, j + 19, k + 27, Blocks.log, 1);
		this.setBlock(world, i + 21, j + 19, k + 32, Blocks.wool, 7);
		this.setBlock(world, i + 21, j + 19, k + 41, Blocks.log, 1);
		this.setBlock(world, i + 21, j + 19, k + 45, Blocks.wool, 8);
		this.setBlock(world, i + 21, j + 19, k + 46, Blocks.wool, 8);
		this.setBlock(world, i + 21, j + 19, k + 49, Blocks.fence, 0);
		this.setBlock(world, i + 21, j + 19, k + 50, Blocks.fence, 0);
		this.setBlock(world, i + 21, j + 20, k + 17, Blocks.log, 1);
		this.setBlock(world, i + 21, j + 20, k + 27, Blocks.log, 1);
		this.setBlock(world, i + 21, j + 20, k + 32, Blocks.wool, 7);
		this.setBlock(world, i + 21, j + 20, k + 41, Blocks.log, 1);
		this.setBlock(world, i + 21, j + 20, k + 45, Blocks.wool, 3);
		this.setBlock(world, i + 21, j + 20, k + 48, Blocks.fence, 0);
		this.setBlock(world, i + 21, j + 20, k + 49, Blocks.fence, 0);
		this.setBlock(world, i + 21, j + 21, k + 17, Blocks.log, 1);
		this.setBlock(world, i + 21, j + 21, k + 27, Blocks.log, 1);
		this.setBlock(world, i + 21, j + 21, k + 31, Blocks.wool, 7);
		this.setBlock(world, i + 21, j + 21, k + 41, Blocks.log, 1);
		this.setBlock(world, i + 21, j + 21, k + 45, Blocks.wool, 7);
		this.setBlock(world, i + 21, j + 21, k + 47, Blocks.fence, 0);
		this.setBlock(world, i + 21, j + 21, k + 48, Blocks.fence, 0);
		this.setBlock(world, i + 21, j + 22, k + 17, Blocks.log, 1);
		this.setBlock(world, i + 21, j + 22, k + 27, Blocks.log, 1);
		this.setBlock(world, i + 21, j + 22, k + 30, Blocks.wool, 3);
		this.setBlock(world, i + 21, j + 22, k + 41, Blocks.log, 1);
		this.setBlock(world, i + 21, j + 22, k + 44, Blocks.wool, 8);
		this.setBlock(world, i + 21, j + 22, k + 46, Blocks.fence, 0);
		this.setBlock(world, i + 21, j + 22, k + 47, Blocks.fence, 0);
		this.setBlock(world, i + 21, j + 23, k + 17, Blocks.log, 1);
		this.setBlock(world, i + 21, j + 23, k + 27, Blocks.log, 1);
		this.setBlock(world, i + 21, j + 23, k + 29, Blocks.wool, 3);
		this.setBlock(world, i + 21, j + 23, k + 41, Blocks.log, 1);
		this.setBlock(world, i + 21, j + 23, k + 43, Blocks.wool, 8);
		this.setBlock(world, i + 21, j + 23, k + 45, Blocks.fence, 0);
		this.setBlock(world, i + 21, j + 23, k + 46, Blocks.fence, 0);
		this.setBlock(world, i + 21, j + 24, k + 17, Blocks.log, 1);
		this.setBlock(world, i + 21, j + 24, k + 27, Blocks.log, 1);
		this.setBlock(world, i + 21, j + 24, k + 28, Blocks.wool, 7);
		this.setBlock(world, i + 21, j + 24, k + 41, Blocks.log, 1);
		this.setBlock(world, i + 21, j + 24, k + 42, Blocks.wool, 8);
		this.setBlock(world, i + 21, j + 24, k + 44, Blocks.fence, 0);
		this.setBlock(world, i + 21, j + 24, k + 45, Blocks.fence, 0);
		this.setBlock(world, i + 21, j + 25, k + 17, Blocks.fence, 0);
		this.setBlock(world, i + 21, j + 25, k + 18, Blocks.fence, 0);
		this.setBlock(world, i + 21, j + 25, k + 27, Blocks.log, 1);
		this.setBlock(world, i + 21, j + 25, k + 41, Blocks.log, 1);
		this.setBlock(world, i + 21, j + 25, k + 43, Blocks.fence, 0);
		this.setBlock(world, i + 21, j + 25, k + 44, Blocks.fence, 0);
		this.setBlock(world, i + 21, j + 26, k + 18, Blocks.fence, 0);
		this.setBlock(world, i + 21, j + 26, k + 19, Blocks.fence, 0);
		this.setBlock(world, i + 21, j + 26, k + 27, Blocks.log, 1);
		this.setBlock(world, i + 21, j + 26, k + 28, Blocks.wool, 8);
		this.setBlock(world, i + 21, j + 26, k + 38, Blocks.fence, 0);
		this.setBlock(world, i + 21, j + 26, k + 39, Blocks.fence, 0);
		this.setBlock(world, i + 21, j + 26, k + 41, Blocks.log, 1);
		this.setBlock(world, i + 21, j + 26, k + 42, Blocks.fence, 0);
		this.setBlock(world, i + 21, j + 26, k + 43, Blocks.fence, 0);
		this.setBlock(world, i + 21, j + 27, k + 19, Blocks.fence, 0);
		this.setBlock(world, i + 21, j + 27, k + 20, Blocks.fence, 0);
		this.setBlock(world, i + 21, j + 27, k + 27, Blocks.log, 1);
		this.setBlock(world, i + 21, j + 27, k + 29, Blocks.wool, 8);
		this.setBlock(world, i + 21, j + 27, k + 36, Blocks.fence, 0);
		this.setBlock(world, i + 21, j + 27, k + 37, Blocks.fence, 0);
		this.setBlock(world, i + 21, j + 27, k + 38, Blocks.fence, 0);
		this.setBlock(world, i + 21, j + 27, k + 39, Blocks.fence, 0);
		this.setBlock(world, i + 21, j + 27, k + 40, Blocks.fence, 0);
		this.setBlock(world, i + 21, j + 27, k + 41, Blocks.log, 1);
		this.setBlock(world, i + 21, j + 27, k + 42, Blocks.fence, 0);
		this.setBlock(world, i + 21, j + 28, k + 20, Blocks.fence, 0);
		this.setBlock(world, i + 21, j + 28, k + 21, Blocks.fence, 0);
		this.setBlock(world, i + 21, j + 28, k + 27, Blocks.log, 1);
		this.setBlock(world, i + 21, j + 28, k + 30, Blocks.wool, 3);
		this.setBlock(world, i + 21, j + 28, k + 35, Blocks.fence, 0);
		this.setBlock(world, i + 21, j + 28, k + 36, Blocks.fence, 0);
		this.setBlock(world, i + 21, j + 28, k + 41, Blocks.wooden_slab, 1);
		this.setBlock(world, i + 21, j + 29, k + 21, Blocks.fence, 0);
		this.setBlock(world, i + 21, j + 29, k + 22, Blocks.fence, 0);
		this.setBlock(world, i + 21, j + 29, k + 27, Blocks.log, 1);
		this.setBlock(world, i + 21, j + 29, k + 30, Blocks.wool, 3);
		this.setBlock(world, i + 21, j + 29, k + 34, Blocks.fence, 0);
		this.setBlock(world, i + 21, j + 29, k + 35, Blocks.fence, 0);
		this.setBlock(world, i + 21, j + 30, k + 22, Blocks.fence, 0);
		this.setBlock(world, i + 21, j + 30, k + 23, Blocks.fence, 0);
		this.setBlock(world, i + 21, j + 30, k + 27, Blocks.log, 1);
		this.setBlock(world, i + 21, j + 30, k + 31, Blocks.wool, 8);
		this.setBlock(world, i + 21, j + 30, k + 33, Blocks.fence, 0);
		this.setBlock(world, i + 21, j + 30, k + 34, Blocks.fence, 0);
		this.setBlock(world, i + 21, j + 31, k + 23, Blocks.fence, 0);
		this.setBlock(world, i + 21, j + 31, k + 24, Blocks.fence, 0);
		this.setBlock(world, i + 21, j + 31, k + 27, Blocks.log, 1);
		this.setBlock(world, i + 21, j + 31, k + 30, Blocks.wool, 3);
		this.setBlock(world, i + 21, j + 31, k + 32, Blocks.fence, 0);
		this.setBlock(world, i + 21, j + 31, k + 33, Blocks.fence, 0);
		this.setBlock(world, i + 21, j + 32, k + 24, Blocks.fence, 0);
		this.setBlock(world, i + 21, j + 32, k + 25, Blocks.fence, 0);
		this.setBlock(world, i + 21, j + 32, k + 27, Blocks.log, 1);
		this.setBlock(world, i + 21, j + 32, k + 28, Blocks.wool, 3);
		this.setBlock(world, i + 21, j + 32, k + 29, Blocks.wool, 8);
		this.setBlock(world, i + 21, j + 32, k + 31, Blocks.fence, 0);
		this.setBlock(world, i + 21, j + 32, k + 32, Blocks.fence, 0);
		this.setBlock(world, i + 21, j + 33, k + 25, Blocks.fence, 0);
		this.setBlock(world, i + 21, j + 33, k + 26, Blocks.fence, 0);
		this.setBlock(world, i + 21, j + 33, k + 27, Blocks.log, 1);
		this.setBlock(world, i + 21, j + 33, k + 30, Blocks.fence, 0);
		this.setBlock(world, i + 21, j + 33, k + 31, Blocks.fence, 0);
		this.setBlock(world, i + 21, j + 34, k + 26, Blocks.fence, 0);
		this.setBlock(world, i + 21, j + 34, k + 27, Blocks.log, 1);
		this.setBlock(world, i + 21, j + 34, k + 28, Blocks.fence, 0);
		this.setBlock(world, i + 21, j + 34, k + 29, Blocks.fence, 0);
		this.setBlock(world, i + 21, j + 34, k + 30, Blocks.fence, 0);
		this.setBlock(world, i + 21, j + 35, k + 27, Blocks.wooden_slab, 1);
		this.setBlock(world, i + 22, j + 1, k + 17, Blocks.planks, 1);
		this.setBlock(world, i + 22, j + 1, k + 18, Blocks.planks, 1);
		this.setBlock(world, i + 22, j + 1, k + 19, Blocks.planks, 1);
		this.setBlock(world, i + 22, j + 1, k + 20, Blocks.planks, 1);
		this.setBlock(world, i + 22, j + 1, k + 21, Blocks.planks, 1);
		this.setBlock(world, i + 22, j + 1, k + 22, Blocks.planks, 1);
		this.setBlock(world, i + 22, j + 1, k + 23, Blocks.planks, 1);
		this.setBlock(world, i + 22, j + 1, k + 24, Blocks.planks, 1);
		this.setBlock(world, i + 22, j + 1, k + 25, Blocks.planks, 1);
		this.setBlock(world, i + 22, j + 1, k + 26, Blocks.planks, 1);
		this.setBlock(world, i + 22, j + 1, k + 27, Blocks.planks, 1);
		this.setBlock(world, i + 22, j + 1, k + 28, Blocks.planks, 1);
		this.setBlock(world, i + 22, j + 1, k + 29, Blocks.planks, 1);
		this.setBlock(world, i + 22, j + 1, k + 30, Blocks.planks, 1);
		this.setBlock(world, i + 22, j + 1, k + 31, Blocks.planks, 1);
		this.setBlock(world, i + 22, j + 1, k + 32, Blocks.planks, 1);
		this.setBlock(world, i + 22, j + 1, k + 33, Blocks.planks, 1);
		this.setBlock(world, i + 22, j + 1, k + 34, Blocks.planks, 1);
		this.setBlock(world, i + 22, j + 1, k + 35, Blocks.planks, 1);
		this.setBlock(world, i + 22, j + 1, k + 36, Blocks.planks, 1);
		this.setBlock(world, i + 22, j + 1, k + 37, Blocks.planks, 1);
		this.setBlock(world, i + 22, j + 1, k + 38, Blocks.planks, 1);
		this.setBlock(world, i + 22, j + 1, k + 39, Blocks.planks, 1);
		this.setBlock(world, i + 22, j + 1, k + 40, Blocks.planks, 1);
		this.setBlock(world, i + 22, j + 1, k + 41, Blocks.planks, 1);
		this.setBlock(world, i + 22, j + 2, k + 16, Blocks.planks, 1);
		this.setBlock(world, i + 22, j + 2, k + 17, Blocks.planks, 1);
		this.setBlock(world, i + 22, j + 2, k + 18, Blocks.planks, 1);
		this.setBlock(world, i + 22, j + 2, k + 19, Blocks.planks, 1);
		this.setBlock(world, i + 22, j + 2, k + 20, Blocks.planks, 1);
		this.setBlock(world, i + 22, j + 2, k + 21, Blocks.planks, 1);
		this.setBlock(world, i + 22, j + 2, k + 22, Blocks.planks, 1);
		this.setBlock(world, i + 22, j + 2, k + 23, Blocks.planks, 1);
		this.setBlock(world, i + 22, j + 2, k + 24, Blocks.planks, 1);
		this.setBlock(world, i + 22, j + 2, k + 25, Blocks.planks, 1);
		this.setBlock(world, i + 22, j + 2, k + 26, Blocks.planks, 1);
		this.setBlock(world, i + 22, j + 2, k + 27, Blocks.planks, 1);
		this.setBlock(world, i + 22, j + 2, k + 28, Blocks.planks, 1);
		this.setBlock(world, i + 22, j + 2, k + 29, Blocks.planks, 1);
		this.setBlock(world, i + 22, j + 2, k + 30, Blocks.planks, 1);
		this.setBlock(world, i + 22, j + 2, k + 31, Blocks.planks, 1);
		this.setBlock(world, i + 22, j + 2, k + 32, Blocks.planks, 1);
		this.setBlock(world, i + 22, j + 2, k + 33, Blocks.planks, 1);
		this.setBlock(world, i + 22, j + 2, k + 34, Blocks.planks, 1);
		this.setBlock(world, i + 22, j + 2, k + 35, Blocks.planks, 1);
		this.setBlock(world, i + 22, j + 2, k + 36, Blocks.planks, 1);
		this.setBlock(world, i + 22, j + 2, k + 37, Blocks.planks, 1);
		this.setBlock(world, i + 22, j + 2, k + 38, Blocks.planks, 1);
		this.setBlock(world, i + 22, j + 2, k + 39, Blocks.planks, 1);
		this.setBlock(world, i + 22, j + 2, k + 40, Blocks.planks, 1);
		this.setBlock(world, i + 22, j + 2, k + 41, Blocks.planks, 1);
		this.setBlock(world, i + 22, j + 2, k + 42, Blocks.planks, 1);
		this.setBlock(world, i + 22, j + 2, k + 43, Blocks.planks, 1);
		this.setBlock(world, i + 22, j + 3, k + 15, Blocks.planks, 1);
		this.setBlock(world, i + 22, j + 3, k + 16, Blocks.planks, 1);
		this.setBlock(world, i + 22, j + 3, k + 17, Blocks.wooden_slab, 0);
		//this.setBlock(world, i + 22, j + 3, k + 22, Blocks.blockSteel, 0);
		//this.setBlock(world, i + 22, j + 3, k + 25, Blocks.blockSteel, 0);
		//this.setBlock(world, i + 22, j + 3, k + 28, Blocks.blockSteel, 0);
		//this.setBlock(world, i + 22, j + 3, k + 31, Blocks.blockSteel, 0);
		//this.setBlock(world, i + 22, j + 3, k + 34, Blocks.blockSteel, 0);
		//this.setBlock(world, i + 22, j + 3, k + 37, Blocks.blockSteel, 0);
		this.setBlock(world, i + 22, j + 3, k + 43, Blocks.wooden_slab, 0);
		this.setBlock(world, i + 22, j + 3, k + 44, Blocks.planks, 1);
		this.setBlock(world, i + 22, j + 4, k + 14, Blocks.planks, 1);
		this.setBlock(world, i + 22, j + 4, k + 15, Blocks.wooden_slab, 0);
		this.setBlock(world, i + 22, j + 4, k + 44, Blocks.wooden_slab, 0);
		this.setBlock(world, i + 22, j + 4, k + 45, Blocks.planks, 1);
		this.setBlock(world, i + 22, j + 5, k + 13, Blocks.air, 6);
		//this.setBlock(world, i + 22, j + 5, k + 14, Blocks.blockDiamond, 0);
		this.setBlock(world, i + 22, j + 5, k + 45, Blocks.wooden_slab, 0);
		this.setBlock(world, i + 22, j + 5, k + 46, Blocks.planks, 1);
		this.setBlock(world, i + 22, j + 6, k + 13, Blocks.log, 1);
		this.setBlock(world, i + 22, j + 6, k + 14, Blocks.wooden_slab, 9);
		this.setBlock(world, i + 22, j + 6, k + 15, Blocks.planks, 1);
		this.setBlock(world, i + 22, j + 6, k + 16, Blocks.planks, 1);
		this.setBlock(world, i + 22, j + 6, k + 17, Blocks.planks, 1);
		this.setBlock(world, i + 22, j + 6, k + 18, Blocks.planks, 1);
		this.setBlock(world, i + 22, j + 6, k + 19, Blocks.planks, 1);
		this.setBlock(world, i + 22, j + 6, k + 20, Blocks.planks, 1);
		this.setBlock(world, i + 22, j + 6, k + 21, Blocks.planks, 1);
		this.setBlock(world, i + 22, j + 6, k + 22, Blocks.planks, 1);
		this.setBlock(world, i + 22, j + 6, k + 23, Blocks.planks, 1);
		this.setBlock(world, i + 22, j + 6, k + 24, Blocks.planks, 1);
		this.setBlock(world, i + 22, j + 6, k + 25, Blocks.planks, 1);
		this.setBlock(world, i + 22, j + 6, k + 26, Blocks.planks, 1);
		this.setBlock(world, i + 22, j + 6, k + 27, Blocks.planks, 1);
		this.setBlock(world, i + 22, j + 6, k + 28, Blocks.planks, 1);
		this.setBlock(world, i + 22, j + 6, k + 29, Blocks.planks, 1);
		this.setBlock(world, i + 22, j + 6, k + 30, Blocks.planks, 1);
		this.setBlock(world, i + 22, j + 6, k + 31, Blocks.planks, 1);
		this.setBlock(world, i + 22, j + 6, k + 32, Blocks.planks, 1);
		this.setBlock(world, i + 22, j + 6, k + 33, Blocks.planks, 1);
		this.setBlock(world, i + 22, j + 6, k + 34, Blocks.planks, 1);
		this.setBlock(world, i + 22, j + 6, k + 35, Blocks.planks, 1);
		this.setBlock(world, i + 22, j + 6, k + 36, Blocks.planks, 1);
		this.setBlock(world, i + 22, j + 6, k + 37, Blocks.planks, 1);
		this.setBlock(world, i + 22, j + 6, k + 38, Blocks.planks, 1);
		this.setBlock(world, i + 22, j + 6, k + 39, Blocks.planks, 1);
		this.setBlock(world, i + 22, j + 6, k + 40, Blocks.planks, 1);
		this.setBlock(world, i + 22, j + 6, k + 41, Blocks.planks, 1);
		this.setBlock(world, i + 22, j + 6, k + 42, Blocks.planks, 1);
		this.setBlock(world, i + 22, j + 6, k + 43, Blocks.planks, 1);
		this.setBlock(world, i + 22, j + 6, k + 44, Blocks.planks, 1);
		this.setBlock(world, i + 22, j + 6, k + 45, Blocks.planks, 1);
		this.setBlock(world, i + 22, j + 6, k + 46, Blocks.planks, 1);
		this.setBlock(world, i + 22, j + 6, k + 47, Blocks.log, 1);
		this.setBlock(world, i + 22, j + 7, k + 13, Blocks.log, 1);
		this.setBlock(world, i + 22, j + 7, k + 14, Blocks.air, 3);
		this.setBlock(world, i + 22, j + 7, k + 22, Blocks.air, 2);
		this.setBlock(world, i + 22, j + 7, k + 23, Blocks.planks, 1);
		this.setBlock(world, i + 22, j + 7, k + 38, Blocks.planks, 1);
		this.setBlock(world, i + 22, j + 7, k + 41, Blocks.wooden_slab, 1);
		this.setBlock(world, i + 22, j + 7, k + 42, Blocks.wooden_slab, 1);
		this.setBlock(world, i + 22, j + 7, k + 47, Blocks.log, 1);
		this.setBlock(world, i + 22, j + 8, k + 13, Blocks.air, 8);
		this.setBlock(world, i + 22, j + 8, k + 22, Blocks.wooden_slab, 8);
		this.setBlock(world, i + 22, j + 8, k + 23, Blocks.planks, 1);
		this.setBlock(world, i + 22, j + 8, k + 38, Blocks.planks, 1);
		this.setBlock(world, i + 22, j + 8, k + 47, Blocks.planks, 1);
		this.setBlock(world, i + 22, j + 8, k + 48, Blocks.planks, 1);
		this.setBlock(world, i + 22, j + 9, k + 13, Blocks.log, 1);
		this.setBlock(world, i + 22, j + 9, k + 14, Blocks.log, 1);
		this.setBlock(world, i + 22, j + 9, k + 15, Blocks.planks, 1);
		this.setBlock(world, i + 22, j + 9, k + 16, Blocks.planks, 1);
		this.setBlock(world, i + 22, j + 9, k + 17, Blocks.planks, 1);
		this.setBlock(world, i + 22, j + 9, k + 18, Blocks.planks, 1);
		this.setBlock(world, i + 22, j + 9, k + 19, Blocks.planks, 1);
		this.setBlock(world, i + 22, j + 9, k + 20, Blocks.planks, 1);
		this.setBlock(world, i + 22, j + 9, k + 21, Blocks.planks, 1);
		this.setBlock(world, i + 22, j + 9, k + 22, Blocks.planks, 1);
		this.setBlock(world, i + 22, j + 9, k + 23, Blocks.planks, 1);
		this.setBlock(world, i + 22, j + 9, k + 38, Blocks.planks, 1);
		this.setBlock(world, i + 22, j + 9, k + 39, Blocks.planks, 1);
		this.setBlock(world, i + 22, j + 9, k + 40, Blocks.planks, 1);
		this.setBlock(world, i + 22, j + 9, k + 41, Blocks.planks, 1);
		this.setBlock(world, i + 22, j + 9, k + 42, Blocks.planks, 1);
		this.setBlock(world, i + 22, j + 9, k + 43, Blocks.planks, 1);
		this.setBlock(world, i + 22, j + 9, k + 44, Blocks.planks, 1);
		this.setBlock(world, i + 22, j + 9, k + 45, Blocks.planks, 1);
		this.setBlock(world, i + 22, j + 9, k + 46, Blocks.planks, 1);
		this.setBlock(world, i + 22, j + 9, k + 47, Blocks.log, 1);
		this.setBlock(world, i + 22, j + 9, k + 48, Blocks.log, 1);
		this.setBlock(world, i + 22, j + 10, k + 13, Blocks.air, 2);
		this.setBlock(world, i + 22, j + 10, k + 14, Blocks.log, 1);
		this.setBlock(world, i + 22, j + 10, k + 23, Blocks.fence, 0);
		this.setBlock(world, i + 22, j + 10, k + 38, Blocks.planks, 1);
		this.setBlock(world, i + 22, j + 10, k + 47, Blocks.log, 1);
		this.setBlock(world, i + 22, j + 10, k + 48, Blocks.wooden_slab, 1);
		this.setBlock(world, i + 22, j + 11, k + 14, Blocks.fence, 0);
		this.setBlock(world, i + 22, j + 11, k + 38, Blocks.fence, 0);
		this.setBlock(world, i + 22, j + 11, k + 47, Blocks.planks, 1);
		this.setBlock(world, i + 22, j + 12, k + 47, Blocks.wooden_slab, 0);
		this.setBlock(world, i + 22, j + 13, k + 18, Blocks.wool, 7);
		this.setBlock(world, i + 22, j + 13, k + 19, Blocks.wool, 7);
		this.setBlock(world, i + 22, j + 13, k + 20, Blocks.wool, 3);
		this.setBlock(world, i + 22, j + 13, k + 21, Blocks.log, 1);
		this.setBlock(world, i + 22, j + 13, k + 27, Blocks.log, 1);
		this.setBlock(world, i + 22, j + 14, k + 19, Blocks.wool, 7);
		this.setBlock(world, i + 22, j + 14, k + 20, Blocks.log, 1);
		this.setBlock(world, i + 22, j + 14, k + 21, Blocks.wooden_slab, 1);
		this.setBlock(world, i + 22, j + 14, k + 27, Blocks.wooden_slab, 1);
		this.setBlock(world, i + 22, j + 14, k + 30, Blocks.wool, 3);
		this.setBlock(world, i + 22, j + 14, k + 41, Blocks.log, 1);
		this.setBlock(world, i + 22, j + 15, k + 18, Blocks.wool, 8);
		this.setBlock(world, i + 22, j + 15, k + 19, Blocks.log, 1);
		this.setBlock(world, i + 22, j + 15, k + 20, Blocks.wooden_slab, 1);
		this.setBlock(world, i + 22, j + 15, k + 31, Blocks.wool, 8);
		this.setBlock(world, i + 22, j + 15, k + 41, Blocks.wooden_slab, 1);
		this.setBlock(world, i + 22, j + 15, k + 43, Blocks.wool, 8);
		this.setBlock(world, i + 22, j + 15, k + 44, Blocks.wool, 3);
		this.setBlock(world, i + 22, j + 16, k + 17, Blocks.wool, 8);
		this.setBlock(world, i + 22, j + 16, k + 18, Blocks.log, 1);
		this.setBlock(world, i + 22, j + 16, k + 19, Blocks.wooden_slab, 1);
		this.setBlock(world, i + 22, j + 16, k + 31, Blocks.wool, 7);
		this.setBlock(world, i + 22, j + 16, k + 44, Blocks.wool, 3);
		this.setBlock(world, i + 22, j + 17, k + 10, Blocks.wool, 3);
		this.setBlock(world, i + 22, j + 17, k + 16, Blocks.wool, 3);
		this.setBlock(world, i + 22, j + 17, k + 17, Blocks.log, 1);
		this.setBlock(world, i + 22, j + 17, k + 18, Blocks.wooden_slab, 1);
		this.setBlock(world, i + 22, j + 17, k + 32, Blocks.wool, 7);
		this.setBlock(world, i + 22, j + 17, k + 45, Blocks.wool, 8);
		this.setBlock(world, i + 22, j + 18, k + 10, Blocks.wool, 8);
		this.setBlock(world, i + 22, j + 18, k + 15, Blocks.wool, 7);
		this.setBlock(world, i + 22, j + 18, k + 16, Blocks.log, 1);
		this.setBlock(world, i + 22, j + 18, k + 17, Blocks.wooden_slab, 1);
		this.setBlock(world, i + 22, j + 18, k + 32, Blocks.wool, 7);
		this.setBlock(world, i + 22, j + 18, k + 45, Blocks.wool, 8);
		this.setBlock(world, i + 22, j + 19, k + 11, Blocks.wool, 7);
		this.setBlock(world, i + 22, j + 19, k + 14, Blocks.wool, 8);
		this.setBlock(world, i + 22, j + 19, k + 15, Blocks.log, 1);
		this.setBlock(world, i + 22, j + 19, k + 16, Blocks.wooden_slab, 1);
		this.setBlock(world, i + 22, j + 19, k + 32, Blocks.wool, 7);
		this.setBlock(world, i + 22, j + 19, k + 45, Blocks.wool, 8);
		this.setBlock(world, i + 22, j + 20, k + 11, Blocks.wool, 7);
		this.setBlock(world, i + 22, j + 20, k + 13, Blocks.wool, 7);
		this.setBlock(world, i + 22, j + 20, k + 14, Blocks.log, 1);
		this.setBlock(world, i + 22, j + 20, k + 15, Blocks.wooden_slab, 1);
		this.setBlock(world, i + 22, j + 20, k + 31, Blocks.wool, 7);
		this.setBlock(world, i + 22, j + 20, k + 45, Blocks.wool, 8);
		this.setBlock(world, i + 22, j + 21, k + 11, Blocks.wool, 8);
		this.setBlock(world, i + 22, j + 21, k + 12, Blocks.wool, 7);
		this.setBlock(world, i + 22, j + 21, k + 13, Blocks.log, 1);
		this.setBlock(world, i + 22, j + 21, k + 14, Blocks.wooden_slab, 1);
		this.setBlock(world, i + 22, j + 21, k + 31, Blocks.wool, 8);
		this.setBlock(world, i + 22, j + 21, k + 44, Blocks.wool, 3);
		this.setBlock(world, i + 22, j + 22, k + 11, Blocks.wool, 8);
		this.setBlock(world, i + 22, j + 22, k + 12, Blocks.log, 1);
		this.setBlock(world, i + 22, j + 22, k + 13, Blocks.wooden_slab, 1);
		this.setBlock(world, i + 22, j + 22, k + 30, Blocks.wool, 3);
		this.setBlock(world, i + 22, j + 22, k + 44, Blocks.wool, 3);
		this.setBlock(world, i + 22, j + 23, k + 11, Blocks.log, 1);
		this.setBlock(world, i + 22, j + 23, k + 12, Blocks.wooden_slab, 1);
		this.setBlock(world, i + 22, j + 23, k + 29, Blocks.wool, 3);
		this.setBlock(world, i + 22, j + 23, k + 43, Blocks.wool, 8);
		this.setBlock(world, i + 22, j + 24, k + 11, Blocks.wooden_slab, 1);
		this.setBlock(world, i + 22, j + 24, k + 27, Blocks.log, 1);
		this.setBlock(world, i + 22, j + 24, k + 28, Blocks.wool, 8);
		this.setBlock(world, i + 22, j + 24, k + 41, Blocks.log, 1);
		this.setBlock(world, i + 22, j + 24, k + 42, Blocks.wool, 3);
		this.setBlock(world, i + 22, j + 25, k + 27, Blocks.wooden_slab, 1);
		this.setBlock(world, i + 22, j + 25, k + 41, Blocks.wooden_slab, 1);
		this.setBlock(world, i + 22, j + 26, k + 28, Blocks.wool, 7);
		this.setBlock(world, i + 22, j + 27, k + 29, Blocks.wool, 7);
		this.setBlock(world, i + 22, j + 28, k + 29, Blocks.wool, 8);
		this.setBlock(world, i + 22, j + 29, k + 30, Blocks.wool, 3);
		this.setBlock(world, i + 22, j + 30, k + 30, Blocks.wool, 3);
		this.setBlock(world, i + 22, j + 31, k + 29, Blocks.wool, 8);
		this.setBlock(world, i + 22, j + 32, k + 27, Blocks.log, 1);
		this.setBlock(world, i + 22, j + 32, k + 28, Blocks.wool, 8);
		this.setBlock(world, i + 22, j + 33, k + 27, Blocks.wooden_slab, 1);
		this.setBlock(world, i + 23, j + 2, k + 17, Blocks.planks, 1);
		this.setBlock(world, i + 23, j + 2, k + 18, Blocks.planks, 1);
		this.setBlock(world, i + 23, j + 2, k + 19, Blocks.planks, 1);
		this.setBlock(world, i + 23, j + 2, k + 20, Blocks.planks, 1);
		this.setBlock(world, i + 23, j + 2, k + 21, Blocks.planks, 1);
		this.setBlock(world, i + 23, j + 2, k + 22, Blocks.planks, 1);
		this.setBlock(world, i + 23, j + 2, k + 23, Blocks.planks, 1);
		this.setBlock(world, i + 23, j + 2, k + 24, Blocks.planks, 1);
		this.setBlock(world, i + 23, j + 2, k + 25, Blocks.planks, 1);
		this.setBlock(world, i + 23, j + 2, k + 26, Blocks.planks, 1);
		this.setBlock(world, i + 23, j + 2, k + 27, Blocks.planks, 1);
		this.setBlock(world, i + 23, j + 2, k + 28, Blocks.planks, 1);
		this.setBlock(world, i + 23, j + 2, k + 29, Blocks.planks, 1);
		this.setBlock(world, i + 23, j + 2, k + 30, Blocks.planks, 1);
		this.setBlock(world, i + 23, j + 2, k + 31, Blocks.planks, 1);
		this.setBlock(world, i + 23, j + 2, k + 32, Blocks.planks, 1);
		this.setBlock(world, i + 23, j + 2, k + 33, Blocks.planks, 1);
		this.setBlock(world, i + 23, j + 2, k + 34, Blocks.planks, 1);
		this.setBlock(world, i + 23, j + 2, k + 35, Blocks.planks, 1);
		this.setBlock(world, i + 23, j + 2, k + 36, Blocks.planks, 1);
		this.setBlock(world, i + 23, j + 2, k + 37, Blocks.planks, 1);
		this.setBlock(world, i + 23, j + 2, k + 38, Blocks.planks, 1);
		this.setBlock(world, i + 23, j + 2, k + 39, Blocks.planks, 1);
		this.setBlock(world, i + 23, j + 2, k + 40, Blocks.planks, 1);
		this.setBlock(world, i + 23, j + 2, k + 41, Blocks.planks, 1);
		this.setBlock(world, i + 23, j + 2, k + 42, Blocks.planks, 1);
		this.setBlock(world, i + 23, j + 3, k + 16, Blocks.planks, 1);
		this.setBlock(world, i + 23, j + 3, k + 17, Blocks.wooden_slab, 0);
		this.setBlock(world, i + 23, j + 3, k + 18, Blocks.wooden_slab, 0);
		this.setBlock(world, i + 23, j + 3, k + 19, Blocks.wooden_slab, 0);
		this.setBlock(world, i + 23, j + 3, k + 20, Blocks.wooden_slab, 0);
		this.setBlock(world, i + 23, j + 3, k + 21, Blocks.wooden_slab, 0);
		this.setBlock(world, i + 23, j + 3, k + 22, Blocks.wooden_slab, 0);
		this.setBlock(world, i + 23, j + 3, k + 23, Blocks.wooden_slab, 0);
		this.setBlock(world, i + 23, j + 3, k + 24, Blocks.wooden_slab, 0);
		this.setBlock(world, i + 23, j + 3, k + 25, Blocks.wooden_slab, 0);
		this.setBlock(world, i + 23, j + 3, k + 26, Blocks.wooden_slab, 0);
		this.setBlock(world, i + 23, j + 3, k + 27, Blocks.wooden_slab, 0);
		this.setBlock(world, i + 23, j + 3, k + 28, Blocks.wooden_slab, 0);
		this.setBlock(world, i + 23, j + 3, k + 29, Blocks.wooden_slab, 0);
		this.setBlock(world, i + 23, j + 3, k + 30, Blocks.wooden_slab, 0);
		this.setBlock(world, i + 23, j + 3, k + 31, Blocks.wooden_slab, 0);
		this.setBlock(world, i + 23, j + 3, k + 32, Blocks.wooden_slab, 0);
		this.setBlock(world, i + 23, j + 3, k + 33, Blocks.wooden_slab, 0);
		this.setBlock(world, i + 23, j + 3, k + 34, Blocks.wooden_slab, 0);
		this.setBlock(world, i + 23, j + 3, k + 35, Blocks.wooden_slab, 0);
		this.setBlock(world, i + 23, j + 3, k + 36, Blocks.wooden_slab, 0);
		this.setBlock(world, i + 23, j + 3, k + 37, Blocks.wooden_slab, 0);
		this.setBlock(world, i + 23, j + 3, k + 38, Blocks.wooden_slab, 0);
		this.setBlock(world, i + 23, j + 3, k + 39, Blocks.wooden_slab, 0);
		this.setBlock(world, i + 23, j + 3, k + 40, Blocks.wooden_slab, 0);
		this.setBlock(world, i + 23, j + 3, k + 41, Blocks.wooden_slab, 0);
		this.setBlock(world, i + 23, j + 3, k + 42, Blocks.wooden_slab, 0);
		this.setBlock(world, i + 23, j + 3, k + 43, Blocks.planks, 1);
		this.setBlock(world, i + 23, j + 4, k + 15, Blocks.planks, 1);
		this.setBlock(world, i + 23, j + 4, k + 16, Blocks.wooden_slab, 0);
		this.setBlock(world, i + 23, j + 4, k + 43, Blocks.wooden_slab, 0);
		this.setBlock(world, i + 23, j + 4, k + 44, Blocks.planks, 1);
		this.setBlock(world, i + 23, j + 5, k + 14, Blocks.planks, 1);
		this.setBlock(world, i + 23, j + 5, k + 15, Blocks.wooden_slab, 0);
		this.setBlock(world, i + 23, j + 5, k + 44, Blocks.wooden_slab, 0);

		generate2(world, rand, i, j, k);
		return true;
	}

	public boolean generate2(World world, Random rand, int i, int j, int k) {
		this.setBlock(world, i + 23, j + 5, k + 45, Blocks.planks, 1);
		this.setBlock(world, i + 23, j + 6, k + 14, Blocks.log, 1);
		this.setBlock(world, i + 23, j + 6, k + 15, Blocks.planks, 1);
		this.setBlock(world, i + 23, j + 6, k + 16, Blocks.planks, 1);
		this.setBlock(world, i + 23, j + 6, k + 17, Blocks.planks, 1);
		this.setBlock(world, i + 23, j + 6, k + 18, Blocks.planks, 1);
		this.setBlock(world, i + 23, j + 6, k + 19, Blocks.planks, 1);
		this.setBlock(world, i + 23, j + 6, k + 20, Blocks.planks, 1);
		this.setBlock(world, i + 23, j + 6, k + 21, Blocks.planks, 1);
		this.setBlock(world, i + 23, j + 6, k + 22, Blocks.planks, 1);
		this.setBlock(world, i + 23, j + 6, k + 23, Blocks.planks, 1);
		this.setBlock(world, i + 23, j + 6, k + 24, Blocks.planks, 1);
		this.setBlock(world, i + 23, j + 6, k + 25, Blocks.planks, 1);
		this.setBlock(world, i + 23, j + 6, k + 26, Blocks.planks, 1);
		this.setBlock(world, i + 23, j + 6, k + 27, Blocks.planks, 1);
		this.setBlock(world, i + 23, j + 6, k + 28, Blocks.planks, 1);
		this.setBlock(world, i + 23, j + 6, k + 29, Blocks.planks, 1);
		this.setBlock(world, i + 23, j + 6, k + 30, Blocks.planks, 1);
