/*
 * ** MADE BY MITHION'S .SCHEMATIC TO JAVA CONVERTING TOOLv0.1 ***
 */
package net.arcticraft.world.gen;

import java.util.Random;

import net.arcticraft.block.ACBlocks;
import net.arcticraft.entities.hostile.EntityCaptain;
import net.arcticraft.entities.hostile.EntityPirate;
import net.arcticraft.main.Arcticraft;
import net.minecraft.block.Block;
import net.minecraft.block.BlockFlower;
import net.minecraft.block.BlockSnow;
import net.minecraft.entity.item.EntityItem;
import net.minecraft.init.Blocks;
import net.minecraft.item.ItemStack;
import net.minecraft.tileentity.TileEntityChest;
import net.minecraft.util.WeightedRandomChestContent;
import net.minecraft.world.World;
import net.minecraft.world.gen.feature.WorldGenerator;
import net.minecraftforge.common.ChestGenHooks;

public class WorldGenShip extends WorldGenerator{

	private static final int SIZE_X = 16; // Ship Base
	private static final int SIZE_Y = 32;
	private static final int SIZE_Z = 64;
	private static final int PLATFORM_AREA = SIZE_X * SIZE_Z; // Ship Base
	private static final int VOLUME = SIZE_X * SIZE_Y * SIZE_Z; // Volume of the ship

	public WorldGenShip(){}

	public boolean checkSpawn(World world, Random rand, int x, int y, int z)
	{
		if(rand.nextInt(1000) > 5)
		{
			return false;
		}
		int validPlatformBlocks = 0;
		int validVolumeBlocks = 0;
		for(int xx = x; xx < x + SIZE_X; ++xx)
		{
			for(int zz = z; zz < z + SIZE_Z; ++zz)
			{
				if(world.getBlock(xx, y, zz) == ACBlocks.frostWaterBlock)
				{
					validPlatformBlocks++;
				}
				for(int yy = y; yy < y + SIZE_Y; ++yy)
				{
					Block block = world.getBlock(xx, yy, zz);
					if(block == Blocks.air || block == Blocks.log || block != null && block.isReplaceable(world, xx, yy, zz) || block.isLeaves(world, xx, yy, zz) || block instanceof BlockFlower || block instanceof BlockSnow)
					{
						validVolumeBlocks++;
					}
				}
			}
		}
		double validPlatformBlocksPercentage = validPlatformBlocks / PLATFORM_AREA * 100;
		double validAreaBlocksPercentage = validVolumeBlocks / VOLUME * 100; //
		// FMLLog.info("PlatformBlocks: %f ; VolumeBlocks: %f", validPlatformBlocksPercentage, validAreaBlocksPercentage);
		return(validPlatformBlocksPercentage == 100 && validAreaBlocksPercentage > 60);
	}

	public boolean generate(World world, Random rand, int x, int y, int z)
	{

		if(!checkSpawn(world, rand, x, y, z))
		{
			return false;
		}

		Arcticraft.notifyOfGenertion("Ship", Integer.toString(x), Integer.toString(z));
		world.setBlock(x + 7, y + 0, z + 6, Blocks.log, 13, 1);
		world.setBlock(x + 8, y + 0, z + 6, Blocks.log, 13, 1);
		world.setBlock(x + 9, y + 0, z + 6, Blocks.log, 13, 1);
		world.setBlock(x + 7, y + 0, z + 7, Blocks.log, 13, 1);
		world.setBlock(x + 8, y + 0, z + 7, Blocks.log, 13, 1);
		world.setBlock(x + 9, y + 0, z + 7, Blocks.log, 13, 1);
		world.setBlock(x + 6, y + 0, z + 8, Blocks.log, 13, 1);
		world.setBlock(x + 7, y + 0, z + 8, Blocks.log, 13, 1);
		world.setBlock(x + 8, y + 0, z + 8, Blocks.log, 13, 1);
		world.setBlock(x + 9, y + 0, z + 8, Blocks.log, 13, 1);
		world.setBlock(x + 10, y + 0, z + 8, Blocks.log, 13, 1);
		world.setBlock(x + 6, y + 0, z + 9, Blocks.log, 13, 1);
		world.setBlock(x + 7, y + 0, z + 9, Blocks.log, 13, 1);
		world.setBlock(x + 8, y + 0, z + 9, Blocks.log, 13, 1);
		world.setBlock(x + 9, y + 0, z + 9, Blocks.log, 13, 1);
		world.setBlock(x + 10, y + 0, z + 9, Blocks.log, 13, 1);
		world.setBlock(x + 6, y + 0, z + 10, Blocks.log, 13, 1);
		world.setBlock(x + 7, y + 0, z + 10, Blocks.log, 9, 1);
		world.setBlock(x + 8, y + 0, z + 10, Blocks.log, 9, 1);
		world.setBlock(x + 9, y + 0, z + 10, Blocks.log, 9, 1);
		world.setBlock(x + 10, y + 0, z + 10, Blocks.log, 13, 1);
		world.setBlock(x + 6, y + 0, z + 11, Blocks.log, 13, 1);
		world.setBlock(x + 7, y + 0, z + 11, Blocks.log, 9, 1);
		world.setBlock(x + 8, y + 0, z + 11, Blocks.log, 9, 1);
		world.setBlock(x + 9, y + 0, z + 11, Blocks.log, 9, 1);
		world.setBlock(x + 10, y + 0, z + 11, Blocks.log, 13, 1);
		world.setBlock(x + 6, y + 0, z + 12, Blocks.log, 13, 1);
		world.setBlock(x + 7, y + 0, z + 12, Blocks.log, 13, 1);
		world.setBlock(x + 8, y + 0, z + 12, Blocks.log, 13, 1);
		world.setBlock(x + 9, y + 0, z + 12, Blocks.log, 13, 1);
		world.setBlock(x + 10, y + 0, z + 12, Blocks.log, 13, 1);
		world.setBlock(x + 6, y + 0, z + 13, Blocks.log, 13, 1);
		world.setBlock(x + 7, y + 0, z + 13, Blocks.log, 13, 1);
		world.setBlock(x + 8, y + 0, z + 13, Blocks.log, 13, 1);
		world.setBlock(x + 9, y + 0, z + 13, Blocks.log, 13, 1);
		world.setBlock(x + 10, y + 0, z + 13, Blocks.log, 13, 1);
		world.setBlock(x + 6, y + 0, z + 14, Blocks.log, 13, 1);
		world.setBlock(x + 7, y + 0, z + 14, Blocks.log, 13, 1);
		world.setBlock(x + 8, y + 0, z + 14, Blocks.log, 13, 1);
		world.setBlock(x + 9, y + 0, z + 14, Blocks.log, 13, 1);
		world.setBlock(x + 10, y + 0, z + 14, Blocks.log, 13, 1);
		world.setBlock(x + 6, y + 0, z + 15, Blocks.log, 13, 1);
		world.setBlock(x + 7, y + 0, z + 15, Blocks.log, 13, 1);
		world.setBlock(x + 8, y + 0, z + 15, Blocks.log, 13, 1);
		world.setBlock(x + 9, y + 0, z + 15, Blocks.log, 13, 1);
		world.setBlock(x + 10, y + 0, z + 15, Blocks.log, 13, 1);
		world.setBlock(x + 6, y + 0, z + 16, Blocks.log, 9, 1);
		world.setBlock(x + 7, y + 0, z + 16, Blocks.log, 13, 1);
		world.setBlock(x + 8, y + 0, z + 16, Blocks.log, 13, 1);
		world.setBlock(x + 9, y + 0, z + 16, Blocks.log, 13, 1);
		world.setBlock(x + 10, y + 0, z + 16, Blocks.log, 9, 1);
		world.setBlock(x + 6, y + 0, z + 17, Blocks.log, 13, 1);
		world.setBlock(x + 7, y + 0, z + 17, Blocks.log, 13, 1);
		world.setBlock(x + 8, y + 0, z + 17, Blocks.log, 13, 1);
		world.setBlock(x + 9, y + 0, z + 17, Blocks.log, 13, 1);
		world.setBlock(x + 10, y + 0, z + 17, Blocks.log, 13, 1);
		world.setBlock(x + 6, y + 0, z + 18, Blocks.log, 9, 1);
		world.setBlock(x + 7, y + 0, z + 18, Blocks.log, 13, 1);
		world.setBlock(x + 8, y + 0, z + 18, Blocks.log, 13, 1);
		world.setBlock(x + 9, y + 0, z + 18, Blocks.log, 13, 1);
		world.setBlock(x + 10, y + 0, z + 18, Blocks.log, 9, 1);
		world.setBlock(x + 6, y + 0, z + 19, Blocks.log, 13, 1);
		world.setBlock(x + 7, y + 0, z + 19, Blocks.log, 13, 1);
		world.setBlock(x + 8, y + 0, z + 19, Blocks.log, 13, 1);
		world.setBlock(x + 9, y + 0, z + 19, Blocks.log, 13, 1);
		world.setBlock(x + 10, y + 0, z + 19, Blocks.log, 13, 1);
		world.setBlock(x + 6, y + 0, z + 20, Blocks.log, 9, 1);
		world.setBlock(x + 7, y + 0, z + 20, Blocks.log, 13, 1);
		world.setBlock(x + 8, y + 0, z + 20, Blocks.log, 13, 1);
		world.setBlock(x + 9, y + 0, z + 20, Blocks.log, 13, 1);
		world.setBlock(x + 10, y + 0, z + 20, Blocks.log, 9, 1);
		world.setBlock(x + 6, y + 0, z + 21, Blocks.log, 13, 1);
		world.setBlock(x + 7, y + 0, z + 21, Blocks.log, 13, 1);
		world.setBlock(x + 8, y + 0, z + 21, Blocks.log, 13, 1);
		world.setBlock(x + 9, y + 0, z + 21, Blocks.log, 13, 1);
		world.setBlock(x + 10, y + 0, z + 21, Blocks.log, 13, 1);
		world.setBlock(x + 6, y + 0, z + 22, Blocks.log, 9, 1);
		world.setBlock(x + 7, y + 0, z + 22, Blocks.log, 13, 1);
		world.setBlock(x + 8, y + 0, z + 22, Blocks.log, 13, 1);
		world.setBlock(x + 9, y + 0, z + 22, Blocks.log, 13, 1);
		world.setBlock(x + 10, y + 0, z + 22, Blocks.log, 9, 1);
		world.setBlock(x + 6, y + 0, z + 23, Blocks.log, 13, 1);
		world.setBlock(x + 7, y + 0, z + 23, Blocks.log, 13, 1);
		world.setBlock(x + 8, y + 0, z + 23, Blocks.log, 13, 1);
		world.setBlock(x + 9, y + 0, z + 23, Blocks.log, 13, 1);
		world.setBlock(x + 10, y + 0, z + 23, Blocks.log, 13, 1);
		world.setBlock(x + 6, y + 0, z + 24, Blocks.log, 9, 1);
		world.setBlock(x + 7, y + 0, z + 24, Blocks.log, 13, 1);
		world.setBlock(x + 8, y + 0, z + 24, Blocks.log, 13, 1);
		world.setBlock(x + 9, y + 0, z + 24, Blocks.log, 13, 1);
		world.setBlock(x + 10, y + 0, z + 24, Blocks.log, 9, 1);
		world.setBlock(x + 6, y + 0, z + 25, Blocks.log, 13, 1);
		world.setBlock(x + 7, y + 0, z + 25, Blocks.log, 13, 1);
		world.setBlock(x + 8, y + 0, z + 25, Blocks.log, 13, 1);
		world.setBlock(x + 9, y + 0, z + 25, Blocks.log, 13, 1);
		world.setBlock(x + 10, y + 0, z + 25, Blocks.log, 13, 1);
		world.setBlock(x + 6, y + 0, z + 26, Blocks.log, 13, 1);
		world.setBlock(x + 7, y + 0, z + 26, Blocks.log, 13, 1);
		world.setBlock(x + 8, y + 0, z + 26, Blocks.log, 13, 1);
		world.setBlock(x + 9, y + 0, z + 26, Blocks.log, 13, 1);
		world.setBlock(x + 10, y + 0, z + 26, Blocks.log, 13, 1);
		world.setBlock(x + 6, y + 0, z + 27, Blocks.log, 13, 1);
		world.setBlock(x + 7, y + 0, z + 27, Blocks.log, 13, 1);
		world.setBlock(x + 8, y + 0, z + 27, Blocks.log, 13, 1);
		world.setBlock(x + 9, y + 0, z + 27, Blocks.log, 13, 1);
		world.setBlock(x + 10, y + 0, z + 27, Blocks.log, 13, 1);
		world.setBlock(x + 6, y + 0, z + 28, Blocks.log, 13, 1);
		world.setBlock(x + 7, y + 0, z + 28, Blocks.log, 13, 1);
		world.setBlock(x + 8, y + 0, z + 28, Blocks.log, 13, 1);
		world.setBlock(x + 9, y + 0, z + 28, Blocks.log, 13, 1);
		world.setBlock(x + 10, y + 0, z + 28, Blocks.log, 13, 1);
		world.setBlock(x + 6, y + 0, z + 29, Blocks.log, 13, 1);
		world.setBlock(x + 7, y + 0, z + 29, Blocks.log, 13, 1);
		world.setBlock(x + 8, y + 0, z + 29, Blocks.log, 13, 1);
		world.setBlock(x + 9, y + 0, z + 29, Blocks.log, 13, 1);
		world.setBlock(x + 10, y + 0, z + 29, Blocks.log, 13, 1);
		world.setBlock(x + 7, y + 0, z + 30, Blocks.log, 13, 1);
		world.setBlock(x + 8, y + 0, z + 30, Blocks.log, 13, 1);
		world.setBlock(x + 9, y + 0, z + 30, Blocks.log, 13, 1);
		world.setBlock(x + 8, y + 0, z + 31, Blocks.log, 13, 1);
		world.setBlock(x + 6, y + 1, z + 6, Blocks.log, 13, 1);
		world.setBlock(x + 7, y + 1, z + 6, Blocks.log, 13, 1);
		world.setBlock(x + 8, y + 1, z + 6, Blocks.log, 13, 1);
		world.setBlock(x + 9, y + 1, z + 6, Blocks.log, 13, 1);
		world.setBlock(x + 10, y + 1, z + 6, Blocks.log, 13, 1);
		world.setBlock(x + 6, y + 1, z + 7, Blocks.log, 13, 1);
		world.setBlock(x + 10, y + 1, z + 7, Blocks.log, 13, 1);
		world.setBlock(x + 6, y + 1, z + 8, Blocks.log, 13, 1);
		world.setBlock(x + 10, y + 1, z + 8, Blocks.log, 13, 1);
		world.setBlock(x + 6, y + 1, z + 9, Blocks.log, 13, 1);
		world.setBlock(x + 10, y + 1, z + 9, Blocks.log, 13, 1);
		world.setBlock(x + 5, y + 1, z + 10, Blocks.log, 13, 1);
		world.setBlock(x + 6, y + 1, z + 10, Blocks.log, 13, 1);
		world.setBlock(x + 10, y + 1, z + 10, Blocks.log, 13, 1);
		world.setBlock(x + 11, y + 1, z + 10, Blocks.log, 13, 1);
		world.setBlock(x + 5, y + 1, z + 11, Blocks.log, 13, 1);
		world.setBlock(x + 6, y + 1, z + 11, Blocks.log, 13, 1);
		world.setBlock(x + 10, y + 1, z + 11, Blocks.log, 13, 1);
		world.setBlock(x + 11, y + 1, z + 11, Blocks.log, 13, 1);
		world.setBlock(x + 5, y + 1, z + 12, Blocks.log, 13, 1);
		world.setBlock(x + 6, y + 1, z + 12, Blocks.log, 13, 1);
		world.setBlock(x + 10, y + 1, z + 12, Blocks.log, 13, 1);
		world.setBlock(x + 11, y + 1, z + 12, Blocks.log, 13, 1);
		world.setBlock(x + 5, y + 1, z + 13, Blocks.log, 13, 1);
		world.setBlock(x + 6, y + 1, z + 13, Blocks.log, 13, 1);
		world.setBlock(x + 7, y + 1, z + 13, Blocks.log, 13, 1);
		world.setBlock(x + 8, y + 1, z + 13, Blocks.spruce_stairs, 2, 1);
		world.setBlock(x + 9, y + 1, z + 13, Blocks.log, 13, 1);
		world.setBlock(x + 10, y + 1, z + 13, Blocks.log, 13, 1);
		world.setBlock(x + 11, y + 1, z + 13, Blocks.log, 13, 1);
		world.setBlock(x + 5, y + 1, z + 14, Blocks.log, 13, 1);
		world.setBlock(x + 6, y + 1, z + 14, Blocks.log, 13, 1);
		world.setBlock(x + 7, y + 1, z + 14, Blocks.log, 13, 1);
		world.setBlock(x + 8, y + 1, z + 14, Blocks.log, 13, 1);
		world.setBlock(x + 9, y + 1, z + 14, Blocks.log, 13, 1);
		world.setBlock(x + 10, y + 1, z + 14, Blocks.log, 13, 1);
		world.setBlock(x + 11, y + 1, z + 14, Blocks.log, 13, 1);
		world.setBlock(x + 5, y + 1, z + 15, Blocks.log, 9, 1);
		world.setBlock(x + 7, y + 1, z + 15, Blocks.log, 13, 1);
		world.setBlock(x + 8, y + 1, z + 15, Blocks.log, 13, 1);
		world.setBlock(x + 9, y + 1, z + 15, Blocks.log, 13, 1);
		world.setBlock(x + 11, y + 1, z + 15, Blocks.log, 9, 1);
		world.setBlock(x + 5, y + 1, z + 16, Blocks.log, 13, 1);
		world.setBlock(x + 11, y + 1, z + 16, Blocks.log, 13, 1);
		world.setBlock(x + 5, y + 1, z + 17, Blocks.log, 9, 1);
		world.setBlock(x + 11, y + 1, z + 17, Blocks.log, 9, 1);
		world.setBlock(x + 5, y + 1, z + 18, Blocks.log, 13, 1);
		world.setBlock(x + 11, y + 1, z + 18, Blocks.log, 13, 1);
		world.setBlock(x + 5, y + 1, z + 19, Blocks.log, 9, 1);
		world.setBlock(x + 8, y + 1, z + 19, Blocks.log, 13, 1);
		world.setBlock(x + 11, y + 1, z + 19, Blocks.log, 9, 1);
		world.setBlock(x + 5, y + 1, z + 20, Blocks.log, 13, 1);
		world.setBlock(x + 11, y + 1, z + 20, Blocks.log, 13, 1);
		world.setBlock(x + 5, y + 1, z + 21, Blocks.log, 9, 1);
		world.setBlock(x + 11, y + 1, z + 21, Blocks.log, 9, 1);
		world.setBlock(x + 5, y + 1, z + 22, Blocks.log, 13, 1);
		world.setBlock(x + 11, y + 1, z + 22, Blocks.log, 13, 1);
		world.setBlock(x + 5, y + 1, z + 23, Blocks.log, 9, 1);
		world.setBlock(x + 11, y + 1, z + 23, Blocks.log, 9, 1);
		world.setBlock(x + 5, y + 1, z + 24, Blocks.log, 13, 1);
		world.setBlock(x + 11, y + 1, z + 24, Blocks.log, 13, 1);
		world.setBlock(x + 6, y + 1, z + 25, Blocks.log, 13, 1);
		world.setBlock(x + 8, y + 1, z + 25, Blocks.log, 1, 1);
		world.setBlock(x + 10, y + 1, z + 25, Blocks.log, 13, 1);
		world.setBlock(x + 6, y + 1, z + 26, Blocks.log, 13, 1);
		world.setBlock(x + 8, y + 1, z + 26, Blocks.ladder, 3, 1);
		world.setBlock(x + 10, y + 1, z + 26, Blocks.log, 13, 1);
		world.setBlock(x + 6, y + 1, z + 27, Blocks.log, 13, 1);
		world.setBlock(x + 10, y + 1, z + 27, Blocks.log, 13, 1);
		world.setBlock(x + 6, y + 1, z + 28, Blocks.log, 13, 1);
		world.setBlock(x + 8, y + 1, z + 28, Blocks.log, 13, 1);
		world.setBlock(x + 10, y + 1, z + 28, Blocks.log, 13, 1);
		world.setBlock(x + 6, y + 1, z + 29, Blocks.log, 13, 1);
		world.setBlock(x + 10, y + 1, z + 29, Blocks.log, 13, 1);
		world.setBlock(x + 6, y + 1, z + 30, Blocks.log, 13, 1);
		world.setBlock(x + 7, y + 1, z + 30, Blocks.log, 13, 1);
		world.setBlock(x + 8, y + 1, z + 30, Blocks.crafting_table, 0, 1);
		world.setBlock(x + 9, y + 1, z + 30, Blocks.log, 13, 1);
		world.setBlock(x + 10, y + 1, z + 30, Blocks.log, 13, 1);
		world.setBlock(x + 7, y + 1, z + 31, Blocks.log, 13, 1);
		world.setBlock(x + 8, y + 1, z + 31, Blocks.log, 13, 1);
		world.setBlock(x + 9, y + 1, z + 31, Blocks.log, 13, 1);
		world.setBlock(x + 8, y + 1, z + 32, Blocks.log, 13, 1);
		world.setBlock(x + 5, y + 2, z + 6, Blocks.log, 13, 1);
		world.setBlock(x + 6, y + 2, z + 6, Blocks.log, 13, 1);
		world.setBlock(x + 7, y + 2, z + 6, Blocks.log, 13, 1);
		world.setBlock(x + 8, y + 2, z + 6, Blocks.log, 13, 1);
		world.setBlock(x + 9, y + 2, z + 6, Blocks.log, 13, 1);
		world.setBlock(x + 10, y + 2, z + 6, Blocks.log, 13, 1);
		world.setBlock(x + 11, y + 2, z + 6, Blocks.log, 13, 1);
		world.setBlock(x + 5, y + 2, z + 7, Blocks.log, 13, 1);
		world.setBlock(x + 6, y + 2, z + 7, Blocks.furnace, 5, 1);
		world.setBlock(x + 10, y + 2, z + 7, Blocks.furnace, 1, 1);
		world.setBlock(x + 11, y + 2, z + 7, Blocks.log, 13, 1);
		world.setBlock(x + 5, y + 2, z + 8, Blocks.log, 13, 1);
		world.setBlock(x + 6, y + 2, z + 8, Blocks.log, 1, 1);
		world.setBlock(x + 10, y + 2, z + 8, Blocks.log, 1, 1);
		world.setBlock(x + 11, y + 2, z + 8, Blocks.log, 13, 1);
		world.setBlock(x + 5, y + 2, z + 9, Blocks.log, 13, 1);
		world.setBlock(x + 6, y + 2, z + 9, Blocks.furnace, 5, 1);
		world.setBlock(x + 10, y + 2, z + 9, Blocks.furnace, 1, 1);
		world.setBlock(x + 11, y + 2, z + 9, Blocks.log, 13, 1);
		world.setBlock(x + 5, y + 2, z + 10, Blocks.log, 13, 1);
		world.setBlock(x + 6, y + 2, z + 10, Blocks.log, 1, 1);
		world.setBlock(x + 10, y + 2, z + 10, Blocks.log, 1, 1);
		world.setBlock(x + 11, y + 2, z + 10, Blocks.log, 13, 1);
		world.setBlock(x + 5, y + 2, z + 11, Blocks.log, 13, 1);
		world.setBlock(x + 6, y + 2, z + 11, Blocks.furnace, 5, 1);
		world.setBlock(x + 10, y + 2, z + 11, Blocks.furnace, 1, 1);
		world.setBlock(x + 11, y + 2, z + 11, Blocks.log, 13, 1);
		world.setBlock(x + 5, y + 2, z + 12, Blocks.log, 13, 1);
		world.setBlock(x + 6, y + 2, z + 12, Blocks.log, 13, 1);
		world.setBlock(x + 10, y + 2, z + 12, Blocks.log, 13, 1);
		world.setBlock(x + 11, y + 2, z + 12, Blocks.log, 13, 1);
		world.setBlock(x + 5, y + 2, z + 13, Blocks.log, 13, 1);
		world.setBlock(x + 6, y + 2, z + 13, Blocks.log, 13, 1);
		world.setBlock(x + 7, y + 2, z + 13, Blocks.log, 13, 1);
		world.setBlock(x + 9, y + 2, z + 13, Blocks.log, 13, 1);
		world.setBlock(x + 10, y + 2, z + 13, Blocks.log, 13, 1);
		world.setBlock(x + 11, y + 2, z + 13, Blocks.log, 13, 1);
		world.setBlock(x + 5, y + 2, z + 14, Blocks.log, 13, 1);
		world.setBlock(x + 6, y + 2, z + 14, Blocks.log, 13, 1);
		world.setBlock(x + 7, y + 2, z + 14, Blocks.planks, 1, 1);
		world.setBlock(x + 8, y + 2, z + 14, Blocks.spruce_stairs, 2, 1);
		world.setBlock(x + 9, y + 2, z + 14, Blocks.planks, 1, 1);
		world.setBlock(x + 10, y + 2, z + 14, Blocks.log, 13, 1);
		world.setBlock(x + 11, y + 2, z + 14, Blocks.log, 13, 1);
		world.setBlock(x + 5, y + 2, z + 15, Blocks.iron_bars, 0, 1);
		world.setBlock(x + 7, y + 2, z + 15, Blocks.log, 13, 1);
		world.setBlock(x + 8, y + 2, z + 15, Blocks.log, 13, 1);
		world.setBlock(x + 9, y + 2, z + 15, Blocks.log, 13, 1);
		world.setBlock(x + 11, y + 2, z + 15, Blocks.iron_bars, 0, 1);
		world.setBlock(x + 5, y + 2, z + 16, Blocks.log, 13, 1);
		world.setBlock(x + 11, y + 2, z + 16, Blocks.log, 13, 1);
		world.setBlock(x + 5, y + 2, z + 17, Blocks.iron_bars, 0, 1);
		world.setBlock(x + 11, y + 2, z + 17, Blocks.iron_bars, 0, 1);
		world.setBlock(x + 5, y + 2, z + 18, Blocks.log, 13, 1);
		world.setBlock(x + 6, y + 2, z + 18, Blocks.torch, 1, 1);
		world.setBlock(x + 10, y + 2, z + 18, Blocks.torch, 2, 1);
		world.setBlock(x + 11, y + 2, z + 18, Blocks.log, 13, 1);
		world.setBlock(x + 5, y + 2, z + 19, Blocks.iron_bars, 0, 1);
		world.setBlock(x + 8, y + 2, z + 19, Blocks.log, 13, 1);
		world.setBlock(x + 11, y + 2, z + 19, Blocks.iron_bars, 0, 1);
		world.setBlock(x + 5, y + 2, z + 20, Blocks.log, 13, 1);
		world.setBlock(x + 11, y + 2, z + 20, Blocks.log, 13, 1);
		world.setBlock(x + 5, y + 2, z + 21, Blocks.iron_bars, 0, 1);
		world.setBlock(x + 11, y + 2, z + 21, Blocks.iron_bars, 0, 1);
		world.setBlock(x + 5, y + 2, z + 22, Blocks.log, 13, 1);
		world.setBlock(x + 6, y + 2, z + 22, Blocks.torch, 1, 1);
		world.setBlock(x + 10, y + 2, z + 22, Blocks.torch, 2, 1);
		world.setBlock(x + 11, y + 2, z + 22, Blocks.log, 13, 1);
		world.setBlock(x + 5, y + 2, z + 23, Blocks.iron_bars, 0, 1);
		world.setBlock(x + 11, y + 2, z + 23, Blocks.iron_bars, 0, 1);
		world.setBlock(x + 5, y + 2, z + 24, Blocks.log, 1, 1);
		world.setBlock(x + 11, y + 2, z + 24, Blocks.log, 13, 1);
		world.setBlock(x + 5, y + 2, z + 25, Blocks.log, 13, 1);
		world.setBlock(x + 8, y + 2, z + 25, Blocks.log, 1, 1);
		world.setBlock(x + 11, y + 2, z + 25, Blocks.log, 13, 1);
		world.setBlock(x + 5, y + 2, z + 26, Blocks.log, 13, 1);
		world.setBlock(x + 8, y + 2, z + 26, Blocks.ladder, 3, 1);
		world.setBlock(x + 11, y + 2, z + 26, Blocks.log, 13, 1);
		world.setBlock(x + 5, y + 2, z + 27, Blocks.log, 13, 1);
		world.setBlock(x + 11, y + 2, z + 27, Blocks.log, 13, 1);
		world.setBlock(x + 5, y + 2, z + 28, Blocks.log, 13, 1);
		world.setBlock(x + 8, y + 2, z + 28, Blocks.log, 13, 1);
		world.setBlock(x + 11, y + 2, z + 28, Blocks.log, 13, 1);
		world.setBlock(x + 5, y + 2, z + 29, Blocks.log, 13, 1);
		world.setBlock(x + 11, y + 2, z + 29, Blocks.log, 13, 1);
		world.setBlock(x + 6, y + 2, z + 30, Blocks.log, 13, 1);
		world.setBlock(x + 10, y + 2, z + 30, Blocks.log, 13, 1);
		world.setBlock(x + 11, y + 2, z + 30, Blocks.log, 13, 1);
		world.setBlock(x + 6, y + 2, z + 31, Blocks.log, 13, 1);
		world.setBlock(x + 7, y + 2, z + 31, Blocks.log, 13, 1);
		world.setBlock(x + 9, y + 2, z + 31, Blocks.log, 13, 1);
		world.setBlock(x + 10, y + 2, z + 31, Blocks.log, 13, 1);
		world.setBlock(x + 7, y + 2, z + 32, Blocks.log, 13, 1);
		world.setBlock(x + 8, y + 2, z + 32, Blocks.log, 13, 1);
		world.setBlock(x + 9, y + 2, z + 32, Blocks.log, 13, 1);
		world.setBlock(x + 8, y + 2, z + 33, Blocks.log, 13, 1);
		world.setBlock(x + 5, y + 3, z + 6, Blocks.log, 13, 1);
		world.setBlock(x + 6, y + 3, z + 6, Blocks.log, 13, 1);
		world.setBlock(x + 7, y + 3, z + 6, Blocks.log, 13, 1);
		world.setBlock(x + 8, y + 3, z + 6, Blocks.log, 13, 1);
		world.setBlock(x + 9, y + 3, z + 6, Blocks.log, 13, 1);
		world.setBlock(x + 10, y + 3, z + 6, Blocks.log, 13, 1);
		world.setBlock(x + 11, y + 3, z + 6, Blocks.log, 13, 1);
		world.setBlock(x + 5, y + 3, z + 7, Blocks.log, 13, 1);
		world.setBlock(x + 6, y + 3, z + 7, Blocks.log, 13, 1);
		world.setBlock(x + 7, y + 3, z + 7, Blocks.torch, 3, 1);
		world.setBlock(x + 9, y + 3, z + 7, Blocks.torch, 3, 1);
		world.setBlock(x + 10, y + 3, z + 7, Blocks.log, 13, 1);
		world.setBlock(x + 11, y + 3, z + 7, Blocks.log, 13, 1);
		world.setBlock(x + 5, y + 3, z + 8, Blocks.log, 13, 1);
		world.setBlock(x + 6, y + 3, z + 8, Blocks.log, 1, 1);
		world.setBlock(x + 10, y + 3, z + 8, Blocks.log, 1, 1);
		world.setBlock(x + 11, y + 3, z + 8, Blocks.log, 13, 1);
		world.setBlock(x + 5, y + 3, z + 9, Blocks.log, 13, 1);
		world.setBlock(x + 6, y + 3, z + 9, Blocks.log, 13, 1);
		world.setBlock(x + 10, y + 3, z + 9, Blocks.log, 13, 1);
		world.setBlock(x + 11, y + 3, z + 9, Blocks.log, 13, 1);
		world.setBlock(x + 5, y + 3, z + 10, Blocks.log, 13, 1);
		world.setBlock(x + 6, y + 3, z + 10, Blocks.log, 1, 1);
		world.setBlock(x + 10, y + 3, z + 10, Blocks.log, 1, 1);
		world.setBlock(x + 11, y + 3, z + 10, Blocks.log, 13, 1);
		world.setBlock(x + 5, y + 3, z + 11, Blocks.log, 13, 1);
		world.setBlock(x + 6, y + 3, z + 11, Blocks.log, 13, 1);
		world.setBlock(x + 10, y + 3, z + 11, Blocks.log, 13, 1);
		world.setBlock(x + 11, y + 3, z + 11, Blocks.log, 13, 1);
		world.setBlock(x + 5, y + 3, z + 12, Blocks.log, 13, 1);
		world.setBlock(x + 6, y + 3, z + 12, Blocks.log, 13, 1);
		world.setBlock(x + 7, y + 3, z + 12, Blocks.torch, 4, 1);
		world.setBlock(x + 9, y + 3, z + 12, Blocks.torch, 4, 1);
		world.setBlock(x + 10, y + 3, z + 12, Blocks.log, 13, 1);
		world.setBlock(x + 11, y + 3, z + 12, Blocks.log, 13, 1);
		world.setBlock(x + 5, y + 3, z + 13, Blocks.log, 13, 1);
		world.setBlock(x + 6, y + 3, z + 13, Blocks.log, 13, 1);
		world.setBlock(x + 7, y + 3, z + 13, Blocks.log, 13, 1);
		world.setBlock(x + 9, y + 3, z + 13, Blocks.log, 13, 1);
		world.setBlock(x + 10, y + 3, z + 13, Blocks.log, 13, 1);
		world.setBlock(x + 11, y + 3, z + 13, Blocks.log, 13, 1);
		world.setBlock(x + 5, y + 3, z + 14, Blocks.log, 13, 1);
		world.setBlock(x + 6, y + 3, z + 14, Blocks.log, 13, 1);
		world.setBlock(x + 7, y + 3, z + 14, Blocks.planks, 1, 1);
		world.setBlock(x + 9, y + 3, z + 14, Blocks.planks, 1, 1);
		world.setBlock(x + 10, y + 3, z + 14, Blocks.log, 13, 1);
		world.setBlock(x + 11, y + 3, z + 14, Blocks.log, 13, 1);
		world.setBlock(x + 5, y + 3, z + 15, Blocks.iron_bars, 0, 1);
		world.setBlock(x + 7, y + 3, z + 15, Blocks.planks, 1, 1);
		world.setBlock(x + 8, y + 3, z + 15, Blocks.spruce_stairs, 2, 1);
		world.setBlock(x + 9, y + 3, z + 15, Blocks.planks, 1, 1);
		world.setBlock(x + 11, y + 3, z + 15, Blocks.iron_bars, 0, 1);
		world.setBlock(x + 5, y + 3, z + 16, Blocks.log, 13, 1);
		world.setBlock(x + 8, y + 3, z + 16, Blocks.planks, 1, 1);
		world.setBlock(x + 11, y + 3, z + 16, Blocks.log, 13, 1);
		world.setBlock(x + 5, y + 3, z + 17, Blocks.iron_bars, 0, 1);
		world.setBlock(x + 11, y + 3, z + 17, Blocks.iron_bars, 0, 1);
		world.setBlock(x + 5, y + 3, z + 18, Blocks.log, 13, 1);
		world.setBlock(x + 11, y + 3, z + 18, Blocks.log, 13, 1);
		world.setBlock(x + 5, y + 3, z + 19, Blocks.iron_bars, 0, 1);
		world.setBlock(x + 8, y + 3, z + 19, Blocks.log, 13, 1);
		world.setBlock(x + 11, y + 3, z + 19, Blocks.iron_bars, 0, 1);
		world.setBlock(x + 5, y + 3, z + 20, Blocks.log, 13, 1);
		world.setBlock(x + 11, y + 3, z + 20, Blocks.log, 13, 1);
		world.setBlock(x + 5, y + 3, z + 21, Blocks.iron_bars, 0, 1);
		world.setBlock(x + 11, y + 3, z + 21, Blocks.iron_bars, 0, 1);
		world.setBlock(x + 5, y + 3, z + 22, Blocks.log, 13, 1);
		world.setBlock(x + 11, y + 3, z + 22, Blocks.log, 13, 1);
		world.setBlock(x + 5, y + 3, z + 23, Blocks.iron_bars, 0, 1);
		world.setBlock(x + 11, y + 3, z + 23, Blocks.iron_bars, 0, 1);
		world.setBlock(x + 5, y + 3, z + 24, Blocks.log, 13, 1);
		world.setBlock(x + 11, y + 3, z + 24, Blocks.log, 13, 1);
		world.setBlock(x + 5, y + 3, z + 25, Blocks.log, 13, 1);
		world.setBlock(x + 8, y + 3, z + 25, Blocks.log, 1, 1);
		world.setBlock(x + 11, y + 3, z + 25, Blocks.log, 13, 1);
		world.setBlock(x + 5, y + 3, z + 26, Blocks.log, 13, 1);
		world.setBlock(x + 8, y + 3, z + 26, Blocks.ladder, 3, 1);
		world.setBlock(x + 11, y + 3, z + 26, Blocks.log, 13, 1);
		world.setBlock(x + 5, y + 3, z + 27, Blocks.log, 13, 1);
		world.setBlock(x + 11, y + 3, z + 27, Blocks.log, 13, 1);
		world.setBlock(x + 5, y + 3, z + 28, Blocks.log, 13, 1);
		world.setBlock(x + 8, y + 3, z + 28, Blocks.log, 13, 1);
		world.setBlock(x + 11, y + 3, z + 28, Blocks.log, 13, 1);
		world.setBlock(x + 5, y + 3, z + 29, Blocks.log, 13, 1);
		world.setBlock(x + 11, y + 3, z + 29, Blocks.log, 13, 1);
		world.setBlock(x + 5, y + 3, z + 30, Blocks.log, 13, 1);
		world.setBlock(x + 11, y + 3, z + 30, Blocks.log, 13, 1);
		world.setBlock(x + 5, y + 3, z + 31, Blocks.log, 13, 1);
		world.setBlock(x + 11, y + 3, z + 31, Blocks.log, 13, 1);
		world.setBlock(x + 6, y + 3, z + 32, Blocks.log, 13, 1);
		world.setBlock(x + 7, y + 3, z + 32, Blocks.log, 13, 1);
		world.setBlock(x + 9, y + 3, z + 32, Blocks.log, 13, 1);
		world.setBlock(x + 10, y + 3, z + 32, Blocks.log, 13, 1);
		world.setBlock(x + 7, y + 3, z + 33, Blocks.log, 13, 1);
		world.setBlock(x + 8, y + 3, z + 33, Blocks.log, 13, 1);
		world.setBlock(x + 9, y + 3, z + 33, Blocks.log, 13, 1);
		world.setBlock(x + 8, y + 3, z + 34, Blocks.log, 13, 1);
		world.setBlock(x + 5, y + 4, z + 5, Blocks.log, 13, 1);
		world.setBlock(x + 6, y + 4, z + 5, Blocks.log, 13, 1);
		world.setBlock(x + 7, y + 4, z + 5, Blocks.log, 13, 1);
		world.setBlock(x + 8, y + 4, z + 5, Blocks.log, 13, 1);
		world.setBlock(x + 9, y + 4, z + 5, Blocks.log, 13, 1);
		world.setBlock(x + 10, y + 4, z + 5, Blocks.log, 13, 1);
		world.setBlock(x + 11, y + 4, z + 5, Blocks.log, 13, 1);
		world.setBlock(x + 5, y + 4, z + 6, Blocks.log, 13, 1);
		world.setBlock(x + 6, y + 4, z + 6, Blocks.log, 13, 1);
		world.setBlock(x + 7, y + 4, z + 6, Blocks.log, 13, 1);
		world.setBlock(x + 8, y + 4, z + 6, Blocks.log, 13, 1);
		world.setBlock(x + 9, y + 4, z + 6, Blocks.log, 13, 1);
		world.setBlock(x + 10, y + 4, z + 6, Blocks.log, 13, 1);
		world.setBlock(x + 11, y + 4, z + 6, Blocks.log, 13, 1);
		world.setBlock(x + 5, y + 4, z + 7, Blocks.glass, 0, 1);
		world.setBlock(x + 11, y + 4, z + 7, Blocks.glass, 0, 1);
		world.setBlock(x + 5, y + 4, z + 8, Blocks.log, 13, 1);
		world.setBlock(x + 6, y + 4, z + 8, Blocks.log, 13, 1);
		world.setBlock(x + 10, y + 4, z + 8, Blocks.log, 13, 1);
		world.setBlock(x + 11, y + 4, z + 8, Blocks.log, 13, 1);
		world.setBlock(x + 5, y + 4, z + 9, Blocks.glass, 0, 1);
		world.setBlock(x + 11, y + 4, z + 9, Blocks.glass, 0, 1);
		world.setBlock(x + 5, y + 4, z + 10, Blocks.log, 13, 1);
		world.setBlock(x + 6, y + 4, z + 10, Blocks.log, 13, 1);
		world.setBlock(x + 10, y + 4, z + 10, Blocks.log, 13, 1);
		world.setBlock(x + 11, y + 4, z + 10, Blocks.log, 13, 1);
		world.setBlock(x + 5, y + 4, z + 11, Blocks.glass, 0, 1);
		world.setBlock(x + 11, y + 4, z + 11, Blocks.glass, 0, 1);
		world.setBlock(x + 5, y + 4, z + 12, Blocks.log, 13, 1);
		world.setBlock(x + 6, y + 4, z + 12, Blocks.log, 13, 1);
		world.setBlock(x + 10, y + 4, z + 12, Blocks.log, 13, 1);
		world.setBlock(x + 11, y + 4, z + 12, Blocks.log, 13, 1);
		world.setBlock(x + 5, y + 4, z + 13, Blocks.log, 13, 1);
		world.setBlock(x + 6, y + 4, z + 13, Blocks.log, 13, 1);
		world.setBlock(x + 7, y + 4, z + 13, Blocks.log, 13, 1);
		world.setBlock(x + 9, y + 4, z + 13, Blocks.log, 13, 1);
		world.setBlock(x + 10, y + 4, z + 13, Blocks.log, 13, 1);
		world.setBlock(x + 11, y + 4, z + 13, Blocks.log, 13, 1);
		world.setBlock(x + 4, y + 4, z + 14, Blocks.log, 13, 1);
		world.setBlock(x + 5, y + 4, z + 14, Blocks.planks, 1, 1);
		world.setBlock(x + 6, y + 4, z + 14, Blocks.planks, 1, 1);
		world.setBlock(x + 7, y + 4, z + 14, Blocks.planks, 1, 1);
		world.setBlock(x + 9, y + 4, z + 14, Blocks.planks, 1, 1);
		world.setBlock(x + 10, y + 4, z + 14, Blocks.planks, 1, 1);
		world.setBlock(x + 11, y + 4, z + 14, Blocks.planks, 1, 1);
		world.setBlock(x + 12, y + 4, z + 14, Blocks.log, 13, 1);
		world.setBlock(x + 4, y + 4, z + 15, Blocks.log, 13, 1);
		world.setBlock(x + 5, y + 4, z + 15, Blocks.planks, 1, 1);
		world.setBlock(x + 6, y + 4, z + 15, Blocks.planks, 1, 1);
		world.setBlock(x + 7, y + 4, z + 15, Blocks.planks, 1, 1);
		world.setBlock(x + 9, y + 4, z + 15, Blocks.planks, 1, 1);
		world.setBlock(x + 10, y + 4, z + 15, Blocks.planks, 1, 1);
		world.setBlock(x + 11, y + 4, z + 15, Blocks.planks, 1, 1);
		world.setBlock(x + 12, y + 4, z + 15, Blocks.log, 13, 1);
		world.setBlock(x + 4, y + 4, z + 16, Blocks.log, 13, 1);
		world.setBlock(x + 5, y + 4, z + 16, Blocks.planks, 1, 1);
		world.setBlock(x + 6, y + 4, z + 16, Blocks.planks, 1, 1);
		world.setBlock(x + 7, y + 4, z + 16, Blocks.planks, 1, 1);
		world.setBlock(x + 8, y + 4, z + 16, Blocks.spruce_stairs, 2, 1);
		world.setBlock(x + 9, y + 4, z + 16, Blocks.planks, 1, 1);
		world.setBlock(x + 10, y + 4, z + 16, Blocks.planks, 1, 1);
		world.setBlock(x + 11, y + 4, z + 16, Blocks.planks, 1, 1);
		world.setBlock(x + 12, y + 4, z + 16, Blocks.log, 13, 1);
		world.setBlock(x + 4, y + 4, z + 17, Blocks.log, 13, 1);
		world.setBlock(x + 5, y + 4, z + 17, Blocks.planks, 1, 1);
		world.setBlock(x + 6, y + 4, z + 17, Blocks.planks, 1, 1);
		world.setBlock(x + 7, y + 4, z + 17, Blocks.planks, 1, 1);
		world.setBlock(x + 8, y + 4, z + 17, Blocks.planks, 1, 1);
		world.setBlock(x + 9, y + 4, z + 17, Blocks.planks, 1, 1);
		world.setBlock(x + 10, y + 4, z + 17, Blocks.planks, 1, 1);
		world.setBlock(x + 11, y + 4, z + 17, Blocks.planks, 1, 1);
		world.setBlock(x + 12, y + 4, z + 17, Blocks.log, 13, 1);
		world.setBlock(x + 4, y + 4, z + 18, Blocks.log, 13, 1);
		world.setBlock(x + 5, y + 4, z + 18, Blocks.planks, 1, 1);
		world.setBlock(x + 6, y + 4, z + 18, Blocks.planks, 1, 1);
		world.setBlock(x + 7, y + 4, z + 18, Blocks.planks, 1, 1);
		world.setBlock(x + 8, y + 4, z + 18, Blocks.planks, 1, 1);
		world.setBlock(x + 9, y + 4, z + 18, Blocks.planks, 1, 1);
		world.setBlock(x + 10, y + 4, z + 18, Blocks.planks, 1, 1);
		world.setBlock(x + 11, y + 4, z + 18, Blocks.planks, 1, 1);
		world.setBlock(x + 12, y + 4, z + 18, Blocks.log, 13, 1);
		world.setBlock(x + 4, y + 4, z + 19, Blocks.log, 13, 1);
		world.setBlock(x + 5, y + 4, z + 19, Blocks.planks, 1, 1);
		world.setBlock(x + 6, y + 4, z + 19, Blocks.planks, 1, 1);
		world.setBlock(x + 7, y + 4, z + 19, Blocks.planks, 1, 1);
		world.setBlock(x + 8, y + 4, z + 19, Blocks.log, 13, 1);
		world.setBlock(x + 9, y + 4, z + 19, Blocks.planks, 1, 1);
		world.setBlock(x + 10, y + 4, z + 19, Blocks.planks, 1, 1);
		world.setBlock(x + 11, y + 4, z + 19, Blocks.planks, 1, 1);
		world.setBlock(x + 12, y + 4, z + 19, Blocks.log, 13, 1);
		world.setBlock(x + 4, y + 4, z + 20, Blocks.log, 13, 1);
		world.setBlock(x + 5, y + 4, z + 20, Blocks.planks, 1, 1);
		world.setBlock(x + 6, y + 4, z + 20, Blocks.planks, 1, 1);
		world.setBlock(x + 7, y + 4, z + 20, Blocks.planks, 1, 1);
		world.setBlock(x + 8, y + 4, z + 20, Blocks.planks, 1, 1);
		world.setBlock(x + 9, y + 4, z + 20, Blocks.planks, 1, 1);
		world.setBlock(x + 10, y + 4, z + 20, Blocks.planks, 1, 1);
		world.setBlock(x + 11, y + 4, z + 20, Blocks.planks, 1, 1);
		world.setBlock(x + 12, y + 4, z + 20, Blocks.log, 13, 1);
		world.setBlock(x + 4, y + 4, z + 21, Blocks.log, 13, 1);
		world.setBlock(x + 5, y + 4, z + 21, Blocks.planks, 1, 1);
		world.setBlock(x + 6, y + 4, z + 21, Blocks.planks, 1, 1);
		world.setBlock(x + 7, y + 4, z + 21, Blocks.planks, 1, 1);
		world.setBlock(x + 8, y + 4, z + 21, Blocks.planks, 1, 1);
		world.setBlock(x + 9, y + 4, z + 21, Blocks.planks, 1, 1);
		world.setBlock(x + 10, y + 4, z + 21, Blocks.planks, 1, 1);
		world.setBlock(x + 11, y + 4, z + 21, Blocks.planks, 1, 1);
		world.setBlock(x + 12, y + 4, z + 21, Blocks.log, 13, 1);
		world.setBlock(x + 4, y + 4, z + 22, Blocks.log, 13, 1);
		world.setBlock(x + 5, y + 4, z + 22, Blocks.planks, 1, 1);
		world.setBlock(x + 6, y + 4, z + 22, Blocks.planks, 1, 1);
		world.setBlock(x + 7, y + 4, z + 22, Blocks.planks, 1, 1);
		world.setBlock(x + 8, y + 4, z + 22, Blocks.planks, 1, 1);
		world.setBlock(x + 9, y + 4, z + 22, Blocks.planks, 1, 1);
		world.setBlock(x + 10, y + 4, z + 22, Blocks.planks, 1, 1);
		world.setBlock(x + 11, y + 4, z + 22, Blocks.planks, 1, 1);
		world.setBlock(x + 12, y + 4, z + 22, Blocks.log, 13, 1);
		world.setBlock(x + 4, y + 4, z + 23, Blocks.log, 13, 1);
		world.setBlock(x + 5, y + 4, z + 23, Blocks.planks, 1, 1);
		world.setBlock(x + 6, y + 4, z + 23, Blocks.planks, 1, 1);
		world.setBlock(x + 7, y + 4, z + 23, Blocks.planks, 1, 1);
		world.setBlock(x + 8, y + 4, z + 23, Blocks.planks, 1, 1);
		world.setBlock(x + 9, y + 4, z + 23, Blocks.planks, 1, 1);
		world.setBlock(x + 10, y + 4, z + 23, Blocks.planks, 1, 1);
		world.setBlock(x + 11, y + 4, z + 23, Blocks.planks, 1, 1);
		world.setBlock(x + 12, y + 4, z + 23, Blocks.log, 13, 1);
		world.setBlock(x + 4, y + 4, z + 24, Blocks.log, 13, 1);
		world.setBlock(x + 5, y + 4, z + 24, Blocks.planks, 1, 1);
		world.setBlock(x + 6, y + 4, z + 24, Blocks.planks, 1, 1);
		world.setBlock(x + 7, y + 4, z + 24, Blocks.planks, 1, 1);
		world.setBlock(x + 8, y + 4, z + 24, Blocks.planks, 1, 1);
		world.setBlock(x + 9, y + 4, z + 24, Blocks.planks, 1, 1);
		world.setBlock(x + 10, y + 4, z + 24, Blocks.planks, 1, 1);
		world.setBlock(x + 11, y + 4, z + 24, Blocks.planks, 1, 1);
		world.setBlock(x + 12, y + 4, z + 24, Blocks.log, 13, 1);
		world.setBlock(x + 5, y + 4, z + 25, Blocks.glass, 0, 1);
		world.setBlock(x + 8, y + 4, z + 25, Blocks.log, 1, 1);
		world.setBlock(x + 11, y + 4, z + 25, Blocks.glass, 0, 1);
		world.setBlock(x + 5, y + 4, z + 26, Blocks.log, 13, 1);
		world.setBlock(x + 6, y + 4, z + 26, Blocks.torch, 1, 1);
		world.setBlock(x + 8, y + 4, z + 26, Blocks.ladder, 3, 1);
		world.setBlock(x + 10, y + 4, z + 26, Blocks.torch, 2, 1);
		world.setBlock(x + 11, y + 4, z + 26, Blocks.log, 13, 1);
		world.setBlock(x + 5, y + 4, z + 27, Blocks.glass, 0, 1);
		world.setBlock(x + 11, y + 4, z + 27, Blocks.glass, 0, 1);
		world.setBlock(x + 5, y + 4, z + 28, Blocks.log, 13, 1);
		world.setBlock(x + 6, y + 4, z + 28, Blocks.torch, 1, 1);
		world.setBlock(x + 8, y + 4, z + 28, Blocks.log, 13, 1);
		world.setBlock(x + 10, y + 4, z + 28, Blocks.torch, 2, 1);
		world.setBlock(x + 11, y + 4, z + 28, Blocks.log, 13, 1);
		world.setBlock(x + 5, y + 4, z + 29, Blocks.glass, 0, 1);
		world.setBlock(x + 11, y + 4, z + 29, Blocks.glass, 0, 1);
		world.setBlock(x + 5, y + 4, z + 30, Blocks.log, 13, 1);
		world.setBlock(x + 11, y + 4, z + 30, Blocks.log, 13, 1);
		world.setBlock(x + 5, y + 4, z + 31, Blocks.log, 13, 1);
		world.setBlock(x + 11, y + 4, z + 31, Blocks.glass, 0, 1);
		world.setBlock(x + 5, y + 4, z + 32, Blocks.log, 13, 1);
		world.setBlock(x + 6, y + 4, z + 32, Blocks.log, 13, 1);
		world.setBlock(x + 11, y + 4, z + 32, Blocks.log, 13, 1);
		world.setBlock(x + 6, y + 4, z + 33, Blocks.log, 13, 1);
		world.setBlock(x + 7, y + 4, z + 33, Blocks.log, 13, 1);
		world.setBlock(x + 8, y + 4, z + 33, Blocks.torch, 4, 1);
		world.setBlock(x + 9, y + 4, z + 33, Blocks.log, 13, 1);
		world.setBlock(x + 10, y + 4, z + 33, Blocks.log, 13, 1);
		world.setBlock(x + 7, y + 4, z + 34, Blocks.log, 13, 1);
		world.setBlock(x + 8, y + 4, z + 34, Blocks.log, 13, 1);
		world.setBlock(x + 9, y + 4, z + 34, Blocks.log, 13, 1);
		world.setBlock(x + 8, y + 4, z + 35, Blocks.log, 13, 1);
		world.setBlock(x + 5, y + 5, z + 2, Blocks.log, 13, 1);
		world.setBlock(x + 6, y + 5, z + 2, Blocks.log, 13, 1);
		world.setBlock(x + 7, y + 5, z + 2, Blocks.log, 13, 1);
		world.setBlock(x + 8, y + 5, z + 2, Blocks.log, 13, 1);
		world.setBlock(x + 9, y + 5, z + 2, Blocks.log, 13, 1);
		world.setBlock(x + 10, y + 5, z + 2, Blocks.log, 13, 1);
		world.setBlock(x + 11, y + 5, z + 2, Blocks.log, 13, 1);
		world.setBlock(x + 5, y + 5, z + 3, Blocks.log, 13, 1);
		world.setBlock(x + 6, y + 5, z + 3, Blocks.log, 13, 1);
		world.setBlock(x + 7, y + 5, z + 3, Blocks.log, 13, 1);
		world.setBlock(x + 8, y + 5, z + 3, Blocks.log, 13, 1);
		world.setBlock(x + 9, y + 5, z + 3, Blocks.log, 13, 1);
		world.setBlock(x + 10, y + 5, z + 3, Blocks.log, 13, 1);
		world.setBlock(x + 11, y + 5, z + 3, Blocks.log, 13, 1);
		world.setBlock(x + 5, y + 5, z + 4, Blocks.log, 13, 1);
		world.setBlock(x + 6, y + 5, z + 4, Blocks.log, 13, 1);
		world.setBlock(x + 7, y + 5, z + 4, Blocks.log, 13, 1);
		world.setBlock(x + 8, y + 5, z + 4, Blocks.log, 13, 1);
		world.setBlock(x + 9, y + 5, z + 4, Blocks.log, 13, 1);
		world.setBlock(x + 10, y + 5, z + 4, Blocks.log, 13, 1);
		world.setBlock(x + 11, y + 5, z + 4, Blocks.log, 13, 1);
		world.setBlock(x + 4, y + 5, z + 5, Blocks.log, 13, 1);
		world.setBlock(x + 5, y + 5, z + 5, Blocks.log, 13, 1);
		world.setBlock(x + 6, y + 5, z + 5, Blocks.log, 13, 1);
		world.setBlock(x + 7, y + 5, z + 5, Blocks.log, 13, 1);
		world.setBlock(x + 8, y + 5, z + 5, Blocks.log, 13, 1);
		world.setBlock(x + 9, y + 5, z + 5, Blocks.log, 13, 1);
		world.setBlock(x + 10, y + 5, z + 5, Blocks.log, 13, 1);
		world.setBlock(x + 11, y + 5, z + 5, Blocks.log, 13, 1);
		world.setBlock(x + 12, y + 5, z + 5, Blocks.log, 13, 1);
		world.setBlock(x + 4, y + 5, z + 6, Blocks.log, 13, 1);
		world.setBlock(x + 5, y + 5, z + 6, Blocks.log, 13, 1);
		world.setBlock(x + 6, y + 5, z + 6, Blocks.log, 13, 1);
		world.setBlock(x + 7, y + 5, z + 6, Blocks.log, 13, 1);
		world.setBlock(x + 8, y + 5, z + 6, Blocks.log, 13, 1);
		world.setBlock(x + 9, y + 5, z + 6, Blocks.log, 13, 1);
		world.setBlock(x + 10, y + 5, z + 6, Blocks.planks, 1, 1);
		world.setBlock(x + 11, y + 5, z + 6, Blocks.log, 13, 1);
		world.setBlock(x + 12, y + 5, z + 6, Blocks.log, 13, 1);
		world.setBlock(x + 4, y + 5, z + 7, Blocks.log, 13, 1);
		world.setBlock(x + 5, y + 5, z + 7, Blocks.log, 13, 1);
		world.setBlock(x + 6, y + 5, z + 7, Blocks.planks, 1, 1);
		world.setBlock(x + 7, y + 5, z + 7, Blocks.planks, 1, 1);
		world.setBlock(x + 8, y + 5, z + 7, Blocks.planks, 1, 1);
		world.setBlock(x + 9, y + 5, z + 7, Blocks.planks, 1, 1);
		world.setBlock(x + 10, y + 5, z + 7, Blocks.planks, 1, 1);
		world.setBlock(x + 11, y + 5, z + 7, Blocks.log, 13, 1);
		world.setBlock(x + 12, y + 5, z + 7, Blocks.log, 13, 1);
		world.setBlock(x + 4, y + 5, z + 8, Blocks.log, 13, 1);
		world.setBlock(x + 5, y + 5, z + 8, Blocks.log, 13, 1);
		world.setBlock(x + 6, y + 5, z + 8, Blocks.planks, 1, 1);
		world.setBlock(x + 7, y + 5, z + 8, Blocks.planks, 1, 1);
		world.setBlock(x + 8, y + 5, z + 8, Blocks.planks, 1, 1);
		world.setBlock(x + 9, y + 5, z + 8, Blocks.planks, 1, 1);
		world.setBlock(x + 10, y + 5, z + 8, Blocks.planks, 1, 1);
		world.setBlock(x + 11, y + 5, z + 8, Blocks.log, 13, 1);
		world.setBlock(x + 12, y + 5, z + 8, Blocks.log, 13, 1);
		world.setBlock(x + 4, y + 5, z + 9, Blocks.log, 13, 1);
		world.setBlock(x + 5, y + 5, z + 9, Blocks.log, 13, 1);
		world.setBlock(x + 6, y + 5, z + 9, Blocks.planks, 1, 1);
		world.setBlock(x + 7, y + 5, z + 9, Blocks.planks, 1, 1);
		world.setBlock(x + 8, y + 5, z + 9, Blocks.planks, 1, 1);
		world.setBlock(x + 9, y + 5, z + 9, Blocks.planks, 1, 1);
		world.setBlock(x + 10, y + 5, z + 9, Blocks.planks, 1, 1);
		world.setBlock(x + 11, y + 5, z + 9, Blocks.log, 13, 1);
		world.setBlock(x + 12, y + 5, z + 9, Blocks.log, 13, 1);
		world.setBlock(x + 4, y + 5, z + 10, Blocks.log, 13, 1);
		world.setBlock(x + 5, y + 5, z + 10, Blocks.log, 13, 1);
		world.setBlock(x + 6, y + 5, z + 10, Blocks.planks, 1, 1);
		world.setBlock(x + 7, y + 5, z + 10, Blocks.planks, 1, 1);
		world.setBlock(x + 8, y + 5, z + 10, Blocks.planks, 1, 1);
		world.setBlock(x + 9, y + 5, z + 10, Blocks.planks, 1, 1);
		world.setBlock(x + 10, y + 5, z + 10, Blocks.planks, 1, 1);
		world.setBlock(x + 11, y + 5, z + 10, Blocks.log, 13, 1);
		world.setBlock(x + 12, y + 5, z + 10, Blocks.log, 13, 1);
		world.setBlock(x + 4, y + 5, z + 11, Blocks.log, 13, 1);
		world.setBlock(x + 5, y + 5, z + 11, Blocks.log, 13, 1);
		world.setBlock(x + 6, y + 5, z + 11, Blocks.planks, 1, 1);
		world.setBlock(x + 7, y + 5, z + 11, Blocks.planks, 1, 1);
		world.setBlock(x + 8, y + 5, z + 11, Blocks.planks, 1, 1);
		world.setBlock(x + 9, y + 5, z + 11, Blocks.planks, 1, 1);
		world.setBlock(x + 10, y + 5, z + 11, Blocks.planks, 1, 1);
		world.setBlock(x + 11, y + 5, z + 11, Blocks.log, 13, 1);
		world.setBlock(x + 12, y + 5, z + 11, Blocks.log, 13, 1);
		world.setBlock(x + 4, y + 5, z + 12, Blocks.log, 13, 1);
		world.setBlock(x + 5, y + 5, z + 12, Blocks.log, 13, 1);
		world.setBlock(x + 6, y + 5, z + 12, Blocks.planks, 1, 1);
		world.setBlock(x + 7, y + 5, z + 12, Blocks.planks, 1, 1);
		world.setBlock(x + 8, y + 5, z + 12, Blocks.planks, 1, 1);
		world.setBlock(x + 9, y + 5, z + 12, Blocks.planks, 1, 1);
		world.setBlock(x + 10, y + 5, z + 12, Blocks.planks, 1, 1);
		world.setBlock(x + 11, y + 5, z + 12, Blocks.log, 13, 1);
		world.setBlock(x + 12, y + 5, z + 12, Blocks.log, 13, 1);
		world.setBlock(x + 4, y + 5, z + 13, Blocks.log, 13, 1);
		world.setBlock(x + 5, y + 5, z + 13, Blocks.spruce_stairs, 3, 1);
		world.setBlock(x + 6, y + 5, z + 13, Blocks.log, 13, 1);
		world.setBlock(x + 7, y + 5, z + 13, Blocks.log, 13, 1);
		world.setBlock(x + 8, y + 5, z + 13, Blocks.log, 13, 1);
		world.setBlock(x + 9, y + 5, z + 13, Blocks.log, 13, 1);
		world.setBlock(x + 10, y + 5, z + 13, Blocks.log, 13, 1);
		world.setBlock(x + 11, y + 5, z + 13, Blocks.spruce_stairs, 3, 1);
		world.setBlock(x + 12, y + 5, z + 13, Blocks.log, 13, 1);
		world.setBlock(x + 4, y + 5, z + 14, Blocks.log, 13, 1);
		world.setBlock(x + 12, y + 5, z + 14, Blocks.log, 13, 1);
		world.setBlock(x + 4, y + 5, z + 15, Blocks.fence, 0, 1);
		world.setBlock(x + 12, y + 5, z + 15, Blocks.fence, 0, 1);
		world.setBlock(x + 4, y + 5, z + 16, Blocks.fence, 0, 1);
		world.setBlock(x + 12, y + 5, z + 16, Blocks.fence, 0, 1);
		world.setBlock(x + 6, y + 5, z + 17, ACBlocks.cannon, 1, 1);
		world.setBlock(x + 12, y + 5, z + 17, Blocks.fence, 0, 1);
		world.setBlock(x + 4, y + 5, z + 18, Blocks.fence, 0, 1);
		world.setBlock(x + 8, y + 5, z + 18, Blocks.ladder, 2, 1);
		world.setBlock(x + 12, y + 5, z + 18, Blocks.fence, 0, 1);
		world.setBlock(x + 4, y + 5, z + 19, Blocks.fence_gate, 1, 1);
		world.setBlock(x + 7, y + 5, z + 19, Blocks.spruce_stairs, 0, 1);
		world.setBlock(x + 8, y + 5, z + 19, Blocks.log, 13, 1);
		world.setBlock(x + 9, y + 5, z + 19, Blocks.spruce_stairs, 1, 1);
		world.setBlock(x + 12, y + 5, z + 19, Blocks.fence, 0, 1);
		world.setBlock(x + 4, y + 5, z + 20, Blocks.fence, 0, 1);
		world.setBlock(x + 8, y + 5, z + 20, Blocks.spruce_stairs, 3, 1);
		world.setBlock(x + 12, y + 5, z + 20, Blocks.fence, 0, 1);
		world.setBlock(x + 4, y + 5, z + 21, Blocks.fence, 0, 1);
		world.setBlock(x + 12, y + 5, z + 21, Blocks.fence, 0, 1);
		world.setBlock(x + 6, y + 5, z + 22, ACBlocks.cannon, 1, 1);
		world.setBlock(x + 12, y + 5, z + 22, Blocks.fence, 0, 1);
		world.setBlock(x + 4, y + 5, z + 23, Blocks.fence, 0, 1);
		world.setBlock(x + 12, y + 5, z + 23, Blocks.fence, 0, 1);
		world.setBlock(x + 4, y + 5, z + 24, Blocks.log, 13, 1);
		world.setBlock(x + 12, y + 5, z + 24, Blocks.log, 13, 1);
		world.setBlock(x + 4, y + 5, z + 25, Blocks.log, 13, 1);
		world.setBlock(x + 5, y + 5, z + 25, Blocks.spruce_stairs, 2, 1);
		world.setBlock(x + 6, y + 5, z + 25, Blocks.spruce_stairs, 2, 1);
		world.setBlock(x + 7, y + 5, z + 25, Blocks.log, 1, 1);
		world.setBlock(x + 8, y + 5, z + 25, Blocks.log, 13, 1);
		world.setBlock(x + 9, y + 5, z + 25, Blocks.log, 13, 1);
		world.setBlock(x + 10, y + 5, z + 25, Blocks.spruce_stairs, 2, 1);
		world.setBlock(x + 11, y + 5, z + 25, Blocks.spruce_stairs, 2, 1);
		world.setBlock(x + 12, y + 5, z + 25, Blocks.log, 13, 1);
		world.setBlock(x + 4, y + 5, z + 26, Blocks.log, 13, 1);
		world.setBlock(x + 8, y + 5, z + 26, Blocks.ladder, 3, 1);
		world.setBlock(x + 12, y + 5, z + 26, Blocks.log, 13, 1);
		world.setBlock(x + 4, y + 5, z + 27, Blocks.log, 13, 1);
		world.setBlock(x + 12, y + 5, z + 27, Blocks.log, 13, 1);
		world.setBlock(x + 4, y + 5, z + 28, Blocks.log, 13, 1);
		world.setBlock(x + 8, y + 5, z + 28, Blocks.log, 13, 1);
		world.setBlock(x + 12, y + 5, z + 28, Blocks.log, 13, 1);
		world.setBlock(x + 4, y + 5, z + 29, Blocks.log, 13, 1);
		world.setBlock(x + 12, y + 5, z + 29, Blocks.log, 13, 1);
		world.setBlock(x + 4, y + 5, z + 30, Blocks.log, 13, 1);
		world.setBlock(x + 12, y + 5, z + 30, Blocks.log, 13, 1);
		world.setBlock(x + 4, y + 5, z + 31, Blocks.log, 13, 1);
		world.setBlock(x + 12, y + 5, z + 31, Blocks.log, 13, 1);
		world.setBlock(x + 5, y + 5, z + 32, Blocks.log, 13, 1);
		world.setBlock(x + 11, y + 5, z + 32, Blocks.log, 13, 1);
		world.setBlock(x + 5, y + 5, z + 33, Blocks.log, 13, 1);
		world.setBlock(x + 6, y + 5, z + 33, Blocks.log, 13, 1);
		world.setBlock(x + 10, y + 5, z + 33, Blocks.log, 13, 1);
		world.setBlock(x + 11, y + 5, z + 33, Blocks.log, 13, 1);
		world.setBlock(x + 6, y + 5, z + 34, Blocks.log, 13, 1);
		world.setBlock(x + 7, y + 5, z + 34, Blocks.log, 13, 1);
		world.setBlock(x + 9, y + 5, z + 34, Blocks.log, 13, 1);
		world.setBlock(x + 10, y + 5, z + 34, Blocks.log, 13, 1);
		world.setBlock(x + 7, y + 5, z + 35, Blocks.log, 13, 1);
		world.setBlock(x + 8, y + 5, z + 35, Blocks.log, 13, 1);
		world.setBlock(x + 9, y + 5, z + 35, Blocks.log, 13, 1);
		world.setBlock(x + 8, y + 5, z + 36, Blocks.log, 13, 1);
		world.setBlock(x + 4, y + 6, z + 1, Blocks.log, 13, 1);
		world.setBlock(x + 5, y + 6, z + 1, Blocks.log, 13, 1);
		world.setBlock(x + 6, y + 6, z + 1, Blocks.log, 13, 1);
		world.setBlock(x + 7, y + 6, z + 1, Blocks.log, 13, 1);
		world.setBlock(x + 8, y + 6, z + 1, Blocks.log, 13, 1);
		world.setBlock(x + 9, y + 6, z + 1, Blocks.log, 13, 1);
		world.setBlock(x + 10, y + 6, z + 1, Blocks.log, 13, 1);
		world.setBlock(x + 11, y + 6, z + 1, Blocks.log, 13, 1);
		world.setBlock(x + 12, y + 6, z + 1, Blocks.log, 13, 1);
		world.setBlock(x + 4, y + 6, z + 2, Blocks.log, 13, 1);
		world.setBlock(x + 5, y + 6, z + 2, Blocks.planks, 1, 1);
		world.setBlock(x + 6, y + 6, z + 2, Blocks.planks, 1, 1);
		world.setBlock(x + 7, y + 6, z + 2, Blocks.planks, 1, 1);
		world.setBlock(x + 8, y + 6, z + 2, Blocks.planks, 1, 1);
		world.setBlock(x + 9, y + 6, z + 2, Blocks.planks, 1, 1);
		world.setBlock(x + 10, y + 6, z + 2, Blocks.planks, 1, 1);
		world.setBlock(x + 11, y + 6, z + 2, Blocks.planks, 1, 1);
		world.setBlock(x + 12, y + 6, z + 2, Blocks.log, 13, 1);
		world.setBlock(x + 4, y + 6, z + 3, Blocks.log, 13, 1);
		world.setBlock(x + 5, y + 6, z + 3, Blocks.planks, 1, 1);
		world.setBlock(x + 6, y + 6, z + 3, Blocks.planks, 1, 1);
		world.setBlock(x + 7, y + 6, z + 3, Blocks.planks, 1, 1);
		world.setBlock(x + 8, y + 6, z + 3, Blocks.planks, 1, 1);
		world.setBlock(x + 9, y + 6, z + 3, Blocks.planks, 1, 1);
		world.setBlock(x + 10, y + 6, z + 3, Blocks.planks, 1, 1);
		world.setBlock(x + 11, y + 6, z + 3, Blocks.planks, 1, 1);
		world.setBlock(x + 12, y + 6, z + 3, Blocks.log, 13, 1);
		world.setBlock(x + 4, y + 6, z + 4, Blocks.log, 13, 1);
		world.setBlock(x + 5, y + 6, z + 4, Blocks.planks, 1, 1);
		world.setBlock(x + 6, y + 6, z + 4, Blocks.planks, 1, 1);
		world.setBlock(x + 7, y + 6, z + 4, Blocks.planks, 1, 1);
		world.setBlock(x + 8, y + 6, z + 4, Blocks.planks, 1, 1);
		world.setBlock(x + 9, y + 6, z + 4, Blocks.planks, 1, 1);
		world.setBlock(x + 10, y + 6, z + 4, Blocks.planks, 1, 1);
		world.setBlock(x + 11, y + 6, z + 4, Blocks.planks, 1, 1);
		world.setBlock(x + 12, y + 6, z + 4, Blocks.log, 13, 1);
		world.setBlock(x + 4, y + 6, z + 5, Blocks.log, 13, 1);
		world.setBlock(x + 5, y + 6, z + 5, Blocks.planks, 1, 1);
		world.setBlock(x + 6, y + 6, z + 5, Blocks.planks, 1, 1);
		world.setBlock(x + 7, y + 6, z + 5, Blocks.planks, 1, 1);
		world.setBlock(x + 8, y + 6, z + 5, Blocks.planks, 1, 1);
		world.setBlock(x + 9, y + 6, z + 5, Blocks.planks, 1, 1);
		world.setBlock(x + 10, y + 6, z + 5, Blocks.planks, 1, 1);
		world.setBlock(x + 11, y + 6, z + 5, Blocks.planks, 1, 1);
		world.setBlock(x + 12, y + 6, z + 5, Blocks.log, 13, 1);
		world.setBlock(x + 4, y + 6, z + 6, Blocks.log, 13, 1);
		world.setBlock(x + 5, y + 6, z + 6, Blocks.planks, 1, 1);
		world.setBlock(x + 6, y + 6, z + 6, Blocks.planks, 1, 1);
		world.setBlock(x + 7, y + 6, z + 6, Blocks.planks, 1, 1);
		world.setBlock(x + 8, y + 6, z + 6, Blocks.planks, 1, 1);
		world.setBlock(x + 9, y + 6, z + 6, Blocks.planks, 1, 1);
		world.setBlock(x + 10, y + 6, z + 6, Blocks.planks, 1, 1);
		world.setBlock(x + 11, y + 6, z + 6, Blocks.planks, 1, 1);
		world.setBlock(x + 12, y + 6, z + 6, Blocks.log, 13, 1);
		world.setBlock(x + 4, y + 6, z + 7, Blocks.log, 13, 1);
		world.setBlock(x + 5, y + 6, z + 7, Blocks.log, 13, 1);
		world.setBlock(x + 6, y + 6, z + 7, Blocks.planks, 1, 1);
		world.setBlock(x + 7, y + 6, z + 7, Blocks.planks, 1, 1);
		world.setBlock(x + 8, y + 6, z + 7, Blocks.planks, 1, 1);
		world.setBlock(x + 9, y + 6, z + 7, Blocks.planks, 1, 1);
		world.setBlock(x + 10, y + 6, z + 7, Blocks.planks, 1, 1);
		world.setBlock(x + 11, y + 6, z + 7, Blocks.log, 13, 1);
		world.setBlock(x + 12, y + 6, z + 7, Blocks.log, 13, 1);
		world.setBlock(x + 4, y + 6, z + 8, Blocks.log, 13, 1);
		world.setBlock(x + 5, y + 6, z + 8, Blocks.log, 13, 1);
		world.setBlock(x + 6, y + 6, z + 8, Blocks.planks, 1, 1);
		world.setBlock(x + 7, y + 6, z + 8, Blocks.planks, 1, 1);
		world.setBlock(x + 8, y + 6, z + 8, Blocks.planks, 1, 1);
		world.setBlock(x + 9, y + 6, z + 8, Blocks.planks, 1, 1);
		world.setBlock(x + 10, y + 6, z + 8, Blocks.planks, 1, 1);
		world.setBlock(x + 11, y + 6, z + 8, Blocks.log, 13, 1);
		world.setBlock(x + 12, y + 6, z + 8, Blocks.log, 13, 1);
		world.setBlock(x + 4, y + 6, z + 9, Blocks.log, 13, 1);
		world.setBlock(x + 5, y + 6, z + 9, Blocks.log, 13, 1);
		world.setBlock(x + 6, y + 6, z + 9, Blocks.planks, 1, 1);
		world.setBlock(x + 7, y + 6, z + 9, Blocks.planks, 1, 1);
		world.setBlock(x + 8, y + 6, z + 9, Blocks.planks, 1, 1);
		world.setBlock(x + 9, y + 6, z + 9, Blocks.planks, 1, 1);
		world.setBlock(x + 10, y + 6, z + 9, Blocks.planks, 1, 1);
		world.setBlock(x + 11, y + 6, z + 9, Blocks.log, 13, 1);
		world.setBlock(x + 12, y + 6, z + 9, Blocks.log, 13, 1);
		world.setBlock(x + 4, y + 6, z + 10, Blocks.log, 13, 1);
		world.setBlock(x + 5, y + 6, z + 10, Blocks.planks, 1, 1);
		world.setBlock(x + 6, y + 6, z + 10, Blocks.planks, 1, 1);
		world.setBlock(x + 7, y + 6, z + 10, Blocks.planks, 1, 1);
		world.setBlock(x + 8, y + 6, z + 10, Blocks.planks, 1, 1);
		world.setBlock(x + 9, y + 6, z + 10, Blocks.planks, 1, 1);
		world.setBlock(x + 10, y + 6, z + 10, Blocks.planks, 1, 1);
		world.setBlock(x + 11, y + 6, z + 10, Blocks.planks, 1, 1);
		world.setBlock(x + 12, y + 6, z + 10, Blocks.log, 13, 1);
		world.setBlock(x + 4, y + 6, z + 11, Blocks.log, 13, 1);
		world.setBlock(x + 5, y + 6, z + 11, Blocks.planks, 1, 1);
		world.setBlock(x + 6, y + 6, z + 11, Blocks.planks, 1, 1);
		world.setBlock(x + 7, y + 6, z + 11, Blocks.planks, 1, 1);
		world.setBlock(x + 8, y + 6, z + 11, Blocks.log, 0, 1);
		world.setBlock(x + 9, y + 6, z + 11, Blocks.planks, 1, 1);
		world.setBlock(x + 10, y + 6, z + 11, Blocks.planks, 1, 1);
		world.setBlock(x + 11, y + 6, z + 11, Blocks.planks, 1, 1);
		world.setBlock(x + 12, y + 6, z + 11, Blocks.log, 13, 1);
		world.setBlock(x + 4, y + 6, z + 12, Blocks.log, 13, 1);
		world.setBlock(x + 5, y + 6, z + 12, Blocks.spruce_stairs, 3, 1);
		world.setBlock(x + 6, y + 6, z + 12, Blocks.planks, 1, 1);
		world.setBlock(x + 7, y + 6, z + 12, Blocks.planks, 1, 1);
		world.setBlock(x + 8, y + 6, z + 12, Blocks.planks, 1, 1);
		world.setBlock(x + 9, y + 6, z + 12, Blocks.planks, 1, 1);
		world.setBlock(x + 10, y + 6, z + 12, Blocks.planks, 1, 1);
		world.setBlock(x + 11, y + 6, z + 12, Blocks.spruce_stairs, 3, 1);
		world.setBlock(x + 12, y + 6, z + 12, Blocks.log, 13, 1);
		world.setBlock(x + 4, y + 6, z + 13, Blocks.log, 13, 1);
		world.setBlock(x + 6, y + 6, z + 13, Blocks.log, 13, 1);
		world.setBlock(x + 7, y + 6, z + 13, Blocks.log, 13, 1);
		world.setBlock(x + 8, y + 6, z + 13, Blocks.log, 13, 1);
		world.setBlock(x + 9, y + 6, z + 13, Blocks.log, 13, 1);
		world.setBlock(x + 10, y + 6, z + 13, Blocks.log, 13, 1);
		world.setBlock(x + 12, y + 6, z + 13, Blocks.log, 13, 1);
		world.setBlock(x + 4, y + 6, z + 14, Blocks.fence, 0, 1);
		world.setBlock(x + 7, y + 6, z + 14, Blocks.torch, 3, 1);
		world.setBlock(x + 9, y + 6, z + 14, Blocks.torch, 3, 1);
		world.setBlock(x + 12, y + 6, z + 14, Blocks.fence, 0, 1);
		world.setBlock(x + 4, y + 6, z + 15, Blocks.fence, 0, 1);
		world.setBlock(x + 12, y + 6, z + 15, Blocks.fence, 0, 1);
		world.setBlock(x + 4, y + 6, z + 18, Blocks.torch, 5, 1);
		world.setBlock(x + 8, y + 6, z + 18, Blocks.ladder, 2, 1);
		world.setBlock(x + 8, y + 6, z + 19, Blocks.log, 13, 1);
		world.setBlock(x + 4, y + 6, z + 20, Blocks.torch, 5, 1);
		world.setBlock(x + 4, y + 6, z + 23, Blocks.fence, 0, 1);
		world.setBlock(x + 4, y + 6, z + 24, Blocks.fence, 0, 1);
		world.setBlock(x + 7, y + 6, z + 24, Blocks.torch, 4, 1);
		world.setBlock(x + 9, y + 6, z + 24, Blocks.torch, 4, 1);
		world.setBlock(x + 12, y + 6, z + 24, Blocks.fence, 0, 1);
		world.setBlock(x + 4, y + 6, z + 25, Blocks.fence, 0, 1);
		world.setBlock(x + 7, y + 6, z + 25, Blocks.log, 13, 1);
		world.setBlock(x + 8, y + 6, z + 25, Blocks.log, 13, 1);
		world.setBlock(x + 9, y + 6, z + 25, Blocks.log, 13, 1);
		world.setBlock(x + 12, y + 6, z + 25, Blocks.fence, 0, 1);
		world.setBlock(x + 4, y + 6, z + 26, Blocks.log, 13, 1);
		world.setBlock(x + 5, y + 6, z + 26, Blocks.spruce_stairs, 2, 1);
		world.setBlock(x + 6, y + 6, z + 26, Blocks.spruce_stairs, 2, 1);
		world.setBlock(x + 7, y + 6, z + 26, Blocks.planks, 1, 1);
		world.setBlock(x + 8, y + 6, z + 26, Blocks.ladder, 3, 1);
		world.setBlock(x + 9, y + 6, z + 26, Blocks.planks, 1, 1);
		world.setBlock(x + 10, y + 6, z + 26, Blocks.spruce_stairs, 2, 1);
		world.setBlock(x + 11, y + 6, z + 26, Blocks.spruce_stairs, 2, 1);
		world.setBlock(x + 12, y + 6, z + 26, Blocks.log, 13, 1);
		world.setBlock(x + 4, y + 6, z + 27, Blocks.log, 13, 1);
		world.setBlock(x + 5, y + 6, z + 27, Blocks.planks, 1, 1);
		world.setBlock(x + 6, y + 6, z + 27, Blocks.planks, 1, 1);
		world.setBlock(x + 7, y + 6, z + 27, Blocks.planks, 1, 1);
		world.setBlock(x + 8, y + 6, z + 27, Blocks.planks, 1, 1);
		world.setBlock(x + 9, y + 6, z + 27, Blocks.planks, 1, 1);
		world.setBlock(x + 10, y + 6, z + 27, Blocks.planks, 1, 1);
		world.setBlock(x + 11, y + 6, z + 27, Blocks.planks, 1, 1);
		world.setBlock(x + 12, y + 6, z + 27, Blocks.log, 13, 1);
		world.setBlock(x + 4, y + 6, z + 28, Blocks.log, 13, 1);
		world.setBlock(x + 5, y + 6, z + 28, Blocks.planks, 1, 1);
		world.setBlock(x + 6, y + 6, z + 28, Blocks.planks, 1, 1);
		world.setBlock(x + 7, y + 6, z + 28, Blocks.planks, 1, 1);
		world.setBlock(x + 8, y + 6, z + 28, Blocks.log, 13, 1);
		world.setBlock(x + 9, y + 6, z + 28, Blocks.planks, 1, 1);
		world.setBlock(x + 10, y + 6, z + 28, Blocks.planks, 1, 1);
		world.setBlock(x + 11, y + 6, z + 28, Blocks.planks, 1, 1);
		world.setBlock(x + 12, y + 6, z + 28, Blocks.log, 13, 1);
		world.setBlock(x + 4, y + 6, z + 29, Blocks.log, 13, 1);
		world.setBlock(x + 5, y + 6, z + 29, Blocks.planks, 1, 1);
		world.setBlock(x + 6, y + 6, z + 29, Blocks.planks, 1, 1);
		world.setBlock(x + 7, y + 6, z + 29, Blocks.planks, 1, 1);
		world.setBlock(x + 8, y + 6, z + 29, Blocks.planks, 1, 1);
		world.setBlock(x + 9, y + 6, z + 29, Blocks.planks, 1, 1);
		world.setBlock(x + 10, y + 6, z + 29, Blocks.planks, 1, 1);
		world.setBlock(x + 11, y + 6, z + 29, Blocks.planks, 1, 1);
		world.setBlock(x + 12, y + 6, z + 29, Blocks.log, 13, 1);
		world.setBlock(x + 4, y + 6, z + 30, Blocks.log, 13, 1);
		world.setBlock(x + 5, y + 6, z + 30, Blocks.planks, 1, 1);
		world.setBlock(x + 6, y + 6, z + 30, Blocks.planks, 1, 1);
		world.setBlock(x + 7, y + 6, z + 30, Blocks.planks, 1, 1);
		world.setBlock(x + 8, y + 6, z + 30, Blocks.planks, 1, 1);
		world.setBlock(x + 9, y + 6, z + 30, Blocks.planks, 1, 1);
		world.setBlock(x + 10, y + 6, z + 30, Blocks.planks, 1, 1);
		world.setBlock(x + 11, y + 6, z + 30, Blocks.planks, 1, 1);
		world.setBlock(x + 12, y + 6, z + 30, Blocks.log, 13, 1);
		world.setBlock(x + 4, y + 6, z + 31, Blocks.log, 13, 1);
		world.setBlock(x + 12, y + 6, z + 31, Blocks.log, 13, 1);
		world.setBlock(x + 4, y + 6, z + 32, Blocks.log, 13, 1);
		world.setBlock(x + 12, y + 6, z + 32, Blocks.log, 13, 1);
		world.setBlock(x + 4, y + 6, z + 33, Blocks.log, 13, 1);
		world.setBlock(x + 12, y + 6, z + 33, Blocks.log, 13, 1);
		world.setBlock(x + 5, y + 6, z + 34, Blocks.log, 13, 1);
		world.setBlock(x + 6, y + 6, z + 34, Blocks.log, 13, 1);
		world.setBlock(x + 10, y + 6, z + 34, Blocks.log, 13, 1);
		world.setBlock(x + 11, y + 6, z + 34, Blocks.log, 13, 1);
		world.setBlock(x + 6, y + 6, z + 35, Blocks.log, 13, 1);
		world.setBlock(x + 7, y + 6, z + 35, Blocks.log, 13, 1);
		world.setBlock(x + 9, y + 6, z + 35, Blocks.log, 13, 1);
		world.setBlock(x + 10, y + 6, z + 35, Blocks.log, 13, 1);
		world.setBlock(x + 7, y + 6, z + 36, Blocks.log, 13, 1);
		world.setBlock(x + 8, y + 6, z + 36, Blocks.log, 13, 1);
		world.setBlock(x + 9, y + 6, z + 36, Blocks.log, 13, 1);
		world.setBlock(x + 8, y + 6, z + 37, Blocks.log, 13, 1);
		world.setBlock(x + 8, y + 6, z + 38, Blocks.log, 13, 1);
		world.setBlock(x + 4, y + 7, z + 0, Blocks.log, 13, 1);
		world.setBlock(x + 5, y + 7, z + 0, Blocks.log, 13, 1);
		world.setBlock(x + 6, y + 7, z + 0, Blocks.log, 13, 1);
		world.setBlock(x + 7, y + 7, z + 0, Blocks.log, 13, 1);
		world.setBlock(x + 8, y + 7, z + 0, Blocks.log, 13, 1);
		world.setBlock(x + 9, y + 7, z + 0, Blocks.log, 13, 1);
		world.setBlock(x + 10, y + 7, z + 0, Blocks.log, 13, 1);
		world.setBlock(x + 11, y + 7, z + 0, Blocks.log, 13, 1);
		world.setBlock(x + 12, y + 7, z + 0, Blocks.log, 13, 1);
		world.setBlock(x + 4, y + 7, z + 1, Blocks.log, 13, 1);
		world.setBlock(x + 5, y + 7, z + 1, Blocks.wooden_slab, 1, 1);
		world.setBlock(x + 6, y + 7, z + 1, Blocks.wooden_slab, 1, 1);
		world.setBlock(x + 7, y + 7, z + 1, Blocks.wool, 0, 1);
		world.setBlock(x + 8, y + 7, z + 1, Blocks.wool, 0, 1);
		world.setBlock(x + 9, y + 7, z + 1, Blocks.wool, 0, 1);
		world.setBlock(x + 10, y + 7, z + 1, Blocks.wooden_slab, 1, 1);
		world.setBlock(x + 11, y + 7, z + 1, Blocks.wooden_slab, 1, 1);
		world.setBlock(x + 12, y + 7, z + 1, Blocks.log, 13, 1);
		world.setBlock(x + 4, y + 7, z + 2, Blocks.log, 13, 1);
		world.setBlock(x + 6, y + 7, z + 2, Blocks.wooden_slab, 1, 1);
		world.setBlock(x + 7, y + 7, z + 2, Blocks.wool, 14, 1);
		world.setBlock(x + 8, y + 7, z + 2, Blocks.wool, 14, 1);
		world.setBlock(x + 9, y + 7, z + 2, Blocks.wool, 14, 1);
		world.setBlock(x + 10, y + 7, z + 2, Blocks.wooden_slab, 1, 1);
		world.setBlock(x + 12, y + 7, z + 2, Blocks.log, 13, 1);
		world.setBlock(x + 4, y + 7, z + 3, Blocks.log, 13, 1);
		world.setBlock(x + 7, y + 7, z + 3, Blocks.wooden_slab, 1, 1);
		world.setBlock(x + 8, y + 7, z + 3, Blocks.wooden_slab, 1, 1);
		world.setBlock(x + 9, y + 7, z + 3, Blocks.wooden_slab, 1, 1);
		world.setBlock(x + 12, y + 7, z + 3, Blocks.log, 13, 1);
		world.setBlock(x + 4, y + 7, z + 4, Blocks.log, 13, 1);
		world.setBlock(x + 5, y + 7, z + 4, Blocks.spruce_stairs, 7, 1);
		world.setBlock(x + 12, y + 7, z + 4, Blocks.log, 13, 1);
		world.setBlock(x + 4, y + 7, z + 5, Blocks.log, 13, 1);
		world.setBlock(x + 5, y + 7, z + 5, Blocks.spruce_stairs, 6, 1);
		world.setBlock(x + 12, y + 7, z + 5, Blocks.log, 13, 1);
		world.setBlock(x + 4, y + 7, z + 6, Blocks.log, 13, 1);
		world.setBlock(x + 5, y + 7, z + 6, Blocks.log, 13, 1);
		world.setBlock(x + 11, y + 7, z + 6, Blocks.log, 13, 1);
		world.setBlock(x + 12, y + 7, z + 6, Blocks.log, 13, 1);
		world.setBlock(x + 4, y + 7, z + 7, Blocks.log, 13, 1);
		world.setBlock(x + 5, y + 7, z + 7, Blocks.log, 13, 1);
		world.setBlock(x + 6, y + 7, z + 7, Blocks.log, 13, 1);
		world.setBlock(x + 10, y + 7, z + 7, Blocks.log, 13, 1);
		world.setBlock(x + 11, y + 7, z + 7, Blocks.log, 13, 1);
		world.setBlock(x + 12, y + 7, z + 7, Blocks.log, 13, 1);
		world.setBlock(x + 4, y + 7, z + 8, Blocks.log, 13, 1);
		world.setBlock(x + 5, y + 7, z + 8, Blocks.log, 13, 1);
		world.setBlock(x + 6, y + 7, z + 8, Blocks.log, 13, 1);
		world.setBlock(x + 7, y + 7, z + 8, Blocks.log, 13, 1);
		world.setBlock(x + 8, y + 7, z + 8, Blocks.wooden_door, 7, 1);
		world.setBlock(x + 9, y + 7, z + 8, Blocks.log, 13, 1);
		world.setBlock(x + 10, y + 7, z + 8, Blocks.log, 13, 1);
		world.setBlock(x + 11, y + 7, z + 8, Blocks.log, 13, 1);
		world.setBlock(x + 12, y + 7, z + 8, Blocks.log, 13, 1);
		world.setBlock(x + 4, y + 7, z + 9, Blocks.log, 13, 1);
		world.setBlock(x + 5, y + 7, z + 9, Blocks.spruce_stairs, 3, 1);
		world.setBlock(x + 6, y + 7, z + 9, Blocks.fence, 0, 1);
		world.setBlock(x + 10, y + 7, z + 9, Blocks.fence, 0, 1);
		world.setBlock(x + 11, y + 7, z + 9, Blocks.spruce_stairs, 3, 1);
		world.setBlock(x + 12, y + 7, z + 9, Blocks.log, 13, 1);
		world.setBlock(x + 4, y + 7, z + 10, Blocks.fence, 0, 1);
		world.setBlock(x + 12, y + 7, z + 10, Blocks.fence, 0, 1);
		world.setBlock(x + 4, y + 7, z + 11, Blocks.fence, 0, 1);
		world.setBlock(x + 7, y + 7, z + 11, Blocks.spruce_stairs, 0, 1);
		world.setBlock(x + 8, y + 7, z + 11, Blocks.log, 13, 1);
		world.setBlock(x + 9, y + 7, z + 11, Blocks.spruce_stairs, 1, 1);
		world.setBlock(x + 12, y + 7, z + 11, Blocks.fence, 0, 1);
		world.setBlock(x + 4, y + 7, z + 12, Blocks.fence, 0, 1);
		world.setBlock(x + 8, y + 7, z + 12, Blocks.spruce_stairs, 3, 1);
		world.setBlock(x + 12, y + 7, z + 12, Blocks.fence, 0, 1);
		world.setBlock(x + 4, y + 7, z + 13, Blocks.fence, 0, 1);
		world.setBlock(x + 6, y + 7, z + 13, Blocks.fence, 0, 1);
		world.setBlock(x + 7, y + 7, z + 13, Blocks.fence, 0, 1);
		world.setBlock(x + 8, y + 7, z + 13, Blocks.fence, 0, 1);
		world.setBlock(x + 9, y + 7, z + 13, Blocks.fence, 0, 1);
		world.setBlock(x + 10, y + 7, z + 13, Blocks.fence, 0, 1);
		world.setBlock(x + 12, y + 7, z + 13, Blocks.fence, 0, 1);
		world.setBlock(x + 4, y + 7, z + 14, Blocks.fence, 0, 1);
		world.setBlock(x + 12, y + 7, z + 14, Blocks.fence, 0, 1);
		world.setBlock(x + 8, y + 7, z + 18, Blocks.ladder, 2, 1);
		world.setBlock(x + 8, y + 7, z + 19, Blocks.log, 13, 1);
		world.setBlock(x + 4, y + 7, z + 25, Blocks.fence, 0, 1);
		world.setBlock(x + 7, y + 7, z + 25, Blocks.fence, 0, 1);
		world.setBlock(x + 8, y + 7, z + 25, Blocks.fence, 0, 1);
		world.setBlock(x + 9, y + 7, z + 25, Blocks.fence, 0, 1);
		world.setBlock(x + 12, y + 7, z + 25, Blocks.fence, 0, 1);
		world.setBlock(x + 4, y + 7, z + 26, Blocks.fence, 0, 1);
		world.setBlock(x + 12, y + 7, z + 26, Blocks.fence, 0, 1);
		world.setBlock(x + 4, y + 7, z + 27, Blocks.fence, 0, 1);
		world.setBlock(x + 8, y + 7, z + 27, Blocks.spruce_stairs, 2, 1);
		world.setBlock(x + 12, y + 7, z + 27, Blocks.fence, 0, 1);
		world.setBlock(x + 4, y + 7, z + 28, Blocks.fence, 0, 1);
		world.setBlock(x + 7, y + 7, z + 28, Blocks.spruce_stairs, 0, 1);
		world.setBlock(x + 8, y + 7, z + 28, Blocks.log, 13, 1);
		world.setBlock(x + 9, y + 7, z + 28, Blocks.spruce_stairs, 1, 1);
		world.setBlock(x + 12, y + 7, z + 28, Blocks.fence, 0, 1);
		world.setBlock(x + 4, y + 7, z + 29, Blocks.fence, 0, 1);
		world.setBlock(x + 8, y + 7, z + 29, Blocks.spruce_stairs, 3, 1);
		world.setBlock(x + 12, y + 7, z + 29, Blocks.fence, 0, 1);
		world.setBlock(x + 4, y + 7, z + 30, Blocks.log, 13, 1);
		world.setBlock(x + 5, y + 7, z + 30, Blocks.spruce_stairs, 2, 1);
		world.setBlock(x + 6, y + 7, z + 30, Blocks.log, 13, 1);
		world.setBlock(x + 10, y + 7, z + 30, Blocks.log, 13, 1);
		world.setBlock(x + 11, y + 7, z + 30, Blocks.spruce_stairs, 2, 1);
		world.setBlock(x + 12, y + 7, z + 30, Blocks.log, 13, 1);
		world.setBlock(x + 4, y + 7, z + 31, Blocks.log, 13, 1);
		world.setBlock(x + 5, y + 7, z + 31, Blocks.planks, 1, 1);
		world.setBlock(x + 6, y + 7, z + 31, Blocks.log, 13, 1);
		world.setBlock(x + 7, y + 7, z + 31, Blocks.log, 13, 1);
		world.setBlock(x + 8, y + 7, z + 31, Blocks.log, 13, 1);
		world.setBlock(x + 9, y + 7, z + 31, Blocks.log, 13, 1);
		world.setBlock(x + 10, y + 7, z + 31, Blocks.log, 13, 1);
		world.setBlock(x + 11, y + 7, z + 31, Blocks.planks, 1, 1);
		world.setBlock(x + 12, y + 7, z + 31, Blocks.log, 13, 1);
		world.setBlock(x + 4, y + 7, z + 32, Blocks.log, 13, 1);
		world.setBlock(x + 5, y + 7, z + 32, Blocks.planks, 1, 1);
		world.setBlock(x + 6, y + 7, z + 32, Blocks.planks, 1, 1);
		world.setBlock(x + 7, y + 7, z + 32, Blocks.planks, 1, 1);
		world.setBlock(x + 8, y + 7, z + 32, Blocks.planks, 1, 1);
		world.setBlock(x + 9, y + 7, z + 32, Blocks.planks, 1, 1);
		world.setBlock(x + 10, y + 7, z + 32, Blocks.planks, 1, 1);
		world.setBlock(x + 11, y + 7, z + 32, Blocks.planks, 1, 1);
		world.setBlock(x + 12, y + 7, z + 32, Blocks.log, 13, 1);
		world.setBlock(x + 4, y + 7, z + 33, Blocks.log, 13, 1);
		world.setBlock(x + 5, y + 7, z + 33, Blocks.planks, 1, 1);
		world.setBlock(x + 6, y + 7, z + 33, Blocks.planks, 1, 1);
		world.setBlock(x + 7, y + 7, z + 33, Blocks.planks, 1, 1);
		world.setBlock(x + 8, y + 7, z + 33, Blocks.planks, 1, 1);
		world.setBlock(x + 9, y + 7, z + 33, Blocks.planks, 1, 1);
		world.setBlock(x + 10, y + 7, z + 33, Blocks.planks, 1, 1);
		world.setBlock(x + 11, y + 7, z + 33, Blocks.planks, 1, 1);
		world.setBlock(x + 12, y + 7, z + 33, Blocks.log, 13, 1);
		world.setBlock(x + 4, y + 7, z + 34, Blocks.log, 13, 1);
		world.setBlock(x + 5, y + 7, z + 34, Blocks.planks, 1, 1);
		world.setBlock(x + 6, y + 7, z + 34, Blocks.planks, 1, 1);
		world.setBlock(x + 7, y + 7, z + 34, Blocks.planks, 1, 1);
		world.setBlock(x + 8, y + 7, z + 34, Blocks.planks, 1, 1);
		world.setBlock(x + 9, y + 7, z + 34, Blocks.planks, 1, 1);
		world.setBlock(x + 10, y + 7, z + 34, Blocks.planks, 1, 1);
		world.setBlock(x + 11, y + 7, z + 34, Blocks.planks, 1, 1);
		world.setBlock(x + 12, y + 7, z + 34, Blocks.log, 13, 1);
		world.setBlock(x + 5, y + 7, z + 35, Blocks.log, 13, 1);
		world.setBlock(x + 6, y + 7, z + 35, Blocks.log, 13, 1);
		world.setBlock(x + 10, y + 7, z + 35, Blocks.log, 13, 1);
		world.setBlock(x + 11, y + 7, z + 35, Blocks.log, 13, 1);
		world.setBlock(x + 6, y + 7, z + 36, Blocks.log, 13, 1);
		world.setBlock(x + 7, y + 7, z + 36, Blocks.log, 13, 1);
		world.setBlock(x + 9, y + 7, z + 36, Blocks.log, 13, 1);
		world.setBlock(x + 10, y + 7, z + 36, Blocks.log, 13, 1);
		world.setBlock(x + 7, y + 7, z + 37, Blocks.log, 13, 1);
		world.setBlock(x + 8, y + 7, z + 37, Blocks.log, 13, 1);
		world.setBlock(x + 9, y + 7, z + 37, Blocks.log, 13, 1);
		world.setBlock(x + 8, y + 7, z + 38, Blocks.log, 13, 1);
		world.setBlock(x + 8, y + 7, z + 39, Blocks.log, 13, 1);
		world.setBlock(x + 8, y + 7, z + 40, Blocks.log, 13, 1);
		world.setBlock(x + 4, y + 8, z + 0, Blocks.log, 13, 1);
		world.setBlock(x + 5, y + 8, z + 0, Blocks.log, 13, 1);
		world.setBlock(x + 6, y + 8, z + 0, Blocks.glass, 0, 1);
		world.setBlock(x + 7, y + 8, z + 0, Blocks.glass, 0, 1);
		world.setBlock(x + 8, y + 8, z + 0, Blocks.log, 13, 1);
		world.setBlock(x + 9, y + 8, z + 0, Blocks.glass, 0, 1);
		world.setBlock(x + 10, y + 8, z + 0, Blocks.glass, 0, 1);
		world.setBlock(x + 11, y + 8, z + 0, Blocks.log, 13, 1);
		world.setBlock(x + 12, y + 8, z + 0, Blocks.log, 13, 1);
		world.setBlock(x + 4, y + 8, z + 1, Blocks.glass, 0, 1);
		world.setBlock(x + 12, y + 8, z + 1, Blocks.glass, 0, 1);
		world.setBlock(x + 4, y + 8, z + 2, Blocks.glass, 0, 1);
		world.setBlock(x + 12, y + 8, z + 2, Blocks.glass, 0, 1);
		world.setBlock(x + 4, y + 8, z + 3, Blocks.log, 13, 1);
		world.setBlock(x + 12, y + 8, z + 3, Blocks.log, 13, 1);
		world.setBlock(x + 4, y + 8, z + 4, Blocks.glass, 0, 1);
		world.setBlock(x + 12, y + 8, z + 4, Blocks.glass, 0, 1);
		world.setBlock(x + 4, y + 8, z + 5, Blocks.glass, 0, 1);
		world.setBlock(x + 12, y + 8, z + 5, Blocks.glass, 0, 1);
		world.setBlock(x + 4, y + 8, z + 6, Blocks.log, 13, 1);
		world.setBlock(x + 5, y + 8, z + 6, Blocks.log, 13, 1);
		world.setBlock(x + 11, y + 8, z + 6, Blocks.log, 13, 1);
		world.setBlock(x + 12, y + 8, z + 6, Blocks.log, 13, 1);
		world.setBlock(x + 4, y + 8, z + 7, Blocks.log, 13, 1);
		world.setBlock(x + 5, y + 8, z + 7, Blocks.log, 13, 1);
		world.setBlock(x + 6, y + 8, z + 7, Blocks.log, 13, 1);
		world.setBlock(x + 10, y + 8, z + 7, Blocks.log, 13, 1);
		world.setBlock(x + 11, y + 8, z + 7, Blocks.log, 13, 1);
		world.setBlock(x + 12, y + 8, z + 7, Blocks.log, 13, 1);
		world.setBlock(x + 4, y + 8, z + 8, Blocks.log, 13, 1);
		world.setBlock(x + 5, y + 8, z + 8, Blocks.spruce_stairs, 3, 1);
		world.setBlock(x + 6, y + 8, z + 8, Blocks.log, 13, 1);
		world.setBlock(x + 7, y + 8, z + 8, Blocks.glass, 0, 1);
		world.setBlock(x + 9, y + 8, z + 8, Blocks.glass, 0, 1);
		world.setBlock(x + 10, y + 8, z + 8, Blocks.log, 13, 1);
		world.setBlock(x + 11, y + 8, z + 8, Blocks.spruce_stairs, 3, 1);
		world.setBlock(x + 12, y + 8, z + 8, Blocks.log, 13, 1);
		world.setBlock(x + 4, y + 8, z + 9, Blocks.fence, 0, 1);
		world.setBlock(x + 6, y + 8, z + 9, Blocks.fence, 0, 1);
		world.setBlock(x + 10, y + 8, z + 9, Blocks.fence, 0, 1);
		world.setBlock(x + 12, y + 8, z + 9, Blocks.fence, 0, 1);
		world.setBlock(x + 4, y + 8, z + 10, Blocks.fence, 0, 1);
		world.setBlock(x + 12, y + 8, z + 10, Blocks.fence, 0, 1);
		world.setBlock(x + 8, y + 8, z + 11, Blocks.log, 13, 1);
		world.setBlock(x + 6, y + 8, z + 13, Blocks.torch, 5, 1);
		world.setBlock(x + 10, y + 8, z + 13, Blocks.torch, 5, 1);
		world.setBlock(x + 8, y + 8, z + 18, Blocks.ladder, 2, 1);
		world.setBlock(x + 7, y + 8, z + 19, Blocks.torch, 2, 1);
		world.setBlock(x + 8, y + 8, z + 19, Blocks.log, 13, 1);
		world.setBlock(x + 9, y + 8, z + 19, Blocks.torch, 1, 1);
		world.setBlock(x + 8, y + 8, z + 20, Blocks.torch, 3, 1);
		world.setBlock(x + 7, y + 8, z + 25, Blocks.torch, 5, 1);
		world.setBlock(x + 9, y + 8, z + 25, Blocks.torch, 5, 1);
		world.setBlock(x + 8, y + 8, z + 28, Blocks.log, 13, 1);
		world.setBlock(x + 4, y + 8, z + 29, Blocks.fence, 0, 1);
		world.setBlock(x + 12, y + 8, z + 29, Blocks.fence, 0, 1);
		world.setBlock(x + 4, y + 8, z + 30, Blocks.fence, 0, 1);
		world.setBlock(x + 6, y + 8, z + 30, Blocks.fence, 0, 1);
		world.setBlock(x + 10, y + 8, z + 30, Blocks.fence, 0, 1);
		world.setBlock(x + 12, y + 8, z + 30, Blocks.fence, 0, 1);
		world.setBlock(x + 4, y + 8, z + 31, Blocks.fence, 0, 1);
		world.setBlock(x + 6, y + 8, z + 31, Blocks.fence, 0, 1);
		world.setBlock(x + 7, y + 8, z + 31, Blocks.fence, 0, 1);
		world.setBlock(x + 8, y + 8, z + 31, Blocks.fence, 0, 1);
		world.setBlock(x + 9, y + 8, z + 31, Blocks.fence, 0, 1);
		world.setBlock(x + 10, y + 8, z + 31, Blocks.fence, 0, 1);
		world.setBlock(x + 12, y + 8, z + 31, Blocks.fence, 0, 1);
		world.setBlock(x + 4, y + 8, z + 32, Blocks.fence, 0, 1);
		world.setBlock(x + 12, y + 8, z + 32, Blocks.fence, 0, 1);
		world.setBlock(x + 6, y + 8, z + 33, ACBlocks.cannon, 1, 1);
		world.setBlock(x + 10, y + 8, z + 33, ACBlocks.cannon, 3, 1);
		world.setBlock(x + 4, y + 8, z + 34, Blocks.log, 13, 1);
		world.setBlock(x + 12, y + 8, z + 34, Blocks.log, 13, 1);
		world.setBlock(x + 4, y + 8, z + 35, Blocks.log, 13, 1);
		world.setBlock(x + 5, y + 8, z + 35, Blocks.log, 13, 1);
		world.setBlock(x + 6, y + 8, z + 35, Blocks.spruce_stairs, 1, 1);
		world.setBlock(x + 7, y + 8, z + 35, Blocks.spruce_stairs, 2, 1);
		world.setBlock(x + 8, y + 8, z + 35, Blocks.spruce_stairs, 2, 1);
		world.setBlock(x + 9, y + 8, z + 35, Blocks.spruce_stairs, 2, 1);
		world.setBlock(x + 10, y + 8, z + 35, Blocks.spruce_stairs, 0, 1);
		world.setBlock(x + 11, y + 8, z + 35, Blocks.log, 13, 1);
		world.setBlock(x + 12, y + 8, z + 35, Blocks.log, 13, 1);
		world.setBlock(x + 5, y + 8, z + 36, Blocks.log, 13, 1);
		world.setBlock(x + 6, y + 8, z + 36, Blocks.log, 13, 1);
		world.setBlock(x + 7, y + 8, z + 36, Blocks.planks, 1, 1);
		world.setBlock(x + 8, y + 8, z + 36, Blocks.planks, 1, 1);
		world.setBlock(x + 9, y + 8, z + 36, Blocks.planks, 1, 1);
		world.setBlock(x + 10, y + 8, z + 36, Blocks.log, 13, 1);
		world.setBlock(x + 11, y + 8, z + 36, Blocks.log, 13, 1);
		world.setBlock(x + 6, y + 8, z + 37, Blocks.log, 13, 1);
		world.setBlock(x + 7, y + 8, z + 37, Blocks.log, 13, 1);
		world.setBlock(x + 8, y + 8, z + 37, Blocks.planks, 1, 1);
		world.setBlock(x + 9, y + 8, z + 37, Blocks.log, 13, 1);
		world.setBlock(x + 10, y + 8, z + 37, Blocks.log, 13, 1);
		world.setBlock(x + 7, y + 8, z + 38, Blocks.log, 13, 1);
		world.setBlock(x + 8, y + 8, z + 38, Blocks.planks, 1, 1);
		world.setBlock(x + 9, y + 8, z + 38, Blocks.log, 13, 1);
		world.setBlock(x + 8, y + 8, z + 39, Blocks.log, 13, 1);
		world.setBlock(x + 8, y + 8, z + 40, Blocks.log, 13, 1);
		world.setBlock(x + 8, y + 8, z + 41, Blocks.log, 13, 1);
		world.setBlock(x + 8, y + 8, z + 42, Blocks.log, 13, 1);
		world.setBlock(x + 8, y + 8, z + 43, Blocks.log, 13, 1);
		world.setBlock(x + 8, y + 8, z + 44, Blocks.log, 13, 1);
		world.setBlock(x + 7, y + 8, z + 45, Blocks.torch, 2, 1);
		world.setBlock(x + 8, y + 8, z + 45, Blocks.log, 13, 1);
		world.setBlock(x + 9, y + 8, z + 45, Blocks.torch, 1, 1);
		world.setBlock(x + 4, y + 9, z + 0, Blocks.log, 13, 1);
		world.setBlock(x + 5, y + 9, z + 0, Blocks.log, 13, 1);
		world.setBlock(x + 6, y + 9, z + 0, Blocks.glass, 0, 1);
		world.setBlock(x + 7, y + 9, z + 0, Blocks.glass, 0, 1);
		world.setBlock(x + 8, y + 9, z + 0, Blocks.log, 13, 1);
		world.setBlock(x + 9, y + 9, z + 0, Blocks.glass, 0, 1);
		world.setBlock(x + 10, y + 9, z + 0, Blocks.glass, 0, 1);
		world.setBlock(x + 11, y + 9, z + 0, Blocks.log, 13, 1);
		world.setBlock(x + 12, y + 9, z + 0, Blocks.log, 13, 1);
		world.setBlock(x + 4, y + 9, z + 1, Blocks.glass, 0, 1);
		world.setBlock(x + 5, y + 9, z + 1, Blocks.torch, 3, 1);
		world.setBlock(x + 8, y + 9, z + 1, Blocks.torch, 3, 1);
		world.setBlock(x + 11, y + 9, z + 1, Blocks.torch, 3, 1);
		world.setBlock(x + 12, y + 9, z + 1, Blocks.glass, 0, 1);
		world.setBlock(x + 4, y + 9, z + 2, Blocks.glass, 0, 1);
		world.setBlock(x + 12, y + 9, z + 2, Blocks.glass, 0, 1);
		world.setBlock(x + 4, y + 9, z + 3, Blocks.log, 13, 1);
		world.setBlock(x + 5, y + 9, z + 3, Blocks.torch, 1, 1);
		world.setBlock(x + 11, y + 9, z + 3, Blocks.torch, 2, 1);
		world.setBlock(x + 12, y + 9, z + 3, Blocks.log, 13, 1);
		world.setBlock(x + 4, y + 9, z + 4, Blocks.glass, 0, 1);
		world.setBlock(x + 12, y + 9, z + 4, Blocks.glass, 0, 1);
		world.setBlock(x + 4, y + 9, z + 5, Blocks.glass, 0, 1);
		world.setBlock(x + 5, y + 9, z + 5, Blocks.torch, 4, 1);
		world.setBlock(x + 11, y + 9, z + 5, Blocks.torch, 4, 1);
		world.setBlock(x + 12, y + 9, z + 5, Blocks.glass, 0, 1);
		world.setBlock(x + 4, y + 9, z + 6, Blocks.log, 13, 1);
		world.setBlock(x + 5, y + 9, z + 6, Blocks.log, 13, 1);
		world.setBlock(x + 6, y + 9, z + 6, Blocks.torch, 4, 1);
		world.setBlock(x + 10, y + 9, z + 6, Blocks.torch, 4, 1);
		world.setBlock(x + 11, y + 9, z + 6, Blocks.log, 13, 1);
		world.setBlock(x + 12, y + 9, z + 6, Blocks.log, 13, 1);
		world.setBlock(x + 4, y + 9, z + 7, Blocks.log, 13, 1);
		world.setBlock(x + 5, y + 9, z + 7, Blocks.spruce_stairs, 3, 1);
		world.setBlock(x + 6, y + 9, z + 7, Blocks.log, 13, 1);
		world.setBlock(x + 7, y + 9, z + 7, Blocks.torch, 4, 1);
		world.setBlock(x + 9, y + 9, z + 7, Blocks.torch, 4, 1);
		world.setBlock(x + 10, y + 9, z + 7, Blocks.log, 13, 1);
		world.setBlock(x + 11, y + 9, z + 7, Blocks.spruce_stairs, 3, 1);
		world.setBlock(x + 12, y + 9, z + 7, Blocks.log, 13, 1);
		world.setBlock(x + 4, y + 9, z + 8, Blocks.fence, 0, 1);
		world.setBlock(x + 6, y + 9, z + 8, Blocks.log, 13, 1);
		world.setBlock(x + 7, y + 9, z + 8, Blocks.log, 13, 1);
		world.setBlock(x + 8, y + 9, z + 8, Blocks.log, 13, 1);
		world.setBlock(x + 9, y + 9, z + 8, Blocks.log, 13, 1);
		world.setBlock(x + 10, y + 9, z + 8, Blocks.log, 13, 1);
		world.setBlock(x + 12, y + 9, z + 8, Blocks.fence, 0, 1);
		world.setBlock(x + 4, y + 9, z + 9, Blocks.fence, 0, 1);
		world.setBlock(x + 6, y + 9, z + 9, Blocks.fence, 0, 1);
		world.setBlock(x + 7, y + 9, z + 9, Blocks.torch, 3, 1);
		world.setBlock(x + 9, y + 9, z + 9, Blocks.torch, 3, 1);
		world.setBlock(x + 10, y + 9, z + 9, Blocks.fence, 0, 1);
		world.setBlock(x + 12, y + 9, z + 9, Blocks.fence, 0, 1);
		world.setBlock(x + 8, y + 9, z + 11, Blocks.log, 13, 1);
		world.setBlock(x + 8, y + 9, z + 18, Blocks.ladder, 2, 1);
		world.setBlock(x + 8, y + 9, z + 19, Blocks.log, 13, 1);
		world.setBlock(x + 8, y + 9, z + 28, Blocks.log, 13, 1);
		world.setBlock(x + 6, y + 9, z + 31, Blocks.torch, 5, 1);
		world.setBlock(x + 10, y + 9, z + 31, Blocks.torch, 5, 1);
		world.setBlock(x + 4, y + 9, z + 34, Blocks.fence, 0, 1);
		world.setBlock(x + 12, y + 9, z + 34, Blocks.fence, 0, 1);
		world.setBlock(x + 4, y + 9, z + 35, Blocks.fence, 0, 1);
		world.setBlock(x + 5, y + 9, z + 35, Blocks.fence, 0, 1);
		world.setBlock(x + 11, y + 9, z + 35, Blocks.fence, 0, 1);
		world.setBlock(x + 12, y + 9, z + 35, Blocks.fence, 0, 1);
		world.setBlock(x + 5, y + 9, z + 36, Blocks.fence, 0, 1);
		world.setBlock(x + 6, y + 9, z + 36, Blocks.fence, 0, 1);
		world.setBlock(x + 10, y + 9, z + 36, Blocks.fence, 0, 1);
		world.setBlock(x + 11, y + 9, z + 36, Blocks.fence, 0, 1);
		world.setBlock(x + 6, y + 9, z + 37, Blocks.fence, 0, 1);
		world.setBlock(x + 7, y + 9, z + 37, Blocks.fence, 0, 1);
		world.setBlock(x + 9, y + 9, z + 37, Blocks.fence, 0, 1);
		world.setBlock(x + 10, y + 9, z + 37, Blocks.fence, 0, 1);
		world.setBlock(x + 7, y + 9, z + 38, Blocks.fence, 0, 1);
		world.setBlock(x + 8, y + 9, z + 38, Blocks.fence, 0, 1);
		world.setBlock(x + 9, y + 9, z + 38, Blocks.fence, 0, 1);
		world.setBlock(x + 8, y + 9, z + 39, Blocks.fence, 0, 1);
		world.setBlock(x + 8, y + 9, z + 40, Blocks.fence, 0, 1);
		world.setBlock(x + 8, y + 9, z + 41, Blocks.fence, 0, 1);
		world.setBlock(x + 8, y + 9, z + 42, Blocks.fence, 0, 1);
		world.setBlock(x + 8, y + 9, z + 43, Blocks.fence, 0, 1);
		world.setBlock(x + 8, y + 9, z + 44, Blocks.fence, 0, 1);
		world.setBlock(x + 8, y + 9, z + 45, Blocks.fence, 0, 1);
		world.setBlock(x + 4, y + 10, z + 0, Blocks.log, 13, 1);
		world.setBlock(x + 5, y + 10, z + 0, Blocks.log, 13, 1);
		world.setBlock(x + 6, y + 10, z + 0, Blocks.log, 13, 1);
		world.setBlock(x + 7, y + 10, z + 0, Blocks.log, 13, 1);
		world.setBlock(x + 8, y + 10, z + 0, Blocks.log, 13, 1);
		world.setBlock(x + 9, y + 10, z + 0, Blocks.log, 13, 1);
		world.setBlock(x + 10, y + 10, z + 0, Blocks.log, 13, 1);
		world.setBlock(x + 11, y + 10, z + 0, Blocks.log, 13, 1);
		world.setBlock(x + 12, y + 10, z + 0, Blocks.log, 13, 1);
		world.setBlock(x + 4, y + 10, z + 1, Blocks.log, 13, 1);
		world.setBlock(x + 5, y + 10, z + 1, Blocks.planks, 1, 1);
		world.setBlock(x + 6, y + 10, z + 1, Blocks.planks, 1, 1);
		world.setBlock(x + 7, y + 10, z + 1, Blocks.planks, 1, 1);
		world.setBlock(x + 8, y + 10, z + 1, Blocks.planks, 1, 1);
		world.setBlock(x + 9, y + 10, z + 1, Blocks.planks, 1, 1);
		world.setBlock(x + 10, y + 10, z + 1, Blocks.planks, 1, 1);
		world.setBlock(x + 11, y + 10, z + 1, Blocks.planks, 1, 1);
		world.setBlock(x + 12, y + 10, z + 1, Blocks.log, 13, 1);
		world.setBlock(x + 4, y + 10, z + 2, Blocks.log, 13, 1);
		world.setBlock(x + 5, y + 10, z + 2, Blocks.planks, 1, 1);
		world.setBlock(x + 6, y + 10, z + 2, Blocks.planks, 1, 1);
		world.setBlock(x + 7, y + 10, z + 2, Blocks.planks, 1, 1);
		world.setBlock(x + 8, y + 10, z + 2, Blocks.planks, 1, 1);
		world.setBlock(x + 9, y + 10, z + 2, Blocks.planks, 1, 1);
		world.setBlock(x + 10, y + 10, z + 2, Blocks.planks, 1, 1);
		world.setBlock(x + 11, y + 10, z + 2, Blocks.planks, 1, 1);
		world.setBlock(x + 12, y + 10, z + 2, Blocks.log, 13, 1);
		world.setBlock(x + 4, y + 10, z + 3, Blocks.log, 13, 1);
		world.setBlock(x + 5, y + 10, z + 3, Blocks.planks, 1, 1);
		world.setBlock(x + 6, y + 10, z + 3, Blocks.planks, 1, 1);
		world.setBlock(x + 7, y + 10, z + 3, Blocks.planks, 1, 1);
		world.setBlock(x + 8, y + 10, z + 3, Blocks.planks, 1, 1);
		world.setBlock(x + 9, y + 10, z + 3, Blocks.planks, 1, 1);
		world.setBlock(x + 10, y + 10, z + 3, Blocks.planks, 1, 1);
		world.setBlock(x + 11, y + 10, z + 3, Blocks.planks, 1, 1);
		world.setBlock(x + 12, y + 10, z + 3, Blocks.log, 13, 1);
		world.setBlock(x + 4, y + 10, z + 4, Blocks.log, 13, 1);
		world.setBlock(x + 5, y + 10, z + 4, Blocks.planks, 1, 1);
		world.setBlock(x + 6, y + 10, z + 4, Blocks.planks, 1, 1);
		world.setBlock(x + 7, y + 10, z + 4, Blocks.planks, 1, 1);
		world.setBlock(x + 8, y + 10, z + 4, Blocks.planks, 1, 1);
		world.setBlock(x + 9, y + 10, z + 4, Blocks.planks, 1, 1);
		world.setBlock(x + 10, y + 10, z + 4, Blocks.planks, 1, 1);
		world.setBlock(x + 11, y + 10, z + 4, Blocks.planks, 1, 1);
		world.setBlock(x + 12, y + 10, z + 4, Blocks.log, 13, 1);
		world.setBlock(x + 4, y + 10, z + 5, Blocks.log, 13, 1);
		world.setBlock(x + 5, y + 10, z + 5, Blocks.planks, 1, 1);
		world.setBlock(x + 6, y + 10, z + 5, Blocks.planks, 1, 1);
		world.setBlock(x + 7, y + 10, z + 5, Blocks.planks, 1, 1);
		world.setBlock(x + 8, y + 10, z + 5, Blocks.planks, 1, 1);
		world.setBlock(x + 9, y + 10, z + 5, Blocks.planks, 1, 1);
		world.setBlock(x + 10, y + 10, z + 5, Blocks.planks, 1, 1);
		world.setBlock(x + 11, y + 10, z + 5, Blocks.planks, 1, 1);
		world.setBlock(x + 12, y + 10, z + 5, Blocks.log, 13, 1);
		world.setBlock(x + 4, y + 10, z + 6, Blocks.log, 13, 1);
		world.setBlock(x + 5, y + 10, z + 6, Blocks.spruce_stairs, 3, 1);
		world.setBlock(x + 6, y + 10, z + 6, Blocks.planks, 1, 1);
		world.setBlock(x + 7, y + 10, z + 6, Blocks.planks, 1, 1);
		world.setBlock(x + 8, y + 10, z + 6, Blocks.planks, 1, 1);
		world.setBlock(x + 9, y + 10, z + 6, Blocks.planks, 1, 1);
		world.setBlock(x + 10, y + 10, z + 6, Blocks.planks, 1, 1);
		world.setBlock(x + 11, y + 10, z + 6, Blocks.spruce_stairs, 3, 1);
		world.setBlock(x + 12, y + 10, z + 6, Blocks.log, 13, 1);
		world.setBlock(x + 4, y + 10, z + 7, Blocks.fence, 0, 1);
		world.setBlock(x + 6, y + 10, z + 7, Blocks.log, 13, 1);
		world.setBlock(x + 7, y + 10, z + 7, Blocks.planks, 1, 1);
		world.setBlock(x + 8, y + 10, z + 7, Blocks.planks, 1, 1);
		world.setBlock(x + 9, y + 10, z + 7, Blocks.planks, 1, 1);
		world.setBlock(x + 10, y + 10, z + 7, Blocks.log, 13, 1);
		world.setBlock(x + 12, y + 10, z + 7, Blocks.fence, 0, 1);
		world.setBlock(x + 4, y + 10, z + 8, Blocks.fence, 0, 1);
		world.setBlock(x + 6, y + 10, z + 8, Blocks.log, 13, 1);
		world.setBlock(x + 7, y + 10, z + 8, Blocks.log, 13, 1);
		world.setBlock(x + 8, y + 10, z + 8, Blocks.log, 13, 1);
		world.setBlock(x + 9, y + 10, z + 8, Blocks.log, 13, 1);
		world.setBlock(x + 10, y + 10, z + 8, Blocks.log, 13, 1);
		world.setBlock(x + 12, y + 10, z + 8, Blocks.fence, 0, 1);
		world.setBlock(x + 6, y + 10, z + 9, Blocks.wooden_slab, 1, 1);
		world.setBlock(x + 7, y + 10, z + 9, Blocks.wooden_slab, 1, 1);
		world.setBlock(x + 8, y + 10, z + 9, Blocks.wooden_slab, 1, 1);
		world.setBlock(x + 9, y + 10, z + 9, Blocks.wooden_slab, 1, 1);
		world.setBlock(x + 10, y + 10, z + 9, Blocks.wooden_slab, 1, 1);
		world.setBlock(x + 8, y + 10, z + 10, Blocks.torch, 4, 1);
		world.setBlock(x + 7, y + 10, z + 11, Blocks.torch, 2, 1);
		world.setBlock(x + 8, y + 10, z + 11, Blocks.log, 13, 1);
		world.setBlock(x + 9, y + 10, z + 11, Blocks.torch, 1, 1);
		world.setBlock(x + 8, y + 10, z + 12, Blocks.torch, 3, 1);
		world.setBlock(x + 8, y + 10, z + 18, Blocks.ladder, 2, 1);
		world.setBlock(x + 8, y + 10, z + 19, Blocks.log, 13, 1);
		world.setBlock(x + 8, y + 10, z + 27, Blocks.torch, 4, 1);
		world.setBlock(x + 7, y + 10, z + 28, Blocks.torch, 2, 1);
		world.setBlock(x + 8, y + 10, z + 28, Blocks.log, 13, 1);
		world.setBlock(x + 9, y + 10, z + 28, Blocks.torch, 1, 1);
		world.setBlock(x + 8, y + 10, z + 29, Blocks.torch, 3, 1);
		world.setBlock(x + 5, y + 10, z + 35, Blocks.torch, 5, 1);
		world.setBlock(x + 11, y + 10, z + 35, Blocks.torch, 5, 1);
		world.setBlock(x + 7, y + 10, z + 38, Blocks.torch, 5, 1);
		world.setBlock(x + 9, y + 10, z + 38, Blocks.torch, 5, 1);
		world.setBlock(x + 4, y + 11, z + 0, Blocks.fence, 0, 1);
		world.setBlock(x + 5, y + 11, z + 0, Blocks.fence, 0, 1);
		world.setBlock(x + 6, y + 11, z + 0, Blocks.fence, 0, 1);
		world.setBlock(x + 7, y + 11, z + 0, Blocks.fence, 0, 1);
		world.setBlock(x + 8, y + 11, z + 0, Blocks.fence, 0, 1);
		world.setBlock(x + 9, y + 11, z + 0, Blocks.fence, 0, 1);
		world.setBlock(x + 10, y + 11, z + 0, Blocks.fence, 0, 1);
		world.setBlock(x + 11, y + 11, z + 0, Blocks.fence, 0, 1);
		world.setBlock(x + 12, y + 11, z + 0, Blocks.fence, 0, 1);
		world.setBlock(x + 4, y + 11, z + 1, Blocks.fence, 0, 1);
		world.setBlock(x + 12, y + 11, z + 1, Blocks.fence, 0, 1);
		world.setBlock(x + 4, y + 11, z + 2, Blocks.fence, 0, 1);
		world.setBlock(x + 6, y + 11, z + 2, ACBlocks.cannon, 2, 1);
		world.setBlock(x + 10, y + 11, z + 2, ACBlocks.cannon, 2, 1);
		world.setBlock(x + 12, y + 11, z + 2, Blocks.fence, 0, 1);
		world.setBlock(x + 4, y + 11, z + 3, Blocks.fence, 0, 1);
		world.setBlock(x + 12, y + 11, z + 3, Blocks.fence, 0, 1);
		world.setBlock(x + 4, y + 11, z + 4, Blocks.fence, 0, 1);
		world.setBlock(x + 12, y + 11, z + 4, Blocks.fence, 0, 1);
		world.setBlock(x + 4, y + 11, z + 5, Blocks.fence, 0, 1);
		world.setBlock(x + 12, y + 11, z + 5, Blocks.fence, 0, 1);
		world.setBlock(x + 4, y + 11, z + 6, Blocks.fence, 0, 1);
		world.setBlock(x + 12, y + 11, z + 6, Blocks.fence, 0, 1);
		world.setBlock(x + 4, y + 11, z + 7, Blocks.fence, 0, 1);
		world.setBlock(x + 6, y + 11, z + 7, Blocks.fence, 0, 1);
		world.setBlock(x + 8, y + 11, z + 7, Blocks.fence, 0, 1);
		world.setBlock(x + 10, y + 11, z + 7, Blocks.fence, 0, 1);
		world.setBlock(x + 12, y + 11, z + 7, Blocks.fence, 0, 1);
		world.setBlock(x + 6, y + 11, z + 8, Blocks.fence, 0, 1);
		world.setBlock(x + 7, y + 11, z + 8, Blocks.fence, 0, 1);
		world.setBlock(x + 8, y + 11, z + 8, Blocks.fence, 0, 1);
		world.setBlock(x + 9, y + 11, z + 8, Blocks.fence, 0, 1);
		world.setBlock(x + 10, y + 11, z + 8, Blocks.fence, 0, 1);
		world.setBlock(x + 8, y + 11, z + 11, Blocks.log, 13, 1);
		world.setBlock(x + 8, y + 11, z + 18, Blocks.ladder, 2, 1);
		world.setBlock(x + 1, y + 11, z + 19, Blocks.log, 13, 1);
		world.setBlock(x + 2, y + 11, z + 19, Blocks.log, 13, 1);
		world.setBlock(x + 3, y + 11, z + 19, Blocks.log, 13, 1);
		world.setBlock(x + 4, y + 11, z + 19, Blocks.log, 13, 1);
		world.setBlock(x + 5, y + 11, z + 19, Blocks.log, 13, 1);
		world.setBlock(x + 6, y + 11, z + 19, Blocks.log, 13, 1);
		world.setBlock(x + 7, y + 11, z + 19, Blocks.log, 13, 1);
		world.setBlock(x + 8, y + 11, z + 19, Blocks.log, 13, 1);
		world.setBlock(x + 9, y + 11, z + 19, Blocks.log, 13, 1);
		world.setBlock(x + 10, y + 11, z + 19, Blocks.log, 13, 1);
		world.setBlock(x + 11, y + 11, z + 19, Blocks.log, 13, 1);
		world.setBlock(x + 12, y + 11, z + 19, Blocks.log, 13, 1);
		world.setBlock(x + 13, y + 11, z + 19, Blocks.log, 13, 1);
		world.setBlock(x + 14, y + 11, z + 19, Blocks.log, 13, 1);
		world.setBlock(x + 15, y + 11, z + 19, Blocks.log, 13, 1);
		world.setBlock(x + 1, y + 11, z + 20, Blocks.wool, 14, 1);
		world.setBlock(x + 2, y + 11, z + 20, Blocks.wool, 14, 1);
		world.setBlock(x + 3, y + 11, z + 20, Blocks.wool, 14, 1);
		world.setBlock(x + 4, y + 11, z + 20, Blocks.wool, 0, 1);
		world.setBlock(x + 5, y + 11, z + 20, Blocks.wool, 0, 1);
		world.setBlock(x + 6, y + 11, z + 20, Blocks.wool, 0, 1);
		world.setBlock(x + 7, y + 11, z + 20, Blocks.wool, 14, 1);
		world.setBlock(x + 8, y + 11, z + 20, Blocks.wool, 14, 1);
		world.setBlock(x + 9, y + 11, z + 20, Blocks.wool, 14, 1);
		world.setBlock(x + 10, y + 11, z + 20, Blocks.wool, 0, 1);
		world.setBlock(x + 11, y + 11, z + 20, Blocks.wool, 0, 1);
		world.setBlock(x + 12, y + 11, z + 20, Blocks.wool, 0, 1);
		world.setBlock(x + 13, y + 11, z + 20, Blocks.wool, 14, 1);
		world.setBlock(x + 14, y + 11, z + 20, Blocks.wool, 14, 1);
		world.setBlock(x + 15, y + 11, z + 20, Blocks.wool, 14, 1);
		world.setBlock(x + 8, y + 11, z + 28, Blocks.log, 13, 1);
		world.setBlock(x + 4, y + 12, z + 0, Blocks.torch, 5, 1);
		world.setBlock(x + 12, y + 12, z + 0, Blocks.torch, 5, 1);
		world.setBlock(x + 7, y + 12, z + 6, Blocks.lever, 2, 1);
		world.setBlock(x + 8, y + 12, z + 6, Blocks.planks, 1, 1);
		world.setBlock(x + 9, y + 12, z + 6, Blocks.lever, 1, 1);
		world.setBlock(x + 4, y + 12, z + 7, Blocks.torch, 5, 1);
		world.setBlock(x + 8, y + 12, z + 7, Blocks.fence, 0, 1);
		world.setBlock(x + 12, y + 12, z + 7, Blocks.torch, 5, 1);
		world.setBlock(x + 6, y + 12, z + 8, Blocks.torch, 5, 1);
		world.setBlock(x + 10, y + 12, z + 8, Blocks.torch, 5, 1);
		world.setBlock(x + 8, y + 12, z + 11, Blocks.log, 13, 1);
		world.setBlock(x + 8, y + 12, z + 18, Blocks.ladder, 2, 1);
		world.setBlock(x + 8, y + 12, z + 19, Blocks.log, 13, 1);
		world.setBlock(x + 8, y + 12, z + 20, Blocks.torch, 3, 1);
		world.setBlock(x + 1, y + 12, z + 21, Blocks.wool, 14, 1);
		world.setBlock(x + 2, y + 12, z + 21, Blocks.wool, 14, 1);
		world.setBlock(x + 3, y + 12, z + 21, Blocks.wool, 14, 1);
		world.setBlock(x + 4, y + 12, z + 21, Blocks.wool, 0, 1);
		world.setBlock(x + 5, y + 12, z + 21, Blocks.wool, 0, 1);
		world.setBlock(x + 6, y + 12, z + 21, Blocks.wool, 0, 1);
		world.setBlock(x + 7, y + 12, z + 21, Blocks.wool, 14, 1);
		world.setBlock(x + 8, y + 12, z + 21, Blocks.wool, 14, 1);
		world.setBlock(x + 9, y + 12, z + 21, Blocks.wool, 14, 1);
		world.setBlock(x + 10, y + 12, z + 21, Blocks.wool, 0, 1);
		world.setBlock(x + 11, y + 12, z + 21, Blocks.wool, 0, 1);
		world.setBlock(x + 12, y + 12, z + 21, Blocks.wool, 0, 1);
		world.setBlock(x + 13, y + 12, z + 21, Blocks.wool, 14, 1);
		world.setBlock(x + 14, y + 12, z + 21, Blocks.wool, 14, 1);
		world.setBlock(x + 15, y + 12, z + 21, Blocks.wool, 14, 1);
		world.setBlock(x + 8, y + 12, z + 28, Blocks.log, 13, 1);
		world.setBlock(x + 8, y + 13, z + 11, Blocks.log, 13, 1);
		world.setBlock(x + 8, y + 13, z + 18, Blocks.ladder, 2, 1);
		world.setBlock(x + 8, y + 13, z + 19, Blocks.log, 13, 1);
		world.setBlock(x + 1, y + 13, z + 21, Blocks.wool, 14, 1);
		world.setBlock(x + 2, y + 13, z + 21, Blocks.wool, 14, 1);
		world.setBlock(x + 3, y + 13, z + 21, Blocks.wool, 14, 1);
		world.setBlock(x + 4, y + 13, z + 21, Blocks.wool, 0, 1);
		world.setBlock(x + 5, y + 13, z + 21, Blocks.wool, 0, 1);
		world.setBlock(x + 6, y + 13, z + 21, Blocks.wool, 0, 1);
		world.setBlock(x + 7, y + 13, z + 21, Blocks.wool, 14, 1);
		world.setBlock(x + 8, y + 13, z + 21, Blocks.wool, 14, 1);
		world.setBlock(x + 9, y + 13, z + 21, Blocks.wool, 14, 1);
		world.setBlock(x + 10, y + 13, z + 21, Blocks.wool, 0, 1);
		world.setBlock(x + 11, y + 13, z + 21, Blocks.wool, 0, 1);
		world.setBlock(x + 12, y + 13, z + 21, Blocks.wool, 0, 1);
		world.setBlock(x + 13, y + 13, z + 21, Blocks.wool, 14, 1);
		world.setBlock(x + 14, y + 13, z + 21, Blocks.wool, 14, 1);
		world.setBlock(x + 15, y + 13, z + 21, Blocks.wool, 14, 1);
		world.setBlock(x + 8, y + 13, z + 28, Blocks.log, 13, 1);
		world.setBlock(x + 4, y + 14, z + 11, Blocks.log, 13, 1);
		world.setBlock(x + 5, y + 14, z + 11, Blocks.log, 13, 1);
		world.setBlock(x + 6, y + 14, z + 11, Blocks.log, 13, 1);
		world.setBlock(x + 7, y + 14, z + 11, Blocks.log, 13, 1);
		world.setBlock(x + 8, y + 14, z + 11, Blocks.log, 13, 1);
		world.setBlock(x + 9, y + 14, z + 11, Blocks.log, 13, 1);
		world.setBlock(x + 10, y + 14, z + 11, Blocks.log, 13, 1);
		world.setBlock(x + 11, y + 14, z + 11, Blocks.log, 13, 1);
		world.setBlock(x + 12, y + 14, z + 11, Blocks.log, 13, 1);
		world.setBlock(x + 4, y + 14, z + 12, Blocks.wool, 14, 1);
		world.setBlock(x + 5, y + 14, z + 12, Blocks.wool, 0, 1);
		world.setBlock(x + 6, y + 14, z + 12, Blocks.wool, 0, 1);
		world.setBlock(x + 7, y + 14, z + 12, Blocks.wool, 14, 1);
		world.setBlock(x + 8, y + 14, z + 12, Blocks.wool, 14, 1);
		world.setBlock(x + 9, y + 14, z + 12, Blocks.wool, 14, 1);
		world.setBlock(x + 10, y + 14, z + 12, Blocks.wool, 0, 1);
		world.setBlock(x + 11, y + 14, z + 12, Blocks.wool, 0, 1);
		world.setBlock(x + 12, y + 14, z + 12, Blocks.wool, 14, 1);
		world.setBlock(x + 8, y + 14, z + 18, Blocks.ladder, 2, 1);
		world.setBlock(x + 8, y + 14, z + 19, Blocks.log, 13, 1);
		world.setBlock(x + 1, y + 14, z + 21, Blocks.wool, 14, 1);
		world.setBlock(x + 2, y + 14, z + 21, Blocks.wool, 14, 1);
		world.setBlock(x + 3, y + 14, z + 21, Blocks.wool, 14, 1);
		world.setBlock(x + 4, y + 14, z + 21, Blocks.wool, 0, 1);
		world.setBlock(x + 5, y + 14, z + 21, Blocks.wool, 0, 1);
		world.setBlock(x + 6, y + 14, z + 21, Blocks.wool, 0, 1);
		world.setBlock(x + 7, y + 14, z + 21, Blocks.wool, 14, 1);
		world.setBlock(x + 8, y + 14, z + 21, Blocks.wool, 14, 1);
		world.setBlock(x + 9, y + 14, z + 21, Blocks.wool, 14, 1);
		world.setBlock(x + 10, y + 14, z + 21, Blocks.wool, 0, 1);
		world.setBlock(x + 11, y + 14, z + 21, Blocks.wool, 0, 1);
		world.setBlock(x + 12, y + 14, z + 21, Blocks.wool, 0, 1);
		world.setBlock(x + 13, y + 14, z + 21, Blocks.wool, 14, 1);
		world.setBlock(x + 14, y + 14, z + 21, Blocks.wool, 14, 1);
		world.setBlock(x + 15, y + 14, z + 21, Blocks.wool, 14, 1);
		world.setBlock(x + 4, y + 14, z + 28, Blocks.log, 13, 1);
		world.setBlock(x + 5, y + 14, z + 28, Blocks.log, 13, 1);
		world.setBlock(x + 6, y + 14, z + 28, Blocks.log, 13, 1);
		world.setBlock(x + 7, y + 14, z + 28, Blocks.log, 13, 1);
		world.setBlock(x + 8, y + 14, z + 28, Blocks.log, 13, 1);
		world.setBlock(x + 9, y + 14, z + 28, Blocks.log, 13, 1);
		world.setBlock(x + 10, y + 14, z + 28, Blocks.log, 13, 1);
		world.setBlock(x + 11, y + 14, z + 28, Blocks.log, 13, 1);
		world.setBlock(x + 12, y + 14, z + 28, Blocks.log, 13, 1);
		world.setBlock(x + 4, y + 14, z + 29, Blocks.wool, 14, 1);
		world.setBlock(x + 5, y + 14, z + 29, Blocks.wool, 0, 1);
		world.setBlock(x + 6, y + 14, z + 29, Blocks.wool, 0, 1);
		world.setBlock(x + 7, y + 14, z + 29, Blocks.wool, 14, 1);
		world.setBlock(x + 8, y + 14, z + 29, Blocks.wool, 14, 1);
		world.setBlock(x + 9, y + 14, z + 29, Blocks.wool, 14, 1);
		world.setBlock(x + 10, y + 14, z + 29, Blocks.wool, 0, 1);
		world.setBlock(x + 11, y + 14, z + 29, Blocks.wool, 0, 1);
		world.setBlock(x + 12, y + 14, z + 29, Blocks.wool, 14, 1);
		world.setBlock(x + 8, y + 15, z + 11, Blocks.log, 13, 1);
		world.setBlock(x + 8, y + 15, z + 12, Blocks.torch, 3, 1);
		world.setBlock(x + 4, y + 15, z + 13, Blocks.wool, 14, 1);
		world.setBlock(x + 5, y + 15, z + 13, Blocks.wool, 0, 1);
		world.setBlock(x + 6, y + 15, z + 13, Blocks.wool, 0, 1);
		world.setBlock(x + 7, y + 15, z + 13, Blocks.wool, 14, 1);
		world.setBlock(x + 8, y + 15, z + 13, Blocks.wool, 14, 1);
		world.setBlock(x + 9, y + 15, z + 13, Blocks.wool, 14, 1);
		world.setBlock(x + 10, y + 15, z + 13, Blocks.wool, 0, 1);
		world.setBlock(x + 11, y + 15, z + 13, Blocks.wool, 0, 1);
		world.setBlock(x + 12, y + 15, z + 13, Blocks.wool, 14, 1);
		world.setBlock(x + 8, y + 15, z + 18, Blocks.ladder, 2, 1);
		world.setBlock(x + 8, y + 15, z + 19, Blocks.log, 13, 1);
		world.setBlock(x + 1, y + 15, z + 22, Blocks.wool, 14, 1);
		world.setBlock(x + 2, y + 15, z + 22, Blocks.wool, 14, 1);
		world.setBlock(x + 3, y + 15, z + 22, Blocks.wool, 14, 1);
		world.setBlock(x + 4, y + 15, z + 22, Blocks.wool, 0, 1);
		world.setBlock(x + 5, y + 15, z + 22, Blocks.wool, 0, 1);
		world.setBlock(x + 6, y + 15, z + 22, Blocks.wool, 0, 1);
		world.setBlock(x + 7, y + 15, z + 22, Blocks.wool, 14, 1);
		world.setBlock(x + 8, y + 15, z + 22, Blocks.wool, 14, 1);
		world.setBlock(x + 9, y + 15, z + 22, Blocks.wool, 14, 1);
		world.setBlock(x + 10, y + 15, z + 22, Blocks.wool, 0, 1);
		world.setBlock(x + 11, y + 15, z + 22, Blocks.wool, 0, 1);
		world.setBlock(x + 12, y + 15, z + 22, Blocks.wool, 0, 1);
		world.setBlock(x + 13, y + 15, z + 22, Blocks.wool, 14, 1);
		world.setBlock(x + 14, y + 15, z + 22, Blocks.wool, 14, 1);
		world.setBlock(x + 15, y + 15, z + 22, Blocks.wool, 14, 1);
		world.setBlock(x + 8, y + 15, z + 28, Blocks.log, 13, 1);
		world.setBlock(x + 8, y + 15, z + 29, Blocks.torch, 3, 1);
		world.setBlock(x + 4, y + 15, z + 30, Blocks.wool, 14, 1);
		world.setBlock(x + 5, y + 15, z + 30, Blocks.wool, 0, 1);
		world.setBlock(x + 6, y + 15, z + 30, Blocks.wool, 0, 1);
		world.setBlock(x + 7, y + 15, z + 30, Blocks.wool, 14, 1);
		world.setBlock(x + 8, y + 15, z + 30, Blocks.wool, 14, 1);
		world.setBlock(x + 9, y + 15, z + 30, Blocks.wool, 14, 1);
		world.setBlock(x + 10, y + 15, z + 30, Blocks.wool, 0, 1);
		world.setBlock(x + 11, y + 15, z + 30, Blocks.wool, 0, 1);
		world.setBlock(x + 12, y + 15, z + 30, Blocks.wool, 14, 1);
		world.setBlock(x + 8, y + 16, z + 11, Blocks.log, 13, 1);
		world.setBlock(x + 4, y + 16, z + 13, Blocks.wool, 14, 1);
		world.setBlock(x + 5, y + 16, z + 13, Blocks.wool, 0, 1);
		world.setBlock(x + 6, y + 16, z + 13, Blocks.wool, 0, 1);
		world.setBlock(x + 7, y + 16, z + 13, Blocks.wool, 14, 1);
		world.setBlock(x + 8, y + 16, z + 13, Blocks.wool, 14, 1);
		world.setBlock(x + 9, y + 16, z + 13, Blocks.wool, 14, 1);
		world.setBlock(x + 10, y + 16, z + 13, Blocks.wool, 0, 1);
		world.setBlock(x + 11, y + 16, z + 13, Blocks.wool, 0, 1);
		world.setBlock(x + 12, y + 16, z + 13, Blocks.wool, 14, 1);
		world.setBlock(x + 8, y + 16, z + 18, Blocks.ladder, 2, 1);
		world.setBlock(x + 8, y + 16, z + 19, Blocks.log, 13, 1);
		world.setBlock(x + 1, y + 16, z + 22, Blocks.wool, 14, 1);
		world.setBlock(x + 2, y + 16, z + 22, Blocks.wool, 14, 1);
		world.setBlock(x + 3, y + 16, z + 22, Blocks.wool, 14, 1);
		world.setBlock(x + 4, y + 16, z + 22, Blocks.wool, 0, 1);
		world.setBlock(x + 5, y + 16, z + 22, Blocks.wool, 0, 1);
		world.setBlock(x + 6, y + 16, z + 22, Blocks.wool, 0, 1);
		world.setBlock(x + 7, y + 16, z + 22, Blocks.wool, 14, 1);
		world.setBlock(x + 8, y + 16, z + 22, Blocks.wool, 14, 1);
		world.setBlock(x + 9, y + 16, z + 22, Blocks.wool, 14, 1);
		world.setBlock(x + 10, y + 16, z + 22, Blocks.wool, 0, 1);
		world.setBlock(x + 11, y + 16, z + 22, Blocks.wool, 0, 1);
		world.setBlock(x + 12, y + 16, z + 22, Blocks.wool, 0, 1);
		world.setBlock(x + 13, y + 16, z + 22, Blocks.wool, 14, 1);
		world.setBlock(x + 14, y + 16, z + 22, Blocks.wool, 14, 1);
		world.setBlock(x + 15, y + 16, z + 22, Blocks.wool, 14, 1);
		world.setBlock(x + 8, y + 16, z + 28, Blocks.log, 13, 1);
		world.setBlock(x + 4, y + 16, z + 30, Blocks.wool, 14, 1);
		world.setBlock(x + 5, y + 16, z + 30, Blocks.wool, 0, 1);
		world.setBlock(x + 6, y + 16, z + 30, Blocks.wool, 0, 1);
		world.setBlock(x + 7, y + 16, z + 30, Blocks.wool, 14, 1);
		world.setBlock(x + 8, y + 16, z + 30, Blocks.wool, 14, 1);
		world.setBlock(x + 9, y + 16, z + 30, Blocks.wool, 14, 1);
		world.setBlock(x + 10, y + 16, z + 30, Blocks.wool, 0, 1);
		world.setBlock(x + 11, y + 16, z + 30, Blocks.wool, 0, 1);
		world.setBlock(x + 12, y + 16, z + 30, Blocks.wool, 14, 1);
		world.setBlock(x + 8, y + 17, z + 11, Blocks.log, 13, 1);
		world.setBlock(x + 4, y + 17, z + 13, Blocks.wool, 14, 1);
		world.setBlock(x + 5, y + 17, z + 13, Blocks.wool, 0, 1);
		world.setBlock(x + 6, y + 17, z + 13, Blocks.wool, 0, 1);
