/*
 *** MADE BY MRPONYCAPTAIN'S .SCHEMATIC TO .JAVA CONVERTING TOOL v2.0 ***
 */

package net.arcticraft.world.gen;

import java.util.Random;

import net.arcticraft.main.Arcticraft;
import net.minecraft.block.Block;
import net.minecraft.init.Blocks;
import net.minecraft.world.World;
import net.minecraft.world.chunk.IChunkProvider;
import net.minecraft.world.gen.feature.WorldGenerator;
import cpw.mods.fml.common.IWorldGenerator;

public class WorldGenShip extends WorldGenerator implements IWorldGenerator{

	public WorldGenShip(){}

	@Override
	public void generate(Random random, int chunkX, int chunkZ, World world, IChunkProvider chunkGenerator, IChunkProvider chunkProvider)
	{}

	public void setBlock(World world, int x, int y, int z, Block block, int metadata)
	{
		Block b1 = world.getBlock(x, y, z);

		if(b1.isAir(world, x, y, z) || b1.isLeaves(world, x, y, z))
		{
			world.setBlock(x, y, z, block, metadata, 2);
		}
	}

	public boolean generate(World world, Random rand, int i, int j, int k)
	{
		Arcticraft.notifyOfGenertion("ship", Integer.toString(i), Integer.toString(k));
		this.setBlock(world, i + 0, j + 7, k + 3, Blocks.log, 13);
		this.setBlock(world, i + 0, j + 7, k + 4, Blocks.log, 13);
		this.setBlock(world, i + 0, j + 7, k + 5, Blocks.log, 13);
		this.setBlock(world, i + 0, j + 7, k + 6, Blocks.log, 13);
		this.setBlock(world, i + 0, j + 7, k + 7, Blocks.log, 13);
		this.setBlock(world, i + 0, j + 7, k + 8, Blocks.log, 13);
		this.setBlock(world, i + 0, j + 7, k + 9, Blocks.log, 13);
		this.setBlock(world, i + 0, j + 7, k + 10, Blocks.log, 13);
		this.setBlock(world, i + 0, j + 7, k + 11, Blocks.log, 13);
		this.setBlock(world, i + 0, j + 8, k + 3, Blocks.log, 13);
		this.setBlock(world, i + 0, j + 8, k + 4, Blocks.log, 13);
		this.setBlock(world, i + 0, j + 8, k + 5, Blocks.glass, 0);
		this.setBlock(world, i + 0, j + 8, k + 6, Blocks.glass, 0);
		this.setBlock(world, i + 0, j + 8, k + 7, Blocks.log, 13);
		this.setBlock(world, i + 0, j + 8, k + 8, Blocks.glass, 0);
		this.setBlock(world, i + 0, j + 8, k + 9, Blocks.glass, 0);
		this.setBlock(world, i + 0, j + 8, k + 10, Blocks.log, 13);
		this.setBlock(world, i + 0, j + 8, k + 11, Blocks.log, 13);
		this.setBlock(world, i + 0, j + 9, k + 3, Blocks.log, 13);
		this.setBlock(world, i + 0, j + 9, k + 4, Blocks.log, 13);
		this.setBlock(world, i + 0, j + 9, k + 5, Blocks.glass, 0);
		this.setBlock(world, i + 0, j + 9, k + 6, Blocks.glass, 0);
		this.setBlock(world, i + 0, j + 9, k + 7, Blocks.log, 13);
		this.setBlock(world, i + 0, j + 9, k + 8, Blocks.glass, 0);
		this.setBlock(world, i + 0, j + 9, k + 9, Blocks.glass, 0);
		this.setBlock(world, i + 0, j + 9, k + 10, Blocks.log, 13);
		this.setBlock(world, i + 0, j + 9, k + 11, Blocks.log, 13);
		this.setBlock(world, i + 0, j + 10, k + 3, Blocks.log, 13);
		this.setBlock(world, i + 0, j + 10, k + 4, Blocks.log, 13);
		this.setBlock(world, i + 0, j + 10, k + 5, Blocks.log, 13);
		this.setBlock(world, i + 0, j + 10, k + 6, Blocks.log, 13);
		this.setBlock(world, i + 0, j + 10, k + 7, Blocks.log, 13);
		this.setBlock(world, i + 0, j + 10, k + 8, Blocks.log, 13);
		this.setBlock(world, i + 0, j + 10, k + 9, Blocks.log, 13);
		this.setBlock(world, i + 0, j + 10, k + 10, Blocks.log, 13);
		this.setBlock(world, i + 0, j + 10, k + 11, Blocks.log, 13);
		this.setBlock(world, i + 0, j + 11, k + 3, Blocks.fence, 0);
		this.setBlock(world, i + 0, j + 11, k + 4, Blocks.fence, 0);
		this.setBlock(world, i + 0, j + 11, k + 5, Blocks.fence, 0);
		this.setBlock(world, i + 0, j + 11, k + 6, Blocks.fence, 0);
		this.setBlock(world, i + 0, j + 11, k + 7, Blocks.fence, 0);
		this.setBlock(world, i + 0, j + 11, k + 8, Blocks.fence, 0);
		this.setBlock(world, i + 0, j + 11, k + 9, Blocks.fence, 0);
		this.setBlock(world, i + 0, j + 11, k + 10, Blocks.fence, 0);
		this.setBlock(world, i + 0, j + 11, k + 11, Blocks.fence, 0);
		this.setBlock(world, i + 1, j + 6, k + 3, Blocks.log, 13);
		this.setBlock(world, i + 1, j + 6, k + 4, Blocks.log, 13);
		this.setBlock(world, i + 1, j + 6, k + 5, Blocks.log, 13);
		this.setBlock(world, i + 1, j + 6, k + 6, Blocks.log, 13);
		this.setBlock(world, i + 1, j + 6, k + 7, Blocks.log, 13);
		this.setBlock(world, i + 1, j + 6, k + 8, Blocks.log, 13);
		this.setBlock(world, i + 1, j + 6, k + 9, Blocks.log, 13);
		this.setBlock(world, i + 1, j + 6, k + 10, Blocks.log, 13);
		this.setBlock(world, i + 1, j + 6, k + 11, Blocks.log, 13);
		this.setBlock(world, i + 1, j + 7, k + 3, Blocks.log, 13);
		this.setBlock(world, i + 1, j + 7, k + 4, Blocks.wooden_slab, 1);
		this.setBlock(world, i + 1, j + 7, k + 5, Blocks.wooden_slab, 1);
		this.setBlock(world, i + 1, j + 7, k + 6, Blocks.wool, 0);
		this.setBlock(world, i + 1, j + 7, k + 7, Blocks.wool, 0);
		this.setBlock(world, i + 1, j + 7, k + 8, Blocks.wool, 0);
		this.setBlock(world, i + 1, j + 7, k + 9, Blocks.wooden_slab, 1);
		this.setBlock(world, i + 1, j + 7, k + 10, Blocks.wooden_slab, 1);
		this.setBlock(world, i + 1, j + 7, k + 11, Blocks.log, 13);
		this.setBlock(world, i + 1, j + 8, k + 3, Blocks.glass, 0);
		this.setBlock(world, i + 1, j + 8, k + 11, Blocks.glass, 0);
		this.setBlock(world, i + 1, j + 9, k + 3, Blocks.glass, 0);
		this.setBlock(world, i + 1, j + 9, k + 11, Blocks.glass, 0);
		this.setBlock(world, i + 1, j + 10, k + 3, Blocks.log, 13);
		this.setBlock(world, i + 1, j + 10, k + 4, Blocks.planks, 1);
		this.setBlock(world, i + 1, j + 10, k + 5, Blocks.planks, 1);
		this.setBlock(world, i + 1, j + 10, k + 6, Blocks.planks, 1);
		this.setBlock(world, i + 1, j + 10, k + 7, Blocks.planks, 1);
		this.setBlock(world, i + 1, j + 10, k + 8, Blocks.planks, 1);
		this.setBlock(world, i + 1, j + 10, k + 9, Blocks.planks, 1);
		this.setBlock(world, i + 1, j + 10, k + 10, Blocks.planks, 1);
		this.setBlock(world, i + 1, j + 10, k + 11, Blocks.log, 13);
		this.setBlock(world, i + 1, j + 11, k + 3, Blocks.fence, 0);
		this.setBlock(world, i + 1, j + 11, k + 11, Blocks.fence, 0);
		this.setBlock(world, i + 2, j + 5, k + 4, Blocks.log, 13);
		this.setBlock(world, i + 2, j + 5, k + 5, Blocks.log, 13);
		this.setBlock(world, i + 2, j + 5, k + 6, Blocks.log, 13);
		this.setBlock(world, i + 2, j + 5, k + 7, Blocks.log, 13);
		this.setBlock(world, i + 2, j + 5, k + 8, Blocks.log, 13);
		this.setBlock(world, i + 2, j + 5, k + 9, Blocks.log, 13);
		this.setBlock(world, i + 2, j + 5, k + 10, Blocks.log, 13);
		this.setBlock(world, i + 2, j + 6, k + 3, Blocks.log, 13);
		this.setBlock(world, i + 2, j + 6, k + 4, Blocks.planks, 1);
		this.setBlock(world, i + 2, j + 6, k + 5, Blocks.planks, 1);
		this.setBlock(world, i + 2, j + 6, k + 6, Blocks.planks, 1);
		this.setBlock(world, i + 2, j + 6, k + 7, Blocks.planks, 1);
		this.setBlock(world, i + 2, j + 6, k + 8, Blocks.planks, 1);
		this.setBlock(world, i + 2, j + 6, k + 9, Blocks.planks, 1);
		this.setBlock(world, i + 2, j + 6, k + 10, Blocks.planks, 1);
		this.setBlock(world, i + 2, j + 6, k + 11, Blocks.log, 13);
		this.setBlock(world, i + 2, j + 7, k + 3, Blocks.log, 13);
		this.setBlock(world, i + 2, j + 7, k + 5, Blocks.wooden_slab, 1);
		this.setBlock(world, i + 2, j + 7, k + 6, Blocks.wool, 14);
		this.setBlock(world, i + 2, j + 7, k + 7, Blocks.wool, 14);
		this.setBlock(world, i + 2, j + 7, k + 8, Blocks.wool, 14);
		this.setBlock(world, i + 2, j + 7, k + 9, Blocks.wooden_slab, 1);
		this.setBlock(world, i + 2, j + 7, k + 11, Blocks.log, 13);
		this.setBlock(world, i + 2, j + 8, k + 3, Blocks.glass, 0);
		this.setBlock(world, i + 2, j + 8, k + 11, Blocks.glass, 0);
		this.setBlock(world, i + 2, j + 9, k + 3, Blocks.glass, 0);
		this.setBlock(world, i + 2, j + 9, k + 11, Blocks.glass, 0);
		this.setBlock(world, i + 2, j + 10, k + 3, Blocks.log, 13);
		this.setBlock(world, i + 2, j + 10, k + 4, Blocks.planks, 1);
		this.setBlock(world, i + 2, j + 10, k + 5, Blocks.planks, 1);
		this.setBlock(world, i + 2, j + 10, k + 6, Blocks.planks, 1);
		this.setBlock(world, i + 2, j + 10, k + 7, Blocks.planks, 1);
		this.setBlock(world, i + 2, j + 10, k + 8, Blocks.planks, 1);
		this.setBlock(world, i + 2, j + 10, k + 9, Blocks.planks, 1);
		this.setBlock(world, i + 2, j + 10, k + 10, Blocks.planks, 1);
		this.setBlock(world, i + 2, j + 10, k + 11, Blocks.log, 13);
		this.setBlock(world, i + 2, j + 11, k + 3, Blocks.fence, 0);
		this.setBlock(world, i + 2, j + 11, k + 5, Blocks.lapis_block, 2);
		this.setBlock(world, i + 2, j + 11, k + 9, Blocks.lapis_block, 2);
		this.setBlock(world, i + 2, j + 11, k + 11, Blocks.fence, 0);
		this.setBlock(world, i + 3, j + 5, k + 4, Blocks.log, 13);
		this.setBlock(world, i + 3, j + 5, k + 5, Blocks.log, 13);
		this.setBlock(world, i + 3, j + 5, k + 6, Blocks.log, 13);
		this.setBlock(world, i + 3, j + 5, k + 7, Blocks.log, 13);
		this.setBlock(world, i + 3, j + 5, k + 8, Blocks.log, 13);
		this.setBlock(world, i + 3, j + 5, k + 9, Blocks.log, 13);
		this.setBlock(world, i + 3, j + 5, k + 10, Blocks.log, 13);
		this.setBlock(world, i + 3, j + 6, k + 3, Blocks.log, 13);
		this.setBlock(world, i + 3, j + 6, k + 4, Blocks.planks, 1);
		this.setBlock(world, i + 3, j + 6, k + 5, Blocks.planks, 1);
		this.setBlock(world, i + 3, j + 6, k + 6, Blocks.planks, 1);
		this.setBlock(world, i + 3, j + 6, k + 7, Blocks.planks, 1);
		this.setBlock(world, i + 3, j + 6, k + 8, Blocks.planks, 1);
		this.setBlock(world, i + 3, j + 6, k + 9, Blocks.planks, 1);
		this.setBlock(world, i + 3, j + 6, k + 10, Blocks.planks, 1);
		this.setBlock(world, i + 3, j + 6, k + 11, Blocks.log, 13);
		this.setBlock(world, i + 3, j + 7, k + 3, Blocks.log, 13);
		this.setBlock(world, i + 3, j + 7, k + 6, Blocks.wooden_slab, 1);
		this.setBlock(world, i + 3, j + 7, k + 7, Blocks.wooden_slab, 1);
		this.setBlock(world, i + 3, j + 7, k + 8, Blocks.wooden_slab, 1);
		this.setBlock(world, i + 3, j + 7, k + 11, Blocks.log, 13);
		this.setBlock(world, i + 3, j + 8, k + 3, Blocks.log, 13);
		this.setBlock(world, i + 3, j + 8, k + 11, Blocks.log, 13);
		this.setBlock(world, i + 3, j + 9, k + 3, Blocks.log, 13);
		this.setBlock(world, i + 3, j + 9, k + 11, Blocks.log, 13);
		this.setBlock(world, i + 3, j + 10, k + 3, Blocks.log, 13);
		this.setBlock(world, i + 3, j + 10, k + 4, Blocks.planks, 1);
		this.setBlock(world, i + 3, j + 10, k + 5, Blocks.planks, 1);
		this.setBlock(world, i + 3, j + 10, k + 6, Blocks.planks, 1);
		this.setBlock(world, i + 3, j + 10, k + 7, Blocks.planks, 1);
		this.setBlock(world, i + 3, j + 10, k + 8, Blocks.planks, 1);
		this.setBlock(world, i + 3, j + 10, k + 9, Blocks.planks, 1);
		this.setBlock(world, i + 3, j + 10, k + 10, Blocks.planks, 1);
		this.setBlock(world, i + 3, j + 10, k + 11, Blocks.log, 13);
		this.setBlock(world, i + 3, j + 11, k + 3, Blocks.fence, 0);
		this.setBlock(world, i + 3, j + 11, k + 7, Blocks.wool, 11);
		this.setBlock(world, i + 3, j + 11, k + 11, Blocks.fence, 0);
		this.setBlock(world, i + 4, j + 5, k + 4, Blocks.log, 13);
		this.setBlock(world, i + 4, j + 5, k + 5, Blocks.log, 13);
		this.setBlock(world, i + 4, j + 5, k + 6, Blocks.log, 13);
		this.setBlock(world, i + 4, j + 5, k + 7, Blocks.log, 13);
		this.setBlock(world, i + 4, j + 5, k + 8, Blocks.log, 13);
		this.setBlock(world, i + 4, j + 5, k + 9, Blocks.log, 13);
		this.setBlock(world, i + 4, j + 5, k + 10, Blocks.log, 13);
		this.setBlock(world, i + 4, j + 6, k + 3, Blocks.log, 13);
		this.setBlock(world, i + 4, j + 6, k + 4, Blocks.planks, 1);
		this.setBlock(world, i + 4, j + 6, k + 5, Blocks.planks, 1);
		this.setBlock(world, i + 4, j + 6, k + 6, Blocks.planks, 1);
		this.setBlock(world, i + 4, j + 6, k + 7, Blocks.planks, 1);
		this.setBlock(world, i + 4, j + 6, k + 8, Blocks.planks, 1);
		this.setBlock(world, i + 4, j + 6, k + 9, Blocks.planks, 1);
		this.setBlock(world, i + 4, j + 6, k + 10, Blocks.planks, 1);
		this.setBlock(world, i + 4, j + 6, k + 11, Blocks.log, 13);
		this.setBlock(world, i + 4, j + 7, k + 3, Blocks.log, 13);
		this.setBlock(world, i + 4, j + 7, k + 11, Blocks.log, 13);
		this.setBlock(world, i + 4, j + 8, k + 3, Blocks.glass, 0);
		this.setBlock(world, i + 4, j + 8, k + 11, Blocks.glass, 0);
		this.setBlock(world, i + 4, j + 9, k + 3, Blocks.glass, 0);
		this.setBlock(world, i + 4, j + 9, k + 11, Blocks.glass, 0);
		this.setBlock(world, i + 4, j + 10, k + 3, Blocks.log, 13);
		this.setBlock(world, i + 4, j + 10, k + 4, Blocks.planks, 1);
		this.setBlock(world, i + 4, j + 10, k + 5, Blocks.planks, 1);
		this.setBlock(world, i + 4, j + 10, k + 6, Blocks.planks, 1);
		this.setBlock(world, i + 4, j + 10, k + 7, Blocks.planks, 1);
		this.setBlock(world, i + 4, j + 10, k + 8, Blocks.planks, 1);
		this.setBlock(world, i + 4, j + 10, k + 9, Blocks.planks, 1);
		this.setBlock(world, i + 4, j + 10, k + 10, Blocks.planks, 1);
		this.setBlock(world, i + 4, j + 10, k + 11, Blocks.log, 13);
		this.setBlock(world, i + 4, j + 11, k + 3, Blocks.fence, 0);
		this.setBlock(world, i + 4, j + 11, k + 11, Blocks.fence, 0);
		this.setBlock(world, i + 5, j + 4, k + 4, Blocks.log, 13);
		this.setBlock(world, i + 5, j + 4, k + 5, Blocks.log, 13);
		this.setBlock(world, i + 5, j + 4, k + 6, Blocks.log, 13);
		this.setBlock(world, i + 5, j + 4, k + 7, Blocks.log, 13);
		this.setBlock(world, i + 5, j + 4, k + 8, Blocks.log, 13);
		this.setBlock(world, i + 5, j + 4, k + 9, Blocks.log, 13);
		this.setBlock(world, i + 5, j + 4, k + 10, Blocks.log, 13);
		this.setBlock(world, i + 5, j + 5, k + 3, Blocks.log, 13);
		this.setBlock(world, i + 5, j + 5, k + 4, Blocks.log, 13);
		this.setBlock(world, i + 5, j + 5, k + 5, Blocks.log, 13);
		this.setBlock(world, i + 5, j + 5, k + 6, Blocks.log, 13);
		this.setBlock(world, i + 5, j + 5, k + 7, Blocks.log, 13);
		this.setBlock(world, i + 5, j + 5, k + 8, Blocks.log, 13);
		this.setBlock(world, i + 5, j + 5, k + 9, Blocks.log, 13);
		this.setBlock(world, i + 5, j + 5, k + 10, Blocks.log, 13);
		this.setBlock(world, i + 5, j + 5, k + 11, Blocks.log, 13);
		this.setBlock(world, i + 5, j + 6, k + 3, Blocks.log, 13);
		this.setBlock(world, i + 5, j + 6, k + 4, Blocks.planks, 1);
		this.setBlock(world, i + 5, j + 6, k + 5, Blocks.planks, 1);
		this.setBlock(world, i + 5, j + 6, k + 6, Blocks.planks, 1);
		this.setBlock(world, i + 5, j + 6, k + 7, Blocks.planks, 1);
		this.setBlock(world, i + 5, j + 6, k + 8, Blocks.planks, 1);
		this.setBlock(world, i + 5, j + 6, k + 9, Blocks.planks, 1);
		this.setBlock(world, i + 5, j + 6, k + 10, Blocks.planks, 1);
		this.setBlock(world, i + 5, j + 6, k + 11, Blocks.log, 13);
		this.setBlock(world, i + 5, j + 7, k + 3, Blocks.log, 13);
		this.setBlock(world, i + 5, j + 7, k + 4, Blocks.chest, 3);
		this.setBlock(world, i + 5, j + 7, k + 10, Blocks.chest, 2);
		this.setBlock(world, i + 5, j + 7, k + 11, Blocks.log, 13);
		this.setBlock(world, i + 5, j + 8, k + 3, Blocks.glass, 0);
		this.setBlock(world, i + 5, j + 8, k + 11, Blocks.glass, 0);
		this.setBlock(world, i + 5, j + 9, k + 3, Blocks.glass, 0);
		this.setBlock(world, i + 5, j + 9, k + 11, Blocks.glass, 0);
		this.setBlock(world, i + 5, j + 10, k + 3, Blocks.log, 13);
		this.setBlock(world, i + 5, j + 10, k + 4, Blocks.planks, 1);
		this.setBlock(world, i + 5, j + 10, k + 5, Blocks.planks, 1);
		this.setBlock(world, i + 5, j + 10, k + 6, Blocks.planks, 1);
		this.setBlock(world, i + 5, j + 10, k + 7, Blocks.planks, 1);
		this.setBlock(world, i + 5, j + 10, k + 8, Blocks.planks, 1);
		this.setBlock(world, i + 5, j + 10, k + 9, Blocks.planks, 1);
		this.setBlock(world, i + 5, j + 10, k + 10, Blocks.planks, 1);
		this.setBlock(world, i + 5, j + 10, k + 11, Blocks.log, 13);
		this.setBlock(world, i + 5, j + 11, k + 3, Blocks.fence, 0);
		this.setBlock(world, i + 5, j + 11, k + 11, Blocks.fence, 0);
		this.setBlock(world, i + 6, j + 0, k + 6, Blocks.log, 13);
		this.setBlock(world, i + 6, j + 0, k + 7, Blocks.log, 13);
		this.setBlock(world, i + 6, j + 0, k + 8, Blocks.log, 13);
		this.setBlock(world, i + 6, j + 1, k + 5, Blocks.log, 13);
		this.setBlock(world, i + 6, j + 1, k + 6, Blocks.log, 13);
		this.setBlock(world, i + 6, j + 1, k + 7, Blocks.log, 13);
		this.setBlock(world, i + 6, j + 1, k + 8, Blocks.log, 13);
		this.setBlock(world, i + 6, j + 1, k + 9, Blocks.log, 13);
		this.setBlock(world, i + 6, j + 2, k + 4, Blocks.log, 13);
		this.setBlock(world, i + 6, j + 2, k + 5, Blocks.log, 13);
		this.setBlock(world, i + 6, j + 2, k + 6, Blocks.log, 13);
		this.setBlock(world, i + 6, j + 2, k + 7, Blocks.log, 13);
		this.setBlock(world, i + 6, j + 2, k + 8, Blocks.log, 13);
		this.setBlock(world, i + 6, j + 2, k + 9, Blocks.log, 13);
		this.setBlock(world, i + 6, j + 2, k + 10, Blocks.log, 13);
		this.setBlock(world, i + 6, j + 3, k + 4, Blocks.log, 13);
		this.setBlock(world, i + 6, j + 3, k + 5, Blocks.log, 13);
		this.setBlock(world, i + 6, j + 3, k + 6, Blocks.log, 13);
		this.setBlock(world, i + 6, j + 3, k + 7, Blocks.log, 13);
		this.setBlock(world, i + 6, j + 3, k + 8, Blocks.log, 13);
		this.setBlock(world, i + 6, j + 3, k + 9, Blocks.log, 13);
		this.setBlock(world, i + 6, j + 3, k + 10, Blocks.log, 13);
		this.setBlock(world, i + 6, j + 4, k + 4, Blocks.log, 13);
		this.setBlock(world, i + 6, j + 4, k + 5, Blocks.log, 13);
		this.setBlock(world, i + 6, j + 4, k + 6, Blocks.log, 13);
		this.setBlock(world, i + 6, j + 4, k + 7, Blocks.log, 13);
		this.setBlock(world, i + 6, j + 4, k + 8, Blocks.log, 13);
		this.setBlock(world, i + 6, j + 4, k + 9, Blocks.log, 13);
		this.setBlock(world, i + 6, j + 4, k + 10, Blocks.log, 13);
		this.setBlock(world, i + 6, j + 5, k + 3, Blocks.log, 13);
		this.setBlock(world, i + 6, j + 5, k + 4, Blocks.log, 13);
		this.setBlock(world, i + 6, j + 5, k + 5, Blocks.planks, 1);
		this.setBlock(world, i + 6, j + 5, k + 6, Blocks.log, 13);
		this.setBlock(world, i + 6, j + 5, k + 7, Blocks.log, 13);
		this.setBlock(world, i + 6, j + 5, k + 8, Blocks.log, 13);
		this.setBlock(world, i + 6, j + 5, k + 9, Blocks.log, 13);
		this.setBlock(world, i + 6, j + 5, k + 10, Blocks.log, 13);
		this.setBlock(world, i + 6, j + 5, k + 11, Blocks.log, 13);
		this.setBlock(world, i + 6, j + 6, k + 3, Blocks.log, 13);
		this.setBlock(world, i + 6, j + 6, k + 4, Blocks.planks, 1);
		this.setBlock(world, i + 6, j + 6, k + 5, Blocks.planks, 1);
		this.setBlock(world, i + 6, j + 6, k + 6, Blocks.planks, 1);
		this.setBlock(world, i + 6, j + 6, k + 7, Blocks.planks, 1);
		this.setBlock(world, i + 6, j + 6, k + 8, Blocks.planks, 1);
		this.setBlock(world, i + 6, j + 6, k + 9, Blocks.planks, 1);
		this.setBlock(world, i + 6, j + 6, k + 10, Blocks.planks, 1);
		this.setBlock(world, i + 6, j + 6, k + 11, Blocks.log, 13);
		this.setBlock(world, i + 6, j + 7, k + 3, Blocks.log, 13);
		this.setBlock(world, i + 6, j + 7, k + 4, Blocks.log, 13);
		this.setBlock(world, i + 6, j + 7, k + 10, Blocks.log, 13);
		this.setBlock(world, i + 6, j + 7, k + 11, Blocks.log, 13);
		this.setBlock(world, i + 6, j + 8, k + 3, Blocks.log, 13);
		this.setBlock(world, i + 6, j + 8, k + 4, Blocks.log, 13);
		this.setBlock(world, i + 6, j + 8, k + 10, Blocks.log, 13);
		this.setBlock(world, i + 6, j + 8, k + 11, Blocks.log, 13);
		this.setBlock(world, i + 6, j + 9, k + 3, Blocks.log, 13);
		this.setBlock(world, i + 6, j + 9, k + 4, Blocks.log, 13);
		this.setBlock(world, i + 6, j + 9, k + 10, Blocks.log, 13);
		this.setBlock(world, i + 6, j + 9, k + 11, Blocks.log, 13);
		this.setBlock(world, i + 6, j + 10, k + 3, Blocks.log, 13);
		this.setBlock(world, i + 6, j + 10, k + 4, Blocks.air, 1);
		this.setBlock(world, i + 6, j + 10, k + 5, Blocks.planks, 1);
		this.setBlock(world, i + 6, j + 10, k + 6, Blocks.planks, 1);
		this.setBlock(world, i + 6, j + 10, k + 7, Blocks.planks, 1);
		this.setBlock(world, i + 6, j + 10, k + 8, Blocks.planks, 1);
		this.setBlock(world, i + 6, j + 10, k + 9, Blocks.planks, 1);
		this.setBlock(world, i + 6, j + 10, k + 10, Blocks.air, 1);
		this.setBlock(world, i + 6, j + 10, k + 11, Blocks.log, 13);
		this.setBlock(world, i + 6, j + 11, k + 3, Blocks.fence, 0);
		this.setBlock(world, i + 6, j + 11, k + 11, Blocks.fence, 0);
		this.setBlock(world, i + 6, j + 12, k + 7, Blocks.planks, 1);
		this.setBlock(world, i + 7, j + 0, k + 6, Blocks.log, 13);
		this.setBlock(world, i + 7, j + 0, k + 7, Blocks.log, 13);
		this.setBlock(world, i + 7, j + 0, k + 8, Blocks.log, 13);
		this.setBlock(world, i + 7, j + 1, k + 5, Blocks.log, 13);
		this.setBlock(world, i + 7, j + 1, k + 9, Blocks.log, 13);
		this.setBlock(world, i + 7, j + 2, k + 4, Blocks.log, 13);
		this.setBlock(world, i + 7, j + 2, k + 5, Blocks.furnace, 3);
		this.setBlock(world, i + 7, j + 2, k + 9, Blocks.furnace, 2);
		this.setBlock(world, i + 7, j + 2, k + 10, Blocks.log, 13);
		this.setBlock(world, i + 7, j + 3, k + 4, Blocks.log, 13);
		this.setBlock(world, i + 7, j + 3, k + 5, Blocks.log, 13);
		this.setBlock(world, i + 7, j + 3, k + 9, Blocks.log, 13);
		this.setBlock(world, i + 7, j + 3, k + 10, Blocks.log, 13);
		this.setBlock(world, i + 7, j + 4, k + 4, Blocks.glass, 0);
		this.setBlock(world, i + 7, j + 4, k + 10, Blocks.glass, 0);
		this.setBlock(world, i + 7, j + 5, k + 3, Blocks.log, 13);
		this.setBlock(world, i + 7, j + 5, k + 4, Blocks.log, 13);
		this.setBlock(world, i + 7, j + 5, k + 5, Blocks.planks, 1);
		this.setBlock(world, i + 7, j + 5, k + 6, Blocks.planks, 1);
		this.setBlock(world, i + 7, j + 5, k + 7, Blocks.planks, 1);
		this.setBlock(world, i + 7, j + 5, k + 8, Blocks.planks, 1);
		this.setBlock(world, i + 7, j + 5, k + 9, Blocks.planks, 1);
		this.setBlock(world, i + 7, j + 5, k + 10, Blocks.log, 13);
		this.setBlock(world, i + 7, j + 5, k + 11, Blocks.log, 13);
		this.setBlock(world, i + 7, j + 6, k + 3, Blocks.log, 13);
		this.setBlock(world, i + 7, j + 6, k + 4, Blocks.log, 13);
		this.setBlock(world, i + 7, j + 6, k + 5, Blocks.planks, 1);
		this.setBlock(world, i + 7, j + 6, k + 6, Blocks.planks, 1);
		this.setBlock(world, i + 7, j + 6, k + 7, Blocks.planks, 1);
		this.setBlock(world, i + 7, j + 6, k + 8, Blocks.planks, 1);
		this.setBlock(world, i + 7, j + 6, k + 9, Blocks.planks, 1);
		this.setBlock(world, i + 7, j + 6, k + 10, Blocks.log, 13);
		this.setBlock(world, i + 7, j + 6, k + 11, Blocks.log, 13);
		this.setBlock(world, i + 7, j + 7, k + 3, Blocks.log, 13);
		this.setBlock(world, i + 7, j + 7, k + 4, Blocks.log, 13);
		this.setBlock(world, i + 7, j + 7, k + 5, Blocks.log, 13);
		this.setBlock(world, i + 7, j + 7, k + 9, Blocks.log, 13);
		this.setBlock(world, i + 7, j + 7, k + 10, Blocks.log, 13);
		this.setBlock(world, i + 7, j + 7, k + 11, Blocks.log, 13);
		this.setBlock(world, i + 7, j + 8, k + 3, Blocks.log, 13);
		this.setBlock(world, i + 7, j + 8, k + 4, Blocks.log, 13);
		this.setBlock(world, i + 7, j + 8, k + 5, Blocks.log, 13);
		this.setBlock(world, i + 7, j + 8, k + 9, Blocks.log, 13);
		this.setBlock(world, i + 7, j + 8, k + 10, Blocks.log, 13);
		this.setBlock(world, i + 7, j + 8, k + 11, Blocks.log, 13);
		this.setBlock(world, i + 7, j + 9, k + 3, Blocks.log, 13);
		this.setBlock(world, i + 7, j + 9, k + 4, Blocks.air, 1);
		this.setBlock(world, i + 7, j + 9, k + 5, Blocks.log, 13);
		this.setBlock(world, i + 7, j + 9, k + 9, Blocks.log, 13);
		this.setBlock(world, i + 7, j + 9, k + 10, Blocks.air, 1);
		this.setBlock(world, i + 7, j + 9, k + 11, Blocks.log, 13);
		this.setBlock(world, i + 7, j + 10, k + 3, Blocks.fence, 0);
		this.setBlock(world, i + 7, j + 10, k + 5, Blocks.log, 13);
		this.setBlock(world, i + 7, j + 10, k + 6, Blocks.planks, 1);
		this.setBlock(world, i + 7, j + 10, k + 7, Blocks.planks, 1);
		this.setBlock(world, i + 7, j + 10, k + 8, Blocks.planks, 1);
		this.setBlock(world, i + 7, j + 10, k + 9, Blocks.log, 13);
		this.setBlock(world, i + 7, j + 10, k + 11, Blocks.fence, 0);
		this.setBlock(world, i + 7, j + 11, k + 3, Blocks.fence, 0);
		this.setBlock(world, i + 7, j + 11, k + 5, Blocks.fence, 0);
		this.setBlock(world, i + 7, j + 11, k + 7, Blocks.fence, 0);
		this.setBlock(world, i + 7, j + 11, k + 9, Blocks.fence, 0);
		this.setBlock(world, i + 7, j + 11, k + 11, Blocks.fence, 0);
		this.setBlock(world, i + 7, j + 12, k + 7, Blocks.fence, 0);
		this.setBlock(world, i + 8, j + 0, k + 5, Blocks.log, 13);
		this.setBlock(world, i + 8, j + 0, k + 6, Blocks.log, 13);
		this.setBlock(world, i + 8, j + 0, k + 7, Blocks.log, 13);
		this.setBlock(world, i + 8, j + 0, k + 8, Blocks.log, 13);
		this.setBlock(world, i + 8, j + 0, k + 9, Blocks.log, 13);
		this.setBlock(world, i + 8, j + 1, k + 5, Blocks.log, 13);
		this.setBlock(world, i + 8, j + 1, k + 9, Blocks.log, 13);
		this.setBlock(world, i + 8, j + 2, k + 4, Blocks.log, 13);
		this.setBlock(world, i + 8, j + 2, k + 5, Blocks.log, 1);
		this.setBlock(world, i + 8, j + 2, k + 9, Blocks.log, 1);
		this.setBlock(world, i + 8, j + 2, k + 10, Blocks.log, 13);
		this.setBlock(world, i + 8, j + 3, k + 4, Blocks.log, 13);
		this.setBlock(world, i + 8, j + 3, k + 5, Blocks.log, 1);
		this.setBlock(world, i + 8, j + 3, k + 9, Blocks.log, 1);
		this.setBlock(world, i + 8, j + 3, k + 10, Blocks.log, 13);
		this.setBlock(world, i + 8, j + 4, k + 4, Blocks.log, 13);
		this.setBlock(world, i + 8, j + 4, k + 5, Blocks.log, 13);
		this.setBlock(world, i + 8, j + 4, k + 9, Blocks.log, 13);
		this.setBlock(world, i + 8, j + 4, k + 10, Blocks.log, 13);
		this.setBlock(world, i + 8, j + 5, k + 3, Blocks.log, 13);
		this.setBlock(world, i + 8, j + 5, k + 4, Blocks.log, 13);
		this.setBlock(world, i + 8, j + 5, k + 5, Blocks.planks, 1);
		this.setBlock(world, i + 8, j + 5, k + 6, Blocks.planks, 1);
		this.setBlock(world, i + 8, j + 5, k + 7, Blocks.planks, 1);
		this.setBlock(world, i + 8, j + 5, k + 8, Blocks.planks, 1);
		this.setBlock(world, i + 8, j + 5, k + 9, Blocks.planks, 1);
		this.setBlock(world, i + 8, j + 5, k + 10, Blocks.log, 13);
		this.setBlock(world, i + 8, j + 5, k + 11, Blocks.log, 13);
		this.setBlock(world, i + 8, j + 6, k + 3, Blocks.log, 13);
		this.setBlock(world, i + 8, j + 6, k + 4, Blocks.log, 13);
		this.setBlock(world, i + 8, j + 6, k + 5, Blocks.planks, 1);
		this.setBlock(world, i + 8, j + 6, k + 6, Blocks.planks, 1);
		this.setBlock(world, i + 8, j + 6, k + 7, Blocks.planks, 1);
		this.setBlock(world, i + 8, j + 6, k + 8, Blocks.planks, 1);
		this.setBlock(world, i + 8, j + 6, k + 9, Blocks.planks, 1);
		this.setBlock(world, i + 8, j + 6, k + 10, Blocks.log, 13);
		this.setBlock(world, i + 8, j + 6, k + 11, Blocks.log, 13);
		this.setBlock(world, i + 8, j + 7, k + 3, Blocks.log, 13);
		this.setBlock(world, i + 8, j + 7, k + 4, Blocks.log, 13);
		this.setBlock(world, i + 8, j + 7, k + 5, Blocks.log, 13);
		this.setBlock(world, i + 8, j + 7, k + 6, Blocks.log, 13);
		this.setBlock(world, i + 8, j + 7, k + 8, Blocks.log, 13);
		this.setBlock(world, i + 8, j + 7, k + 9, Blocks.log, 13);
		this.setBlock(world, i + 8, j + 7, k + 10, Blocks.log, 13);
		this.setBlock(world, i + 8, j + 7, k + 11, Blocks.log, 13);
		this.setBlock(world, i + 8, j + 8, k + 3, Blocks.log, 13);
		this.setBlock(world, i + 8, j + 8, k + 4, Blocks.air, 1);
		this.setBlock(world, i + 8, j + 8, k + 5, Blocks.log, 13);
		this.setBlock(world, i + 8, j + 8, k + 6, Blocks.glass, 0);
		this.setBlock(world, i + 8, j + 8, k + 8, Blocks.glass, 0);
		this.setBlock(world, i + 8, j + 8, k + 9, Blocks.log, 13);
		this.setBlock(world, i + 8, j + 8, k + 10, Blocks.air, 1);
		this.setBlock(world, i + 8, j + 8, k + 11, Blocks.log, 13);
		this.setBlock(world, i + 8, j + 9, k + 3, Blocks.fence, 0);
		this.setBlock(world, i + 8, j + 9, k + 5, Blocks.log, 13);
		this.setBlock(world, i + 8, j + 9, k + 6, Blocks.log, 13);
		this.setBlock(world, i + 8, j + 9, k + 7, Blocks.log, 13);
		this.setBlock(world, i + 8, j + 9, k + 8, Blocks.log, 13);
		this.setBlock(world, i + 8, j + 9, k + 9, Blocks.log, 13);
		this.setBlock(world, i + 8, j + 9, k + 11, Blocks.fence, 0);
		this.setBlock(world, i + 8, j + 10, k + 3, Blocks.fence, 0);
		this.setBlock(world, i + 8, j + 10, k + 5, Blocks.log, 13);
		this.setBlock(world, i + 8, j + 10, k + 6, Blocks.log, 13);
		this.setBlock(world, i + 8, j + 10, k + 7, Blocks.log, 13);
		this.setBlock(world, i + 8, j + 10, k + 8, Blocks.log, 13);
		this.setBlock(world, i + 8, j + 10, k + 9, Blocks.log, 13);
		this.setBlock(world, i + 8, j + 10, k + 11, Blocks.fence, 0);
		this.setBlock(world, i + 8, j + 11, k + 5, Blocks.fence, 0);
		this.setBlock(world, i + 8, j + 11, k + 6, Blocks.fence, 0);
		this.setBlock(world, i + 8, j + 11, k + 7, Blocks.fence, 0);
		this.setBlock(world, i + 8, j + 11, k + 8, Blocks.fence, 0);
		this.setBlock(world, i + 8, j + 11, k + 9, Blocks.fence, 0);
		this.setBlock(world, i + 9, j + 0, k + 5, Blocks.log, 13);
		this.setBlock(world, i + 9, j + 0, k + 6, Blocks.log, 13);
		this.setBlock(world, i + 9, j + 0, k + 7, Blocks.log, 13);
		this.setBlock(world, i + 9, j + 0, k + 8, Blocks.log, 13);
		this.setBlock(world, i + 9, j + 0, k + 9, Blocks.log, 13);
		this.setBlock(world, i + 9, j + 1, k + 5, Blocks.log, 13);
		this.setBlock(world, i + 9, j + 1, k + 9, Blocks.log, 13);
		this.setBlock(world, i + 9, j + 2, k + 4, Blocks.log, 13);
		this.setBlock(world, i + 9, j + 2, k + 5, Blocks.furnace, 3);
		this.setBlock(world, i + 9, j + 2, k + 9, Blocks.furnace, 2);
		this.setBlock(world, i + 9, j + 2, k + 10, Blocks.log, 13);
		this.setBlock(world, i + 9, j + 3, k + 4, Blocks.log, 13);
		this.setBlock(world, i + 9, j + 3, k + 5, Blocks.log, 13);
		this.setBlock(world, i + 9, j + 3, k + 9, Blocks.log, 13);
		this.setBlock(world, i + 9, j + 3, k + 10, Blocks.log, 13);
		this.setBlock(world, i + 9, j + 4, k + 4, Blocks.glass, 0);
		this.setBlock(world, i + 9, j + 4, k + 10, Blocks.glass, 0);
		this.setBlock(world, i + 9, j + 5, k + 3, Blocks.log, 13);
		this.setBlock(world, i + 9, j + 5, k + 4, Blocks.log, 13);
		this.setBlock(world, i + 9, j + 5, k + 5, Blocks.planks, 1);
		this.setBlock(world, i + 9, j + 5, k + 6, Blocks.planks, 1);
		this.setBlock(world, i + 9, j + 5, k + 7, Blocks.planks, 1);
		this.setBlock(world, i + 9, j + 5, k + 8, Blocks.planks, 1);
		this.setBlock(world, i + 9, j + 5, k + 9, Blocks.planks, 1);
		this.setBlock(world, i + 9, j + 5, k + 10, Blocks.log, 13);
		this.setBlock(world, i + 9, j + 5, k + 11, Blocks.log, 13);
		this.setBlock(world, i + 9, j + 6, k + 3, Blocks.log, 13);
		this.setBlock(world, i + 9, j + 6, k + 4, Blocks.log, 13);
		this.setBlock(world, i + 9, j + 6, k + 5, Blocks.planks, 1);
		this.setBlock(world, i + 9, j + 6, k + 6, Blocks.planks, 1);
		this.setBlock(world, i + 9, j + 6, k + 7, Blocks.planks, 1);
		this.setBlock(world, i + 9, j + 6, k + 8, Blocks.planks, 1);
		this.setBlock(world, i + 9, j + 6, k + 9, Blocks.planks, 1);
		this.setBlock(world, i + 9, j + 6, k + 10, Blocks.log, 13);
		this.setBlock(world, i + 9, j + 6, k + 11, Blocks.log, 13);
		this.setBlock(world, i + 9, j + 7, k + 3, Blocks.log, 13);
		this.setBlock(world, i + 9, j + 7, k + 4, Blocks.air, 1);
		this.setBlock(world, i + 9, j + 7, k + 5, Blocks.fence, 0);
		this.setBlock(world, i + 9, j + 7, k + 9, Blocks.fence, 0);
		this.setBlock(world, i + 9, j + 7, k + 10, Blocks.air, 1);
		this.setBlock(world, i + 9, j + 7, k + 11, Blocks.log, 13);
		this.setBlock(world, i + 9, j + 8, k + 3, Blocks.fence, 0);
		this.setBlock(world, i + 9, j + 8, k + 5, Blocks.fence, 0);
		this.setBlock(world, i + 9, j + 8, k + 9, Blocks.fence, 0);
		this.setBlock(world, i + 9, j + 8, k + 11, Blocks.fence, 0);
		this.setBlock(world, i + 9, j + 9, k + 3, Blocks.fence, 0);
		this.setBlock(world, i + 9, j + 9, k + 5, Blocks.fence, 0);
		this.setBlock(world, i + 9, j + 9, k + 9, Blocks.fence, 0);
		this.setBlock(world, i + 9, j + 9, k + 11, Blocks.fence, 0);
		this.setBlock(world, i + 9, j + 10, k + 5, Blocks.wooden_slab, 1);
		this.setBlock(world, i + 9, j + 10, k + 6, Blocks.wooden_slab, 1);
		this.setBlock(world, i + 9, j + 10, k + 7, Blocks.wooden_slab, 1);
		this.setBlock(world, i + 9, j + 10, k + 8, Blocks.wooden_slab, 1);
		this.setBlock(world, i + 9, j + 10, k + 9, Blocks.wooden_slab, 1);
		this.setBlock(world, i + 10, j + 0, k + 5, Blocks.log, 13);
		this.setBlock(world, i + 10, j + 0, k + 6, Blocks.log, 9);
		this.setBlock(world, i + 10, j + 0, k + 7, Blocks.log, 9);
		this.setBlock(world, i + 10, j + 0, k + 8, Blocks.log, 9);
		this.setBlock(world, i + 10, j + 0, k + 9, Blocks.log, 13);
		this.setBlock(world, i + 10, j + 1, k + 4, Blocks.log, 13);
		this.setBlock(world, i + 10, j + 1, k + 5, Blocks.log, 13);
		this.setBlock(world, i + 10, j + 1, k + 7, Blocks.wool, 8);
		this.setBlock(world, i + 10, j + 1, k + 9, Blocks.log, 13);
		this.setBlock(world, i + 10, j + 1, k + 10, Blocks.log, 13);
		this.setBlock(world, i + 10, j + 2, k + 4, Blocks.log, 13);
		this.setBlock(world, i + 10, j + 2, k + 5, Blocks.log, 1);
		this.setBlock(world, i + 10, j + 2, k + 9, Blocks.log, 1);
		this.setBlock(world, i + 10, j + 2, k + 10, Blocks.log, 13);
		this.setBlock(world, i + 10, j + 3, k + 4, Blocks.log, 13);
		this.setBlock(world, i + 10, j + 3, k + 5, Blocks.log, 1);
		this.setBlock(world, i + 10, j + 3, k + 9, Blocks.log, 1);
		this.setBlock(world, i + 10, j + 3, k + 10, Blocks.log, 13);
		this.setBlock(world, i + 10, j + 4, k + 4, Blocks.log, 13);
		this.setBlock(world, i + 10, j + 4, k + 5, Blocks.log, 13);
		this.setBlock(world, i + 10, j + 4, k + 9, Blocks.log, 13);
		this.setBlock(world, i + 10, j + 4, k + 10, Blocks.log, 13);
		this.setBlock(world, i + 10, j + 5, k + 3, Blocks.log, 13);
		this.setBlock(world, i + 10, j + 5, k + 4, Blocks.log, 13);
		this.setBlock(world, i + 10, j + 5, k + 5, Blocks.planks, 1);
		this.setBlock(world, i + 10, j + 5, k + 6, Blocks.planks, 1);
		this.setBlock(world, i + 10, j + 5, k + 7, Blocks.planks, 1);
		this.setBlock(world, i + 10, j + 5, k + 8, Blocks.planks, 1);
		this.setBlock(world, i + 10, j + 5, k + 9, Blocks.planks, 1);
		this.setBlock(world, i + 10, j + 5, k + 10, Blocks.log, 13);
		this.setBlock(world, i + 10, j + 5, k + 11, Blocks.log, 13);
		this.setBlock(world, i + 10, j + 6, k + 3, Blocks.log, 13);
		this.setBlock(world, i + 10, j + 6, k + 4, Blocks.planks, 1);
		this.setBlock(world, i + 10, j + 6, k + 5, Blocks.planks, 1);
		this.setBlock(world, i + 10, j + 6, k + 6, Blocks.planks, 1);
		this.setBlock(world, i + 10, j + 6, k + 7, Blocks.planks, 1);
		this.setBlock(world, i + 10, j + 6, k + 8, Blocks.planks, 1);
		this.setBlock(world, i + 10, j + 6, k + 9, Blocks.planks, 1);
		this.setBlock(world, i + 10, j + 6, k + 10, Blocks.planks, 1);
		this.setBlock(world, i + 10, j + 6, k + 11, Blocks.log, 13);
		this.setBlock(world, i + 10, j + 7, k + 3, Blocks.fence, 0);
		this.setBlock(world, i + 10, j + 7, k + 7, Blocks.spruce_stairs, 0);
		this.setBlock(world, i + 10, j + 7, k + 11, Blocks.fence, 0);
		this.setBlock(world, i + 10, j + 8, k + 3, Blocks.fence, 0);
		this.setBlock(world, i + 10, j + 8, k + 11, Blocks.fence, 0);
		this.setBlock(world, i + 11, j + 0, k + 5, Blocks.log, 13);
		this.setBlock(world, i + 11, j + 0, k + 6, Blocks.log, 9);
		this.setBlock(world, i + 11, j + 0, k + 7, Blocks.log, 9);
		this.setBlock(world, i + 11, j + 0, k + 8, Blocks.log, 9);
		this.setBlock(world, i + 11, j + 0, k + 9, Blocks.log, 13);
		this.setBlock(world, i + 11, j + 1, k + 4, Blocks.log, 13);
		this.setBlock(world, i + 11, j + 1, k + 5, Blocks.log, 13);
		this.setBlock(world, i + 11, j + 1, k + 9, Blocks.log, 13);
		this.setBlock(world, i + 11, j + 1, k + 10, Blocks.log, 13);
		this.setBlock(world, i + 11, j + 2, k + 4, Blocks.log, 13);
		this.setBlock(world, i + 11, j + 2, k + 5, Blocks.furnace, 3);
		this.setBlock(world, i + 11, j + 2, k + 9, Blocks.furnace, 2);
		this.setBlock(world, i + 11, j + 2, k + 10, Blocks.log, 13);
		this.setBlock(world, i + 11, j + 3, k + 4, Blocks.log, 13);
		this.setBlock(world, i + 11, j + 3, k + 5, Blocks.log, 13);
		this.setBlock(world, i + 11, j + 3, k + 9, Blocks.log, 13);
		this.setBlock(world, i + 11, j + 3, k + 10, Blocks.log, 13);
		this.setBlock(world, i + 11, j + 4, k + 4, Blocks.glass, 0);
		this.setBlock(world, i + 11, j + 4, k + 10, Blocks.glass, 0);
		this.setBlock(world, i + 11, j + 5, k + 3, Blocks.log, 13);
		this.setBlock(world, i + 11, j + 5, k + 4, Blocks.log, 13);
		this.setBlock(world, i + 11, j + 5, k + 5, Blocks.planks, 1);
		this.setBlock(world, i + 11, j + 5, k + 6, Blocks.planks, 1);
		this.setBlock(world, i + 11, j + 5, k + 7, Blocks.planks, 1);
		this.setBlock(world, i + 11, j + 5, k + 8, Blocks.planks, 1);
		this.setBlock(world, i + 11, j + 5, k + 9, Blocks.planks, 1);
		this.setBlock(world, i + 11, j + 5, k + 10, Blocks.log, 13);
		this.setBlock(world, i + 11, j + 5, k + 11, Blocks.log, 13);
		this.setBlock(world, i + 11, j + 6, k + 3, Blocks.log, 13);
		this.setBlock(world, i + 11, j + 6, k + 4, Blocks.planks, 1);
		this.setBlock(world, i + 11, j + 6, k + 5, Blocks.planks, 1);
		this.setBlock(world, i + 11, j + 6, k + 6, Blocks.planks, 1);
		this.setBlock(world, i + 11, j + 6, k + 7, Blocks.log, 0);
		this.setBlock(world, i + 11, j + 6, k + 8, Blocks.planks, 1);
		this.setBlock(world, i + 11, j + 6, k + 9, Blocks.planks, 1);
		this.setBlock(world, i + 11, j + 6, k + 10, Blocks.planks, 1);
		this.setBlock(world, i + 11, j + 6, k + 11, Blocks.log, 13);
		this.setBlock(world, i + 11, j + 7, k + 3, Blocks.fence, 0);
		this.setBlock(world, i + 11, j + 7, k + 5, Blocks.wool, 7);
		this.setBlock(world, i + 11, j + 7, k + 6, Blocks.air, 2);
		this.setBlock(world, i + 11, j + 7, k + 7, Blocks.log, 13);
		this.setBlock(world, i + 11, j + 7, k + 8, Blocks.air, 3);
		this.setBlock(world, i + 11, j + 7, k + 9, Blocks.wool, 6);
		this.setBlock(world, i + 11, j + 7, k + 11, Blocks.fence, 0);
		this.setBlock(world, i + 11, j + 8, k + 7, Blocks.log, 13);
		this.setBlock(world, i + 11, j + 9, k + 7, Blocks.log, 13);
		this.setBlock(world, i + 11, j + 10, k + 7, Blocks.log, 13);
		this.setBlock(world, i + 11, j + 11, k + 7, Blocks.log, 13);
		this.setBlock(world, i + 11, j + 12, k + 7, Blocks.log, 13);
		this.setBlock(world, i + 11, j + 13, k + 7, Blocks.log, 13);
		this.setBlock(world, i + 11, j + 14, k + 3, Blocks.log, 13);
		this.setBlock(world, i + 11, j + 14, k + 4, Blocks.log, 13);
		this.setBlock(world, i + 11, j + 14, k + 5, Blocks.log, 13);
		this.setBlock(world, i + 11, j + 14, k + 6, Blocks.log, 13);
		this.setBlock(world, i + 11, j + 14, k + 7, Blocks.log, 13);
		this.setBlock(world, i + 11, j + 14, k + 8, Blocks.log, 13);
		this.setBlock(world, i + 11, j + 14, k + 9, Blocks.log, 13);
		this.setBlock(world, i + 11, j + 14, k + 10, Blocks.log, 13);
		this.setBlock(world, i + 11, j + 14, k + 11, Blocks.log, 13);
		this.setBlock(world, i + 11, j + 15, k + 7, Blocks.log, 13);
		this.setBlock(world, i + 11, j + 16, k + 7, Blocks.log, 13);
		this.setBlock(world, i + 11, j + 17, k + 7, Blocks.log, 13);
		this.setBlock(world, i + 11, j + 18, k + 7, Blocks.log, 13);
		this.setBlock(world, i + 11, j + 19, k + 7, Blocks.log, 13);
		this.setBlock(world, i + 11, j + 20, k + 7, Blocks.log, 13);
		this.setBlock(world, i + 11, j + 21, k + 3, Blocks.log, 13);
		this.setBlock(world, i + 11, j + 21, k + 4, Blocks.log, 13);
		this.setBlock(world, i + 11, j + 21, k + 5, Blocks.log, 13);
		this.setBlock(world, i + 11, j + 21, k + 6, Blocks.log, 13);
		this.setBlock(world, i + 11, j + 21, k + 7, Blocks.log, 13);
		this.setBlock(world, i + 11, j + 21, k + 8, Blocks.log, 13);
		this.setBlock(world, i + 11, j + 21, k + 9, Blocks.log, 13);
		this.setBlock(world, i + 11, j + 21, k + 10, Blocks.log, 13);
		this.setBlock(world, i + 11, j + 21, k + 11, Blocks.log, 13);
		this.setBlock(world, i + 11, j + 22, k + 7, Blocks.log, 13);
		this.setBlock(world, i + 11, j + 23, k + 7, Blocks.log, 13);
		this.setBlock(world, i + 11, j + 24, k + 7, Blocks.log, 13);
		this.setBlock(world, i + 12, j + 0, k + 5, Blocks.log, 13);
		this.setBlock(world, i + 12, j + 0, k + 6, Blocks.log, 13);
		this.setBlock(world, i + 12, j + 0, k + 7, Blocks.log, 13);
		this.setBlock(world, i + 12, j + 0, k + 8, Blocks.log, 13);
		this.setBlock(world, i + 12, j + 0, k + 9, Blocks.log, 13);
		this.setBlock(world, i + 12, j + 1, k + 4, Blocks.log, 13);
		this.setBlock(world, i + 12, j + 1, k + 5, Blocks.log, 13);
		this.setBlock(world, i + 12, j + 1, k + 9, Blocks.log, 13);
		this.setBlock(world, i + 12, j + 1, k + 10, Blocks.log, 13);
		this.setBlock(world, i + 12, j + 2, k + 4, Blocks.log, 13);
		this.setBlock(world, i + 12, j + 2, k + 5, Blocks.log, 13);
		this.setBlock(world, i + 12, j + 2, k + 9, Blocks.log, 13);
		this.setBlock(world, i + 12, j + 2, k + 10, Blocks.log, 13);
		this.setBlock(world, i + 12, j + 3, k + 4, Blocks.log, 13);
		this.setBlock(world, i + 12, j + 3, k + 5, Blocks.log, 13);
		this.setBlock(world, i + 12, j + 3, k + 9, Blocks.log, 13);
		this.setBlock(world, i + 12, j + 3, k + 10, Blocks.log, 13);
		this.setBlock(world, i + 12, j + 4, k + 4, Blocks.log, 13);
		this.setBlock(world, i + 12, j + 4, k + 5, Blocks.log, 13);
		this.setBlock(world, i + 12, j + 4, k + 9, Blocks.log, 13);
		this.setBlock(world, i + 12, j + 4, k + 10, Blocks.log, 13);
		this.setBlock(world, i + 12, j + 5, k + 3, Blocks.log, 13);
		this.setBlock(world, i + 12, j + 5, k + 4, Blocks.log, 13);
		this.setBlock(world, i + 12, j + 5, k + 5, Blocks.planks, 1);
		this.setBlock(world, i + 12, j + 5, k + 6, Blocks.planks, 1);
		this.setBlock(world, i + 12, j + 5, k + 7, Blocks.planks, 1);
		this.setBlock(world, i + 12, j + 5, k + 8, Blocks.planks, 1);
		this.setBlock(world, i + 12, j + 5, k + 9, Blocks.planks, 1);
		this.setBlock(world, i + 12, j + 5, k + 10, Blocks.log, 13);
		this.setBlock(world, i + 12, j + 5, k + 11, Blocks.log, 13);
		this.setBlock(world, i + 12, j + 6, k + 3, Blocks.log, 13);
		this.setBlock(world, i + 12, j + 6, k + 4, Blocks.air, 1);
		this.setBlock(world, i + 12, j + 6, k + 5, Blocks.planks, 1);
		this.setBlock(world, i + 12, j + 6, k + 6, Blocks.planks, 1);
		this.setBlock(world, i + 12, j + 6, k + 7, Blocks.planks, 1);
		this.setBlock(world, i + 12, j + 6, k + 8, Blocks.planks, 1);
		this.setBlock(world, i + 12, j + 6, k + 9, Blocks.planks, 1);
		this.setBlock(world, i + 12, j + 6, k + 10, Blocks.air, 3);
		this.setBlock(world, i + 12, j + 6, k + 11, Blocks.log, 13);
		this.setBlock(world, i + 12, j + 7, k + 3, Blocks.fence, 0);
		this.setBlock(world, i + 12, j + 7, k + 7, Blocks.air, 1);
		this.setBlock(world, i + 12, j + 7, k + 11, Blocks.fence, 0);
		this.setBlock(world, i + 12, j + 14, k + 3, Blocks.wool, 14);
		this.setBlock(world, i + 12, j + 14, k + 4, Blocks.wool, 0);
		this.setBlock(world, i + 12, j + 14, k + 5, Blocks.wool, 0);
		this.setBlock(world, i + 12, j + 14, k + 6, Blocks.wool, 14);
		this.setBlock(world, i + 12, j + 14, k + 7, Blocks.wool, 14);
		this.setBlock(world, i + 12, j + 14, k + 8, Blocks.wool, 14);
		this.setBlock(world, i + 12, j + 14, k + 9, Blocks.wool, 0);
		this.setBlock(world, i + 12, j + 14, k + 10, Blocks.wool, 0);
		this.setBlock(world, i + 12, j + 14, k + 11, Blocks.wool, 14);
		this.setBlock(world, i + 12, j + 21, k + 3, Blocks.wool, 14);
		this.setBlock(world, i + 12, j + 21, k + 4, Blocks.wool, 0);
		this.setBlock(world, i + 12, j + 21, k + 5, Blocks.wool, 0);
		this.setBlock(world, i + 12, j + 21, k + 6, Blocks.wool, 14);
		this.setBlock(world, i + 12, j + 21, k + 7, Blocks.wool, 14);
		this.setBlock(world, i + 12, j + 21, k + 8, Blocks.wool, 14);
		this.setBlock(world, i + 12, j + 21, k + 9, Blocks.wool, 0);
		this.setBlock(world, i + 12, j + 21, k + 10, Blocks.wool, 0);
		this.setBlock(world, i + 12, j + 21, k + 11, Blocks.wool, 14);
		this.setBlock(world, i + 13, j + 0, k + 5, Blocks.log, 13);
		this.setBlock(world, i + 13, j + 0, k + 6, Blocks.log, 13);
		this.setBlock(world, i + 13, j + 0, k + 7, Blocks.log, 13);
		this.setBlock(world, i + 13, j + 0, k + 8, Blocks.log, 13);
		this.setBlock(world, i + 13, j + 0, k + 9, Blocks.log, 13);
		this.setBlock(world, i + 13, j + 1, k + 4, Blocks.log, 13);
		this.setBlock(world, i + 13, j + 1, k + 5, Blocks.log, 13);
		this.setBlock(world, i + 13, j + 1, k + 6, Blocks.log, 13);
		this.setBlock(world, i + 13, j + 1, k + 7, Blocks.spruce_stairs,  0);
		this.setBlock(world, i + 13, j + 1, k + 8, Blocks.log, 13);
		this.setBlock(world, i + 13, j + 1, k + 9, Blocks.log, 13);
		this.setBlock(world, i + 13, j + 1, k + 10, Blocks.log, 13);
		this.setBlock(world, i + 13, j + 2, k + 4, Blocks.log, 13);
		this.setBlock(world, i + 13, j + 2, k + 5, Blocks.log, 13);
		this.setBlock(world, i + 13, j + 2, k + 6, Blocks.log, 13);
		this.setBlock(world, i + 13, j + 2, k + 8, Blocks.log, 13);
		this.setBlock(world, i + 13, j + 2, k + 9, Blocks.log, 13);
		this.setBlock(world, i + 13, j + 2, k + 10, Blocks.log, 13);
		this.setBlock(world, i + 13, j + 3, k + 4, Blocks.log, 13);
		this.setBlock(world, i + 13, j + 3, k + 5, Blocks.log, 13);
		this.setBlock(world, i + 13, j + 3, k + 6, Blocks.log, 13);
		this.setBlock(world, i + 13, j + 3, k + 8, Blocks.log, 13);
		this.setBlock(world, i + 13, j + 3, k + 9, Blocks.log, 13);
		this.setBlock(world, i + 13, j + 3, k + 10, Blocks.log, 13);
		this.setBlock(world, i + 13, j + 4, k + 4, Blocks.log, 13);
		this.setBlock(world, i + 13, j + 4, k + 5, Blocks.log, 13);
		this.setBlock(world, i + 13, j + 4, k + 6, Blocks.log, 13);
		this.setBlock(world, i + 13, j + 4, k + 8, Blocks.log, 13);
		this.setBlock(world, i + 13, j + 4, k + 9, Blocks.log, 13);
		this.setBlock(world, i + 13, j + 4, k + 10, Blocks.log, 13);
		this.setBlock(world, i + 13, j + 5, k + 3, Blocks.log, 13);
		this.setBlock(world, i + 13, j + 5, k + 4, Blocks.air, 1);
		this.setBlock(world, i + 13, j + 5, k + 5, Blocks.log, 13);
		this.setBlock(world, i + 13, j + 5, k + 6, Blocks.log, 13);
		this.setBlock(world, i + 13, j + 5, k + 7, Blocks.log, 13);
		this.setBlock(world, i + 13, j + 5, k + 8, Blocks.log, 13);
		this.setBlock(world, i + 13, j + 5, k + 9, Blocks.log, 13);
		this.setBlock(world, i + 13, j + 5, k + 10, Blocks.air, 3);
		this.setBlock(world, i + 13, j + 5, k + 11, Blocks.log, 13);
		this.setBlock(world, i + 13, j + 6, k + 3, Blocks.log, 13);
		this.setBlock(world, i + 13, j + 6, k + 5, Blocks.log, 13);
		this.setBlock(world, i + 13, j + 6, k + 6, Blocks.log, 13);
		this.setBlock(world, i + 13, j + 6, k + 7, Blocks.log, 13);
		this.setBlock(world, i + 13, j + 6, k + 8, Blocks.log, 13);
		this.setBlock(world, i + 13, j + 6, k + 9, Blocks.log, 13);
		this.setBlock(world, i + 13, j + 6, k + 11, Blocks.log, 13);
		this.setBlock(world, i + 13, j + 7, k + 3, Blocks.fence, 0);
		this.setBlock(world, i + 13, j + 7, k + 5, Blocks.fence, 0);
		this.setBlock(world, i + 13, j + 7, k + 6, Blocks.fence, 0);
		this.setBlock(world, i + 13, j + 7, k + 7, Blocks.fence, 0);
		this.setBlock(world, i + 13, j + 7, k + 8, Blocks.fence, 0);
		this.setBlock(world, i + 13, j + 7, k + 9, Blocks.fence, 0);
		this.setBlock(world, i + 13, j + 7, k + 11, Blocks.fence, 0);
		this.setBlock(world, i + 13, j + 15, k + 3, Blocks.wool, 14);
		this.setBlock(world, i + 13, j + 15, k + 4, Blocks.wool, 0);
		this.setBlock(world, i + 13, j + 15, k + 5, Blocks.wool, 0);
		this.setBlock(world, i + 13, j + 15, k + 6, Blocks.wool, 14);
		this.setBlock(world, i + 13, j + 15, k + 7, Blocks.wool, 14);
		this.setBlock(world, i + 13, j + 15, k + 8, Blocks.wool, 14);
		this.setBlock(world, i + 13, j + 15, k + 9, Blocks.wool, 0);
		this.setBlock(world, i + 13, j + 15, k + 10, Blocks.wool, 0);
		this.setBlock(world, i + 13, j + 15, k + 11, Blocks.wool, 14);
		this.setBlock(world, i + 13, j + 16, k + 3, Blocks.wool, 14);
		this.setBlock(world, i + 13, j + 16, k + 4, Blocks.wool, 0);
		this.setBlock(world, i + 13, j + 16, k + 5, Blocks.wool, 0);
		this.setBlock(world, i + 13, j + 16, k + 6, Blocks.wool, 14);
		this.setBlock(world, i + 13, j + 16, k + 7, Blocks.wool, 14);
		this.setBlock(world, i + 13, j + 16, k + 8, Blocks.wool, 14);
		this.setBlock(world, i + 13, j + 16, k + 9, Blocks.wool, 0);
		this.setBlock(world, i + 13, j + 16, k + 10, Blocks.wool, 0);
		this.setBlock(world, i + 13, j + 16, k + 11, Blocks.wool, 14);
		this.setBlock(world, i + 13, j + 17, k + 3, Blocks.wool, 14);
		this.setBlock(world, i + 13, j + 17, k + 4, Blocks.wool, 0);
		this.setBlock(world, i + 13, j + 17, k + 5, Blocks.wool, 0);
		this.setBlock(world, i + 13, j + 17, k + 6, Blocks.wool, 14);
		this.setBlock(world, i + 13, j + 17, k + 7, Blocks.wool, 14);
		this.setBlock(world, i + 13, j + 17, k + 8, Blocks.wool, 14);
		this.setBlock(world, i + 13, j + 17, k + 9, Blocks.wool, 0);
		this.setBlock(world, i + 13, j + 17, k + 10, Blocks.wool, 0);
		this.setBlock(world, i + 13, j + 17, k + 11, Blocks.wool, 14);
		this.setBlock(world, i + 13, j + 18, k + 3, Blocks.wool, 14);
		this.setBlock(world, i + 13, j + 18, k + 4, Blocks.wool, 0);
		this.setBlock(world, i + 13, j + 18, k + 5, Blocks.wool, 0);
		this.setBlock(world, i + 13, j + 18, k + 6, Blocks.wool, 14);
		this.setBlock(world, i + 13, j + 18, k + 7, Blocks.wool, 14);
		this.setBlock(world, i + 13, j + 18, k + 8, Blocks.wool, 14);
		this.setBlock(world, i + 13, j + 18, k + 9, Blocks.wool, 0);
		this.setBlock(world, i + 13, j + 18, k + 10, Blocks.wool, 0);
		this.setBlock(world, i + 13, j + 18, k + 11, Blocks.wool, 14);
		this.setBlock(world, i + 13, j + 19, k + 3, Blocks.wool, 14);
		this.setBlock(world, i + 13, j + 19, k + 4, Blocks.wool, 0);
		this.setBlock(world, i + 13, j + 19, k + 5, Blocks.wool, 0);
		this.setBlock(world, i + 13, j + 19, k + 6, Blocks.wool, 14);
		this.setBlock(world, i + 13, j + 19, k + 7, Blocks.wool, 14);
		this.setBlock(world, i + 13, j + 19, k + 8, Blocks.wool, 14);
		this.setBlock(world, i + 13, j + 19, k + 9, Blocks.wool, 0);
		this.setBlock(world, i + 13, j + 19, k + 10, Blocks.wool, 0);
		this.setBlock(world, i + 13, j + 19, k + 11, Blocks.wool, 14);
		this.setBlock(world, i + 13, j + 20, k + 3, Blocks.wool, 14);
		this.setBlock(world, i + 13, j + 20, k + 4, Blocks.wool, 0);
		this.setBlock(world, i + 13, j + 20, k + 5, Blocks.wool, 0);
		this.setBlock(world, i + 13, j + 20, k + 6, Blocks.wool, 14);
		this.setBlock(world, i + 13, j + 20, k + 7, Blocks.wool, 14);
		this.setBlock(world, i + 13, j + 20, k + 8, Blocks.wool, 14);
		this.setBlock(world, i + 13, j + 20, k + 9, Blocks.wool, 0);
		this.setBlock(world, i + 13, j + 20, k + 10, Blocks.wool, 0);
		this.setBlock(world, i + 13, j + 20, k + 11, Blocks.wool, 14);
		this.setBlock(world, i + 14, j + 0, k + 5, Blocks.log, 13);
		this.setBlock(world, i + 14, j + 0, k + 6, Blocks.log, 13);
		this.setBlock(world, i + 14, j + 0, k + 7, Blocks.log, 13);
		this.setBlock(world, i + 14, j + 0, k + 8, Blocks.log, 13);
		this.setBlock(world, i + 14, j + 0, k + 9, Blocks.log, 13);
		this.setBlock(world, i + 14, j + 1, k + 4, Blocks.log, 13);
		this.setBlock(world, i + 14, j + 1, k + 5, Blocks.log, 13);
		this.setBlock(world, i + 14, j + 1, k + 6, Blocks.log, 13);
		this.setBlock(world, i + 14, j + 1, k + 7, Blocks.log, 13);
		this.setBlock(world, i + 14, j + 1, k + 8, Blocks.log, 13);
		this.setBlock(world, i + 14, j + 1, k + 9, Blocks.log, 13);
		this.setBlock(world, i + 14, j + 1, k + 10, Blocks.log, 13);
		this.setBlock(world, i + 14, j + 2, k + 4, Blocks.log, 13);
		this.setBlock(world, i + 14, j + 2, k + 5, Blocks.log, 13);
		this.setBlock(world, i + 14, j + 2, k + 6, Blocks.planks, 1);
		this.setBlock(world, i + 14, j + 2, k + 7, Blocks.spruce_stairs,  0);
		this.setBlock(world, i + 14, j + 2, k + 8, Blocks.planks, 1);
		this.setBlock(world, i + 14, j + 2, k + 9, Blocks.log, 13);
		this.setBlock(world, i + 14, j + 2, k + 10, Blocks.log, 13);
		this.setBlock(world, i + 14, j + 3, k + 4, Blocks.log, 13);
		this.setBlock(world, i + 14, j + 3, k + 5, Blocks.log, 13);
		this.setBlock(world, i + 14, j + 3, k + 6, Blocks.planks, 1);
		this.setBlock(world, i + 14, j + 3, k + 8, Blocks.planks, 1);
		this.setBlock(world, i + 14, j + 3, k + 9, Blocks.log, 13);
		this.setBlock(world, i + 14, j + 3, k + 10, Blocks.log, 13);
		this.setBlock(world, i + 14, j + 4, k + 3, Blocks.log, 13);
		this.setBlock(world, i + 14, j + 4, k + 4, Blocks.planks, 1);
		this.setBlock(world, i + 14, j + 4, k + 5, Blocks.planks, 1);
		this.setBlock(world, i + 14, j + 4, k + 6, Blocks.planks, 1);
		this.setBlock(world, i + 14, j + 4, k + 8, Blocks.planks, 1);
		this.setBlock(world, i + 14, j + 4, k + 9, Blocks.planks, 1);
		this.setBlock(world, i + 14, j + 4, k + 10, Blocks.planks, 1);
		this.setBlock(world, i + 14, j + 4, k + 11, Blocks.log, 13);
		this.setBlock(world, i + 14, j + 5, k + 3, Blocks.log, 13);
		this.setBlock(world, i + 14, j + 5, k + 11, Blocks.log, 13);
		this.setBlock(world, i + 14, j + 6, k + 3, Blocks.fence, 0);
		this.setBlock(world, i + 14, j + 6, k + 11, Blocks.fence, 0);
		this.setBlock(world, i + 14, j + 7, k + 3, Blocks.fence, 0);
		this.setBlock(world, i + 14, j + 7, k + 11, Blocks.fence, 0);
		this.setBlock(world, i + 15, j + 0, k + 5, Blocks.log, 13);
		this.setBlock(world, i + 15, j + 0, k + 6, Blocks.log, 13);
		this.setBlock(world, i + 15, j + 0, k + 7, Blocks.log, 13);
		this.setBlock(world, i + 15, j + 0, k + 8, Blocks.log, 13);
		this.setBlock(world, i + 15, j + 0, k + 9, Blocks.log, 13);
		this.setBlock(world, i + 15, j + 1, k + 4, Blocks.log, 9);
		this.setBlock(world, i + 15, j + 1, k + 6, Blocks.log, 13);
		this.setBlock(world, i + 15, j + 1, k + 7, Blocks.diamond_block, 0);
		this.setBlock(world, i + 15, j + 1, k + 8, Blocks.log, 13);
		this.setBlock(world, i + 15, j + 1, k + 10, Blocks.log, 9);
		this.setBlock(world, i + 15, j + 2, k + 4, Blocks.iron_bars, 0);
		this.setBlock(world, i + 15, j + 2, k + 6, Blocks.log, 13);
		this.setBlock(world, i + 15, j + 2, k + 8, Blocks.log, 13);
		this.setBlock(world, i + 15, j + 2, k + 10, Blocks.iron_bars, 0);
		this.setBlock(world, i + 15, j + 3, k + 4, Blocks.iron_bars, 0);
		this.setBlock(world, i + 15, j + 3, k + 6, Blocks.planks, 1);
		this.setBlock(world, i + 15, j + 3, k + 7, Blocks.spruce_stairs,  0);
		this.setBlock(world, i + 15, j + 3, k + 8, Blocks.planks, 1);
		this.setBlock(world, i + 15, j + 3, k + 10, Blocks.iron_bars, 0);
		this.setBlock(world, i + 15, j + 4, k + 3, Blocks.log, 13);
		this.setBlock(world, i + 15, j + 4, k + 4, Blocks.planks, 1);
		this.setBlock(world, i + 15, j + 4, k + 5, Blocks.planks, 1);
		this.setBlock(world, i + 15, j + 4, k + 6, Blocks.planks, 1);
		this.setBlock(world, i + 15, j + 4, k + 8, Blocks.planks, 1);
		this.setBlock(world, i + 15, j + 4, k + 9, Blocks.planks, 1);
		this.setBlock(world, i + 15, j + 4, k + 10, Blocks.planks, 1);
		this.setBlock(world, i + 15, j + 4, k + 11, Blocks.log, 13);
		this.setBlock(world, i + 15, j + 5, k + 3, Blocks.fence, 0);
		this.setBlock(world, i + 15, j + 5, k + 11, Blocks.fence, 0);
		this.setBlock(world, i + 15, j + 6, k + 3, Blocks.fence, 0);
		this.setBlock(world, i + 15, j + 6, k + 11, Blocks.fence, 0);
		this.setBlock(world, i + 16, j + 0, k + 5, Blocks.log, 9);
		this.setBlock(world, i + 16, j + 0, k + 6, Blocks.log, 13);
		this.setBlock(world, i + 16, j + 0, k + 7, Blocks.log, 13);
		this.setBlock(world, i + 16, j + 0, k + 8, Blocks.log, 13);
		this.setBlock(world, i + 16, j + 0, k + 9, Blocks.log, 9);
		this.setBlock(world, i + 16, j + 1, k + 4, Blocks.log, 13);
		this.setBlock(world, i + 16, j + 1, k + 10, Blocks.log, 13);
		this.setBlock(world, i + 16, j + 2, k + 4, Blocks.log, 13);
		this.setBlock(world, i + 16, j + 2, k + 10, Blocks.log, 13);
		this.setBlock(world, i + 16, j + 3, k + 4, Blocks.log, 13);
		this.setBlock(world, i + 16, j + 3, k + 7, Blocks.planks, 1);
		this.setBlock(world, i + 16, j + 3, k + 10, Blocks.log, 13);
		this.setBlock(world, i + 16, j + 4, k + 3, Blocks.log, 13);
		this.setBlock(world, i + 16, j + 4, k + 4, Blocks.planks, 1);
		this.setBlock(world, i + 16, j + 4, k + 5, Blocks.planks, 1);
		this.setBlock(world, i + 16, j + 4, k + 6, Blocks.planks, 1);
		this.setBlock(world, i + 16, j + 4, k + 7, Blocks.spruce_stairs,  0);
		this.setBlock(world, i + 16, j + 4, k + 8, Blocks.planks, 1);
		this.setBlock(world, i + 16, j + 4, k + 9, Blocks.planks, 1);
		this.setBlock(world, i + 16, j + 4, k + 10, Blocks.planks, 1);
		this.setBlock(world, i + 16, j + 4, k + 11, Blocks.log, 13);
		this.setBlock(world, i + 16, j + 5, k + 3, Blocks.fence, 0);
		this.setBlock(world, i + 16, j + 5, k + 11, Blocks.fence, 0);
		this.setBlock(world, i + 17, j + 0, k + 5, Blocks.log, 13);
		this.setBlock(world, i + 17, j + 0, k + 6, Blocks.log, 13);
		this.setBlock(world, i + 17, j + 0, k + 7, Blocks.log, 13);
		this.setBlock(world, i + 17, j + 0, k + 8, Blocks.log, 13);
		this.setBlock(world, i + 17, j + 0, k + 9, Blocks.log, 13);
		this.setBlock(world, i + 17, j + 1, k + 4, Blocks.log, 9);
		this.setBlock(world, i + 17, j + 1, k + 7, Blocks.wool, 13);
		this.setBlock(world, i + 17, j + 1, k + 10, Blocks.log, 9);
		this.setBlock(world, i + 17, j + 2, k + 4, Blocks.iron_bars, 0);
		this.setBlock(world, i + 17, j + 2, k + 10, Blocks.iron_bars, 0);
		this.setBlock(world, i + 17, j + 3, k + 4, Blocks.iron_bars, 0);
		this.setBlock(world, i + 17, j + 3, k + 10, Blocks.iron_bars, 0);
		this.setBlock(world, i + 17, j + 4, k + 3, Blocks.log, 13);
		this.setBlock(world, i + 17, j + 4, k + 4, Blocks.planks, 1);
		this.setBlock(world, i + 17, j + 4, k + 5, Blocks.planks, 1);
		this.setBlock(world, i + 17, j + 4, k + 6, Blocks.planks, 1);
		this.setBlock(world, i + 17, j + 4, k + 7, Blocks.planks, 1);
		this.setBlock(world, i + 17, j + 4, k + 8, Blocks.planks, 1);
		this.setBlock(world, i + 17, j + 4, k + 9, Blocks.planks, 1);
		this.setBlock(world, i + 17, j + 4, k + 10, Blocks.planks, 1);
		this.setBlock(world, i + 17, j + 4, k + 11, Blocks.log, 13);
		this.setBlock(world, i + 17, j + 5, k + 5, Blocks.bedrock, 0);
		this.setBlock(world, i + 17, j + 5, k + 9, Blocks.gold_block, 0);
		this.setBlock(world, i + 17, j + 28, k + 6, Blocks.planks, 1);
		this.setBlock(world, i + 17, j + 28, k + 7, Blocks.planks, 1);
		this.setBlock(world, i + 17, j + 28, k + 8, Blocks.planks, 1);
		this.setBlock(world, i + 17, j + 29, k + 6, Blocks.fence, 0);
		this.setBlock(world, i + 17, j + 29, k + 7, Blocks.fence, 0);
		this.setBlock(world, i + 17, j + 29, k + 8, Blocks.fence, 0);
		this.setBlock(world, i + 18, j + 0, k + 5, Blocks.log, 9);
		this.setBlock(world, i + 18, j + 0, k + 6, Blocks.log, 13);
		this.setBlock(world, i + 18, j + 0, k + 7, Blocks.log, 13);
		this.setBlock(world, i + 18, j + 0, k + 8, Blocks.log, 13);
		this.setBlock(world, i + 18, j + 0, k + 9, Blocks.log, 9);
		this.setBlock(world, i + 18, j + 1, k + 4, Blocks.log, 13);
		this.setBlock(world, i + 18, j + 1, k + 10, Blocks.log, 13);
		this.setBlock(world, i + 18, j + 2, k + 4, Blocks.log, 13);
		this.setBlock(world, i + 18, j + 2, k + 10, Blocks.log, 13);
		this.setBlock(world, i + 18, j + 3, k + 4, Blocks.log, 13);
		this.setBlock(world, i + 18, j + 3, k + 10, Blocks.log, 13);
		this.setBlock(world, i + 18, j + 4, k + 3, Blocks.log, 13);
		this.setBlock(world, i + 18, j + 4, k + 4, Blocks.planks, 1);
		this.setBlock(world, i + 18, j + 4, k + 5, Blocks.planks, 1);
		this.setBlock(world, i + 18, j + 4, k + 6, Blocks.planks, 1);
		this.setBlock(world, i + 18, j + 4, k + 7, Blocks.planks, 1);
		this.setBlock(world, i + 18, j + 4, k + 8, Blocks.planks, 1);
		this.setBlock(world, i + 18, j + 4, k + 9, Blocks.planks, 1);
		this.setBlock(world, i + 18, j + 4, k + 10, Blocks.planks, 1);
		this.setBlock(world, i + 18, j + 4, k + 11, Blocks.log, 13);
		this.setBlock(world, i + 18, j + 5, k + 3, Blocks.fence, 0);
		this.setBlock(world, i + 18, j + 5, k + 11, Blocks.fence, 0);
		this.setBlock(world, i + 18, j + 27, k + 6, Blocks.air, 4);
		this.setBlock(world, i + 18, j + 27, k + 8, Blocks.air, 4);
		this.setBlock(world, i + 18, j + 28, k + 5, Blocks.planks, 1);
		this.setBlock(world, i + 18, j + 28, k + 9, Blocks.planks, 1);
		this.setBlock(world, i + 18, j + 29, k + 5, Blocks.fence, 0);
		this.setBlock(world, i + 18, j + 29, k + 9, Blocks.fence, 0);
		this.setBlock(world, i + 19, j + 0, k + 5, Blocks.log, 13);
		this.setBlock(world, i + 19, j + 0, k + 6, Blocks.log, 13);
		this.setBlock(world, i + 19, j + 0, k + 7, Blocks.log, 13);
		this.setBlock(world, i + 19, j + 0, k + 8, Blocks.log, 13);
		this.setBlock(world, i + 19, j + 0, k + 9, Blocks.log, 13);
		this.setBlock(world, i + 19, j + 1, k + 4, Blocks.log, 9);
		this.setBlock(world, i + 19, j + 1, k + 7, Blocks.log, 13);
		this.setBlock(world, i + 19, j + 1, k + 10, Blocks.log, 9);
		this.setBlock(world, i + 19, j + 2, k + 4, Blocks.iron_bars, 0);
		this.setBlock(world, i + 19, j + 2, k + 7, Blocks.log, 13);
		this.setBlock(world, i + 19, j + 2, k + 10, Blocks.iron_bars, 0);
		this.setBlock(world, i + 19, j + 3, k + 4, Blocks.iron_bars, 0);
		this.setBlock(world, i + 19, j + 3, k + 7, Blocks.log, 13);
		this.setBlock(world, i + 19, j + 3, k + 10, Blocks.iron_bars, 0);
		this.setBlock(world, i + 19, j + 4, k + 3, Blocks.log, 13);
		this.setBlock(world, i + 19, j + 4, k + 4, Blocks.planks, 1);
		this.setBlock(world, i + 19, j + 4, k + 5, Blocks.planks, 1);
		this.setBlock(world, i + 19, j + 4, k + 6, Blocks.planks, 1);
		this.setBlock(world, i + 19, j + 4, k + 7, Blocks.log, 13);
		this.setBlock(world, i + 19, j + 4, k + 8, Blocks.planks, 1);
		this.setBlock(world, i + 19, j + 4, k + 9, Blocks.planks, 1);
		this.setBlock(world, i + 19, j + 4, k + 10, Blocks.planks, 1);
		this.setBlock(world, i + 19, j + 4, k + 11, Blocks.log, 13);
		this.setBlock(world, i + 19, j + 5, k + 3, Blocks.fence, 0);
		this.setBlock(world, i + 19, j + 5, k + 5, Blocks.wool, 4);
		this.setBlock(world, i + 19, j + 5, k + 6, Blocks.air, 2);
		this.setBlock(world, i + 19, j + 5, k + 7, Blocks.log, 13);
		this.setBlock(world, i + 19, j + 5, k + 8, Blocks.air, 3);
		this.setBlock(world, i + 19, j + 5, k + 9, Blocks.wool, 5);
		this.setBlock(world, i + 19, j + 5, k + 11, Blocks.fence, 0);
		this.setBlock(world, i + 19, j + 6, k + 7, Blocks.log, 13);
		this.setBlock(world, i + 19, j + 7, k + 7, Blocks.log, 13);
		this.setBlock(world, i + 19, j + 8, k + 7, Blocks.log, 13);
		this.setBlock(world, i + 19, j + 9, k + 7, Blocks.log, 13);
		this.setBlock(world, i + 19, j + 10, k + 7, Blocks.log, 13);
		this.setBlock(world, i + 19, j + 11, k + 0, Blocks.log, 13);
		this.setBlock(world, i + 19, j + 11, k + 1, Blocks.log, 13);
		this.setBlock(world, i + 19, j + 11, k + 2, Blocks.log, 13);
		this.setBlock(world, i + 19, j + 11, k + 3, Blocks.log, 13);
		this.setBlock(world, i + 19, j + 11, k + 4, Blocks.log, 13);
		this.setBlock(world, i + 19, j + 11, k + 5, Blocks.log, 13);
		this.setBlock(world, i + 19, j + 11, k + 6, Blocks.log, 13);
		this.setBlock(world, i + 19, j + 11, k + 7, Blocks.log, 13);
		this.setBlock(world, i + 19, j + 11, k + 8, Blocks.log, 13);
		this.setBlock(world, i + 19, j + 11, k + 9, Blocks.log, 13);
		this.setBlock(world, i + 19, j + 11, k + 10, Blocks.log, 13);
		this.setBlock(world, i + 19, j + 11, k + 11, Blocks.log, 13);
		this.setBlock(world, i + 19, j + 11, k + 12, Blocks.log, 13);
		this.setBlock(world, i + 19, j + 11, k + 13, Blocks.log, 13);
		this.setBlock(world, i + 19, j + 11, k + 14, Blocks.log, 13);
		this.setBlock(world, i + 19, j + 12, k + 7, Blocks.log, 13);
		this.setBlock(world, i + 19, j + 13, k + 7, Blocks.log, 13);
		this.setBlock(world, i + 19, j + 14, k + 7, Blocks.log, 13);
		this.setBlock(world, i + 19, j + 15, k + 7, Blocks.log, 13);
		this.setBlock(world, i + 19, j + 16, k + 7, Blocks.log, 13);
		this.setBlock(world, i + 19, j + 17, k + 7, Blocks.log, 13);
		this.setBlock(world, i + 19, j + 18, k + 7, Blocks.log, 13);
		this.setBlock(world, i + 19, j + 19, k + 7, Blocks.log, 13);
		this.setBlock(world, i + 19, j + 20, k + 7, Blocks.log, 13);
		this.setBlock(world, i + 19, j + 21, k + 7, Blocks.log, 13);
		this.setBlock(world, i + 19, j + 22, k + 7, Blocks.log, 13);
		this.setBlock(world, i + 19, j + 23, k + 7, Blocks.log, 13);
		this.setBlock(world, i + 19, j + 24, k + 7, Blocks.log, 13);
		this.setBlock(world, i + 19, j + 25, k + 0, Blocks.log, 13);
		this.setBlock(world, i + 19, j + 25, k + 1, Blocks.log, 13);
		this.setBlock(world, i + 19, j + 25, k + 2, Blocks.log, 13);
		this.setBlock(world, i + 19, j + 25, k + 3, Blocks.log, 13);
		this.setBlock(world, i + 19, j + 25, k + 4, Blocks.log, 13);
		this.setBlock(world, i + 19, j + 25, k + 5, Blocks.log, 9);
		this.setBlock(world, i + 19, j + 25, k + 6, Blocks.log, 13);
		this.setBlock(world, i + 19, j + 25, k + 7, Blocks.log, 13);
		this.setBlock(world, i + 19, j + 25, k + 8, Blocks.log, 13);
		this.setBlock(world, i + 19, j + 25, k + 9, Blocks.log, 13);
		this.setBlock(world, i + 19, j + 25, k + 10, Blocks.log, 9);
		this.setBlock(world, i + 19, j + 25, k + 11, Blocks.log, 13);
		this.setBlock(world, i + 19, j + 25, k + 12, Blocks.log, 13);
		this.setBlock(world, i + 19, j + 25, k + 13, Blocks.log, 13);
		this.setBlock(world, i + 19, j + 25, k + 14, Blocks.log, 13);
		this.setBlock(world, i + 19, j + 26, k + 7, Blocks.log, 13);
		this.setBlock(world, i + 19, j + 27, k + 6, Blocks.air, 6);
		this.setBlock(world, i + 19, j + 27, k + 7, Blocks.log, 13);
		this.setBlock(world, i + 19, j + 27, k + 8, Blocks.air, 7);
		this.setBlock(world, i + 19, j + 28, k + 5, Blocks.planks, 1);
		this.setBlock(world, i + 19, j + 28, k + 7, Blocks.log, 13);
		this.setBlock(world, i + 19, j + 28, k + 9, Blocks.planks, 1);
		this.setBlock(world, i + 19, j + 29, k + 5, Blocks.fence, 0);
		this.setBlock(world, i + 19, j + 29, k + 7, Blocks.log, 13);
		this.setBlock(world, i + 19, j + 29, k + 9, Blocks.fence, 0);
		this.setBlock(world, i + 19, j + 30, k + 7, Blocks.log, 13);
		this.setBlock(world, i + 19, j + 31, k + 7, Blocks.log, 13);
		this.setBlock(world, i + 19, j + 32, k + 7, Blocks.log, 13);
		this.setBlock(world, i + 20, j + 0, k + 5, Blocks.log, 9);
		this.setBlock(world, i + 20, j + 0, k + 6, Blocks.log, 13);
		this.setBlock(world, i + 20, j + 0, k + 7, Blocks.log, 13);
		this.setBlock(world, i + 20, j + 0, k + 8, Blocks.log, 13);
		this.setBlock(world, i + 20, j + 0, k + 9, Blocks.log, 9);
		this.setBlock(world, i + 20, j + 1, k + 4, Blocks.log, 13);
		this.setBlock(world, i + 20, j + 1, k + 5, Blocks.chest, 3);
		this.setBlock(world, i + 20, j + 1, k + 9, Blocks.chest, 2);
		this.setBlock(world, i + 20, j + 1, k + 10, Blocks.log, 13);
		this.setBlock(world, i + 20, j + 2, k + 4, Blocks.log, 13);
		this.setBlock(world, i + 20, j + 2, k + 10, Blocks.log, 13);
		this.setBlock(world, i + 20, j + 3, k + 4, Blocks.log, 13);
		this.setBlock(world, i + 20, j + 3, k + 10, Blocks.log, 13);
		this.setBlock(world, i + 20, j + 4, k + 3, Blocks.log, 13);
		this.setBlock(world, i + 20, j + 4, k + 4, Blocks.planks, 1);
		this.setBlock(world, i + 20, j + 4, k + 5, Blocks.planks, 1);
		this.setBlock(world, i + 20, j + 4, k + 6, Blocks.planks, 1);
		this.setBlock(world, i + 20, j + 4, k + 7, Blocks.planks, 1);
		this.setBlock(world, i + 20, j + 4, k + 8, Blocks.planks, 1);
		this.setBlock(world, i + 20, j + 4, k + 9, Blocks.planks, 1);
		this.setBlock(world, i + 20, j + 4, k + 10, Blocks.planks, 1);
		this.setBlock(world, i + 20, j + 4, k + 11, Blocks.log, 13);
		this.setBlock(world, i + 20, j + 5, k + 3, Blocks.fence, 0);
		this.setBlock(world, i + 20, j + 5, k + 7, Blocks.air, 1);
		this.setBlock(world, i + 20, j + 5, k + 11, Blocks.fence, 0);
		this.setBlock(world, i + 20, j + 11, k + 0, Blocks.wool, 14);
		this.setBlock(world, i + 20, j + 11, k + 1, Blocks.wool, 14);
		this.setBlock(world, i + 20, j + 11, k + 2, Blocks.wool, 14);
		this.setBlock(world, i + 20, j + 11, k + 3, Blocks.wool, 0);
		this.setBlock(world, i + 20, j + 11, k + 4, Blocks.wool, 0);
		this.setBlock(world, i + 20, j + 11, k + 5, Blocks.wool, 0);
		this.setBlock(world, i + 20, j + 11, k + 6, Blocks.wool, 14);
		this.setBlock(world, i + 20, j + 11, k + 7, Blocks.wool, 14);
		this.setBlock(world, i + 20, j + 11, k + 8, Blocks.wool, 14);
		this.setBlock(world, i + 20, j + 11, k + 9, Blocks.wool, 0);
		this.setBlock(world, i + 20, j + 11, k + 10, Blocks.wool, 0);
		this.setBlock(world, i + 20, j + 11, k + 11, Blocks.wool, 0);
		this.setBlock(world, i + 20, j + 11, k + 12, Blocks.wool, 14);
		this.setBlock(world, i + 20, j + 11, k + 13, Blocks.wool, 14);
		this.setBlock(world, i + 20, j + 11, k + 14, Blocks.wool, 14);
		this.setBlock(world, i + 20, j + 25, k + 0, Blocks.wool, 14);
		this.setBlock(world, i + 20, j + 25, k + 1, Blocks.wool, 14);
		this.setBlock(world, i + 20, j + 25, k + 2, Blocks.wool, 14);
		this.setBlock(world, i + 20, j + 25, k + 3, Blocks.wool, 0);
		this.setBlock(world, i + 20, j + 25, k + 4, Blocks.wool, 0);
		this.setBlock(world, i + 20, j + 25, k + 5, Blocks.wool, 0);
		this.setBlock(world, i + 20, j + 25, k + 6, Blocks.wool, 14);
		this.setBlock(world, i + 20, j + 25, k + 7, Blocks.wool, 14);
		this.setBlock(world, i + 20, j + 25, k + 8, Blocks.wool, 14);
		this.setBlock(world, i + 20, j + 25, k + 9, Blocks.wool, 0);
		this.setBlock(world, i + 20, j + 25, k + 10, Blocks.wool, 0);
		this.setBlock(world, i + 20, j + 25, k + 11, Blocks.wool, 0);
		this.setBlock(world, i + 20, j + 25, k + 12, Blocks.wool, 14);
		this.setBlock(world, i + 20, j + 25, k + 13, Blocks.wool, 14);
		this.setBlock(world, i + 20, j + 25, k + 14, Blocks.wool, 14);
		this.setBlock(world, i + 20, j + 27, k + 6, Blocks.air, 5);
		this.setBlock(world, i + 20, j + 27, k + 7, Blocks.air, 5);
		this.setBlock(world, i + 20, j + 27, k + 8, Blocks.air, 5);
		this.setBlock(world, i + 20, j + 28, k + 5, Blocks.planks, 1);
		this.setBlock(world, i + 20, j + 28, k + 9, Blocks.planks, 1);
		this.setBlock(world, i + 20, j + 29, k + 5, Blocks.fence, 0);
		this.setBlock(world, i + 20, j + 29, k + 9, Blocks.fence, 0);
		this.setBlock(world, i + 21, j + 0, k + 5, Blocks.log, 13);
		this.setBlock(world, i + 21, j + 0, k + 6, Blocks.log, 9);
		this.setBlock(world, i + 21, j + 0, k + 7, Blocks.log, 13);
		this.setBlock(world, i + 21, j + 0, k + 8, Blocks.log, 13);
		this.setBlock(world, i + 21, j + 0, k + 9, Blocks.log, 13);
		this.setBlock(world, i + 21, j + 1, k + 4, Blocks.log, 9);
		this.setBlock(world, i + 21, j + 1, k + 10, Blocks.log, 9);
		this.setBlock(world, i + 21, j + 2, k + 4, Blocks.iron_bars, 0);
		this.setBlock(world, i + 21, j + 2, k + 10, Blocks.iron_bars, 0);
		this.setBlock(world, i + 21, j + 3, k + 4, Blocks.iron_bars, 0);
		this.setBlock(world, i + 21, j + 3, k + 10, Blocks.iron_bars, 0);
		this.setBlock(world, i + 21, j + 4, k + 3, Blocks.log, 13);
		this.setBlock(world, i + 21, j + 4, k + 4, Blocks.planks, 1);
		this.setBlock(world, i + 21, j + 4, k + 5, Blocks.planks, 1);
		this.setBlock(world, i + 21, j + 4, k + 6, Blocks.planks, 1);
		this.setBlock(world, i + 21, j + 4, k + 7, Blocks.planks, 1);
		this.setBlock(world, i + 21, j + 4, k + 8, Blocks.planks, 1);
		this.setBlock(world, i + 21, j + 4, k + 9, Blocks.planks, 1);
		this.setBlock(world, i + 21, j + 4, k + 10, Blocks.planks, 1);
		this.setBlock(world, i + 21, j + 4, k + 11, Blocks.log, 13);
		this.setBlock(world, i + 21, j + 5, k + 3, Blocks.fence, 0);
		this.setBlock(world, i + 21, j + 5, k + 11, Blocks.fence, 0);
		this.setBlock(world, i + 21, j + 12, k + 0, Blocks.wool, 14);
		this.setBlock(world, i + 21, j + 12, k + 1, Blocks.wool, 14);
		this.setBlock(world, i + 21, j + 12, k + 2, Blocks.wool, 14);
		this.setBlock(world, i + 21, j + 12, k + 3, Blocks.wool, 0);
		this.setBlock(world, i + 21, j + 12, k + 4, Blocks.wool, 0);
		this.setBlock(world, i + 21, j + 12, k + 5, Blocks.wool, 0);
		this.setBlock(world, i + 21, j + 12, k + 6, Blocks.wool, 14);
		this.setBlock(world, i + 21, j + 12, k + 7, Blocks.wool, 14);
		this.setBlock(world, i + 21, j + 12, k + 8, Blocks.wool, 14);
		this.setBlock(world, i + 21, j + 12, k + 9, Blocks.wool, 0);
		this.setBlock(world, i + 21, j + 12, k + 10, Blocks.wool, 0);
		this.setBlock(world, i + 21, j + 12, k + 11, Blocks.wool, 0);
		this.setBlock(world, i + 21, j + 12, k + 12, Blocks.wool, 14);
		this.setBlock(world, i + 21, j + 12, k + 13, Blocks.wool, 14);
		this.setBlock(world, i + 21, j + 12, k + 14, Blocks.wool, 14);
		this.setBlock(world, i + 21, j + 13, k + 0, Blocks.wool, 14);
		this.setBlock(world, i + 21, j + 13, k + 1, Blocks.wool, 14);
		this.setBlock(world, i + 21, j + 13, k + 2, Blocks.wool, 14);
		this.setBlock(world, i + 21, j + 13, k + 3, Blocks.wool, 0);
		this.setBlock(world, i + 21, j + 13, k + 4, Blocks.wool, 0);
		this.setBlock(world, i + 21, j + 13, k + 5, Blocks.wool, 0);
		this.setBlock(world, i + 21, j + 13, k + 6, Blocks.wool, 14);
		this.setBlock(world, i + 21, j + 13, k + 7, Blocks.wool, 14);
		this.setBlock(world, i + 21, j + 13, k + 8, Blocks.wool, 14);
		this.setBlock(world, i + 21, j + 13, k + 9, Blocks.wool, 0);
		this.setBlock(world, i + 21, j + 13, k + 10, Blocks.wool, 0);
		this.setBlock(world, i + 21, j + 13, k + 11, Blocks.wool, 0);
		this.setBlock(world, i + 21, j + 13, k + 12, Blocks.wool, 14);
		this.setBlock(world, i + 21, j + 13, k + 13, Blocks.wool, 14);
		this.setBlock(world, i + 21, j + 13, k + 14, Blocks.wool, 14);
		this.setBlock(world, i + 21, j + 14, k + 0, Blocks.wool, 14);
		this.setBlock(world, i + 21, j + 14, k + 1, Blocks.wool, 14);
		this.setBlock(world, i + 21, j + 14, k + 2, Blocks.wool, 14);
		this.setBlock(world, i + 21, j + 14, k + 3, Blocks.wool, 0);
		this.setBlock(world, i + 21, j + 14, k + 4, Blocks.wool, 0);
		this.setBlock(world, i + 21, j + 14, k + 5, Blocks.wool, 0);
		this.setBlock(world, i + 21, j + 14, k + 6, Blocks.wool, 14);
		this.setBlock(world, i + 21, j + 14, k + 7, Blocks.wool, 14);
		this.setBlock(world, i + 21, j + 14, k + 8, Blocks.wool, 14);
		this.setBlock(world, i + 21, j + 14, k + 9, Blocks.wool, 0);
		this.setBlock(world, i + 21, j + 14, k + 10, Blocks.wool, 0);
		this.setBlock(world, i + 21, j + 14, k + 11, Blocks.wool, 0);
		this.setBlock(world, i + 21, j + 14, k + 12, Blocks.wool, 14);
		this.setBlock(world, i + 21, j + 14, k + 13, Blocks.wool, 14);
		this.setBlock(world, i + 21, j + 14, k + 14, Blocks.wool, 14);
		this.setBlock(world, i + 21, j + 22, k + 0, Blocks.wool, 14);
		this.setBlock(world, i + 21, j + 22, k + 1, Blocks.wool, 14);
		this.setBlock(world, i + 21, j + 22, k + 2, Blocks.wool, 14);
		this.setBlock(world, i + 21, j + 22, k + 3, Blocks.wool, 0);
		this.setBlock(world, i + 21, j + 22, k + 4, Blocks.wool, 0);
		this.setBlock(world, i + 21, j + 22, k + 5, Blocks.wool, 0);
		this.setBlock(world, i + 21, j + 22, k + 6, Blocks.wool, 14);
		this.setBlock(world, i + 21, j + 22, k + 7, Blocks.wool, 14);
		this.setBlock(world, i + 21, j + 22, k + 8, Blocks.wool, 14);
		this.setBlock(world, i + 21, j + 22, k + 9, Blocks.wool, 0);
		this.setBlock(world, i + 21, j + 22, k + 10, Blocks.wool, 0);
		this.setBlock(world, i + 21, j + 22, k + 11, Blocks.wool, 0);
		this.setBlock(world, i + 21, j + 22, k + 12, Blocks.wool, 14);
		this.setBlock(world, i + 21, j + 22, k + 13, Blocks.wool, 14);
		this.setBlock(world, i + 21, j + 22, k + 14, Blocks.wool, 14);
		this.setBlock(world, i + 21, j + 23, k + 0, Blocks.wool, 14);
		this.setBlock(world, i + 21, j + 23, k + 1, Blocks.wool, 14);
		this.setBlock(world, i + 21, j + 23, k + 2, Blocks.wool, 14);
		this.setBlock(world, i + 21, j + 23, k + 3, Blocks.wool, 0);
		this.setBlock(world, i + 21, j + 23, k + 4, Blocks.wool, 0);
		this.setBlock(world, i + 21, j + 23, k + 5, Blocks.wool, 0);
		this.setBlock(world, i + 21, j + 23, k + 6, Blocks.wool, 14);
		this.setBlock(world, i + 21, j + 23, k + 7, Blocks.wool, 14);
		this.setBlock(world, i + 21, j + 23, k + 8, Blocks.wool, 14);
		this.setBlock(world, i + 21, j + 23, k + 9, Blocks.wool, 0);
		this.setBlock(world, i + 21, j + 23, k + 10, Blocks.wool, 0);
		this.setBlock(world, i + 21, j + 23, k + 11, Blocks.wool, 0);
		this.setBlock(world, i + 21, j + 23, k + 12, Blocks.wool, 14);
		this.setBlock(world, i + 21, j + 23, k + 13, Blocks.wool, 14);
		this.setBlock(world, i + 21, j + 23, k + 14, Blocks.wool, 14);
		this.setBlock(world, i + 21, j + 24, k + 0, Blocks.wool, 14);
		this.setBlock(world, i + 21, j + 24, k + 1, Blocks.wool, 14);
		this.setBlock(world, i + 21, j + 24, k + 2, Blocks.wool, 14);
		this.setBlock(world, i + 21, j + 24, k + 3, Blocks.wool, 0);
		this.setBlock(world, i + 21, j + 24, k + 4, Blocks.wool, 0);
		this.setBlock(world, i + 21, j + 24, k + 5, Blocks.wool, 0);
		this.setBlock(world, i + 21, j + 24, k + 6, Blocks.wool, 14);
		this.setBlock(world, i + 21, j + 24, k + 7, Blocks.wool, 14);
		this.setBlock(world, i + 21, j + 24, k + 8, Blocks.wool, 14);
		this.setBlock(world, i + 21, j + 24, k + 9, Blocks.wool, 0);
		this.setBlock(world, i + 21, j + 24, k + 10, Blocks.wool, 0);
		this.setBlock(world, i + 21, j + 24, k + 11, Blocks.wool, 0);
		this.setBlock(world, i + 21, j + 24, k + 12, Blocks.wool, 14);
		this.setBlock(world, i + 21, j + 24, k + 13, Blocks.wool, 14);
		this.setBlock(world, i + 21, j + 24, k + 14, Blocks.wool, 14);
		this.setBlock(world, i + 21, j + 28, k + 6, Blocks.planks, 1);
		this.setBlock(world, i + 21, j + 28, k + 7, Blocks.planks, 1);
		this.setBlock(world, i + 21, j + 28, k + 8, Blocks.planks, 1);
		this.setBlock(world, i + 21, j + 29, k + 6, Blocks.fence, 0);
		this.setBlock(world, i + 21, j + 29, k + 7, Blocks.fence, 0);
		this.setBlock(world, i + 21, j + 29, k + 8, Blocks.fence, 0);
		this.setBlock(world, i + 22, j + 0, k + 5, Blocks.log, 9);
		this.setBlock(world, i + 22, j + 0, k + 6, Blocks.log, 13);
		this.setBlock(world, i + 22, j + 0, k + 7, Blocks.log, 13);
		this.setBlock(world, i + 22, j + 0, k + 8, Blocks.log, 13);
		this.setBlock(world, i + 22, j + 0, k + 9, Blocks.log, 9);
		this.setBlock(world, i + 22, j + 1, k + 4, Blocks.log, 13);
		this.setBlock(world, i + 22, j + 1, k + 7, Blocks.wool, 12);
		this.setBlock(world, i + 22, j + 1, k + 10, Blocks.log, 13);
		this.setBlock(world, i + 22, j + 2, k + 4, Blocks.log, 13);
		this.setBlock(world, i + 22, j + 2, k + 10, Blocks.log, 13);
		this.setBlock(world, i + 22, j + 3, k + 4, Blocks.log, 13);
		this.setBlock(world, i + 22, j + 3, k + 10, Blocks.log, 13);
		this.setBlock(world, i + 22, j + 4, k + 3, Blocks.log, 13);
		this.setBlock(world, i + 22, j + 4, k + 4, Blocks.planks, 1);
		this.setBlock(world, i + 22, j + 4, k + 5, Blocks.planks, 1);
		this.setBlock(world, i + 22, j + 4, k + 6, Blocks.planks, 1);
		this.setBlock(world, i + 22, j + 4, k + 7, Blocks.planks, 1);
		this.setBlock(world, i + 22, j + 4, k + 8, Blocks.planks, 1);
		this.setBlock(world, i + 22, j + 4, k + 9, Blocks.planks, 1);
		this.setBlock(world, i + 22, j + 4, k + 10, Blocks.planks, 1);
		this.setBlock(world, i + 22, j + 4, k + 11, Blocks.log, 13);
		this.setBlock(world, i + 22, j + 5, k + 5, Blocks.bedrock, 0);
		this.setBlock(world, i + 22, j + 5, k + 9, Blocks.gold_block, 0);
		this.setBlock(world, i + 22, j + 15, k + 0, Blocks.wool, 14);
		this.setBlock(world, i + 22, j + 15, k + 1, Blocks.wool, 14);
		this.setBlock(world, i + 22, j + 15, k + 2, Blocks.wool, 14);
		this.setBlock(world, i + 22, j + 15, k + 3, Blocks.wool, 0);
		this.setBlock(world, i + 22, j + 15, k + 4, Blocks.wool, 0);
		this.setBlock(world, i + 22, j + 15, k + 5, Blocks.wool, 0);
		this.setBlock(world, i + 22, j + 15, k + 6, Blocks.wool, 14);
		this.setBlock(world, i + 22, j + 15, k + 7, Blocks.wool, 14);
		this.setBlock(world, i + 22, j + 15, k + 8, Blocks.wool, 14);
		this.setBlock(world, i + 22, j + 15, k + 9, Blocks.wool, 0);
		this.setBlock(world, i + 22, j + 15, k + 10, Blocks.wool, 0);
		this.setBlock(world, i + 22, j + 15, k + 11, Blocks.wool, 0);
		this.setBlock(world, i + 22, j + 15, k + 12, Blocks.wool, 14);
		this.setBlock(world, i + 22, j + 15, k + 13, Blocks.wool, 14);
		this.setBlock(world, i + 22, j + 15, k + 14, Blocks.wool, 14);
		this.setBlock(world, i + 22, j + 16, k + 0, Blocks.wool, 14);
		this.setBlock(world, i + 22, j + 16, k + 1, Blocks.wool, 14);
		this.setBlock(world, i + 22, j + 16, k + 2, Blocks.wool, 14);
		this.setBlock(world, i + 22, j + 16, k + 3, Blocks.wool, 0);
		this.setBlock(world, i + 22, j + 16, k + 4, Blocks.wool, 0);
		this.setBlock(world, i + 22, j + 16, k + 5, Blocks.wool, 0);
		this.setBlock(world, i + 22, j + 16, k + 6, Blocks.wool, 14);
		this.setBlock(world, i + 22, j + 16, k + 7, Blocks.wool, 14);
		this.setBlock(world, i + 22, j + 16, k + 8, Blocks.wool, 14);
		this.setBlock(world, i + 22, j + 16, k + 9, Blocks.wool, 0);
		this.setBlock(world, i + 22, j + 16, k + 10, Blocks.wool, 0);
		this.setBlock(world, i + 22, j + 16, k + 11, Blocks.wool, 0);
		this.setBlock(world, i + 22, j + 16, k + 12, Blocks.wool, 14);
		this.setBlock(world, i + 22, j + 16, k + 13, Blocks.wool, 14);
		this.setBlock(world, i + 22, j + 16, k + 14, Blocks.wool, 14);
		this.setBlock(world, i + 22, j + 17, k + 0, Blocks.wool, 14);
		this.setBlock(world, i + 22, j + 17, k + 1, Blocks.wool, 14);
		this.setBlock(world, i + 22, j + 17, k + 2, Blocks.wool, 14);
		this.setBlock(world, i + 22, j + 17, k + 3, Blocks.wool, 0);
		this.setBlock(world, i + 22, j + 17, k + 4, Blocks.wool, 0);
		this.setBlock(world, i + 22, j + 17, k + 5, Blocks.wool, 0);
		this.setBlock(world, i + 22, j + 17, k + 6, Blocks.wool, 14);
		this.setBlock(world, i + 22, j + 17, k + 7, Blocks.wool, 14);
		this.setBlock(world, i + 22, j + 17, k + 8, Blocks.wool, 14);
		this.setBlock(world, i + 22, j + 17, k + 9, Blocks.wool, 0);
		this.setBlock(world, i + 22, j + 17, k + 10, Blocks.wool, 0);
		this.setBlock(world, i + 22, j + 17, k + 11, Blocks.wool, 0);
		this.setBlock(world, i + 22, j + 17, k + 12, Blocks.wool, 14);
		this.setBlock(world, i + 22, j + 17, k + 13, Blocks.wool, 14);
		this.setBlock(world, i + 22, j + 17, k + 14, Blocks.wool, 14);
		this.setBlock(world, i + 22, j + 18, k + 0, Blocks.wool, 14);
		this.setBlock(world, i + 22, j + 18, k + 1, Blocks.wool, 14);
		this.setBlock(world, i + 22, j + 18, k + 2, Blocks.wool, 14);
		this.setBlock(world, i + 22, j + 18, k + 3, Blocks.wool, 0);
		this.setBlock(world, i + 22, j + 18, k + 4, Blocks.wool, 0);
		this.setBlock(world, i + 22, j + 18, k + 5, Blocks.wool, 0);
		this.setBlock(world, i + 22, j + 18, k + 6, Blocks.wool, 14);
		this.setBlock(world, i + 22, j + 18, k + 7, Blocks.wool, 14);
		this.setBlock(world, i + 22, j + 18, k + 8, Blocks.wool, 14);
		this.setBlock(world, i + 22, j + 18, k + 9, Blocks.wool, 0);
		this.setBlock(world, i + 22, j + 18, k + 10, Blocks.wool, 0);
		this.setBlock(world, i + 22, j + 18, k + 11, Blocks.wool, 0);
		this.setBlock(world, i + 22, j + 18, k + 12, Blocks.wool, 14);
		this.setBlock(world, i + 22, j + 18, k + 13, Blocks.wool, 14);
		this.setBlock(world, i + 22, j + 18, k + 14, Blocks.wool, 14);
		this.setBlock(world, i + 22, j + 19, k + 0, Blocks.wool, 14);
		this.setBlock(world, i + 22, j + 19, k + 1, Blocks.wool, 14);
		this.setBlock(world, i + 22, j + 19, k + 2, Blocks.wool, 14);
		this.setBlock(world, i + 22, j + 19, k + 3, Blocks.wool, 0);
		this.setBlock(world, i + 22, j + 19, k + 4, Blocks.wool, 0);
		this.setBlock(world, i + 22, j + 19, k + 5, Blocks.wool, 0);
		this.setBlock(world, i + 22, j + 19, k + 6, Blocks.wool, 14);
		this.setBlock(world, i + 22, j + 19, k + 7, Blocks.wool, 14);
		this.setBlock(world, i + 22, j + 19, k + 8, Blocks.wool, 14);
		this.setBlock(world, i + 22, j + 19, k + 9, Blocks.wool, 0);
		this.setBlock(world, i + 22, j + 19, k + 10, Blocks.wool, 0);
		this.setBlock(world, i + 22, j + 19, k + 11, Blocks.wool, 0);
		this.setBlock(world, i + 22, j + 19, k + 12, Blocks.wool, 14);
		this.setBlock(world, i + 22, j + 19, k + 13, Blocks.wool, 14);
		this.setBlock(world, i + 22, j + 19, k + 14, Blocks.wool, 14);
		this.setBlock(world, i + 22, j + 20, k + 0, Blocks.wool, 14);
		this.setBlock(world, i + 22, j + 20, k + 1, Blocks.wool, 14);
		this.setBlock(world, i + 22, j + 20, k + 2, Blocks.wool, 14);
		this.setBlock(world, i + 22, j + 20, k + 3, Blocks.wool, 0);
		this.setBlock(world, i + 22, j + 20, k + 4, Blocks.wool, 0);
		this.setBlock(world, i + 22, j + 20, k + 5, Blocks.wool, 0);
		this.setBlock(world, i + 22, j + 20, k + 6, Blocks.wool, 14);
		this.setBlock(world, i + 22, j + 20, k + 7, Blocks.wool, 14);
		this.setBlock(world, i + 22, j + 20, k + 8, Blocks.wool, 14);
		this.setBlock(world, i + 22, j + 20, k + 9, Blocks.wool, 0);
		this.setBlock(world, i + 22, j + 20, k + 10, Blocks.wool, 0);
		this.setBlock(world, i + 22, j + 20, k + 11, Blocks.wool, 0);
		this.setBlock(world, i + 22, j + 20, k + 12, Blocks.wool, 14);
		this.setBlock(world, i + 22, j + 20, k + 13, Blocks.wool, 14);
		this.setBlock(world, i + 22, j + 20, k + 14, Blocks.wool, 14);
		this.setBlock(world, i + 22, j + 21, k + 0, Blocks.wool, 14);
		this.setBlock(world, i + 22, j + 21, k + 1, Blocks.wool, 14);
		this.setBlock(world, i + 22, j + 21, k + 2, Blocks.wool, 14);
		this.setBlock(world, i + 22, j + 21, k + 3, Blocks.wool, 0);
		this.setBlock(world, i + 22, j + 21, k + 4, Blocks.wool, 0);
		this.setBlock(world, i + 22, j + 21, k + 5, Blocks.wool, 0);
		this.setBlock(world, i + 22, j + 21, k + 6, Blocks.wool, 14);
		this.setBlock(world, i + 22, j + 21, k + 7, Blocks.wool, 14);
		this.setBlock(world, i + 22, j + 21, k + 8, Blocks.wool, 14);
		this.setBlock(world, i + 22, j + 21, k + 9, Blocks.wool, 0);
		this.setBlock(world, i + 22, j + 21, k + 10, Blocks.wool, 0);
		this.setBlock(world, i + 22, j + 21, k + 11, Blocks.wool, 0);
		this.setBlock(world, i + 22, j + 21, k + 12, Blocks.wool, 14);
		this.setBlock(world, i + 22, j + 21, k + 13, Blocks.wool, 14);
		this.setBlock(world, i + 22, j + 21, k + 14, Blocks.wool, 14);
		this.setBlock(world, i + 23, j + 0, k + 5, Blocks.log, 13);
		this.setBlock(world, i + 23, j + 0, k + 6, Blocks.log, 13);
		this.setBlock(world, i + 23, j + 0, k + 7, Blocks.log, 13);
		this.setBlock(world, i + 23, j + 0, k + 8, Blocks.log, 13);
		this.setBlock(world, i + 23, j + 0, k + 9, Blocks.log, 13);
		this.setBlock(world, i + 23, j + 1, k + 4, Blocks.log, 9);
		this.setBlock(world, i + 23, j + 1, k + 10, Blocks.log, 9);
		this.setBlock(world, i + 23, j + 2, k + 4, Blocks.iron_bars, 0);
		this.setBlock(world, i + 23, j + 2, k + 10, Blocks.iron_bars, 0);
		this.setBlock(world, i + 23, j + 3, k + 4, Blocks.iron_bars, 0);
		this.setBlock(world, i + 23, j + 3, k + 10, Blocks.iron_bars, 0);
		this.setBlock(world, i + 23, j + 4, k + 3, Blocks.log, 13);
		this.setBlock(world, i + 23, j + 4, k + 4, Blocks.planks, 1);
		this.setBlock(world, i + 23, j + 4, k + 5, Blocks.planks, 1);
		this.setBlock(world, i + 23, j + 4, k + 6, Blocks.planks, 1);
		this.setBlock(world, i + 23, j + 4, k + 7, Blocks.planks, 1);
		this.setBlock(world, i + 23, j + 4, k + 8, Blocks.planks, 1);
		this.setBlock(world, i + 23, j + 4, k + 9, Blocks.planks, 1);
		this.setBlock(world, i + 23, j + 4, k + 10, Blocks.planks, 1);
		this.setBlock(world, i + 23, j + 4, k + 11, Blocks.log, 13);
		this.setBlock(world, i + 23, j + 5, k + 3, Blocks.fence, 0);
		this.setBlock(world, i + 23, j + 5, k + 11, Blocks.fence, 0);
		this.setBlock(world, i + 23, j + 6, k + 11, Blocks.fence, 0);
		this.setBlock(world, i + 24, j + 0, k + 5, Blocks.log, 9);
		this.setBlock(world, i + 24, j + 0, k + 6, Blocks.log, 13);
		this.setBlock(world, i + 24, j + 0, k + 7, Blocks.log, 13);
		this.setBlock(world, i + 24, j + 0, k + 8, Blocks.log, 13);
		this.setBlock(world, i + 24, j + 0, k + 9, Blocks.log, 9);
		this.setBlock(world, i + 24, j + 1, k + 4, Blocks.log, 13);
		this.setBlock(world, i + 24, j + 1, k + 10, Blocks.log, 13);
		this.setBlock(world, i + 24, j + 2, k + 4, Blocks.log, 13);
		this.setBlock(world, i + 24, j + 2, k + 10, Blocks.log, 1);
		this.setBlock(world, i + 24, j + 3, k + 4, Blocks.log, 13);
		this.setBlock(world, i + 24, j + 3, k + 10, Blocks.log, 13);
		this.setBlock(world, i + 24, j + 4, k + 3, Blocks.log, 13);
		this.setBlock(world, i + 24, j + 4, k + 4, Blocks.planks, 1);
		this.setBlock(world, i + 24, j + 4, k + 5, Blocks.planks, 1);
		this.setBlock(world, i + 24, j + 4, k + 6, Blocks.planks, 1);
		this.setBlock(world, i + 24, j + 4, k + 7, Blocks.planks, 1);
		this.setBlock(world, i + 24, j + 4, k + 8, Blocks.planks, 1);
		this.setBlock(world, i + 24, j + 4, k + 9, Blocks.planks, 1);
		this.setBlock(world, i + 24, j + 4, k + 10, Blocks.planks, 1);
		this.setBlock(world, i + 24, j + 4, k + 11, Blocks.log, 13);
		this.setBlock(world, i + 24, j + 5, k + 3, Blocks.log, 13);
		this.setBlock(world, i + 24, j + 5, k + 11, Blocks.log, 13);
		this.setBlock(world, i + 24, j + 6, k + 3, Blocks.fence, 0);
		this.setBlock(world, i + 24, j + 6, k + 11, Blocks.fence, 0);
		this.setBlock(world, i + 25, j + 0, k + 5, Blocks.log, 13);
		this.setBlock(world, i + 25, j + 0, k + 6, Blocks.log, 13);
		this.setBlock(world, i + 25, j + 0, k + 7, Blocks.log, 13);
		this.setBlock(world, i + 25, j + 0, k + 8, Blocks.log, 13);
		this.setBlock(world, i + 25, j + 0, k + 9, Blocks.log, 13);
		this.setBlock(world, i + 25, j + 1, k + 5, Blocks.log, 13);
		this.setBlock(world, i + 25, j + 1, k + 7, Blocks.log, 1);
		this.setBlock(world, i + 25, j + 1, k + 9, Blocks.log, 13);
		this.setBlock(world, i + 25, j + 2, k + 4, Blocks.log, 13);
		this.setBlock(world, i + 25, j + 2, k + 7, Blocks.log, 1);
		this.setBlock(world, i + 25, j + 2, k + 10, Blocks.log, 13);
		this.setBlock(world, i + 25, j + 3, k + 4, Blocks.log, 13);
		this.setBlock(world, i + 25, j + 3, k + 7, Blocks.log, 1);
		this.setBlock(world, i + 25, j + 3, k + 10, Blocks.log, 13);
		this.setBlock(world, i + 25, j + 4, k + 4, Blocks.glass, 0);
		this.setBlock(world, i + 25, j + 4, k + 7, Blocks.log, 1);
		this.setBlock(world, i + 25, j + 4, k + 10, Blocks.glass, 0);
		this.setBlock(world, i + 25, j + 5, k + 3, Blocks.log, 13);
		this.setBlock(world, i + 25, j + 5, k + 4, Blocks.spruce_stairs,  0);
		this.setBlock(world, i + 25, j + 5, k + 5, Blocks.spruce_stairs,  0);
		this.setBlock(world, i + 25, j + 5, k + 6, Blocks.log, 13);
		this.setBlock(world, i + 25, j + 5, k + 7, Blocks.log, 13);
		this.setBlock(world, i + 25, j + 5, k + 8, Blocks.log, 1);
		this.setBlock(world, i + 25, j + 5, k + 9, Blocks.spruce_stairs,  0);
		this.setBlock(world, i + 25, j + 5, k + 10, Blocks.spruce_stairs,  0);
		this.setBlock(world, i + 25, j + 5, k + 11, Blocks.log, 13);
		this.setBlock(world, i + 25, j + 6, k + 3, Blocks.fence, 0);
		this.setBlock(world, i + 25, j + 6, k + 6, Blocks.log, 13);
		this.setBlock(world, i + 25, j + 6, k + 7, Blocks.log, 13);
		this.setBlock(world, i + 25, j + 6, k + 8, Blocks.log, 13);
		this.setBlock(world, i + 25, j + 6, k + 11, Blocks.fence, 0);
		this.setBlock(world, i + 25, j + 7, k + 3, Blocks.fence, 0);
		this.setBlock(world, i + 25, j + 7, k + 6, Blocks.fence, 0);
		this.setBlock(world, i + 25, j + 7, k + 7, Blocks.fence, 0);
		this.setBlock(world, i + 25, j + 7, k + 8, Blocks.fence, 0);
		this.setBlock(world, i + 25, j + 7, k + 11, Blocks.fence, 0);
		this.setBlock(world, i + 26, j + 0, k + 5, Blocks.log, 13);
		this.setBlock(world, i + 26, j + 0, k + 6, Blocks.log, 13);
		this.setBlock(world, i + 26, j + 0, k + 7, Blocks.log, 13);
		this.setBlock(world, i + 26, j + 0, k + 8, Blocks.log, 13);
		this.setBlock(world, i + 26, j + 0, k + 9, Blocks.log, 13);
		this.setBlock(world, i + 26, j + 1, k + 5, Blocks.log, 13);
		this.setBlock(world, i + 26, j + 1, k + 9, Blocks.log, 13);
		this.setBlock(world, i + 26, j + 2, k + 4, Blocks.log, 13);
		this.setBlock(world, i + 26, j + 2, k + 10, Blocks.log, 13);
		this.setBlock(world, i + 26, j + 3, k + 4, Blocks.log, 13);
		this.setBlock(world, i + 26, j + 3, k + 10, Blocks.log, 13);
		this.setBlock(world, i + 26, j + 4, k + 4, Blocks.log, 13);
		this.setBlock(world, i + 26, j + 4, k + 10, Blocks.log, 13);
		this.setBlock(world, i + 26, j + 5, k + 3, Blocks.log, 13);
		this.setBlock(world, i + 26, j + 5, k + 11, Blocks.log, 13);
		this.setBlock(world, i + 26, j + 6, k + 3, Blocks.log, 13);
		this.setBlock(world, i + 26, j + 6, k + 4, Blocks.spruce_stairs,  0);
		this.setBlock(world, i + 26, j + 6, k + 5, Blocks.spruce_stairs,  0);
		this.setBlock(world, i + 26, j + 6, k + 6, Blocks.planks, 1);
		this.setBlock(world, i + 26, j + 6, k + 8, Blocks.planks, 1);
		this.setBlock(world, i + 26, j + 6, k + 9, Blocks.spruce_stairs,  0);
		this.setBlock(world, i + 26, j + 6, k + 10, Blocks.spruce_stairs,  0);
		this.setBlock(world, i + 26, j + 6, k + 11, Blocks.log, 13);
		this.setBlock(world, i + 26, j + 7, k + 3, Blocks.fence, 0);
		this.setBlock(world, i + 26, j + 7, k + 11, Blocks.fence, 0);
		this.setBlock(world, i + 27, j + 0, k + 5, Blocks.log, 13);
		this.setBlock(world, i + 27, j + 0, k + 6, Blocks.log, 13);
		this.setBlock(world, i + 27, j + 0, k + 7, Blocks.log, 13);
		this.setBlock(world, i + 27, j + 0, k + 8, Blocks.log, 13);
		this.setBlock(world, i + 27, j + 0, k + 9, Blocks.log, 13);
		this.setBlock(world, i + 27, j + 1, k + 5, Blocks.log, 13);
		this.setBlock(world, i + 27, j + 1, k + 9, Blocks.log, 13);
		this.setBlock(world, i + 27, j + 2, k + 4, Blocks.log, 13);
		this.setBlock(world, i + 27, j + 2, k + 10, Blocks.log, 13);
		this.setBlock(world, i + 27, j + 3, k + 4, Blocks.log, 13);
		this.setBlock(world, i + 27, j + 3, k + 10, Blocks.log, 13);
		this.setBlock(world, i + 27, j + 4, k + 4, Blocks.glass, 0);
		this.setBlock(world, i + 27, j + 4, k + 10, Blocks.glass, 0);
		this.setBlock(world, i + 27, j + 5, k + 3, Blocks.log, 13);
		this.setBlock(world, i + 27, j + 5, k + 11, Blocks.log, 13);
		this.setBlock(world, i + 27, j + 6, k + 3, Blocks.log, 13);
		this.setBlock(world, i + 27, j + 6, k + 4, Blocks.planks, 1);
		this.setBlock(world, i + 27, j + 6, k + 5, Blocks.planks, 1);
		this.setBlock(world, i + 27, j + 6, k + 6, Blocks.planks, 1);
		this.setBlock(world, i + 27, j + 6, k + 7, Blocks.planks, 1);
		this.setBlock(world, i + 27, j + 6, k + 8, Blocks.planks, 1);
		this.setBlock(world, i + 27, j + 6, k + 9, Blocks.planks, 1);
		this.setBlock(world, i + 27, j + 6, k + 10, Blocks.planks, 1);
		this.setBlock(world, i + 27, j + 6, k + 11, Blocks.log, 13);
		this.setBlock(world, i + 27, j + 7, k + 3, Blocks.fence, 0);
		this.setBlock(world, i + 27, j + 7, k + 7, Blocks.spruce_stairs,  0);
		this.setBlock(world, i + 27, j + 7, k + 11, Blocks.fence, 0);
		this.setBlock(world, i + 28, j + 0, k + 5, Blocks.log, 13);
		this.setBlock(world, i + 28, j + 0, k + 6, Blocks.log, 13);
		this.setBlock(world, i + 28, j + 0, k + 7, Blocks.log, 13);
		this.setBlock(world, i + 28, j + 0, k + 8, Blocks.log, 13);
		this.setBlock(world, i + 28, j + 0, k + 9, Blocks.log, 13);
		this.setBlock(world, i + 28, j + 1, k + 5, Blocks.log, 13);
		this.setBlock(world, i + 28, j + 1, k + 7, Blocks.log, 13);
		this.setBlock(world, i + 28, j + 1, k + 9, Blocks.log, 13);
		this.setBlock(world, i + 28, j + 2, k + 4, Blocks.log, 13);
		this.setBlock(world, i + 28, j + 2, k + 7, Blocks.log, 13);
		this.setBlock(world, i + 28, j + 2, k + 10, Blocks.log, 13);
		this.setBlock(world, i + 28, j + 3, k + 4, Blocks.log, 13);
		this.setBlock(world, i + 28, j + 3, k + 7, Blocks.log, 13);
		this.setBlock(world, i + 28, j + 3, k + 10, Blocks.log, 13);
		this.setBlock(world, i + 28, j + 4, k + 4, Blocks.log, 13);
		this.setBlock(world, i + 28, j + 4, k + 7, Blocks.log, 13);
		this.setBlock(world, i + 28, j + 4, k + 10, Blocks.log, 13);
		this.setBlock(world, i + 28, j + 5, k + 3, Blocks.log, 13);
		this.setBlock(world, i + 28, j + 5, k + 7, Blocks.log, 13);
		this.setBlock(world, i + 28, j + 5, k + 11, Blocks.log, 13);
		this.setBlock(world, i + 28, j + 6, k + 3, Blocks.log, 13);
		this.setBlock(world, i + 28, j + 6, k + 4, Blocks.planks, 1);
		this.setBlock(world, i + 28, j + 6, k + 5, Blocks.planks, 1);
		this.setBlock(world, i + 28, j + 6, k + 6, Blocks.planks, 1);
		this.setBlock(world, i + 28, j + 6, k + 7, Blocks.log, 13);
		this.setBlock(world, i + 28, j + 6, k + 8, Blocks.planks, 1);
		this.setBlock(world, i + 28, j + 6, k + 9, Blocks.planks, 1);
		this.setBlock(world, i + 28, j + 6, k + 10, Blocks.planks, 1);
		this.setBlock(world, i + 28, j + 6, k + 11, Blocks.log, 13);
		this.setBlock(world, i + 28, j + 7, k + 3, Blocks.fence, 0);
		this.setBlock(world, i + 28, j + 7, k + 4, Blocks.wool, 2);
		this.setBlock(world, i + 28, j + 7, k + 6, Blocks.air, 2);
		this.setBlock(world, i + 28, j + 7, k + 7, Blocks.log, 13);
		this.setBlock(world, i + 28, j + 7, k + 8, Blocks.air, 3);

		generate2(world, rand, i, j, k);
		return true;
	}

	public boolean generate2(World world, Random rand, int i, int j, int k)
	{
		this.setBlock(world, i + 28, j + 7, k + 10, Blocks.wool, 3);
		this.setBlock(world, i + 28, j + 7, k + 11, Blocks.fence, 0);
		this.setBlock(world, i + 28, j + 8, k + 7, Blocks.log, 13);
		this.setBlock(world, i + 28, j + 9, k + 7, Blocks.log, 13);
		this.setBlock(world, i + 28, j + 10, k + 7, Blocks.log, 13);
		this.setBlock(world, i + 28, j + 11, k + 7, Blocks.log, 13);
		this.setBlock(world, i + 28, j + 12, k + 7, Blocks.log, 13);
		this.setBlock(world, i + 28, j + 13, k + 7, Blocks.log, 13);
		this.setBlock(world, i + 28, j + 14, k + 3, Blocks.log, 13);
		this.setBlock(world, i + 28, j + 14, k + 4, Blocks.log, 13);
		this.setBlock(world, i + 28, j + 14, k + 5, Blocks.log, 13);
		this.setBlock(world, i + 28, j + 14, k + 6, Blocks.log, 13);
		this.setBlock(world, i + 28, j + 14, k + 7, Blocks.log, 13);
		this.setBlock(world, i + 28, j + 14, k + 8, Blocks.log, 13);
		this.setBlock(world, i + 28, j + 14, k + 9, Blocks.log, 13);
		this.setBlock(world, i + 28, j + 14, k + 10, Blocks.log, 13);
		this.setBlock(world, i + 28, j + 14, k + 11, Blocks.log, 13);
		this.setBlock(world, i + 28, j + 15, k + 7, Blocks.log, 13);
		this.setBlock(world, i + 28, j + 16, k + 7, Blocks.log, 13);
		this.setBlock(world, i + 28, j + 17, k + 7, Blocks.log, 13);
		this.setBlock(world, i + 28, j + 18, k + 7, Blocks.log, 13);
		this.setBlock(world, i + 28, j + 19, k + 7, Blocks.log, 13);
		this.setBlock(world, i + 28, j + 20, k + 7, Blocks.log, 13);
		this.setBlock(world, i + 28, j + 21, k + 3, Blocks.log, 13);
		this.setBlock(world, i + 28, j + 21, k + 4, Blocks.log, 13);
		this.setBlock(world, i + 28, j + 21, k + 5, Blocks.log, 13);
		this.setBlock(world, i + 28, j + 21, k + 6, Blocks.log, 13);
		this.setBlock(world, i + 28, j + 21, k + 7, Blocks.log, 13);
		this.setBlock(world, i + 28, j + 21, k + 8, Blocks.log, 13);
		this.setBlock(world, i + 28, j + 21, k + 9, Blocks.log, 13);
		this.setBlock(world, i + 28, j + 21, k + 10, Blocks.log, 13);
		this.setBlock(world, i + 28, j + 21, k + 11, Blocks.log, 13);
		this.setBlock(world, i + 28, j + 22, k + 7, Blocks.log, 13);
		this.setBlock(world, i + 28, j + 23, k + 7, Blocks.log, 13);
		this.setBlock(world, i + 28, j + 24, k + 7, Blocks.log, 13);
		this.setBlock(world, i + 29, j + 0, k + 5, Blocks.log, 13);
		this.setBlock(world, i + 29, j + 0, k + 6, Blocks.log, 13);
		this.setBlock(world, i + 29, j + 0, k + 7, Blocks.log, 13);
		this.setBlock(world, i + 29, j + 0, k + 8, Blocks.log, 13);
		this.setBlock(world, i + 29, j + 0, k + 9, Blocks.log, 13);
		this.setBlock(world, i + 29, j + 1, k + 5, Blocks.log, 13);
		this.setBlock(world, i + 29, j + 1, k + 9, Blocks.log, 13);
		this.setBlock(world, i + 29, j + 2, k + 4, Blocks.log, 13);
		this.setBlock(world, i + 29, j + 2, k + 10, Blocks.log, 13);
		this.setBlock(world, i + 29, j + 3, k + 4, Blocks.log, 13);
		this.setBlock(world, i + 29, j + 3, k + 10, Blocks.log, 13);
		this.setBlock(world, i + 29, j + 4, k + 4, Blocks.glass, 0);
		this.setBlock(world, i + 29, j + 4, k + 10, Blocks.glass, 0);
		this.setBlock(world, i + 29, j + 5, k + 3, Blocks.log, 13);
		this.setBlock(world, i + 29, j + 5, k + 11, Blocks.log, 13);
		this.setBlock(world, i + 29, j + 6, k + 3, Blocks.log, 13);
		this.setBlock(world, i + 29, j + 6, k + 4, Blocks.planks, 1);
		this.setBlock(world, i + 29, j + 6, k + 5, Blocks.planks, 1);
		this.setBlock(world, i + 29, j + 6, k + 6, Blocks.planks, 1);
		this.setBlock(world, i + 29, j + 6, k + 7, Blocks.planks, 1);
		this.setBlock(world, i + 29, j + 6, k + 8, Blocks.planks, 1);
		this.setBlock(world, i + 29, j + 6, k + 9, Blocks.planks, 1);
		this.setBlock(world, i + 29, j + 6, k + 10, Blocks.planks, 1);
		this.setBlock(world, i + 29, j + 6, k + 11, Blocks.log, 13);
		this.setBlock(world, i + 29, j + 7, k + 3, Blocks.fence, 0);
		this.setBlock(world, i + 29, j + 7, k + 7, Blocks.air, 1);
		this.setBlock(world, i + 29, j + 7, k + 11, Blocks.fence, 0);
		this.setBlock(world, i + 29, j + 8, k + 3, Blocks.fence, 0);
		this.setBlock(world, i + 29, j + 8, k + 11, Blocks.fence, 0);
		this.setBlock(world, i + 29, j + 14, k + 3, Blocks.wool, 14);
		this.setBlock(world, i + 29, j + 14, k + 4, Blocks.wool, 0);
		this.setBlock(world, i + 29, j + 14, k + 5, Blocks.wool, 0);
