package net.arcticraft.world.gen;

import java.util.Random;

import net.arcticraft.entities.passive.EntityIceMage;
import net.arcticraft.main.Arcticraft;
import net.minecraft.block.Block;
import net.minecraft.block.BlockFlower;
import net.minecraft.block.BlockSnow;
import net.minecraft.init.Blocks;
import net.minecraft.tileentity.TileEntityChest;
import net.minecraft.tileentity.TileEntityMobSpawner;
import net.minecraft.util.WeightedRandomChestContent;
import net.minecraft.world.World;
import net.minecraft.world.biome.BiomeGenBase;
import net.minecraft.world.chunk.IChunkProvider;
import net.minecraft.world.gen.feature.WorldGenerator;
import net.minecraftforge.common.ChestGenHooks;
import net.minecraftforge.common.DungeonHooks;

public class WorldGenMageTower extends WorldGenerator{

	private static final int SIZE_X = 16;
	private static final int SIZE_Z = 16;
	private static final int SIZE_Y = 24;
	private static final int PLATFORM_AREA = SIZE_X * SIZE_Z;
	private static final int VOLUME = PLATFORM_AREA * SIZE_Y;

	public WorldGenMageTower(){}

	public boolean checkSpawn(World world, Random rand, int x, int y, int z)
	{
		if(rand.nextInt(1000) > 200)
		{
			return false;
		}
		int validPlatformBlocks = 0;
		int validVolumeBlocks = 0;
		for(int xx = x; xx < x + SIZE_X; ++xx)
		{
			for(int zz = z; zz < z + SIZE_Z; ++zz)
			{
				if(world.getBlock(xx, y - 1, zz) != Blocks.air && world.getBlock(x, y, z) != null && !world.getBlock(xx, y - 1, zz).isReplaceable(world, xx, y - 1, zz))
				{
					validPlatformBlocks++;
				}

				for(int yy = y; yy < y + SIZE_Y; ++yy)
				{
					Block block = world.getBlock(xx, yy, zz);
					if(block == Blocks.air || block == Blocks.log || block != null && block.isReplaceable(world, xx, yy, zz) || block.isLeaves(world, xx, yy, zz) || block instanceof BlockFlower || block instanceof BlockSnow)
					{
						validVolumeBlocks++;
					}
				}
			}
		}

		double validPlatformBlocksPercentage = (1.0d * validPlatformBlocks / PLATFORM_AREA) * 100;
		double validVolumeBlocksPercentage = (1.0d * validVolumeBlocks / VOLUME) * 100;
		// FMLLog.info("PlatformBlocks: %f ; VolumeBlocks: %f", validPlatformBlocksPercentage,validVolumeBlocksPercentage);
		return(validPlatformBlocksPercentage > 80 && validVolumeBlocksPercentage > 95d);
	}

	public boolean generate(World world, Random rand, int i, int j, int k)
	{
		if(!checkSpawn(world, rand, i, j, k))
		{
			return false;
		}

		clearArea(world, i, j + 3, k);
		buildPlatform(world, i, j, k);
		Arcticraft.notifyOfGenertion("Mage Tower", Integer.toString(i), Integer.toString(k));

		world.setBlock(i + 1, j + 0, k + 6, Blocks.nether_brick, 0, 2);
		world.setBlock(i + 1, j + 0, k + 7, Blocks.planks, 2, 2);
		world.setBlock(i + 1, j + 0, k + 8, Blocks.planks, 2, 2);
		world.setBlock(i + 1, j + 0, k + 9, Blocks.nether_brick, 0, 2);
		world.setBlock(i + 1, j + 1, k + 6, Blocks.brick_stairs, 0, 2);
		world.setBlock(i + 1, j + 1, k + 9, Blocks.brick_stairs, 0, 2);
		world.setBlock(i + 1, j + 2, k + 5, Blocks.nether_brick_fence, 0, 2);
		world.setBlock(i + 1, j + 2, k + 6, Blocks.brick_stairs, 0, 2);
		world.setBlock(i + 1, j + 2, k + 9, Blocks.brick_stairs, 0, 2);
		world.setBlock(i + 1, j + 2, k + 10, Blocks.nether_brick_fence, 0, 2);
		world.setBlock(i + 1, j + 3, k + 6, Blocks.brick_stairs, 2, 2);
		world.setBlock(i + 1, j + 3, k + 7, Blocks.brick_stairs, 0, 2);
		world.setBlock(i + 1, j + 3, k + 8, Blocks.brick_stairs, 0, 2);
		world.setBlock(i + 1, j + 3, k + 9, Blocks.brick_stairs, 3, 2);
		world.setBlock(i + 1, j + 5, k + 6, Blocks.stone_brick_stairs, 0, 2);
		world.setBlock(i + 1, j + 5, k + 7, Blocks.stone_brick_stairs, 0, 2);
		world.setBlock(i + 1, j + 5, k + 8, Blocks.stone_brick_stairs, 0, 2);
		world.setBlock(i + 1, j + 5, k + 9, Blocks.stone_brick_stairs, 0, 2);
		world.setBlock(i + 2, j + 0, k + 5, Blocks.log, 1, 2);
		world.setBlock(i + 2, j + 0, k + 6, Blocks.stonebrick, this.pickStoneblockType(rand), 2);
		world.setBlock(i + 2, j + 0, k + 7, Blocks.planks, 2, 2);
		world.setBlock(i + 2, j + 0, k + 8, Blocks.planks, 2, 2);
		world.setBlock(i + 2, j + 0, k + 9, Blocks.stonebrick, this.pickStoneblockType(rand), 2);
		world.setBlock(i + 2, j + 0, k + 10, Blocks.log, 1, 2);
		world.setBlock(i + 2, j + 1, k + 5, Blocks.log, 1, 2);
		world.setBlock(i + 2, j + 1, k + 6, Blocks.stonebrick, this.pickStoneblockType(rand), 2);
		world.setBlock(i + 2, j + 1, k + 9, Blocks.stonebrick, this.pickStoneblockType(rand), 2);
		world.setBlock(i + 2, j + 1, k + 10, Blocks.log, 1, 2);
		world.setBlock(i + 2, j + 2, k + 5, Blocks.log, 1, 2);
		world.setBlock(i + 2, j + 2, k + 6, Blocks.stonebrick, this.pickStoneblockType(rand), 2);
		world.setBlock(i + 2, j + 2, k + 9, Blocks.stonebrick, this.pickStoneblockType(rand), 2);
		world.setBlock(i + 2, j + 2, k + 10, Blocks.log, 1, 2);
		world.setBlock(i + 2, j + 3, k + 5, Blocks.log, 1, 2);
		world.setBlock(i + 2, j + 3, k + 6, Blocks.stonebrick, this.pickStoneblockType(rand), 2);
		world.setBlock(i + 2, j + 3, k + 7, Blocks.nether_brick, 0, 2);
		world.setBlock(i + 2, j + 3, k + 8, Blocks.nether_brick, 0, 2);
		world.setBlock(i + 2, j + 3, k + 9, Blocks.stonebrick, this.pickStoneblockType(rand), 2);
		world.setBlock(i + 2, j + 3, k + 10, Blocks.log, 1, 2);
		world.setBlock(i + 2, j + 4, k + 5, Blocks.log, 1, 2);
		world.setBlock(i + 2, j + 4, k + 6, Blocks.stonebrick, this.pickStoneblockType(rand), 2);
		world.setBlock(i + 2, j + 4, k + 7, Blocks.glass_pane, 0, 2);
		world.setBlock(i + 2, j + 4, k + 8, Blocks.glass_pane, 0, 2);
		world.setBlock(i + 2, j + 4, k + 9, Blocks.stonebrick, this.pickStoneblockType(rand), 2);
		world.setBlock(i + 2, j + 4, k + 10, Blocks.log, 1, 2);
		world.setBlock(i + 2, j + 5, k + 4, Blocks.stone_brick_stairs, 0, 2);
		world.setBlock(i + 2, j + 5, k + 5, Blocks.stone_brick_stairs, 0, 2);
		world.setBlock(i + 2, j + 5, k + 6, Blocks.brick_block, 0, 2);
		world.setBlock(i + 2, j + 5, k + 7, Blocks.stonebrick, this.pickStoneblockType(rand), 2);
		world.setBlock(i + 2, j + 5, k + 8, Blocks.stonebrick, this.pickStoneblockType(rand), 2);
		world.setBlock(i + 2, j + 5, k + 9, Blocks.brick_block, 0, 2);
		world.setBlock(i + 2, j + 5, k + 10, Blocks.stone_brick_stairs, 0, 2);
		world.setBlock(i + 2, j + 5, k + 11, Blocks.stone_brick_stairs, 0, 2);
		world.setBlock(i + 2, j + 6, k + 6, Blocks.stone_brick_stairs, 0, 2);
		world.setBlock(i + 2, j + 6, k + 7, Blocks.stone_brick_stairs, 0, 2);
		world.setBlock(i + 2, j + 6, k + 8, Blocks.stone_brick_stairs, 0, 2);
		world.setBlock(i + 2, j + 6, k + 9, Blocks.stone_brick_stairs, 0, 2);
		world.setBlock(i + 3, j + 0, k + 4, Blocks.stonebrick, this.pickStoneblockType(rand), 2);
		world.setBlock(i + 3, j + 0, k + 5, Blocks.stonebrick, this.pickStoneblockType(rand), 2);
		world.setBlock(i + 3, j + 0, k + 6, Blocks.planks, 2, 2);
		world.setBlock(i + 3, j + 0, k + 7, Blocks.planks, 2, 2);
		world.setBlock(i + 3, j + 0, k + 8, Blocks.planks, 2, 2);
		world.setBlock(i + 3, j + 0, k + 9, Blocks.planks, 2, 2);
		world.setBlock(i + 3, j + 0, k + 10, Blocks.planks, 2, 2);
		world.setBlock(i + 3, j + 0, k + 11, Blocks.stonebrick, this.pickStoneblockType(rand), 2);
		world.setBlock(i + 3, j + 1, k + 4, Blocks.stonebrick, this.pickStoneblockType(rand), 2);
		world.setBlock(i + 3, j + 1, k + 5, Blocks.stonebrick, this.pickStoneblockType(rand), 2);
		world.setBlock(i + 3, j + 1, k + 6, Blocks.wooden_slab, 2, 2);
		world.setBlock(i + 3, j + 1, k + 7, Blocks.air, 0, 2);
		world.setBlock(i + 3, j + 1, k + 8, Blocks.air, 0, 2);
		world.setBlock(i + 3, j + 1, k + 9, Blocks.wooden_slab, 2, 2);
		world.setBlock(i + 3, j + 1, k + 10, Blocks.stonebrick, this.pickStoneblockType(rand), 2);
		world.setBlock(i + 3, j + 1, k + 11, Blocks.stonebrick, this.pickStoneblockType(rand), 2);
		world.setBlock(i + 3, j + 2, k + 4, Blocks.stonebrick, this.pickStoneblockType(rand), 2);
		world.setBlock(i + 3, j + 2, k + 5, Blocks.stonebrick, this.pickStoneblockType(rand), 2);
		world.setBlock(i + 3, j + 2, k + 6, Blocks.wooden_slab, 9, 2);
		world.setBlock(i + 3, j + 2, k + 7, Blocks.air, 0, 2);
		world.setBlock(i + 3, j + 2, k + 8, Blocks.air, 0, 2);
		world.setBlock(i + 3, j + 2, k + 9, Blocks.wooden_slab, 9, 2);
		world.setBlock(i + 3, j + 2, k + 10, Blocks.stonebrick, this.pickStoneblockType(rand), 2);
		world.setBlock(i + 3, j + 2, k + 11, Blocks.stonebrick, this.pickStoneblockType(rand), 2);
		world.setBlock(i + 3, j + 3, k + 4, Blocks.stonebrick, this.pickStoneblockType(rand), 2);
		world.setBlock(i + 3, j + 3, k + 5, Blocks.stonebrick, this.pickStoneblockType(rand), 2);
		world.setBlock(i + 3, j + 3, k + 6, Blocks.double_wooden_slab, 1, 2);
		world.setBlock(i + 3, j + 3, k + 7, Blocks.wooden_slab, 9, 2);
		world.setBlock(i + 3, j + 3, k + 8, Blocks.wooden_slab, 9, 2);
		world.setBlock(i + 3, j + 3, k + 9, Blocks.double_wooden_slab, 1, 2);
		world.setBlock(i + 3, j + 3, k + 10, Blocks.stonebrick, this.pickStoneblockType(rand), 2);
		world.setBlock(i + 3, j + 3, k + 11, Blocks.stonebrick, this.pickStoneblockType(rand), 2);
		world.setBlock(i + 3, j + 4, k + 4, Blocks.stonebrick, this.pickStoneblockType(rand), 2);
		world.setBlock(i + 3, j + 4, k + 5, Blocks.stonebrick, this.pickStoneblockType(rand), 2);
		world.setBlock(i + 3, j + 4, k + 7, Blocks.air, 0, 2);
		world.setBlock(i + 3, j + 4, k + 8, Blocks.air, 0, 2);
		world.setBlock(i + 3, j + 4, k + 10, Blocks.stonebrick, this.pickStoneblockType(rand), 2);
		world.setBlock(i + 3, j + 4, k + 11, Blocks.stonebrick, this.pickStoneblockType(rand), 2);
		world.setBlock(i + 3, j + 5, k + 3, Blocks.stone_brick_stairs, 0, 2);
		world.setBlock(i + 3, j + 5, k + 4, Blocks.brick_block, 0, 2);
		world.setBlock(i + 3, j + 5, k + 5, Blocks.stonebrick, this.pickStoneblockType(rand), 2);
		world.setBlock(i + 3, j + 5, k + 6, Blocks.air, 0, 2);
		world.setBlock(i + 3, j + 5, k + 7, Blocks.air, 0, 2);
		world.setBlock(i + 3, j + 5, k + 8, Blocks.air, 0, 2);
		world.setBlock(i + 3, j + 5, k + 9, Blocks.air, 0, 2);
		world.setBlock(i + 3, j + 5, k + 10, Blocks.stonebrick, this.pickStoneblockType(rand), 2);
		world.setBlock(i + 3, j + 5, k + 11, Blocks.brick_block, 0, 2);
		world.setBlock(i + 3, j + 5, k + 12, Blocks.stone_brick_stairs, 0, 2);
		world.setBlock(i + 3, j + 6, k + 4, Blocks.stone_brick_stairs, 0, 2);
		world.setBlock(i + 3, j + 6, k + 5, Blocks.stone_brick_stairs, 0, 2);
		world.setBlock(i + 3, j + 6, k + 6, Blocks.brick_block, 0, 2);
		world.setBlock(i + 3, j + 6, k + 7, Blocks.stonebrick, this.pickStoneblockType(rand), 2);
		world.setBlock(i + 3, j + 6, k + 8, Blocks.stonebrick, this.pickStoneblockType(rand), 2);
		world.setBlock(i + 3, j + 6, k + 9, Blocks.brick_block, 0, 2);
		world.setBlock(i + 3, j + 6, k + 10, Blocks.stone_brick_stairs, 0, 2);
		world.setBlock(i + 3, j + 6, k + 11, Blocks.stone_brick_stairs, 0, 2);
		world.setBlock(i + 3, j + 7, k + 6, Blocks.log, 1, 2);
		world.setBlock(i + 3, j + 7, k + 7, Blocks.stonebrick, this.pickStoneblockType(rand), 2);
		world.setBlock(i + 3, j + 7, k + 8, Blocks.stonebrick, this.pickStoneblockType(rand), 2);
		world.setBlock(i + 3, j + 7, k + 9, Blocks.log, 1, 2);
		world.setBlock(i + 3, j + 8, k + 6, Blocks.log, 1, 2);
		world.setBlock(i + 3, j + 8, k + 7, Blocks.netherrack, 0, 2);
		world.setBlock(i + 3, j + 8, k + 8, Blocks.netherrack, 0, 2);
		world.setBlock(i + 3, j + 8, k + 9, Blocks.log, 1, 2);
		world.setBlock(i + 3, j + 9, k + 6, Blocks.log, 1, 2);
		world.setBlock(i + 3, j + 9, k + 7, Blocks.netherrack, 0, 2);
		world.setBlock(i + 3, j + 9, k + 8, Blocks.netherrack, 0, 2);
		world.setBlock(i + 3, j + 9, k + 9, Blocks.log, 1, 2);
		world.setBlock(i + 3, j + 10, k + 6, Blocks.log, 1, 2);
		world.setBlock(i + 3, j + 10, k + 7, Blocks.stonebrick, this.pickStoneblockType(rand), 2);
		world.setBlock(i + 3, j + 10, k + 8, Blocks.stonebrick, this.pickStoneblockType(rand), 2);
		world.setBlock(i + 3, j + 10, k + 9, Blocks.log, 1, 2);
		world.setBlock(i + 3, j + 11, k + 6, Blocks.log, 1, 2);
		world.setBlock(i + 3, j + 11, k + 7, Blocks.stonebrick, this.pickStoneblockType(rand), 2);
		world.setBlock(i + 3, j + 11, k + 8, Blocks.stonebrick, this.pickStoneblockType(rand), 2);
		world.setBlock(i + 3, j + 11, k + 9, Blocks.log, 1, 2);
		world.setBlock(i + 3, j + 17, k + 5, Blocks.wool, 11, 2);
		world.setBlock(i + 3, j + 17, k + 6, Blocks.wool, 11, 2);
		world.setBlock(i + 3, j + 17, k + 7, Blocks.wool, 11, 2);
		world.setBlock(i + 3, j + 17, k + 8, Blocks.wool, 11, 2);
		world.setBlock(i + 3, j + 17, k + 9, Blocks.wool, 11, 2);
		world.setBlock(i + 3, j + 17, k + 10, Blocks.wool, 11, 2);
		world.setBlock(i + 4, j + 0, k + 3, Blocks.stonebrick, this.pickStoneblockType(rand), 2);
		world.setBlock(i + 4, j + 0, k + 4, Blocks.planks, 2, 2);
		world.setBlock(i + 4, j + 0, k + 5, Blocks.planks, 2, 2);
		world.setBlock(i + 4, j + 0, k + 6, Blocks.planks, 1, 2);
		world.setBlock(i + 4, j + 0, k + 7, Blocks.planks, 1, 2);
		world.setBlock(i + 4, j + 0, k + 8, Blocks.planks, 1, 2);
		world.setBlock(i + 4, j + 0, k + 9, Blocks.planks, 1, 2);
		world.setBlock(i + 4, j + 0, k + 10, Blocks.planks, 2, 2);
		world.setBlock(i + 4, j + 0, k + 11, Blocks.planks, 2, 2);
		world.setBlock(i + 4, j + 0, k + 12, Blocks.stonebrick, this.pickStoneblockType(rand), 2);
		world.setBlock(i + 4, j + 1, k + 3, Blocks.stonebrick, this.pickStoneblockType(rand), 2);
		world.setBlock(i + 4, j + 1, k + 4, Blocks.wooden_slab, 2, 2);
		world.setBlock(i + 4, j + 1, k + 5, Blocks.wooden_slab, 2, 2);
		world.setBlock(i + 4, j + 1, k + 6, Blocks.air, 0, 2);
		world.setBlock(i + 4, j + 1, k + 7, Blocks.air, 0, 2);
		world.setBlock(i + 4, j + 1, k + 8, Blocks.air, 0, 2);
		world.setBlock(i + 4, j + 1, k + 9, Blocks.air, 0, 2);
		world.setBlock(i + 4, j + 1, k + 10, Blocks.wooden_slab, 2, 2);
		world.setBlock(i + 4, j + 1, k + 11, Blocks.wooden_slab, 2, 2);
		world.setBlock(i + 4, j + 1, k + 12, Blocks.stonebrick, this.pickStoneblockType(rand), 2);
		world.setBlock(i + 4, j + 2, k + 3, Blocks.stonebrick, this.pickStoneblockType(rand), 2);
		world.setBlock(i + 4, j + 2, k + 4, Blocks.wooden_slab, 9, 2);
		world.setBlock(i + 4, j + 2, k + 5, Blocks.wooden_slab, 9, 2);
		world.setBlock(i + 4, j + 2, k + 6, Blocks.air, 0, 2);
		world.setBlock(i + 4, j + 2, k + 7, Blocks.air, 0, 2);
		world.setBlock(i + 4, j + 2, k + 8, Blocks.air, 0, 2);
		world.setBlock(i + 4, j + 2, k + 9, Blocks.air, 0, 2);
		world.setBlock(i + 4, j + 2, k + 10, Blocks.wooden_slab, 9, 2);
		world.setBlock(i + 4, j + 2, k + 11, Blocks.wooden_slab, 9, 2);
		world.setBlock(i + 4, j + 2, k + 12, Blocks.stonebrick, this.pickStoneblockType(rand), 2);
		world.setBlock(i + 4, j + 3, k + 3, Blocks.stonebrick, this.pickStoneblockType(rand), 2);
		world.setBlock(i + 4, j + 3, k + 4, Blocks.bookshelf, 0, 2);
		world.setBlock(i + 4, j + 3, k + 5, Blocks.bookshelf, 0, 2);
		world.setBlock(i + 4, j + 3, k + 6, Blocks.air, 0, 2);
		world.setBlock(i + 4, j + 3, k + 7, Blocks.air, 0, 2);
		world.setBlock(i + 4, j + 3, k + 8, Blocks.air, 0, 2);
		world.setBlock(i + 4, j + 3, k + 9, Blocks.air, 0, 2);
		world.setBlock(i + 4, j + 3, k + 10, Blocks.bookshelf, 0, 2);
		world.setBlock(i + 4, j + 3, k + 11, Blocks.bookshelf, 0, 2);
		world.setBlock(i + 4, j + 3, k + 12, Blocks.stonebrick, this.pickStoneblockType(rand), 2);
		world.setBlock(i + 4, j + 4, k + 3, Blocks.stonebrick, this.pickStoneblockType(rand), 2);
		world.setBlock(i + 4, j + 4, k + 4, Blocks.air, 0, 2);
		world.setBlock(i + 4, j + 4, k + 5, Blocks.air, 0, 2);
		world.setBlock(i + 4, j + 4, k + 6, Blocks.air, 0, 2);
		world.setBlock(i + 4, j + 4, k + 7, Blocks.air, 0, 2);
		world.setBlock(i + 4, j + 4, k + 8, Blocks.air, 0, 2);
		world.setBlock(i + 4, j + 4, k + 9, Blocks.air, 0, 2);
		world.setBlock(i + 4, j + 4, k + 10, Blocks.air, 0, 2);
		world.setBlock(i + 4, j + 4, k + 11, Blocks.air, 0, 2);
		world.setBlock(i + 4, j + 4, k + 12, Blocks.stonebrick, this.pickStoneblockType(rand), 2);
		world.setBlock(i + 4, j + 5, k + 2, Blocks.stone_brick_stairs, 2, 2);
		world.setBlock(i + 4, j + 5, k + 3, Blocks.stonebrick, this.pickStoneblockType(rand), 2);
		world.setBlock(i + 4, j + 5, k + 4, Blocks.air, 0, 2);
		world.setBlock(i + 4, j + 5, k + 5, Blocks.air, 0, 2);
		world.setBlock(i + 4, j + 5, k + 6, Blocks.air, 0, 2);
		world.setBlock(i + 4, j + 5, k + 7, Blocks.air, 0, 2);
		world.setBlock(i + 4, j + 5, k + 8, Blocks.air, 0, 2);
		world.setBlock(i + 4, j + 5, k + 9, Blocks.air, 0, 2);
		world.setBlock(i + 4, j + 5, k + 10, Blocks.air, 0, 2);
		world.setBlock(i + 4, j + 5, k + 11, Blocks.air, 0, 2);
		world.setBlock(i + 4, j + 5, k + 12, Blocks.stonebrick, this.pickStoneblockType(rand), 2);
		world.setBlock(i + 4, j + 5, k + 13, Blocks.stone_brick_stairs, 3, 2);
		world.setBlock(i + 4, j + 6, k + 3, Blocks.stone_slab, 4, 2);
		world.setBlock(i + 4, j + 6, k + 4, Blocks.brick_block, 0, 2);
		world.setBlock(i + 4, j + 6, k + 5, Blocks.stonebrick, this.pickStoneblockType(rand), 2);
		world.setBlock(i + 4, j + 6, k + 6, Blocks.stonebrick, this.pickStoneblockType(rand), 2);
		world.setBlock(i + 4, j + 6, k + 7, this.pickDungeonBlock(rand), 0, 2);
		world.setBlock(i + 4, j + 6, k + 8, Blocks.stonebrick, this.pickStoneblockType(rand), 2);
		world.setBlock(i + 4, j + 6, k + 9, this.pickDungeonBlock(rand), 0, 2);
		world.setBlock(i + 4, j + 6, k + 10, Blocks.stonebrick, this.pickStoneblockType(rand), 2);
		world.setBlock(i + 4, j + 6, k + 11, Blocks.brick_block, 0, 2);
		world.setBlock(i + 4, j + 6, k + 12, Blocks.stone_slab, 4, 2);
		world.setBlock(i + 4, j + 7, k + 4, Blocks.stonebrick, this.pickStoneblockType(rand), 2);
		world.setBlock(i + 4, j + 7, k + 5, Blocks.stonebrick, this.pickStoneblockType(rand), 2);
		world.setBlock(i + 4, j + 7, k + 6, this.pickDungeonBlock(rand), 0, 2);
		world.setBlock(i + 4, j + 7, k + 7, Blocks.air, 0, 2);
		world.setBlock(i + 4, j + 7, k + 8, Blocks.stonebrick, this.pickStoneblockType(rand), 2);
		world.setBlock(i + 4, j + 7, k + 9, Blocks.air, 0, 2);
		world.setBlock(i + 4, j + 7, k + 10, Blocks.stonebrick, this.pickStoneblockType(rand), 2);
		world.setBlock(i + 4, j + 7, k + 11, Blocks.stonebrick, this.pickStoneblockType(rand), 2);
		world.setBlock(i + 4, j + 8, k + 4, Blocks.stonebrick, this.pickStoneblockType(rand), 2);
		world.setBlock(i + 4, j + 8, k + 5, Blocks.stonebrick, this.pickStoneblockType(rand), 2);
		world.setBlock(i + 4, j + 8, k + 6, Blocks.air, 0, 2);
		world.setBlock(i + 4, j + 8, k + 7, Blocks.air, 0, 2);
		world.setBlock(i + 4, j + 8, k + 8, Blocks.air, 0, 2);
		world.setBlock(i + 4, j + 8, k + 9, this.pickDungeonBlock(rand), 0, 2);
		world.setBlock(i + 4, j + 8, k + 10, Blocks.stonebrick, this.pickStoneblockType(rand), 2);
		world.setBlock(i + 4, j + 8, k + 11, Blocks.stonebrick, this.pickStoneblockType(rand), 2);
		world.setBlock(i + 4, j + 9, k + 4, Blocks.stonebrick, this.pickStoneblockType(rand), 2);
		world.setBlock(i + 4, j + 9, k + 5, Blocks.stonebrick, this.pickStoneblockType(rand), 2);
		world.setBlock(i + 4, j + 9, k + 6, Blocks.air, 0, 2);
		world.setBlock(i + 4, j + 9, k + 7, Blocks.air, 0, 2);
		world.setBlock(i + 4, j + 9, k + 8, Blocks.air, 0, 2);
		world.setBlock(i + 4, j + 9, k + 9, Blocks.air, 0, 2);
		world.setBlock(i + 4, j + 9, k + 10, Blocks.stonebrick, this.pickStoneblockType(rand), 2);
		world.setBlock(i + 4, j + 9, k + 11, Blocks.stonebrick, this.pickStoneblockType(rand), 2);
		world.setBlock(i + 4, j + 10, k + 4, Blocks.stonebrick, this.pickStoneblockType(rand), 2);
		world.setBlock(i + 4, j + 10, k + 5, Blocks.stonebrick, this.pickStoneblockType(rand), 2);
		world.setBlock(i + 4, j + 10, k + 6, Blocks.air, 0, 2);
		world.setBlock(i + 4, j + 10, k + 7, Blocks.air, 0, 2);
		world.setBlock(i + 4, j + 10, k + 8, Blocks.air, 0, 2);
		world.setBlock(i + 4, j + 10, k + 9, Blocks.air, 0, 2);
		world.setBlock(i + 4, j + 10, k + 10, Blocks.stonebrick, this.pickStoneblockType(rand), 2);
		world.setBlock(i + 4, j + 10, k + 11, Blocks.stonebrick, this.pickStoneblockType(rand), 2);
		world.setBlock(i + 4, j + 11, k + 4, Blocks.stonebrick, this.pickStoneblockType(rand), 2);
		world.setBlock(i + 4, j + 11, k + 5, Blocks.stonebrick, this.pickStoneblockType(rand), 2);
		world.setBlock(i + 4, j + 11, k + 6, Blocks.log, 0, 2);
		world.setBlock(i + 4, j + 11, k + 7, Blocks.log, 0, 2);
		world.setBlock(i + 4, j + 11, k + 8, Blocks.log, 0, 2);
		world.setBlock(i + 4, j + 11, k + 9, Blocks.log, 0, 2);
		world.setBlock(i + 4, j + 11, k + 10, Blocks.stonebrick, this.pickStoneblockType(rand), 2);
		world.setBlock(i + 4, j + 11, k + 11, Blocks.stonebrick, this.pickStoneblockType(rand), 2);
		world.setBlock(i + 4, j + 12, k + 6, Blocks.log, 1, 2);
		world.setBlock(i + 4, j + 12, k + 7, Blocks.stonebrick, this.pickStoneblockType(rand), 2);
		world.setBlock(i + 4, j + 12, k + 8, Blocks.stonebrick, this.pickStoneblockType(rand), 2);
		world.setBlock(i + 4, j + 12, k + 9, Blocks.log, 1, 2);
		world.setBlock(i + 4, j + 13, k + 6, Blocks.log, 1, 2);
		world.setBlock(i + 4, j + 13, k + 7, Blocks.glass_pane, 0, 2);
		world.setBlock(i + 4, j + 13, k + 8, Blocks.glass_pane, 0, 2);
		world.setBlock(i + 4, j + 13, k + 9, Blocks.log, 1, 2);
		world.setBlock(i + 4, j + 14, k + 6, Blocks.log, 1, 2);
		world.setBlock(i + 4, j + 14, k + 7, Blocks.glass_pane, 0, 2);
		world.setBlock(i + 4, j + 14, k + 8, Blocks.glass_pane, 0, 2);
		world.setBlock(i + 4, j + 14, k + 9, Blocks.log, 1, 2);
		world.setBlock(i + 4, j + 15, k + 6, Blocks.log, 1, 2);
		world.setBlock(i + 4, j + 15, k + 7, Blocks.stonebrick, this.pickStoneblockType(rand), 2);
		world.setBlock(i + 4, j + 15, k + 8, Blocks.stonebrick, this.pickStoneblockType(rand), 2);
		world.setBlock(i + 4, j + 15, k + 9, Blocks.log, 1, 2);
		world.setBlock(i + 4, j + 16, k + 6, Blocks.log, 1, 2);
		world.setBlock(i + 4, j + 16, k + 7, Blocks.stonebrick, this.pickStoneblockType(rand), 2);
		world.setBlock(i + 4, j + 16, k + 8, Blocks.stonebrick, this.pickStoneblockType(rand), 2);
		world.setBlock(i + 4, j + 16, k + 9, Blocks.log, 1, 2);
		world.setBlock(i + 4, j + 17, k + 3, Blocks.wool, 11, 2);
		world.setBlock(i + 4, j + 17, k + 4, Blocks.wool, 11, 2);
		world.setBlock(i + 4, j + 17, k + 5, Blocks.wool, 11, 2);
		world.setBlock(i + 4, j + 17, k + 6, Blocks.log, 1, 2);
		world.setBlock(i + 4, j + 17, k + 7, Blocks.stonebrick, this.pickStoneblockType(rand), 2);
		world.setBlock(i + 4, j + 17, k + 8, Blocks.stonebrick, this.pickStoneblockType(rand), 2);
		world.setBlock(i + 4, j + 17, k + 9, Blocks.log, 1, 2);
		world.setBlock(i + 4, j + 17, k + 10, Blocks.wool, 11, 2);
		world.setBlock(i + 4, j + 17, k + 11, Blocks.wool, 11, 2);
		world.setBlock(i + 4, j + 17, k + 12, Blocks.wool, 11, 2);
		world.setBlock(i + 4, j + 18, k + 5, Blocks.wool, 11, 2);
		world.setBlock(i + 4, j + 18, k + 6, Blocks.wool, 11, 2);
		world.setBlock(i + 4, j + 18, k + 7, Blocks.wool, 11, 2);
		world.setBlock(i + 4, j + 18, k + 8, Blocks.wool, 11, 2);
		world.setBlock(i + 4, j + 18, k + 9, Blocks.wool, 11, 2);
		world.setBlock(i + 4, j + 18, k + 10, Blocks.wool, 11, 2);
		world.setBlock(i + 5, j + 0, k + 2, Blocks.stonebrick, this.pickStoneblockType(rand), 2);
		world.setBlock(i + 5, j + 0, k + 3, Blocks.planks, 2, 2);
		world.setBlock(i + 5, j + 0, k + 4, Blocks.glowstone, 0, 2);
		world.setBlock(i + 5, j + 0, k + 5, Blocks.planks, 1, 2);
		world.setBlock(i + 5, j + 0, k + 6, Blocks.planks, 2, 2);
		world.setBlock(i + 5, j + 0, k + 7, Blocks.planks, 2, 2);
		world.setBlock(i + 5, j + 0, k + 8, Blocks.planks, 2, 2);
		world.setBlock(i + 5, j + 0, k + 9, Blocks.planks, 2, 2);
		world.setBlock(i + 5, j + 0, k + 10, Blocks.planks, 1, 2);
		world.setBlock(i + 5, j + 0, k + 11, Blocks.glowstone, 0, 2);
		world.setBlock(i + 5, j + 0, k + 12, Blocks.planks, 2, 2);
		world.setBlock(i + 5, j + 0, k + 13, Blocks.stonebrick, this.pickStoneblockType(rand), 2);
		world.setBlock(i + 5, j + 1, k + 2, Blocks.stonebrick, this.pickStoneblockType(rand), 2);
		world.setBlock(i + 5, j + 1, k + 3, Blocks.wooden_slab, 2, 2);
		world.setBlock(i + 5, j + 1, k + 4, Blocks.air, 0, 2);
		world.setBlock(i + 5, j + 1, k + 5, Blocks.air, 0, 2);
		world.setBlock(i + 5, j + 1, k + 6, Blocks.air, 0, 2);
		world.setBlock(i + 5, j + 1, k + 7, Blocks.air, 0, 2);
		world.setBlock(i + 5, j + 1, k + 8, Blocks.air, 0, 2);
		world.setBlock(i + 5, j + 1, k + 9, Blocks.air, 0, 2);
		world.setBlock(i + 5, j + 1, k + 10, Blocks.air, 0, 2);
		world.setBlock(i + 5, j + 1, k + 11, Blocks.air, 0, 2);
		world.setBlock(i + 5, j + 1, k + 12, Blocks.wooden_slab, 2, 2);
		world.setBlock(i + 5, j + 1, k + 13, Blocks.stonebrick, this.pickStoneblockType(rand), 2);
		world.setBlock(i + 5, j + 2, k + 2, Blocks.stonebrick, this.pickStoneblockType(rand), 2);
		world.setBlock(i + 5, j + 2, k + 3, Blocks.wooden_slab, 9, 2);
		world.setBlock(i + 5, j + 2, k + 4, Blocks.air, 0, 2);
		world.setBlock(i + 5, j + 2, k + 5, Blocks.air, 0, 2);
		world.setBlock(i + 5, j + 2, k + 6, Blocks.air, 0, 2);
		world.setBlock(i + 5, j + 2, k + 7, Blocks.air, 0, 2);
		world.setBlock(i + 5, j + 2, k + 8, Blocks.air, 0, 2);
		world.setBlock(i + 5, j + 2, k + 9, Blocks.air, 0, 2);
		world.setBlock(i + 5, j + 2, k + 10, Blocks.air, 0, 2);
		world.setBlock(i + 5, j + 2, k + 11, Blocks.air, 0, 2);
		world.setBlock(i + 5, j + 2, k + 12, Blocks.wooden_slab, 9, 2);
		world.setBlock(i + 5, j + 2, k + 13, Blocks.stonebrick, this.pickStoneblockType(rand), 2);
		world.setBlock(i + 5, j + 3, k + 2, Blocks.stonebrick, this.pickStoneblockType(rand), 2);
		world.setBlock(i + 5, j + 3, k + 3, Blocks.bookshelf, 0, 2);
		world.setBlock(i + 5, j + 3, k + 4, Blocks.air, 0, 2);
		world.setBlock(i + 5, j + 3, k + 5, Blocks.air, 0, 2);
		world.setBlock(i + 5, j + 3, k + 6, Blocks.air, 0, 2);
		world.setBlock(i + 5, j + 3, k + 7, Blocks.air, 0, 2);
		world.setBlock(i + 5, j + 3, k + 8, Blocks.air, 0, 2);
		world.setBlock(i + 5, j + 3, k + 9, Blocks.air, 0, 2);
		world.setBlock(i + 5, j + 3, k + 10, Blocks.air, 0, 2);
		world.setBlock(i + 5, j + 3, k + 11, Blocks.air, 0, 2);
		world.setBlock(i + 5, j + 3, k + 12, Blocks.bookshelf, 0, 2);
		world.setBlock(i + 5, j + 3, k + 13, Blocks.stonebrick, this.pickStoneblockType(rand), 2);
		world.setBlock(i + 5, j + 4, k + 2, Blocks.stonebrick, this.pickStoneblockType(rand), 2);
		world.setBlock(i + 5, j + 4, k + 3, Blocks.air, 0, 2);
		world.setBlock(i + 5, j + 4, k + 4, Blocks.air, 0, 2);
		world.setBlock(i + 5, j + 4, k + 5, Blocks.air, 0, 2);
		world.setBlock(i + 5, j + 4, k + 6, Blocks.air, 0, 2);
		world.setBlock(i + 5, j + 4, k + 7, Blocks.air, 0, 2);
		world.setBlock(i + 5, j + 4, k + 8, Blocks.air, 0, 2);
		world.setBlock(i + 5, j + 4, k + 9, Blocks.air, 0, 2);
		world.setBlock(i + 5, j + 4, k + 10, Blocks.air, 0, 2);
		world.setBlock(i + 5, j + 4, k + 11, Blocks.air, 0, 2);
		world.setBlock(i + 5, j + 4, k + 12, Blocks.air, 0, 2);
		world.setBlock(i + 5, j + 4, k + 13, Blocks.stonebrick, this.pickStoneblockType(rand), 2);
		world.setBlock(i + 5, j + 5, k + 1, Blocks.stone_brick_stairs, 2, 2);
		world.setBlock(i + 5, j + 5, k + 2, Blocks.brick_block, 0, 2);
		world.setBlock(i + 5, j + 5, k + 3, Blocks.air, 0, 2);
		world.setBlock(i + 5, j + 5, k + 4, Blocks.air, 0, 2);
		world.setBlock(i + 5, j + 5, k + 5, Blocks.air, 0, 2);
		world.setBlock(i + 5, j + 5, k + 6, Blocks.air, 0, 2);
		world.setBlock(i + 5, j + 5, k + 7, Blocks.air, 0, 2);
		world.setBlock(i + 5, j + 5, k + 8, Blocks.air, 0, 2);
		world.setBlock(i + 5, j + 5, k + 9, Blocks.air, 0, 2);
		world.setBlock(i + 5, j + 5, k + 10, Blocks.air, 0, 2);
		world.setBlock(i + 5, j + 5, k + 11, Blocks.air, 0, 2);
		world.setBlock(i + 5, j + 5, k + 12, Blocks.air, 0, 2);
		world.setBlock(i + 5, j + 5, k + 13, Blocks.brick_block, 0, 2);
		world.setBlock(i + 5, j + 5, k + 14, Blocks.stone_brick_stairs, 3, 2);
		world.setBlock(i + 5, j + 6, k + 2, Blocks.stone_brick_stairs, 2, 2);
		world.setBlock(i + 5, j + 6, k + 3, Blocks.brick_block, 0, 2);
		world.setBlock(i + 5, j + 6, k + 4, this.pickDungeonBlock(rand), 0, 2);
		world.setBlock(i + 5, j + 6, k + 5, this.pickDungeonBlock(rand), 0, 2);
		world.setBlock(i + 5, j + 6, k + 6, this.pickDungeonBlock(rand), 0, 2);
		world.setBlock(i + 5, j + 6, k + 7, this.pickDungeonBlock(rand), 0, 2);
		world.setBlock(i + 5, j + 6, k + 8, this.pickDungeonBlock(rand), 0, 2);
		world.setBlock(i + 5, j + 6, k + 9, this.pickDungeonBlock(rand), 0, 2);
		world.setBlock(i + 5, j + 6, k + 10, this.pickDungeonBlock(rand), 0, 2);
		world.setBlock(i + 5, j + 6, k + 11, this.pickDungeonBlock(rand), 0, 2);
		world.setBlock(i + 5, j + 6, k + 12, Blocks.brick_block, 0, 2);
		world.setBlock(i + 5, j + 6, k + 13, Blocks.stone_brick_stairs, 3, 2);
		world.setBlock(i + 5, j + 7, k + 3, Blocks.stonebrick, this.pickStoneblockType(rand), 2);
		world.setBlock(i + 5, j + 7, k + 5, Blocks.stonebrick, this.pickStoneblockType(rand), 2);
		world.setBlock(i + 5, j + 7, k + 6, Blocks.air, 0, 2);
		world.setBlock(i + 5, j + 7, k + 7, Blocks.air, 0, 2);
		world.setBlock(i + 5, j + 7, k + 8, Blocks.air, 0, 2);
		world.setBlock(i + 5, j + 7, k + 9, Blocks.air, 0, 2);
		world.setBlock(i + 5, j + 7, k + 10, Blocks.stonebrick, this.pickStoneblockType(rand), 2);
		world.setBlock(i + 5, j + 7, k + 12, Blocks.stonebrick, this.pickStoneblockType(rand), 2);
		world.setBlock(i + 5, j + 8, k + 3, Blocks.stonebrick, this.pickStoneblockType(rand), 2);
		world.setBlock(i + 5, j + 8, k + 5, Blocks.air, 0, 2);
		world.setBlock(i + 5, j + 8, k + 6, Blocks.air, 0, 2);
		world.setBlock(i + 5, j + 8, k + 7, Blocks.air, 0, 2);
		world.setBlock(i + 5, j + 8, k + 8, Blocks.air, 0, 2);
		world.setBlock(i + 5, j + 8, k + 9, Blocks.air, 0, 2);
		world.setBlock(i + 5, j + 8, k + 10, Blocks.air, 0, 2);
		world.setBlock(i + 5, j + 8, k + 11, Blocks.air, 0, 2);
		world.setBlock(i + 5, j + 8, k + 12, Blocks.stonebrick, this.pickStoneblockType(rand), 2);
		world.setBlock(i + 5, j + 9, k + 3, Blocks.stonebrick, this.pickStoneblockType(rand), 2);
		world.setBlock(i + 5, j + 9, k + 4, Blocks.air, 0, 2);
		world.setBlock(i + 5, j + 9, k + 5, Blocks.air, 0, 2);
		world.setBlock(i + 5, j + 9, k + 6, Blocks.air, 0, 2);
		world.setBlock(i + 5, j + 9, k + 7, Blocks.air, 0, 2);
		world.setBlock(i + 5, j + 9, k + 8, Blocks.air, 0, 2);
		world.setBlock(i + 5, j + 9, k + 9, Blocks.air, 0, 2);
		world.setBlock(i + 5, j + 9, k + 10, Blocks.air, 0, 2);
		world.setBlock(i + 5, j + 9, k + 11, Blocks.air, 0, 2);
		world.setBlock(i + 5, j + 9, k + 12, Blocks.stonebrick, this.pickStoneblockType(rand), 2);
		world.setBlock(i + 5, j + 10, k + 3, Blocks.stonebrick, this.pickStoneblockType(rand), 2);
		world.setBlock(i + 5, j + 10, k + 4, Blocks.air, 0, 2);
		world.setBlock(i + 5, j + 10, k + 5, Blocks.air, 0, 2);
		world.setBlock(i + 5, j + 10, k + 6, Blocks.air, 0, 2);
		world.setBlock(i + 5, j + 10, k + 7, Blocks.air, 0, 2);
		world.setBlock(i + 5, j + 10, k + 8, Blocks.air, 0, 2);
		world.setBlock(i + 5, j + 10, k + 9, Blocks.air, 0, 2);
		world.setBlock(i + 5, j + 10, k + 10, Blocks.air, 0, 2);
		world.setBlock(i + 5, j + 10, k + 11, this.pickDungeonBlock(rand), 0, 2);
		world.setBlock(i + 5, j + 10, k + 12, Blocks.stonebrick, this.pickStoneblockType(rand), 2);
		world.setBlock(i + 5, j + 11, k + 3, Blocks.stonebrick, this.pickStoneblockType(rand), 2);
		world.setBlock(i + 5, j + 11, k + 4, Blocks.log, 0, 2);
		world.setBlock(i + 5, j + 11, k + 5, Blocks.log, 0, 2);
		world.setBlock(i + 5, j + 11, k + 6, Blocks.planks, 1, 2);
		world.setBlock(i + 5, j + 11, k + 7, Blocks.planks, 1, 2);
		world.setBlock(i + 5, j + 11, k + 8, Blocks.planks, 1, 2);
		world.setBlock(i + 5, j + 11, k + 9, Blocks.planks, 1, 2);
		world.setBlock(i + 5, j + 11, k + 10, Blocks.log, 0, 2);
		world.setBlock(i + 5, j + 11, k + 11, Blocks.log, 0, 2);
		world.setBlock(i + 5, j + 11, k + 12, Blocks.stonebrick, this.pickStoneblockType(rand), 2);
		world.setBlock(i + 5, j + 12, k + 4, Blocks.stonebrick, this.pickStoneblockType(rand), 2);
		world.setBlock(i + 5, j + 12, k + 5, Blocks.stonebrick, this.pickStoneblockType(rand), 2);
		world.setBlock(i + 5, j + 12, k + 10, Blocks.stonebrick, this.pickStoneblockType(rand), 2);
		world.setBlock(i + 5, j + 12, k + 11, Blocks.stonebrick, this.pickStoneblockType(rand), 2);
		world.setBlock(i + 5, j + 13, k + 4, Blocks.stonebrick, this.pickStoneblockType(rand), 2);
		world.setBlock(i + 5, j + 13, k + 5, Blocks.stonebrick, this.pickStoneblockType(rand), 2);
		world.setBlock(i + 5, j + 13, k + 6, Blocks.air, 0, 2);
		world.setBlock(i + 5, j + 13, k + 7, Blocks.air, 0, 2);
		world.setBlock(i + 5, j + 13, k + 8, Blocks.air, 0, 2);
		world.setBlock(i + 5, j + 13, k + 9, Blocks.air, 0, 2);
		world.setBlock(i + 5, j + 13, k + 10, Blocks.stonebrick, this.pickStoneblockType(rand), 2);
		world.setBlock(i + 5, j + 13, k + 11, Blocks.stonebrick, this.pickStoneblockType(rand), 2);
		world.setBlock(i + 5, j + 14, k + 4, Blocks.stonebrick, this.pickStoneblockType(rand), 2);
		world.setBlock(i + 5, j + 14, k + 5, Blocks.stonebrick, this.pickStoneblockType(rand), 2);
		world.setBlock(i + 5, j + 14, k + 6, Blocks.air, 0, 2);
		world.setBlock(i + 5, j + 14, k + 7, Blocks.air, 0, 2);
		world.setBlock(i + 5, j + 14, k + 8, Blocks.air, 0, 2);
		world.setBlock(i + 5, j + 14, k + 9, Blocks.air, 0, 2);
		world.setBlock(i + 5, j + 14, k + 10, Blocks.stonebrick, this.pickStoneblockType(rand), 2);
		world.setBlock(i + 5, j + 14, k + 11, Blocks.stonebrick, this.pickStoneblockType(rand), 2);
		world.setBlock(i + 5, j + 15, k + 4, Blocks.stonebrick, this.pickStoneblockType(rand), 2);
		world.setBlock(i + 5, j + 15, k + 5, Blocks.stonebrick, this.pickStoneblockType(rand), 2);
		world.setBlock(i + 5, j + 15, k + 6, Blocks.air, 0, 2);
		world.setBlock(i + 5, j + 15, k + 7, Blocks.air, 0, 2);
		world.setBlock(i + 5, j + 15, k + 8, Blocks.air, 0, 2);
		world.setBlock(i + 5, j + 15, k + 9, Blocks.air, 0, 2);
		world.setBlock(i + 5, j + 15, k + 10, Blocks.stonebrick, this.pickStoneblockType(rand), 2);
		world.setBlock(i + 5, j + 15, k + 11, Blocks.stonebrick, this.pickStoneblockType(rand), 2);
		world.setBlock(i + 5, j + 16, k + 4, Blocks.stonebrick, this.pickStoneblockType(rand), 2);
		world.setBlock(i + 5, j + 16, k + 5, Blocks.stonebrick, this.pickStoneblockType(rand), 2);
		world.setBlock(i + 5, j + 16, k + 6, Blocks.air, 0, 2);
		world.setBlock(i + 5, j + 16, k + 7, Blocks.air, 0, 2);
		world.setBlock(i + 5, j + 16, k + 8, Blocks.air, 0, 2);
		world.setBlock(i + 5, j + 16, k + 9, Blocks.air, 0, 2);
		world.setBlock(i + 5, j + 16, k + 10, Blocks.stonebrick, this.pickStoneblockType(rand), 2);
		world.setBlock(i + 5, j + 16, k + 11, Blocks.stonebrick, this.pickStoneblockType(rand), 2);
		world.setBlock(i + 5, j + 17, k + 2, Blocks.wool, 11, 2);
		world.setBlock(i + 5, j + 17, k + 3, Blocks.wool, 11, 2);
		world.setBlock(i + 5, j + 17, k + 4, Blocks.stonebrick, this.pickStoneblockType(rand), 2);
		world.setBlock(i + 5, j + 17, k + 5, Blocks.stonebrick, this.pickStoneblockType(rand), 2);
		world.setBlock(i + 5, j + 17, k + 6, Blocks.air, 0, 2);
		world.setBlock(i + 5, j + 17, k + 7, Blocks.air, 0, 2);
		world.setBlock(i + 5, j + 17, k + 8, Blocks.air, 0, 2);
		world.setBlock(i + 5, j + 17, k + 9, Blocks.air, 0, 2);
		world.setBlock(i + 5, j + 17, k + 10, Blocks.stonebrick, this.pickStoneblockType(rand), 2);
		world.setBlock(i + 5, j + 17, k + 11, Blocks.stonebrick, this.pickStoneblockType(rand), 2);
		world.setBlock(i + 5, j + 17, k + 12, Blocks.wool, 11, 2);
		world.setBlock(i + 5, j + 18, k + 4, Blocks.wool, 11, 2);
		world.setBlock(i + 5, j + 18, k + 5, Blocks.wool, 11, 2);
		world.setBlock(i + 5, j + 18, k + 6, Blocks.air, 0, 2);
		world.setBlock(i + 5, j + 18, k + 7, Blocks.air, 0, 2);
		world.setBlock(i + 5, j + 18, k + 8, Blocks.air, 0, 2);
		world.setBlock(i + 5, j + 18, k + 9, Blocks.air, 0, 2);
		world.setBlock(i + 5, j + 18, k + 10, Blocks.wool, 11, 2);
		world.setBlock(i + 5, j + 18, k + 11, Blocks.wool, 11, 2);
		world.setBlock(i + 5, j + 19, k + 6, Blocks.wool, 11, 2);
		world.setBlock(i + 5, j + 19, k + 7, Blocks.wool, 11, 2);
		world.setBlock(i + 5, j + 19, k + 8, Blocks.wool, 11, 2);
		world.setBlock(i + 5, j + 19, k + 9, Blocks.wool, 11, 2);
		world.setBlock(i + 6, j + 0, k + 2, Blocks.stonebrick, this.pickStoneblockType(rand), 2);
		world.setBlock(i + 6, j + 0, k + 3, Blocks.planks, 2, 2);
		world.setBlock(i + 6, j + 0, k + 4, Blocks.planks, 1, 2);
		world.setBlock(i + 6, j + 0, k + 5, Blocks.planks, 2, 2);
		world.setBlock(i + 6, j + 0, k + 6, Blocks.planks, 2, 2);
		world.setBlock(i + 6, j + 0, k + 7, Blocks.planks, 0, 2);
		world.setBlock(i + 6, j + 0, k + 8, Blocks.planks, 0, 2);
		world.setBlock(i + 6, j + 0, k + 9, Blocks.planks, 2, 2);
		world.setBlock(i + 6, j + 0, k + 10, Blocks.planks, 2, 2);
		world.setBlock(i + 6, j + 0, k + 11, Blocks.planks, 1, 2);
		world.setBlock(i + 6, j + 0, k + 12, Blocks.planks, 2, 2);
		world.setBlock(i + 6, j + 0, k + 13, Blocks.stonebrick, this.pickStoneblockType(rand), 2);
		world.setBlock(i + 6, j + 1, k + 2, Blocks.stonebrick, this.pickStoneblockType(rand), 2);
		world.setBlock(i + 6, j + 1, k + 3, Blocks.wooden_slab, 2, 2);
		world.setBlock(i + 6, j + 1, k + 4, Blocks.air, 0, 2);
		world.setBlock(i + 6, j + 1, k + 5, Blocks.air, 0, 2);
		world.setBlock(i + 6, j + 1, k + 6, Blocks.stonebrick, 0, 2);
		world.setBlock(i + 6, j + 1, k + 7, Blocks.oak_stairs, 0, 2);
		world.setBlock(i + 6, j + 1, k + 8, Blocks.oak_stairs, 0, 2);
		world.setBlock(i + 6, j + 1, k + 9, Blocks.stonebrick, 0, 2);
		world.setBlock(i + 6, j + 1, k + 10, Blocks.air, 0, 2);
		world.setBlock(i + 6, j + 1, k + 11, Blocks.air, 0, 2);
		world.setBlock(i + 6, j + 1, k + 12, Blocks.wooden_slab, 2, 2);
		world.setBlock(i + 6, j + 1, k + 13, Blocks.stonebrick, this.pickStoneblockType(rand), 2);
		world.setBlock(i + 6, j + 2, k + 2, Blocks.stonebrick, this.pickStoneblockType(rand), 2);
		world.setBlock(i + 6, j + 2, k + 3, Blocks.wooden_slab, 9, 2);
		world.setBlock(i + 6, j + 2, k + 4, Blocks.air, 0, 2);
		world.setBlock(i + 6, j + 2, k + 5, Blocks.air, 0, 2);
		world.setBlock(i + 6, j + 2, k + 6, Blocks.air, 0, 2);
		world.setBlock(i + 6, j + 2, k + 7, Blocks.air, 0, 2);
		world.setBlock(i + 6, j + 2, k + 8, Blocks.air, 0, 2);
		world.setBlock(i + 6, j + 2, k + 9, Blocks.air, 0, 2);
		world.setBlock(i + 6, j + 2, k + 10, Blocks.air, 0, 2);
		world.setBlock(i + 6, j + 2, k + 11, Blocks.air, 0, 2);
		world.setBlock(i + 6, j + 2, k + 12, Blocks.wooden_slab, 9, 2);
		world.setBlock(i + 6, j + 2, k + 13, Blocks.stonebrick, this.pickStoneblockType(rand), 2);
		world.setBlock(i + 6, j + 3, k + 2, Blocks.stonebrick, this.pickStoneblockType(rand), 2);
		world.setBlock(i + 6, j + 3, k + 3, Blocks.bookshelf, 0, 2);
		world.setBlock(i + 6, j + 3, k + 4, Blocks.air, 0, 2);
		world.setBlock(i + 6, j + 3, k + 5, Blocks.air, 0, 2);
		world.setBlock(i + 6, j + 3, k + 6, Blocks.air, 0, 2);
		world.setBlock(i + 6, j + 3, k + 7, Blocks.air, 0, 2);
		world.setBlock(i + 6, j + 3, k + 8, Blocks.air, 0, 2);
		world.setBlock(i + 6, j + 3, k + 9, Blocks.air, 0, 2);
		world.setBlock(i + 6, j + 3, k + 10, Blocks.air, 0, 2);
		world.setBlock(i + 6, j + 3, k + 11, Blocks.air, 0, 2);
		world.setBlock(i + 6, j + 3, k + 12, Blocks.bookshelf, 0, 2);
		world.setBlock(i + 6, j + 3, k + 13, Blocks.stonebrick, this.pickStoneblockType(rand), 2);
		world.setBlock(i + 6, j + 4, k + 2, Blocks.stonebrick, this.pickStoneblockType(rand), 2);
		world.setBlock(i + 6, j + 4, k + 3, Blocks.air, 0, 2);
		world.setBlock(i + 6, j + 4, k + 4, Blocks.air, 0, 2);
		world.setBlock(i + 6, j + 4, k + 5, Blocks.air, 0, 2);
		world.setBlock(i + 6, j + 4, k + 6, Blocks.air, 0, 2);
		world.setBlock(i + 6, j + 4, k + 7, Blocks.air, 0, 2);
		world.setBlock(i + 6, j + 4, k + 8, Blocks.air, 0, 2);
		world.setBlock(i + 6, j + 4, k + 9, Blocks.air, 0, 2);
		world.setBlock(i + 6, j + 4, k + 10, Blocks.air, 0, 2);
		world.setBlock(i + 6, j + 4, k + 11, Blocks.air, 0, 2);
		world.setBlock(i + 6, j + 4, k + 12, Blocks.air, 0, 2);
		world.setBlock(i + 6, j + 4, k + 13, Blocks.stonebrick, this.pickStoneblockType(rand), 2);
		world.setBlock(i + 6, j + 5, k + 1, Blocks.stone_brick_stairs, 2, 2);
		world.setBlock(i + 6, j + 5, k + 2, Blocks.stonebrick, this.pickStoneblockType(rand), 2);
		world.setBlock(i + 6, j + 5, k + 3, Blocks.air, 0, 2);
		world.setBlock(i + 6, j + 5, k + 4, Blocks.air, 0, 2);
		world.setBlock(i + 6, j + 5, k + 5, Blocks.air, 0, 2);
		world.setBlock(i + 6, j + 5, k + 6, Blocks.log, 5, 2);
		world.setBlock(i + 6, j + 5, k + 7, Blocks.log, 9, 2);
		world.setBlock(i + 6, j + 5, k + 8, Blocks.log, 9, 2);
		world.setBlock(i + 6, j + 5, k + 9, Blocks.log, 5, 2);
		world.setBlock(i + 6, j + 5, k + 10, Blocks.air, 0, 2);
		world.setBlock(i + 6, j + 5, k + 11, Blocks.air, 0, 2);
		world.setBlock(i + 6, j + 5, k + 12, Blocks.air, 0, 2);
		world.setBlock(i + 6, j + 5, k + 13, Blocks.stonebrick, this.pickStoneblockType(rand), 2);
		world.setBlock(i + 6, j + 5, k + 14, Blocks.stone_brick_stairs, 3, 2);
		world.setBlock(i + 6, j + 6, k + 2, Blocks.stone_brick_stairs, 2, 2);
		world.setBlock(i + 6, j + 6, k + 3, Blocks.stonebrick, this.pickStoneblockType(rand), 2);
		world.setBlock(i + 6, j + 6, k + 4, Blocks.stonebrick, this.pickStoneblockType(rand), 2);
		world.setBlock(i + 6, j + 6, k + 5, this.pickDungeonBlock(rand), 0, 2);
		world.setBlock(i + 6, j + 6, k + 6, this.pickDungeonBlock(rand), 0, 2);
		world.setBlock(i + 6, j + 6, k + 7, Blocks.stonebrick, this.pickStoneblockType(rand), 2);
		world.setBlock(i + 6, j + 6, k + 8, Blocks.stonebrick, this.pickStoneblockType(rand), 2);
		world.setBlock(i + 6, j + 6, k + 9, this.pickDungeonBlock(rand), 0, 2);
		world.setBlock(i + 6, j + 6, k + 10, Blocks.stonebrick, this.pickStoneblockType(rand), 2);
		world.setBlock(i + 6, j + 6, k + 11, Blocks.stonebrick, this.pickStoneblockType(rand), 2);
		world.setBlock(i + 6, j + 6, k + 12, Blocks.stonebrick, this.pickStoneblockType(rand), 2);
		world.setBlock(i + 6, j + 6, k + 13, Blocks.stone_brick_stairs, 3, 2);
		world.setBlock(i + 6, j + 7, k + 3, Blocks.stonebrick, this.pickStoneblockType(rand), 2);
		world.setBlock(i + 6, j + 7, k + 4, Blocks.air, 0, 2);
		world.setBlock(i + 6, j + 7, k + 5, Blocks.air, 0, 2);
		world.setBlock(i + 6, j + 7, k + 6, Blocks.air, 0, 2);
		world.setBlock(i + 6, j + 7, k + 7, Blocks.air, 0, 2);
		world.setBlock(i + 6, j + 7, k + 8, Blocks.air, 0, 2);
		world.setBlock(i + 6, j + 7, k + 9, Blocks.air, 0, 2);
		world.setBlock(i + 6, j + 7, k + 10, Blocks.air, 0, 2);
		world.setBlock(i + 6, j + 7, k + 11, Blocks.air, 0, 2);
		world.setBlock(i + 6, j + 7, k + 12, Blocks.stonebrick, this.pickStoneblockType(rand), 2);
		world.setBlock(i + 6, j + 8, k + 3, Blocks.stonebrick, this.pickStoneblockType(rand), 2);
		world.setBlock(i + 6, j + 8, k + 4, Blocks.air, 0, 2);
		world.setBlock(i + 6, j + 8, k + 5, Blocks.air, 0, 2);
		world.setBlock(i + 6, j + 8, k + 6, Blocks.air, 0, 2);
		world.setBlock(i + 6, j + 8, k + 7, Blocks.air, 0, 2);
		world.setBlock(i + 6, j + 8, k + 8, Blocks.air, 0, 2);
		world.setBlock(i + 6, j + 8, k + 9, Blocks.air, 0, 2);
		world.setBlock(i + 6, j + 8, k + 10, Blocks.air, 0, 2);
		world.setBlock(i + 6, j + 8, k + 11, Blocks.air, 0, 2);
		world.setBlock(i + 6, j + 8, k + 12, Blocks.stonebrick, this.pickStoneblockType(rand), 2);
		world.setBlock(i + 6, j + 9, k + 3, Blocks.stonebrick, this.pickStoneblockType(rand), 2);
		world.setBlock(i + 6, j + 9, k + 4, Blocks.air, 0, 2);
		world.setBlock(i + 6, j + 9, k + 5, Blocks.air, 0, 2);
		world.setBlock(i + 6, j + 9, k + 6, Blocks.air, 0, 2);
		world.setBlock(i + 6, j + 9, k + 7, Blocks.air, 0, 2);
		world.setBlock(i + 6, j + 9, k + 8, Blocks.air, 0, 2);
		world.setBlock(i + 6, j + 9, k + 9, Blocks.air, 0, 2);
		world.setBlock(i + 6, j + 9, k + 10, Blocks.air, 0, 2);
		world.setBlock(i + 6, j + 9, k + 11, this.pickDungeonBlock(rand), 0, 2);
		world.setBlock(i + 6, j + 9, k + 12, Blocks.stonebrick, this.pickStoneblockType(rand), 2);
		world.setBlock(i + 6, j + 10, k + 3, Blocks.stonebrick, this.pickStoneblockType(rand), 2);
		world.setBlock(i + 6, j + 10, k + 4, Blocks.air, 0, 2);
		world.setBlock(i + 6, j + 10, k + 5, Blocks.air, 0, 2);
		world.setBlock(i + 6, j + 10, k + 6, Blocks.air, 0, 2);
		world.setBlock(i + 6, j + 10, k + 7, Blocks.air, 0, 2);
		world.setBlock(i + 6, j + 10, k + 8, Blocks.air, 0, 2);
		world.setBlock(i + 6, j + 10, k + 9, Blocks.air, 0, 2);
		world.setBlock(i + 6, j + 10, k + 10, Blocks.air, 0, 2);
		world.setBlock(i + 6, j + 10, k + 11, Blocks.air, 0, 2);
		world.setBlock(i + 6, j + 10, k + 12, Blocks.stonebrick, this.pickStoneblockType(rand), 2);
		world.setBlock(i + 6, j + 11, k + 3, Blocks.stonebrick, this.pickStoneblockType(rand), 2);
		world.setBlock(i + 6, j + 11, k + 4, Blocks.log, 0, 2);
		world.setBlock(i + 6, j + 11, k + 5, Blocks.planks, 1, 2);
		world.setBlock(i + 6, j + 11, k + 6, Blocks.planks, 1, 2);
		world.setBlock(i + 6, j + 11, k + 7, Blocks.log, 0, 2);
		world.setBlock(i + 6, j + 11, k + 8, Blocks.log, 0, 2);
		world.setBlock(i + 6, j + 11, k + 9, Blocks.planks, 1, 2);
		world.setBlock(i + 6, j + 11, k + 10, Blocks.planks, 1, 2);
		world.setBlock(i + 6, j + 11, k + 11, Blocks.log, 0, 2);
		world.setBlock(i + 6, j + 11, k + 12, Blocks.stonebrick, this.pickStoneblockType(rand), 2);
		world.setBlock(i + 6, j + 12, k + 4, Blocks.stonebrick, this.pickStoneblockType(rand), 2);
		world.setBlock(i + 6, j + 12, k + 5, Blocks.wool, 3, 2);
		world.setBlock(i + 6, j + 12, k + 6, Blocks.air, 0, 2);
		world.setBlock(i + 6, j + 12, k + 7, Blocks.air, 0, 2);
		world.setBlock(i + 6, j + 12, k + 8, Blocks.air, 0, 2);
		world.setBlock(i + 6, j + 12, k + 9, Blocks.air, 0, 2);
		world.setBlock(i + 6, j + 12, k + 10, Blocks.air, 0, 2);
		world.setBlock(i + 6, j + 12, k + 11, Blocks.stonebrick, this.pickStoneblockType(rand), 2);
		world.setBlock(i + 6, j + 13, k + 4, Blocks.stonebrick, this.pickStoneblockType(rand), 2);
		world.setBlock(i + 6, j + 13, k + 5, Blocks.wool, 3, 2);
		world.setBlock(i + 6, j + 13, k + 6, Blocks.air, 0, 2);
		world.setBlock(i + 6, j + 13, k + 7, Blocks.air, 0, 2);
		world.setBlock(i + 6, j + 13, k + 8, Blocks.air, 0, 2);
		world.setBlock(i + 6, j + 13, k + 9, Blocks.air, 0, 2);
		world.setBlock(i + 6, j + 13, k + 10, Blocks.air, 0, 2);
		world.setBlock(i + 6, j + 13, k + 11, Blocks.stonebrick, this.pickStoneblockType(rand), 2);
		world.setBlock(i + 6, j + 14, k + 4, Blocks.stonebrick, this.pickStoneblockType(rand), 2);
		world.setBlock(i + 6, j + 14, k + 6, Blocks.air, 0, 2);
		world.setBlock(i + 6, j + 14, k + 7, Blocks.air, 0, 2);
		world.setBlock(i + 6, j + 14, k + 8, Blocks.air, 0, 2);
		world.setBlock(i + 6, j + 14, k + 9, Blocks.air, 0, 2);
		world.setBlock(i + 6, j + 14, k + 10, Blocks.air, 0, 2);
		world.setBlock(i + 6, j + 14, k + 11, Blocks.stonebrick, this.pickStoneblockType(rand), 2);
		world.setBlock(i + 6, j + 15, k + 4, Blocks.stonebrick, this.pickStoneblockType(rand), 2);
		world.setBlock(i + 6, j + 15, k + 5, Blocks.air, 0, 2);
		world.setBlock(i + 6, j + 15, k + 6, Blocks.air, 0, 2);
		world.setBlock(i + 6, j + 15, k + 7, Blocks.air, 0, 2);
		world.setBlock(i + 6, j + 15, k + 8, Blocks.air, 0, 2);
		world.setBlock(i + 6, j + 15, k + 9, Blocks.air, 0, 2);
		world.setBlock(i + 6, j + 15, k + 10, Blocks.air, 0, 2);
		world.setBlock(i + 6, j + 15, k + 11, Blocks.stonebrick, this.pickStoneblockType(rand), 2);
		world.setBlock(i + 6, j + 16, k + 4, Blocks.stonebrick, this.pickStoneblockType(rand), 2);
		world.setBlock(i + 6, j + 16, k + 5, Blocks.air, 0, 2);
		world.setBlock(i + 6, j + 16, k + 6, Blocks.air, 0, 2);
		world.setBlock(i + 6, j + 16, k + 7, Blocks.air, 0, 2);
		world.setBlock(i + 6, j + 16, k + 8, Blocks.air, 0, 2);
		world.setBlock(i + 6, j + 16, k + 9, Blocks.air, 0, 2);
		world.setBlock(i + 6, j + 16, k + 10, Blocks.air, 0, 2);
		world.setBlock(i + 6, j + 16, k + 11, Blocks.stonebrick, this.pickStoneblockType(rand), 2);
		world.setBlock(i + 6, j + 17, k + 2, Blocks.wool, 11, 2);
		world.setBlock(i + 6, j + 17, k + 3, Blocks.wool, 11, 2);
		world.setBlock(i + 6, j + 17, k + 4, Blocks.stonebrick, this.pickStoneblockType(rand), 2);
		world.setBlock(i + 6, j + 17, k + 5, Blocks.air, 0, 2);
		world.setBlock(i + 6, j + 17, k + 6, Blocks.air, 0, 2);
		world.setBlock(i + 6, j + 17, k + 7, Blocks.air, 0, 2);
		world.setBlock(i + 6, j + 17, k + 8, Blocks.air, 0, 2);
		world.setBlock(i + 6, j + 17, k + 9, Blocks.air, 0, 2);
		world.setBlock(i + 6, j + 17, k + 10, Blocks.air, 0, 2);
		world.setBlock(i + 6, j + 17, k + 11, Blocks.stonebrick, this.pickStoneblockType(rand), 2);
		world.setBlock(i + 6, j + 17, k + 12, Blocks.wool, 11, 2);
		world.setBlock(i + 6, j + 17, k + 13, Blocks.wool, 11, 2);
		world.setBlock(i + 6, j + 18, k + 3, Blocks.wool, 11, 2);
		world.setBlock(i + 6, j + 18, k + 4, Blocks.wool, 11, 2);
		world.setBlock(i + 6, j + 18, k + 5, Blocks.air, 0, 2);
		world.setBlock(i + 6, j + 18, k + 6, Blocks.air, 0, 2);
		world.setBlock(i + 6, j + 18, k + 7, Blocks.air, 0, 2);
		world.setBlock(i + 6, j + 18, k + 8, Blocks.air, 0, 2);
		world.setBlock(i + 6, j + 18, k + 9, Blocks.air, 0, 2);
		world.setBlock(i + 6, j + 18, k + 10, Blocks.air, 0, 2);
		world.setBlock(i + 6, j + 18, k + 11, Blocks.wool, 11, 2);
		world.setBlock(i + 6, j + 18, k + 12, Blocks.wool, 11, 2);
		world.setBlock(i + 6, j + 19, k + 5, Blocks.wool, 11, 2);
		world.setBlock(i + 6, j + 19, k + 6, Blocks.wool, 11, 2);
		world.setBlock(i + 6, j + 19, k + 7, Blocks.air, 0, 2);
		world.setBlock(i + 6, j + 19, k + 8, Blocks.air, 0, 2);
		world.setBlock(i + 6, j + 19, k + 9, Blocks.wool, 11, 2);
		world.setBlock(i + 6, j + 19, k + 10, Blocks.wool, 11, 2);
		world.setBlock(i + 6, j + 20, k + 7, Blocks.wool, 11, 2);
		world.setBlock(i + 6, j + 20, k + 8, Blocks.wool, 11, 2);
		world.setBlock(i + 7, j + 0, k + 1, Blocks.stonebrick, this.pickStoneblockType(rand), 2);
		world.setBlock(i + 7, j + 0, k + 2, Blocks.planks, 2, 2);
		world.setBlock(i + 7, j + 0, k + 3, Blocks.planks, 1, 2);
		world.setBlock(i + 7, j + 0, k + 4, Blocks.planks, 2, 2);
		world.setBlock(i + 7, j + 0, k + 5, Blocks.planks, 2, 2);
		world.setBlock(i + 7, j + 0, k + 6, Blocks.planks, 0, 2);
		world.setBlock(i + 7, j + 0, k + 7, Blocks.log, 9, 2);
		world.setBlock(i + 7, j + 0, k + 8, Blocks.log, 9, 2);
		world.setBlock(i + 7, j + 0, k + 9, Blocks.planks, 0, 2);
		world.setBlock(i + 7, j + 0, k + 10, Blocks.planks, 2, 2);
		world.setBlock(i + 7, j + 0, k + 11, Blocks.planks, 2, 2);
		world.setBlock(i + 7, j + 0, k + 12, Blocks.planks, 1, 2);
		world.setBlock(i + 7, j + 0, k + 13, Blocks.planks, 2, 2);
		world.setBlock(i + 7, j + 0, k + 14, Blocks.stonebrick, this.pickStoneblockType(rand), 2);
		world.setBlock(i + 7, j + 1, k + 1, Blocks.stonebrick, this.pickStoneblockType(rand), 2);
		world.setBlock(i + 7, j + 1, k + 2, Blocks.wooden_slab, 2, 2);
		world.setBlock(i + 7, j + 1, k + 3, Blocks.air, 0, 2);
		world.setBlock(i + 7, j + 1, k + 4, Blocks.air, 0, 2);
		world.setBlock(i + 7, j + 1, k + 5, Blocks.stonebrick, 0, 2);
		world.setBlock(i + 7, j + 1, k + 6, Blocks.log, 1, 2);
		world.setBlock(i + 7, j + 1, k + 7, Blocks.log, 1, 2);
		world.setBlock(i + 7, j + 1, k + 8, Blocks.log, 1, 2);
		world.setBlock(i + 7, j + 1, k + 9, Blocks.log, 1, 2);
		world.setBlock(i + 7, j + 1, k + 10, Blocks.stonebrick, 0, 2);
		world.setBlock(i + 7, j + 1, k + 11, Blocks.air, 0, 2);
		world.setBlock(i + 7, j + 1, k + 12, Blocks.air, 0, 2);
		world.setBlock(i + 7, j + 1, k + 13, Blocks.wooden_slab, 2, 2);
		world.setBlock(i + 7, j + 1, k + 14, Blocks.stonebrick, this.pickStoneblockType(rand), 2);
		world.setBlock(i + 7, j + 2, k + 1, Blocks.stonebrick, this.pickStoneblockType(rand), 2);
		world.setBlock(i + 7, j + 2, k + 2, Blocks.wooden_slab, 9, 2);
		world.setBlock(i + 7, j + 2, k + 3, Blocks.air, 0, 2);
		world.setBlock(i + 7, j + 2, k + 4, Blocks.air, 0, 2);
		world.setBlock(i + 7, j + 2, k + 5, Blocks.air, 0, 2);
		world.setBlock(i + 7, j + 2, k + 6, Blocks.log, 1, 2);
		world.setBlock(i + 7, j + 2, k + 7, Blocks.oak_stairs, 0, 2);
		world.setBlock(i + 7, j + 2, k + 8, Blocks.oak_stairs, 0, 2);
		world.setBlock(i + 7, j + 2, k + 9, Blocks.log, 1, 2);
		world.setBlock(i + 7, j + 2, k + 10, Blocks.air, 0, 2);
		world.setBlock(i + 7, j + 2, k + 11, Blocks.air, 0, 2);
		world.setBlock(i + 7, j + 2, k + 12, Blocks.air, 0, 2);
		world.setBlock(i + 7, j + 2, k + 13, Blocks.wooden_slab, 9, 2);
		world.setBlock(i + 7, j + 2, k + 14, Blocks.stonebrick, this.pickStoneblockType(rand), 2);
		world.setBlock(i + 7, j + 3, k + 1, Blocks.stonebrick, this.pickStoneblockType(rand), 2);
		world.setBlock(i + 7, j + 3, k + 2, Blocks.bookshelf, 0, 2);
		world.setBlock(i + 7, j + 3, k + 3, Blocks.air, 0, 2);
		world.setBlock(i + 7, j + 3, k + 4, Blocks.air, 0, 2);
		world.setBlock(i + 7, j + 3, k + 5, Blocks.air, 0, 2);
		world.setBlock(i + 7, j + 3, k + 6, Blocks.log, 1, 2);
		world.setBlock(i + 7, j + 3, k + 7, Blocks.air, 0, 2);
		world.setBlock(i + 7, j + 3, k + 8, Blocks.air, 0, 2);
		world.setBlock(i + 7, j + 3, k + 9, Blocks.log, 1, 2);
		world.setBlock(i + 7, j + 3, k + 10, Blocks.air, 0, 2);
		world.setBlock(i + 7, j + 3, k + 11, Blocks.air, 0, 2);
		world.setBlock(i + 7, j + 3, k + 12, Blocks.air, 0, 2);
		world.setBlock(i + 7, j + 3, k + 13, Blocks.bookshelf, 0, 2);
		world.setBlock(i + 7, j + 3, k + 14, Blocks.stonebrick, this.pickStoneblockType(rand), 2);
		world.setBlock(i + 7, j + 4, k + 1, Blocks.stonebrick, this.pickStoneblockType(rand), 2);
		world.setBlock(i + 7, j + 4, k + 2, Blocks.air, 0, 2);
		world.setBlock(i + 7, j + 4, k + 3, Blocks.air, 0, 2);
		world.setBlock(i + 7, j + 4, k + 4, Blocks.air, 0, 2);
		world.setBlock(i + 7, j + 4, k + 5, Blocks.air, 0, 2);
		world.setBlock(i + 7, j + 4, k + 6, Blocks.log, 1, 2);
		world.setBlock(i + 7, j + 4, k + 9, Blocks.log, 1, 2);
		world.setBlock(i + 7, j + 4, k + 10, Blocks.air, 0, 2);
		world.setBlock(i + 7, j + 4, k + 11, Blocks.air, 0, 2);
		world.setBlock(i + 7, j + 4, k + 12, Blocks.air, 0, 2);
		world.setBlock(i + 7, j + 4, k + 13, Blocks.air, 0, 2);
		world.setBlock(i + 7, j + 4, k + 14, Blocks.stonebrick, this.pickStoneblockType(rand), 2);
		world.setBlock(i + 7, j + 5, k + 0, Blocks.stone_brick_stairs, 2, 2);
		world.setBlock(i + 7, j + 5, k + 1, Blocks.brick_block, 0, 2);
		world.setBlock(i + 7, j + 5, k + 2, Blocks.air, 0, 2);
		world.setBlock(i + 7, j + 5, k + 4, Blocks.air, 0, 2);
		world.setBlock(i + 7, j + 5, k + 5, Blocks.log, 9, 2);
		world.setBlock(i + 7, j + 5, k + 6, Blocks.log, 1, 2);
		world.setBlock(i + 7, j + 5, k + 9, Blocks.log, 1, 2);
		world.setBlock(i + 7, j + 5, k + 10, Blocks.log, 9, 2);
		world.setBlock(i + 7, j + 5, k + 11, Blocks.air, 0, 2);
		world.setBlock(i + 7, j + 5, k + 12, Blocks.air, 0, 2);
		world.setBlock(i + 7, j + 5, k + 13, Blocks.air, 0, 2);
		world.setBlock(i + 7, j + 5, k + 14, Blocks.brick_block, 0, 2);
		world.setBlock(i + 7, j + 5, k + 15, Blocks.stone_brick_stairs, 3, 2);
		world.setBlock(i + 7, j + 6, k + 1, Blocks.stone_brick_stairs, 2, 2);
		world.setBlock(i + 7, j + 6, k + 2, Blocks.brick_block, 0, 2);
		world.setBlock(i + 7, j + 6, k + 3, this.pickDungeonBlock(rand), 0, 2);
		world.setBlock(i + 7, j + 6, k + 4, this.pickDungeonBlock(rand), 0, 2);
		world.setBlock(i + 7, j + 6, k + 5, this.pickDungeonBlock(rand), 0, 2);
		world.setBlock(i + 7, j + 6, k + 6, Blocks.stonebrick, this.pickStoneblockType(rand), 2);
		world.setBlock(i + 7, j + 6, k + 9, this.pickDungeonBlock(rand), 0, 2);
		world.setBlock(i + 7, j + 6, k + 10, this.pickDungeonBlock(rand), 0, 2);
		world.setBlock(i + 7, j + 6, k + 11, this.pickDungeonBlock(rand), 0, 2);
		world.setBlock(i + 7, j + 6, k + 12, this.pickDungeonBlock(rand), 0, 2);
		world.setBlock(i + 7, j + 6, k + 13, Blocks.brick_block, 0, 2);
		world.setBlock(i + 7, j + 6, k + 14, Blocks.stone_brick_stairs, 3, 2);
		world.setBlock(i + 7, j + 7, k + 2, Blocks.stonebrick, this.pickStoneblockType(rand), 2);
		world.setBlock(i + 7, j + 7, k + 3, Blocks.air, 0, 2);
		world.setBlock(i + 7, j + 7, k + 4, Blocks.air, 0, 2);
		world.setBlock(i + 7, j + 7, k + 5, this.pickDungeonBlock(rand), 0, 2);
		world.setBlock(i + 7, j + 7, k + 6, Blocks.air, 0, 2);
		world.setBlock(i + 7, j + 7, k + 9, Blocks.air, 0, 2);
		world.setBlock(i + 7, j + 7, k + 11, Blocks.stonebrick, this.pickStoneblockType(rand), 2);
		world.setBlock(i + 7, j + 7, k + 12, Blocks.air, 0, 2);
		world.setBlock(i + 7, j + 7, k + 13, Blocks.stonebrick, this.pickStoneblockType(rand), 2);
		world.setBlock(i + 7, j + 8, k + 2, Blocks.stonebrick, this.pickStoneblockType(rand), 2);
		world.setBlock(i + 7, j + 8, k + 3, this.pickDungeonBlock(rand), 0, 2);
		world.setBlock(i + 7, j + 8, k + 4, Blocks.air, 0, 2);
		world.setBlock(i + 7, j + 8, k + 5, Blocks.air, 0, 2);
		world.setBlock(i + 7, j + 8, k + 6, Blocks.air, 0, 2);
		world.setBlock(i + 7, j + 8, k + 7, Blocks.air, 0, 2);
		world.setBlock(i + 7, j + 8, k + 8, Blocks.air, 0, 2);
		world.setBlock(i + 7, j + 8, k + 9, Blocks.air, 0, 2);
		world.setBlock(i + 7, j + 8, k + 11, Blocks.stonebrick, this.pickStoneblockType(rand), 2);
		world.setBlock(i + 7, j + 8, k + 12, Blocks.air, 0, 2);
		world.setBlock(i + 7, j + 8, k + 13, Blocks.stonebrick, this.pickStoneblockType(rand), 2);
		world.setBlock(i + 7, j + 9, k + 2, Blocks.stonebrick, this.pickStoneblockType(rand), 2);
		world.setBlock(i + 7, j + 9, k + 3, Blocks.air, 0, 2);
		world.setBlock(i + 7, j + 9, k + 4, Blocks.air, 0, 2);
		world.setBlock(i + 7, j + 9, k + 5, Blocks.air, 0, 2);
		world.setBlock(i + 7, j + 9, k + 6, Blocks.air, 0, 2);
		world.setBlock(i + 7, j + 9, k + 7, Blocks.air, 0, 2);
		world.setBlock(i + 7, j + 9, k + 8, Blocks.air, 0, 2);
		world.setBlock(i + 7, j + 9, k + 9, Blocks.air, 0, 2);
		world.setBlock(i + 7, j + 9, k + 11, Blocks.stonebrick, this.pickStoneblockType(rand), 2);
		world.setBlock(i + 7, j + 9, k + 12, Blocks.air, 0, 2);
		world.setBlock(i + 7, j + 9, k + 13, Blocks.stonebrick, this.pickStoneblockType(rand), 2);
		world.setBlock(i + 7, j + 10, k + 2, Blocks.stonebrick, this.pickStoneblockType(rand), 2);
		world.setBlock(i + 7, j + 10, k + 3, Blocks.air, 0, 2);
		world.setBlock(i + 7, j + 10, k + 4, Blocks.air, 0, 2);
		world.setBlock(i + 7, j + 10, k + 5, Blocks.air, 0, 2);
		world.setBlock(i + 7, j + 10, k + 6, Blocks.air, 0, 2);
		world.setBlock(i + 7, j + 10, k + 7, Blocks.air, 0, 2);
		world.setBlock(i + 7, j + 10, k + 8, Blocks.air, 0, 2);
		world.setBlock(i + 7, j + 10, k + 9, Blocks.air, 0, 2);
		world.setBlock(i + 7, j + 10, k + 11, Blocks.stonebrick, this.pickStoneblockType(rand), 2);
		world.setBlock(i + 7, j + 10, k + 12, Blocks.air, 0, 2);
		world.setBlock(i + 7, j + 10, k + 13, Blocks.stonebrick, this.pickStoneblockType(rand), 2);
		world.setBlock(i + 7, j + 11, k + 2, Blocks.stonebrick, this.pickStoneblockType(rand), 2);
		world.setBlock(i + 7, j + 11, k + 3, Blocks.log, 0, 2);
		world.setBlock(i + 7, j + 11, k + 4, Blocks.log, 0, 2);
		world.setBlock(i + 7, j + 11, k + 5, Blocks.planks, 1, 2);
		world.setBlock(i + 7, j + 11, k + 6, Blocks.log, 0, 2);
		world.setBlock(i + 7, j + 11, k + 7, Blocks.planks, 1, 2);
		world.setBlock(i + 7, j + 11, k + 8, Blocks.planks, 1, 2);
		world.setBlock(i + 7, j + 11, k + 9, Blocks.log, 0, 2);
		world.setBlock(i + 7, j + 11, k + 11, Blocks.air, 0, 2);
		world.setBlock(i + 7, j + 11, k + 12, Blocks.log, 0, 2);
		world.setBlock(i + 7, j + 11, k + 13, Blocks.stonebrick, this.pickStoneblockType(rand), 2);
		world.setBlock(i + 7, j + 12, k + 3, Blocks.stonebrick, this.pickStoneblockType(rand), 2);
		world.setBlock(i + 7, j + 12, k + 5, Blocks.air, 0, 2);
		world.setBlock(i + 7, j + 12, k + 6, Blocks.air, 0, 2);
		world.setBlock(i + 7, j + 12, k + 7, Blocks.air, 0, 2);
		world.setBlock(i + 7, j + 12, k + 8, Blocks.air, 0, 2);
		world.setBlock(i + 7, j + 12, k + 9, Blocks.air, 0, 2);
		world.setBlock(i + 7, j + 12, k + 10, Blocks.air, 0, 2);
		world.setBlock(i + 7, j + 12, k + 11, Blocks.air, 0, 2);
		world.setBlock(i + 7, j + 12, k + 12, Blocks.stonebrick, this.pickStoneblockType(rand), 2);
		world.setBlock(i + 7, j + 13, k + 3, Blocks.stonebrick, this.pickStoneblockType(rand), 2);
		world.setBlock(i + 7, j + 13, k + 4, Blocks.air, 0, 2);
		world.setBlock(i + 7, j + 13, k + 5, Blocks.air, 0, 2);
		world.setBlock(i + 7, j + 13, k + 6, Blocks.air, 0, 2);
		world.setBlock(i + 7, j + 13, k + 7, Blocks.air, 0, 2);
		world.setBlock(i + 7, j + 13, k + 8, Blocks.air, 0, 2);
		world.setBlock(i + 7, j + 13, k + 9, Blocks.air, 0, 2);
		world.setBlock(i + 7, j + 13, k + 10, Blocks.air, 0, 2);
		world.setBlock(i + 7, j + 13, k + 11, Blocks.air, 0, 2);
		world.setBlock(i + 7, j + 13, k + 12, Blocks.stonebrick, this.pickStoneblockType(rand), 2);
		world.setBlock(i + 7, j + 14, k + 3, Blocks.stonebrick, this.pickStoneblockType(rand), 2);
		world.setBlock(i + 7, j + 14, k + 4, Blocks.air, 0, 2);
		world.setBlock(i + 7, j + 14, k + 5, Blocks.air, 0, 2);
		world.setBlock(i + 7, j + 14, k + 6, Blocks.air, 0, 2);
		world.setBlock(i + 7, j + 14, k + 7, Blocks.air, 0, 2);
		world.setBlock(i + 7, j + 14, k + 8, Blocks.air, 0, 2);
		world.setBlock(i + 7, j + 14, k + 9, Blocks.air, 0, 2);
		world.setBlock(i + 7, j + 14, k + 10, Blocks.air, 0, 2);
		world.setBlock(i + 7, j + 14, k + 11, Blocks.air, 0, 2);
		world.setBlock(i + 7, j + 14, k + 12, Blocks.stonebrick, this.pickStoneblockType(rand), 2);
		world.setBlock(i + 7, j + 15, k + 3, Blocks.stonebrick, this.pickStoneblockType(rand), 2);
		world.setBlock(i + 7, j + 15, k + 4, Blocks.air, 0, 2);
		world.setBlock(i + 7, j + 15, k + 5, Blocks.air, 0, 2);
		world.setBlock(i + 7, j + 15, k + 6, Blocks.air, 0, 2);
		world.setBlock(i + 7, j + 15, k + 7, Blocks.air, 0, 2);
		world.setBlock(i + 7, j + 15, k + 8, Blocks.air, 0, 2);
		world.setBlock(i + 7, j + 15, k + 9, Blocks.air, 0, 2);
		world.setBlock(i + 7, j + 15, k + 10, Blocks.air, 0, 2);
		world.setBlock(i + 7, j + 15, k + 11, Blocks.air, 0, 2);
		world.setBlock(i + 7, j + 15, k + 12, Blocks.stonebrick, this.pickStoneblockType(rand), 2);
		world.setBlock(i + 7, j + 16, k + 3, Blocks.stonebrick, this.pickStoneblockType(rand), 2);
		world.setBlock(i + 7, j + 16, k + 4, Blocks.air, 0, 2);
		world.setBlock(i + 7, j + 16, k + 5, Blocks.air, 0, 2);
		world.setBlock(i + 7, j + 16, k + 6, Blocks.air, 0, 2);
		world.setBlock(i + 7, j + 16, k + 7, Blocks.air, 0, 2);
		world.setBlock(i + 7, j + 16, k + 8, Blocks.glowstone, 0, 2);
		world.setBlock(i + 7, j + 16, k + 9, Blocks.air, 0, 2);
		world.setBlock(i + 7, j + 16, k + 10, Blocks.air, 0, 2);
		world.setBlock(i + 7, j + 16, k + 11, Blocks.air, 0, 2);
		world.setBlock(i + 7, j + 16, k + 12, Blocks.stonebrick, this.pickStoneblockType(rand), 2);
		world.setBlock(i + 7, j + 17, k + 2, Blocks.wool, 11, 2);
		world.setBlock(i + 7, j + 17, k + 3, Blocks.stonebrick, this.pickStoneblockType(rand), 2);
		world.setBlock(i + 7, j + 17, k + 4, Blocks.air, 0, 2);
		world.setBlock(i + 7, j + 17, k + 5, Blocks.air, 0, 2);
		world.setBlock(i + 7, j + 17, k + 6, Blocks.air, 0, 2);
		world.setBlock(i + 7, j + 17, k + 7, Blocks.air, 0, 2);
		world.setBlock(i + 7, j + 17, k + 8, Blocks.fence, 0, 2);
		world.setBlock(i + 7, j + 17, k + 9, Blocks.air, 0, 2);
		world.setBlock(i + 7, j + 17, k + 10, Blocks.air, 0, 2);
		world.setBlock(i + 7, j + 17, k + 11, Blocks.air, 0, 2);
		world.setBlock(i + 7, j + 17, k + 12, Blocks.stonebrick, this.pickStoneblockType(rand), 2);
		world.setBlock(i + 7, j + 17, k + 13, Blocks.wool, 11, 2);
		world.setBlock(i + 7, j + 18, k + 3, Blocks.wool, 11, 2);
		world.setBlock(i + 7, j + 18, k + 4, Blocks.air, 0, 2);
		world.setBlock(i + 7, j + 18, k + 5, Blocks.air, 0, 2);
		world.setBlock(i + 7, j + 18, k + 6, Blocks.air, 0, 2);
		world.setBlock(i + 7, j + 18, k + 7, Blocks.air, 0, 2);
		world.setBlock(i + 7, j + 18, k + 8, Blocks.fence, 0, 2);
		world.setBlock(i + 7, j + 18, k + 9, Blocks.air, 0, 2);
		world.setBlock(i + 7, j + 18, k + 10, Blocks.air, 0, 2);
		world.setBlock(i + 7, j + 18, k + 11, Blocks.air, 0, 2);
		world.setBlock(i + 7, j + 18, k + 12, Blocks.wool, 11, 2);
		world.setBlock(i + 7, j + 19, k + 4, Blocks.wool, 11, 2);
		world.setBlock(i + 7, j + 19, k + 5, Blocks.wool, 11, 2);
		world.setBlock(i + 7, j + 19, k + 6, Blocks.air, 0, 2);
		world.setBlock(i + 7, j + 19, k + 7, Blocks.air, 0, 2);
		world.setBlock(i + 7, j + 19, k + 8, Blocks.fence, 0, 2);
		world.setBlock(i + 7, j + 19, k + 9, Blocks.air, 0, 2);
		world.setBlock(i + 7, j + 19, k + 10, Blocks.wool, 11, 2);
		world.setBlock(i + 7, j + 19, k + 11, Blocks.wool, 11, 2);
		world.setBlock(i + 7, j + 20, k + 6, Blocks.wool, 11, 2);
		world.setBlock(i + 7, j + 20, k + 7, Blocks.wool, 11, 2);
		world.setBlock(i + 7, j + 20, k + 8, Blocks.wool, 11, 2);
		world.setBlock(i + 7, j + 20, k + 9, Blocks.wool, 11, 2);
		world.setBlock(i + 8, j + 0, k + 1, Blocks.stonebrick, this.pickStoneblockType(rand), 2);
		world.setBlock(i + 8, j + 0, k + 2, Blocks.planks, 2, 2);
		world.setBlock(i + 8, j + 0, k + 3, Blocks.planks, 1, 2);
		world.setBlock(i + 8, j + 0, k + 4, Blocks.planks, 2, 2);
		world.setBlock(i + 8, j + 0, k + 5, Blocks.planks, 0, 2);
		world.setBlock(i + 8, j + 0, k + 6, Blocks.log, 5, 2);
		world.setBlock(i + 8, j + 0, k + 7, Blocks.log, 1, 2);
		world.setBlock(i + 8, j + 0, k + 8, Blocks.log, 1, 2);
		world.setBlock(i + 8, j + 0, k + 9, Blocks.log, 5, 2);
		world.setBlock(i + 8, j + 0, k + 10, Blocks.planks, 0, 2);
		world.setBlock(i + 8, j + 0, k + 11, Blocks.planks, 2, 2);
		world.setBlock(i + 8, j + 0, k + 12, Blocks.planks, 1, 2);
		world.setBlock(i + 8, j + 0, k + 13, Blocks.planks, 2, 2);
		world.setBlock(i + 8, j + 0, k + 14, Blocks.stonebrick, this.pickStoneblockType(rand), 2);
		world.setBlock(i + 8, j + 1, k + 1, Blocks.stonebrick, this.pickStoneblockType(rand), 2);
		world.setBlock(i + 8, j + 1, k + 2, Blocks.wooden_slab, 2, 2);
		world.setBlock(i + 8, j + 1, k + 3, Blocks.air, 0, 2);
		world.setBlock(i + 8, j + 1, k + 4, Blocks.air, 0, 2);
		world.setBlock(i + 8, j + 1, k + 5, Blocks.oak_stairs, 2, 2);
		world.setBlock(i + 8, j + 1, k + 6, Blocks.log, 1, 2);
		world.setBlock(i + 8, j + 1, k + 7, Blocks.planks, 2, 2);
		world.setBlock(i + 8, j + 1, k + 8, Blocks.planks, 2, 2);
		world.setBlock(i + 8, j + 1, k + 9, Blocks.log, 1, 2);
		world.setBlock(i + 8, j + 1, k + 10, Blocks.oak_stairs, 3, 2);
		world.setBlock(i + 8, j + 1, k + 11, Blocks.air, 0, 2);
		world.setBlock(i + 8, j + 1, k + 12, Blocks.air, 0, 2);
		world.setBlock(i + 8, j + 1, k + 13, Blocks.wooden_slab, 2, 2);
		world.setBlock(i + 8, j + 1, k + 14, Blocks.stonebrick, this.pickStoneblockType(rand), 2);
		world.setBlock(i + 8, j + 2, k + 1, Blocks.stonebrick, this.pickStoneblockType(rand), 2);
		world.setBlock(i + 8, j + 2, k + 2, Blocks.wooden_slab, 9, 2);
		world.setBlock(i + 8, j + 2, k + 3, Blocks.air, 0, 2);
		world.setBlock(i + 8, j + 2, k + 4, Blocks.air, 0, 2);
		world.setBlock(i + 8, j + 2, k + 5, Blocks.air, 0, 2);
		world.setBlock(i + 8, j + 2, k + 6, Blocks.oak_stairs, 2, 2);
		world.setBlock(i + 8, j + 2, k + 7, Blocks.planks, 2, 2);
		world.setBlock(i + 8, j + 2, k + 8, Blocks.planks, 2, 2);
		world.setBlock(i + 8, j + 2, k + 9, Blocks.oak_stairs, 3, 2);
		world.setBlock(i + 8, j + 2, k + 10, Blocks.air, 0, 2);
		world.setBlock(i + 8, j + 2, k + 11, Blocks.air, 0, 2);
		world.setBlock(i + 8, j + 2, k + 12, Blocks.air, 0, 2);
		world.setBlock(i + 8, j + 2, k + 13, Blocks.wooden_slab, 9, 2);
		world.setBlock(i + 8, j + 2, k + 14, Blocks.stonebrick, this.pickStoneblockType(rand), 2);
		world.setBlock(i + 8, j + 3, k + 1, Blocks.glass_pane, 0, 2);
		world.setBlock(i + 8, j + 3, k + 2, Blocks.air, 0, 2);
		world.setBlock(i + 8, j + 3, k + 3, Blocks.air, 0, 2);
		world.setBlock(i + 8, j + 3, k + 4, Blocks.air, 0, 2);
		world.setBlock(i + 8, j + 3, k + 5, Blocks.air, 0, 2);
		world.setBlock(i + 8, j + 3, k + 6, Blocks.air, 0, 2);
		world.setBlock(i + 8, j + 3, k + 7, Blocks.air, 0, 2);
		world.setBlock(i + 8, j + 3, k + 8, Blocks.air, 0, 2);
		world.setBlock(i + 8, j + 3, k + 9, Blocks.air, 0, 2);
		world.setBlock(i + 8, j + 3, k + 10, Blocks.air, 0, 2);
		world.setBlock(i + 8, j + 3, k + 11, Blocks.air, 0, 2);
		world.setBlock(i + 8, j + 3, k + 12, Blocks.air, 0, 2);
		world.setBlock(i + 8, j + 3, k + 13, Blocks.air, 0, 2);
		world.setBlock(i + 8, j + 3, k + 14, Blocks.glass_pane, 0, 2);
		world.setBlock(i + 8, j + 4, k + 1, Blocks.glass_pane, 0, 2);
		world.setBlock(i + 8, j + 4, k + 2, Blocks.air, 0, 2);
		world.setBlock(i + 8, j + 4, k + 3, Blocks.air, 0, 2);
		world.setBlock(i + 8, j + 4, k + 4, Blocks.air, 0, 2);
		world.setBlock(i + 8, j + 4, k + 5, Blocks.air, 0, 2);
		world.setBlock(i + 8, j + 4, k + 7, Blocks.air, 0, 2);
		world.setBlock(i + 8, j + 4, k + 8, Blocks.air, 0, 2);
		world.setBlock(i + 8, j + 4, k + 10, Blocks.air, 0, 2);
		world.setBlock(i + 8, j + 4, k + 11, Blocks.air, 0, 2);
		world.setBlock(i + 8, j + 4, k + 12, Blocks.air, 0, 2);
		world.setBlock(i + 8, j + 4, k + 13, Blocks.air, 0, 2);
		world.setBlock(i + 8, j + 4, k + 14, Blocks.glass_pane, 0, 2);
		world.setBlock(i + 8, j + 5, k + 0, Blocks.stone_brick_stairs, 2, 2);
		world.setBlock(i + 8, j + 5, k + 1, Blocks.stonebrick, this.pickStoneblockType(rand), 2);
		world.setBlock(i + 8, j + 5, k + 2, Blocks.air, 0, 2);
		world.setBlock(i + 8, j + 5, k + 3, Blocks.air, 0, 2);
		world.setBlock(i + 8, j + 5, k + 4, Blocks.air, 0, 2);
		world.setBlock(i + 8, j + 5, k + 5, Blocks.log, 5, 2);
		world.setBlock(i + 8, j + 5, k + 7, Blocks.air, 0, 2);
		world.setBlock(i + 8, j + 5, k + 8, Blocks.air, 0, 2);
		world.setBlock(i + 8, j + 5, k + 10, Blocks.log, 5, 2);
		world.setBlock(i + 8, j + 5, k + 11, Blocks.air, 0, 2);
		world.setBlock(i + 8, j + 5, k + 12, Blocks.air, 0, 2);
		world.setBlock(i + 8, j + 5, k + 13, Blocks.air, 0, 2);
		world.setBlock(i + 8, j + 5, k + 14, Blocks.stonebrick, this.pickStoneblockType(rand), 2);
		world.setBlock(i + 8, j + 5, k + 15, Blocks.stone_brick_stairs, 3, 2);
		world.setBlock(i + 8, j + 6, k + 1, Blocks.stone_brick_stairs, 2, 2);
		world.setBlock(i + 8, j + 6, k + 2, Blocks.stonebrick, this.pickStoneblockType(rand), 2);
		world.setBlock(i + 8, j + 6, k + 3, Blocks.stonebrick, this.pickStoneblockType(rand), 2);
		world.setBlock(i + 8, j + 6, k + 4, this.pickDungeonBlock(rand), 0, 2);
		world.setBlock(i + 8, j + 6, k + 5, this.pickDungeonBlock(rand), 0, 2);
		world.setBlock(i + 8, j + 6, k + 7, Blocks.wooden_slab, 9, 2);
		world.setBlock(i + 8, j + 6, k + 8, Blocks.wooden_slab, 9, 2);
		world.setBlock(i + 8, j + 6, k + 10, Blocks.stonebrick, this.pickStoneblockType(rand), 2);
		world.setBlock(i + 8, j + 6, k + 11, this.pickDungeonBlock(rand), 0, 2);
		world.setBlock(i + 8, j + 6, k + 12, this.pickDungeonBlock(rand), 0, 2);
		world.setBlock(i + 8, j + 6, k + 13, Blocks.stonebrick, this.pickStoneblockType(rand), 2);
		world.setBlock(i + 8, j + 6, k + 14, Blocks.stone_brick_stairs, 3, 2);
		world.setBlock(i + 8, j + 7, k + 2, Blocks.stonebrick, this.pickStoneblockType(rand), 2);
		world.setBlock(i + 8, j + 7, k + 3, Blocks.air, 0, 2);
		world.setBlock(i + 8, j + 7, k + 4, Blocks.air, 0, 2);
		world.setBlock(i + 8, j + 7, k + 5, Blocks.air, 0, 2);
		world.setBlock(i + 8, j + 7, k + 7, Blocks.stone_slab, 0, 2);
		world.setBlock(i + 8, j + 7, k + 8, Blocks.stone_slab, 0, 2);
		world.setBlock(i + 8, j + 7, k + 10, Blocks.air, 0, 2);
		world.setBlock(i + 8, j + 7, k + 11, Blocks.air, 0, 2);
		world.setBlock(i + 8, j + 7, k + 12, Blocks.air, 0, 2);
		world.setBlock(i + 8, j + 7, k + 13, Blocks.stonebrick, this.pickStoneblockType(rand), 2);
		world.setBlock(i + 8, j + 8, k + 2, Blocks.netherrack, 0, 2);
		world.setBlock(i + 8, j + 8, k + 3, Blocks.air, 0, 2);
		world.setBlock(i + 8, j + 8, k + 4, Blocks.air, 0, 2);
		world.setBlock(i + 8, j + 8, k + 5, Blocks.air, 0, 2);
		world.setBlock(i + 8, j + 8, k + 6, Blocks.air, 0, 2);
		world.setBlock(i + 8, j + 8, k + 7, Blocks.air, 0, 2);
		world.setBlock(i + 8, j + 8, k + 8, Blocks.air, 0, 2);
		world.setBlock(i + 8, j + 8, k + 9, Blocks.air, 0, 2);
		world.setBlock(i + 8, j + 8, k + 10, Blocks.air, 0, 2);
		world.setBlock(i + 8, j + 8, k + 11, Blocks.air, 0, 2);
		world.setBlock(i + 8, j + 8, k + 12, Blocks.stonebrick, this.pickStoneblockType(rand), 2);
		world.setBlock(i + 8, j + 8, k + 13, Blocks.netherrack, 0, 2);
		world.setBlock(i + 8, j + 9, k + 2, Blocks.netherrack, 0, 2);
		world.setBlock(i + 8, j + 9, k + 3, Blocks.air, 0, 2);
		world.setBlock(i + 8, j + 9, k + 4, Blocks.air, 0, 2);
		world.setBlock(i + 8, j + 9, k + 5, Blocks.air, 0, 2);
		world.setBlock(i + 8, j + 9, k + 6, Blocks.air, 0, 2);
		world.setBlock(i + 8, j + 9, k + 7, Blocks.air, 0, 2);
		world.setBlock(i + 8, j + 9, k + 8, Blocks.air, 0, 2);
		world.setBlock(i + 8, j + 9, k + 9, Blocks.air, 0, 2);
		world.setBlock(i + 8, j + 9, k + 10, Blocks.air, 0, 2);
		world.setBlock(i + 8, j + 9, k + 11, Blocks.air, 0, 2);
		world.setBlock(i + 8, j + 9, k + 12, Blocks.air, 0, 2);
		world.setBlock(i + 8, j + 9, k + 13, Blocks.netherrack, 0, 2);
		world.setBlock(i + 8, j + 10, k + 2, Blocks.stonebrick, this.pickStoneblockType(rand), 2);
		world.setBlock(i + 8, j + 10, k + 3, this.pickDungeonBlock(rand), 0, 2);
		world.setBlock(i + 8, j + 10, k + 4, Blocks.air, 0, 2);
		world.setBlock(i + 8, j + 10, k + 5, Blocks.air, 0, 2);
		world.setBlock(i + 8, j + 10, k + 6, Blocks.air, 0, 2);
		world.setBlock(i + 8, j + 10, k + 7, Blocks.air, 0, 2);
		world.setBlock(i + 8, j + 10, k + 8, Blocks.air, 0, 2);
		world.setBlock(i + 8, j + 10, k + 9, Blocks.air, 0, 2);
		world.setBlock(i + 8, j + 10, k + 10, Blocks.air, 0, 2);
		world.setBlock(i + 8, j + 10, k + 11, Blocks.air, 0, 2);
		world.setBlock(i + 8, j + 10, k + 12, Blocks.air, 0, 2);
		world.setBlock(i + 8, j + 10, k + 13, Blocks.stonebrick, this.pickStoneblockType(rand), 2);
		world.setBlock(i + 8, j + 11, k + 2, Blocks.stonebrick, this.pickStoneblockType(rand), 2);
		world.setBlock(i + 8, j + 11, k + 3, Blocks.log, 0, 2);
		world.setBlock(i + 8, j + 11, k + 4, Blocks.planks, 1, 2);
		world.setBlock(i + 8, j + 11, k + 5, Blocks.log, 0, 2);
		world.setBlock(i + 8, j + 11, k + 6, Blocks.planks, 1, 2);
		world.setBlock(i + 8, j + 11, k + 7, Blocks.log, 0, 2);
		world.setBlock(i + 8, j + 11, k + 8, Blocks.log, 0, 2);
		world.setBlock(i + 8, j + 11, k + 9, Blocks.planks, 1, 2);
		world.setBlock(i + 8, j + 11, k + 10, Blocks.log, 0, 2);
		world.setBlock(i + 8, j + 11, k + 11, Blocks.planks, 1, 2);
		world.setBlock(i + 8, j + 11, k + 12, Blocks.log, 0, 2);
		world.setBlock(i + 8, j + 11, k + 13, Blocks.stonebrick, this.pickStoneblockType(rand), 2);
		world.setBlock(i + 8, j + 12, k + 3, Blocks.stonebrick, this.pickStoneblockType(rand), 2);
		world.setBlock(i + 8, j + 12, k + 5, Blocks.air, 0, 2);
		world.setBlock(i + 8, j + 12, k + 6, Blocks.oak_stairs, 7, 2);
		world.setBlock(i + 8, j + 12, k + 9, Blocks.air, 0, 2);
		world.setBlock(i + 8, j + 12, k + 10, Blocks.air, 0, 2);
		world.setBlock(i + 8, j + 12, k + 12, Blocks.stonebrick, this.pickStoneblockType(rand), 2);
		world.setBlock(i + 8, j + 13, k + 3, Blocks.glass_pane, 0, 2);
		world.setBlock(i + 8, j + 13, k + 4, Blocks.air, 0, 2);
		world.setBlock(i + 8, j + 13, k + 5, Blocks.air, 0, 2);
		world.setBlock(i + 8, j + 13, k + 6, Blocks.air, 0, 2);
		world.setBlock(i + 8, j + 13, k + 7, Blocks.air, 0, 2);
		world.setBlock(i + 8, j + 13, k + 8, Blocks.air, 0, 2);
		world.setBlock(i + 8, j + 13, k + 9, Blocks.air, 0, 2);
		world.setBlock(i + 8, j + 13, k + 10, Blocks.air, 0, 2);
		world.setBlock(i + 8, j + 13, k + 11, Blocks.air, 0, 2);
		world.setBlock(i + 8, j + 13, k + 12, Blocks.stonebrick, this.pickStoneblockType(rand), 2);
		world.setBlock(i + 8, j + 14, k + 3, Blocks.glass_pane, 0, 2);
		world.setBlock(i + 8, j + 14, k + 4, Blocks.air, 0, 2);
		world.setBlock(i + 8, j + 14, k + 5, Blocks.air, 0, 2);
		world.setBlock(i + 8, j + 14, k + 6, Blocks.air, 0, 2);
		world.setBlock(i + 8, j + 14, k + 7, Blocks.air, 0, 2);
		world.setBlock(i + 8, j + 14, k + 8, Blocks.air, 0, 2);
		world.setBlock(i + 8, j + 14, k + 9, Blocks.air, 0, 2);
		world.setBlock(i + 8, j + 14, k + 10, Blocks.air, 0, 2);
		world.setBlock(i + 8, j + 14, k + 11, Blocks.air, 0, 2);
		world.setBlock(i + 8, j + 14, k + 12, Blocks.stonebrick, this.pickStoneblockType(rand), 2);
		world.setBlock(i + 8, j + 15, k + 3, Blocks.stonebrick, this.pickStoneblockType(rand), 2);
		world.setBlock(i + 8, j + 15, k + 4, Blocks.air, 0, 2);
		world.setBlock(i + 8, j + 15, k + 5, Blocks.air, 0, 2);
		world.setBlock(i + 8, j + 15, k + 6, Blocks.air, 0, 2);
		world.setBlock(i + 8, j + 15, k + 7, Blocks.air, 0, 2);
		world.setBlock(i + 8, j + 15, k + 8, Blocks.air, 0, 2);
		world.setBlock(i + 8, j + 15, k + 9, Blocks.air, 0, 2);
		world.setBlock(i + 8, j + 15, k + 10, Blocks.air, 0, 2);
		world.setBlock(i + 8, j + 15, k + 11, Blocks.air, 0, 2);
		world.setBlock(i + 8, j + 15, k + 12, Blocks.stonebrick, this.pickStoneblockType(rand), 2);
		world.setBlock(i + 8, j + 16, k + 3, Blocks.stonebrick, this.pickStoneblockType(rand), 2);
		world.setBlock(i + 8, j + 16, k + 4, Blocks.air, 0, 2);
		world.setBlock(i + 8, j + 16, k + 5, Blocks.air, 0, 2);
		world.setBlock(i + 8, j + 16, k + 6, Blocks.air, 0, 2);
		world.setBlock(i + 8, j + 16, k + 7, Blocks.air, 0, 2);
		world.setBlock(i + 8, j + 16, k + 8, Blocks.air, 0, 2);
		world.setBlock(i + 8, j + 16, k + 9, Blocks.air, 0, 2);
		world.setBlock(i + 8, j + 16, k + 10, Blocks.air, 0, 2);
		world.setBlock(i + 8, j + 16, k + 11, Blocks.air, 0, 2);
		world.setBlock(i + 8, j + 16, k + 12, Blocks.stonebrick, this.pickStoneblockType(rand), 2);
		world.setBlock(i + 8, j + 17, k + 2, Blocks.wool, 11, 2);
		world.setBlock(i + 8, j + 17, k + 3, Blocks.stonebrick, this.pickStoneblockType(rand), 2);
		world.setBlock(i + 8, j + 17, k + 4, Blocks.air, 0, 2);
		world.setBlock(i + 8, j + 17, k + 5, Blocks.air, 0, 2);
		world.setBlock(i + 8, j + 17, k + 6, Blocks.air, 0, 2);
		world.setBlock(i + 8, j + 17, k + 7, Blocks.air, 0, 2);
		world.setBlock(i + 8, j + 17, k + 8, Blocks.air, 0, 2);
		world.setBlock(i + 8, j + 17, k + 9, Blocks.air, 0, 2);
		world.setBlock(i + 8, j + 17, k + 10, Blocks.air, 0, 2);
		world.setBlock(i + 8, j + 17, k + 11, Blocks.air, 0, 2);
		world.setBlock(i + 8, j + 17, k + 12, Blocks.stonebrick, this.pickStoneblockType(rand), 2);
		world.setBlock(i + 8, j + 17, k + 13, Blocks.wool, 11, 2);
		world.setBlock(i + 8, j + 18, k + 3, Blocks.wool, 11, 2);
		world.setBlock(i + 8, j + 18, k + 4, Blocks.air, 0, 2);
		world.setBlock(i + 8, j + 18, k + 5, Blocks.air, 0, 2);
		world.setBlock(i + 8, j + 18, k + 6, Blocks.air, 0, 2);
		world.setBlock(i + 8, j + 18, k + 7, Blocks.air, 0, 2);
		world.setBlock(i + 8, j + 18, k + 8, Blocks.air, 0, 2);
		world.setBlock(i + 8, j + 18, k + 9, Blocks.air, 0, 2);
		world.setBlock(i + 8, j + 18, k + 10, Blocks.air, 0, 2);
		world.setBlock(i + 8, j + 18, k + 11, Blocks.air, 0, 2);
		world.setBlock(i + 8, j + 18, k + 12, Blocks.wool, 11, 2);
		world.setBlock(i + 8, j + 19, k + 4, Blocks.wool, 11, 2);
		world.setBlock(i + 8, j + 19, k + 5, Blocks.air, 0, 2);
		world.setBlock(i + 8, j + 19, k + 6, Blocks.air, 0, 2);
		world.setBlock(i + 8, j + 19, k + 7, Blocks.air, 0, 2);
		world.setBlock(i + 8, j + 19, k + 8, Blocks.air, 0, 2);
		world.setBlock(i + 8, j + 19, k + 9, Blocks.air, 0, 2);
		world.setBlock(i + 8, j + 19, k + 10, Blocks.air, 0, 2);
		world.setBlock(i + 8, j + 19, k + 11, Blocks.wool, 11, 2);
		world.setBlock(i + 8, j + 20, k + 5, Blocks.wool, 11, 2);
		world.setBlock(i + 8, j + 20, k + 6, Blocks.wool, 11, 2);
		world.setBlock(i + 8, j + 20, k + 7, Blocks.ice, 0, 2);
		world.setBlock(i + 8, j + 20, k + 8, Blocks.ice, 0, 2);
		world.setBlock(i + 8, j + 20, k + 9, Blocks.wool, 11, 2);
		world.setBlock(i + 8, j + 20, k + 10, Blocks.wool, 11, 2);
		world.setBlock(i + 8, j + 21, k + 7, Blocks.wool, 11, 2);
		world.setBlock(i + 8, j + 21, k + 8, Blocks.wool, 11, 2);
		world.setBlock(i + 9, j + 0, k + 1, Blocks.stonebrick, this.pickStoneblockType(rand), 2);
		world.setBlock(i + 9, j + 0, k + 2, Blocks.planks, 2, 2);
		world.setBlock(i + 9, j + 0, k + 3, Blocks.planks, 1, 2);
		world.setBlock(i + 9, j + 0, k + 4, Blocks.planks, 2, 2);
		world.setBlock(i + 9, j + 0, k + 5, Blocks.planks, 0, 2);
		world.setBlock(i + 9, j + 0, k + 6, Blocks.log, 5, 2);
		world.setBlock(i + 9, j + 0, k + 7, Blocks.log, 1, 2);
		world.setBlock(i + 9, j + 0, k + 8, Blocks.log, 1, 2);
		world.setBlock(i + 9, j + 0, k + 9, Blocks.log, 5, 2);
		world.setBlock(i + 9, j + 0, k + 10, Blocks.planks, 0, 2);
		world.setBlock(i + 9, j + 0, k + 11, Blocks.planks, 2, 2);
		world.setBlock(i + 9, j + 0, k + 12, Blocks.planks, 1, 2);
		world.setBlock(i + 9, j + 0, k + 13, Blocks.planks, 2, 2);
		world.setBlock(i + 9, j + 0, k + 14, Blocks.stonebrick, this.pickStoneblockType(rand), 2);
		world.setBlock(i + 9, j + 1, k + 1, Blocks.stonebrick, this.pickStoneblockType(rand), 2);
		world.setBlock(i + 9, j + 1, k + 2, Blocks.wooden_slab, 2, 2);
		world.setBlock(i + 9, j + 1, k + 3, Blocks.air, 0, 2);
		world.setBlock(i + 9, j + 1, k + 4, Blocks.air, 0, 2);
		world.setBlock(i + 9, j + 1, k + 5, Blocks.oak_stairs, 2, 2);
		world.setBlock(i + 9, j + 1, k + 6, Blocks.log, 1, 2);
		world.setBlock(i + 9, j + 1, k + 7, Blocks.planks, 2, 2);
		world.setBlock(i + 9, j + 1, k + 8, Blocks.planks, 2, 2);
		world.setBlock(i + 9, j + 1, k + 9, Blocks.log, 1, 2);
		world.setBlock(i + 9, j + 1, k + 10, Blocks.oak_stairs, 3, 2);
		world.setBlock(i + 9, j + 1, k + 11, Blocks.air, 0, 2);
		world.setBlock(i + 9, j + 1, k + 12, Blocks.air, 0, 2);
		world.setBlock(i + 9, j + 1, k + 13, Blocks.wooden_slab, 2, 2);
		world.setBlock(i + 9, j + 1, k + 14, Blocks.stonebrick, this.pickStoneblockType(rand), 2);
		world.setBlock(i + 9, j + 2, k + 1, Blocks.stonebrick, this.pickStoneblockType(rand), 2);
		world.setBlock(i + 9, j + 2, k + 2, Blocks.wooden_slab, 9, 2);
		world.setBlock(i + 9, j + 2, k + 3, Blocks.air, 0, 2);
		world.setBlock(i + 9, j + 2, k + 4, Blocks.air, 0, 2);
		world.setBlock(i + 9, j + 2, k + 5, Blocks.air, 0, 2);
		world.setBlock(i + 9, j + 2, k + 6, Blocks.oak_stairs, 2, 2);
		world.setBlock(i + 9, j + 2, k + 7, Blocks.planks, 2, 2);
		world.setBlock(i + 9, j + 2, k + 8, Blocks.planks, 2, 2);
		world.setBlock(i + 9, j + 2, k + 9, Blocks.oak_stairs, 3, 2);
		world.setBlock(i + 9, j + 2, k + 10, Blocks.air, 0, 2);
		world.setBlock(i + 9, j + 2, k + 11, Blocks.air, 0, 2);
		world.setBlock(i + 9, j + 2, k + 12, Blocks.air, 0, 2);
		world.setBlock(i + 9, j + 2, k + 13, Blocks.wooden_slab, 9, 2);
		world.setBlock(i + 9, j + 2, k + 14, Blocks.stonebrick, this.pickStoneblockType(rand), 2);
		world.setBlock(i + 9, j + 3, k + 1, Blocks.glass_pane, 0, 2);
		world.setBlock(i + 9, j + 3, k + 2, Blocks.air, 0, 2);
		world.setBlock(i + 9, j + 3, k + 3, Blocks.air, 0, 2);
		world.setBlock(i + 9, j + 3, k + 4, Blocks.air, 0, 2);
		world.setBlock(i + 9, j + 3, k + 5, Blocks.air, 0, 2);
		world.setBlock(i + 9, j + 3, k + 6, Blocks.air, 0, 2);
		world.setBlock(i + 9, j + 3, k + 7, Blocks.air, 0, 2);
		world.setBlock(i + 9, j + 3, k + 8, Blocks.air, 0, 2);
		world.setBlock(i + 9, j + 3, k + 9, Blocks.air, 0, 2);
		world.setBlock(i + 9, j + 3, k + 10, Blocks.air, 0, 2);
		world.setBlock(i + 9, j + 3, k + 11, Blocks.air, 0, 2);
		world.setBlock(i + 9, j + 3, k + 12, Blocks.air, 0, 2);
		world.setBlock(i + 9, j + 3, k + 13, Blocks.air, 0, 2);
		world.setBlock(i + 9, j + 3, k + 14, Blocks.glass_pane, 0, 2);
		world.setBlock(i + 9, j + 4, k + 1, Blocks.glass_pane, 0, 2);
		world.setBlock(i + 9, j + 4, k + 2, Blocks.air, 0, 2);
		world.setBlock(i + 9, j + 4, k + 3, Blocks.air, 0, 2);
		world.setBlock(i + 9, j + 4, k + 4, Blocks.air, 0, 2);
		world.setBlock(i + 9, j + 4, k + 5, Blocks.air, 0, 2);
		world.setBlock(i + 9, j + 4, k + 7, Blocks.air, 0, 2);
		world.setBlock(i + 9, j + 4, k + 8, Blocks.air, 0, 2);
		world.setBlock(i + 9, j + 4, k + 10, Blocks.air, 0, 2);
		world.setBlock(i + 9, j + 4, k + 11, Blocks.air, 0, 2);
		world.setBlock(i + 9, j + 4, k + 12, Blocks.air, 0, 2);
		world.setBlock(i + 9, j + 4, k + 13, Blocks.air, 0, 2);
		world.setBlock(i + 9, j + 4, k + 14, Blocks.glass_pane, 0, 2);
		world.setBlock(i + 9, j + 5, k + 0, Blocks.stone_brick_stairs, 2, 2);
		world.setBlock(i + 9, j + 5, k + 1, Blocks.stonebrick, this.pickStoneblockType(rand), 2);
		world.setBlock(i + 9, j + 5, k + 2, Blocks.air, 0, 2);
		world.setBlock(i + 9, j + 5, k + 3, Blocks.air, 0, 2);
		world.setBlock(i + 9, j + 5, k + 4, Blocks.air, 0, 2);
		world.setBlock(i + 9, j + 5, k + 5, Blocks.log, 5, 2);
		world.setBlock(i + 9, j + 5, k + 7, Blocks.air, 0, 2);
		world.setBlock(i + 9, j + 5, k + 8, Blocks.air, 0, 2);
		world.setBlock(i + 9, j + 5, k + 10, Blocks.log, 5, 2);
		world.setBlock(i + 9, j + 5, k + 11, Blocks.air, 0, 2);
		world.setBlock(i + 9, j + 5, k + 12, Blocks.air, 0, 2);
		world.setBlock(i + 9, j + 5, k + 13, Blocks.air, 0, 2);
		world.setBlock(i + 9, j + 5, k + 14, Blocks.stonebrick, this.pickStoneblockType(rand), 2);
		world.setBlock(i + 9, j + 5, k + 15, Blocks.stone_brick_stairs, 3, 2);
		world.setBlock(i + 9, j + 6, k + 1, Blocks.stone_brick_stairs, 2, 2);
		world.setBlock(i + 9, j + 6, k + 2, Blocks.stonebrick, this.pickStoneblockType(rand), 2);
		world.setBlock(i + 9, j + 6, k + 3, Blocks.stonebrick, this.pickStoneblockType(rand), 2);
		world.setBlock(i + 9, j + 6, k + 4, this.pickDungeonBlock(rand), 0, 2);
		world.setBlock(i + 9, j + 6, k + 5, this.pickDungeonBlock(rand), 0, 2);
		world.setBlock(i + 9, j + 6, k + 7, Blocks.wooden_slab, 9, 2);
		world.setBlock(i + 9, j + 6, k + 8, Blocks.wooden_slab, 9, 2);
		world.setBlock(i + 9, j + 6, k + 10, this.pickDungeonBlock(rand), 0, 2);
		world.setBlock(i + 9, j + 6, k + 11, this.pickDungeonBlock(rand), 0, 2);
		world.setBlock(i + 9, j + 6, k + 12, this.pickDungeonBlock(rand), 0, 2);
		world.setBlock(i + 9, j + 6, k + 13, Blocks.stonebrick, this.pickStoneblockType(rand), 2);
		world.setBlock(i + 9, j + 6, k + 14, Blocks.stone_brick_stairs, 3, 2);
		world.setBlock(i + 9, j + 7, k + 2, Blocks.stonebrick, this.pickStoneblockType(rand), 2);
		world.setBlock(i + 9, j + 7, k + 3, Blocks.air, 0, 2);
		world.setBlock(i + 9, j + 7, k + 4, Blocks.stonebrick, this.pickStoneblockType(rand), 2);
		world.setBlock(i + 9, j + 7, k + 5, Blocks.air, 0, 2);
		world.setBlock(i + 9, j + 7, k + 7, Blocks.stone_slab, 0, 2);
		world.setBlock(i + 9, j + 7, k + 8, Blocks.stone_slab, 0, 2);
		world.setBlock(i + 9, j + 7, k + 10, Blocks.air, 0, 2);
		world.setBlock(i + 9, j + 7, k + 11, Blocks.air, 0, 2);
		world.setBlock(i + 9, j + 7, k + 12, this.pickDungeonBlock(rand), 0, 2);
		world.setBlock(i + 9, j + 7, k + 13, Blocks.stonebrick, this.pickStoneblockType(rand), 2);
		world.setBlock(i + 9, j + 8, k + 2, Blocks.netherrack, 0, 2);
		world.setBlock(i + 9, j + 8, k + 3, Blocks.air, 0, 2);
		world.setBlock(i + 9, j + 8, k + 4, Blocks.air, 0, 2);
		world.setBlock(i + 9, j + 8, k + 5, Blocks.air, 0, 2);
		world.setBlock(i + 9, j + 8, k + 6, Blocks.air, 0, 2);
		world.setBlock(i + 9, j + 8, k + 7, Blocks.air, 0, 2);
		world.setBlock(i + 9, j + 8, k + 8, Blocks.air, 0, 2);
		world.setBlock(i + 9, j + 8, k + 9, Blocks.air, 0, 2);
		world.setBlock(i + 9, j + 8, k + 10, Blocks.air, 0, 2);
		world.setBlock(i + 9, j + 8, k + 11, Blocks.air, 0, 2);
		world.setBlock(i + 9, j + 8, k + 12, Blocks.air, 0, 2);
		world.setBlock(i + 9, j + 8, k + 13, Blocks.netherrack, 0, 2);
		world.setBlock(i + 9, j + 9, k + 2, Blocks.netherrack, 0, 2);
		world.setBlock(i + 9, j + 9, k + 3, Blocks.air, 0, 2);
		world.setBlock(i + 9, j + 9, k + 4, Blocks.air, 0, 2);
		world.setBlock(i + 9, j + 9, k + 5, Blocks.air, 0, 2);
		world.setBlock(i + 9, j + 9, k + 6, Blocks.air, 0, 2);
		world.setBlock(i + 9, j + 9, k + 7, Blocks.air, 0, 2);
		world.setBlock(i + 9, j + 9, k + 8, Blocks.air, 0, 2);
		world.setBlock(i + 9, j + 9, k + 9, Blocks.air, 0, 2);
		world.setBlock(i + 9, j + 9, k + 10, Blocks.air, 0, 2);
		world.setBlock(i + 9, j + 9, k + 11, Blocks.air, 0, 2);
		world.setBlock(i + 9, j + 9, k + 12, this.pickDungeonBlock(rand), 0, 2);
		world.setBlock(i + 9, j + 9, k + 13, Blocks.netherrack, 0, 2);
		world.setBlock(i + 9, j + 10, k + 2, Blocks.stonebrick, this.pickStoneblockType(rand), 2);
		world.setBlock(i + 9, j + 10, k + 3, Blocks.air, 0, 2);
		world.setBlock(i + 9, j + 10, k + 4, Blocks.air, 0, 2);
		world.setBlock(i + 9, j + 10, k + 5, Blocks.air, 0, 2);
		world.setBlock(i + 9, j + 10, k + 6, Blocks.air, 0, 2);
		world.setBlock(i + 9, j + 10, k + 7, Blocks.air, 0, 2);
		world.setBlock(i + 9, j + 10, k + 8, Blocks.air, 0, 2);
		world.setBlock(i + 9, j + 10, k + 9, Blocks.air, 0, 2);
		world.setBlock(i + 9, j + 10, k + 10, Blocks.air, 0, 2);
		world.setBlock(i + 9, j + 10, k + 11, Blocks.air, 0, 2);
		world.setBlock(i + 9, j + 10, k + 12, Blocks.stonebrick, this.pickStoneblockType(rand), 2);
		world.setBlock(i + 9, j + 10, k + 13, Blocks.stonebrick, this.pickStoneblockType(rand), 2);
		world.setBlock(i + 9, j + 11, k + 2, Blocks.stonebrick, this.pickStoneblockType(rand), 2);
		world.setBlock(i + 9, j + 11, k + 3, Blocks.log, 0, 2);
		world.setBlock(i + 9, j + 11, k + 4, Blocks.planks, 1, 2);
		world.setBlock(i + 9, j + 11, k + 5, Blocks.log, 0, 2);
		world.setBlock(i + 9, j + 11, k + 6, Blocks.planks, 1, 2);
		world.setBlock(i + 9, j + 11, k + 7, Blocks.log, 0, 2);
		world.setBlock(i + 9, j + 11, k + 8, Blocks.log, 0, 2);
		world.setBlock(i + 9, j + 11, k + 9, Blocks.planks, 1, 2);
		world.setBlock(i + 9, j + 11, k + 10, Blocks.log, 0, 2);
		world.setBlock(i + 9, j + 11, k + 11, Blocks.planks, 1, 2);
		world.setBlock(i + 9, j + 11, k + 12, Blocks.log, 0, 2);
		world.setBlock(i + 9, j + 11, k + 13, Blocks.stonebrick, this.pickStoneblockType(rand), 2);
		world.setBlock(i + 9, j + 12, k + 3, Blocks.stonebrick, this.pickStoneblockType(rand), 2);
		world.setBlock(i + 9, j + 12, k + 5, Blocks.air, 0, 2);
		world.setBlock(i + 9, j + 12, k + 6, Blocks.oak_stairs, 7, 2);
		world.setBlock(i + 9, j + 12, k + 9, Blocks.air, 0, 2);
		world.setBlock(i + 9, j + 12, k + 10, Blocks.air, 0, 2);
		world.setBlock(i + 9, j + 12, k + 12, Blocks.stonebrick, this.pickStoneblockType(rand), 2);
		world.setBlock(i + 9, j + 13, k + 3, Blocks.glass_pane, 0, 2);
		world.setBlock(i + 9, j + 13, k + 4, Blocks.air, 0, 2);
		world.setBlock(i + 9, j + 13, k + 5, Blocks.air, 0, 2);
		world.setBlock(i + 9, j + 13, k + 6, Blocks.air, 0, 2);
		world.setBlock(i + 9, j + 13, k + 7, Blocks.air, 0, 2);
		world.setBlock(i + 9, j + 13, k + 8, Blocks.air, 0, 2);
		world.setBlock(i + 9, j + 13, k + 9, Blocks.air, 0, 2);
		world.setBlock(i + 9, j + 13, k + 10, Blocks.air, 0, 2);
		world.setBlock(i + 9, j + 13, k + 11, Blocks.air, 0, 2);
		world.setBlock(i + 9, j + 13, k + 12, Blocks.stonebrick, this.pickStoneblockType(rand), 2);
		world.setBlock(i + 9, j + 14, k + 3, Blocks.glass_pane, 0, 2);
		world.setBlock(i + 9, j + 14, k + 4, Blocks.air, 0, 2);
		world.setBlock(i + 9, j + 14, k + 5, Blocks.air, 0, 2);
		world.setBlock(i + 9, j + 14, k + 6, Blocks.air, 0, 2);
		world.setBlock(i + 9, j + 14, k + 7, Blocks.air, 0, 2);
		world.setBlock(i + 9, j + 14, k + 8, Blocks.air, 0, 2);
		world.setBlock(i + 9, j + 14, k + 9, Blocks.air, 0, 2);
		world.setBlock(i + 9, j + 14, k + 10, Blocks.air, 0, 2);
		world.setBlock(i + 9, j + 14, k + 11, Blocks.air, 0, 2);
		world.setBlock(i + 9, j + 14, k + 12, Blocks.stonebrick, this.pickStoneblockType(rand), 2);
		world.setBlock(i + 9, j + 15, k + 3, Blocks.stonebrick, this.pickStoneblockType(rand), 2);
		world.setBlock(i + 9, j + 15, k + 4, Blocks.air, 0, 2);
		world.setBlock(i + 9, j + 15, k + 5, Blocks.air, 0, 2);
		world.setBlock(i + 9, j + 15, k + 6, Blocks.air, 0, 2);
		world.setBlock(i + 9, j + 15, k + 7, Blocks.air, 0, 2);
		world.setBlock(i + 9, j + 15, k + 8, Blocks.air, 0, 2);
		world.setBlock(i + 9, j + 15, k + 9, Blocks.air, 0, 2);
		world.setBlock(i + 9, j + 15, k + 10, Blocks.air, 0, 2);
		world.setBlock(i + 9, j + 15, k + 11, Blocks.air, 0, 2);
		world.setBlock(i + 9, j + 15, k + 12, Blocks.stonebrick, this.pickStoneblockType(rand), 2);
		world.setBlock(i + 9, j + 16, k + 3, Blocks.stonebrick, this.pickStoneblockType(rand), 2);
		world.setBlock(i + 9, j + 16, k + 4, Blocks.air, 0, 2);
		world.setBlock(i + 9, j + 16, k + 5, Blocks.air, 0, 2);
		world.setBlock(i + 9, j + 16, k + 6, Blocks.air, 0, 2);
		world.setBlock(i + 9, j + 16, k + 7, Blocks.air, 0, 2);
		world.setBlock(i + 9, j + 16, k + 8, Blocks.air, 0, 2);
		world.setBlock(i + 9, j + 16, k + 9, Blocks.air, 0, 2);
		world.setBlock(i + 9, j + 16, k + 10, Blocks.air, 0, 2);
		world.setBlock(i + 9, j + 16, k + 11, Blocks.air, 0, 2);
		world.setBlock(i + 9, j + 16, k + 12, Blocks.stonebrick, this.pickStoneblockType(rand), 2);
		world.setBlock(i + 9, j + 17, k + 2, Blocks.wool, 11, 2);
		world.setBlock(i + 9, j + 17, k + 3, Blocks.stonebrick, this.pickStoneblockType(rand), 2);
		world.setBlock(i + 9, j + 17, k + 4, Blocks.air, 0, 2);
		world.setBlock(i + 9, j + 17, k + 5, Blocks.air, 0, 2);
		world.setBlock(i + 9, j + 17, k + 6, Blocks.air, 0, 2);
		world.setBlock(i + 9, j + 17, k + 7, Blocks.air, 0, 2);
		world.setBlock(i + 9, j + 17, k + 8, Blocks.air, 0, 2);
		world.setBlock(i + 9, j + 17, k + 9, Blocks.air, 0, 2);
		world.setBlock(i + 9, j + 17, k + 10, Blocks.air, 0, 2);
		world.setBlock(i + 9, j + 17, k + 11, Blocks.air, 0, 2);
		world.setBlock(i + 9, j + 17, k + 12, Blocks.stonebrick, this.pickStoneblockType(rand), 2);
		world.setBlock(i + 9, j + 17, k + 13, Blocks.wool, 11, 2);
		world.setBlock(i + 9, j + 18, k + 3, Blocks.wool, 11, 2);
		world.setBlock(i + 9, j + 18, k + 4, Blocks.air, 0, 2);
		world.setBlock(i + 9, j + 18, k + 5, Blocks.air, 0, 2);
		world.setBlock(i + 9, j + 18, k + 6, Blocks.air, 0, 2);
		world.setBlock(i + 9, j + 18, k + 7, Blocks.air, 0, 2);
		world.setBlock(i + 9, j + 18, k + 8, Blocks.air, 0, 2);
		world.setBlock(i + 9, j + 18, k + 9, Blocks.air, 0, 2);
		world.setBlock(i + 9, j + 18, k + 10, Blocks.air, 0, 2);
		world.setBlock(i + 9, j + 18, k + 11, Blocks.air, 0, 2);
		world.setBlock(i + 9, j + 18, k + 12, Blocks.wool, 11, 2);
		world.setBlock(i + 9, j + 19, k + 4, Blocks.wool, 11, 2);
		world.setBlock(i + 9, j + 19, k + 5, Blocks.air, 0, 2);
		world.setBlock(i + 9, j + 19, k + 6, Blocks.air, 0, 2);
		world.setBlock(i + 9, j + 19, k + 7, Blocks.air, 0, 2);
		world.setBlock(i + 9, j + 19, k + 8, Blocks.air, 0, 2);
		world.setBlock(i + 9, j + 19, k + 9, Blocks.air, 0, 2);
		world.setBlock(i + 9, j + 19, k + 10, Blocks.air, 0, 2);
		world.setBlock(i + 9, j + 19, k + 11, Blocks.wool, 11, 2);
		world.setBlock(i + 9, j + 20, k + 5, Blocks.wool, 11, 2);
		world.setBlock(i + 9, j + 20, k + 6, Blocks.wool, 11, 2);
		world.setBlock(i + 9, j + 20, k + 7, Blocks.ice, 0, 2);
		world.setBlock(i + 9, j + 20, k + 8, Blocks.ice, 0, 2);
		world.setBlock(i + 9, j + 20, k + 9, Blocks.wool, 11, 2);
		world.setBlock(i + 9, j + 20, k + 10, Blocks.wool, 11, 2);
		world.setBlock(i + 9, j + 21, k + 7, Blocks.wool, 11, 2);
		world.setBlock(i + 9, j + 21, k + 8, Blocks.wool, 11, 2);
		world.setBlock(i + 10, j + 0, k + 1, Blocks.stonebrick, this.pickStoneblockType(rand), 2);
		world.setBlock(i + 10, j + 0, k + 2, Blocks.planks, 2, 2);
		world.setBlock(i + 10, j + 0, k + 3, Blocks.planks, 1, 2);
		world.setBlock(i + 10, j + 0, k + 4, Blocks.planks, 2, 2);
		world.setBlock(i + 10, j + 0, k + 5, Blocks.planks, 2, 2);
		world.setBlock(i + 10, j + 0, k + 6, Blocks.planks, 0, 2);
		world.setBlock(i + 10, j + 0, k + 7, Blocks.log, 9, 2);
		world.setBlock(i + 10, j + 0, k + 8, Blocks.log, 9, 2);
		world.setBlock(i + 10, j + 0, k + 9, Blocks.planks, 0, 2);
		world.setBlock(i + 10, j + 0, k + 10, Blocks.planks, 2, 2);
		world.setBlock(i + 10, j + 0, k + 11, Blocks.planks, 2, 2);
		world.setBlock(i + 10, j + 0, k + 12, Blocks.planks, 1, 2);
		world.setBlock(i + 10, j + 0, k + 13, Blocks.planks, 2, 2);
		world.setBlock(i + 10, j + 0, k + 14, Blocks.stonebrick, this.pickStoneblockType(rand), 2);
		world.setBlock(i + 10, j + 1, k + 1, Blocks.stonebrick, this.pickStoneblockType(rand), 2);
		world.setBlock(i + 10, j + 1, k + 2, Blocks.wooden_slab, 2, 2);
		world.setBlock(i + 10, j + 1, k + 3, Blocks.air, 0, 2);
		world.setBlock(i + 10, j + 1, k + 4, Blocks.air, 0, 2);
		world.setBlock(i + 10, j + 1, k + 5, Blocks.stonebrick, 0, 2);
		world.setBlock(i + 10, j + 1, k + 6, Blocks.log, 1, 2);
		world.setBlock(i + 10, j + 1, k + 7, Blocks.log, 1, 2);
		world.setBlock(i + 10, j + 1, k + 8, Blocks.log, 1, 2);
		world.setBlock(i + 10, j + 1, k + 9, Blocks.log, 1, 2);
		world.setBlock(i + 10, j + 1, k + 10, Blocks.stonebrick, 0, 2);
		world.setBlock(i + 10, j + 1, k + 11, Blocks.air, 0, 2);
		world.setBlock(i + 10, j + 1, k + 12, Blocks.air, 0, 2);
		world.setBlock(i + 10, j + 1, k + 13, Blocks.wooden_slab, 2, 2);
		world.setBlock(i + 10, j + 1, k + 14, Blocks.stonebrick, this.pickStoneblockType(rand), 2);
		world.setBlock(i + 10, j + 2, k + 1, Blocks.stonebrick, this.pickStoneblockType(rand), 2);
		world.setBlock(i + 10, j + 2, k + 2, Blocks.wooden_slab, 9, 2);
		world.setBlock(i + 10, j + 2, k + 3, Blocks.air, 0, 2);
		world.setBlock(i + 10, j + 2, k + 4, Blocks.air, 0, 2);
		world.setBlock(i + 10, j + 2, k + 5, Blocks.air, 0, 2);
		world.setBlock(i + 10, j + 2, k + 6, Blocks.log, 1, 2);
		world.setBlock(i + 10, j + 2, k + 7, Blocks.oak_stairs, 1, 2);
		world.setBlock(i + 10, j + 2, k + 8, Blocks.oak_stairs, 1, 2);
		world.setBlock(i + 10, j + 2, k + 9, Blocks.log, 1, 2);
		world.setBlock(i + 10, j + 2, k + 10, Blocks.air, 0, 2);
		world.setBlock(i + 10, j + 2, k + 11, Blocks.air, 0, 2);
		world.setBlock(i + 10, j + 2, k + 12, Blocks.air, 0, 2);
		world.setBlock(i + 10, j + 2, k + 13, Blocks.wooden_slab, 9, 2);
		world.setBlock(i + 10, j + 2, k + 14, Blocks.stonebrick, this.pickStoneblockType(rand), 2);
		world.setBlock(i + 10, j + 3, k + 1, Blocks.stonebrick, this.pickStoneblockType(rand), 2);
		world.setBlock(i + 10, j + 3, k + 2, Blocks.bookshelf, 0, 2);
		world.setBlock(i + 10, j + 3, k + 3, Blocks.air, 0, 2);
		world.setBlock(i + 10, j + 3, k + 4, Blocks.air, 0, 2);
		world.setBlock(i + 10, j + 3, k + 5, Blocks.air, 0, 2);
		world.setBlock(i + 10, j + 3, k + 6, Blocks.log, 1, 2);
		world.setBlock(i + 10, j + 3, k + 7, Blocks.air, 0, 2);
		world.setBlock(i + 10, j + 3, k + 8, Blocks.air, 0, 2);
		world.setBlock(i + 10, j + 3, k + 9, Blocks.log, 1, 2);
		world.setBlock(i + 10, j + 3, k + 10, Blocks.air, 0, 2);
		world.setBlock(i + 10, j + 3, k + 11, Blocks.air, 0, 2);
		world.setBlock(i + 10, j + 3, k + 12, Blocks.air, 0, 2);
		world.setBlock(i + 10, j + 3, k + 13, Blocks.bookshelf, 0, 2);
		world.setBlock(i + 10, j + 3, k + 14, Blocks.stonebrick, this.pickStoneblockType(rand), 2);
		world.setBlock(i + 10, j + 4, k + 1, Blocks.stonebrick, this.pickStoneblockType(rand), 2);
		world.setBlock(i + 10, j + 4, k + 2, Blocks.air, 0, 2);
		world.setBlock(i + 10, j + 4, k + 3, Blocks.air, 0, 2);
		world.setBlock(i + 10, j + 4, k + 4, Blocks.air, 0, 2);
		world.setBlock(i + 10, j + 4, k + 5, Blocks.air, 0, 2);
		world.setBlock(i + 10, j + 4, k + 6, Blocks.log, 1, 2);
		world.setBlock(i + 10, j + 4, k + 9, Blocks.log, 1, 2);
		world.setBlock(i + 10, j + 4, k + 10, Blocks.air, 0, 2);
		world.setBlock(i + 10, j + 4, k + 11, Blocks.air, 0, 2);
		world.setBlock(i + 10, j + 4, k + 12, Blocks.air, 0, 2);
		world.setBlock(i + 10, j + 4, k + 13, Blocks.air, 0, 2);
		world.setBlock(i + 10, j + 4, k + 14, Blocks.stonebrick, this.pickStoneblockType(rand), 2);
		world.setBlock(i + 10, j + 5, k + 0, Blocks.stone_brick_stairs, 2, 2);
		world.setBlock(i + 10, j + 5, k + 1, Blocks.brick_block, 0, 2);
		world.setBlock(i + 10, j + 5, k + 2, Blocks.air, 0, 2);
		world.setBlock(i + 10, j + 5, k + 3, Blocks.air, 0, 2);
		world.setBlock(i + 10, j + 5, k + 4, Blocks.air, 0, 2);
		world.setBlock(i + 10, j + 5, k + 5, Blocks.log, 9, 2);
		world.setBlock(i + 10, j + 5, k + 6, Blocks.log, 1, 2);
		world.setBlock(i + 10, j + 5, k + 9, Blocks.log, 1, 2);
		world.setBlock(i + 10, j + 5, k + 10, Blocks.log, 9, 2);
		world.setBlock(i + 10, j + 5, k + 11, Blocks.air, 0, 2);
		world.setBlock(i + 10, j + 5, k + 12, Blocks.air, 0, 2);
		world.setBlock(i + 10, j + 5, k + 13, Blocks.air, 0, 2);
		world.setBlock(i + 10, j + 5, k + 14, Blocks.brick_block, 0, 2);
		world.setBlock(i + 10, j + 5, k + 15, Blocks.stone_brick_stairs, 3, 2);
		world.setBlock(i + 10, j + 6, k + 1, Blocks.stone_brick_stairs, 2, 2);
		world.setBlock(i + 10, j + 6, k + 2, Blocks.brick_block, 0, 2);
