/*
 * ** MADE BY MITHION'S .SCHEMATIC TO JAVA CONVERTING TOOL v1.6 ***
 */

package net.arcticraft.world.gen;

import java.util.Random;

import net.arcticraft.block.ACBlocks;
import net.arcticraft.entities.passive.EntityEskimo;
import net.arcticraft.entities.passive.EntityEskimoChef;
import net.arcticraft.entities.passive.EntityEskimoChief;
import net.arcticraft.entities.passive.EntityEskimoHunter;
import net.arcticraft.entities.passive.EntityEskimoTrader;
import net.arcticraft.main.Arcticraft;
import net.minecraft.block.Block;
import net.minecraft.init.Blocks;
import net.minecraft.world.World;
import net.minecraft.world.gen.feature.WorldGenerator;

public class WorldGenEskimoVillage extends WorldGenerator{

	protected Block[] GetValidSpawnBlocks()
	{
		return new Block[] {Blocks.snow_layer, Blocks.snow, /* AC_Block.thickSnow.blockID */ACBlocks.frostGrass, ACBlocks.frostSnow};
	}

	public boolean LocationIsValidSpawn(World world, int i, int j, int k)
	{
		int distanceToAir = 0;
		Block checkBlock = world.getBlock(i, j, k);

		while(checkBlock != Blocks.air)
		{
			distanceToAir++;
			checkBlock = world.getBlock(i, j + distanceToAir, k);
		}

		if(distanceToAir > 0)
		{
			return false;
		}
		j += distanceToAir - 1;

		Block block = world.getBlock(i, j, k);
		Block blockAbove = world.getBlock(i, j + 1, k);
		Block blockBelow = world.getBlock(i, j - 1, k);
		for(Block x : GetValidSpawnBlocks())
		{
			if(blockAbove != Blocks.air)
			{
				return false;
			}
			if(block == x)
			{
				return true;
			}
			else if(block == Blocks.snow_layer && blockBelow == x)
			{
				return true;
			}
		}
		return false;
	}

	private void clearArea(World world, int x, int y, int z, int xSize, int ySize, int zSize)
	{
		for(int xx = x; xx < x + xSize; ++xx)
		{
			for(int yy = y; yy < y + ySize; ++yy)
			{
				for(int zz = z; zz < z + zSize; ++zz)
				{
					world.setBlock(xx, yy, zz, Blocks.air);
				}
			}
		}
	}

	public boolean generate(World world, Random rand, int i, int j, int k)
	{

		// check that each corner is one of the valid spawn blocks
		/*if(!LocationIsValidSpawn(world, i, j, k) || !LocationIsValidSpawn(world, i + 69, j, k) || !LocationIsValidSpawn(world, i + 69, j, k + 28) || !LocationIsValidSpawn(world, i, j, k + 28))
		{
			return false;
		}*/
		if(rand.nextInt(1000) > 100)
		{
			return false;
		}
		clearArea(world, i, j, k, 70, 5, 70);
		Arcticraft.notifyOfGenertion("Eskimo Village", Integer.toString(i), Integer.toString(k));
		world.setBlock(i + 1, j + 0, k + 12, Blocks.snow);
		world.setBlock(i + 1, j + 0, k + 13, Blocks.snow);
		world.setBlock(i + 1, j + 0, k + 14, Blocks.snow);
		world.setBlock(i + 1, j + 0, k + 15, Blocks.snow);
		world.setBlock(i + 1, j + 0, k + 16, Blocks.snow);
		world.setBlock(i + 1, j + 1, k + 12, Blocks.snow);
		world.setBlock(i + 1, j + 1, k + 13, Blocks.snow);
		world.setBlock(i + 1, j + 1, k + 14, Blocks.snow);
		world.setBlock(i + 1, j + 1, k + 15, Blocks.snow);
		world.setBlock(i + 1, j + 1, k + 16, Blocks.snow);
		world.setBlock(i + 1, j + 2, k + 12, ACBlocks.unbreakableIce);
		world.setBlock(i + 1, j + 2, k + 13, ACBlocks.unbreakableIce);
		world.setBlock(i + 1, j + 2, k + 14, ACBlocks.unbreakableIce);
		world.setBlock(i + 1, j + 2, k + 15, ACBlocks.unbreakableIce);
		world.setBlock(i + 1, j + 2, k + 16, ACBlocks.unbreakableIce);
		world.setBlock(i + 1, j + 3, k + 12, ACBlocks.unbreakableIce);
		world.setBlock(i + 1, j + 3, k + 13, ACBlocks.unbreakableIce);
		world.setBlock(i + 1, j + 3, k + 14, ACBlocks.unbreakableIce);
		world.setBlock(i + 1, j + 3, k + 15, ACBlocks.unbreakableIce);
		world.setBlock(i + 1, j + 3, k + 16, ACBlocks.unbreakableIce);
		world.setBlock(i + 1, j + 4, k + 12, ACBlocks.unbreakableIce);
		world.setBlock(i + 1, j + 4, k + 13, ACBlocks.unbreakableIce);
		world.setBlock(i + 1, j + 4, k + 14, ACBlocks.unbreakableIce);
		world.setBlock(i + 1, j + 4, k + 15, ACBlocks.unbreakableIce);
		world.setBlock(i + 1, j + 4, k + 16, ACBlocks.unbreakableIce);
		world.setBlock(i + 1, j + 5, k + 12, ACBlocks.unbreakableIce);
		world.setBlock(i + 1, j + 5, k + 13, ACBlocks.unbreakableIce);
		world.setBlock(i + 1, j + 5, k + 14, ACBlocks.unbreakableIce);
		world.setBlock(i + 1, j + 5, k + 15, ACBlocks.unbreakableIce);
		world.setBlock(i + 1, j + 5, k + 16, ACBlocks.unbreakableIce);
		world.setBlock(i + 1, j + 6, k + 12, ACBlocks.unbreakableIce);
		world.setBlock(i + 1, j + 6, k + 13, ACBlocks.unbreakableIce);
		world.setBlock(i + 1, j + 6, k + 14, ACBlocks.unbreakableIce);
		world.setBlock(i + 1, j + 6, k + 15, ACBlocks.unbreakableIce);
		world.setBlock(i + 1, j + 6, k + 16, ACBlocks.unbreakableIce);
		world.setBlock(i + 1, j + 7, k + 12, ACBlocks.unbreakableIce);
		world.setBlock(i + 1, j + 7, k + 13, ACBlocks.unbreakableIce);
		world.setBlock(i + 1, j + 7, k + 14, ACBlocks.unbreakableIce);
		world.setBlock(i + 1, j + 7, k + 15, ACBlocks.unbreakableIce);
		world.setBlock(i + 1, j + 7, k + 16, ACBlocks.unbreakableIce);
		world.setBlock(i + 1, j + 8, k + 12, ACBlocks.unbreakableIce);
		world.setBlock(i + 1, j + 8, k + 13, ACBlocks.unbreakableIce);
		world.setBlock(i + 1, j + 8, k + 14, ACBlocks.unbreakableIce);
		world.setBlock(i + 1, j + 8, k + 15, ACBlocks.unbreakableIce);
		world.setBlock(i + 1, j + 8, k + 16, ACBlocks.unbreakableIce);
		world.setBlock(i + 2, j + 0, k + 11, Blocks.snow);
		world.setBlock(i + 2, j + 0, k + 12, ACBlocks.acPlanks);
		world.setBlock(i + 2, j + 0, k + 13, ACBlocks.acPlanks);
		world.setBlock(i + 2, j + 0, k + 14, ACBlocks.acPlanks);
		world.setBlock(i + 2, j + 0, k + 15, ACBlocks.acPlanks);
		world.setBlock(i + 2, j + 0, k + 16, ACBlocks.acPlanks);
		world.setBlock(i + 2, j + 0, k + 17, Blocks.snow);
		world.setBlock(i + 2, j + 1, k + 11, Blocks.snow);
		world.setBlock(i + 2, j + 1, k + 12, ACBlocks.arcaneStone);
		world.setBlock(i + 2, j + 1, k + 13, Blocks.air);
		world.setBlock(i + 2, j + 1, k + 14, Blocks.air);
		world.setBlock(i + 2, j + 1, k + 15, Blocks.air);
		world.setBlock(i + 2, j + 1, k + 16, ACBlocks.arcaneStone);
		world.setBlock(i + 2, j + 1, k + 17, Blocks.snow);
		world.setBlock(i + 2, j + 2, k + 11, ACBlocks.unbreakableIce);
		world.setBlock(i + 2, j + 2, k + 12, Blocks.air);
		world.setBlock(i + 2, j + 2, k + 13, Blocks.air);
		world.setBlock(i + 2, j + 2, k + 14, Blocks.air);
		world.setBlock(i + 2, j + 2, k + 15, Blocks.air);
		world.setBlock(i + 2, j + 2, k + 16, Blocks.air);
		world.setBlock(i + 2, j + 2, k + 17, ACBlocks.unbreakableIce);
		world.setBlock(i + 2, j + 3, k + 11, ACBlocks.unbreakableIce);
		world.setBlock(i + 2, j + 3, k + 17, ACBlocks.unbreakableIce);
		world.setBlock(i + 2, j + 4, k + 11, ACBlocks.unbreakableIce);
		world.setBlock(i + 2, j + 4, k + 17, ACBlocks.unbreakableIce);
		world.setBlock(i + 2, j + 5, k + 11, ACBlocks.unbreakableIce);
		world.setBlock(i + 2, j + 5, k + 17, ACBlocks.unbreakableIce);
		world.setBlock(i + 2, j + 6, k + 11, ACBlocks.unbreakableIce);
		world.setBlock(i + 2, j + 6, k + 17, ACBlocks.unbreakableIce);
		world.setBlock(i + 2, j + 7, k + 11, ACBlocks.unbreakableIce);
		world.setBlock(i + 2, j + 7, k + 17, ACBlocks.unbreakableIce);
		world.setBlock(i + 2, j + 8, k + 11, ACBlocks.unbreakableIce);
		world.setBlock(i + 2, j + 8, k + 17, ACBlocks.unbreakableIce);
		world.setBlock(i + 2, j + 9, k + 12, ACBlocks.unbreakableIce);
		world.setBlock(i + 2, j + 9, k + 13, ACBlocks.unbreakableIce);
		world.setBlock(i + 2, j + 9, k + 14, ACBlocks.unbreakableIce);
		world.setBlock(i + 2, j + 9, k + 15, ACBlocks.unbreakableIce);
		world.setBlock(i + 2, j + 9, k + 16, ACBlocks.unbreakableIce);
		world.setBlock(i + 3, j + 0, k + 10, Blocks.snow);
		world.setBlock(i + 3, j + 0, k + 11, ACBlocks.acPlanks);
		world.setBlock(i + 3, j + 0, k + 12, ACBlocks.acPlanks);
		world.setBlock(i + 3, j + 0, k + 13, ACBlocks.acPlanks);
		world.setBlock(i + 3, j + 0, k + 14, ACBlocks.acPlanks);
		world.setBlock(i + 3, j + 0, k + 15, ACBlocks.acPlanks);
		world.setBlock(i + 3, j + 0, k + 16, ACBlocks.acPlanks);
		world.setBlock(i + 3, j + 0, k + 17, ACBlocks.acPlanks);
		world.setBlock(i + 3, j + 0, k + 18, Blocks.snow);
		world.setBlock(i + 3, j + 1, k + 10, Blocks.snow);
		world.setBlock(i + 3, j + 1, k + 11, Blocks.air);
		world.setBlock(i + 3, j + 1, k + 12, Blocks.air);
		world.setBlock(i + 3, j + 1, k + 13, Blocks.air);
		world.setBlock(i + 3, j + 1, k + 14, Blocks.air);
		world.setBlock(i + 3, j + 1, k + 15, Blocks.air);
		world.setBlock(i + 3, j + 1, k + 16, Blocks.air);
		world.setBlock(i + 3, j + 1, k + 17, Blocks.air);
		world.setBlock(i + 3, j + 1, k + 18, Blocks.snow);
		world.setBlock(i + 3, j + 2, k + 10, ACBlocks.unbreakableIce);
		world.setBlock(i + 3, j + 2, k + 11, Blocks.air);
		world.setBlock(i + 3, j + 2, k + 12, Blocks.air);
		world.setBlock(i + 3, j + 2, k + 13, Blocks.air);
		world.setBlock(i + 3, j + 2, k + 14, Blocks.air);
		world.setBlock(i + 3, j + 2, k + 15, Blocks.air);
		world.setBlock(i + 3, j + 2, k + 16, Blocks.air);
		world.setBlock(i + 3, j + 2, k + 17, Blocks.air);
		world.setBlock(i + 3, j + 2, k + 18, ACBlocks.unbreakableIce);
		world.setBlock(i + 3, j + 3, k + 10, ACBlocks.unbreakableIce);
		world.setBlock(i + 3, j + 3, k + 18, ACBlocks.unbreakableIce);
		world.setBlock(i + 3, j + 4, k + 10, ACBlocks.unbreakableIce);
		world.setBlock(i + 3, j + 4, k + 18, ACBlocks.unbreakableIce);
		world.setBlock(i + 3, j + 5, k + 10, ACBlocks.unbreakableIce);
		world.setBlock(i + 3, j + 5, k + 18, ACBlocks.unbreakableIce);
		world.setBlock(i + 3, j + 6, k + 10, ACBlocks.unbreakableIce);
		world.setBlock(i + 3, j + 6, k + 18, ACBlocks.unbreakableIce);
		world.setBlock(i + 3, j + 7, k + 10, ACBlocks.unbreakableIce);
		world.setBlock(i + 3, j + 7, k + 18, ACBlocks.unbreakableIce);
		world.setBlock(i + 3, j + 8, k + 10, ACBlocks.unbreakableIce);
		world.setBlock(i + 3, j + 8, k + 18, ACBlocks.unbreakableIce);
		world.setBlock(i + 3, j + 9, k + 11, ACBlocks.unbreakableIce);
		world.setBlock(i + 3, j + 9, k + 17, ACBlocks.unbreakableIce);
		world.setBlock(i + 3, j + 10, k + 12, ACBlocks.unbreakableIce);
		world.setBlock(i + 3, j + 10, k + 13, ACBlocks.unbreakableIce);
		world.setBlock(i + 3, j + 10, k + 14, ACBlocks.unbreakableIce);
		world.setBlock(i + 3, j + 10, k + 15, ACBlocks.unbreakableIce);
		world.setBlock(i + 3, j + 10, k + 16, ACBlocks.unbreakableIce);
		world.setBlock(i + 4, j + 0, k + 10, Blocks.snow);
		world.setBlock(i + 4, j + 0, k + 11, ACBlocks.acPlanks);
		world.setBlock(i + 4, j + 0, k + 12, ACBlocks.acPlanks);
		world.setBlock(i + 4, j + 0, k + 13, ACBlocks.acPlanks);
		world.setBlock(i + 4, j + 0, k + 14, ACBlocks.acPlanks);
		world.setBlock(i + 4, j + 0, k + 15, ACBlocks.acPlanks);
		world.setBlock(i + 4, j + 0, k + 16, ACBlocks.acPlanks);
		world.setBlock(i + 4, j + 0, k + 17, ACBlocks.acPlanks);
		world.setBlock(i + 4, j + 0, k + 18, Blocks.snow);
		world.setBlock(i + 4, j + 1, k + 10, Blocks.snow);
		world.setBlock(i + 4, j + 1, k + 11, Blocks.air);
		world.setBlock(i + 4, j + 1, k + 12, Blocks.air);
		world.setBlock(i + 4, j + 1, k + 13, Blocks.air);
		world.setBlock(i + 4, j + 1, k + 15, Blocks.air);
		world.setBlock(i + 4, j + 1, k + 16, Blocks.air);
		world.setBlock(i + 4, j + 1, k + 17, Blocks.air);
		world.setBlock(i + 4, j + 1, k + 18, Blocks.snow);
		world.setBlock(i + 4, j + 2, k + 10, ACBlocks.unbreakableIce);
		world.setBlock(i + 4, j + 2, k + 11, Blocks.air);
		world.setBlock(i + 4, j + 2, k + 12, Blocks.air);
		world.setBlock(i + 4, j + 2, k + 13, Blocks.air);
		world.setBlock(i + 4, j + 2, k + 14, Blocks.air);
		world.setBlock(i + 4, j + 2, k + 15, Blocks.air);
		world.setBlock(i + 4, j + 2, k + 16, Blocks.air);
		world.setBlock(i + 4, j + 2, k + 17, Blocks.air);
		world.setBlock(i + 4, j + 2, k + 18, ACBlocks.unbreakableIce);
		world.setBlock(i + 4, j + 3, k + 10, ACBlocks.unbreakableIce);
		world.setBlock(i + 4, j + 3, k + 18, ACBlocks.unbreakableIce);
		world.setBlock(i + 4, j + 4, k + 10, ACBlocks.unbreakableIce);
		world.setBlock(i + 4, j + 4, k + 18, ACBlocks.unbreakableIce);
		world.setBlock(i + 4, j + 5, k + 10, ACBlocks.unbreakableIce);
		world.setBlock(i + 4, j + 5, k + 18, ACBlocks.unbreakableIce);
		world.setBlock(i + 4, j + 6, k + 10, ACBlocks.unbreakableIce);
		world.setBlock(i + 4, j + 6, k + 18, ACBlocks.unbreakableIce);
		world.setBlock(i + 4, j + 7, k + 10, ACBlocks.unbreakableIce);
		world.setBlock(i + 4, j + 7, k + 18, ACBlocks.unbreakableIce);
		world.setBlock(i + 4, j + 8, k + 10, ACBlocks.unbreakableIce);
		world.setBlock(i + 4, j + 8, k + 18, ACBlocks.unbreakableIce);
		world.setBlock(i + 4, j + 9, k + 11, ACBlocks.unbreakableIce);
		world.setBlock(i + 4, j + 9, k + 17, ACBlocks.unbreakableIce);
		world.setBlock(i + 4, j + 10, k + 12, ACBlocks.unbreakableIce);
		world.setBlock(i + 4, j + 10, k + 16, ACBlocks.unbreakableIce);
		world.setBlock(i + 4, j + 11, k + 13, ACBlocks.unbreakableIce);
		world.setBlock(i + 4, j + 11, k + 14, ACBlocks.unbreakableIce);
		world.setBlock(i + 4, j + 11, k + 15, ACBlocks.unbreakableIce);
		world.setBlock(i + 5, j + 0, k + 10, Blocks.snow);
		world.setBlock(i + 5, j + 0, k + 11, ACBlocks.acPlanks);
		world.setBlock(i + 5, j + 0, k + 12, ACBlocks.acPlanks);
		world.setBlock(i + 5, j + 0, k + 13, ACBlocks.acPlanks);
		world.setBlock(i + 5, j + 0, k + 14, ACBlocks.acPlanks);
		world.setBlock(i + 5, j + 0, k + 15, ACBlocks.acPlanks);
		world.setBlock(i + 5, j + 0, k + 16, ACBlocks.acPlanks);
		world.setBlock(i + 5, j + 0, k + 17, ACBlocks.acPlanks);
		world.setBlock(i + 5, j + 0, k + 18, Blocks.snow);
		world.setBlock(i + 5, j + 1, k + 10, Blocks.snow);
		world.setBlock(i + 5, j + 1, k + 11, Blocks.air);
		world.setBlock(i + 5, j + 1, k + 12, Blocks.air);
		world.setBlock(i + 5, j + 1, k + 13, Blocks.air);
		world.setBlock(i + 5, j + 1, k + 14, Blocks.air);
		world.setBlock(i + 5, j + 1, k + 15, Blocks.air);
		world.setBlock(i + 5, j + 1, k + 16, Blocks.air);
		world.setBlock(i + 5, j + 1, k + 17, Blocks.air);
		world.setBlock(i + 5, j + 1, k + 18, Blocks.snow);
		world.setBlock(i + 5, j + 2, k + 10, ACBlocks.unbreakableIce);
		world.setBlock(i + 5, j + 2, k + 11, Blocks.air);
		world.setBlock(i + 5, j + 2, k + 12, Blocks.air);
		world.setBlock(i + 5, j + 2, k + 13, Blocks.air);
		world.setBlock(i + 5, j + 2, k + 14, Blocks.air);
		world.setBlock(i + 5, j + 2, k + 15, Blocks.air);
		world.setBlock(i + 5, j + 2, k + 16, Blocks.air);
		world.setBlock(i + 5, j + 2, k + 17, Blocks.air);
		world.setBlock(i + 5, j + 2, k + 18, ACBlocks.unbreakableIce);
		world.setBlock(i + 5, j + 3, k + 10, ACBlocks.unbreakableIce);
		world.setBlock(i + 5, j + 3, k + 18, ACBlocks.unbreakableIce);
		world.setBlock(i + 5, j + 4, k + 10, ACBlocks.unbreakableIce);
		world.setBlock(i + 5, j + 4, k + 18, ACBlocks.unbreakableIce);
		world.setBlock(i + 5, j + 5, k + 10, ACBlocks.unbreakableIce);
		world.setBlock(i + 5, j + 5, k + 18, ACBlocks.unbreakableIce);
		world.setBlock(i + 5, j + 6, k + 10, ACBlocks.unbreakableIce);
		world.setBlock(i + 5, j + 6, k + 18, ACBlocks.unbreakableIce);
		world.setBlock(i + 5, j + 7, k + 10, ACBlocks.unbreakableIce);
		world.setBlock(i + 5, j + 7, k + 18, ACBlocks.unbreakableIce);
		world.setBlock(i + 5, j + 8, k + 10, ACBlocks.unbreakableIce);
		world.setBlock(i + 5, j + 8, k + 18, ACBlocks.unbreakableIce);
		world.setBlock(i + 5, j + 9, k + 11, ACBlocks.unbreakableIce);
		world.setBlock(i + 5, j + 9, k + 17, ACBlocks.unbreakableIce);
		world.setBlock(i + 5, j + 10, k + 12, ACBlocks.unbreakableIce);
		world.setBlock(i + 5, j + 10, k + 16, ACBlocks.unbreakableIce);
		world.setBlock(i + 5, j + 11, k + 13, ACBlocks.unbreakableIce);
		world.setBlock(i + 5, j + 11, k + 15, ACBlocks.unbreakableIce);
		world.setBlock(i + 5, j + 12, k + 14, ACBlocks.unbreakableIce);
		world.setBlock(i + 6, j + 0, k + 10, Blocks.snow);
		world.setBlock(i + 6, j + 0, k + 11, ACBlocks.acPlanks);
		world.setBlock(i + 6, j + 0, k + 12, ACBlocks.acPlanks);
		world.setBlock(i + 6, j + 0, k + 13, ACBlocks.acPlanks);
		world.setBlock(i + 6, j + 0, k + 14, ACBlocks.acPlanks);
		world.setBlock(i + 6, j + 0, k + 15, ACBlocks.acPlanks);
		world.setBlock(i + 6, j + 0, k + 16, ACBlocks.acPlanks);
		world.setBlock(i + 6, j + 0, k + 17, ACBlocks.acPlanks);
		world.setBlock(i + 6, j + 0, k + 18, Blocks.snow);
		world.setBlock(i + 6, j + 1, k + 10, Blocks.snow);
		world.setBlock(i + 6, j + 1, k + 11, Blocks.air);
		world.setBlock(i + 6, j + 1, k + 12, Blocks.air);
		world.setBlock(i + 6, j + 1, k + 13, Blocks.air);
		world.setBlock(i + 6, j + 1, k + 14, Blocks.air);
		world.setBlock(i + 6, j + 1, k + 15, Blocks.air);
		world.setBlock(i + 6, j + 1, k + 16, Blocks.air);
		world.setBlock(i + 6, j + 1, k + 17, Blocks.air);
		world.setBlock(i + 6, j + 1, k + 18, Blocks.snow);
		world.setBlock(i + 6, j + 2, k + 10, ACBlocks.unbreakableIce);
		world.setBlock(i + 6, j + 2, k + 11, Blocks.air);
		world.setBlock(i + 6, j + 2, k + 12, Blocks.air);
		world.setBlock(i + 6, j + 2, k + 13, Blocks.air);
		world.setBlock(i + 6, j + 2, k + 14, Blocks.air);
		world.setBlock(i + 6, j + 2, k + 15, Blocks.air);
		world.setBlock(i + 6, j + 2, k + 16, Blocks.air);
		world.setBlock(i + 6, j + 2, k + 17, Blocks.air);
		world.setBlock(i + 6, j + 2, k + 18, ACBlocks.unbreakableIce);
		world.setBlock(i + 6, j + 3, k + 10, ACBlocks.unbreakableIce);
		world.setBlock(i + 6, j + 3, k + 18, ACBlocks.unbreakableIce);
		world.setBlock(i + 6, j + 4, k + 10, ACBlocks.unbreakableIce);
		world.setBlock(i + 6, j + 4, k + 18, ACBlocks.unbreakableIce);
		world.setBlock(i + 6, j + 5, k + 10, ACBlocks.unbreakableIce);
		world.setBlock(i + 6, j + 5, k + 18, ACBlocks.unbreakableIce);
		world.setBlock(i + 6, j + 6, k + 10, ACBlocks.unbreakableIce);
		world.setBlock(i + 6, j + 6, k + 18, ACBlocks.unbreakableIce);
		world.setBlock(i + 6, j + 7, k + 10, ACBlocks.unbreakableIce);
		world.setBlock(i + 6, j + 7, k + 18, ACBlocks.unbreakableIce);
		world.setBlock(i + 6, j + 8, k + 10, ACBlocks.unbreakableIce);
		world.setBlock(i + 6, j + 8, k + 18, ACBlocks.unbreakableIce);
		world.setBlock(i + 6, j + 9, k + 11, ACBlocks.unbreakableIce);
		world.setBlock(i + 6, j + 9, k + 17, ACBlocks.unbreakableIce);
		world.setBlock(i + 6, j + 10, k + 12, ACBlocks.unbreakableIce);
		world.setBlock(i + 6, j + 10, k + 16, ACBlocks.unbreakableIce);
		world.setBlock(i + 6, j + 11, k + 13, ACBlocks.unbreakableIce);
		world.setBlock(i + 6, j + 11, k + 15, ACBlocks.unbreakableIce);
		world.setBlock(i + 6, j + 12, k + 14, ACBlocks.unbreakableIce);
		world.setBlock(i + 7, j + 0, k + 9, Blocks.snow);
		world.setBlock(i + 7, j + 0, k + 10, ACBlocks.acPlanks);
		world.setBlock(i + 7, j + 0, k + 11, ACBlocks.acPlanks);
		world.setBlock(i + 7, j + 0, k + 12, ACBlocks.acPlanks);
		world.setBlock(i + 7, j + 0, k + 13, ACBlocks.acPlanks);
		world.setBlock(i + 7, j + 0, k + 14, ACBlocks.acPlanks);
		world.setBlock(i + 7, j + 0, k + 15, ACBlocks.acPlanks);
		world.setBlock(i + 7, j + 0, k + 16, ACBlocks.acPlanks);
		world.setBlock(i + 7, j + 0, k + 17, ACBlocks.acPlanks);
		world.setBlock(i + 7, j + 0, k + 18, ACBlocks.acPlanks);
		world.setBlock(i + 7, j + 0, k + 19, Blocks.snow);
		world.setBlock(i + 7, j + 1, k + 9, Blocks.snow);
		world.setBlock(i + 7, j + 1, k + 10, Blocks.air);
		world.setBlock(i + 7, j + 1, k + 11, Blocks.air);
		world.setBlock(i + 7, j + 1, k + 12, Blocks.air);
		world.setBlock(i + 7, j + 1, k + 13, Blocks.air);
		world.setBlock(i + 7, j + 1, k + 14, Blocks.air);
		world.setBlock(i + 7, j + 1, k + 15, Blocks.air);
		world.setBlock(i + 7, j + 1, k + 16, Blocks.air);
		world.setBlock(i + 7, j + 1, k + 17, Blocks.air);
		world.setBlock(i + 7, j + 1, k + 18, Blocks.air);
		world.setBlock(i + 7, j + 1, k + 19, Blocks.snow);
		world.setBlock(i + 7, j + 2, k + 9, ACBlocks.unbreakableIce);
		world.setBlock(i + 7, j + 2, k + 10, Blocks.air);
		world.setBlock(i + 7, j + 2, k + 11, Blocks.air);
		world.setBlock(i + 7, j + 2, k + 12, Blocks.air);
		world.setBlock(i + 7, j + 2, k + 13, Blocks.air);
		world.setBlock(i + 7, j + 2, k + 14, Blocks.air);
		world.setBlock(i + 7, j + 2, k + 15, Blocks.air);
		world.setBlock(i + 7, j + 2, k + 16, Blocks.air);
		world.setBlock(i + 7, j + 2, k + 17, Blocks.air);
		world.setBlock(i + 7, j + 2, k + 18, Blocks.air);
		world.setBlock(i + 7, j + 2, k + 19, ACBlocks.unbreakableIce);
		world.setBlock(i + 7, j + 3, k + 9, ACBlocks.unbreakableIce);
		world.setBlock(i + 7, j + 3, k + 19, ACBlocks.unbreakableIce);
		world.setBlock(i + 7, j + 4, k + 9, ACBlocks.unbreakableIce);
		world.setBlock(i + 7, j + 4, k + 19, ACBlocks.unbreakableIce);
		world.setBlock(i + 7, j + 5, k + 9, ACBlocks.unbreakableIce);
		world.setBlock(i + 7, j + 5, k + 19, ACBlocks.unbreakableIce);
		world.setBlock(i + 7, j + 6, k + 9, ACBlocks.unbreakableIce);
		world.setBlock(i + 7, j + 6, k + 19, ACBlocks.unbreakableIce);
		world.setBlock(i + 7, j + 7, k + 9, ACBlocks.unbreakableIce);
		world.setBlock(i + 7, j + 7, k + 19, ACBlocks.unbreakableIce);
		world.setBlock(i + 7, j + 8, k + 9, ACBlocks.unbreakableIce);
		world.setBlock(i + 7, j + 8, k + 19, ACBlocks.unbreakableIce);
		world.setBlock(i + 7, j + 9, k + 10, ACBlocks.unbreakableIce);
		world.setBlock(i + 7, j + 9, k + 18, ACBlocks.unbreakableIce);
		world.setBlock(i + 7, j + 10, k + 11, ACBlocks.unbreakableIce);
		world.setBlock(i + 7, j + 10, k + 17, ACBlocks.unbreakableIce);
		world.setBlock(i + 7, j + 11, k + 12, ACBlocks.unbreakableIce);
		world.setBlock(i + 7, j + 11, k + 16, ACBlocks.unbreakableIce);
		world.setBlock(i + 7, j + 12, k + 13, ACBlocks.unbreakableIce);
		world.setBlock(i + 7, j + 12, k + 14, ACBlocks.unbreakableIce);
		world.setBlock(i + 7, j + 12, k + 15, ACBlocks.unbreakableIce);
		world.setBlock(i + 8, j + 0, k + 8, Blocks.snow);
		world.setBlock(i + 8, j + 0, k + 9, ACBlocks.acPlanks);
		world.setBlock(i + 8, j + 0, k + 10, ACBlocks.acPlanks);
		world.setBlock(i + 8, j + 0, k + 11, ACBlocks.acPlanks);
		world.setBlock(i + 8, j + 0, k + 12, ACBlocks.acPlanks);
		world.setBlock(i + 8, j + 0, k + 13, ACBlocks.acPlanks);
		world.setBlock(i + 8, j + 0, k + 14, ACBlocks.acPlanks);
		world.setBlock(i + 8, j + 0, k + 15, ACBlocks.acPlanks);
		world.setBlock(i + 8, j + 0, k + 16, ACBlocks.acPlanks);
		world.setBlock(i + 8, j + 0, k + 17, ACBlocks.acPlanks);
		world.setBlock(i + 8, j + 0, k + 18, ACBlocks.acPlanks);
		world.setBlock(i + 8, j + 0, k + 19, ACBlocks.acPlanks);
		world.setBlock(i + 8, j + 0, k + 20, Blocks.snow);
		world.setBlock(i + 8, j + 1, k + 8, Blocks.snow);
		world.setBlock(i + 8, j + 1, k + 9, ACBlocks.arcaneStone);
		world.setBlock(i + 8, j + 1, k + 10, Blocks.air);
		world.setBlock(i + 8, j + 1, k + 11, Blocks.air);
		world.setBlock(i + 8, j + 1, k + 12, Blocks.air);
		world.setBlock(i + 8, j + 1, k + 13, Blocks.stonebrick);
		world.setBlock(i + 8, j + 1, k + 14, Blocks.stonebrick);
		world.setBlock(i + 8, j + 1, k + 15, Blocks.stonebrick);
		world.setBlock(i + 8, j + 1, k + 16, Blocks.air);
		world.setBlock(i + 8, j + 1, k + 17, Blocks.air);
		world.setBlock(i + 8, j + 1, k + 18, Blocks.air);
		world.setBlock(i + 8, j + 1, k + 19, ACBlocks.arcaneStone);
		world.setBlock(i + 8, j + 1, k + 20, Blocks.snow);
		world.setBlock(i + 8, j + 2, k + 8, ACBlocks.unbreakableIce);
		world.setBlock(i + 8, j + 2, k + 9, Blocks.air);
		world.setBlock(i + 8, j + 2, k + 10, Blocks.air);
		world.setBlock(i + 8, j + 2, k + 11, Blocks.air);
		world.setBlock(i + 8, j + 2, k + 12, Blocks.air);
		world.setBlock(i + 8, j + 2, k + 13, Blocks.air);
		world.setBlock(i + 8, j + 2, k + 14, Blocks.air);
		world.setBlock(i + 8, j + 2, k + 15, Blocks.air);
		world.setBlock(i + 8, j + 2, k + 16, Blocks.air);
		world.setBlock(i + 8, j + 2, k + 17, Blocks.air);
		world.setBlock(i + 8, j + 2, k + 18, Blocks.air);
		world.setBlock(i + 8, j + 2, k + 19, Blocks.air);
		world.setBlock(i + 8, j + 2, k + 20, ACBlocks.unbreakableIce);
		world.setBlock(i + 8, j + 3, k + 8, ACBlocks.unbreakableIce);
		world.setBlock(i + 8, j + 3, k + 20, ACBlocks.unbreakableIce);
		world.setBlock(i + 8, j + 4, k + 8, ACBlocks.unbreakableIce);
		world.setBlock(i + 8, j + 4, k + 20, ACBlocks.unbreakableIce);
		world.setBlock(i + 8, j + 5, k + 8, ACBlocks.unbreakableIce);
		world.setBlock(i + 8, j + 5, k + 20, ACBlocks.unbreakableIce);
		world.setBlock(i + 8, j + 6, k + 8, ACBlocks.unbreakableIce);
		world.setBlock(i + 8, j + 6, k + 20, ACBlocks.unbreakableIce);
		world.setBlock(i + 8, j + 7, k + 8, ACBlocks.unbreakableIce);
		world.setBlock(i + 8, j + 7, k + 20, ACBlocks.unbreakableIce);
		world.setBlock(i + 8, j + 8, k + 8, ACBlocks.unbreakableIce);
		world.setBlock(i + 8, j + 8, k + 20, ACBlocks.unbreakableIce);
		world.setBlock(i + 8, j + 9, k + 9, ACBlocks.unbreakableIce);
		world.setBlock(i + 8, j + 9, k + 19, ACBlocks.unbreakableIce);
		world.setBlock(i + 8, j + 10, k + 10, ACBlocks.unbreakableIce);
		world.setBlock(i + 8, j + 10, k + 18, ACBlocks.unbreakableIce);
		world.setBlock(i + 8, j + 11, k + 11, ACBlocks.unbreakableIce);
		world.setBlock(i + 8, j + 11, k + 17, ACBlocks.unbreakableIce);
		world.setBlock(i + 8, j + 12, k + 12, ACBlocks.unbreakableIce);
		world.setBlock(i + 8, j + 12, k + 13, ACBlocks.unbreakableIce);
		world.setBlock(i + 8, j + 12, k + 14, ACBlocks.unbreakableIce);
		world.setBlock(i + 8, j + 12, k + 15, ACBlocks.unbreakableIce);
		world.setBlock(i + 8, j + 12, k + 16, ACBlocks.unbreakableIce);
		world.setBlock(i + 9, j + 0, k + 7, Blocks.snow);
		world.setBlock(i + 9, j + 0, k + 8, ACBlocks.acPlanks);
		world.setBlock(i + 9, j + 0, k + 9, ACBlocks.acPlanks);
		world.setBlock(i + 9, j + 0, k + 10, ACBlocks.acPlanks);
		world.setBlock(i + 9, j + 0, k + 11, ACBlocks.acPlanks);
		world.setBlock(i + 9, j + 0, k + 12, ACBlocks.acPlanks);
		world.setBlock(i + 9, j + 0, k + 13, ACBlocks.acPlanks);
		world.setBlock(i + 9, j + 0, k + 14, ACBlocks.acPlanks);
		world.setBlock(i + 9, j + 0, k + 15, ACBlocks.acPlanks);
		world.setBlock(i + 9, j + 0, k + 16, ACBlocks.acPlanks);
		world.setBlock(i + 9, j + 0, k + 17, ACBlocks.acPlanks);
		world.setBlock(i + 9, j + 0, k + 18, ACBlocks.acPlanks);
		world.setBlock(i + 9, j + 0, k + 19, ACBlocks.acPlanks);
		world.setBlock(i + 9, j + 0, k + 20, ACBlocks.acPlanks);
		world.setBlock(i + 9, j + 0, k + 21, Blocks.snow);
		world.setBlock(i + 9, j + 1, k + 7, Blocks.snow);
		world.setBlock(i + 9, j + 1, k + 8, Blocks.air);
		world.setBlock(i + 9, j + 1, k + 9, Blocks.air);
		world.setBlock(i + 9, j + 1, k + 10, Blocks.air);
		world.setBlock(i + 9, j + 1, k + 11, Blocks.air);
		world.setBlock(i + 9, j + 1, k + 12, Blocks.air);
		world.setBlock(i + 9, j + 1, k + 13, Blocks.stonebrick);
		world.setBlock(i + 9, j + 1, k + 15, Blocks.stonebrick);
		world.setBlock(i + 9, j + 1, k + 16, Blocks.air);
		world.setBlock(i + 9, j + 1, k + 17, Blocks.air);
		world.setBlock(i + 9, j + 1, k + 18, Blocks.air);
		world.setBlock(i + 9, j + 1, k + 19, Blocks.air);
		world.setBlock(i + 9, j + 1, k + 20, Blocks.air);
		world.setBlock(i + 9, j + 1, k + 21, Blocks.snow);
		world.setBlock(i + 9, j + 2, k + 7, ACBlocks.unbreakableIce);
		world.setBlock(i + 9, j + 2, k + 8, Blocks.air);
		world.setBlock(i + 9, j + 2, k + 9, Blocks.air);
		world.setBlock(i + 9, j + 2, k + 10, Blocks.air);
		world.setBlock(i + 9, j + 2, k + 11, Blocks.air);
		world.setBlock(i + 9, j + 2, k + 12, Blocks.air);
		world.setBlock(i + 9, j + 2, k + 13, Blocks.air);
		world.setBlock(i + 9, j + 2, k + 14, ACBlocks.acPlanks);
		world.setBlock(i + 9, j + 2, k + 15, Blocks.air);
		world.setBlock(i + 9, j + 2, k + 16, Blocks.air);
		world.setBlock(i + 9, j + 2, k + 17, Blocks.air);
		world.setBlock(i + 9, j + 2, k + 18, Blocks.air);
		world.setBlock(i + 9, j + 2, k + 19, Blocks.air);
		world.setBlock(i + 9, j + 2, k + 20, Blocks.air);
		world.setBlock(i + 9, j + 2, k + 21, ACBlocks.unbreakableIce);
		world.setBlock(i + 9, j + 3, k + 7, ACBlocks.unbreakableIce);
		world.setBlock(i + 9, j + 3, k + 14, Blocks.skull);
		world.setBlock(i + 9, j + 3, k + 21, ACBlocks.unbreakableIce);
		world.setBlock(i + 9, j + 4, k + 7, ACBlocks.unbreakableIce);
		world.setBlock(i + 9, j + 4, k + 21, ACBlocks.unbreakableIce);
		world.setBlock(i + 9, j + 5, k + 7, ACBlocks.unbreakableIce);
		world.setBlock(i + 9, j + 5, k + 21, ACBlocks.unbreakableIce);
		world.setBlock(i + 9, j + 6, k + 7, ACBlocks.unbreakableIce);
		world.setBlock(i + 9, j + 6, k + 21, ACBlocks.unbreakableIce);
		world.setBlock(i + 9, j + 7, k + 7, ACBlocks.unbreakableIce);
		world.setBlock(i + 9, j + 7, k + 21, ACBlocks.unbreakableIce);
		world.setBlock(i + 9, j + 8, k + 7, ACBlocks.unbreakableIce);
		world.setBlock(i + 9, j + 8, k + 21, ACBlocks.unbreakableIce);
		world.setBlock(i + 9, j + 9, k + 8, ACBlocks.unbreakableIce);
		world.setBlock(i + 9, j + 9, k + 20, ACBlocks.unbreakableIce);
		world.setBlock(i + 9, j + 10, k + 9, ACBlocks.unbreakableIce);
		world.setBlock(i + 9, j + 10, k + 19, ACBlocks.unbreakableIce);
		world.setBlock(i + 9, j + 11, k + 10, ACBlocks.unbreakableIce);
		world.setBlock(i + 9, j + 11, k + 18, ACBlocks.unbreakableIce);
		world.setBlock(i + 9, j + 12, k + 11, ACBlocks.unbreakableIce);
		world.setBlock(i + 9, j + 12, k + 12, ACBlocks.unbreakableIce);
		world.setBlock(i + 9, j + 12, k + 13, ACBlocks.unbreakableIce);
		world.setBlock(i + 9, j + 12, k + 14, ACBlocks.unbreakableIce);
		world.setBlock(i + 9, j + 12, k + 15, ACBlocks.unbreakableIce);
		world.setBlock(i + 9, j + 12, k + 16, ACBlocks.unbreakableIce);
		world.setBlock(i + 9, j + 12, k + 17, ACBlocks.unbreakableIce);
		world.setBlock(i + 10, j + 0, k + 6, Blocks.snow);
		world.setBlock(i + 10, j + 0, k + 7, ACBlocks.acPlanks);
		world.setBlock(i + 10, j + 0, k + 8, ACBlocks.acPlanks);
		world.setBlock(i + 10, j + 0, k + 9, ACBlocks.acPlanks);
		world.setBlock(i + 10, j + 0, k + 10, ACBlocks.acPlanks);
		world.setBlock(i + 10, j + 0, k + 11, ACBlocks.acPlanks);
		world.setBlock(i + 10, j + 0, k + 12, ACBlocks.acPlanks);
		world.setBlock(i + 10, j + 0, k + 13, ACBlocks.acPlanks);
		world.setBlock(i + 10, j + 0, k + 14, ACBlocks.acPlanks);
		world.setBlock(i + 10, j + 0, k + 15, ACBlocks.acPlanks);
		world.setBlock(i + 10, j + 0, k + 16, ACBlocks.acPlanks);
		world.setBlock(i + 10, j + 0, k + 17, ACBlocks.acPlanks);
		world.setBlock(i + 10, j + 0, k + 18, ACBlocks.acPlanks);
		world.setBlock(i + 10, j + 0, k + 19, ACBlocks.acPlanks);
		world.setBlock(i + 10, j + 0, k + 20, ACBlocks.acPlanks);
		world.setBlock(i + 10, j + 0, k + 21, ACBlocks.acPlanks);
		world.setBlock(i + 10, j + 0, k + 22, Blocks.snow);
		world.setBlock(i + 10, j + 1, k + 6, Blocks.snow);
		world.setBlock(i + 10, j + 1, k + 7, Blocks.air);
		world.setBlock(i + 10, j + 1, k + 8, Blocks.air);
		world.setBlock(i + 10, j + 1, k + 9, Blocks.air);
		world.setBlock(i + 10, j + 1, k + 10, Blocks.air);
		world.setBlock(i + 10, j + 1, k + 11, Blocks.air);
		world.setBlock(i + 10, j + 1, k + 12, Blocks.air);
		world.setBlock(i + 10, j + 1, k + 13, Blocks.stone_brick_stairs, 1, 3);
		world.setBlock(i + 10, j + 1, k + 14, Blocks.stone_brick_stairs, 1, 3);
		world.setBlock(i + 10, j + 1, k + 15, Blocks.stone_brick_stairs, 1, 3);
		world.setBlock(i + 10, j + 1, k + 16, Blocks.air);
		world.setBlock(i + 10, j + 1, k + 17, Blocks.air);
		world.setBlock(i + 10, j + 1, k + 18, Blocks.air);
		world.setBlock(i + 10, j + 1, k + 19, Blocks.air);
		world.setBlock(i + 10, j + 1, k + 20, Blocks.air);
		world.setBlock(i + 10, j + 1, k + 21, Blocks.air);
		world.setBlock(i + 10, j + 1, k + 22, Blocks.snow);
		world.setBlock(i + 10, j + 2, k + 6, ACBlocks.unbreakableIce);
		world.setBlock(i + 10, j + 2, k + 7, Blocks.air);
		world.setBlock(i + 10, j + 2, k + 8, Blocks.air);
		world.setBlock(i + 10, j + 2, k + 9, Blocks.air);
		world.setBlock(i + 10, j + 2, k + 10, Blocks.air);
		world.setBlock(i + 10, j + 2, k + 11, Blocks.air);
		world.setBlock(i + 10, j + 2, k + 12, Blocks.air);
		world.setBlock(i + 10, j + 2, k + 13, Blocks.air);
		world.setBlock(i + 10, j + 2, k + 14, Blocks.air);
		world.setBlock(i + 10, j + 2, k + 15, Blocks.air);
		world.setBlock(i + 10, j + 2, k + 16, Blocks.air);
		world.setBlock(i + 10, j + 2, k + 17, Blocks.air);
		world.setBlock(i + 10, j + 2, k + 18, Blocks.air);
		world.setBlock(i + 10, j + 2, k + 19, Blocks.air);
		world.setBlock(i + 10, j + 2, k + 20, Blocks.air);
		world.setBlock(i + 10, j + 2, k + 21, Blocks.air);
		world.setBlock(i + 10, j + 2, k + 22, ACBlocks.unbreakableIce);
		world.setBlock(i + 10, j + 3, k + 6, ACBlocks.unbreakableIce);
		world.setBlock(i + 10, j + 3, k + 22, ACBlocks.unbreakableIce);
		world.setBlock(i + 10, j + 4, k + 6, ACBlocks.unbreakableIce);
		world.setBlock(i + 10, j + 4, k + 22, ACBlocks.unbreakableIce);
		world.setBlock(i + 10, j + 5, k + 6, ACBlocks.unbreakableIce);
		world.setBlock(i + 10, j + 5, k + 22, ACBlocks.unbreakableIce);
		world.setBlock(i + 10, j + 6, k + 6, ACBlocks.unbreakableIce);
		world.setBlock(i + 10, j + 6, k + 22, ACBlocks.unbreakableIce);
		world.setBlock(i + 10, j + 7, k + 6, ACBlocks.unbreakableIce);
		world.setBlock(i + 10, j + 7, k + 22, ACBlocks.unbreakableIce);
		world.setBlock(i + 10, j + 8, k + 6, ACBlocks.unbreakableIce);
		world.setBlock(i + 10, j + 8, k + 22, ACBlocks.unbreakableIce);
		world.setBlock(i + 10, j + 9, k + 7, ACBlocks.unbreakableIce);
		world.setBlock(i + 10, j + 9, k + 21, ACBlocks.unbreakableIce);
		world.setBlock(i + 10, j + 10, k + 8, ACBlocks.unbreakableIce);
		world.setBlock(i + 10, j + 10, k + 20, ACBlocks.unbreakableIce);
		world.setBlock(i + 10, j + 11, k + 9, ACBlocks.unbreakableIce);
		world.setBlock(i + 10, j + 11, k + 19, ACBlocks.unbreakableIce);
		world.setBlock(i + 10, j + 12, k + 10, ACBlocks.unbreakableIce);
		world.setBlock(i + 10, j + 12, k + 11, ACBlocks.unbreakableIce);
		world.setBlock(i + 10, j + 12, k + 12, ACBlocks.unbreakableIce);
		world.setBlock(i + 10, j + 12, k + 13, ACBlocks.unbreakableIce);
		world.setBlock(i + 10, j + 12, k + 14, ACBlocks.unbreakableIce);
		world.setBlock(i + 10, j + 12, k + 15, ACBlocks.unbreakableIce);
		world.setBlock(i + 10, j + 12, k + 16, ACBlocks.unbreakableIce);
		world.setBlock(i + 10, j + 12, k + 17, ACBlocks.unbreakableIce);
		world.setBlock(i + 10, j + 12, k + 18, ACBlocks.unbreakableIce);
		world.setBlock(i + 11, j + 0, k + 6, Blocks.snow);
		world.setBlock(i + 11, j + 0, k + 7, ACBlocks.acPlanks);
		world.setBlock(i + 11, j + 0, k + 8, ACBlocks.acPlanks);
		world.setBlock(i + 11, j + 0, k + 9, ACBlocks.acPlanks);
		world.setBlock(i + 11, j + 0, k + 10, ACBlocks.acPlanks);
		world.setBlock(i + 11, j + 0, k + 11, ACBlocks.acPlanks);
		world.setBlock(i + 11, j + 0, k + 12, ACBlocks.acPlanks);
		world.setBlock(i + 11, j + 0, k + 13, ACBlocks.acPlanks);
		world.setBlock(i + 11, j + 0, k + 14, ACBlocks.acPlanks);
		world.setBlock(i + 11, j + 0, k + 15, ACBlocks.acPlanks);
		world.setBlock(i + 11, j + 0, k + 16, ACBlocks.acPlanks);
		world.setBlock(i + 11, j + 0, k + 17, ACBlocks.acPlanks);
		world.setBlock(i + 11, j + 0, k + 18, ACBlocks.acPlanks);
		world.setBlock(i + 11, j + 0, k + 19, ACBlocks.acPlanks);
		world.setBlock(i + 11, j + 0, k + 20, ACBlocks.acPlanks);
		world.setBlock(i + 11, j + 0, k + 21, ACBlocks.acPlanks);
		world.setBlock(i + 11, j + 0, k + 22, Blocks.snow);
		world.setBlock(i + 11, j + 1, k + 6, Blocks.snow);
		world.setBlock(i + 11, j + 1, k + 7, Blocks.air);
		world.setBlock(i + 11, j + 1, k + 8, Blocks.air);
		world.setBlock(i + 11, j + 1, k + 9, Blocks.air);
		world.setBlock(i + 11, j + 1, k + 10, Blocks.air);
		world.setBlock(i + 11, j + 1, k + 11, Blocks.air);
		world.setBlock(i + 11, j + 1, k + 12, Blocks.air);
		world.setBlock(i + 11, j + 1, k + 13, Blocks.air);
		world.setBlock(i + 11, j + 1, k + 14, Blocks.air);
		world.setBlock(i + 11, j + 1, k + 15, Blocks.air);
		world.setBlock(i + 11, j + 1, k + 16, Blocks.air);
		world.setBlock(i + 11, j + 1, k + 17, Blocks.air);
		world.setBlock(i + 11, j + 1, k + 18, Blocks.air);
		world.setBlock(i + 11, j + 1, k + 19, Blocks.air);
		world.setBlock(i + 11, j + 1, k + 20, Blocks.air);
		world.setBlock(i + 11, j + 1, k + 21, Blocks.air);
		world.setBlock(i + 11, j + 1, k + 22, Blocks.snow);
		world.setBlock(i + 11, j + 2, k + 6, ACBlocks.unbreakableIce);
		world.setBlock(i + 11, j + 2, k + 7, Blocks.air);
		world.setBlock(i + 11, j + 2, k + 8, Blocks.air);
		world.setBlock(i + 11, j + 2, k + 9, Blocks.air);
		world.setBlock(i + 11, j + 2, k + 10, Blocks.air);
		world.setBlock(i + 11, j + 2, k + 11, Blocks.air);
		world.setBlock(i + 11, j + 2, k + 12, Blocks.air);
		world.setBlock(i + 11, j + 2, k + 13, Blocks.air);
		world.setBlock(i + 11, j + 2, k + 14, Blocks.air);
		world.setBlock(i + 11, j + 2, k + 15, Blocks.air);
		world.setBlock(i + 11, j + 2, k + 16, Blocks.air);
		world.setBlock(i + 11, j + 2, k + 17, Blocks.air);
		world.setBlock(i + 11, j + 2, k + 18, Blocks.air);
		world.setBlock(i + 11, j + 2, k + 19, Blocks.air);
		world.setBlock(i + 11, j + 2, k + 20, Blocks.air);
		world.setBlock(i + 11, j + 2, k + 21, Blocks.air);
		world.setBlock(i + 11, j + 2, k + 22, ACBlocks.unbreakableIce);
		world.setBlock(i + 11, j + 3, k + 6, ACBlocks.unbreakableIce);
		world.setBlock(i + 11, j + 3, k + 22, ACBlocks.unbreakableIce);
		world.setBlock(i + 11, j + 4, k + 6, ACBlocks.unbreakableIce);
		world.setBlock(i + 11, j + 4, k + 22, ACBlocks.unbreakableIce);
		world.setBlock(i + 11, j + 5, k + 6, ACBlocks.unbreakableIce);
		world.setBlock(i + 11, j + 5, k + 22, ACBlocks.unbreakableIce);
		world.setBlock(i + 11, j + 6, k + 6, ACBlocks.unbreakableIce);
		world.setBlock(i + 11, j + 6, k + 22, ACBlocks.unbreakableIce);
		world.setBlock(i + 11, j + 7, k + 6, ACBlocks.unbreakableIce);
		world.setBlock(i + 11, j + 7, k + 22, ACBlocks.unbreakableIce);
		world.setBlock(i + 11, j + 8, k + 6, ACBlocks.unbreakableIce);
		world.setBlock(i + 11, j + 8, k + 22, ACBlocks.unbreakableIce);
		world.setBlock(i + 11, j + 9, k + 7, ACBlocks.unbreakableIce);
		world.setBlock(i + 11, j + 9, k + 21, ACBlocks.unbreakableIce);
		world.setBlock(i + 11, j + 10, k + 8, ACBlocks.unbreakableIce);
		world.setBlock(i + 11, j + 10, k + 20, ACBlocks.unbreakableIce);
		world.setBlock(i + 11, j + 11, k + 9, ACBlocks.unbreakableIce);
		world.setBlock(i + 11, j + 11, k + 19, ACBlocks.unbreakableIce);
		world.setBlock(i + 11, j + 12, k + 10, ACBlocks.unbreakableIce);
		world.setBlock(i + 11, j + 12, k + 11, ACBlocks.unbreakableIce);
		world.setBlock(i + 11, j + 12, k + 12, ACBlocks.unbreakableIce);
		world.setBlock(i + 11, j + 12, k + 13, ACBlocks.unbreakableIce);
		world.setBlock(i + 11, j + 12, k + 14, ACBlocks.unbreakableIce);
		world.setBlock(i + 11, j + 12, k + 15, ACBlocks.unbreakableIce);
		world.setBlock(i + 11, j + 12, k + 16, ACBlocks.unbreakableIce);
		world.setBlock(i + 11, j + 12, k + 17, ACBlocks.unbreakableIce);
		world.setBlock(i + 11, j + 12, k + 18, ACBlocks.unbreakableIce);
		world.setBlock(i + 12, j + 0, k + 6, Blocks.snow);
		world.setBlock(i + 12, j + 0, k + 7, ACBlocks.acPlanks);
		world.setBlock(i + 12, j + 0, k + 8, ACBlocks.acPlanks);
		world.setBlock(i + 12, j + 0, k + 9, ACBlocks.acPlanks);
		world.setBlock(i + 12, j + 0, k + 10, ACBlocks.acPlanks);
		world.setBlock(i + 12, j + 0, k + 11, ACBlocks.acPlanks);
		world.setBlock(i + 12, j + 0, k + 12, ACBlocks.acPlanks);
		world.setBlock(i + 12, j + 0, k + 13, ACBlocks.acPlanks);
		world.setBlock(i + 12, j + 0, k + 14, ACBlocks.acPlanks);
		world.setBlock(i + 12, j + 0, k + 15, ACBlocks.acPlanks);
		world.setBlock(i + 12, j + 0, k + 16, ACBlocks.acPlanks);
		world.setBlock(i + 12, j + 0, k + 17, ACBlocks.acPlanks);
		world.setBlock(i + 12, j + 0, k + 18, ACBlocks.acPlanks);
		world.setBlock(i + 12, j + 0, k + 19, ACBlocks.acPlanks);
		world.setBlock(i + 12, j + 0, k + 20, ACBlocks.acPlanks);
		world.setBlock(i + 12, j + 0, k + 21, ACBlocks.acPlanks);
		world.setBlock(i + 12, j + 0, k + 22, Blocks.snow);
		world.setBlock(i + 12, j + 1, k + 6, Blocks.snow);
		world.setBlock(i + 12, j + 1, k + 7, Blocks.air);
		world.setBlock(i + 12, j + 1, k + 8, Blocks.air);
		world.setBlock(i + 12, j + 1, k + 9, Blocks.air);
		world.setBlock(i + 12, j + 1, k + 10, Blocks.air);
		world.setBlock(i + 12, j + 1, k + 11, Blocks.air);
		world.setBlock(i + 12, j + 1, k + 12, Blocks.air);
		world.setBlock(i + 12, j + 1, k + 13, Blocks.air);
		world.setBlock(i + 12, j + 1, k + 14, Blocks.air);
		world.setBlock(i + 12, j + 1, k + 15, Blocks.air);
		world.setBlock(i + 12, j + 1, k + 16, Blocks.air);
		world.setBlock(i + 12, j + 1, k + 17, Blocks.air);
		world.setBlock(i + 12, j + 1, k + 18, Blocks.air);
		world.setBlock(i + 12, j + 1, k + 19, Blocks.air);
		world.setBlock(i + 12, j + 1, k + 20, Blocks.air);
		world.setBlock(i + 12, j + 1, k + 21, Blocks.air);
		world.setBlock(i + 12, j + 1, k + 22, Blocks.snow);
		world.setBlock(i + 12, j + 2, k + 6, ACBlocks.unbreakableIce);
		world.setBlock(i + 12, j + 2, k + 7, Blocks.air);
		world.setBlock(i + 12, j + 2, k + 8, Blocks.air);
		world.setBlock(i + 12, j + 2, k + 9, Blocks.air);
		world.setBlock(i + 12, j + 2, k + 10, Blocks.air);
		world.setBlock(i + 12, j + 2, k + 11, Blocks.air);
		world.setBlock(i + 12, j + 2, k + 12, Blocks.air);
		world.setBlock(i + 12, j + 2, k + 13, Blocks.air);
		world.setBlock(i + 12, j + 2, k + 14, Blocks.air);
		world.setBlock(i + 12, j + 2, k + 15, Blocks.air);
		world.setBlock(i + 12, j + 2, k + 16, Blocks.air);
		world.setBlock(i + 12, j + 2, k + 17, Blocks.air);
		world.setBlock(i + 12, j + 2, k + 18, Blocks.air);
		world.setBlock(i + 12, j + 2, k + 19, Blocks.air);
		world.setBlock(i + 12, j + 2, k + 20, Blocks.air);
		world.setBlock(i + 12, j + 2, k + 21, Blocks.air);
		world.setBlock(i + 12, j + 2, k + 22, ACBlocks.unbreakableIce);
		world.setBlock(i + 12, j + 3, k + 6, ACBlocks.unbreakableIce);
		world.setBlock(i + 12, j + 3, k + 22, ACBlocks.unbreakableIce);
		world.setBlock(i + 12, j + 4, k + 6, ACBlocks.unbreakableIce);
		world.setBlock(i + 12, j + 4, k + 22, ACBlocks.unbreakableIce);
		world.setBlock(i + 12, j + 5, k + 6, ACBlocks.unbreakableIce);
		world.setBlock(i + 12, j + 5, k + 22, ACBlocks.unbreakableIce);
		world.setBlock(i + 12, j + 6, k + 6, ACBlocks.unbreakableIce);
		world.setBlock(i + 12, j + 6, k + 22, ACBlocks.unbreakableIce);
		world.setBlock(i + 12, j + 7, k + 6, ACBlocks.unbreakableIce);
		world.setBlock(i + 12, j + 7, k + 22, ACBlocks.unbreakableIce);
		world.setBlock(i + 12, j + 8, k + 6, ACBlocks.unbreakableIce);
		world.setBlock(i + 12, j + 8, k + 22, ACBlocks.unbreakableIce);
		world.setBlock(i + 12, j + 9, k + 7, ACBlocks.unbreakableIce);
		world.setBlock(i + 12, j + 9, k + 21, ACBlocks.unbreakableIce);
		world.setBlock(i + 12, j + 10, k + 8, ACBlocks.unbreakableIce);
		world.setBlock(i + 12, j + 10, k + 20, ACBlocks.unbreakableIce);
		world.setBlock(i + 12, j + 11, k + 9, ACBlocks.unbreakableIce);
		world.setBlock(i + 12, j + 11, k + 19, ACBlocks.unbreakableIce);
		world.setBlock(i + 12, j + 12, k + 10, ACBlocks.unbreakableIce);
		world.setBlock(i + 12, j + 12, k + 11, ACBlocks.unbreakableIce);
		world.setBlock(i + 12, j + 12, k + 12, ACBlocks.unbreakableIce);
		world.setBlock(i + 12, j + 12, k + 13, ACBlocks.unbreakableIce);
		world.setBlock(i + 12, j + 12, k + 14, ACBlocks.unbreakableIce);
		world.setBlock(i + 12, j + 12, k + 15, ACBlocks.unbreakableIce);
		world.setBlock(i + 12, j + 12, k + 16, ACBlocks.unbreakableIce);
		world.setBlock(i + 12, j + 12, k + 17, ACBlocks.unbreakableIce);
		world.setBlock(i + 12, j + 12, k + 18, ACBlocks.unbreakableIce);
		world.setBlock(i + 13, j + 0, k + 6, Blocks.snow);
		world.setBlock(i + 13, j + 0, k + 7, ACBlocks.acPlanks);
		world.setBlock(i + 13, j + 0, k + 8, ACBlocks.acPlanks);
		world.setBlock(i + 13, j + 0, k + 9, ACBlocks.acPlanks);
		world.setBlock(i + 13, j + 0, k + 10, ACBlocks.acPlanks);
		world.setBlock(i + 13, j + 0, k + 11, ACBlocks.acPlanks);
		world.setBlock(i + 13, j + 0, k + 12, ACBlocks.acPlanks);
		world.setBlock(i + 13, j + 0, k + 13, ACBlocks.acPlanks);
		world.setBlock(i + 13, j + 0, k + 14, ACBlocks.acPlanks);
		world.setBlock(i + 13, j + 0, k + 15, ACBlocks.acPlanks);
		world.setBlock(i + 13, j + 0, k + 16, ACBlocks.acPlanks);
		world.setBlock(i + 13, j + 0, k + 17, ACBlocks.acPlanks);
		world.setBlock(i + 13, j + 0, k + 18, ACBlocks.acPlanks);
		world.setBlock(i + 13, j + 0, k + 19, ACBlocks.acPlanks);
		world.setBlock(i + 13, j + 0, k + 20, ACBlocks.acPlanks);
		world.setBlock(i + 13, j + 0, k + 21, ACBlocks.acPlanks);
		world.setBlock(i + 13, j + 0, k + 22, Blocks.snow);
		world.setBlock(i + 13, j + 1, k + 6, Blocks.snow);
		world.setBlock(i + 13, j + 1, k + 7, Blocks.air);
		world.setBlock(i + 13, j + 1, k + 8, Blocks.air);
		world.setBlock(i + 13, j + 1, k + 9, Blocks.air);
		world.setBlock(i + 13, j + 1, k + 10, Blocks.air);
		world.setBlock(i + 13, j + 1, k + 11, ACBlocks.frostStairs);
		world.setBlock(i + 13, j + 1, k + 12, ACBlocks.frostStairs);
		world.setBlock(i + 13, j + 1, k + 13, Blocks.air);
		world.setBlock(i + 13, j + 1, k + 14, Blocks.air);
		world.setBlock(i + 13, j + 1, k + 15, Blocks.air);
		world.setBlock(i + 13, j + 1, k + 16, ACBlocks.frostStairs);
		world.setBlock(i + 13, j + 1, k + 17, ACBlocks.frostStairs);
		world.setBlock(i + 13, j + 1, k + 18, Blocks.air);
		world.setBlock(i + 13, j + 1, k + 19, Blocks.air);
		world.setBlock(i + 13, j + 1, k + 20, Blocks.air);
		world.setBlock(i + 13, j + 1, k + 21, Blocks.air);
		world.setBlock(i + 13, j + 1, k + 22, Blocks.snow);
		world.setBlock(i + 13, j + 2, k + 6, ACBlocks.unbreakableIce);
		world.setBlock(i + 13, j + 2, k + 7, Blocks.air);
		world.setBlock(i + 13, j + 2, k + 8, Blocks.air);
		world.setBlock(i + 13, j + 2, k + 9, Blocks.air);
		world.setBlock(i + 13, j + 2, k + 10, Blocks.air);
		world.setBlock(i + 13, j + 2, k + 11, Blocks.air);
		world.setBlock(i + 13, j + 2, k + 12, Blocks.air);
		world.setBlock(i + 13, j + 2, k + 13, Blocks.air);
		world.setBlock(i + 13, j + 2, k + 14, Blocks.air);
		world.setBlock(i + 13, j + 2, k + 15, Blocks.air);
		world.setBlock(i + 13, j + 2, k + 16, Blocks.air);
		world.setBlock(i + 13, j + 2, k + 17, Blocks.air);
		world.setBlock(i + 13, j + 2, k + 18, Blocks.air);
		world.setBlock(i + 13, j + 2, k + 19, Blocks.air);
		world.setBlock(i + 13, j + 2, k + 20, Blocks.air);
		world.setBlock(i + 13, j + 2, k + 21, Blocks.air);
		world.setBlock(i + 13, j + 2, k + 22, ACBlocks.unbreakableIce);
		world.setBlock(i + 13, j + 3, k + 6, ACBlocks.unbreakableIce);
		world.setBlock(i + 13, j + 3, k + 22, ACBlocks.unbreakableIce);
		world.setBlock(i + 13, j + 4, k + 6, ACBlocks.unbreakableIce);
		world.setBlock(i + 13, j + 4, k + 22, ACBlocks.unbreakableIce);
		world.setBlock(i + 13, j + 5, k + 6, ACBlocks.unbreakableIce);
		world.setBlock(i + 13, j + 5, k + 22, ACBlocks.unbreakableIce);
		world.setBlock(i + 13, j + 6, k + 6, ACBlocks.unbreakableIce);
		world.setBlock(i + 13, j + 6, k + 22, ACBlocks.unbreakableIce);
		world.setBlock(i + 13, j + 7, k + 6, ACBlocks.unbreakableIce);
		world.setBlock(i + 13, j + 7, k + 22, ACBlocks.unbreakableIce);
		world.setBlock(i + 13, j + 8, k + 6, ACBlocks.unbreakableIce);
		world.setBlock(i + 13, j + 8, k + 22, ACBlocks.unbreakableIce);
		world.setBlock(i + 13, j + 9, k + 7, ACBlocks.unbreakableIce);
		world.setBlock(i + 13, j + 9, k + 21, ACBlocks.unbreakableIce);
		world.setBlock(i + 13, j + 10, k + 8, ACBlocks.unbreakableIce);
		world.setBlock(i + 13, j + 10, k + 20, ACBlocks.unbreakableIce);
		world.setBlock(i + 13, j + 11, k + 9, ACBlocks.unbreakableIce);
		world.setBlock(i + 13, j + 11, k + 19, ACBlocks.unbreakableIce);
		world.setBlock(i + 13, j + 12, k + 10, ACBlocks.unbreakableIce);
		world.setBlock(i + 13, j + 12, k + 11, ACBlocks.unbreakableIce);
		world.setBlock(i + 13, j + 12, k + 12, ACBlocks.unbreakableIce);
		world.setBlock(i + 13, j + 12, k + 13, ACBlocks.unbreakableIce);
		world.setBlock(i + 13, j + 12, k + 14, ACBlocks.unbreakableIce);
		world.setBlock(i + 13, j + 12, k + 15, ACBlocks.unbreakableIce);
		world.setBlock(i + 13, j + 12, k + 16, ACBlocks.unbreakableIce);
		world.setBlock(i + 13, j + 12, k + 17, ACBlocks.unbreakableIce);
		world.setBlock(i + 13, j + 12, k + 18, ACBlocks.unbreakableIce);
		world.setBlock(i + 14, j + 0, k + 6, Blocks.snow);
		world.setBlock(i + 14, j + 0, k + 7, ACBlocks.acPlanks);
		world.setBlock(i + 14, j + 0, k + 8, ACBlocks.acPlanks);
		world.setBlock(i + 14, j + 0, k + 9, ACBlocks.acPlanks);
		world.setBlock(i + 14, j + 0, k + 10, ACBlocks.acPlanks);
		world.setBlock(i + 14, j + 0, k + 11, ACBlocks.acPlanks);
		world.setBlock(i + 14, j + 0, k + 12, ACBlocks.acPlanks);
		world.setBlock(i + 14, j + 0, k + 13, ACBlocks.acPlanks);
		world.setBlock(i + 14, j + 0, k + 14, ACBlocks.acPlanks);
		world.setBlock(i + 14, j + 0, k + 15, ACBlocks.acPlanks);
		world.setBlock(i + 14, j + 0, k + 16, ACBlocks.acPlanks);
		world.setBlock(i + 14, j + 0, k + 17, ACBlocks.acPlanks);
		world.setBlock(i + 14, j + 0, k + 18, ACBlocks.acPlanks);
		world.setBlock(i + 14, j + 0, k + 19, ACBlocks.acPlanks);
		world.setBlock(i + 14, j + 0, k + 20, ACBlocks.acPlanks);
		world.setBlock(i + 14, j + 0, k + 21, ACBlocks.acPlanks);
		world.setBlock(i + 14, j + 0, k + 22, Blocks.snow);
		world.setBlock(i + 14, j + 1, k + 6, Blocks.snow);
		world.setBlock(i + 14, j + 1, k + 7, Blocks.air);
		world.setBlock(i + 14, j + 1, k + 8, Blocks.air);
		world.setBlock(i + 14, j + 1, k + 9, Blocks.air);
		world.setBlock(i + 14, j + 1, k + 10, Blocks.air);
		world.setBlock(i + 14, j + 1, k + 11, Blocks.air);
		world.setBlock(i + 14, j + 1, k + 12, Blocks.air);
		world.setBlock(i + 14, j + 1, k + 13, Blocks.air);
		world.setBlock(i + 14, j + 1, k + 14, Blocks.air);
		world.setBlock(i + 14, j + 1, k + 15, Blocks.air);
		world.setBlock(i + 14, j + 1, k + 16, Blocks.air);
		world.setBlock(i + 14, j + 1, k + 17, Blocks.air);
		world.setBlock(i + 14, j + 1, k + 18, Blocks.air);
		world.setBlock(i + 14, j + 1, k + 19, Blocks.air);
		world.setBlock(i + 14, j + 1, k + 20, Blocks.air);
		world.setBlock(i + 14, j + 1, k + 21, Blocks.air);
		world.setBlock(i + 14, j + 1, k + 22, Blocks.snow);
		world.setBlock(i + 14, j + 2, k + 6, ACBlocks.unbreakableIce);
		world.setBlock(i + 14, j + 2, k + 7, Blocks.air);
		world.setBlock(i + 14, j + 2, k + 8, Blocks.air);
		world.setBlock(i + 14, j + 2, k + 9, Blocks.air);
		world.setBlock(i + 14, j + 2, k + 10, Blocks.air);
		world.setBlock(i + 14, j + 2, k + 11, Blocks.air);
		world.setBlock(i + 14, j + 2, k + 12, Blocks.air);
		world.setBlock(i + 14, j + 2, k + 13, Blocks.air);
		world.setBlock(i + 14, j + 2, k + 14, Blocks.air);
		world.setBlock(i + 14, j + 2, k + 15, Blocks.air);
		world.setBlock(i + 14, j + 2, k + 16, Blocks.air);
		world.setBlock(i + 14, j + 2, k + 17, Blocks.air);
		world.setBlock(i + 14, j + 2, k + 18, Blocks.air);
		world.setBlock(i + 14, j + 2, k + 19, Blocks.air);
		world.setBlock(i + 14, j + 2, k + 20, Blocks.air);
		world.setBlock(i + 14, j + 2, k + 21, Blocks.air);
		world.setBlock(i + 14, j + 2, k + 22, ACBlocks.unbreakableIce);
		world.setBlock(i + 14, j + 3, k + 6, ACBlocks.unbreakableIce);
		world.setBlock(i + 14, j + 3, k + 22, ACBlocks.unbreakableIce);
		world.setBlock(i + 14, j + 4, k + 6, ACBlocks.unbreakableIce);
		world.setBlock(i + 14, j + 4, k + 22, ACBlocks.unbreakableIce);
		world.setBlock(i + 14, j + 5, k + 6, ACBlocks.unbreakableIce);
		world.setBlock(i + 14, j + 5, k + 22, ACBlocks.unbreakableIce);
		world.setBlock(i + 14, j + 6, k + 6, ACBlocks.unbreakableIce);
		world.setBlock(i + 14, j + 6, k + 22, ACBlocks.unbreakableIce);
		world.setBlock(i + 14, j + 7, k + 6, ACBlocks.unbreakableIce);
		world.setBlock(i + 14, j + 7, k + 22, ACBlocks.unbreakableIce);
		world.setBlock(i + 14, j + 8, k + 6, ACBlocks.unbreakableIce);
		world.setBlock(i + 14, j + 8, k + 22, ACBlocks.unbreakableIce);
		world.setBlock(i + 14, j + 9, k + 7, ACBlocks.unbreakableIce);
		world.setBlock(i + 14, j + 9, k + 21, ACBlocks.unbreakableIce);
		world.setBlock(i + 14, j + 10, k + 8, ACBlocks.unbreakableIce);
		world.setBlock(i + 14, j + 10, k + 20, ACBlocks.unbreakableIce);
		world.setBlock(i + 14, j + 11, k + 9, ACBlocks.unbreakableIce);
		world.setBlock(i + 14, j + 11, k + 19, ACBlocks.unbreakableIce);
		world.setBlock(i + 14, j + 12, k + 10, ACBlocks.unbreakableIce);
		world.setBlock(i + 14, j + 12, k + 11, ACBlocks.unbreakableIce);
		world.setBlock(i + 14, j + 12, k + 12, ACBlocks.unbreakableIce);
		world.setBlock(i + 14, j + 12, k + 13, ACBlocks.unbreakableIce);
		world.setBlock(i + 14, j + 12, k + 14, ACBlocks.unbreakableIce);
		world.setBlock(i + 14, j + 12, k + 15, ACBlocks.unbreakableIce);
		world.setBlock(i + 14, j + 12, k + 16, ACBlocks.unbreakableIce);
		world.setBlock(i + 14, j + 12, k + 17, ACBlocks.unbreakableIce);
		world.setBlock(i + 14, j + 12, k + 18, ACBlocks.unbreakableIce);
		world.setBlock(i + 15, j + 0, k + 7, Blocks.snow);
		world.setBlock(i + 15, j + 0, k + 8, ACBlocks.acPlanks);
		world.setBlock(i + 15, j + 0, k + 9, ACBlocks.acPlanks);
		world.setBlock(i + 15, j + 0, k + 10, ACBlocks.acPlanks);
		world.setBlock(i + 15, j + 0, k + 11, ACBlocks.acPlanks);
		world.setBlock(i + 15, j + 0, k + 12, ACBlocks.acPlanks);
		world.setBlock(i + 15, j + 0, k + 13, ACBlocks.acPlanks);
		world.setBlock(i + 15, j + 0, k + 14, ACBlocks.acPlanks);
		world.setBlock(i + 15, j + 0, k + 15, ACBlocks.acPlanks);
		world.setBlock(i + 15, j + 0, k + 16, ACBlocks.acPlanks);
		world.setBlock(i + 15, j + 0, k + 17, ACBlocks.acPlanks);
		world.setBlock(i + 15, j + 0, k + 18, ACBlocks.acPlanks);
		world.setBlock(i + 15, j + 0, k + 19, ACBlocks.acPlanks);
		world.setBlock(i + 15, j + 0, k + 20, ACBlocks.acPlanks);
		world.setBlock(i + 15, j + 0, k + 21, Blocks.snow);
		world.setBlock(i + 15, j + 1, k + 7, Blocks.snow);
		world.setBlock(i + 15, j + 1, k + 8, Blocks.air);
		world.setBlock(i + 15, j + 1, k + 9, Blocks.air);
		world.setBlock(i + 15, j + 1, k + 10, Blocks.air);
		world.setBlock(i + 15, j + 1, k + 11, ACBlocks.frostStairs);
		world.setBlock(i + 15, j + 1, k + 12, ACBlocks.frostStairs);
		world.setBlock(i + 15, j + 1, k + 13, Blocks.air);
		world.setBlock(i + 15, j + 1, k + 14, Blocks.air);
		world.setBlock(i + 15, j + 1, k + 15, Blocks.air);
		world.setBlock(i + 15, j + 1, k + 16, ACBlocks.frostStairs);
		world.setBlock(i + 15, j + 1, k + 17, ACBlocks.frostStairs);
		world.setBlock(i + 15, j + 1, k + 18, Blocks.air);
		world.setBlock(i + 15, j + 1, k + 19, Blocks.air);
		world.setBlock(i + 15, j + 1, k + 20, Blocks.air);
		world.setBlock(i + 15, j + 1, k + 21, Blocks.snow);
		world.setBlock(i + 15, j + 2, k + 7, ACBlocks.unbreakableIce);
		world.setBlock(i + 15, j + 2, k + 8, Blocks.air);
		world.setBlock(i + 15, j + 2, k + 9, Blocks.air);
		world.setBlock(i + 15, j + 2, k + 10, Blocks.air);
		world.setBlock(i + 15, j + 2, k + 11, Blocks.air);
		world.setBlock(i + 15, j + 2, k + 12, Blocks.air);
		world.setBlock(i + 15, j + 2, k + 13, Blocks.air);
		world.setBlock(i + 15, j + 2, k + 14, Blocks.air);
		world.setBlock(i + 15, j + 2, k + 15, Blocks.air);
		world.setBlock(i + 15, j + 2, k + 16, Blocks.air);
		world.setBlock(i + 15, j + 2, k + 17, Blocks.air);
		world.setBlock(i + 15, j + 2, k + 18, Blocks.air);
		world.setBlock(i + 15, j + 2, k + 19, Blocks.air);
		world.setBlock(i + 15, j + 2, k + 20, Blocks.air);
		world.setBlock(i + 15, j + 2, k + 21, ACBlocks.unbreakableIce);
		world.setBlock(i + 15, j + 3, k + 7, ACBlocks.unbreakableIce);
		world.setBlock(i + 15, j + 3, k + 21, ACBlocks.unbreakableIce);
		world.setBlock(i + 15, j + 4, k + 7, ACBlocks.unbreakableIce);
		world.setBlock(i + 15, j + 4, k + 21, ACBlocks.unbreakableIce);
		world.setBlock(i + 15, j + 5, k + 7, ACBlocks.unbreakableIce);
		world.setBlock(i + 15, j + 5, k + 21, ACBlocks.unbreakableIce);
		world.setBlock(i + 15, j + 6, k + 7, ACBlocks.unbreakableIce);
		world.setBlock(i + 15, j + 6, k + 21, ACBlocks.unbreakableIce);
		world.setBlock(i + 15, j + 7, k + 7, ACBlocks.unbreakableIce);
		world.setBlock(i + 15, j + 7, k + 21, ACBlocks.unbreakableIce);
		world.setBlock(i + 15, j + 8, k + 7, ACBlocks.unbreakableIce);
		world.setBlock(i + 15, j + 8, k + 21, ACBlocks.unbreakableIce);
		world.setBlock(i + 15, j + 9, k + 8, ACBlocks.unbreakableIce);
		world.setBlock(i + 15, j + 9, k + 20, ACBlocks.unbreakableIce);
		world.setBlock(i + 15, j + 10, k + 9, ACBlocks.unbreakableIce);
		world.setBlock(i + 15, j + 10, k + 19, ACBlocks.unbreakableIce);
		world.setBlock(i + 15, j + 11, k + 10, ACBlocks.unbreakableIce);
		world.setBlock(i + 15, j + 11, k + 18, ACBlocks.unbreakableIce);
		world.setBlock(i + 15, j + 12, k + 11, ACBlocks.unbreakableIce);
		world.setBlock(i + 15, j + 12, k + 12, ACBlocks.unbreakableIce);
		world.setBlock(i + 15, j + 12, k + 13, ACBlocks.unbreakableIce);
		world.setBlock(i + 15, j + 12, k + 14, ACBlocks.unbreakableIce);
		world.setBlock(i + 15, j + 12, k + 15, ACBlocks.unbreakableIce);
		world.setBlock(i + 15, j + 12, k + 16, ACBlocks.unbreakableIce);
		world.setBlock(i + 15, j + 12, k + 17, ACBlocks.unbreakableIce);
		world.setBlock(i + 16, j + 0, k + 8, Blocks.snow);
		world.setBlock(i + 16, j + 0, k + 9, ACBlocks.acPlanks);
		world.setBlock(i + 16, j + 0, k + 10, ACBlocks.acPlanks);
		world.setBlock(i + 16, j + 0, k + 11, ACBlocks.acPlanks);
		world.setBlock(i + 16, j + 0, k + 12, ACBlocks.acPlanks);
		world.setBlock(i + 16, j + 0, k + 13, ACBlocks.acPlanks);
		world.setBlock(i + 16, j + 0, k + 14, ACBlocks.acPlanks);
		world.setBlock(i + 16, j + 0, k + 15, ACBlocks.acPlanks);
		world.setBlock(i + 16, j + 0, k + 16, ACBlocks.acPlanks);
		world.setBlock(i + 16, j + 0, k + 17, ACBlocks.acPlanks);
		world.setBlock(i + 16, j + 0, k + 18, ACBlocks.acPlanks);
		world.setBlock(i + 16, j + 0, k + 19, ACBlocks.acPlanks);
		world.setBlock(i + 16, j + 0, k + 20, Blocks.snow);
		world.setBlock(i + 16, j + 1, k + 8, Blocks.snow);
		world.setBlock(i + 16, j + 1, k + 9, ACBlocks.arcaneStone);
		world.setBlock(i + 16, j + 1, k + 10, Blocks.air);
		world.setBlock(i + 16, j + 1, k + 11, Blocks.air);
		world.setBlock(i + 16, j + 1, k + 12, Blocks.air);
		world.setBlock(i + 16, j + 1, k + 13, Blocks.air);
		world.setBlock(i + 16, j + 1, k + 14, Blocks.air);
		world.setBlock(i + 16, j + 1, k + 15, Blocks.air);
		world.setBlock(i + 16, j + 1, k + 16, Blocks.air);
		world.setBlock(i + 16, j + 1, k + 17, Blocks.air);
		world.setBlock(i + 16, j + 1, k + 18, Blocks.air);
		world.setBlock(i + 16, j + 1, k + 19, ACBlocks.arcaneStone);
		world.setBlock(i + 16, j + 1, k + 20, Blocks.snow);
		world.setBlock(i + 16, j + 2, k + 8, ACBlocks.unbreakableIce);
		world.setBlock(i + 16, j + 2, k + 9, Blocks.air);
		world.setBlock(i + 16, j + 2, k + 10, Blocks.air);
		world.setBlock(i + 16, j + 2, k + 11, Blocks.air);
		world.setBlock(i + 16, j + 2, k + 12, Blocks.air);
		world.setBlock(i + 16, j + 2, k + 13, Blocks.air);
		world.setBlock(i + 16, j + 2, k + 14, Blocks.air);
		world.setBlock(i + 16, j + 2, k + 15, Blocks.air);
		world.setBlock(i + 16, j + 2, k + 16, Blocks.air);
		world.setBlock(i + 16, j + 2, k + 17, Blocks.air);
		world.setBlock(i + 16, j + 2, k + 18, Blocks.air);
		world.setBlock(i + 16, j + 2, k + 19, Blocks.air);
		world.setBlock(i + 16, j + 2, k + 20, ACBlocks.unbreakableIce);
		world.setBlock(i + 16, j + 3, k + 8, ACBlocks.unbreakableIce);
		world.setBlock(i + 16, j + 3, k + 20, ACBlocks.unbreakableIce);
		world.setBlock(i + 16, j + 4, k + 8, ACBlocks.unbreakableIce);
		world.setBlock(i + 16, j + 4, k + 20, ACBlocks.unbreakableIce);
		world.setBlock(i + 16, j + 5, k + 8, ACBlocks.unbreakableIce);
		world.setBlock(i + 16, j + 5, k + 20, ACBlocks.unbreakableIce);
		world.setBlock(i + 16, j + 6, k + 8, ACBlocks.unbreakableIce);
		world.setBlock(i + 16, j + 6, k + 20, ACBlocks.unbreakableIce);
		world.setBlock(i + 16, j + 7, k + 8, ACBlocks.unbreakableIce);
		world.setBlock(i + 16, j + 7, k + 20, ACBlocks.unbreakableIce);
		world.setBlock(i + 16, j + 8, k + 8, ACBlocks.unbreakableIce);
		world.setBlock(i + 16, j + 8, k + 20, ACBlocks.unbreakableIce);
		world.setBlock(i + 16, j + 9, k + 9, ACBlocks.unbreakableIce);
		world.setBlock(i + 16, j + 9, k + 19, ACBlocks.unbreakableIce);
		world.setBlock(i + 16, j + 10, k + 10, ACBlocks.unbreakableIce);
		world.setBlock(i + 16, j + 10, k + 18, ACBlocks.unbreakableIce);
		world.setBlock(i + 16, j + 11, k + 11, ACBlocks.unbreakableIce);
		world.setBlock(i + 16, j + 11, k + 12, ACBlocks.unbreakableIce);
		world.setBlock(i + 16, j + 11, k + 17, ACBlocks.unbreakableIce);
		world.setBlock(i + 16, j + 12, k + 12, ACBlocks.unbreakableIce);
		world.setBlock(i + 16, j + 12, k + 13, ACBlocks.unbreakableIce);
		world.setBlock(i + 16, j + 12, k + 14, ACBlocks.unbreakableIce);
		world.setBlock(i + 16, j + 12, k + 15, ACBlocks.unbreakableIce);
		world.setBlock(i + 16, j + 12, k + 16, ACBlocks.unbreakableIce);
		world.setBlock(i + 17, j + 0, k + 9, Blocks.snow);
		world.setBlock(i + 17, j + 0, k + 10, ACBlocks.acPlanks);
		world.setBlock(i + 17, j + 0, k + 11, ACBlocks.acPlanks);
		world.setBlock(i + 17, j + 0, k + 12, ACBlocks.acPlanks);
		world.setBlock(i + 17, j + 0, k + 13, ACBlocks.acPlanks);
		world.setBlock(i + 17, j + 0, k + 14, ACBlocks.acPlanks);
		world.setBlock(i + 17, j + 0, k + 15, ACBlocks.acPlanks);
		world.setBlock(i + 17, j + 0, k + 16, ACBlocks.acPlanks);
		world.setBlock(i + 17, j + 0, k + 17, ACBlocks.acPlanks);
		world.setBlock(i + 17, j + 0, k + 18, ACBlocks.acPlanks);
		world.setBlock(i + 17, j + 0, k + 19, Blocks.snow);
		world.setBlock(i + 17, j + 1, k + 9, Blocks.snow);
		world.setBlock(i + 17, j + 1, k + 10, Blocks.air);
		world.setBlock(i + 17, j + 1, k + 11, ACBlocks.frostStairs);
		world.setBlock(i + 17, j + 1, k + 12, ACBlocks.frostStairs);
		world.setBlock(i + 17, j + 1, k + 13, Blocks.air);
		world.setBlock(i + 17, j + 1, k + 14, Blocks.air);
		world.setBlock(i + 17, j + 1, k + 15, Blocks.air);
		world.setBlock(i + 17, j + 1, k + 16, ACBlocks.frostStairs);
		world.setBlock(i + 17, j + 1, k + 17, ACBlocks.frostStairs);
		world.setBlock(i + 17, j + 1, k + 18, Blocks.air);
		world.setBlock(i + 17, j + 1, k + 19, Blocks.snow);
		world.setBlock(i + 17, j + 2, k + 9, ACBlocks.unbreakableIce);
		world.setBlock(i + 17, j + 2, k + 10, Blocks.air);
		world.setBlock(i + 17, j + 2, k + 11, Blocks.air);
		world.setBlock(i + 17, j + 2, k + 12, Blocks.air);
		world.setBlock(i + 17, j + 2, k + 13, Blocks.air);
		world.setBlock(i + 17, j + 2, k + 14, Blocks.air);
		world.setBlock(i + 17, j + 2, k + 15, Blocks.air);
		world.setBlock(i + 17, j + 2, k + 16, Blocks.air);
		world.setBlock(i + 17, j + 2, k + 17, Blocks.air);
		world.setBlock(i + 17, j + 2, k + 18, Blocks.air);
		world.setBlock(i + 17, j + 2, k + 19, ACBlocks.unbreakableIce);
		world.setBlock(i + 17, j + 3, k + 9, ACBlocks.unbreakableIce);
		world.setBlock(i + 17, j + 3, k + 19, ACBlocks.unbreakableIce);
		world.setBlock(i + 17, j + 4, k + 9, ACBlocks.unbreakableIce);
		world.setBlock(i + 17, j + 4, k + 19, ACBlocks.unbreakableIce);
		world.setBlock(i + 17, j + 5, k + 9, ACBlocks.unbreakableIce);
		world.setBlock(i + 17, j + 5, k + 19, ACBlocks.unbreakableIce);
		world.setBlock(i + 17, j + 6, k + 9, ACBlocks.unbreakableIce);
		world.setBlock(i + 17, j + 6, k + 19, ACBlocks.unbreakableIce);
		world.setBlock(i + 17, j + 7, k + 9, ACBlocks.unbreakableIce);
		world.setBlock(i + 17, j + 7, k + 19, ACBlocks.unbreakableIce);
		world.setBlock(i + 17, j + 8, k + 9, ACBlocks.unbreakableIce);
		world.setBlock(i + 17, j + 8, k + 19, ACBlocks.unbreakableIce);
		world.setBlock(i + 17, j + 9, k + 10, ACBlocks.unbreakableIce);
		world.setBlock(i + 17, j + 9, k + 18, ACBlocks.unbreakableIce);
		world.setBlock(i + 17, j + 10, k + 11, ACBlocks.unbreakableIce);
		world.setBlock(i + 17, j + 10, k + 17, ACBlocks.unbreakableIce);
		world.setBlock(i + 17, j + 11, k + 12, ACBlocks.unbreakableIce);
		world.setBlock(i + 17, j + 11, k + 16, ACBlocks.unbreakableIce);
		world.setBlock(i + 17, j + 12, k + 13, ACBlocks.unbreakableIce);
		world.setBlock(i + 17, j + 12, k + 14, ACBlocks.unbreakableIce);
		world.setBlock(i + 17, j + 12, k + 15, ACBlocks.unbreakableIce);
		world.setBlock(i + 18, j + 0, k + 9, Blocks.snow);
		world.setBlock(i + 18, j + 0, k + 10, ACBlocks.acPlanks);
		world.setBlock(i + 18, j + 0, k + 11, ACBlocks.acPlanks);
		world.setBlock(i + 18, j + 0, k + 12, ACBlocks.acPlanks);
		world.setBlock(i + 18, j + 0, k + 13, ACBlocks.acPlanks);
		world.setBlock(i + 18, j + 0, k + 14, ACBlocks.acPlanks);
		world.setBlock(i + 18, j + 0, k + 15, ACBlocks.acPlanks);
		world.setBlock(i + 18, j + 0, k + 16, ACBlocks.acPlanks);
		world.setBlock(i + 18, j + 0, k + 17, ACBlocks.acPlanks);
		world.setBlock(i + 18, j + 0, k + 18, ACBlocks.acPlanks);
		world.setBlock(i + 18, j + 0, k + 19, Blocks.snow);
		world.setBlock(i + 18, j + 1, k + 9, Blocks.snow);
		world.setBlock(i + 18, j + 1, k + 10, Blocks.air);
		world.setBlock(i + 18, j + 1, k + 11, Blocks.air);
		world.setBlock(i + 18, j + 1, k + 12, Blocks.air);
		world.setBlock(i + 18, j + 1, k + 13, Blocks.air);
		world.setBlock(i + 18, j + 1, k + 14, Blocks.air);
		world.setBlock(i + 18, j + 1, k + 15, Blocks.air);
		world.setBlock(i + 18, j + 1, k + 16, Blocks.air);
		world.setBlock(i + 18, j + 1, k + 17, Blocks.air);
		world.setBlock(i + 18, j + 1, k + 18, Blocks.air);
		world.setBlock(i + 18, j + 1, k + 19, Blocks.snow);
		world.setBlock(i + 18, j + 2, k + 9, ACBlocks.unbreakableIce);
		world.setBlock(i + 18, j + 2, k + 10, Blocks.air);
		world.setBlock(i + 18, j + 2, k + 11, Blocks.air);
		world.setBlock(i + 18, j + 2, k + 12, Blocks.air);
		world.setBlock(i + 18, j + 2, k + 13, Blocks.air);
		world.setBlock(i + 18, j + 2, k + 14, Blocks.air);
		world.setBlock(i + 18, j + 2, k + 15, Blocks.air);
		world.setBlock(i + 18, j + 2, k + 16, Blocks.air);
		world.setBlock(i + 18, j + 2, k + 17, Blocks.air);
		world.setBlock(i + 18, j + 2, k + 18, Blocks.air);
		world.setBlock(i + 18, j + 2, k + 19, ACBlocks.unbreakableIce);
		world.setBlock(i + 18, j + 3, k + 9, ACBlocks.unbreakableIce);
		world.setBlock(i + 18, j + 3, k + 19, ACBlocks.unbreakableIce);
		world.setBlock(i + 18, j + 4, k + 9, ACBlocks.unbreakableIce);
		world.setBlock(i + 18, j + 4, k + 19, ACBlocks.unbreakableIce);
		world.setBlock(i + 18, j + 5, k + 9, ACBlocks.unbreakableIce);
		world.setBlock(i + 18, j + 5, k + 19, ACBlocks.unbreakableIce);
		world.setBlock(i + 18, j + 6, k + 9, ACBlocks.unbreakableIce);
		world.setBlock(i + 18, j + 6, k + 19, ACBlocks.unbreakableIce);
		world.setBlock(i + 18, j + 7, k + 9, ACBlocks.unbreakableIce);
		world.setBlock(i + 18, j + 7, k + 19, ACBlocks.unbreakableIce);
		world.setBlock(i + 18, j + 8, k + 9, ACBlocks.unbreakableIce);
		world.setBlock(i + 18, j + 8, k + 19, ACBlocks.unbreakableIce);
		world.setBlock(i + 18, j + 9, k + 10, ACBlocks.unbreakableIce);
		world.setBlock(i + 18, j + 9, k + 18, ACBlocks.unbreakableIce);
		world.setBlock(i + 18, j + 10, k + 11, ACBlocks.unbreakableIce);
		world.setBlock(i + 18, j + 10, k + 17, ACBlocks.unbreakableIce);
		world.setBlock(i + 18, j + 11, k + 12, ACBlocks.unbreakableIce);
		world.setBlock(i + 18, j + 11, k + 16, ACBlocks.unbreakableIce);
		world.setBlock(i + 18, j + 12, k + 13, ACBlocks.unbreakableIce);
		world.setBlock(i + 18, j + 12, k + 14, ACBlocks.unbreakableIce);
		world.setBlock(i + 18, j + 12, k + 15, ACBlocks.unbreakableIce);
		world.setBlock(i + 19, j + 0, k + 9, Blocks.snow);
		world.setBlock(i + 19, j + 0, k + 10, ACBlocks.acPlanks);
		world.setBlock(i + 19, j + 0, k + 11, ACBlocks.acPlanks);
		world.setBlock(i + 19, j + 0, k + 12, ACBlocks.acPlanks);
		world.setBlock(i + 19, j + 0, k + 13, ACBlocks.acPlanks);
		world.setBlock(i + 19, j + 0, k + 14, ACBlocks.acPlanks);
		world.setBlock(i + 19, j + 0, k + 15, ACBlocks.acPlanks);
		world.setBlock(i + 19, j + 0, k + 16, ACBlocks.acPlanks);
		world.setBlock(i + 19, j + 0, k + 17, ACBlocks.acPlanks);
		world.setBlock(i + 19, j + 0, k + 18, ACBlocks.acPlanks);
		world.setBlock(i + 19, j + 0, k + 19, Blocks.snow);
		world.setBlock(i + 19, j + 1, k + 9, Blocks.snow);
		world.setBlock(i + 19, j + 1, k + 10, Blocks.air);
		world.setBlock(i + 19, j + 1, k + 11, Blocks.air);
		world.setBlock(i + 19, j + 1, k + 12, Blocks.air);
		world.setBlock(i + 19, j + 1, k + 13, Blocks.air);
		world.setBlock(i + 19, j + 1, k + 14, Blocks.air);
		world.setBlock(i + 19, j + 1, k + 15, Blocks.air);
		world.setBlock(i + 19, j + 1, k + 16, Blocks.air);
		world.setBlock(i + 19, j + 1, k + 17, Blocks.air);
		world.setBlock(i + 19, j + 1, k + 18, Blocks.air);
		world.setBlock(i + 19, j + 1, k + 19, Blocks.snow);
		world.setBlock(i + 19, j + 2, k + 9, ACBlocks.unbreakableIce);
		world.setBlock(i + 19, j + 2, k + 10, Blocks.air);
		world.setBlock(i + 19, j + 2, k + 11, Blocks.air);
		world.setBlock(i + 19, j + 2, k + 12, Blocks.air);
		world.setBlock(i + 19, j + 2, k + 13, Blocks.air);
		world.setBlock(i + 19, j + 2, k + 14, Blocks.air);
		world.setBlock(i + 19, j + 2, k + 15, Blocks.air);
		world.setBlock(i + 19, j + 2, k + 16, Blocks.air);
		world.setBlock(i + 19, j + 2, k + 17, Blocks.air);
		world.setBlock(i + 19, j + 2, k + 18, Blocks.air);
		world.setBlock(i + 19, j + 2, k + 19, ACBlocks.unbreakableIce);
		world.setBlock(i + 19, j + 3, k + 9, ACBlocks.unbreakableIce);
		world.setBlock(i + 19, j + 3, k + 19, ACBlocks.unbreakableIce);
		world.setBlock(i + 19, j + 4, k + 9, ACBlocks.unbreakableIce);
		world.setBlock(i + 19, j + 4, k + 19, ACBlocks.unbreakableIce);
		world.setBlock(i + 19, j + 5, k + 9, ACBlocks.unbreakableIce);
		world.setBlock(i + 19, j + 5, k + 19, ACBlocks.unbreakableIce);
		world.setBlock(i + 19, j + 6, k + 9, ACBlocks.unbreakableIce);
		world.setBlock(i + 19, j + 6, k + 19, ACBlocks.unbreakableIce);
		world.setBlock(i + 19, j + 7, k + 9, ACBlocks.unbreakableIce);
		world.setBlock(i + 19, j + 7, k + 19, ACBlocks.unbreakableIce);
		world.setBlock(i + 19, j + 8, k + 9, ACBlocks.unbreakableIce);
		world.setBlock(i + 19, j + 8, k + 19, ACBlocks.unbreakableIce);
		world.setBlock(i + 19, j + 9, k + 10, ACBlocks.unbreakableIce);
		world.setBlock(i + 19, j + 9, k + 18, ACBlocks.unbreakableIce);
		world.setBlock(i + 19, j + 10, k + 11, ACBlocks.unbreakableIce);
		world.setBlock(i + 19, j + 10, k + 17, ACBlocks.unbreakableIce);
		world.setBlock(i + 19, j + 11, k + 12, ACBlocks.unbreakableIce);
		world.setBlock(i + 19, j + 11, k + 16, ACBlocks.unbreakableIce);
		world.setBlock(i + 19, j + 12, k + 13, ACBlocks.unbreakableIce);
		world.setBlock(i + 19, j + 12, k + 14, ACBlocks.unbreakableIce);
		world.setBlock(i + 19, j + 12, k + 15, ACBlocks.unbreakableIce);
		world.setBlock(i + 20, j + 0, k + 9, Blocks.snow);
		world.setBlock(i + 20, j + 0, k + 10, ACBlocks.acPlanks);
		world.setBlock(i + 20, j + 0, k + 11, ACBlocks.acPlanks);
		world.setBlock(i + 20, j + 0, k + 12, ACBlocks.acPlanks);
		world.setBlock(i + 20, j + 0, k + 13, ACBlocks.acPlanks);
		world.setBlock(i + 20, j + 0, k + 14, ACBlocks.acPlanks);
		world.setBlock(i + 20, j + 0, k + 15, ACBlocks.acPlanks);
		world.setBlock(i + 20, j + 0, k + 16, ACBlocks.acPlanks);
		world.setBlock(i + 20, j + 0, k + 17, ACBlocks.acPlanks);
		world.setBlock(i + 20, j + 0, k + 18, ACBlocks.acPlanks);
		world.setBlock(i + 20, j + 0, k + 19, Blocks.snow);
		world.setBlock(i + 20, j + 1, k + 9, Blocks.snow);
		world.setBlock(i + 20, j + 1, k + 10, Blocks.air);
		world.setBlock(i + 20, j + 1, k + 11, Blocks.air);
		world.setBlock(i + 20, j + 1, k + 12, Blocks.air);
		world.setBlock(i + 20, j + 1, k + 13, Blocks.air);
		world.setBlock(i + 20, j + 1, k + 14, Blocks.air);
		world.setBlock(i + 20, j + 1, k + 15, Blocks.air);
		world.setBlock(i + 20, j + 1, k + 16, Blocks.air);
		world.setBlock(i + 20, j + 1, k + 17, Blocks.air);
		world.setBlock(i + 20, j + 1, k + 18, Blocks.air);
		world.setBlock(i + 20, j + 1, k + 19, Blocks.snow);
		world.setBlock(i + 20, j + 2, k + 9, ACBlocks.unbreakableIce);
		world.setBlock(i + 20, j + 2, k + 10, Blocks.air);
		world.setBlock(i + 20, j + 2, k + 11, Blocks.air);
		world.setBlock(i + 20, j + 2, k + 12, Blocks.air);
		world.setBlock(i + 20, j + 2, k + 13, Blocks.air);
		world.setBlock(i + 20, j + 2, k + 14, Blocks.air);
		world.setBlock(i + 20, j + 2, k + 15, Blocks.air);
		world.setBlock(i + 20, j + 2, k + 16, Blocks.air);
		world.setBlock(i + 20, j + 2, k + 17, Blocks.air);
		world.setBlock(i + 20, j + 2, k + 18, Blocks.air);
		world.setBlock(i + 20, j + 2, k + 19, ACBlocks.unbreakableIce);
		world.setBlock(i + 20, j + 3, k + 9, ACBlocks.unbreakableIce);
		world.setBlock(i + 20, j + 3, k + 19, ACBlocks.unbreakableIce);
		world.setBlock(i + 20, j + 4, k + 9, ACBlocks.unbreakableIce);
		world.setBlock(i + 20, j + 4, k + 19, ACBlocks.unbreakableIce);
		world.setBlock(i + 20, j + 5, k + 9, ACBlocks.unbreakableIce);
		world.setBlock(i + 20, j + 5, k + 19, ACBlocks.unbreakableIce);
		world.setBlock(i + 20, j + 6, k + 9, ACBlocks.unbreakableIce);
		world.setBlock(i + 20, j + 6, k + 19, ACBlocks.unbreakableIce);
		world.setBlock(i + 20, j + 7, k + 9, ACBlocks.unbreakableIce);
		world.setBlock(i + 20, j + 7, k + 19, ACBlocks.unbreakableIce);
		world.setBlock(i + 20, j + 8, k + 9, ACBlocks.unbreakableIce);
		world.setBlock(i + 20, j + 8, k + 19, ACBlocks.unbreakableIce);
		world.setBlock(i + 20, j + 9, k + 10, ACBlocks.unbreakableIce);
		world.setBlock(i + 20, j + 9, k + 18, ACBlocks.unbreakableIce);
		world.setBlock(i + 20, j + 10, k + 11, ACBlocks.unbreakableIce);
		world.setBlock(i + 20, j + 10, k + 17, ACBlocks.unbreakableIce);
		world.setBlock(i + 20, j + 11, k + 12, ACBlocks.unbreakableIce);
		world.setBlock(i + 20, j + 11, k + 13, ACBlocks.unbreakableIce);
		world.setBlock(i + 20, j + 11, k + 14, ACBlocks.unbreakableIce);
		world.setBlock(i + 20, j + 11, k + 15, ACBlocks.unbreakableIce);
		world.setBlock(i + 20, j + 11, k + 16, ACBlocks.unbreakableIce);
		world.setBlock(i + 21, j + 0, k + 10, Blocks.snow);
		world.setBlock(i + 21, j + 0, k + 11, ACBlocks.acPlanks);
		world.setBlock(i + 21, j + 0, k + 12, ACBlocks.acPlanks);
		world.setBlock(i + 21, j + 0, k + 13, ACBlocks.acPlanks);
		world.setBlock(i + 21, j + 0, k + 14, ACBlocks.acPlanks);
		world.setBlock(i + 21, j + 0, k + 15, ACBlocks.acPlanks);
		world.setBlock(i + 21, j + 0, k + 16, ACBlocks.acPlanks);
		world.setBlock(i + 21, j + 0, k + 17, ACBlocks.acPlanks);
		world.setBlock(i + 21, j + 0, k + 18, Blocks.snow);
		world.setBlock(i + 21, j + 1, k + 10, Blocks.snow);
		world.setBlock(i + 21, j + 1, k + 11, Blocks.air);
		world.setBlock(i + 21, j + 1, k + 12, Blocks.air);
		world.setBlock(i + 21, j + 1, k + 13, Blocks.air);
		world.setBlock(i + 21, j + 1, k + 14, Blocks.air);
		world.setBlock(i + 21, j + 1, k + 15, Blocks.air);
		world.setBlock(i + 21, j + 1, k + 16, Blocks.air);
		world.setBlock(i + 21, j + 1, k + 17, Blocks.air);
		world.setBlock(i + 21, j + 1, k + 18, Blocks.snow);
		world.setBlock(i + 21, j + 2, k + 10, ACBlocks.unbreakableIce);
		world.setBlock(i + 21, j + 2, k + 11, Blocks.air);
		world.setBlock(i + 21, j + 2, k + 12, Blocks.air);
		world.setBlock(i + 21, j + 2, k + 13, Blocks.air);
		world.setBlock(i + 21, j + 2, k + 14, Blocks.air);
		world.setBlock(i + 21, j + 2, k + 15, Blocks.air);
		world.setBlock(i + 21, j + 2, k + 16, Blocks.air);
		world.setBlock(i + 21, j + 2, k + 17, Blocks.air);
		world.setBlock(i + 21, j + 2, k + 18, ACBlocks.unbreakableIce);
		world.setBlock(i + 21, j + 3, k + 10, ACBlocks.unbreakableIce);
		world.setBlock(i + 21, j + 3, k + 18, ACBlocks.unbreakableIce);
		world.setBlock(i + 21, j + 4, k + 10, ACBlocks.unbreakableIce);
		world.setBlock(i + 21, j + 4, k + 18, ACBlocks.unbreakableIce);
		world.setBlock(i + 21, j + 5, k + 10, ACBlocks.unbreakableIce);
		world.setBlock(i + 21, j + 5, k + 18, ACBlocks.unbreakableIce);
		world.setBlock(i + 21, j + 6, k + 10, ACBlocks.unbreakableIce);
		world.setBlock(i + 21, j + 6, k + 18, ACBlocks.unbreakableIce);
		world.setBlock(i + 21, j + 7, k + 10, ACBlocks.unbreakableIce);
		world.setBlock(i + 21, j + 7, k + 18, ACBlocks.unbreakableIce);
		world.setBlock(i + 21, j + 8, k + 10, ACBlocks.unbreakableIce);
		world.setBlock(i + 21, j + 8, k + 18, ACBlocks.unbreakableIce);
		world.setBlock(i + 21, j + 9, k + 11, ACBlocks.unbreakableIce);
		world.setBlock(i + 21, j + 9, k + 17, ACBlocks.unbreakableIce);
		world.setBlock(i + 21, j + 10, k + 12, ACBlocks.unbreakableIce);
		world.setBlock(i + 21, j + 10, k + 13, ACBlocks.unbreakableIce);
		world.setBlock(i + 21, j + 10, k + 14, ACBlocks.unbreakableIce);
		world.setBlock(i + 21, j + 10, k + 15, ACBlocks.unbreakableIce);
		world.setBlock(i + 21, j + 10, k + 16, ACBlocks.unbreakableIce);
		world.setBlock(i + 22, j + 0, k + 11, Blocks.snow);
		world.setBlock(i + 22, j + 0, k + 12, ACBlocks.acPlanks);
		world.setBlock(i + 22, j + 0, k + 13, ACBlocks.acPlanks);
		world.setBlock(i + 22, j + 0, k + 14, ACBlocks.acPlanks);
		world.setBlock(i + 22, j + 0, k + 15, ACBlocks.acPlanks);
		world.setBlock(i + 22, j + 0, k + 16, ACBlocks.acPlanks);
		world.setBlock(i + 22, j + 0, k + 17, Blocks.snow);
		world.setBlock(i + 22, j + 1, k + 11, Blocks.snow);
		world.setBlock(i + 22, j + 1, k + 12, ACBlocks.arcaneStone);
		world.setBlock(i + 22, j + 1, k + 13, Blocks.air);
		world.setBlock(i + 22, j + 1, k + 14, Blocks.air);
		world.setBlock(i + 22, j + 1, k + 15, Blocks.air);
		world.setBlock(i + 22, j + 1, k + 16, ACBlocks.arcaneStone);
		world.setBlock(i + 22, j + 1, k + 17, Blocks.snow);
		world.setBlock(i + 22, j + 2, k + 11, ACBlocks.unbreakableIce);
		world.setBlock(i + 22, j + 2, k + 12, Blocks.air);
		world.setBlock(i + 22, j + 2, k + 13, Blocks.air);
		world.setBlock(i + 22, j + 2, k + 14, Blocks.air);
		world.setBlock(i + 22, j + 2, k + 15, Blocks.air);
		world.setBlock(i + 22, j + 2, k + 16, Blocks.air);
		world.setBlock(i + 22, j + 2, k + 17, ACBlocks.unbreakableIce);
		world.setBlock(i + 22, j + 3, k + 11, ACBlocks.unbreakableIce);
		world.setBlock(i + 22, j + 3, k + 17, ACBlocks.unbreakableIce);
		world.setBlock(i + 22, j + 4, k + 11, ACBlocks.unbreakableIce);
		world.setBlock(i + 22, j + 4, k + 17, ACBlocks.unbreakableIce);
		world.setBlock(i + 22, j + 5, k + 11, ACBlocks.unbreakableIce);
		world.setBlock(i + 22, j + 5, k + 17, ACBlocks.unbreakableIce);
		world.setBlock(i + 22, j + 6, k + 11, ACBlocks.unbreakableIce);
		world.setBlock(i + 22, j + 6, k + 17, ACBlocks.unbreakableIce);
		world.setBlock(i + 22, j + 7, k + 11, ACBlocks.unbreakableIce);
		world.setBlock(i + 22, j + 7, k + 17, ACBlocks.unbreakableIce);
		world.setBlock(i + 22, j + 8, k + 11, ACBlocks.unbreakableIce);
		world.setBlock(i + 22, j + 8, k + 17, ACBlocks.unbreakableIce);
		world.setBlock(i + 22, j + 9, k + 12, ACBlocks.unbreakableIce);
		world.setBlock(i + 22, j + 9, k + 13, ACBlocks.unbreakableIce);
		world.setBlock(i + 22, j + 9, k + 14, ACBlocks.unbreakableIce);
		world.setBlock(i + 22, j + 9, k + 15, ACBlocks.unbreakableIce);
		world.setBlock(i + 22, j + 9, k + 16, ACBlocks.unbreakableIce);
		world.setBlock(i + 23, j + 0, k + 12, ACBlocks.unbreakableIce);
		world.setBlock(i + 23, j + 0, k + 13, ACBlocks.acPlanks);
		world.setBlock(i + 23, j + 0, k + 14, ACBlocks.acPlanks);
		world.setBlock(i + 23, j + 0, k + 15, ACBlocks.acPlanks);
		world.setBlock(i + 23, j + 0, k + 16, ACBlocks.unbreakableIce);
		world.setBlock(i + 23, j + 1, k + 12, Blocks.snow);
		world.setBlock(i + 23, j + 1, k + 13, Blocks.iron_bars);
		world.setBlock(i + 23, j + 1, k + 14, Blocks.iron_bars);
		world.setBlock(i + 23, j + 1, k + 15, Blocks.iron_bars);
		world.setBlock(i + 23, j + 1, k + 16, Blocks.snow);
		world.setBlock(i + 23, j + 2, k + 12, Blocks.snow);
		world.setBlock(i + 23, j + 2, k + 13, Blocks.iron_bars);
		world.setBlock(i + 23, j + 2, k + 14, Blocks.iron_bars);
		world.setBlock(i + 23, j + 2, k + 15, Blocks.iron_bars);
		world.setBlock(i + 23, j + 2, k + 16, Blocks.snow);
		world.setBlock(i + 23, j + 3, k + 12, Blocks.snow);
		world.setBlock(i + 23, j + 3, k + 13, Blocks.snow);
		world.setBlock(i + 23, j + 3, k + 14, Blocks.iron_bars);
		world.setBlock(i + 23, j + 3, k + 15, Blocks.snow);
		world.setBlock(i + 23, j + 3, k + 16, Blocks.snow);
		world.setBlock(i + 23, j + 4, k + 12, Blocks.snow);
		world.setBlock(i + 23, j + 4, k + 13, Blocks.snow);
		world.setBlock(i + 23, j + 4, k + 14, Blocks.snow);
		world.setBlock(i + 23, j + 4, k + 15, Blocks.snow);
		world.setBlock(i + 23, j + 4, k + 16, Blocks.snow);
		world.setBlock(i + 23, j + 5, k + 12, ACBlocks.unbreakableIce);
		world.setBlock(i + 23, j + 5, k + 13, Blocks.snow);
		world.setBlock(i + 23, j + 5, k + 14, Blocks.snow);
		world.setBlock(i + 23, j + 5, k + 15, Blocks.snow);
		world.setBlock(i + 23, j + 5, k + 16, ACBlocks.unbreakableIce);
		world.setBlock(i + 23, j + 6, k + 12, ACBlocks.unbreakableIce);
		world.setBlock(i + 23, j + 6, k + 13, ACBlocks.unbreakableIce);
		world.setBlock(i + 23, j + 6, k + 14, ACBlocks.unbreakableIce);
		world.setBlock(i + 23, j + 6, k + 15, ACBlocks.unbreakableIce);
		world.setBlock(i + 23, j + 6, k + 16, ACBlocks.unbreakableIce);
		world.setBlock(i + 23, j + 7, k + 12, ACBlocks.unbreakableIce);
		world.setBlock(i + 23, j + 7, k + 13, ACBlocks.unbreakableIce);
		world.setBlock(i + 23, j + 7, k + 14, ACBlocks.unbreakableIce);
		world.setBlock(i + 23, j + 7, k + 15, ACBlocks.unbreakableIce);
		world.setBlock(i + 23, j + 7, k + 16, ACBlocks.unbreakableIce);
		world.setBlock(i + 23, j + 8, k + 12, ACBlocks.unbreakableIce);
		world.setBlock(i + 23, j + 8, k + 13, ACBlocks.unbreakableIce);
		world.setBlock(i + 23, j + 8, k + 14, ACBlocks.unbreakableIce);
		world.setBlock(i + 23, j + 8, k + 15, ACBlocks.unbreakableIce);
		world.setBlock(i + 23, j + 8, k + 16, ACBlocks.unbreakableIce);
		world.setBlock(i + 24, j + 0, k + 13, ACBlocks.unbreakableIce);
		world.setBlock(i + 24, j + 0, k + 14, Blocks.snow);
		world.setBlock(i + 24, j + 0, k + 15, ACBlocks.unbreakableIce);
		world.setBlock(i + 24, j + 1, k + 13, Blocks.air);
		world.setBlock(i + 24, j + 1, k + 14, Blocks.air);
		world.setBlock(i + 24, j + 1, k + 15, Blocks.air);
		world.setBlock(i + 24, j + 2, k + 13, Blocks.air);
		world.setBlock(i + 24, j + 2, k + 14, Blocks.air);
		world.setBlock(i + 24, j + 2, k + 15, Blocks.air);
		world.setBlock(i + 24, j + 3, k + 13, Blocks.air);
		world.setBlock(i + 24, j + 3, k + 14, Blocks.air);
		world.setBlock(i + 24, j + 3, k + 15, Blocks.air);
		world.setBlock(i + 25, j + 0, k + 13, ACBlocks.unbreakableIce);
		world.setBlock(i + 25, j + 0, k + 14, Blocks.snow);
		world.setBlock(i + 25, j + 0, k + 15, ACBlocks.unbreakableIce);
		world.setBlock(i + 25, j + 1, k + 13, Blocks.air);
		world.setBlock(i + 25, j + 1, k + 14, Blocks.air);
		world.setBlock(i + 25, j + 1, k + 15, Blocks.air);
		world.setBlock(i + 25, j + 2, k + 13, Blocks.air);
		world.setBlock(i + 25, j + 2, k + 14, Blocks.air);
		world.setBlock(i + 25, j + 2, k + 15, Blocks.air);
		world.setBlock(i + 25, j + 3, k + 13, Blocks.air);
		world.setBlock(i + 25, j + 3, k + 14, Blocks.air);
		world.setBlock(i + 25, j + 3, k + 15, Blocks.air);
		world.setBlock(i + 26, j + 0, k + 13, ACBlocks.unbreakableIce);
		world.setBlock(i + 26, j + 0, k + 14, Blocks.snow);
		world.setBlock(i + 26, j + 0, k + 15, ACBlocks.unbreakableIce);
		world.setBlock(i + 26, j + 1, k + 13, Blocks.air);
		world.setBlock(i + 26, j + 1, k + 14, Blocks.air);
		world.setBlock(i + 26, j + 1, k + 15, Blocks.air);
		world.setBlock(i + 26, j + 2, k + 13, Blocks.air);
		world.setBlock(i + 26, j + 2, k + 14, Blocks.air);
		world.setBlock(i + 26, j + 2, k + 15, Blocks.air);
		world.setBlock(i + 26, j + 3, k + 13, Blocks.air);
		world.setBlock(i + 26, j + 3, k + 14, Blocks.air);
		world.setBlock(i + 26, j + 3, k + 15, Blocks.air);
		world.setBlock(i + 27, j + 0, k + 13, ACBlocks.unbreakableIce);
		world.setBlock(i + 27, j + 0, k + 14, Blocks.snow);
		world.setBlock(i + 27, j + 0, k + 15, ACBlocks.unbreakableIce);
		world.setBlock(i + 27, j + 1, k + 13, ACBlocks.frostFence);
		world.setBlock(i + 27, j + 1, k + 14, Blocks.air);
		world.setBlock(i + 27, j + 1, k + 15, ACBlocks.frostFence);
		world.setBlock(i + 27, j + 2, k + 13, ACBlocks.frostFence);
		world.setBlock(i + 27, j + 2, k + 14, Blocks.air);
		world.setBlock(i + 27, j + 2, k + 15, ACBlocks.frostFence);
		world.setBlock(i + 27, j + 3, k + 13, ACBlocks.frostFence);
		world.setBlock(i + 27, j + 3, k + 14, ACBlocks.arcaneStone);
		world.setBlock(i + 27, j + 3, k + 15, ACBlocks.frostFence);
		world.setBlock(i + 28, j + 0, k + 13, ACBlocks.unbreakableIce);
		world.setBlock(i + 28, j + 0, k + 14, Blocks.snow);
		world.setBlock(i + 28, j + 0, k + 15, ACBlocks.unbreakableIce);
		world.setBlock(i + 28, j + 1, k + 13, Blocks.air);
		world.setBlock(i + 28, j + 1, k + 14, Blocks.air);
		world.setBlock(i + 28, j + 1, k + 15, Blocks.air);
		world.setBlock(i + 28, j + 2, k + 13, Blocks.air);
		world.setBlock(i + 28, j + 2, k + 14, Blocks.air);
		world.setBlock(i + 28, j + 2, k + 15, Blocks.air);
		world.setBlock(i + 28, j + 3, k + 13, Blocks.air);
		world.setBlock(i + 28, j + 3, k + 14, Blocks.air);
		world.setBlock(i + 28, j + 3, k + 15, Blocks.air);
		world.setBlock(i + 29, j + 0, k + 4, Blocks.snow);
		world.setBlock(i + 29, j + 0, k + 5, Blocks.snow);
		world.setBlock(i + 29, j + 0, k + 6, Blocks.snow);
		world.setBlock(i + 29, j + 0, k + 7, Blocks.snow);
		world.setBlock(i + 29, j + 0, k + 8, Blocks.snow);
		world.setBlock(i + 29, j + 0, k + 13, ACBlocks.unbreakableIce);
		world.setBlock(i + 29, j + 0, k + 14, Blocks.snow);
		world.setBlock(i + 29, j + 0, k + 15, ACBlocks.unbreakableIce);
		world.setBlock(i + 29, j + 0, k + 20, Blocks.snow);
		world.setBlock(i + 29, j + 0, k + 21, Blocks.snow);
		world.setBlock(i + 29, j + 0, k + 22, Blocks.snow);
		world.setBlock(i + 29, j + 0, k + 23, Blocks.snow);
		world.setBlock(i + 29, j + 0, k + 24, Blocks.snow);
		world.setBlock(i + 29, j + 1, k + 4, Blocks.snow);
		world.setBlock(i + 29, j + 1, k + 5, Blocks.snow);
		world.setBlock(i + 29, j + 1, k + 6, Blocks.snow);
		world.setBlock(i + 29, j + 1, k + 7, Blocks.snow);
		world.setBlock(i + 29, j + 1, k + 8, Blocks.snow);
		world.setBlock(i + 29, j + 1, k + 13, Blocks.air);
		world.setBlock(i + 29, j + 1, k + 14, Blocks.air);
		world.setBlock(i + 29, j + 1, k + 15, Blocks.air);
		world.setBlock(i + 29, j + 1, k + 20, Blocks.snow);
		world.setBlock(i + 29, j + 1, k + 21, Blocks.snow);
		world.setBlock(i + 29, j + 1, k + 22, Blocks.snow);
		world.setBlock(i + 29, j + 1, k + 23, Blocks.snow);
		world.setBlock(i + 29, j + 1, k + 24, Blocks.snow);
		world.setBlock(i + 29, j + 2, k + 4, Blocks.snow);
		world.setBlock(i + 29, j + 2, k + 5, Blocks.snow);
		world.setBlock(i + 29, j + 2, k + 6, Blocks.snow);
		world.setBlock(i + 29, j + 2, k + 7, Blocks.snow);
		world.setBlock(i + 29, j + 2, k + 8, Blocks.snow);
		world.setBlock(i + 29, j + 2, k + 13, Blocks.air);
		world.setBlock(i + 29, j + 2, k + 14, Blocks.air);
		world.setBlock(i + 29, j + 2, k + 15, Blocks.air);
		world.setBlock(i + 29, j + 2, k + 20, Blocks.snow);
		world.setBlock(i + 29, j + 2, k + 21, Blocks.snow);
		world.setBlock(i + 29, j + 2, k + 22, Blocks.snow);
		world.setBlock(i + 29, j + 2, k + 23, Blocks.snow);
		world.setBlock(i + 29, j + 2, k + 24, Blocks.snow);
		world.setBlock(i + 29, j + 3, k + 5, Blocks.snow);
		world.setBlock(i + 29, j + 3, k + 6, Blocks.snow);
		world.setBlock(i + 29, j + 3, k + 7, Blocks.snow);
		world.setBlock(i + 29, j + 3, k + 13, Blocks.air);
		world.setBlock(i + 29, j + 3, k + 14, Blocks.air);
		world.setBlock(i + 29, j + 3, k + 15, Blocks.air);
		world.setBlock(i + 29, j + 3, k + 21, Blocks.snow);
		world.setBlock(i + 29, j + 3, k + 22, Blocks.snow);
		world.setBlock(i + 29, j + 3, k + 23, Blocks.snow);
		world.setBlock(i + 30, j + 0, k + 3, Blocks.snow);
		world.setBlock(i + 30, j + 0, k + 4, Blocks.snow);
		world.setBlock(i + 30, j + 0, k + 5, Blocks.snow);
		world.setBlock(i + 30, j + 0, k + 6, Blocks.snow);
		world.setBlock(i + 30, j + 0, k + 7, Blocks.snow);
		world.setBlock(i + 30, j + 0, k + 8, Blocks.snow);
		world.setBlock(i + 30, j + 0, k + 9, Blocks.snow);
		world.setBlock(i + 30, j + 0, k + 13, ACBlocks.unbreakableIce);
		world.setBlock(i + 30, j + 0, k + 14, Blocks.snow);
		world.setBlock(i + 30, j + 0, k + 15, ACBlocks.unbreakableIce);
		world.setBlock(i + 30, j + 0, k + 19, Blocks.snow);
		world.setBlock(i + 30, j + 0, k + 20, Blocks.snow);
		world.setBlock(i + 30, j + 0, k + 21, Blocks.snow);
		world.setBlock(i + 30, j + 0, k + 22, Blocks.snow);
		world.setBlock(i + 30, j + 0, k + 23, Blocks.snow);
		world.setBlock(i + 30, j + 0, k + 24, Blocks.snow);
		world.setBlock(i + 30, j + 0, k + 25, Blocks.snow);
		world.setBlock(i + 30, j + 1, k + 3, Blocks.snow);
		world.setBlock(i + 30, j + 1, k + 4, Blocks.air);
		world.setBlock(i + 30, j + 1, k + 5, Blocks.air);
		world.setBlock(i + 30, j + 1, k + 6, Blocks.air);
		world.setBlock(i + 30, j + 1, k + 7, Blocks.air);
		world.setBlock(i + 30, j + 1, k + 8, Blocks.air);
		world.setBlock(i + 30, j + 1, k + 9, Blocks.snow);
		world.setBlock(i + 30, j + 1, k + 13, Blocks.air);
		world.setBlock(i + 30, j + 1, k + 14, Blocks.air);
		world.setBlock(i + 30, j + 1, k + 15, Blocks.air);
		world.setBlock(i + 30, j + 1, k + 19, Blocks.snow);
		world.setBlock(i + 30, j + 1, k + 20, Blocks.air);
		world.setBlock(i + 30, j + 1, k + 21, Blocks.air);
		world.setBlock(i + 30, j + 1, k + 22, Blocks.air);
		world.setBlock(i + 30, j + 1, k + 23, Blocks.air);
		world.setBlock(i + 30, j + 1, k + 24, Blocks.air);
		world.setBlock(i + 30, j + 1, k + 25, Blocks.snow);
		world.setBlock(i + 30, j + 2, k + 3, Blocks.snow);
		world.setBlock(i + 30, j + 2, k + 4, Blocks.air);
		world.setBlock(i + 30, j + 2, k + 5, Blocks.air);
		world.setBlock(i + 30, j + 2, k + 6, Blocks.air);
		world.setBlock(i + 30, j + 2, k + 7, Blocks.air);
		world.setBlock(i + 30, j + 2, k + 8, Blocks.air);
		world.setBlock(i + 30, j + 2, k + 9, Blocks.snow);
		world.setBlock(i + 30, j + 2, k + 13, Blocks.air);
		world.setBlock(i + 30, j + 2, k + 14, Blocks.air);
		world.setBlock(i + 30, j + 2, k + 15, Blocks.air);
		world.setBlock(i + 30, j + 2, k + 19, Blocks.snow);
		world.setBlock(i + 30, j + 2, k + 20, Blocks.air);
		world.setBlock(i + 30, j + 2, k + 21, Blocks.air);
		world.setBlock(i + 30, j + 2, k + 22, Blocks.air);
		world.setBlock(i + 30, j + 2, k + 23, Blocks.air);
		world.setBlock(i + 30, j + 2, k + 24, Blocks.air);
		world.setBlock(i + 30, j + 2, k + 25, Blocks.snow);
		world.setBlock(i + 30, j + 3, k + 3, Blocks.snow);
		world.setBlock(i + 30, j + 3, k + 4, Blocks.snow);
		world.setBlock(i + 30, j + 3, k + 5, Blocks.air);
		world.setBlock(i + 30, j + 3, k + 6, Blocks.air);
		world.setBlock(i + 30, j + 3, k + 7, Blocks.air);
		world.setBlock(i + 30, j + 3, k + 8, Blocks.snow);
		world.setBlock(i + 30, j + 3, k + 9, Blocks.snow);
		world.setBlock(i + 30, j + 3, k + 13, Blocks.air);
		world.setBlock(i + 30, j + 3, k + 14, Blocks.air);
		world.setBlock(i + 30, j + 3, k + 15, Blocks.air);
		world.setBlock(i + 30, j + 3, k + 19, Blocks.snow);
		world.setBlock(i + 30, j + 3, k + 20, Blocks.snow);
		world.setBlock(i + 30, j + 3, k + 21, Blocks.air);
		world.setBlock(i + 30, j + 3, k + 22, Blocks.air);
		world.setBlock(i + 30, j + 3, k + 23, Blocks.air);
		world.setBlock(i + 30, j + 3, k + 24, Blocks.snow);
		world.setBlock(i + 30, j + 3, k + 25, Blocks.snow);
		world.setBlock(i + 30, j + 4, k + 4, Blocks.snow);
		world.setBlock(i + 30, j + 4, k + 5, Blocks.snow);

		generate2(world, rand, i, j, k);
		return true;
	}

	public boolean generate2(World world, Random rand, int i, int j, int k)
	{
		world.setBlock(i + 30, j + 4, k + 6, Blocks.snow);
		world.setBlock(i + 30, j + 4, k + 7, Blocks.snow);
		world.setBlock(i + 30, j + 4, k + 8, Blocks.snow);
		world.setBlock(i + 30, j + 4, k + 20, Blocks.snow);
		world.setBlock(i + 30, j + 4, k + 21, Blocks.snow);
		world.setBlock(i + 30, j + 4, k + 22, Blocks.snow);
		world.setBlock(i + 30, j + 4, k + 23, Blocks.snow);
		world.setBlock(i + 30, j + 4, k + 24, Blocks.snow);
		world.setBlock(i + 31, j + 0, k + 2, Blocks.snow);
		world.setBlock(i + 31, j + 0, k + 3, Blocks.snow);
		world.setBlock(i + 31, j + 0, k + 4, Blocks.snow);
		world.setBlock(i + 31, j + 0, k + 5, Blocks.snow);
		world.setBlock(i + 31, j + 0, k + 6, Blocks.snow);
		world.setBlock(i + 31, j + 0, k + 7, Blocks.snow);
		world.setBlock(i + 31, j + 0, k + 8, Blocks.snow);
		world.setBlock(i + 31, j + 0, k + 9, Blocks.snow);
		world.setBlock(i + 31, j + 0, k + 10, Blocks.snow);
		world.setBlock(i + 31, j + 0, k + 13, ACBlocks.unbreakableIce);
		world.setBlock(i + 31, j + 0, k + 14, Blocks.snow);
		world.setBlock(i + 31, j + 0, k + 15, ACBlocks.unbreakableIce);
		world.setBlock(i + 31, j + 0, k + 18, Blocks.snow);
		world.setBlock(i + 31, j + 0, k + 19, Blocks.snow);
		world.setBlock(i + 31, j + 0, k + 20, Blocks.snow);
		world.setBlock(i + 31, j + 0, k + 21, Blocks.snow);
		world.setBlock(i + 31, j + 0, k + 22, Blocks.snow);
		world.setBlock(i + 31, j + 0, k + 23, Blocks.snow);
		world.setBlock(i + 31, j + 0, k + 24, Blocks.snow);
		world.setBlock(i + 31, j + 0, k + 25, Blocks.snow);
		world.setBlock(i + 31, j + 0, k + 26, Blocks.snow);
		world.setBlock(i + 31, j + 1, k + 2, Blocks.snow);
		world.setBlock(i + 31, j + 1, k + 3, ACBlocks.arcaneStone);
		world.setBlock(i + 31, j + 1, k + 4, Blocks.air);
		world.setBlock(i + 31, j + 1, k + 5, Blocks.air);
		world.setBlock(i + 31, j + 1, k + 6, Blocks.air);
		world.setBlock(i + 31, j + 1, k + 7, Blocks.air);
		world.setBlock(i + 31, j + 1, k + 8, Blocks.air);
		world.setBlock(i + 31, j + 1, k + 9, Blocks.air);
		world.setBlock(i + 31, j + 1, k + 10, Blocks.snow);
		world.setBlock(i + 31, j + 1, k + 13, ACBlocks.frostFence);
		world.setBlock(i + 31, j + 1, k + 14, Blocks.air);
		world.setBlock(i + 31, j + 1, k + 15, ACBlocks.frostFence);
		world.setBlock(i + 31, j + 1, k + 18, Blocks.snow);
		world.setBlock(i + 31, j + 1, k + 19, Blocks.air);
		world.setBlock(i + 31, j + 1, k + 20, Blocks.air);
		world.setBlock(i + 31, j + 1, k + 21, Blocks.air);
		world.setBlock(i + 31, j + 1, k + 22, Blocks.air);
		world.setBlock(i + 31, j + 1, k + 23, Blocks.air);
		world.setBlock(i + 31, j + 1, k + 24, Blocks.air);
		world.setBlock(i + 31, j + 1, k + 25, ACBlocks.arcaneStone);
		world.setBlock(i + 31, j + 1, k + 26, Blocks.snow);
		world.setBlock(i + 31, j + 2, k + 2, Blocks.snow);
		world.setBlock(i + 31, j + 2, k + 3, Blocks.air);
		world.setBlock(i + 31, j + 2, k + 4, Blocks.air);
		world.setBlock(i + 31, j + 2, k + 5, Blocks.air);
		world.setBlock(i + 31, j + 2, k + 6, Blocks.air);
		world.setBlock(i + 31, j + 2, k + 7, Blocks.air);
		world.setBlock(i + 31, j + 2, k + 8, Blocks.air);
		world.setBlock(i + 31, j + 2, k + 9, Blocks.air);
		world.setBlock(i + 31, j + 2, k + 10, Blocks.snow);
		world.setBlock(i + 31, j + 2, k + 13, ACBlocks.frostFence);
		world.setBlock(i + 31, j + 2, k + 14, Blocks.air);
		world.setBlock(i + 31, j + 2, k + 15, ACBlocks.frostFence);
		world.setBlock(i + 31, j + 2, k + 18, Blocks.snow);
		world.setBlock(i + 31, j + 2, k + 19, Blocks.air);
		world.setBlock(i + 31, j + 2, k + 20, Blocks.air);
		world.setBlock(i + 31, j + 2, k + 21, Blocks.air);
		world.setBlock(i + 31, j + 2, k + 22, Blocks.air);
		world.setBlock(i + 31, j + 2, k + 23, Blocks.air);
		world.setBlock(i + 31, j + 2, k + 24, Blocks.air);
		world.setBlock(i + 31, j + 2, k + 25, Blocks.air);
		world.setBlock(i + 31, j + 2, k + 26, Blocks.snow);
		world.setBlock(i + 31, j + 3, k + 2, Blocks.snow);
		world.setBlock(i + 31, j + 3, k + 3, Blocks.air);
		world.setBlock(i + 31, j + 3, k + 4, Blocks.air);
		world.setBlock(i + 31, j + 3, k + 5, Blocks.air);
		world.setBlock(i + 31, j + 3, k + 6, Blocks.air);
		world.setBlock(i + 31, j + 3, k + 7, Blocks.air);
		world.setBlock(i + 31, j + 3, k + 8, Blocks.air);
		world.setBlock(i + 31, j + 3, k + 9, Blocks.air);
		world.setBlock(i + 31, j + 3, k + 10, Blocks.snow);
		world.setBlock(i + 31, j + 3, k + 13, ACBlocks.frostFence);
		world.setBlock(i + 31, j + 3, k + 14, ACBlocks.arcaneStone);
		world.setBlock(i + 31, j + 3, k + 15, ACBlocks.frostFence);
		world.setBlock(i + 31, j + 3, k + 18, Blocks.snow);
		world.setBlock(i + 31, j + 3, k + 19, Blocks.air);
		world.setBlock(i + 31, j + 3, k + 20, Blocks.air);
		world.setBlock(i + 31, j + 3, k + 21, Blocks.air);
		world.setBlock(i + 31, j + 3, k + 22, Blocks.air);
		world.setBlock(i + 31, j + 3, k + 23, Blocks.air);
		world.setBlock(i + 31, j + 3, k + 24, Blocks.air);
		world.setBlock(i + 31, j + 3, k + 25, Blocks.air);
		world.setBlock(i + 31, j + 3, k + 26, Blocks.snow);
		world.setBlock(i + 31, j + 4, k + 3, Blocks.snow);
		world.setBlock(i + 31, j + 4, k + 4, Blocks.air);
		world.setBlock(i + 31, j + 4, k + 5, Blocks.air);
		world.setBlock(i + 31, j + 4, k + 6, Blocks.air);
		world.setBlock(i + 31, j + 4, k + 7, Blocks.air);
		world.setBlock(i + 31, j + 4, k + 8, Blocks.air);
		world.setBlock(i + 31, j + 4, k + 9, Blocks.snow);
		world.setBlock(i + 31, j + 4, k + 19, Blocks.snow);
		world.setBlock(i + 31, j + 4, k + 20, Blocks.air);
		world.setBlock(i + 31, j + 4, k + 21, Blocks.air);
		world.setBlock(i + 31, j + 4, k + 22, Blocks.air);
		world.setBlock(i + 31, j + 4, k + 23, Blocks.air);
		world.setBlock(i + 31, j + 4, k + 24, Blocks.air);
		world.setBlock(i + 31, j + 4, k + 25, Blocks.snow);
		world.setBlock(i + 31, j + 5, k + 4, Blocks.snow);
		world.setBlock(i + 31, j + 5, k + 5, Blocks.snow);
		world.setBlock(i + 31, j + 5, k + 6, Blocks.snow);
		world.setBlock(i + 31, j + 5, k + 7, Blocks.snow);
		world.setBlock(i + 31, j + 5, k + 8, Blocks.snow);
		world.setBlock(i + 31, j + 5, k + 20, Blocks.snow);
		world.setBlock(i + 31, j + 5, k + 21, Blocks.snow);
		world.setBlock(i + 31, j + 5, k + 22, Blocks.snow);
		world.setBlock(i + 31, j + 5, k + 23, Blocks.snow);
		world.setBlock(i + 31, j + 5, k + 24, Blocks.snow);
		world.setBlock(i + 32, j + 0, k + 1, Blocks.snow);
		world.setBlock(i + 32, j + 0, k + 2, Blocks.snow);
		world.setBlock(i + 32, j + 0, k + 3, Blocks.snow);
		world.setBlock(i + 32, j + 0, k + 4, Blocks.snow);
		world.setBlock(i + 32, j + 0, k + 5, Blocks.snow);
		world.setBlock(i + 32, j + 0, k + 6, Blocks.snow);
		world.setBlock(i + 32, j + 0, k + 7, Blocks.snow);
		world.setBlock(i + 32, j + 0, k + 8, Blocks.snow);
		world.setBlock(i + 32, j + 0, k + 9, Blocks.snow);
		world.setBlock(i + 32, j + 0, k + 10, Blocks.snow);
		world.setBlock(i + 32, j + 0, k + 11, Blocks.snow);
		world.setBlock(i + 32, j + 0, k + 13, ACBlocks.unbreakableIce);
		world.setBlock(i + 32, j + 0, k + 14, Blocks.snow);
		world.setBlock(i + 32, j + 0, k + 15, ACBlocks.unbreakableIce);
		world.setBlock(i + 32, j + 0, k + 17, Blocks.snow);
		world.setBlock(i + 32, j + 0, k + 18, Blocks.snow);
		world.setBlock(i + 32, j + 0, k + 19, Blocks.snow);
		world.setBlock(i + 32, j + 0, k + 20, Blocks.snow);
		world.setBlock(i + 32, j + 0, k + 21, Blocks.snow);
		world.setBlock(i + 32, j + 0, k + 22, Blocks.snow);
		world.setBlock(i + 32, j + 0, k + 23, Blocks.snow);
		world.setBlock(i + 32, j + 0, k + 24, Blocks.snow);
		world.setBlock(i + 32, j + 0, k + 25, Blocks.snow);
		world.setBlock(i + 32, j + 0, k + 26, Blocks.snow);
		world.setBlock(i + 32, j + 0, k + 27, Blocks.snow);
		world.setBlock(i + 32, j + 1, k + 1, Blocks.snow);
		world.setBlock(i + 32, j + 1, k + 2, Blocks.air);
		world.setBlock(i + 32, j + 1, k + 3, Blocks.air);
		world.setBlock(i + 32, j + 1, k + 4, Blocks.air);
		world.setBlock(i + 32, j + 1, k + 5, Blocks.air);
		world.setBlock(i + 32, j + 1, k + 6, Blocks.air);
		world.setBlock(i + 32, j + 1, k + 7, Blocks.air);
		world.setBlock(i + 32, j + 1, k + 8, Blocks.air);
		world.setBlock(i + 32, j + 1, k + 9, Blocks.air);
		world.setBlock(i + 32, j + 1, k + 10, Blocks.air);
		world.setBlock(i + 32, j + 1, k + 11, Blocks.snow);
		world.setBlock(i + 32, j + 1, k + 13, Blocks.air);
		world.setBlock(i + 32, j + 1, k + 14, Blocks.air);
		world.setBlock(i + 32, j + 1, k + 15, Blocks.air);
		world.setBlock(i + 32, j + 1, k + 17, Blocks.snow);
		world.setBlock(i + 32, j + 1, k + 18, Blocks.air);
		world.setBlock(i + 32, j + 1, k + 19, Blocks.air);
		world.setBlock(i + 32, j + 1, k + 20, Blocks.air);
		world.setBlock(i + 32, j + 1, k + 21, Blocks.air);
		world.setBlock(i + 32, j + 1, k + 22, Blocks.air);
		world.setBlock(i + 32, j + 1, k + 23, Blocks.air);
		world.setBlock(i + 32, j + 1, k + 24, Blocks.air);
		world.setBlock(i + 32, j + 1, k + 25, Blocks.air);
		world.setBlock(i + 32, j + 1, k + 26, Blocks.air);
		world.setBlock(i + 32, j + 1, k + 27, Blocks.snow);
